Workbook
Name _: #REF!
Name _: #REF!
Name _??_??_?C?g??: #REF!
Name _??_??_?C?g??: #REF!
Name ___DAT1: [3]원본!#REF!
Name ___DAT10: [3]원본!#REF!
Name ___DAT12: [3]원본!#REF!
Name ___DAT13: [3]원본!#REF!
Name ___DAT14: [3]원본!#REF!
Name ___DAT15: [3]원본!#REF!
Name ___DAT16: [3]원본!#REF!
Name ___DAT17: [3]원본!#REF!
Name ___DAT18: [3]원본!#REF!
Name ___DAT19: [3]원본!#REF!
Name ___DAT2: [3]원본!#REF!
Name ___DAT20: [3]원본!#REF!
Name ___DAT3: [3]원본!#REF!
Name ___DAT4: [3]원본!#REF!
Name ___DAT5: #REF!
Name ___DAT6: [3]원본!#REF!
Name ___DAT7: [3]원본!#REF!
Name ___DAT8: [3]원본!#REF!
Name ___DAT9: [3]원본!#REF!
Name ___QQ123: #REF!
Name __DAT11: #REF!
Name __DAT21: #REF!
Name __DAT22: #REF!
Name __DAT23: #REF!
Name __DAT24: #REF!
Name __DAT25: #REF!
Name __DAT26: #REF!
Name __DAT27: #REF!
Name __DAT28: #REF!
Name __P3: #REF!
Name __P4: #REF!
Name __P5: #REF!
Name __P6: #REF!
Name __PP1: #REF!
Name _0101__장비_설치공사: #REF!
Name _0201__소화_장비설치공사: #REF!
Name _1: #REF!
Name _1: #REF!
Name _1._PANEL_BD.__LP___1: #REF!
Name _1._옥외배관및장비설치공사: #REF!
Name _1_3_0Crite: #REF!
Name _10: [8]고정1!$A$416:$L$458
Name _10A_61: #N/A
Name _10A_62: #N/A
Name _10A_63: #N/A
Name _10A_64: #N/A
Name _10A_65: #N/A
Name _10A_66: #N/A
Name _10A_67: #N/A
Name _10A_68: #N/A
Name _10A_69: #N/A
Name _10A_70: #N/A
Name _10A_71: #N/A
Name _10A_72: #N/A
Name _10A_73: #N/A
Name _10A_74: #N/A

Sheet 용역청구서 표지
B4: 용 역 청 구 서
B7: P4 Ph4 GAS 1공구 마감공사
C8: S25-004
C14: 2026년 01월
C15: 대성이엔지

Sheet 용역 청구서(갑지)
A1: 용 역 청 구 서
A3: 1 | B3: 공 사 명 | C3: : | D3: ='용역청구서 표지'!$B$7 -> P4 Ph4 GAS 1공구 마감공사 | E3: ='용역청구서 표지'!$C$8 -> S25-004
A4: 2 | B4: 공 종 | C4: : | D4: 외주용역(M/M부분)
A5: 3 | B5: 계 약 금 액 | C5: : | D5: =ROUNDUP(E5,0) -> 30000000 | E5: =집계장!I22 -> 30000000 | F5: (VAT 별도)
A6: 4 | B6: 누 계 기 성 금 액 | C6: : | D6: =ROUNDUP(E6,0) -> 30000000 | E6: =E13+E7 -> 30000000 | F6: (VAT 별도)
A7: 5 | B7: 전 회 기 성 금 액 | C7: : | D7: =ROUNDUP(E7,0) -> 0 | F7: (VAT 별도)
A8: 6 | B8: 금 회 기 성 금 액 | C8: : | D8: =ROUNDUP(E8,0) -> 30000000 | E8: =집계장!F18 -> 30000000 | F8: (VAT 별도)
A9: 7 | B9: 선 금 액 | C9: : | D9: =ROUNDUP(E9,0) -> 0 | E9: =집계장!K20 -> 0 | F9: (VAT 별도)
A10: 8 | B10: 선 금 전 회 공 제 | C10: : | D10: =ROUNDUP(E10,0) -> 0 | E10: =집계장!G20 -> 0 | F10: (VAT 별도)
A11: 9 | B11: 선 금 금 회 공 제 | C11: : | D11: =ROUNDUP(E11,0) -> 0 | E11: =집계장!F20 -> 0 | F11: (VAT 별도)
A12: 10 | B12: 선 금 잔 여 금 액 | C12: : | D12: =ROUNDUP(E12,0) -> 0 | E12: =집계장!L20 -> 0 | F12: (VAT 별도)
A13: 11 | B13: 금 회 청 구 금 액 | C13: : | D13: =ROUNDUP(E13,0) -> 30000000 | E13: =집계장!F22 -> 30000000 | F13: (VAT 별도)
A14: 12 | B14: 잔 여 기 성 금 액 | C14: : | D14: =ROUNDUP(E14,0) -> -101700000 | E14: =-ROUNDDOWN(집계장!I7,-5) -> -101700000 | F14: (VAT 별도)
A15: 13 | B15: 공 정 율 | C15: : | D15: 1
A16: 14 | B16: 청 구 공 사 기 간 | C16: : | D16: 2026. 01. 01 ~ 2026. 01. 31
B18: 위 공사의 하도급에 있어서 공사설계도서, 시방서,품질관리 기준 및 약정대로 시공 되었음을 확인하오며. 만약 귀사의 현장담당의 검사에
B19: 관하여 하자가 발견된 때에는 즉시 실액배상 또는 재 시공할것을 서약하고 이에 기성 청구서를 제출합니다.
B20: 상기건과 관련하여 본 청구 이전까지의 모든 대금은 수령하였음을 확약합니다.
F21: 작 성 일 : 2025 년 12 월 31일
F23: 상 호 : | G23: 대성이엔지
B24: ※첨 부 : 기성내역서 1부. | F24: 주 소 : | G24: 경기도 파주시 파주읍 주라위길 380
F25: 대표이사 : | G25: 정 성 기 | I25: (인)
D26: ㈜케이씨이앤씨 귀하

Sheet 용역 내역서(을지)
A1: 용 역 내 역 서
A2: P4 Ph4 GAS 1공구 마감공사 | G2: 단위 : 원
A3: 품 명 | B3: 규 격 | C3: 단위 | D3: 단 가 | E3: 금 회 청 구
E4: 수 량 | F4: 금 액 | G4: 비 고
A5: 고급기술인 | B5: S+ | C5: M/M | D5: 1400000 | E5: 1 | F5: =D5*E5 -> 1400000
A6: 고급기술인 | B6: S | C6: M/M | D6: 1200000 | F6: =D6*E6 -> 0
A7: 중급기술인 | B7: A+ | C7: M/M | D7: 1000000 | F7: =D7*E7 -> 0
A8: 중급기술인 | B8: A | C8: M/M | D8: 900000 | F8: =D8*E8 -> 0
A9: 중급기술인 | B9: B+ | C9: M/M | D9: 800000 | F9: =D9*E9 -> 0
A10: 중급기술인 | B10: B | C10: M/M | D10: 700000 | F10: =D10*E10 -> 0
A11: 초급 기술인 | B11: C | C11: M/M | D11: 600000 | F11: =D11*E11 -> 0
A13: 인센티브 | E13: 0.01 | F13: =SUM(F5:F11)*E13 -> 14000
A15: 총 계 | E15: =SUM(E5:E11) -> 1 | F15: =SUM(F5:F13) -> 1414000

Sheet 내역서(을지)
A1: 용 역 내 역 서
A2: P4 Ph4 GAS 1공구 마감공사 | G2: 단위 : 원
A3: 품 명 | B3: 규 격 | C3: 단위 | D3: 단 가 | E3: 금 회 청 구 | G3: 비 고
E4: 수 량 | F4: 금 액 | K4: =F19 -> 30000000
A5: 고급기술인 | B5: S+ | C5: M/M | D5: 1400000 | E5: 8 | F5: =D5*E5 -> 11200000 | K5: =[2]을지!F13 -> 61200000
A6: 고급기술인 | B6: S | C6: M/M | D6: 1200000 | E6: 4 | F6: =D6*E6 -> 4800000 | K6: =K4-K5 -> -31200000
A7: 중급기술인 | B7: A+ | C7: M/M | D7: 1000000 | E7: 2 | F7: =D7*E7 -> 2000000 | J7: 64
A8: 중급기술인 | B8: A | C8: M/M | D8: 900000 | E8: 2 | F8: =D8*E8 -> 1800000 | J8: =SUM(E5:E11) -> 30
A9: 중급기술인 | B9: B+ | C9: M/M | D9: 800000 | E9: 6 | F9: =D9*E9 -> 4800000 | J9: =J7-J8 -> 34
A10: 중급기술인 | B10: B | C10: M/M | D10: 700000 | E10: 6 | F10: =D10*E10 -> 4200000
A11: 초급기술인 | B11: C | C11: M/M | D11: 600000 | E11: 2 | F11: =D11*E11 -> 1200000
A13: 인센티브 | F13: =SUM(F5:F11)*E13 -> 0
A19: 총 계 | E19: =SUM(E5:E18) -> 30 | F19: =ROUNDDOWN(F5+F6+F7+F8+F9+F10+F11+F13,-5) -> 30000000

Sheet 물량 내역서
A1: 2026년 (01)월 물량 내역서
A2: ='용역청구서 표지'!$B$7 -> P4 Ph4 GAS 1공구 마감공사 | M2: 단위 : 원
A3: 품 명 | B3: 규 격 | C3: 단위 | D3: W/P 수량 | E3: 단 가 | F3: 계 약 내 역 | H3: 전 회 누 계 물 량 | J3: 금 회 물 량 | L3: 누 계 물 량
F4: D/I 수량 | G4: 금액 | H4: D/I 수량 | I4: 금액 | J4: D/I 수량 | K4: 금액 | L4: D/I 수량 | M4: 금액
A5: WEDING POINT | B5: 8A | C5: POINT | E5: 475000 | F5: =L5 -> 0 | G5: =M5 -> 0 | J5: =$D5*'DIA-INCH'!$C5 -> 0 | K5: =$E5*$J5 -> 0 | L5: =H5+J5 -> 0 | M5: =I5+K5 -> 0
A6: WEDING POINT | B6: 15A | C6: POINT | E6: 475000 | F6: =L6 -> 0 | G6: =M6 -> 0 | J6: =$D6*'DIA-INCH'!$C6 -> 0 | K6: =$E6*$J6 -> 0 | L6: =H6+J6 -> 0 | M6: =I6+K6 -> 0
A7: WEDING POINT | B7: 20A | C7: POINT | E7: 475000 | F7: =L7 -> 0 | G7: =M7 -> 0 | J7: =$D7*'DIA-INCH'!$C7 -> 0 | K7: =$E7*$J7 -> 0 | L7: =H7+J7 -> 0 | M7: =I7+K7 -> 0
A8: WEDING POINT | B8: 25A | C8: POINT | D8: 0 | E8: 475000 | F8: =L8 -> 0 | G8: =M8 -> 0 | J8: =$D8*'DIA-INCH'!$C8 -> 0 | K8: =$E8*$J8 -> 0 | L8: =H8+J8 -> 0 | M8: =I8+K8 -> 0
A9: WEDING POINT | B9: 32A | C9: POINT | D9: 0 | E9: 475000 | F9: =L9 -> 0 | G9: =M9 -> 0 | J9: =$D9*'DIA-INCH'!$C9 -> 0 | K9: =$E9*$J9 -> 0 | L9: =H9+J9 -> 0 | M9: =I9+K9 -> 0
A10: WEDING POINT | B10: 40A | C10: POINT | D10: 0 | E10: 475000 | F10: =L10 -> 0 | G10: =M10 -> 0 | J10: =$D10*'DIA-INCH'!$C10 -> 0 | K10: =$E10*$J10 -> 0 | L10: =H10+J10 -> 0 | M10: =I10+K10 -> 0
A11: WEDING POINT | B11: 50A | C11: POINT | D11: 1 | E11: 475000 | F11: =L11 -> 256 | G11: =M11 -> 121600000 | H11: 254 | I11: 120650000 | J11: =$D11*'DIA-INCH'!$C11 -> 2 | K11: =$E11*$J11 -> 950000 | L11: =H11+J11 -> 256 | M11: =I11+K11 -> 121600000
A12: WEDING POINT | B12: 65A | C12: POINT | D12: 0 | E12: 475000 | F12: =L12 -> 0 | G12: =M12 -> 0 | J12: =$D12*'DIA-INCH'!$C12 -> 0 | K12: =$E12*$J12 -> 0 | L12: =H12+J12 -> 0 | M12: =I12+K12 -> 0
A13: WEDING POINT | B13: 80A | C13: POINT | D13: 0 | E13: 475000 | F13: =L13 -> 0 | G13: =M13 -> 0 | J13: =$D13*'DIA-INCH'!$C13 -> 0 | K13: =$E13*$J13 -> 0 | L13: =H13+J13 -> 0 | M13: =I13+K13 -> 0
A14: WEDING POINT | B14: 100A | C14: POINT | D14: 0 | E14: 475000 | F14: =L14 -> 16 | G14: =M14 -> 7600000 | H14: 16 | I14: 7600000 | J14: =$D14*'DIA-INCH'!$C14 -> 0 | K14: =$E14*$J14 -> 0 | L14: =H14+J14 -> 16 | M14: =I14+K14 -> 7600000
A15: WEDING POINT | B15: 110A | C15: POINT | D15: 0 | E15: 475000 | F15: =L15 -> 0 | G15: =M15 -> 0 | J15: =$D15*'DIA-INCH'!$C15 -> 0 | K15: =$E15*$J15 -> 0 | L15: =H15+J15 -> 0 | M15: =I15+K15 -> 0
A16: WEDING POINT | B16: 125A | C16: POINT | D16: 0 | E16: 475000 | F16: =L16 -> 0 | G16: =M16 -> 0 | J16: =$D16*'DIA-INCH'!$C16 -> 0 | K16: =$E16*$J16 -> 0 | L16: =H16+J16 -> 0 | M16: =I16+K16 -> 0
A17: WEDING POINT | B17: 150A | C17: POINT | D17: 0 | E17: 475000 | F17: =L17 -> 0 | G17: =M17 -> 0 | J17: =$D17*'DIA-INCH'!$C17 -> 0 | K17: =$E17*$J17 -> 0 | L17: =H17+J17 -> 0 | M17: =I17+K17 -> 0
A18: WEDING POINT | B18: 175A | C18: POINT | D18: 0 | E18: 475000 | F18: =L18 -> 0 | G18: =M18 -> 0 | J18: =$D18*'DIA-INCH'!$C18 -> 0 | K18: =$E18*$J18 -> 0 | L18: =H18+J18 -> 0 | M18: =I18+K18 -> 0
A19: WEDING POINT | B19: 200A | C19: POINT | D19: 6 | E19: 475000 | F19: =L19 -> 48 | G19: =M19 -> 22800000 | J19: =$D19*'DIA-INCH'!$C19 -> 48 | K19: =$E19*$J19 -> 22800000 | L19: =H19+J19 -> 48 | M19: =I19+K19 -> 22800000
A20: WEDING POINT | B20: 225A | C20: POINT | D20: 0 | E20: 475000 | F20: =L20 -> 0 | G20: =M20 -> 0 | J20: =$D20*'DIA-INCH'!$C20 -> 0 | K20: =$E20*$J20 -> 0 | L20: =H20+J20 -> 0 | M20: =I20+K20 -> 0
A21: WEDING POINT | B21: 250A | C21: POINT | D21: 0 | E21: 475000 | F21: =L21 -> 0 | G21: =M21 -> 0 | J21: =$D21*'DIA-INCH'!$C21 -> 0 | K21: =$E21*$J21 -> 0 | L21: =H21+J21 -> 0 | M21: =I21+K21 -> 0
A22: WEDING POINT | B22: 300A | C22: POINT | D22: 0 | E22: 475000 | F22: =L22 -> 0 | G22: =M22 -> 0 | J22: =$D22*'DIA-INCH'!$C22 -> 0 | K22: =$E22*$J22 -> 0 | L22: =H22+J22 -> 0 | M22: =I22+K22 -> 0
A23: WEDING POINT | B23: 350A | C23: POINT | D23: 0 | E23: 475000 | F23: =L23 -> 0 | G23: =M23 -> 0 | J23: =$D23*'DIA-INCH'!$C23 -> 0 | K23: =$E23*$J23 -> 0 | L23: =H23+J23 -> 0 | M23: =I23+K23 -> 0
A24: WEDING POINT | B24: 400A | C24: POINT | D24: 0 | E24: 475000 | F24: =L24 -> 0 | G24: =M24 -> 0 | J24: =$D24*'DIA-INCH'!$C24 -> 0 | K24: =$E24*$J24 -> 0 | L24: =H24+J24 -> 0 | M24: =I24+K24 -> 0
A25: WEDING POINT | B25: 450A | C25: POINT | D25: 0 | E25: 475000 | F25: =L25 -> 0 | G25: =M25 -> 0 | J25: =$D25*'DIA-INCH'!$C25 -> 0 | K25: =$E25*$J25 -> 0 | L25: =H25+J25 -> 0 | M25: =I25+K25 -> 0
A26: WEDING POINT | B26: 500A | C26: POINT | D26: 0 | E26: 475000 | F26: =L26 -> 0 | G26: =M26 -> 0 | J26: =$D26*'DIA-INCH'!$C26 -> 0 | K26: =$E26*$J26 -> 0 | L26: =H26+J26 -> 0 | M26: =I26+K26 -> 0
A27: WEDING POINT | B27: 550A | C27: POINT | D27: 0 | E27: 475000 | F27: =L27 -> 0 | G27: =M27 -> 0 | J27: =$D27*'DIA-INCH'!$C27 -> 0 | K27: =$E27*$J27 -> 0 | L27: =H27+J27 -> 0 | M27: =I27+K27 -> 0
A28: VALVE 설치비 | B28: 8A | C28: EA | D28: 0 | E28: =$E$31*'DIA-INCH'!$C5 -> 12500 | F28: =L28 -> 0 | G28: =M28 -> 0 | J28: =D28 -> 0 | K28: =$J28*$E28 -> 0 | L28: =H28+J28 -> 0 | M28: =I28+K28 -> 0
A29: VALVE 설치비 | B29: 15A | C29: EA | D29: 0 | E29: =$E$31*'DIA-INCH'!$C6 -> 25000 | F29: =L29 -> 0 | G29: =M29 -> 0 | J29: =D29 -> 0 | K29: =$J29*$E29 -> 0 | L29: =H29+J29 -> 0 | M29: =I29+K29 -> 0
A30: VALVE 설치비 | B30: 20A | C30: EA | D30: 0 | E30: =$E$31*'DIA-INCH'!$C7 -> 37500 | F30: =L30 -> 0 | G30: =M30 -> 0 | J30: =D30 -> 0 | K30: =$J30*$E30 -> 0 | L30: =H30+J30 -> 0 | M30: =I30+K30 -> 0
A31: VALVE 설치비 | B31: 25A | C31: EA | D31: 2 | E31: 50000 | F31: =L31 -> 2 | G31: =M31 -> 100000 | J31: =D31 -> 2 | K31: =$J31*$E31 -> 100000 | L31: =H31+J31 -> 2 | M31: =I31+K31 -> 100000
A32: VALVE 설치비 | B32: 32A | C32: EA | D32: 0 | E32: =$E$31*'DIA-INCH'!$C9 -> 62500 | F32: =L32 -> 0 | G32: =M32 -> 0 | J32: =D32 -> 0 | K32: =$J32*$E32 -> 0 | L32: =H32+J32 -> 0 | M32: =I32+K32 -> 0
A33: VALVE 설치비 | B33: 40A | C33: EA | D33: 0 | E33: =$E$31*'DIA-INCH'!$C10 -> 75000 | F33: =L33 -> 0 | G33: =M33 -> 0 | J33: =D33 -> 0 | K33: =$J33*$E33 -> 0 | L33: =H33+J33 -> 0 | M33: =I33+K33 -> 0
A34: VALVE 설치비 | B34: 50A | C34: EA | D34: 4 | E34: =$E$31*'DIA-INCH'!$C11 -> 100000 | F34: =L34 -> 4 | G34: =M34 -> 400000 | J34: =D34 -> 4 | K34: =$J34*$E34 -> 400000 | L34: =H34+J34 -> 4 | M34: =I34+K34 -> 400000
A35: VALVE 설치비 | B35: 65A | C35: EA | D35: 0 | E35: =$E$31*'DIA-INCH'!$C12 -> 125000 | F35: =L35 -> 0 | G35: =M35 -> 0 | J35: =D35 -> 0 | K35: =$J35*$E35 -> 0 | L35: =H35+J35 -> 0 | M35: =I35+K35 -> 0
A36: VALVE 설치비 | B36: 80A | C36: EA | D36: 0 | E36: =$E$31*'DIA-INCH'!$C13 -> 150000 | F36: =L36 -> 0 | G36: =M36 -> 0 | J36: =D36 -> 0 | K36: =$J36*$E36 -> 0 | L36: =H36+J36 -> 0 | M36: =I36+K36 -> 0
A37: VALVE 설치비 | B37: 100A | C37: EA | D37: 0 | E37: =$E$31*'DIA-INCH'!$C14 -> 200000 | F37: =L37 -> 0 | G37: =M37 -> 0 | J37: =D37 -> 0 | K37: =$J37*$E37 -> 0 | L37: =H37+J37 -> 0 | M37: =I37+K37 -> 0
A38: VALVE 설치비 | B38: 110A | C38: EA | D38: 0 | E38: =$E$31*'DIA-INCH'!$C15 -> 200000 | F38: =L38 -> 0 | G38: =M38 -> 0 | J38: =D38 -> 0 | K38: =$J38*$E38 -> 0 | L38: =H38+J38 -> 0 | M38: =I38+K38 -> 0
A39: VALVE 설치비 | B39: 125A | C39: EA | D39: 0 | E39: =$E$31*'DIA-INCH'!$C16 -> 250000 | F39: =L39 -> 0 | G39: =M39 -> 0 | J39: =D39 -> 0 | K39: =$J39*$E39 -> 0 | L39: =H39+J39 -> 0 | M39: =I39+K39 -> 0
A40: VALVE 설치비 | B40: 150A | C40: EA | D40: 0 | E40: =$E$31*'DIA-INCH'!$C17 -> 300000 | F40: =L40 -> 0 | G40: =M40 -> 0 | J40: =D40 -> 0 | K40: =$J40*$E40 -> 0 | L40: =H40+J40 -> 0 | M40: =I40+K40 -> 0
...

Sheet 집계장
A1: ='용역청구서 표지'!$B$7 -> P4 Ph4 GAS 1공구 마감공사
L2: ='용역청구서 표지'!$C$15 -> 대성이엔지
A3: 구분 | B3: 내역 | C3: 단위 | D3: 수량 | E3: 단가 | F3: 합계 | G3: 전회기성 | H3: 금회기성 | I3: 누계기성 | J3: 비 고
A4: 1. 물량 | B4: WELDING POINT | C4: D/I | D4: =SUM('물량 내역서'!$J$5:$J$27) -> 50 | E4: =F4/D4 -> 475000 | F4: =SUM('[1]물량 내역서'!$K$5:$K$27) -> 23750000 | G4: 128250000 | H4: =F4 -> 23750000 | I4: =G4+H4 -> 152000000
B5: VALVE 설치비 | C5: EA | D5: =SUM('물량 내역서'!$J$28:$J$50) -> 6 | E5: =F5/D5 -> 83333.333 | F5: =SUM('[1]물량 내역서'!$K$28:$K$50) -> 500000 | G5: 0 | H5: =F5 -> 500000 | I5: =G5+H5 -> 500000
B6: 인원 실투입 | C6: M/D | F6: ='[1]근로내역 (01월)'!AP50 -> 0 | G6: 0 | H6: =F6 -> 0 | I6: =G6+H6 -> 0
A7: 2. 기타비용 | B7: 기타지급 운영비 | C7: 式 | F7: 101785535 | G7: 0 | H7: =F7 -> 101785535 | I7: =G7+H7 -> 101785535 | J7: (다음 기성에서 차감)
A8: 소 계 | B8: 물량 | F8: =SUM(F4:F7) -> 126035535 | G8: 128250000 | H8: =SUM(H4:H7) -> 126035535 | I8: =SUM(I4:I7) -> 254285535
A9: 3. 노무비 | B9: 직접노무비 | C9: 式 | D9: ='근로내역 (01월)'!AN51 -> 503.125 | E9: =F9/D9 -> 202792.55 | F9: ='[1]근로내역 (01월)'!AP51 -> 102030000 | G9: 95066250 | H9: =F9 -> 102030000 | I9: =G9+H9 -> 197096250
A10: 4. 숙소 및 식대 | B10: 임대료+관리비 | C10: 式 | D10: =SUM(숙소임차료!H4:H6)+SUM(숙소관리비!H4:H8) -> 40 | E10: =F10/D10 -> 164962.25 | F10: =[1]숙소임차료!I3+[1]숙소관리비!I3 -> 6598490 | G10: 6326340 | H10: =F10 -> 6598490 | I10: =G10+H10 -> 12924830
B11: 식대 | C11: 式 | D11: =SUM(식대비용!G4:G4) -> 24 | E11: =F11/D11 -> 305318.17 | F11: =[1]식대비용!I3 -> 7327636 | G11: 6936819 | H11: =F11 -> 7327636 | I11: =G11+H11 -> 14264455
A12: 5. 기타 공제 내역 | C12: 式 | E12: 0 | F12: =D12*E12 -> 0 | G12: 0 | H12: =F12 -> 0 | I12: =G12+H12 -> 0
A13: 소 계 | B13: 공제 | F13: =SUM(F9:F12) -> 115956126 | G13: 108329409 | H13: =F13 -> 115956126 | I13: =G13+H13 -> 224285535
A14: 합 계 | B14: 기성 (물량-공제) | F14: =F8-F13 -> 10079409 | G14: 19920591 | H14: =F14 -> 10079409 | I14: =G14+H14 -> 30000000
A15: 6. 유보금 | B15: 기성금*XX% | C15: 式 | G15: 0 | H15: =F15 -> 0
A16: 7. 유보금 차액 | B16: 전회 누계유보금+적자 기성액 | C16: 式 | F16: 19920591 | G16: 0 | H16: =F16 -> 19920591
A17: 8. NEGO | B17: NEGO | C17: 式 | G17: 0 | H17: =F17 -> 0
A18: 총 계 | B18: 최종기성 | F18: =F14+F16 -> 30000000 | H18: =H14+H16 -> 30000000 | I18: =I14+I16 -> 30000000
A19: 선급금 | B19: 선수공제 | C19: 式 | G19: 0 | H19: =F19 -> 0 | I19: =G19+H19 -> 0 | K19: 지급 선급금 | L19: 선급금 차액
B20: 단수정리 | C20: 式 | F20: =ROUNDDOWN(F19,-5) -> 0 | G20: 0 | H20: =F20 -> 0 | I20: =G20+H20 -> 0 | J20: 만 단위 이하 절사 | K20: 0 | L20: =K20-I20 -> 0
A21: 공제 후 실 지급액 | F21: =F18-F20 -> 30000000 | H21: =H18 -> 30000000 | I21: =I18 -> 30000000
A22: 세금계산서 기준 | F22: =ROUNDDOWN(F21,-5) -> 30000000 | H22: =ROUNDDOWN(H21,-5) -> 30000000 | I22: =ROUNDDOWN(I21,-5) -> 30000000 | J22: 만 단위 이하 절사
A23: TERMS AND CONDITIONS | D23: NOTE
A24: 1. 납 기 : KCEnC 지정 납기로 별도 협의 하에 결정하는 것으로 함.
A25: 2. 지불조건 : KCEnC 지불 조건에 따름.
A26: 3. 유효기간 : 기성 제출일로 부터 30일 이내

Sheet 근로내역 (01월)
A1: 2026년 ( 01 )월 일용 노무비명세서 | AH1: 현장명 | AM1: ='용역청구서 표지'!$B$7 -> P4 Ph4 GAS 1공구 마감공사
AH2: 현장소장 | AM2: 장 규 철
AH3: 잡코드 | AM3: ='용역청구서 표지'!$C$8 -> S25-004
A5: 번호 | B5: 성명 | C5: 주민등록번호 | D5: 직종 | E5: 연락처(H.P) | F5: 은행명 | G5: 예금주 | H5: 계좌번호 | I5: 1 | J5: 2 | K5: 3 | L5: 4 | M5: 5 | N5: 6 | O5: 7 | P5: 8 | Q5: 9 | R5: 10 | S5: 11 | T5: 12 | U5: 13 | V5: 14 | W5: 15 | X5: 16 | Y5: 17 | Z5: 18 | AA5: 19 | AB5: 20 | AC5: 21 | AD5: 22 | AE5: 23 | AF5: 24 | AG5: 25 | AH5: 26 | AI5: 27 | AJ5: 28 | AK5: 29 | AL5: 30 | AM5: 31 | AN5: 공수 | AO5: 단가 | AP5: 총액
A6: 1 | B6: 김규현 | C6: 060806-3042416 | D6: 보통인부 | E6: 010-7720-8412 | F6: 국민 | G6: 김규현 | H6: 2673052-04-343681 | T6: 0.625 | U6: 0.375 | V6: 0.625 | W6: 1 | X6: 1 | AA6: 0.875 | AB6: 0.375 | AC6: 1 | AD6: 1 | AE6: 1 | AH6: 1.5 | AI6: 1 | AJ6: 1 | AK6: 1 | AN6: =SUM(I6:AM6) -> 12.375 | AO6: 140000 | AP6: =AN6*AO6 -> 1732500
A7: 2 | B7: 김요한 | C7: 810223-1912027 | D7: 보통인부 | E7: 010-6357-6089 | F7: 카카오 | G7: 김요한 | H7: 3333-02-2557107 | M7: 0.625 | N7: 0.375 | AN7: =SUM(I7:AM7) -> 1 | AO7: 140000 | AP7: =AN7*AO7 -> 140000
A8: 3 | B8: 김종완 | C8: 740404-1471013 | D8: 배관공 | E8: 010-9983-3546 | F8: 우리 | G8: 김종완 | H8: 1006-001-448823 | J8: 1 | M8: 1 | N8: 1 | O8: 1 | P8: 1 | Q8: 1 | T8: 1 | U8: 1 | V8: 1 | W8: 1 | X8: 1 | AA8: 1 | AB8: 1 | AC8: 1 | AD8: 1 | AE8: 1 | AH8: 1.5 | AI8: 1 | AJ8: 1 | AK8: 1 | AL8: 1 | AN8: =SUM(I8:AM8) -> 21.5 | AO8: 210000 | AP8: =AN8*AO8 -> 4515000
A9: 4 | B9: 김창우 | C9: 751012-1143412 | D9: 보통인부 | E9: 010-4761-8752 | F9: 국민 | G9: 김창우 | H9: 201301-04-324384 | M9: 1 | N9: 1 | O9: 1 | P9: 1 | Q9: 1 | T9: 1 | U9: 1 | V9: 1 | W9: 1 | X9: 1 | AA9: 1 | AB9: 1 | AC9: 1 | AD9: 1 | AH9: 1.5 | AI9: 1 | AJ9: 1 | AK9: 1 | AL9: 1 | AN9: =SUM(I9:AM9) -> 19.5 | AO9: 170000 | AP9: =AN9*AO9 -> 3315000
A10: 5 | B10: 김철 | C10: 761102-1565911 | D10: 공사보조 | E10: 010-5534-8412 | F10: 신한 | G10: 김철 | H10: 110-470-878920 | J10: 1 | N10: 1 | O10: 1 | P10: 1 | Q10: 1 | T10: 1 | U10: 1 | V10: 1 | W10: 1 | X10: 1 | AA10: 0.875 | AB10: 1 | AC10: 1 | AD10: 1 | AE10: 1 | AH10: 1.5 | AI10: 1 | AJ10: 1 | AK10: 1 | AL10: 0.5 | AN10: =SUM(I10:AM10) -> 19.875 | AO10: 250000 | AP10: =AN10*AO10 -> 4968750
A11: 6 | B11: 남병철 | C11: 750430-1631827 | D11: 보통인부 | E11: 010-5566-6448 | F11: 국민 | G11: 남병철 | H11: 619602-01-375567 | M11: 0.625 | O11: 1 | P11: 1 | Q11: 0.25 | U11: 1 | V11: 0.875 | W11: 0.375 | X11: 0.875 | AN11: =SUM(I11:AM11) -> 6 | AO11: 160000 | AP11: =AN11*AO11 -> 960000
A12: 7 | B12: 류일화 | C12: 821006-2345313 | D12: 보통인부 | E12: 010-8753-3536 | F12: 국민 | G12: 류일화 | H12: 203901-04-045708 | J12: 1 | M12: 1 | O12: 1 | P12: 1 | Q12: 1 | T12: 1 | U12: 1 | V12: 1 | W12: 1 | X12: 1 | AA12: 1 | AB12: 1 | AC12: 1 | AD12: 1 | AE12: 1 | AH12: 1.5 | AI12: 1 | AJ12: 1 | AK12: 1 | AL12: 1 | AN12: =SUM(I12:AM12) -> 20.5 | AO12: 140000 | AP12: =AN12*AO12 -> 2870000
A13: 8 | B13: 박기태 | C13: 841117-1836338 | D13: 배관공 | E13: 010-9800-6028 | F13: 농협 | G13: 박기태 | H13: 883-12-137056 | J13: 1 | M13: 1 | N13: 1 | P13: 1 | Q13: 1 | T13: 1 | U13: 1 | V13: 1 | W13: 1 | X13: 1 | AA13: 1 | AB13: 1 | AC13: 1 | AD13: 1 | AE13: 1 | AH13: 1.5 | AI13: 1 | AJ13: 1 | AK13: 1 | AL13: 1 | AN13: =SUM(I13:AM13) -> 20.5 | AO13: 210000 | AP13: =AN13*AO13 -> 4305000
A14: 9 | B14: 서승희 | C14: 941121-2216111 | D14: 보통인부 | E14: 010-8540-8270 | F14: 국민 | G14: 서승희 | H14: 865302-00-042896 | J14: 1 | N14: 1 | O14: 1 | P14: 1 | Q14: 1 | T14: 1 | U14: 1 | V14: 1 | W14: 1 | X14: 1 | AA14: 1 | AB14: 1 | AC14: 1 | AD14: 1 | AE14: 1 | AH14: 1.5 | AI14: 1 | AJ14: 1 | AK14: 1 | AL14: 1 | AN14: =SUM(I14:AM14) -> 20.5 | AO14: 180000 | AP14: =AN14*AO14 -> 3690000
A15: 10 | B15: 신유호 | C15: 841207-1636517 | D15: 보통인부 | E15: 010-6716-7018 | F15: 카카오 | G15: 신유호 | H15: 3333-04-4294653 | T15: 0.625 | V15: 1 | W15: 1 | X15: 1 | AA15: 1 | AB15: 1 | AC15: 1 | AD15: 1 | AE15: 1 | AH15: 1.5 | AI15: 1 | AJ15: 1 | AK15: 1 | AL15: 1 | AN15: =SUM(I15:AM15) -> 14.125 | AO15: 160000 | AP15: =AN15*AO15 -> 2260000
A16: 11 | B16: 안병문 | C16: 751106-1239319 | D16: 용접공 | E16: 010-9291-2123 | F16: 농협 | G16: 안병문 | H16: 302-1102-5800-61 | J16: 1 | M16: 1 | N16: 1 | O16: 1 | P16: 1 | Q16: 1 | T16: 1 | U16: 1 | V16: 1 | W16: 1 | X16: 1 | AA16: 1 | AB16: 1 | AC16: 1 | AD16: 1 | AE16: 1 | AH16: 1.5 | AI16: 1 | AJ16: 1 | AK16: 1 | AL16: 1 | AN16: =SUM(I16:AM16) -> 21.5 | AO16: 240000 | AP16: =AN16*AO16 -> 5160000
A17: 12 | B17: 엄진용 | C17: 950826-1026312 | D17: 보통인부 | E17: 010-9936-8504 | F17: 국민 | G17: 엄진용 | H17: 99936850449 | J17: 1 | M17: 1 | N17: 1 | O17: 1 | P17: 1 | Q17: 1 | T17: 1 | U17: 0.125 | V17: 1 | W17: 1 | X17: 1 | AA17: 1 | AB17: 1 | AC17: 1 | AD17: 1 | AE17: 1 | AI17: 1 | AJ17: 1 | AK17: 1 | AL17: 1 | AN17: =SUM(I17:AM17) -> 19.125 | AO17: 210000 | AP17: =AN17*AO17 -> 4016250
A18: 13 | B18: 오정석 | C18: 840327-1836316 | D18: 배관공 | E18: 010-3646-6264 | F18: 우리 | G18: 오정석 | H18: 1002-339-959255 | J18: 1 | M18: 1 | N18: 1 | O18: 1 | P18: 1 | Q18: 1 | T18: 1 | U18: 1 | V18: 1 | W18: 1 | X18: 1 | AA18: 1 | AB18: 1 | AC18: 1 | AD18: 1 | AE18: 1 | AH18: 1.5 | AI18: 1 | AJ18: 1 | AK18: 1 | AL18: 1 | AN18: =SUM(I18:AM18) -> 21.5 | AO18: 240000 | AP18: =AN18*AO18 -> 5160000
A19: 14 | B19: 유명욱 | C19: 811120-1921215 | D19: 보통인부 | E19: 010-8075-2745 | F19: 농협 | G19: 유명욱 | H19: 356-0676-7874-53 | M19: 0.625 | O19: 1 | P19: 1 | Q19: 1 | T19: 1 | AN19: =SUM(I19:AM19) -> 4.625 | AO19: 150000 | AP19: =AN19*AO19 -> 693750
A20: 15 | B20: 윤지환 | C20: 770812-1100111 | D20: 공사보조 | E20: 010-6455-8718 | F20: 새마을 | G20: 윤지환 | H20: 9002-1579-4799-1 | J20: 1 | M20: 1 | N20: 1 | P20: 1 | Q20: 1 | T20: 1 | U20: 1 | V20: 1 | W20: 1 | X20: 1 | AA20: 1 | AB20: 1 | AC20: 1 | AD20: 1 | AE20: 1 | AH20: 1.5 | AI20: 1 | AJ20: 1 | AK20: 1 | AL20: 1 | AN20: =SUM(I20:AM20) -> 20.5 | AO20: 240000 | AP20: =AN20*AO20 -> 4920000
A21: 16 | B21: 은소천 | C21: 830224-1026011 | D21: 배관공 | E21: 010-5248-6056 | F21: 우리 | G21: 은소천 | H21: 1002-253-086774 | J21: 1 | M21: 1 | O21: 1 | P21: 1 | Q21: 1 | T21: 1 | U21: 1 | V21: 1 | W21: 1 | X21: 1 | AA21: 1 | AB21: 1 | AC21: 1 | AD21: 1 | AE21: 1 | AH21: 1.5 | AI21: 1 | AJ21: 1 | AK21: 1 | AL21: 1 | AN21: =SUM(I21:AM21) -> 20.5 | AO21: 230000 | AP21: =AN21*AO21 -> 4715000
A22: 17 | B22: 이동건 | C22: 740108-1328319 | D22: 용접공 | E22: 010-8953-4315 | F22: 농협 | G22: 이동건 | H22: 302-1062-4901-11 | T22: 0.875 | V22: 1 | X22: 1 | AA22: 1 | AB22: 1 | AC22: 1 | AD22: 1 | AE22: 1 | AH22: 1.5 | AI22: 1 | AJ22: 1 | AK22: 1 | AL22: 1 | AN22: =SUM(I22:AM22) -> 13.375 | AO22: 240000 | AP22: =AN22*AO22 -> 3210000
A23: 18 | B23: 이인규 | C23: 820704-1083115 | D23: 용접공 | E23: 010-5821-2948 | F23: 농협 | G23: 이인규 | H23: 302-1617-3382-01 | J23: 1 | M23: 1 | N23: 1 | O23: 1 | P23: 1 | Q23: 1 | T23: 1 | U23: 1 | V23: 1 | W23: 1 | X23: 1 | AA23: 1 | AB23: 1 | AC23: 1 | AD23: 1 | AE23: 1 | AH23: 1.5 | AI23: 1 | AJ23: 1 | AK23: 1 | AL23: 1 | AN23: =SUM(I23:AM23) -> 21.5 | AO23: 240000 | AP23: =AN23*AO23 -> 5160000
A24: 19 | B24: 이진호 | C24: 930305-1933311 | D24: 관리보조 | E24: 010-4794-8530 | F24: 우리 | G24: 이진호 | H24: 1002-658-107464 | V24: 1 | W24: 0.75 | X24: 1 | AA24: 0.875 | AB24: 1 | AC24: 1 | AD24: 1 | AH24: 1.5 | AI24: 1 | AJ24: 1 | AK24: 1 | AL24: 0.875 | AN24: =SUM(I24:AM24) -> 12 | AO24: 210000 | AP24: =AN24*AO24 -> 2520000
A25: 20 | B25: 장세형 | C25: 780528-1233527 | D25: 안전보조 | E25: 010-3728-4671 | F25: 신한 | G25: 장세형 | H25: 110-471-057532 | J25: 1 | M25: 1 | N25: 1 | O25: 1 | P25: 1 | Q25: 1 | T25: 1 | U25: 1 | V25: 1 | W25: 1 | X25: 1 | AA25: 1 | AB25: 1 | AC25: 1 | AD25: 1 | AE25: 1 | AH25: 1.5 | AI25: 1 | AJ25: 1 | AK25: 1 | AL25: 1 | AN25: =SUM(I25:AM25) -> 21.5 | AO25: 240000 | AP25: =AN25*AO25 -> 5160000
A26: 21 | B26: 정은선 | C26: 670809-2233120 | D26: 보통인부 | E26: 010-2297-5059 | F26: 기업 | G26: 정은선 | H26: 289-074002-02-015 | J26: 1 | M26: 1 | N26: 1 | O26: 1 | P26: 1 | Q26: 1 | T26: 1 | U26: 1 | V26: 1 | W26: 1 | X26: 1 | AA26: 1 | AB26: 1 | AC26: 1 | AD26: 1 | AE26: 1 | AH26: 1.5 | AI26: 1 | AJ26: 1 | AK26: 1 | AL26: 1 | AN26: =SUM(I26:AM26) -> 21.5 | AO26: 190000 | AP26: =AN26*AO26 -> 4085000
A27: 22 | B27: 진성훈 | C27: 730314-1023930 | D27: 도비공 | E27: 010-5472-6177 | F27: 우리 | G27: 진성훈 | H27: 063-083414-02-501 | J27: 1 | M27: 1 | N27: 1 | O27: 1 | P27: 1 | Q27: 1 | T27: 1 | U27: 1 | V27: 1 | W27: 1 | X27: 1 | AA27: 1 | AB27: 1 | AC27: 1 | AD27: 1 | AE27: 1 | AH27: 1.5 | AI27: 1 | AJ27: 1 | AK27: 1 | AL27: 1 | AN27: =SUM(I27:AM27) -> 21.5 | AO27: 210000 | AP27: =AN27*AO27 -> 4515000
A28: 23 | B28: 최기철 | C28: 780828-1490316 | D28: 보통인부 | E28: 010-9858-6058 | F28: 하나 | G28: 최기철 | H28: 711-910268-82507 | T28: 0.625 | U28: 0.375 | V28: 0.625 | W28: 1 | X28: 0.875 | AN28: =SUM(I28:AM28) -> 3.5 | AO28: 200000 | AP28: =AN28*AO28 -> 700000
A29: 24 | B29: 최세재 | C29: 781010-1906517 | D29: 보통인부 | E29: 010-8548-3215 | F29: 농협 | G29: 최세재 | H29: 356-0637-9273-33 | M29: 1 | N29: 1 | O29: 1 | P29: 1 | Q29: 1 | T29: 1 | U29: 1 | V29: 1 | W29: 1 | X29: 1 | AA29: 1 | AB29: 1 | AC29: 1 | AD29: 1 | AE29: 1 | AH29: 1.5 | AI29: 1 | AJ29: 1 | AK29: 1 | AL29: 1 | AN29: =SUM(I29:AM29) -> 20.5 | AO29: 230000 | AP29: =AN29*AO29 -> 4715000
A30: 25 | B30: 최현우 | C30: 780110-1901921 | D30: 보통인부 | E30: 010-2123-6107 | F30: 국민 | G30: 최현우 | H30: 018302-04-192870 | J30: 1 | M30: 1 | N30: 1 | O30: 1 | P30: 1 | Q30: 1 | T30: 1 | U30: 1 | V30: 1 | W30: 1 | X30: 1 | AA30: 1 | AB30: 1 | AC30: 1 | AD30: 1 | AE30: 1 | AH30: 1.5 | AI30: 1 | AJ30: 1 | AK30: 1 | AL30: 1 | AN30: =SUM(I30:AM30) -> 21.5 | AO30: 220000 | AP30: =AN30*AO30 -> 4730000
A31: 26 | B31: 추인호 | C31: 961227-1874414 | D31: 보통인부 | E31: 010-9535-8943 | F31: 농협 | G31: 추인호 | H31: 356-0753-9167-73 | M31: 0.625 | O31: 1 | P31: 1 | T31: 1 | U31: 1 | W31: 1 | X31: 1 | AA31: 1 | AB31: 1 | AC31: 1 | AE31: 1 | AH31: 1.5 | AI31: 1 | AK31: 0.5 | AN31: =SUM(I31:AM31) -> 13.625 | AO31: 170000 | AP31: =AN31*AO31 -> 2316250
A32: 27 | B32: 한상직 | C32: 690807-1226411 | D32: 보통인부 | E32: 010-6579-0208 | F32: 농협 | G32: 한상직 | H32: 352-2341-4304-03 | T32: 0.625 | V32: 1 | W32: 1 | X32: 1 | AA32: 1 | AB32: 1 | AC32: 1 | AD32: 1 | AE32: 1 | AH32: 1.5 | AI32: 1 | AJ32: 1 | AK32: 1 | AL32: 1 | AN32: =SUM(I32:AM32) -> 14.125 | AO32: 160000 | AP32: =AN32*AO32 -> 2260000
A33: 28 | B33: 한은철 | C33: 870222-1590411 | D33: 보통인부 | E33: 010-5760-6445 | F33: 농협 | G33: 한은철 | H33: 351-0226-9203-83 | M33: 0.625 | O33: 1 | P33: 1 | Q33: 1 | T33: 1 | AN33: =SUM(I33:AM33) -> 4.625 | AO33: 150000 | AP33: =AN33*AO33 -> 693750
A34: 29 | B34: 함지영 | C34: 841031-2481917 | D34: 보통인부 | E34: 010-6304-9316 | F34: 카카오 | G34: 함지영 | H34: 3333-24-6872510 | M34: 0.625 | O34: 1 | P34: 1 | Q34: 1 | T34: 1 | U34: 1 | V34: 1 | W34: 1 | X34: 1 | AA34: 1 | AB34: 1 | AC34: 1 | AD34: 1 | AE34: 1 | AH34: 1.5 | AI34: 1 | AJ34: 1 | AK34: 1 | AL34: 1 | AN34: =SUM(I34:AM34) -> 19.125 | AO34: 150000 | AP34: =AN34*AO34 -> 2868750
A35: 30 | B35: 허서준 | C35: 811117-1481515 | D35: 보통인부 | E35: 010-4800-5002 | F35: 우리 | G35: 허서준 | H35: 1002-157-661919 | M35: 0.625 | O35: 1 | P35: 0.125 | Q35: 1 | T35: 1 | U35: 1 | V35: 1 | W35: 1 | X35: 1 | AA35: 1 | AB35: 1 | AC35: 1 | AD35: 1 | AE35: 1 | AH35: 1.5 | AI35: 1 | AJ35: 1 | AK35: 1 | AL35: 1 | AN35: =SUM(I35:AM35) -> 18.25 | AO35: 170000 | AP35: =AN35*AO35 -> 3102500
A36: 31 | B36: 안준우 | C36: 800707-1821518 | D36: 배관공 | E36: 010-7446-4004 | F36: 기업 | G36: 안준우 | H36: 680-082527-01-016 | AA36: 0.875 | AC36: 1 | AD36: 1 | AE36: 1 | AH36: 1.5 | AI36: 1 | AJ36: 0.5 | AK36: 1 | AL36: 1 | AN36: =SUM(I36:AM36) -> 8.875 | AO36: 220000 | AP36: =AN36*AO36 -> 1952500
A37: 32 | B37: 양다현 | C37: 730610-2011424 | D37: 보통인부 | E37: 010-3330-4550 | F37: 우체국 | G37: 양다현 | H37: 110-0114-34147 | AA37: 0.625 | AB37: 0.375 | AN37: =SUM(I37:AM37) -> 1 | AO37: 140000 | AP37: =AN37*AO37 -> 140000
A38: 33 | B38: 마동우 | C38: 780915-1671011 | D38: 보통인부 | E38: 010-8680-8890 | F38: 신한 | G38: 마동우 | H38: 110-206-542553 | AA38: 0.625 | AC38: 1 | AE38: 1 | AH38: 0.375 | AN38: =SUM(I38:AM38) -> 3 | AO38: 160000 | AP38: =AN38*AO38 -> 480000
A39: 합 계 | I39: =SUM(I6:I38) -> 0 | J39: =SUM(J6:J38) -> 15 | K39: =SUM(K6:K38) -> 0 | L39: =SUM(L6:L38) -> 0 | M39: =SUM(M6:M38) -> 19.375 | N39: =SUM(N6:N38) -> 15.375 | O39: =SUM(O6:O38) -> 21 | P39: =SUM(P6:P38) -> 22.125 | ... AN39: =SUM(AN6:AN38) -> 503.125 | AO39: =AP39/AN39 -> 202792.55 | AP39: =SUM(AP6:AP38) -> 102030000
A40: 1 | AN40: =SUM(I40:AM40) -> 0 | AP40: =AN40*AO40 -> 0
A41: 2 | AN41: =SUM(I41:AM41) -> 0 | AP41: =AN41*AO41 -> 0
...

Sheet 숙소임차료
A1: 숙소 임차료
A2: No. | B2: 납부일 | C2: 구분 | D2: 품명 | E2: 주소 | F2: 호수 | G2: 수량 | H2: 사용인원 | I2: 임차료 | J2: 비 고
I3: =SUM(I4:I9) -> 5400000 | L3: 입력해야하는 항목 외 수정 금지
A4: 1 | B4: 46053 | C4: KC대납 임대료 | D4: 숙소임대료(01월분) | E4: 고덕 함박산1길 16, 202호 | F4: 202호 | G4: 1 | H4: 4 | I4: 800000 | J4: KC 대납 | L4: 납부일
A5: 2 | B5: 46053 | C5: KC대납 임대료 | D5: 숙소임대료(01월분) | E5: 고덕 여염12길 103, 302호 | F5: 302호 | G5: 1 | H5: 6 | I5: 950000 | J5: KC 대납 | L5: 구분
A6: 3 | B6: 46053 | C6: KC대납 임대료 | D6: 숙소임대료(01월분) | E6: 고덕 함박산4길 12, 301호 | F6: 301호 | G6: 1 | H6: 6 | I6: 900000 | J6: KC 대납 | L6: 품명
A7: 4 | B7: 46053 | C7: KC대납 임대료 | D7: 숙소임대료(01월분) | E7: 고덕 함박산9길 46, 301호 | F7: 301호 | G7: 1 | H7: 4 | I7: 850000 | J7: KC 대납 | L7: 주소
A8: 5 | B8: 46025 | C8: KC대납 임대료 | D8: 숙소임대료(01월분) | E8: 고덕 갈평10길 40, 202호 | F8: 202호 | G8: 1 | H8: 6 | I8: 950000 | J8: KC 대납 | L8: 호수
A9: 6 | B9: 46034 | C9: KC대납 임대료 | D9: 숙소임대료(01월분) | E9: 고덕 함박산7길 29, 201호 | F9: 201호 | G9: 1 | H9: 4 | I9: 950000 | J9: KC 대납 | L9: 수량
L10: 사용인원
L12: ■ 구분은 [KC대납 임대료 및 임대료] 이외 항목은 입력금지

Sheet 숙소관리비
A1: 숙소 관리비
A2: No. | B2: 납부일 | C2: 구분 | D2: 품명 | E2: 주소 | F2: 호수 | G2: 수량 | H2: 사용인원 | I2: 관리비 | J2: 비 고
I3: =SUM(I4:I21) -> 1198490
A4: 1 | B4: 46053 | C4: KC대납 관리비 | D4: 숙소수도세(01월분) | E4: 고덕 함박산1길 16, 202호 | F4: 202호 | G4: 1 | H4: 4 | I4: 35700 | J4: KC 대납
A5: 2 | B5: 46053 | C5: KC대납 관리비 | D5: 숙소가스료(01월분) | E5: 고덕 함박산1길 16, 202호 | F5: 202호 | G5: 1 | H5: 4 | I5: 178140 | J5: KC 대납
A6: 3 | B6: 46053 | C6: KC대납 관리비 | D6: 숙소전기료(01월분) | E6: 고덕 함박산1길 16, 202호 | F6: 202호 | G6: 1 | H6: 4 | I6: 47240 | J6: KC 대납
A7: 4 | B7: 46053 | C7: KC대납 관리비 | D7: 숙소수도세(01월분) | E7: 고덕 여염12길 103, 302호 | F7: 302호 | G7: 1 | H7: 6 | I7: 14990 | J7: KC 대납
A8: 5 | B8: 46053 | C8: KC대납 관리비 | D8: 숙소가스료(01월분) | E8: 고덕 여염12길 103, 302호 | F8: 302호 | G8: 1 | H8: 6 | I8: 230810 | J8: KC 대납
A9: 6 | B9: 46053 | C9: KC대납 관리비 | D9: 숙소전기료(01월분) | E9: 고덕 여염12길 103, 302호 | F9: 302호 | G9: 1 | H9: 6 | I9: 28720 | J9: KC 대납
A10: 7 | B10: 46053 | C10: KC대납 관리비 | D10: 숙소수도세(01월분) | E10: 고덕 함박산4길 12, 301호 | F10: 301호 | G10: 1 | H10: 6 | I10: 16710 | J10: KC 대납
A11: 8 | B11: 46053 | C11: KC대납 관리비 | D11: 숙소가스료(01월분) | E11: 고덕 함박산4길 12, 301호 | F11: 301호 | G11: 1 | H11: 6 | I11: 332820 | J11: KC 대납
A12: 9 | B12: 46053 | C12: KC대납 관리비 | D12: 숙소전기료(01월분) | E12: 고덕 함박산4길 12, 301호 | F12: 301호 | G12: 1 | H12: 6 | I12: 28280 | J12: KC 대납
A13: 10 | B13: 46053 | C13: KC대납 관리비 | D13: 숙소수도세(01월분) | E13: 고덕 함박산9길 46, 301호 | F13: 301호 | G13: 1 | H13: 4 | I13: 1200 | J13: KC 대납
A14: 11 | B14: 46053 | C14: KC대납 관리비 | D14: 숙소가스료(01월분) | E14: 고덕 함박산9길 46, 301호 | F14: 301호 | G14: 1 | H14: 4 | I14: 143460 | J14: KC 대납
A15: 12 | B15: 46053 | C15: KC대납 관리비 | D15: 숙소전기료(01월분) | E15: 고덕 함박산9길 46, 301호 | F15: 301호 | G15: 1 | H15: 4 | I15: 29460 | J15: KC 대납
A16: 13 | B16: 46053 | C16: KC대납 관리비 | D16: 숙소수도세(01월분) | E16: 고덕 갈평10길 40, 202호 | F16: 202호 | G16: 1 | H16: 6 | I16: 다음달 청구예정 | J16: KC 대납
A17: 14 | B17: 46053 | C17: KC대납 관리비 | D17: 숙소가스료(01월분) | E17: 고덕 갈평10길 40, 202호 | F17: 202호 | G17: 1 | H17: 6 | I17: 110960 | J17: KC 대납
A18: 15 | B18: 46053 | C18: KC대납 관리비 | D18: 숙소전기료(01월분) | E18: 고덕 갈평10길 40, 202호 | F18: 202호 | G18: 1 | H18: 6 | I18: 다음달 청구예정 | J18: KC 대납
A19: 16 | B19: 46053 | C19: KC대납 관리비 | D19: 숙소수도세(01월분) | E19: 고덕 함박산7길 29, 201호 | F19: 201호 | G19: 1 | H19: 4 | I19: 다음달 청구예정 | J19: KC 대납
A20: 17 | B20: 46053 | C20: KC대납 관리비 | D20: 숙소가스료(01월분) | E20: 고덕 함박산7길 29, 201호 | F20: 201호 | G20: 1 | H20: 4 | I20: 다음달 청구예정 | J20: KC 대납
A21: 18 | B21: 46053 | C21: KC대납 관리비 | D21: 숙소전기료(01월분) | E21: 고덕 함박산7길 29, 201호 | F21: 201호 | G21: 1 | H21: 4 | I21: 다음달 청구예정 | J21: KC 대납

Sheet 식대비용
A1: 식대 비용
A2: No. | B2: 납부일 | C2: 구분 | D2: 품명 | E2: 거래처명 | F2: 수량 | G2: 식수인원 | H2: 단가 | I2: 합 계 | J2: 비 고
I3: =SUM(I4:I5) -> 7327636 | L3: 입력해야하는 항목 외 수정 금지
A4: 1 | B4: 46053 | C4: KC대납 식대 | D4: 기술인및관리자 (현장 식당) | E4: 포세카 | F4: 900 | G4: 24 | H4: 6181.82 | I4: 5563636 | J4: KC 대납 | L4: 입력항목
A5: 2 | B5: 46053 | C5: KC대납 식대 | D5: 기술인및관리자 (현장 식당) | E5: 밥심 | F5: 252 | G5: 18 | H5: 7000 | I5: =F5*H5 -> 1764000 | J5: KC 대납 | L5: 납부일
L6: 구분
L7: 품명
L8: 거래처명
L9: 수량
L10: 식수인원
L11: 단가
L13: ■ 구분은 [KC대납 식대 및 식대] 이외 항목은 입력금지

Sheet 기타비용
A1: 기타 비용
A2: No. | B2: 구매일 | C2: 구분 | D2: 품명 | E2: 거래처명 | F2: 수량 | G2: 단가 | H2: 합계 | I2: 비고
H3: =SUM(H4:H35) -> 1011800 | K3: 입력해야하는 항목 외 수정 금지
A4: 1 | B4: 46028 | C4: 소모품비 | D4: 케이블타이 | E4: 미래공구 | F4: 3 | G4: 6100 | H4: =F4*G4 -> 18300 | I4: 거래명세서 첨부 | K4: 입력항목
A5: 2 | B5: 46028 | C5: 소모품비 | D5: 케이블타이 | E5: 미래공구 | F5: 2 | G5: 3400 | H5: =F5*G5 -> 6800 | I5: 거래명세서 첨부 | K5: 납부일
A6: 3 | B6: 46028 | C6: 소모품비 | D6: 케이블트레이도금보수제 | E6: 미래공구 | F6: 3 | G6: 5900 | H6: =F6*G6 -> 17700 | I6: 거래명세서 첨부 | K6: 구분
A7: 4 | B7: 46030 | C7: 소모품비 | D7: 다이아몬드줄 | E7: 미래공구 | F7: 13 | G7: 9200 | H7: =F7*G7 -> 119600 | I7: 거래명세서 첨부 | K7: 품명
A8: 5 | B8: 46030 | C8: 소모품비 | D8: 다이아몬드줄 | E8: 미래공구 | F8: 8 | G8: 9200 | H8: =F8*G8 -> 73600 | I8: 거래명세서 첨부 | K8: 거래처명
A9: 6 | B9: 46034 | C9: 소모품비 | D9: 먹통 | E9: 미래공구 | F9: 1 | G9: 10300 | H9: =F9*G9 -> 10300 | I9: 거래명세서 첨부 | K9: 수량
A10: 7 | B10: 46036 | C10: 소모품비 | D10: 보루 | E10: 미래공구 | F10: 1 | G10: 12000 | H10: =F10*G10 -> 12000 | I10: 거래명세서 첨부 | K10: 식수인원
A11: 8 | B11: 46036 | C11: 소모품비 | D11: 코발트드릴 | E11: 미래공구 | F11: 10 | G11: 1700 | H11: =F11*G11 -> 17000 | I11: 거래명세서 첨부 | K11: 단가
A12: 9 | B12: 46036 | C12: 소모품비 | D12: 코발트드릴 | E12: 미래공구 | F12: 10 | G12: 3400 | H12: =F12*G12 -> 34000 | I12: 거래명세서 첨부
A13: 10 | B13: 46036 | C13: 소모품비 | D13: 마그네틱드릴부품 | E13: 미래공구 | F13: 1 | G13: 10000 | H13: =F13*G13 -> 10000 | I13: 거래명세서 첨부 | K13: ■ 구분은 [KC대납 식대 및 식대] 이외 항목은 입력금지
A14: 11 | B14: 46037 | C14: 소모품비 | D14: 방우플러그 | E14: 미래공구 | F14: 10 | G14: 4800 | H14: =F14*G14 -> 48000 | I14: 거래명세서 첨부
A15: 12 | B15: 46038 | C15: 소모품비 | D15: 에폭시접착제 | E15: 미래공구 | F15: 2 | G15: 7100 | H15: =F15*G15 -> 14200 | I15: 거래명세서 첨부
A16: 13 | B16: 46038 | C16: 소모품비 | D16: 마대 | E16: 미래공구 | F16: 100 | G16: 300 | H16: =F16*G16 -> 30000 | I16: 거래명세서 첨부
A17: 14 | B17: 46038 | C17: 소모품비 | D17: 먹물 | E17: 미래공구 | F17: 1 | G17: 3600 | H17: =F17*G17 -> 3600 | I17: 거래명세서 첨부
A18: 15 | B18: 46038 | C18: 소모품비 | D18: 투명테이프 | E18: 미래공구 | F18: 5 | G18: 300 | H18: =F18*G18 -> 1500 | I18: 거래명세서 첨부
A19: 16 | B19: 46041 | C19: 소모품비 | D19: 케이블타이 | E19: 미래공구 | F19: 2 | G19: 3400 | H19: =F19*G19 -> 6800 | I19: 거래명세서 첨부
A20: 17 | B20: 46041 | C20: 소모품비 | D20: 케이블타이 | E20: 미래공구 | F20: 3 | G20: 5300 | H20: =F20*G20 -> 15900 | I20: 거래명세서 첨부
A21: 18 | B21: 46041 | C21: 소모품비 | D21: 청보호랩 | E21: 미래공구 | F21: 4 | G21: 18000 | H21: =F21*G21 -> 72000 | I21: 거래명세서 첨부
A22: 19 | B22: 46041 | C22: 소모품비 | D22: 내화학장갑 | E22: 미래공구 | F22: 1 | G22: 21000 | H22: =F22*G22 -> 21000 | I22: 거래명세서 첨부
A23: 20 | B23: 46041 | C23: 소모품비 | D23: 탄력바 | E23: 미래공구 | F23: 1 | G23: 17000 | H23: =F23*G23 -> 17000 | I23: 거래명세서 첨부
A24: 21 | B24: 46043 | C24: 소모품비 | D24: S고리 | E24: 미래공구 | F24: 1 | G24: 20600 | H24: =F24*G24 -> 20600 | I24: 거래명세서 첨부
A25: 22 | B25: 46049 | C25: 소모품비 | D25: 튜브컷터 | E25: 미래공구 | F25: 2 | G25: 41700 | H25: =F25*G25 -> 83400 | I25: 거래명세서 첨부
... A35: 32 | B35: 46051 | C35: 소모품비 | D35: 안전칼 | E35: 미래공구 | F35: 10 | G35: 5700 | H35: =F35*G35 -> 57000 | I35: 거래명세서 첨부

Sheet 서명란
B2: 현 장 확 인 | C2: 소 장 | E2: (서명)
C3: 공 사 | E3: (서명)
C4: 공 무 | E4: (서명)
G6: 사 업 부 | H6: Frontier 사업부 GNP 본부장 | I6: BOC 센터장 | J6: Frontier 사업부장
L8: 본 사 | M8: 담 당 | N8: 검 토 | O8: 검 토
Q11: 구 분 | R11: 확 인
Q12: 품 질 | R12: O O O (인)
Q13: 공 무 | R13: O O O (인)

Sheet DIA-INCH
B3: SIZE
B4: A(mm) | C4: Inch
B5: 8A | C5: 0.25
B6: 15A | C6: 0.5
B7: 20A | C7: 0.75
B8: 25A | C8: 1
B9: 32A | C9: 1.25
B10: 40A | C10: 1.5
B11: 50A | C11: 2
B12: 65A | C12: 2.5
B13: 80A | C13: 3
B14: 100A | C14: 4
B15: 110A | C15: 4
B16: 125A | C16: 5
... B27: 550A | C27: 22
