Workbook
Name _: #REF!
Name _??_??_?C?g??: #REF!
Name ___DAT1: [1]원본!#REF!
Name ___DAT10: [1]원본!#REF!
Name ___DAT12: [1]원본!#REF!
Name ___DAT13: [1]원본!#REF!
Name ___DAT14: [1]원본!#REF!
Name ___DAT15: [1]원본!#REF!
Name ___DAT16: [1]원본!#REF!
Name ___DAT17: [1]원본!#REF!
Name ___DAT18: [1]원본!#REF!
Name ___DAT19: [1]원본!#REF!
Name ___DAT2: [1]원본!#REF!
Name ___DAT20: [1]원본!#REF!
Name ___DAT3: [1]원본!#REF!
Name ___DAT4: [1]원본!#REF!
Name ___DAT5: #REF!
Name ___DAT6: [1]원본!#REF!
Name ___DAT7: [1]원본!#REF!
Name ___DAT8: [1]원본!#REF!
Name ___DAT9: [1]원본!#REF!
Name ___QQ123: #REF!
Name __DAT11: #REF!
Name __DAT21: #REF!
Name __DAT22: #REF!
Name __DAT23: #REF!
Name __DAT24: #REF!
Name __DAT25: #REF!
Name __DAT26: #REF!
Name __DAT27: #REF!
Name __DAT28: #REF!
Name __P3: #REF!
Name __P4: #REF!
Name __P5: #REF!
Name __P6: #REF!
Name __PP1: #REF!
Name _0101__장비_설치공사: #REF!
Name _0201__소화_장비설치공사: #REF!
Name _1: #REF!
Name _1._PANEL_BD.__LP___1: #REF!
Name _1._옥외배관및장비설치공사: #REF!
Name _1_3_0Crite: #REF!
Name _10: [6]고정1!$A$416:$L$458
Name _10A_61: #N/A
Name _10A_62: #N/A
Name _10A_63: #N/A
Name _10A_64: #N/A
Name _10A_65: #N/A
Name _10A_66: #N/A
Name _10A_67: #N/A
Name _10A_68: #N/A
Name _10A_69: #N/A
Name _10A_70: #N/A
Name _10A_71: #N/A
Name _10A_72: #N/A
Name _10A_73: #N/A
Name _10A_74: #N/A
Name _10A_75: #N/A
Name _10A_76: #N/A
Name _10A_77: #N/A

Sheet 용역청구서 표지
B4: 용 역 청 구 서
B7: P4 Ph4 GAS 1공구 마감공사
C8: S25-004
C14: 2026년 02월
C15: ㈜리도시스템

Sheet 용역 청구서(갑지)
A1: 용 역 청 구 서
A3: 1 | B3: 공 사 명 | C3: : | D3: ='용역청구서 표지'!$B$7 -> P4 Ph4 GAS 1공구 마감공사 | E3: ='용역청구서 표지'!$C$8 -> S25-004
A4: 2 | B4: 공 종 | C4: : | D4: 외주용역(M/M부분)
A5: 3 | B5: 계 약 금 액 | C5: : | D5: =ROUNDUP(E5,0) -> 130000000 | E5: =집계장!I23 -> 130000000 | F5: (VAT 별도)
A6: 4 | B6: 누 계 기 성 금 액 | C6: : | D6: =ROUNDUP(E6,0) -> 130000000 | E6: =E7+E13 -> 130000000 | F6: (VAT 별도)
A7: 5 | B7: 전 회 기 성 금 액 | C7: : | D7: =ROUNDUP(E7,0) -> 100000000 | E7: =집계장!G23 -> 100000000 | F7: (VAT 별도)
A8: 6 | B8: 금 회 기 성 금 액 | C8: : | D8: =ROUNDUP(E8,0) -> 30000000 | E8: =집계장!F19 -> 30000000 | F8: (VAT 별도)
A9: 7 | B9: 선 금 액 | C9: : | D9: =ROUNDUP(E9,0) -> 0 | E9: =집계장!K21 -> 0 | F9: (VAT 별도)
A10: 8 | B10: 선 금 전 회 공 제 | C10: : | D10: =ROUNDUP(E10,0) -> 0 | E10: =집계장!G21 -> 0 | F10: (VAT 별도)
A11: 9 | B11: 선 금 금 회 공 제 | C11: : | D11: =ROUNDUP(E11,0) -> 0 | E11: =집계장!F21 -> 0 | F11: (VAT 별도)
A12: 10 | B12: 선 금 잔 여 금 액 | C12: : | D12: =ROUNDUP(E12,0) -> 0 | E12: =집계장!L21 -> 0 | F12: (VAT 별도)
A13: 11 | B13: 금 회 청 구 금 액 | C13: : | D13: =ROUNDUP(E13,0) -> 30000000 | E13: =집계장!F23 -> 30000000 | F13: (VAT 별도)
A14: 12 | B14: 잔 여 기 성 금 액 | C14: : | D14: =ROUNDUP(E14,0) -> 0 | E14: 0 | F14: (VAT 별도)
A15: 13 | B15: 공 정 율 | C15: : | D15: 1
A16: 14 | B16: 청 구 공 사 기 간 | C16: : | D16: 2026. 02. 01 ~ 2026. 02. 28
B18: 위 공사의 하도급에 있어서 공사설계도서, 시방서,품질관리 기준 및 약정대로 시공 되었음을 확인하오며. 만약 귀사의 현장담당의 검사에
B19: 관하여 하자가 발견된 때에는 즉시 실액배상 또는 재 시공할것을 서약하고 이에 기성 청구서를 제출합니다.
B20: 상기건과 관련하여 본 청구 이전까지의 모든 대금은 수령하였음을 확약합니다.
F21: 작 성 일 : 2026년 02월 28일
F23: 상 호 : | G23: ㈜ 리도시스템
B24: ※첨 부 : 기성내역서 1부. | F24: 주 소 : | G24: 충남 천안시 직산읍 군서2길 20, 1층
F25: 대표이사 : | G25: 김 용 근 | I25: (인)
D26: ㈜케이씨이앤씨 귀하

Sheet 용역 내역서(을지)
A1: 용 역 내 역 서
A2: P4 Ph4 GAS 1공구 마감공사 | G2: 단위 : 원
A3: 품 명 | B3: 규 격 | C3: 단위 | D3: 단 가 | E3: 금 회 청 구
E4: 수 량 | F4: 금 액 | G4: 비 고
A5: 고급기술인 | B5: S+ | C5: M/M | D5: 1400000 | E5: 1 | F5: =D5*E5 -> 1400000
A6: 고급기술인 | B6: S | C6: M/M | D6: 1200000 | F6: =D6*E6 -> 0
A7: 중급기술인 | B7: A+ | C7: M/M | D7: 1000000 | F7: =D7*E7 -> 0
A8: 중급기술인 | B8: A | C8: M/M | D8: 900000 | F8: =D8*E8 -> 0
A9: 중급기술인 | B9: B+ | C9: M/M | D9: 800000 | F9: =D9*E9 -> 0
A10: 중급기술인 | B10: B | C10: M/M | D10: 700000 | F10: =D10*E10 -> 0
A11: 초급 기술인 | B11: C | C11: M/M | D11: 600000 | F11: =D11*E11 -> 0
A13: 인센티브 | E13: 0.01 | F13: =SUM(F5:F11)*E13 -> 14000
A15: 총 계 | E15: =SUM(E5:E11) -> 1 | F15: =SUM(F5:F13) -> 1414000

Sheet 내역서(을지)
A1: 용 역 내 역 서
A2: P4 Ph4 GAS 1공구 마감공사 | G2: 단위 : 원
A3: 품 명 | B3: 규 격 | C3: 단위 | D3: 단 가 | E3: 금 회 청 구 | G3: 비 고
E4: 수 량 | F4: 금 액
A5: 고급기술인 | B5: S+ | C5: M/M | D5: 1400000 | E5: 5 | F5: =D5*E5 -> 7000000
A6: 고급기술인 | B6: S | C6: M/M | D6: 1200000 | E6: 5 | F6: =D6*E6 -> 6000000
A7: 중급기술인 | B7: A+ | C7: M/M | D7: 1000000 | E7: 5 | F7: =D7*E7 -> 5000000
A8: 중급기술인 | B8: A | C8: M/M | D8: 900000 | E8: 5 | F8: =D8*E8 -> 4500000
A9: 중급기술인 | B9: B+ | C9: M/M | D9: 800000 | E9: 5 | F9: =D9*E9 -> 4000000
A10: 중급기술인 | B10: B | C10: M/M | D10: 700000 | E10: 5 | F10: =D10*E10 -> 3500000
A11: 초급기술인 | B11: C | C11: M/M | D11: 600000 | F11: =D11*E11 -> 0
A13: 인센티브 | E13: 0 | F13: =SUM(F5:F11)*E13 -> 0
A27: 총 계 | E27: =SUM(E5:E11) -> 30 | F27: =SUM(F5:F26) -> 30000000

Sheet 집계장
A1: ='용역청구서 표지'!$B$7 -> P4 Ph4 GAS 1공구 마감공사
L2: ='용역청구서 표지'!$C$15 -> ㈜리도시스템
A3: 구분 | B3: 내역 | C3: 단위 | D3: 수량 | E3: 단가 | F3: 합계 | G3: 전회기성 | H3: 금회기성 | I3: 누계기성 | J3: 비 고
A4: 1. 물량 | B4: WELDING POINT | C4: D/I | D4: =SUM('물량 내역서'!$J$5:$J$27) -> 810.5 | E4: =F4/D4 -> 435000 | F4: =SUM('물량 내역서'!$K$5:$K$27) -> 352567500 | G4: 607477500 | H4: =F4 -> 352567500 | I4: =G4+H4 -> 960045000
B5: VALVE 설치비 | C5: EA | D5: =SUM('물량 내역서'!$J$28:$J$50) -> 20 | E5: =F5/D5 -> 179812.5 | F5: =SUM('물량 내역서'!$K$28:$K$50) -> 3596250 | G5: 3288000 | H5: =F5 -> 3596250 | I5: =G5+H5 -> 6884250
B6: 인원 실투입 | C6: M/D | F6: ='근로내역 (2월)'!AP91 -> 0 | H6: =F6 -> 0 | I6: =G6+H6 -> 0
A7: 2. 기타비용 | B7: 중대재해발생건 LOSS | G7: 8656351 | I7: =G7+H7 -> 8656351 | J7: 타업체 중대재해발생건으로 인한 건
B8: 기타지급 운영비 | C8: 式 | F8: 305562577 | G8: 275683397 | H8: =30000000-120820 -> 29879180 | I8: =G8+H8 -> 305562577 | J8: (다음 기성에서 차감)
A9: 소 계 | B9: 물량 | F9: =SUM(F4:F8) -> 661726327 | G9: =SUM(G4:G8) -> 895105248 | H9: =SUM(H4:H8) -> 386042930 | I9: =SUM(I4:I8) -> 1281148178
A10: 3. 노무비 | B10: 직접노무비 | C10: 式 | D10: ='근로내역 (2월)'!AN92 -> 1683.125 | E10: =F10/D10 -> 187209.8 | F10: ='근로내역 (2월)'!AP92 -> 315097500 | G10: 706404375 | H10: =F10 -> 315097500 | I10: =G10+H10 -> 1021501875
A11: 4. 숙소 및 식대 | B11: 임대료+관리비 | C11: 式 | D11: =SUM(숙소임차료!H4:H9)+SUM(숙소관리비!H4:H19) -> 84 | E11: =F11/D11 -> 77064.643 | F11: =숙소임차료!I3+숙소관리비!I3 -> 6473430 | G11: 16333055 | H11: =F11 -> 6473430 | I11: =G11+H11 -> 22806485
B12: 식대 | C12: 式 | D12: =SUM(식대비용!G4:G7) -> 74 | E12: =F12/D12 -> 465837.84 | F12: =식대비용!I3 -> 34472000 | G12: 72367818 | H12: =F12 -> 34472000 | I12: =G12+H12 -> 106839818
A13: 5. 기타 공제 내역 | C13: 式
A14: 소 계 | B14: 공제 | F14: =SUM(F10:F12) -> 356042930 | G14: =SUM(G10:G13) -> 795105248 | H14: =SUM(H10:H13) -> 356042930 | I14: =SUM(I10:I13) -> 1151148178
A15: 합 계 | B15: 기성 (물량-공제) | F15: =F9-F14 -> 305683397 | G15: =G9-G14 -> 100000000 | H15: =H9-H14 -> 30000000 | I15: =I9-I14 -> 130000000
A16: 6. 유보금 | B16: 기성금*XX% | C16: 式
A17: 7. 유보금 차액 | B17: 전회 누계유보금+적자 기성액 | C17: 式 | F17: -275683397 | G17: -275683397 | H17: =-H8 -> -29879180 | I17: =G17+H17 -> -305562577
A18: 8. NEGO | B18: NEGO | C18: 式
A19: 총 계 | B19: 최종기성 | F19: =F15-F16+F17+F18 -> 30000000 | G19: =G15 -> 100000000 | H19: =H15 -> 30000000 | I19: =I15 -> 130000000
A20: 선급금 | B20: 선수공제 | C20: 式 | H20: =F20 -> 0 | I20: =G20+H20 -> 0 | K20: 지급 선급금 | L20: 선급금 차액
B21: 단수정리 | C21: 式 | H21: =F21 -> 0 | I21: =G21+H21 -> 0 | J21: 만 단위 이하 절사
A22: 공제 후 실 지급액 | F22: =F19 -> 30000000 | G22: =G19 -> 100000000 | H22: =H19 -> 30000000 | I22: =I19 -> 130000000
A23: 세금계산서 기준 | F23: =ROUNDDOWN(F22,-5) -> 30000000 | G23: =ROUNDDOWN(G22,-5) -> 100000000 | H23: =ROUNDDOWN(H22,-5) -> 30000000 | I23: =ROUNDDOWN(I22,-5) -> 130000000 | J23: 만 단위 이하 절사
A24: TERMS AND CONDITIONS | D24: NOTE
A25: 1. 납 기 : KCEnC 지정 납기로 별도 협의 하에 결정하는 것으로 함.
A26: 2. 지불조건 : KCEnC 지불 조건에 따름.
A27: 3. 유효기간 : 기성 제출일로 부터 30일 이내

Sheet 물량 내역서
A1: 2026년 (02)월 물량 내역서
A2: ='용역청구서 표지'!$B$7 -> P4 Ph4 GAS 1공구 마감공사 | M2: 단위 : 원
A3: 품 명 | B3: 규 격 | C3: 단위 | D3: W/P 수량 | E3: 단 가 | F3: 계 약 내 역 | H3: 전 회 누 계 물 량 | J3: 금 회 물 량 | L3: 누 계 물 량
F4: D/I 수량 | G4: 금액 | H4: D/I 수량 | I4: 금액 | J4: D/I 수량 | K4: 금액 | L4: D/I 수량 | M4: 금액
A5: WEDING POINT | B5: 8A | C5: POINT | D5: 0 | E5: 435000 | F5: =L5 -> 0 | G5: =M5 -> 0 | I5: =E5*H5 -> 0 | J5: =$D5*'DIA-INCH'!$C5 -> 0 | K5: =$E5*$J5 -> 0 | L5: =H5+J5 -> 0 | M5: =I5+K5 -> 0
A6: WEDING POINT | B6: 15A | C6: POINT | D6: 0 | E6: 435000 | F6: =L6 -> 0 | G6: =M6 -> 0 | I6: =E6*H6 -> 0 | J6: =$D6*'DIA-INCH'!$C6 -> 0 | K6: =$E6*$J6 -> 0 | L6: =H6+J6 -> 0 | M6: =I6+K6 -> 0
A7: WEDING POINT | B7: 20A | C7: POINT | D7: 0 | E7: 435000 | F7: =L7 -> 0 | G7: =M7 -> 0 | I7: =E7*H7 -> 0 | J7: =$D7*'DIA-INCH'!$C7 -> 0 | K7: =$E7*$J7 -> 0 | L7: =H7+J7 -> 0 | M7: =I7+K7 -> 0
A8: WEDING POINT | B8: 25A | C8: POINT | D8: 81 | E8: 435000 | F8: =L8 -> 137 | G8: =M8 -> 59595000 | H8: 56 | I8: =E8*H8 -> 24360000 | J8: =$D8*'DIA-INCH'!$C8 -> 81 | K8: =$E8*$J8 -> 35235000 | L8: =H8+J8 -> 137 | M8: =I8+K8 -> 59595000
A9: WEDING POINT | B9: 32A | C9: POINT | E9: 435000 | F9: =L9 -> 0 | G9: =M9 -> 0 | I9: =E9*H9 -> 0 | J9: =$D9*'DIA-INCH'!$C9 -> 0 | K9: =$E9*$J9 -> 0 | L9: =H9+J9 -> 0 | M9: =I9+K9 -> 0
A10: WEDING POINT | B10: 40A | C10: POINT | D10: 27 | E10: 435000 | F10: =L10 -> 141 | G10: =M10 -> 61335000 | H10: 100.5 | I10: =E10*H10 -> 43717500 | J10: =$D10*'DIA-INCH'!$C10 -> 40.5 | K10: =$E10*$J10 -> 17617500 | L10: =H10+J10 -> 141 | M10: =I10+K10 -> 61335000
A11: WEDING POINT | B11: 50A | C11: POINT | D11: 3 | E11: 435000 | F11: =L11 -> 276 | G11: =M11 -> 120060000 | H11: 270 | I11: =E11*H11 -> 117450000 | J11: =$D11*'DIA-INCH'!$C11 -> 6 | K11: =$E11*$J11 -> 2610000 | L11: =H11+J11 -> 276 | M11: =I11+K11 -> 120060000
A12: WEDING POINT | B12: 65A | C12: POINT | D12: 50 | E12: 435000 | F12: =L12 -> 385 | G12: =M12 -> 167475000 | H12: 260 | I12: =E12*H12 -> 113100000 | J12: =$D12*'DIA-INCH'!$C12 -> 125 | K12: =$E12*$J12 -> 54375000 | L12: =H12+J12 -> 385 | M12: =I12+K12 -> 167475000
A13: WEDING POINT | B13: 80A | C13: POINT | D13: 13 | E13: 435000 | F13: =L13 -> 75 | G13: =M13 -> 32625000 | H13: 36 | I13: =E13*H13 -> 15660000 | J13: =$D13*'DIA-INCH'!$C13 -> 39 | K13: =$E13*$J13 -> 16965000 | L13: =H13+J13 -> 75 | M13: =I13+K13 -> 32625000
A14: WEDING POINT | B14: 100A | C14: POINT | D14: 23 | E14: 435000 | F14: =L14 -> 424 | G14: =M14 -> 184440000 | H14: 332 | I14: =E14*H14 -> 144420000 | J14: =$D14*'DIA-INCH'!$C14 -> 92 | K14: =$E14*$J14 -> 40020000 | L14: =H14+J14 -> 424 | M14: =I14+K14 -> 184440000
A15: WEDING POINT | B15: 110A | C15: POINT | E15: 435000 | F15: =L15 -> 0 | G15: =M15 -> 0 | I15: =E15*H15 -> 0 | J15: =$D15*'DIA-INCH'!$C15 -> 0 | K15: =$E15*$J15 -> 0 | L15: =H15+J15 -> 0 | M15: =I15+K15 -> 0
A16: WEDING POINT | B16: 125A | C16: POINT | D16: 77 | E16: 435000 | F16: =L16 -> 715 | G16: =M16 -> 311025000 | H16: 330 | I16: =E16*H16 -> 143550000 | J16: =$D16*'DIA-INCH'!$C16 -> 385 | K16: =$E16*$J16 -> 167475000 | L16: =H16+J16 -> 715 | M16: =I16+K16 -> 311025000
A17: WEDING POINT | B17: 150A | C17: POINT | D17: 3 | E17: 435000 | F17: =L17 -> 30 | G17: =M17 -> 13050000 | H17: 12 | I17: =E17*H17 -> 5220000 | J17: =$D17*'DIA-INCH'!$C17 -> 18 | K17: =$E17*$J17 -> 7830000 | L17: =H17+J17 -> 30 | M17: =I17+K17 -> 13050000
A18: WEDING POINT | B18: 175A | C18: POINT | E18: 435000 | F18: =L18 -> 0 | G18: =M18 -> 0 | I18: =E18*H18 -> 0 | J18: =$D18*'DIA-INCH'!$C18 -> 0 | K18: =$E18*$J18 -> 0 | L18: =H18+J18 -> 0 | M18: =I18+K18 -> 0
A19: WEDING POINT | B19: 200A | C19: POINT | D19: 3 | E19: 435000 | F19: =L19 -> 24 | G19: =M19 -> 10440000 | I19: =E19*H19 -> 0 | J19: =$D19*'DIA-INCH'!$C19 -> 24 | K19: =$E19*$J19 -> 10440000 | L19: =H19+J19 -> 24 | M19: =I19+K19 -> 10440000
A20: WEDING POINT | B20: 225A | C20: POINT | E20: 435000 | F20: =L20 -> 0 | G20: =M20 -> 0 | I20: =E20*H20 -> 0 | J20: =$D20*'DIA-INCH'!$C20 -> 0 | K20: =$E20*$J20 -> 0 | L20: =H20+J20 -> 0 | M20: =I20+K20 -> 0
A21: WEDING POINT | B21: 250A | C21: POINT | E21: 435000 | F21: =L21 -> 0 | G21: =M21 -> 0 | I21: =E21*H21 -> 0 | J21: =$D21*'DIA-INCH'!$C21 -> 0 | K21: =$E21*$J21 -> 0 | L21: =H21+J21 -> 0 | M21: =I21+K21 -> 0
A22: WEDING POINT | B22: 300A | C22: POINT | E22: 435000 | F22: =L22 -> 0 | G22: =M22 -> 0 | I22: =E22*H22 -> 0 | J22: =$D22*'DIA-INCH'!$C22 -> 0 | K22: =$E22*$J22 -> 0 | L22: =H22+J22 -> 0 | M22: =I22+K22 -> 0
A23: WEDING POINT | B23: 350A | C23: POINT | E23: 435000 | F23: =L23 -> 0 | G23: =M23 -> 0 | I23: =E23*H23 -> 0 | J23: =$D23*'DIA-INCH'!$C23 -> 0 | K23: =$E23*$J23 -> 0 | L23: =H23+J23 -> 0 | M23: =I23+K23 -> 0
A24: WEDING POINT | B24: 400A | C24: POINT | E24: 435000 | F24: =L24 -> 0 | G24: =M24 -> 0 | I24: =E24*H24 -> 0 | J24: =$D24*'DIA-INCH'!$C24 -> 0 | K24: =$E24*$J24 -> 0 | L24: =H24+J24 -> 0 | M24: =I24+K24 -> 0
A25: WEDING POINT | B25: 450A | C25: POINT | E25: 435000 | F25: =L25 -> 0 | G25: =M25 -> 0 | I25: =E25*H25 -> 0 | J25: =$D25*'DIA-INCH'!$C25 -> 0 | K25: =$E25*$J25 -> 0 | L25: =H25+J25 -> 0 | M25: =I25+K25 -> 0
A26: WEDING POINT | B26: 500A | C26: POINT | E26: 435000 | F26: =L26 -> 0 | G26: =M26 -> 0 | I26: =E26*H26 -> 0 | J26: =$D26*'DIA-INCH'!$C26 -> 0 | K26: =$E26*$J26 -> 0 | L26: =H26+J26 -> 0 | M26: =I26+K26 -> 0
A27: WEDING POINT | B27: 550A | C27: POINT | E27: 435000 | F27: =L27 -> 0 | G27: =M27 -> 0 | I27: =E27*H27 -> 0 | J27: =$D27*'DIA-INCH'!$C27 -> 0 | K27: =$E27*$J27 -> 0 | L27: =H27+J27 -> 0 | M27: =I27+K27 -> 0
A28: VALVE 설치비 | B28: 8A | C28: EA | E28: =$E$31*'DIA-INCH'!$C5 -> 17125 | F28: =L28 -> 0 | G28: =M28 -> 0 | I28: =E28*H28 -> 0 | J28: =D28 -> 0 | K28: =$J28*$E28 -> 0 | L28: =H28+J28 -> 0 | M28: =I28+K28 -> 0
A29: VALVE 설치비 | B29: 15A | C29: EA | E29: =$E$31*'DIA-INCH'!$C6 -> 34250 | F29: =L29 -> 0 | G29: =M29 -> 0 | I29: =E29*H29 -> 0 | J29: =D29 -> 0 | K29: =$J29*$E29 -> 0 | L29: =H29+J29 -> 0 | M29: =I29+K29 -> 0
A30: VALVE 설치비 | B30: 20A | C30: EA | E30: =$E$31*'DIA-INCH'!$C7 -> 51375 | F30: =L30 -> 0 | G30: =M30 -> 0 | I30: =E30*H30 -> 0 | J30: =D30 -> 0 | K30: =$J30*$E30 -> 0 | L30: =H30+J30 -> 0 | M30: =I30+K30 -> 0
A31: VALVE 설치비 | B31: 25A | C31: EA | D31: 3 | E31: 68500 | F31: =L31 -> 3 | G31: =M31 -> 205500 | I31: =E31*H31 -> 0 | J31: =D31 -> 3 | K31: =$J31*$E31 -> 205500 | L31: =H31+J31 -> 3 | M31: =I31+K31 -> 205500
A32: VALVE 설치비 | B32: 32A | C32: EA | E32: =$E$31*'DIA-INCH'!$C9 -> 85625 | F32: =L32 -> 0 | G32: =M32 -> 0 | I32: =E32*H32 -> 0 | J32: =D32 -> 0 | K32: =$J32*$E32 -> 0 | L32: =H32+J32 -> 0 | M32: =I32+K32 -> 0
A33: VALVE 설치비 | B33: 40A | C33: EA | D33: 9 | E33: =$E$31*'DIA-INCH'!$C10 -> 102750 | F33: =L33 -> 9 | G33: =M33 -> 924750 | I33: =E33*H33 -> 0 | J33: =D33 -> 9 | K33: =$J33*$E33 -> 924750 | L33: =H33+J33 -> 9 | M33: =I33+K33 -> 924750
A34: VALVE 설치비 | B34: 50A | C34: EA | E34: =$E$31*'DIA-INCH'!$C11 -> 137000 | F34: =L34 -> 4 | G34: =M34 -> 548000 | H34: 4 | I34: =E34*H34 -> 548000 | J34: =D34 -> 0 | K34: =$J34*$E34 -> 0 | L34: =H34+J34 -> 4 | M34: =I34+K34 -> 548000
A35: VALVE 설치비 | B35: 65A | C35: EA | E35: =$E$31*'DIA-INCH'!$C12 -> 171250 | F35: =L35 -> 0 | G35: =M35 -> 0 | I35: =E35*H35 -> 0 | J35: =D35 -> 0 | K35: =$J35*$E35 -> 0 | L35: =H35+J35 -> 0 | M35: =I35+K35 -> 0
A36: VALVE 설치비 | B36: 80A | C36: EA | D36: 2 | E36: =$E$31*'DIA-INCH'!$C13 -> 205500 | F36: =L36 -> 2 | G36: =M36 -> 411000 | I36: =E36*H36 -> 0 | J36: =D36 -> 2 | K36: =$J36*$E36 -> 411000 | L36: =H36+J36 -> 2 | M36: =I36+K36 -> 411000
A37: VALVE 설치비 | B37: 100A | C37: EA | E37: =$E$31*'DIA-INCH'!$C14 -> 274000 | F37: =L37 -> 10 | G37: =M37 -> 2740000 | H37: 10 | I37: =E37*H37 -> 2740000 | J37: =D37 -> 0 | K37: =$J37*$E37 -> 0 | L37: =H37+J37 -> 10 | M37: =I37+K37 -> 2740000
A38: VALVE 설치비 | B38: 110A | C38: EA | D38: 0 | E38: =$E$31*'DIA-INCH'!$C15 -> 274000 | F38: =L38 -> 0 | G38: =M38 -> 0 | I38: =E38*H38 -> 0 | J38: =D38 -> 0 | K38: =$J38*$E38 -> 0 | L38: =H38+J38 -> 0 | M38: =I38+K38 -> 0
A39: VALVE 설치비 | B39: 125A | C39: EA | D39: 6 | E39: =$E$31*'DIA-INCH'!$C16 -> 342500 | F39: =L39 -> 6 | G39: =M39 -> 2055000 | I39: =E39*H39 -> 0 | J39: =D39 -> 6 | K39: =$J39*$E39 -> 2055000 | L39: =H39+J39 -> 6 | M39: =I39+K39 -> 2055000
A40: VALVE 설치비 | B40: 150A | C40: EA | D40: 0 | E40: =$E$31*'DIA-INCH'!$C17 -> 411000 | F40: =L40 -> 0 | G40: =M40 -> 0 | I40: =E40*H40 -> 0 | J40: =D40 -> 0 | K40: =$J40*$E40 -> 0 | L40: =H40+J40 -> 0 | M40: =I40+K40 -> 0
...

Sheet 근로내역 (2월)
A1: 2026년 ( 02 )월 일용 노무비명세서 | AH1: 현장명 | AM1: ='용역청구서 표지'!$B$7 -> P4 Ph4 GAS 1공구 마감공사
AH2: 현장소장 | AM2: 장규철
AH3: 잡코드 | AM3: ='용역청구서 표지'!$C$8 -> S25-004
A5: 번호 | B5: 성명 | C5: 주민등록번호 | D5: 직종 | E5: 연락처(H.P) | F5: 은행명 | G5: 예금주 | H5: 계좌번호 | I5: 1 | J5: 2 | K5: 3 | L5: 4 | M5: 5 | N5: 6 | O5: 7 | P5: 8 | Q5: 9 | R5: 10 | S5: 11 | T5: 12 | U5: 13 | V5: 14 | W5: 15 | X5: 16 | Y5: 17 | Z5: 18 | AA5: 19 | AB5: 20 | AC5: 21 | AD5: 22 | AE5: 23 | AF5: 24 | AG5: 25 | AH5: 26 | AI5: 27 | AJ5: 28 | AN5: 공수 | AO5: 단가 | AP5: 총액
A6: 1 | B6: 고경석 | C6: 960824-1063628 | D6: 보통인부 | E6: 010-5713-0029 | F6: 국민 | G6: 고경석 | H6: 686602-01-330663 | J6: 1.5 | K6: 1.5 | L6: 1 | M6: 1.5 | N6: 1.5 | Q6: 1.5 | R6: 1.5 | S6: 1 | T6: 1.5 | U6: 1.5 | AA6: 1 | AB6: 1 | AC6: 1 | AE6: 1.5 | AF6: 1.5 | AG6: 1 | AH6: 1.5 | AI6: 1.5 | AJ6: 1 | AN6: =SUM(I6:AM6) -> 25 | AO6: 150000 | AP6: =AN6*AO6 -> 3750000
A7: =A6+1 -> 2 | B7: 고철영 | C7: 990713-1901218 | D7: 보통인부 | E7: 010-5761-5648 | F7: 미래에셋증권 | G7: 고철영 | H7: 442-7028-5766-1 | J7: 1.5 | K7: 1.5 | L7: 1 | M7: 1.5 | N7: 1.5 | O7: 1 | R7: 1.5 | S7: 1 | T7: 1.5 | U7: 1.5 | AB7: 1 | AC7: 0.5 | AE7: 1.5 | AF7: 1.5 | AG7: 0.5 | AH7: 1.5 | AI7: 1.375 | AN7: =SUM(I7:AM7) -> 21.375 | AO7: 150000 | AP7: =AN7*AO7 -> 3206250
A8: =A7+1 -> 3 | B8: 곽영욱 | C8: 060307-3447619 | D8: 보통인부 | E8: 010-9517-3670 | F8: 하나 | G8: 곽영욱 | H8: 660-911656-91507 | J8: 0.625 | K8: 0.375 | L8: 0.625 | M8: 1.5 | N8: 1.25 | Q8: 1.5 | R8: 1.5 | S8: 1.5 | T8: 1.5 | U8: 1.5 | V8: 1 | AA8: 1 | AB8: 1 | AC8: 1 | AE8: 1.5 | AF8: 1.5 | AG8: 1.5 | AH8: 1.5 | AI8: 1.5 | AJ8: 1 | AN8: =SUM(I8:AM8) -> 24.375 | AO8: 150000 | AP8: =AN8*AO8 -> 3656250
A9: =A8+1 -> 4 | B9: 곽영준 | C9: 031007-3447617 | D9: 보통인부 | E9: 010-9979-3670 | F9: 토스 | G9: 곽영준 | H9: 1000-4627-2747 | J9: 0.625 | L9: 1 | M9: 1.5 | N9: 1.25 | Q9: 1.5 | R9: 1.5 | S9: 1.5 | T9: 1.5 | U9: 1.5 | V9: 1 | AA9: 1 | AB9: 1 | AC9: 1 | AE9: 1.5 | AF9: 1.5 | AG9: 1.5 | AH9: 1.5 | AI9: 1.5 | AJ9: 1 | AN9: =SUM(I9:AM9) -> 24.375 | AO9: 150000 | AP9: =AN9*AO9 -> 3656250
A10: =A9+1 -> 5 | B10: 구현모 | C10: 880417-1155419 | D10: 보통인부 | E10: 010-9552-4105 | F10: 카카오 | G10: 구현모 | H10: 3333-06-3026631 | J10: 1.5 | K10: 1.5 | L10: 1.5 | M10: 1.5 | N10: 1.5 | O10: 1 | Q10: 1.5 | R10: 1.5 | S10: 1.5 | T10: 1.5 | U10: 1.5 | AA10: 1 | AB10: 1 | AC10: 0.5 | AE10: 1.5 | AF10: 1.5 | AG10: 0.5 | AH10: 1.5 | AI10: 1.5 | AN10: =SUM(I10:AM10) -> 25 | AO10: 150000 | AP10: =AN10*AO10 -> 3750000
A11: =A10+1 -> 6 | B11: 국관호 | C11: 860809-1085219 | D11: 배관공 | E11: 010-4121-9703 | F11: 하나 | G11: 국관호 | H11: 265-891181-88607 | J11: 1.5 | K11: 1.5 | L11: 1.5 | M11: 1.5 | N11: 1.5 | Q11: 1.5 | R11: 1.5 | S11: 1.5 | U11: 1.5 | V11: 1 | AA11: 1 | AB11: 1 | AC11: 0.5 | AE11: 1.5 | AF11: 1.5 | AG11: 1.5 | AH11: 1.5 | AI11: 1.5 | AN11: =SUM(I11:AM11) -> 24.5 | AO11: 230000 | AP11: =AN11*AO11 -> 5635000
A12: =A11+1 -> 7 | B12: 권민재 | C12: 000609-3850320 | D12: 보통인부 | E12: 010-9143-3659 | F12: 토스 | G12: 권민재 | H12: 1000-7491-0326 | J12: 0.625 | AN12: =SUM(I12:AM12) -> 0.625 | AO12: 150000 | AP12: =AN12*AO12 -> 93750
A13: =A12+1 -> 8 | B13: 김기수 | C13: 670925-1788311 | D13: 보통인부 | E13: 010-8748-6402 | F13: 신한 | G13: 김기수 | H13: 110-395-269363 | J13: 1.5 | K13: 1.5 | L13: 1 | M13: 1.5 | N13: 1.5 | O13: 1 | S13: 1 | T13: 1.5 | U13: 1.5 | AA13: 1 | AB13: 1.5 | AC13: 1 | AE13: 1.5 | AF13: 1.5 | AG13: 1 | AH13: 1.5 | AI13: 1.5 | AJ13: 1 | AN13: =SUM(I13:AM13) -> 23.5 | AO13: 150000 | AP13: =AN13*AO13 -> 3525000
A14: =A13+1 -> 9 | B14: 김기열 | C14: 980624-1020013 | D14: 보통인부 | E14: 010-5801-1602 | F14: 우리 | G14: 김기열 | H14: 1002-955-483076 | J14: 1.5 | K14: 1.5 | L14: 1 | M14: 1.5 | N14: 1.5 | O14: 1 | Q14: 1.5 | R14: 1.5 | S14: 1 | T14: 1.5 | U14: 1.5 | AA14: 1 | AB14: 1 | AE14: 1.5 | AF14: 0.375 | AG14: 1.5 | AH14: 1.5 | AI14: 1.5 | AJ14: 1 | AN14: =SUM(I14:AM14) -> 24.375 | AO14: 150000 | AP14: =AN14*AO14 -> 3656250
A15: =A14+1 -> 10 | B15: 김기영 | C15: 731015-1696411 | D15: 보통인부 | E15: 010-6857-3033 | F15: 새마을 | G15: 김기영 | H15: 9003-1989-7164-1 | J15: 1.5 | K15: 1.5 | L15: 1 | M15: 1.5 | N15: 1.5 | O15: 1 | Q15: 1.5 | R15: 1.5 | S15: 1 | T15: 1.5 | U15: 1.5 | AA15: 1 | AB15: 1 | AE15: 1 | AF15: 1 | AG15: 1 | AH15: 1 | AI15: 1 | AN15: =SUM(I15:AM15) -> 22 | AO15: 150000 | AP15: =AN15*AO15 -> 3300000
A16: =A15+1 -> 11 | B16: 김다은 | C16: 050613-4351912 | D16: 보통인부 | E16: 010-3935-7002 | F16: 농협 | G16: 김다은 | H16: 352-1652-6948-33 | J16: 1.5 | K16: 1.5 | L16: 1 | AN16: =SUM(I16:AM16) -> 4 | AO16: 140000 | AP16: =AN16*AO16 -> 560000
A17: =A16+1 -> 12 | B17: 김덕주 | C17: 690607-1237512 | D17: 보통인부 | E17: 010-4727-6932 | F17: 우리 | G17: 김덕주 | H17: 1002-641-697004 | K17: 1.5 | L17: 1.5 | M17: 1.5 | N17: 1.5 | O17: 1 | Q17: 1.5 | R17: 1.5 | S17: 1.5 | T17: 1.5 | U17: 1.5 | AA17: 1 | AB17: 1.5 | AC17: 0.5 | AG17: 1.5 | AH17: 1.5 | AI17: 1.5 | AN17: =SUM(I17:AM17) -> 22 | AO17: 150000 | AP17: =AN17*AO17 -> 3300000
A18: =A17+1 -> 13 | B18: 김도훈 | C18: 811123-1847011 | D18: 배관공 | E18: 010-2780-2424 | F18: 카카오 | G18: 김도훈 | H18: 3333-03-0267267 | J18: 1.5 | K18: 1.5 | L18: 1 | M18: 1.5 | N18: 1.5 | O18: 1 | Q18: 1.5 | R18: 1.5 | S18: 1 | T18: 1.5 | U18: 1.5 | AA18: 1 | AB18: 1 | AC18: 0.5 | AE18: 1.5 | AF18: 1.5 | AG18: 1.5 | AH18: 1.5 | AI18: 0.5 | AN18: =SUM(I18:AM18) -> 24 | AO18: 180000 | AP18: =AN18*AO18 -> 4320000
A19: =A18+1 -> 14 | B19: 김도훈 | C19: 921029-1127516 | D19: 용접공 | E19: 010-8506-3952 | F19: 우리 | G19: 김도훈 | H19: 1002-044-533435 | J19: 1.5 | K19: 1.5 | L19: 1.5 | M19: 1.5 | N19: 1.5 | Q19: 1.5 | R19: 1.5 | S19: 1.5 | T19: 1.5 | U19: 1.5 | V19: 1 | AA19: 1 | AB19: 1 | AC19: 0.5 | AE19: 1.5 | AF19: 1.5 | AG19: 1.5 | AH19: 1.5 | AI19: 1.5 | AN19: =SUM(I19:AM19) -> 26 | AO19: 240000 | AP19: =AN19*AO19 -> 6240000
A20: =A19+1 -> 15 | B20: 김동성 | C20: 801129-1670913 | D20: 보통인부 | E20: 010-6479-6009 | F20: 국민 | G20: 김동성 | H20: 645901-04-120115 | J20: 1.5 | K20: 1.5 | L20: 1.5 | M20: 1.5 | N20: 1.5 | O20: 1 | Q20: 1.5 | R20: 1.5 | S20: 1 | T20: 1.5 | U20: 1.5 | V20: 1 | AA20: 1 | AB20: 1 | AC20: 0.5 | AE20: 1.5 | AF20: 1.5 | AG20: 1 | AH20: 1.5 | AI20: 1.5 | AN20: =SUM(I20:AM20) -> 26 | AO20: 150000 | AP20: =AN20*AO20 -> 3900000
A21: =A20+1 -> 16 | B21: 김동현 | C21: 940909-1158612 | D21: 용접공 | E21: 010-2576-5831 | F21: 카카오뱅크 | G21: 김동현 | H21: 3333-09-0796-912 | J21: 1.5 | K21: 1.5 | L21: 1.5 | M21: 1.5 | N21: 1.5 | O21: 1 | Q21: 1.5 | R21: 1.5 | S21: 1 | T21: 1.5 | U21: 1.5 | AA21: 1 | AB21: 1 | AC21: 0.5 | AG21: 1 | AH21: 1.5 | AI21: 1.5 | AN21: =SUM(I21:AM21) -> 22 | AO21: 240000 | AP21: =AN21*AO21 -> 5280000
A22: =A21+1 -> 17 | B22: 김만중 | C22: 700819-1574012 | D22: 보통인부 | E22: 010-3101-2836 | F22: 우리 | G22: 김만중 | H22: 1002-738-181869 | J22: 1.5 | K22: 1.5 | L22: 1.5 | M22: 1.5 | N22: 1.5 | O22: 1 | Q22: 1.5 | R22: 1.5 | S22: 1.5 | T22: 1.5 | U22: 1.5 | AA22: 1 | AB22: 1 | AC22: 0.5 | AE22: 1.5 | AF22: 1.5 | AG22: 1 | AH22: 1.5 | AI22: 1.5 | AN22: =SUM(I22:AM22) -> 25.5 | AO22: 150000 | AP22: =AN22*AO22 -> 3825000
A23: =A22+1 -> 18 | B23: 김민준 | C23: 750121-1923111 | D23: 배관공 | E23: 010-3144-7011 | F23: 우리 | G23: 김민준 | H23: 1002-346-022419 | J23: 1.5 | K23: 1.5 | L23: 1 | M23: 1.5 | N23: 1.5 | Q23: 1.5 | R23: 1.5 | S23: 0.5 | T23: 1.5 | U23: 1.5 | AA23: 1 | AB23: 1 | AC23: 0.5 | AE23: 1.5 | AF23: 1.5 | AG23: 1.5 | AH23: 1.5 | AI23: 1.5 | AJ23: 1 | AN23: =SUM(I23:AM23) -> 24.5 | AO23: 220000 | AP23: =AN23*AO23 -> 5390000
A24: =A23+1 -> 19 | B24: 김민환 | C24: 750913-1633014 | D24: 안전관리자 | E24: 010-4603-8523 | F24: 우리 | G24: 김민환 | H24: 1002-152-759347 | J24: 1.5 | K24: 1.5 | L24: 1.5 | M24: 1.5 | N24: 1.5 | Q24: 1.5 | R24: 1.5 | S24: 1 | T24: 1.5 | U24: 1.5 | AA24: 1 | AB24: 1 | AC24: 1 | AE24: 1.5 | AF24: 1.375 | AG24: 1.5 | AH24: 1.5 | AI24: 1.5 | AN24: =SUM(I24:AM24) -> 24.875 | AO24: 220000 | AP24: =AN24*AO24 -> 5472500
A25: =A24+1 -> 20 | B25: 김상진 | C25: 681128-1001110 | D25: 용접공 | E25: 010-9027-0494 | F25: 농협 | G25: 김상진 | H25: 011-12-089996 | J25: 1.5 | K25: 1.5 | L25: 1.5 | M25: 1.5 | N25: 1.5 | Q25: 1.5 | R25: 1.5 | S25: 1 | T25: 1.5 | U25: 1.5 | AA25: 1 | AB25: 1 | AC25: 0.5 | AF25: 1.5 | AG25: 1.5 | AH25: 1.5 | AI25: 1.5 | AN25: =SUM(I25:AM25) -> 23 | AO25: 240000 | AP25: =AN25*AO25 -> 5520000
A26: =A25+1 -> 21 | B26: 김선우 | C26: 851017-1063211 | D26: 공사관리자 | E26: 010-2290-6800 | F26: 신한 | G26: 김선우 | H26: 110-478-054318 | J26: 1.25 | K26: 1 | L26: 1 | M26: 1 | Q26: 1 | R26: 1 | S26: 1 | U26: 1.25 | V26: 1 | AB26: 1 | AE26: 1 | AG26: 1 | AH26: 1 | AI26: 1 | AN26: =SUM(I26:AM26) -> 14.5 | AO26: 250000 | AP26: =AN26*AO26 -> 3625000
A27: =A26+1 -> 22 | B27: 김성겸 | C27: 880625-1477921 | D27: 보통인부 | E27: 010-6767-8681 | F27: 농협 | G27: 김성겸 | H27: 302-0666-0938-21 | J27: 1.5 | K27: 1.5 | L27: 1.5 | M27: 1.5 | N27: 1.5 | O27: 1 | Q27: 1.5 | R27: 1.5 | S27: 1.5 | U27: 1.5 | V27: 1 | AA27: 1 | AB27: 1.5 | AE27: 1.5 | AF27: 1.5 | AG27: 1.5 | AH27: 1.5 | AI27: 0.5 | AN27: =SUM(I27:AM27) -> 24.5 | AO27: 150000 | AP27: =AN27*AO27 -> 3675000
A28: =A27+1 -> 23 | B28: 김수영 | C28: 810331-2482816 | D28: 안전관리자 | E28: 010-4945-4521 | F28: 카카오뱅크 | G28: 김수영 | H28: 3333-21-9406602 | J28: 1.5 | K28: 1.5 | L28: 1 | M28: 1.5 | N28: 1.5 | O28: 1 | Q28: 1.5 | R28: 1.5 | S28: 1.5 | T28: 1.5 | U28: 1 | V28: 1 | AA28: 1 | AB28: 1.5 | AF28: 1.5 | AG28: 1.5 | AH28: 0.75 | AN28: =SUM(I28:AM28) -> 22.25 | AO28: 150000 | AP28: =AN28*AO28 -> 3337500
A29: =A28+1 -> 24 | B29: 김슬기 | C29: 860203-1051819 | D29: 보통인부 | E29: 010-2200-4561 | F29: 케이뱅크 | G29: 김슬기 | H29: 100-188-670019 | J29: 1.5 | K29: 1.5 | L29: 1.5 | M29: 1.5 | N29: 1.5 | Q29: 1.5 | R29: 1.5 | S29: 1.5 | T29: 1.5 | U29: 1.5 | AA29: 1 | AB29: 1 | AC29: 0.5 | AE29: 1.5 | AF29: 1.5 | AG29: 1 | AH29: 1.5 | AI29: 1.5 | AN29: =SUM(I29:AM29) -> 24.5 | AO29: 220000 | AP29: =AN29*AO29 -> 5390000
A30: =A29+1 -> 25 | B30: 김영복 | C30: 690418-1041211 | D30: 보통인부 | E30: 010-8482-8440 | F30: 신한 | G30: 김영복 | H30: 110-476-957730 | J30: 1.5 | K30: 0.5 | L30: 1.5 | M30: 1.5 | N30: 1.5 | O30: 1 | Q30: 1.5 | R30: 1.5 | S30: 1.5 | T30: 1.5 | U30: 1.5 | AA30: 1 | AB30: 1.5 | AC30: 0.5 | AE30: 1.5 | AF30: 1.5 | AG30: 1.5 | AH30: 1.5 | AI30: 1.5 | AN30: =SUM(I30:AM30) -> 25.5 | AO30: 150000 | AP30: =AN30*AO30 -> 3825000
A31: =A30+1 -> 26 | B31: 김용호 | C31: 800821-1823911 | D31: 용접공 | E31: 010-8661-3999 | F31: 기업 | G31: 김용호 | H31: 175-057885-01-012 | J31: 1.5 | K31: 1.5 | L31: 1.5 | M31: 1.5 | N31: 1.5 | Q31: 1.5 | R31: 1.5 | S31: 1 | T31: 1.5 | U31: 1.5 | AA31: 1 | AB31: 1 | AC31: 0.5 | AE31: 1.5 | AF31: 1.5 | AG31: 1.5 | AH31: 1.5 | AI31: 1.5 | AN31: =SUM(I31:AM31) -> 24.5 | AO31: 240000 | AP31: =AN31*AO31 -> 5880000
A32: =A31+1 -> 27 | B32: 김은규 | C32: 681105-1788311 | D32: 도비공 | E32: 010-3505-9062 | F32: 농협 | G32: 김은규 | H32: 351-0941-0263-23 | J32: 1.5 | K32: 1.5 | L32: 1 | M32: 1.5 | N32: 1.5 | O32: 1 | Q32: 1.5 | R32: 1.5 | S32: 1 | T32: 1.5 | U32: 1.5 | AA32: 1 | AB32: 1.5 | AC32: 1 | AE32: 1.5 | AF32: 1.5 | AG32: 1 | AH32: 1.5 | AI32: 1.5 | AJ32: 1 | AN32: =SUM(I32:AM32) -> 26.5 | AO32: 210000 | AP32: =AN32*AO32 -> 5565000
A33: =A32+1 -> 28 | B33: 김재홍 | C33: 900222-1069719 | D33: 용접공 | E33: 010-4345-0747 | F33: 하나 | G33: 김재홍 | H33: 354-910259-36007 | J33: 1.5 | K33: 1.5 | L33: 1.5 | M33: 1.5 | N33: 1.5 | O33: 1 | Q33: 1.5 | R33: 1.5 | S33: 1.5 | T33: 1.5 | U33: 1.5 | V33: 1 | AA33: 1 | AB33: 1 | AC33: 0.5 | AE33: 1.5 | AF33: 1 | AG33: 1 | AH33: 1.5 | AI33: 1.5 | AN33: =SUM(I33:AM33) -> 26 | AO33: 240000 | AP33: =AN33*AO33 -> 6240000
A34: =A33+1 -> 29 | B34: 김정자 | C34: 691109-2581611 | D34: 보통인부 | E34: 010-8347-1457 | F34: 농협 | G34: 김정자 | H34: 352-0865-6722-63 | J34: 1.5 | K34: 1.5 | L34: 1.5 | M34: 1.5 | N34: 1.5 | O34: 1 | Q34: 1.5 | R34: 1.5 | S34: 1.5 | T34: 1.5 | U34: 1.5 | V34: 1 | AA34: 1 | AB34: 1 | AC34: 1 | AE34: 1.5 | AF34: 1.5 | AG34: 1.5 | AH34: 1.5 | AN34: =SUM(I34:AM34) -> 26 | AO34: 180000 | AP34: =AN34*AO34 -> 4680000
A35: =A34+1 -> 30 | B35: 김진호 | C35: 960130-1068311 | D35: 보통인부 | E35: 010-3011-6048 | F35: 국민 | G35: 김진호 | H35: 681102-01-528180 | J35: 1.5 | K35: 1.5 | L35: 1 | M35: 1.5 | N35: 1.5 | Q35: 1.5 | R35: 1.5 | S35: 1.5 | T35: 1.5 | U35: 1.5 | V35: 1 | AA35: 1 | AB35: 1 | AC35: 0.5 | AE35: 1.5 | AF35: 1.5 | AG35: 1.5 | AH35: 1.5 | AI35: 1.5 | AJ35: 1 | AN35: =SUM(I35:AM35) -> 26.5 | AO35: 150000 | AP35: =AN35*AO35 -> 3975000
A36: =A35+1 -> 31 | B36: 김창배 | C36: 810804-1622417 | D36: 공사관리자 | E36: 010-6414-6535 | F36: 기업 | G36: 김창배 | H36: 529-054406-01-011 | J36: 1.5 | K36: 1.5 | L36: 1.5 | M36: 1.5 | N36: 1.5 | O36: 1 | Q36: 1.5 | R36: 1.5 | T36: 1.5 | U36: 1.5 | AA36: 1 | AB36: 1 | AC36: 0.5 | AE36: 1.5 | AF36: 1.5 | AG36: 1 | AH36: 1.5 | AI36: 1.5 | AN36: =SUM(I36:AM36) -> 24 | AO36: 240000 | AP36: =AN36*AO36 -> 5760000
A37: =A36+1 -> 32 | B37: 김홍우 | C37: 890112-1113810 | D37: 배관공 | E37: 010-9932-4037 | F37: 경남 | G37: 김홍우 | H37: 207-0103-6217-05 | J37: 1.5 | K37: 1.5 | L37: 1.5 | M37: 1.5 | N37: 1.5 | O37: 1 | Q37: 1 | R37: 1.5 | S37: 1.5 | T37: 1.5 | U37: 1.5 | AA37: 1 | AB37: 1 | AC37: 0.5 | AE37: 1.5 | AF37: 1.5 | AG37: 1 | AH37: 1.5 | AN37: =SUM(I37:AM37) -> 23.5 | AO37: 230000 | AP37: =AN37*AO37 -> 5405000
A38: =A37+1 -> 33 | B38: 김희준 | C38: 861220-1703211 | D38: 용접공 | E38: 010-9170-0746 | F38: 국민 | G38: 김희준 | H38: 606402-04-039361 | J38: 1.5 | K38: 0.625 | M38: 1.5 | N38: 1.5 | Q38: 1.5 | R38: 1.5 | S38: 1 | T38: 1.5 | U38: 1.5 | AA38: 1 | AB38: 1 | AE38: 1.5 | AF38: 1.5 | AH38: 1.5 | AI38: 1.5 | AN38: =SUM(I38:AM38) -> 20.125 | AO38: 240000 | AP38: =AN38*AO38 -> 4830000
A39: =A38+1 -> 34 | B39: 박재형 | C39: 770621-1645910 | D39: 배관공 | E39: 010-7763-2808 | F39: 기업 | G39: 박재형 | H39: 565-077418-01-011 | J39: 1.5 | K39: 1.5 | L39: 1 | M39: 1.5 | N39: 1.5 | Q39: 1.5 | R39: 1.5 | S39: 1.5 | T39: 1.5 | U39: 1.5 | AA39: 1 | AB39: 1 | AC39: 1 | AE39: 1.5 | AF39: 1.5 | AG39: 1 | AH39: 1.5 | AI39: 1.5 | AN39: =SUM(I39:AM39) -> 24.5 | AO39: 210000 | AP39: =AN39*AO39 -> 5145000
A40: =A39+1 -> 35 | B40: 박재형 | C40: 780518-1114329 | D40: 공사관리자 | E40: 010-3849-5386 | F40: 국민 | G40: 박재형 | H40: 669502-04-161746 | J40: 1 | L40: 1 | M40: 1.5 | N40: 1.5 | Q40: 1.5 | R40: 1.5 | S40: 1.5 | T40: 1.5 | U40: 1.5 | V40: 1 | AB40: 1.5 | AC40: 1 | AE40: 1.5 | AF40: 1.5 | AG40: 1.5 | AH40: 0.5 | AI40: 1.5 | AN40: =SUM(I40:AM40) -> 22.5 | AO40: 230000 | AP40: =AN40*AO40 -> 5175000
A41: =A40+1 -> 36 | B41: 박태규 | C41: 871003-1850317 | D41: 보통인부 | E41: 010-3562-0647 | F41: 카카오 | G41: 박태규 | H41: 3333-33-8687743 | Q41: 0.75 | R41: 0.375 | S41: 0.625 | T41: 1.5 | U41: 1.5 | AA41: 1 | AB41: 1.5 | AC41: 1 | AE41: 1.5 | AF41: 1.5 | AG41: 1 | AH41: 1.5 | AI41: 1.5 | AN41: =SUM(I41:AM41) -> 15.25 | AO41: 150000 | AP41: =AN41*AO41 -> 2287500
...

Sheet 숙소임차료
A1: 숙소 임차료
A2: No. | B2: 납부일 | C2: 구분 | D2: 품명 | E2: 주소 | F2: 호수 | G2: 수량 | H2: 사용인원 | I2: 임차료 | J2: 비 고
I3: =SUM(I4:I9) -> 5150000 | L3: 입력해야하는 항목 외 수정 금지
A4: 1 | B4: 46081 | C4: KC대납 임대료 | D4: 숙소임대료(2월분) | E4: 경기도 평택시 고덕여염12길 12 201호 | F4: 201호 | G4: 1 | H4: 4 | I4: 900000 | J4: KC 대납 | L4: 납부일
A5: 2 | B5: 46081 | C5: KC대납 임대료 | D5: 숙소임대료(2월분) | E5: 경기도 평택시 고덕여염12길 12 301호 | F5: 301호 | G5: 1 | H5: 4 | I5: 900000 | J5: KC 대납 | L5: 구분
A6: 3 | B6: 46081 | C6: KC대납 임대료 | D6: 숙소임대료(2월분) | E6: 경기도 평택시 고덕여염9길 51 814호 | F6: 814호 | G6: 1 | H6: 2 | I6: 550000 | J6: KC 대납 | L6: 품명
A7: 4 | B7: 46081 | C7: KC대납 임대료 | D7: 숙소임대료(2월분) | E7: 경기도 평택시 고덕여염16길 71 302호 | F7: 302호 | G7: 1 | H7: 5 | I7: 900000 | J7: KC 대납 | L7: 주소
A8: 5 | B8: 46081 | C8: KC대납 임대료 | D8: 숙소임대료(2월분) | E8: 경기도 평택시 고덕여염5길 117-3 202호 | F8: 202호 | G8: 1 | H8: 4 | I8: 1000000 | J8: KC 대납 | L8: 호수
A9: 6 | B9: 46081 | C9: KC대납 임대료 | D9: 숙소임대료(2월분) | E9: 경기도 평택시 고덕여염5길 69-3 302호 | F9: 302호 | G9: 1 | H9: 3 | I9: 900000 | J9: KC 대납 | L9: 수량
A10: 7 | B10: 46081 | C10: 임대료 | D10: 창고임대료(2월분) | E10: 충청남도 천안시 서북구 직산읍 군서2길 20 | F10: 1층 | G10: 1 | I10: 1800000 | L10: 사용인원
A11: 8 | B11: 46081 | C11: 임대료 | D11: 사무실임대료(2월분) | E11: 경기도 평택시 모곡동 447-1 | F11: 806,807호 | G11: 1 | I11: 600000
L12: ■ 구분은 [KC대납 임대료 및 임대료] 이외 항목은 입력금지

Sheet 숙소관리비
A1: 숙소 관리비
A2: No. | B2: 납부일 | C2: 구분 | D2: 품명 | E2: 주소 | F2: 호수 | G2: 수량 | H2: 사용인원 | I2: 임차료 | J2: 비 고
I3: =SUM(I4:I19) -> 1323430
A4: 1 | B4: 46081 | C4: KC대납 관리비 | D4: 숙소수도세(2월분) | E4: 경기도 평택시 고덕여염12길 12 201호 | F4: 201호 | G4: 1 | H4: 4 | I4: 23620 | J4: KC대납
A5: 2 | B5: 46081 | C5: KC대납 관리비 | D5: 숙소수도세(2월분) | E5: 경기도 평택시 고덕여염12길 12 301호 | F5: 301호 | G5: 1 | H5: 4 | I5: 65020 | J5: KC대납
A6: 3 | B6: 46081 | C6: KC대납 관리비 | D6: 숙소수도세(2월분) | E6: 경기도 평택시 고덕여염16길 71 302호 | F6: 302호 | G6: 1 | H6: 5 | I6: 27070 | J6: KC대납
A7: 4 | B7: 46081 | C7: KC대납 관리비 | D7: 숙소수도세(2월분) | E7: 경기도 평택시 고덕여염5길 117-3 202호 | F7: 202호 | G7: 1 | H7: 4 | I7: 17910 | J7: KC대납
A8: 5 | B8: 46081 | C8: KC대납 관리비 | D8: 숙소수도세(2월분) | E8: 경기도 평택시 고덕여염5길 69-3 302호 | F8: 302호 | G8: 1 | H8: 3 | I8: 2400 | J8: KC대납
A9: 6 | B9: 46081 | C9: KC대납 관리비 | D9: 숙소관리비(2월분) | E9: 경기도 평택시 고덕여염9길 51 814호 | F9: 814호 | G9: 1 | H9: 2 | I9: 184730 | J9: KC대납
A10: 7 | B10: 46081 | C10: KC대납 관리비 | D10: 숙소가스료(2월분) | E10: 경기도 평택시 고덕여염12길 12 201호 | F10: 201호 | G10: 1 | H10: 4 | I10: 189420 | J10: KC대납
A11: 8 | B11: 46081 | C11: KC대납 관리비 | D11: 숙소가스료(2월분) | E11: 경기도 평택시 고덕여염12길 12 301호 | F11: 301호 | G11: 1 | H11: 4 | I11: 229490 | J11: KC대납
A12: 9 | B12: 46081 | C12: KC대납 관리비 | D12: 숙소가스료(2월분) | E12: 경기도 평택시 고덕여염16길 71 302호 | F12: 302호 | G12: 1 | H12: 5 | I12: 178850 | J12: KC대납
A13: 10 | B13: 46081 | C13: KC대납 관리비 | D13: 숙소가스료(2월분) | E13: 경기도 평택시 고덕여염5길 117-3 202호 | F13: 202호 | G13: 1 | H13: 4 | I13: 160590 | J13: KC대납
A14: 11 | B14: 46081 | C14: KC대납 관리비 | D14: 숙소가스료(2월분) | E14: 경기도 평택시 고덕여염5길 69-3 302호 | F14: 302호 | G14: 1 | H14: 3 | I14: 124050 | J14: KC대납
A15: 12 | B15: 46081 | C15: KC대납 관리비 | D15: 숙소전기료(2월분) | E15: 경기도 평택시 고덕여염12길 12 201호 | F15: 201호 | G15: 1 | H15: 4 | I15: 26780 | J15: KC대납
... A19: 16 | B19: 46081 | C19: KC대납 관리비 | D19: 숙소전기료(2월분) | E19: 경기도 평택시 고덕여염5길 69-3 302호 | F19: 302호 | G19: 1 | H19: 3 | I19: 18230 | J19: KC대납
A20: 17 | B20: 46081 | C20: 관리비 | D20: 공장전기료(2월분) | E20: 충청남도 천안시 서북구 직산읍 군서2길 20 | F20: 1층 | G20: 1 | I20: 486470
A21: 18 | B21: 46081 | C21: 관리비 | D21: 사무실관리비(2월분) | E21: 경기도 평택시 모곡동 447-1 | F21: 806호 | G21: 1 | I21: 174890
A22: 19 | B22: 46081 | C22: 관리비 | D22: 사무실관리비(2월분) | E22: 경기도 평택시 모곡동 447-1 | F22: 807호 | G22: 1 | I22: 196550

Sheet 식대비용
A1: 식대 비용
A2: No. | B2: 납부일 | C2: 구분 | D2: 품명 | E2: 거래처명 | F2: 수량 | G2: 식수인원 | H2: 단가 | I2: 합 계 | J2: 비 고
I3: =SUM(I4:I9) -> 34472000 | L3: 입력해야하는 항목 외 수정 금지
A4: 1 | B4: 46081 | C4: KC대납 식대 | D4: 기술인및관리자 (현장 식당) | E4: 다모아 한식뷔페 | F4: 1 | G4: 74 | H4: 34472000 | I4: =H4 -> 34472000 | L4: 입력항목
L5: 납부일
L6: 구분
L7: 품명
L8: 거래처명
L9: 수량
L10: 식수인원
L11: 단가
L13: ■ 구분은 [KC대납 식대 및 식대] 이외 항목은 입력금지

Sheet 기타비용
A1: 기타 비용
A2: No. | B2: 구매일 | C2: 구분 | D2: 품명 | E2: 거래처명 | F2: 수량 | G2: 단가 | H2: 합계 | I2: 비고
H3: =SUM(H4:H7) -> 13379584 | K3: 입력해야하는 항목 외 수정 금지
A4: 1 | B4: 46081 | C4: 사무용품 | D4: 현장서류 및 문구류 | E4: 오피스플랜 | F4: 1 | G4: 285100 | H4: =G4 -> 285100 | K4: 입력항목
A5: 2 | B5: 46081 | C5: 소모품비 | D5: 현장 기자재 | E5: 세일종합공구 | F5: 1 | G5: 3190000 | H5: =G5 -> 3190000 | K5: 납부일
A6: 3 | B6: 46081 | C6: 소모품비 | D6: 현장 기자재 (기타) | E6: 영수증 | H6: =G6 -> 0 | K6: 구분
A7: 4 | B7: 46081 | C7: 법인카드 | D7: 법인카드 사용료 | E7: BC카드 | F7: 1 | G7: 9904484 | H7: =G7 -> 9904484 | K7: 품명
K8: 거래처명
K9: 수량
K10: 식수인원
K11: 단가
K13: ■ 구분은 [KC대납 식대 및 식대] 이외 항목은 입력금지

Sheet LOSS
B5: ■ 평택 P4_Ph4 GAS 1공구_FAB LOSS 기록대장_리도 | R5: 25년10월 | S5: 25년11월 | T5: 25년12월 | U5: 26년01월 | V5: 26년02월 | W5: 26년03월 | X5: 26년04월 | Y5: 26년05월 | Z5: 26년06월 | AA5: 26년07월
P6: 작성일 : 2025-12--18 | R6: 193438 | S6: 195968
B7: No. | C7: 공구 | D7: 업체 | E7: 구분 | F7: 내용 | G7: 작업구간 | H7: 날짜 | I7: 시간 | J7: 분 | K7: LOSS M/D | L7: 작업인원 | M7: M/D 합계 | N7: 월 평균단가 | O7: LOSS 금액 | P7: 비 고
B8: 1 | C8: FAB | D8: 리도 | E8: 발주처 요청사항 | F8: 중대재해발생으로 인한 발주처 요청으로 자체 특별교육 및 작업 중단으로 인한 양중 차대 비용 | G8: 현장 전 구간 | H8: 45959 | I8: 09:00~11:00 | J8: 120 | K8: 0.25 | L8: 19 | M8: =K8*L8 -> 4.75 | N8: 193438 | O8: =M8*N8 -> 918830.5 | Q8: 10월
B9: 2 | C9: FAB | D9: 리도 | E9: 발주처 요청사항 | F9: 중대재해발생으로 인한 발주처 요청으로 기술인 특별교육 | G9: 현장 안전교육장, KC 안전교육장 | H9: 25-10-30~31 | I9: 30일12:00~14:00,15:00~17:00 31일07:00~09:00,10:00~12:00 | J9: 960 | K9: 2 | L9: 20 | M9: =K9*L9 -> 40 | N9: 193438 | O9: =M9*N9 -> 7737520 | Q9: 10월
B10: 2025년 10월 LOSS 합계 | M10: =SUM(M8:M9) -> 44.75 | O10: =SUM(O8:O9) -> 8656350.5
B11: 총 합 계 | M11: =M10 -> 44.75 | O11: =O10 -> 8656350.5

Sheet 서명란
B2: 현 장 확 인 | C2: 소 장 | E2: (서명)
C3: 공 사 | E3: (서명)
C4: 공 무 | E4: (서명)
G6: 사 업 부 | H6: Frontier 사업부 GNP 본부장 | I6: BOC 센터장 | J6: Frontier 사업부장
L8: 본 사 | M8: 담 당 | N8: 검 토 | O8: 검 토
Q11: 구 분 | R11: 확 인
Q12: 품 질 | R12: O O O (인)
Q13: 공 무 | R13: O O O (인)

Sheet DIA-INCH
B3: SIZE
B4: A(mm) | C4: Inch
B5: 8A | C5: 0.25
B6: 15A | C6: 0.5
B7: 20A | C7: 0.75
B8: 25A | C8: 1
B9: 32A | C9: 1.25
B10: 40A | C10: 1.5
B11: 50A | C11: 2
B12: 65A | C12: 2.5
B13: 80A | C13: 3
B14: 100A | C14: 4
B15: 110A | C15: 4
B16: 125A | C16: 5
... B27: 550A | C27: 22
