Workbook

Sheet 용역청구서 표지
B4: 용 역 청 구 서
B7: P4 Ph2 GAS&PCW 1공구
C8: S26-001
C14: 2026년 09월
C15: 대성이엔지

Sheet 용역 청구서(갑지)
A1: 용 역 청 구 서
A3: 1 | B3: 공 사 명 | C3: : | D3: ='용역청구서 표지'!$B$7 -> P4 Ph2 GAS&PCW 1공구 | E3: ='용역청구서 표지'!$C$8 -> S26-001
A4: 2 | B4: 공 종 | C4: : | D4: 외주용역(M/M부분)
A5: 3 | B5: 계 약 금 액 | C5: : | D5: =ROUNDUP(E5,0) -> 330000000 | E5: =집계장!J23 -> 330000000 | F5: (VAT 별도)
A6: 4 | B6: 누 계 기 성 금 액 | C6: : | D6: =ROUNDUP(E6,0) -> 330000000 | E6: =E7+E13 -> 330000000 | F6: (VAT 별도)
A7: 5 | B7: 전 회 기 성 금 액 | C7: : | D7: =ROUNDUP(E7,0) -> 130000000 | E7: =집계장!H22 -> 130000000 | F7: (VAT 별도)
A8: 6 | B8: 금 회 기 성 금 액 | C8: : | D8: =ROUNDUP(E8,0) -> 200000000 | E8: =집계장!I23 -> 200000000 | F8: (VAT 별도)
A9: 7 | B9: 선 금 액 | C9: : | D9: =ROUNDUP(E9,0) -> 0 | E9: =집계장!L21 -> 0 | F9: (VAT 별도)
A10: 8 | B10: 선 금 전 회 공 제 | C10: : | D10: =ROUNDUP(E10,0) -> 0 | E10: =집계장!H21 -> 0 | F10: (VAT 별도)
A11: 9 | B11: 선 금 금 회 공 제 | C11: : | D11: =ROUNDUP(E11,0) -> 0 | E11: =집계장!G21 -> 0 | F11: (VAT 별도)
A12: 10 | B12: 선 금 잔 여 금 액 | C12: : | D12: =ROUNDUP(E12,0) -> 0 | E12: =집계장!M21 -> 0 | F12: (VAT 별도)
A13: 11 | B13: 금 회 청 구 금 액 | C13: : | D13: =ROUNDUP(E13,0) -> 200000000 | E13: =집계장!G23 -> 200000000 | F13: (VAT 별도)
A14: 12 | B14: 잔 여 기 성 금 액 | C14: : | D14: =ROUNDUP(E14,0) -> 0 | F14: (VAT 별도)
A15: 13 | B15: 공 정 율 | C15: : | D15: 1
A16: 14 | B16: 청 구 공 사 기 간 | C16: : | D16: 2026. 09. 01 ~ 2026. 09. 30
B18: 위 공사의 하도급에 있어서 공사설계도서, 시방서,품질관리 기준 및 약정대로 시공 되었음을 확인하오며. 만약 귀사의 현장담당의 검사에
B19: 관하여 하자가 발견된 때에는 즉시 실액배상 또는 재 시공할것을 서약하고 이에 기성 청구서를 제출합니다.
B20: 상기건과 관련하여 본 청구 이전까지의 모든 대금은 수령하였음을 확약합니다.
F21: 작 성 일 : 2026 년 09 월 30 일
F23: 상 호 : | G23: 대성이엔지
B24: ※첨 부 : 기성내역서 1부. | F24: 주 소 : | G24: 경기도 파주시 파주읍 주라위길 380
F25: 대표이사 : | G25: 정 성 기 | I25: (인)
D26: ㈜케이씨이앤씨 귀하

Sheet 용역 내역서(을지)
A1: 용 역 내 역 서
A2: P4 Ph4 GAS 1공구 마감공사 | G2: 단위 : 원
A3: 품 명 | B3: 규 격 | C3: 단위 | D3: 단 가 | E3: 금 회 청 구
E4: 수 량 | F4: 금 액 | G4: 비 고
A5: 고급기술인 | B5: S+ | C5: M/M | D5: 1400000 | E5: 1 | F5: =D5*E5 -> 1400000
A6: 고급기술인 | B6: S | C6: M/M | D6: 1200000 | F6: =D6*E6 -> 0
A7: 중급기술인 | B7: A+ | C7: M/M | D7: 1000000 | F7: =D7*E7 -> 0
A8: 중급기술인 | B8: A | C8: M/M | D8: 900000 | F8: =D8*E8 -> 0
A9: 중급기술인 | B9: B+ | C9: M/M | D9: 800000 | F9: =D9*E9 -> 0
A10: 중급기술인 | B10: B | C10: M/M | D10: 700000 | F10: =D10*E10 -> 0
A11: 초급 기술인 | B11: C | C11: M/M | D11: 600000 | F11: =D11*E11 -> 0
A13: 인센티브 | E13: 0.01 | F13: =SUM(F5:F11)*E13 -> 14000
A15: 총 계 | E15: =SUM(E5:E11) -> 1 | F15: =SUM(F5:F13) -> 1414000

Sheet 내역서(을지)
A1: 용 역 내 역 서
A2: =집계장!B2 -> P4 Ph2 GAS&PCW 1공구 | G2: 단위 : 원
A3: 품 명 | B3: 규 격 | C3: 단위 | D3: 단 가 | E3: 금 회 청 구 | G3: 비 고
E4: 수 량 | F4: 금 액
A5: 고급기술인 | B5: S+ | C5: M/M | D5: 1400000 | E5: 8 | F5: =D5*E5 -> 11200000
A6: 고급기술인 | B6: S | C6: M/M | D6: 1200000 | E6: 2 | F6: =D6*E6 -> 2400000
A7: 중급기술인 | B7: A+ | C7: M/M | D7: 1000000 | E7: 6 | F7: =D7*E7 -> 6000000
A8: 중급기술인 | B8: A | C8: M/M | D8: 900000 | E8: 1 | F8: =D8*E8 -> 900000
A9: 중급기술인 | B9: B+ | C9: M/M | D9: 800000 | E9: 4 | F9: =D9*E9 -> 3200000
A10: 중급기술인 | B10: B | C10: M/M | D10: 700000 | E10: 9 | F10: =D10*E10 -> 6300000
A11: 초급기술인 | B11: C | C11: M/M | D11: 600000 | F11: =D11*E11 -> 0
A27: 총 계 | E27: =SUM(E5:E11) -> 30 | F27: =SUM(F5:F26) -> 30000000

Sheet 집계장
B2: ='용역청구서 표지'!$B$7 -> P4 Ph2 GAS&PCW 1공구
M3: ='용역청구서 표지'!$C$15 -> 대성이엔지
B4: 구분 | C4: 내역 | D4: 단위 | E4: 수량 | F4: 단가 | G4: 합계 | H4: 전회기성 | I4: 금회기성 | J4: 누계기성 | K4: 비 고
B5: 1. 물량 | C5: WELDING POINT | D5: D/I | E5: =SUM('물량 내역서'!$J$6:$J$28) -> 1094 | F5: =G5/E5 -> 475000 | G5: =SUM('물량 내역서'!$K$6:$K$28) -> 519650000 | H5: 4371662500 | I5: =G5 -> 519650000 | J5: =H5+I5 -> 4891312500
C6: VALVE 설치비 | D6: EA | E6: =SUM('물량 내역서'!$J$29:$J$51) -> 0 | F6: =G6/E6 -> #DIV/0! | G6: =SUM('물량 내역서'!$K$29:$K$51) -> 0 | H6: 0 | I6: =G6 -> 0 | J6: =H6+I6 -> 0
C7: 인원 실투입 | D7: M/D | E7: ='근로내역 (09월)'!AN162 -> 0 | F7: 0 | G7: =E7*F7 -> 0 | H7: 0 | I7: =G7 -> 0 | J7: =H7+I7 -> 0
B8: 2. 돌관비 | C8: 0.08 | D8: 式 | G8: =ROUND(G5*$C$8,) -> 41572000 | H8: 349733000 | I8: =G8 -> 41572000 | J8: =H8+I8 -> 391305000
B9: 소 계 | C9: 물량 | G9: =SUM(G5:G8) -> 561222000 | H9: =SUM(H5:H8) -> 4721395500 | I9: =SUM(I5:I8) -> 561222000 | J9: =SUM(J5:J8) -> 5282617500
B10: 2. 노무비 | C10: 직접노무비 | D10: 式 | E10: ='근로내역 (09월)'!AN150 -> 3892.875 | F10: =G10/E10 -> 197017.63 | G10: ='근로내역 (09월)'!AP150 -> 766965000 | H10: 3748363125 | I10: =G10 -> 766965000 | J10: =H10+I10 -> 4515328125
B11: 3. 숙소 및 식대 | C11: 임대료+관리비 | D11: 式 | E11: 1 | F11: =G11/E11 -> 53718770 | G11: =숙소임차료!I3+숙소관리비!I3 -> 53718770 | H11: 277467450 | I11: =G11 -> 53718770 | J11: =H11+I11 -> 331186220
C12: 식대 | D12: 式 | E12: 1 | F12: =G12/E12 -> 50466045 | G12: =식대비용!I3 -> 50466045 | H12: 241996500 | I12: =G12 -> 50466045 | J12: =H12+I12 -> 292462545
B13: 4. 기타 공제 내역 | D13: 式 | F13: 0 | G13: =E13*F13 -> 0 | I13: =G13 -> 0 | J13: =H13+I13 -> 0
B14: 소 계 | C14: 공제 | G14: =SUM(G10:G13) -> 871149815 | H14: =SUM(H10:H13) -> 4267827075 | I14: =G14 -> 871149815 | J14: =H14+I14 -> 5138976890 | N14: =+I12+I11 -> 104184815
B15: 합 계 | C15: 기성 (물량-공제) | G15: =G9-G14 -> -309927815 | H15: =H9-H14 -> 453568425 | I15: =G15 -> -309927815 | J15: =H15+I15 -> 143640610
B16: 5. 유보금 | C16: 기성금*XX% | D16: 式 | G16: -509927815 | H16: 323568425 | I16: =G16 -> -509927815 | J16: =H16+I16 -> -186359390
B17: 6. 유보금 차액 | C17: 전회 누계유보금 | D17: 式 | I17: =G17 -> 0 | J17: =H17+I17 -> 0
B18: 7. NEGO | C18: NEGO | D18: 式 | I18: =G18 -> 0
B19: 총 계 | C19: 최종기성 | G19: =G15-G16-G17-G18 -> 200000000 | H19: =H15-H16-H17-H18 -> 130000000 | I19: =I15-I16-I17-I18 -> 200000000 | J19: =J15-J16-J17-J18 -> 330000000
B20: 선급금 | C20: 선수공제 | D20: 式 | G20: 0 | I20: =G20 -> 0 | J20: =H20+I20 -> 0 | L20: 지급 선급금 | M20: 선급금 차액
C21: 단수정리 | D21: 式 | G21: =ROUNDDOWN(G20,-5) -> 0 | I21: =G21 -> 0 | J21: =H21+I21 -> 0 | K21: 만 단위 이하 절사
B22: 공제 후 실 지급액 | G22: =G19-G21 -> 200000000 | H22: =H19-H21 -> 130000000 | I22: =G22 -> 200000000 | J22: =H22+I22 -> 330000000
B23: 세금계산서 기준 | G23: =ROUNDDOWN(G22,-5) -> 200000000 | H23: =ROUNDDOWN(H22,-5) -> 130000000 | I23: =G23 -> 200000000 | J23: =ROUNDDOWN(J22,-5) -> 330000000 | K23: 만 단위 이하 절사
B24: TERMS AND CONDITIONS | E24: NOTE
B25: 1. 납 기 : KCEnC 지정 납기로 별도 협의 하에 결정하는 것으로 함.
B26: 2. 지불조건 : KCEnC 지불 조건에 따름.
B27: 3. 유효기간 : 기성 제출일로 부터 30일 이내

Sheet 물량 내역서
A1: 2026년 (09)월 물량 내역서
A2: ='용역청구서 표지'!$B$7 -> P4 Ph2 GAS&PCW 1공구 | M2: 단위 : 원
A3: 품 명 | B3: 규 격 | C3: 단위 | D3: W/P 수량 | E3: 단 가 | F3: 계 약 내 역 | H3: 전 회 누 계 물 량 | J3: 금 회 물 량 | L3: 누 계 물 량
F4: D/I 수량 | G4: 금액 | H4: D/I 수량 | I4: 금액 | J4: D/I 수량 | K4: 금액 | L4: D/I 수량 | M4: 금액
A6: WEDING POINT | B6: 8A | C6: POINT | D6: 0 | E6: 475000 | F6: =L6 -> 0 | G6: =M6 -> 0 | J6: =$D6*'DIA-INCH'!$C5 -> 0 | K6: =$E6*$J6 -> 0 | L6: =H6+J6 -> 0 | M6: =I6+K6 -> 0
A7: WEDING POINT | B7: 15A | C7: POINT | D7: 0 | E7: 475000 | F7: =L7 -> 0 | G7: =M7 -> 0 | J7: =$D7*'DIA-INCH'!$C6 -> 0 | K7: =$E7*$J7 -> 0 | L7: =H7+J7 -> 0 | M7: =I7+K7 -> 0
A8: WEDING POINT | B8: 20A | C8: POINT | D8: 0 | E8: 475000 | F8: =L8 -> 0 | G8: =M8 -> 0 | J8: =$D8*'DIA-INCH'!$C7 -> 0 | K8: =$E8*$J8 -> 0 | L8: =H8+J8 -> 0 | M8: =I8+K8 -> 0
A9: WEDING POINT | B9: 25A | C9: POINT | D9: 238 | E9: 475000 | F9: =L9 -> 1056 | G9: =M9 -> 501600000 | H9: 818 | I9: 388550000 | J9: =$D9*'DIA-INCH'!$C8 -> 238 | K9: =$E9*$J9 -> 113050000 | L9: =H9+J9 -> 1056 | M9: =I9+K9 -> 501600000
A10: WEDING POINT | B10: 32A | C10: POINT | D10: 0 | E10: 475000 | F10: =L10 -> 0 | G10: =M10 -> 0 | H10: 0 | I10: 0 | J10: =$D10*'DIA-INCH'!$C9 -> 0 | K10: =$E10*$J10 -> 0 | L10: =H10+J10 -> 0 | M10: =I10+K10 -> 0
A11: WEDING POINT | B11: 40A | C11: POINT | D11: 50 | E11: 475000 | F11: =L11 -> 904.5 | G11: =M11 -> 429637500 | H11: 829.5 | I11: 394012500 | J11: =$D11*'DIA-INCH'!$C10 -> 75 | K11: =$E11*$J11 -> 35625000 | L11: =H11+J11 -> 904.5 | M11: =I11+K11 -> 429637500
A12: WEDING POINT | B12: 50A | C12: POINT | D12: 44 | E12: 475000 | F12: =L12 -> 614 | G12: =M12 -> 291650000 | H12: 526 | I12: 249850000 | J12: =$D12*'DIA-INCH'!$C11 -> 88 | K12: =$E12*$J12 -> 41800000 | L12: =H12+J12 -> 614 | M12: =I12+K12 -> 291650000
A13: WEDING POINT | B13: 65A | C13: POINT | D13: 80 | E13: 475000 | F13: =L13 -> 1070 | G13: =M13 -> 508250000 | H13: 870 | I13: 413250000 | J13: =$D13*'DIA-INCH'!$C12 -> 200 | K13: =$E13*$J13 -> 95000000 | L13: =H13+J13 -> 1070 | M13: =I13+K13 -> 508250000
A14: WEDING POINT | B14: 80A | C14: POINT | D14: 41 | E14: 475000 | F14: =L14 -> 534 | G14: =M14 -> 253650000 | H14: 411 | I14: 195225000 | J14: =$D14*'DIA-INCH'!$C13 -> 123 | K14: =$E14*$J14 -> 58425000 | L14: =H14+J14 -> 534 | M14: =I14+K14 -> 253650000
A15: WEDING POINT | B15: 100A | C15: POINT | D15: 33 | E15: 475000 | F15: =L15 -> 852 | G15: =M15 -> 404700000 | H15: 720 | I15: 342000000 | J15: =$D15*'DIA-INCH'!$C14 -> 132 | K15: =$E15*$J15 -> 62700000 | L15: =H15+J15 -> 852 | M15: =I15+K15 -> 404700000
A16: WEDING POINT | B16: 110A | C16: POINT | D16: 0 | E16: 475000 | F16: =L16 -> 0 | G16: =M16 -> 0 | H16: 0 | I16: 0 | J16: =$D16*'DIA-INCH'!$C15 -> 0 | K16: =$E16*$J16 -> 0 | L16: =H16+J16 -> 0 | M16: =I16+K16 -> 0
A17: WEDING POINT | B17: 125A | C17: POINT | D17: 38 | E17: 475000 | F17: =L17 -> 3355 | G17: =M17 -> 1593625000 | H17: 3165 | I17: 1503375000 | J17: =$D17*'DIA-INCH'!$C16 -> 190 | K17: =$E17*$J17 -> 90250000 | L17: =H17+J17 -> 3355 | M17: =I17+K17 -> 1593625000
A18: WEDING POINT | B18: 150A | C18: POINT | D18: 0 | E18: 475000 | F18: =L18 -> 48 | G18: =M18 -> 22800000 | H18: 48 | I18: 22800000 | J18: =$D18*'DIA-INCH'!$C17 -> 0 | K18: =$E18*$J18 -> 0 | L18: =H18+J18 -> 48 | M18: =I18+K18 -> 22800000
A19: WEDING POINT | B19: 175A | C19: POINT | D19: 0 | E19: 475000 | F19: =L19 -> 0 | G19: =M19 -> 0 | H19: 0 | I19: 0 | J19: =$D19*'DIA-INCH'!$C18 -> 0 | K19: =$E19*$J19 -> 0 | L19: =H19+J19 -> 0 | M19: =I19+K19 -> 0
A20: WEDING POINT | B20: 200A | C20: POINT | D20: 6 | E20: 475000 | F20: =L20 -> 1584 | G20: =M20 -> 752400000 | H20: 1536 | I20: 729600000 | J20: =$D20*'DIA-INCH'!$C19 -> 48 | K20: =$E20*$J20 -> 22800000 | L20: =H20+J20 -> 1584 | M20: =I20+K20 -> 752400000
... A23: WEDING POINT | B23: 300A | C23: POINT | D23: 0 | E23: 475000 | F23: =L23 -> 120 | G23: =M23 -> 57000000 | H23: 120 | I23: 57000000 | J23: =$D23*'DIA-INCH'!$C22 -> 0 | K23: =$E23*$J23 -> 0 | L23: =H23+J23 -> 120 | M23: =I23+K23 -> 57000000
A24: WEDING POINT | B24: 350A | C24: POINT | D24: 0 | E24: 475000 | F24: =L24 -> 0 | G24: =M24 -> 0 | J24: =$D24*'DIA-INCH'!$C23 -> 0 | K24: =$E24*$J24 -> 0 | L24: =H24+J24 -> 0 | M24: =I24+K24 -> 0
A25: WEDING POINT | B25: 400A | C25: POINT | D25: 0 | E25: 475000 | F25: =L25 -> 0 | G25: =M25 -> 0 | J25: =$D25*'DIA-INCH'!$C24 -> 0 | K25: =$E25*$J25 -> 0 | L25: =H25+J25 -> 0 | M25: =I25+K25 -> 0
A26: WEDING POINT | B26: 450A | C26: POINT | D26: 0 | E26: 475000 | F26: =L26 -> 0 | G26: =M26 -> 0 | J26: =$D26*'DIA-INCH'!$C25 -> 0 | K26: =$E26*$J26 -> 0 | L26: =H26+J26 -> 0 | M26: =I26+K26 -> 0
A27: WEDING POINT | B27: 500A | C27: POINT | D27: 0 | E27: 475000 | F27: =L27 -> 0 | G27: =M27 -> 0 | J27: =$D27*'DIA-INCH'!$C26 -> 0 | K27: =$E27*$J27 -> 0 | L27: =H27+J27 -> 0 | M27: =I27+K27 -> 0
A28: WEDING POINT | B28: 550A | C28: POINT | D28: 0 | E28: 475000 | F28: =L28 -> 0 | G28: =M28 -> 0 | J28: =$D28*'DIA-INCH'!$C27 -> 0 | K28: =$E28*$J28 -> 0 | L28: =H28+J28 -> 0 | M28: =I28+K28 -> 0
A29: VALVE 설치비 | B29: 8A | C29: EA | D29: 0 | E29: =$E$32*'DIA-INCH'!$C5 -> 12500 | F29: =L29 -> 0 | G29: =M29 -> 0 | J29: =D29 -> 0 | K29: =$J29*$E29 -> 0 | L29: =H29+J29 -> 0 | M29: =I29+K29 -> 0
A30: VALVE 설치비 | B30: 15A | C30: EA | E30: =$E$32*'DIA-INCH'!$C6 -> 25000 | F30: =L30 -> 0 | G30: =M30 -> 0 | J30: =D30 -> 0 | K30: =$J30*$E30 -> 0 | L30: =H30+J30 -> 0 | M30: =I30+K30 -> 0
A31: VALVE 설치비 | B31: 20A | C31: EA | E31: =$E$32*'DIA-INCH'!$C7 -> 37500 | F31: =L31 -> 0 | G31: =M31 -> 0 | J31: =D31 -> 0 | K31: =$J31*$E31 -> 0 | L31: =H31+J31 -> 0 | M31: =I31+K31 -> 0
A32: VALVE 설치비 | B32: 25A | C32: EA | E32: 50000 | F32: =L32 -> 0 | G32: =M32 -> 0 | J32: =D32 -> 0 | K32: =$J32*$E32 -> 0 | L32: =H32+J32 -> 0 | M32: =I32+K32 -> 0
A33: VALVE 설치비 | B33: 32A | C33: EA | E33: =$E$32*'DIA-INCH'!$C9 -> 62500 | F33: =L33 -> 0 | G33: =M33 -> 0 | J33: =D33 -> 0 | K33: =$J33*$E33 -> 0 | L33: =H33+J33 -> 0 | M33: =I33+K33 -> 0
A34: VALVE 설치비 | B34: 40A | C34: EA | E34: =$E$32*'DIA-INCH'!$C10 -> 75000 | F34: =L34 -> 0 | G34: =M34 -> 0 | J34: =D34 -> 0 | K34: =$J34*$E34 -> 0 | L34: =H34+J34 -> 0 | M34: =I34+K34 -> 0
A35: VALVE 설치비 | B35: 50A | C35: EA | E35: =$E$32*'DIA-INCH'!$C11 -> 100000 | F35: =L35 -> 0 | G35: =M35 -> 0 | J35: =D35 -> 0 | K35: =$J35*$E35 -> 0 | L35: =H35+J35 -> 0 | M35: =I35+K35 -> 0
A36: VALVE 설치비 | B36: 65A | C36: EA | E36: =$E$32*'DIA-INCH'!$C12 -> 125000 | F36: =L36 -> 0 | G36: =M36 -> 0 | J36: =D36 -> 0 | K36: =$J36*$E36 -> 0 | L36: =H36+J36 -> 0 | M36: =I36+K36 -> 0
A37: VALVE 설치비 | B37: 80A | C37: EA | E37: =$E$32*'DIA-INCH'!$C13 -> 150000 | F37: =L37 -> 0 | G37: =M37 -> 0 | J37: =D37 -> 0 | K37: =$J37*$E37 -> 0 | L37: =H37+J37 -> 0 | M37: =I37+K37 -> 0
A38: VALVE 설치비 | B38: 100A | C38: EA | E38: =$E$32*'DIA-INCH'!$C14 -> 200000 | F38: =L38 -> 0 | G38: =M38 -> 0 | J38: =D38 -> 0 | K38: =$J38*$E38 -> 0 | L38: =H38+J38 -> 0 | M38: =I38+K38 -> 0
A39: VALVE 설치비 | B39: 110A | C39: EA | E39: =$E$32*'DIA-INCH'!$C15 -> 200000 | F39: =L39 -> 0 | G39: =M39 -> 0 | J39: =D39 -> 0 | K39: =$J39*$E39 -> 0 | L39: =H39+J39 -> 0 | M39: =I39+K39 -> 0
A40: VALVE 설치비 | B40: 125A | C40: EA | E40: =$E$32*'DIA-INCH'!$C16 -> 250000 | F40: =L40 -> 0 | G40: =M40 -> 0 | J40: =D40 -> 0 | K40: =$J40*$E40 -> 0 | L40: =H40+J40 -> 0 | M40: =I40+K40 -> 0
A41: VALVE 설치비 | B41: 150A | C41: EA | E41: =$E$32*'DIA-INCH'!$C17 -> 300000 | F41: =L41 -> 0 | G41: =M41 -> 0 | J41: =D41 -> 0 | K41: =$J41*$E41 -> 0 | L41: =H41+J41 -> 0 | M41: =I41+K41 -> 0
A42: VALVE 설치비 | B42: 175A | C42: EA | E42: =$E$32*'DIA-INCH'!$C18 -> 350000 | F42: =L42 -> 0 | G42: =M42 -> 0 | J42: =D42 -> 0 | K42: =$J42*$E42 -> 0 | L42: =H42+J42 -> 0 | M42: =I42+K42 -> 0
A43: VALVE 설치비 | B43: 200A | C43: EA | E43: =$E$32*'DIA-INCH'!$C19 -> 400000 | F43: =L43 -> 0 | G43: =M43 -> 0 | J43: =D43 -> 0 | K43: =$J43*$E43 -> 0 | L43: =H43+J43 -> 0 | M43: =I43+K43 -> 0
...

Sheet 근로내역 (09월)
A1: 2026년 ( 09 )월 일용 노무비명세서 | AH1: 현장명 | AM1: ='용역청구서 표지'!$B$7 -> P4 Ph2 GAS&PCW 1공구
AH2: 현장소장 | AM2: 조 수 원
AH3: 잡코드 | AM3: ='용역청구서 표지'!$C$8 -> S26-001
A5: 번호 | B5: 성명 | C5: 주민등록번호 | D5: 직종 | E5: 연락처(H.P) | F5: 은행명 | G5: 예금주 | H5: 계좌번호 | I5: 1 | J5: 2 | K5: 3 | L5: 4 | M5: 5 | N5: 6 | O5: 7 | P5: 8 | Q5: 9 | R5: 10 | S5: 11 | T5: 12 | U5: 13 | V5: 14 | W5: 15 | X5: 16 | Y5: 17 | Z5: 18 | AA5: 19 | AB5: 20 | AC5: 21 | AD5: 22 | AE5: 23 | AF5: 24 | AG5: 25 | AH5: 26 | AI5: 27 | AJ5: 28 | AK5: 29 | AL5: 30 | AM5: 31 | AN5: 공수 | AO5: 단가 | AP5: 총액
A6: 1 | B6: 강경호 | C6: 931011-1072918 | D6: 공사보조 | E6: 010-5396-5444 | F6: 신한 | G6: 강경호 | H6: 110-371-147243 | I6: 2 | J6: 2 | K6: 1.75 | L6: 2 | O6: 2 | P6: 2 | Q6: 2 | R6: 2 | S6: 2 | V6: 1 | W6: 2 | X6: 2 | Y6: 2 | Z6: 2 | AC6: 2 | AD6: 1 | AJ6: 2 | AK6: 2 | AL6: 2 | AN6: =SUM(I6:AM6) -> 35.75 | AO6: 180000 | AP6: =AN6*AO6 -> 6435000
A7: 2 | B7: 강동우 | C7: 810127-1026118 | D7: 공사보조 | E7: 010-5289-5546 | F7: 기업 | G7: 강동우 | H7: 186-094740-01-017 | I7: 2 | J7: 2 | K7: 2 | L7: 2 | O7: 2 | P7: 2 | Q7: 2 | R7: 2 | S7: 2 | V7: 0.5 | W7: 1.5 | X7: 1 | Y7: 1.5 | Z7: 1 | AC7: 1.5 | AD7: 1 | AE7: 0.5 | AJ7: 1 | AK7: 0.5 | AL7: 1 | AN7: =SUM(I7:AM7) -> 29 | AO7: 240000 | AP7: =AN7*AO7 -> 6960000
A8: 3 | B8: 한상웅 | C8: 710125-1030325 | D8: 보통인부 | E8: 010-4605-7551 | F8: 신한 | G8: 한상웅 | H8: 110-102-897589 | I8: 1.5 | J8: 1.5 | AN8: =SUM(I8:AM8) -> 3 | AO8: 170000 | AP8: =AN8*AO8 -> 510000
A9: 4 | B9: 강인기 | C9: 020528-3912419 | D9: 보통인부 | E9: 010-9325-6120 | F9: 농협 | G9: 강인기 | H9: 352-1618-5074-53 | I9: 2 | J9: 2 | K9: 2 | L9: 2 | O9: 2 | P9: 2 | Q9: 2 | R9: 2 | S9: 2 | V9: 1 | W9: 2 | X9: 2 | Y9: 2 | Z9: 2 | AC9: 2 | AD9: 2 | AJ9: 2 | AK9: 2 | AL9: 2 | AN9: =SUM(I9:AM9) -> 37 | AO9: 160000 | AP9: =AN9*AO9 -> 5920000
A10: 5 | B10: 강희수 | C10: 730210-1029411 | D10: 도비공 | E10: 010-9561-6101 | F10: 신한 | G10: 강희수 | H10: 110-490-486591 | I10: 1.5 | J10: 1.5 | K10: 1 | L10: 1 | O10: 1 | P10: 1.5 | Q10: 1 | R10: 1.5 | S10: 1 | V10: 1 | W10: 1.5 | X10: 1 | Y10: 1.5 | Z10: 0.5 | AC10: 1.5 | AD10: 1 | AE10: 0.5 | AJ10: 1 | AK10: 1.5 | AL10: 1 | AN10: =SUM(I10:AM10) -> 23 | AO10: 210000 | AP10: =AN10*AO10 -> 4830000
A11: 6 | B11: 권국진 | C11: 690215-1017539 | D11: 보통인부 | E11: 010-4346-0215 | F11: 국민 | G11: 권국진 | H11: 357-21-0173-310 | I11: 2 | J11: 2 | K11: 2 | L11: 2 | O11: 2 | P11: 2 | Q11: 2 | R11: 2 | S11: 2 | V11: 1 | W11: 2 | X11: 2 | Y11: 2 | Z11: 2 | AC11: 2 | AD11: 2 | AJ11: 2 | AK11: 2 | AL11: 2 | AN11: =SUM(I11:AM11) -> 37 | AO11: 170000 | AP11: =AN11*AO11 -> 6290000
A12: 7 | B12: 김대욱 | C12: 890712-1058810 | D12: 용접공 | E12: 010-3646-9962 | F12: 신한 | G12: 김대욱 | H12: 110-248-997659 | I12: 2 | J12: 2 | K12: 2 | L12: 2 | O12: 2 | P12: 2 | Q12: 2 | R12: 2 | S12: 2 | V12: 1 | W12: 2 | X12: 2 | Y12: 2 | Z12: 2 | AC12: 2 | AD12: 2 | AJ12: 2 | AK12: 2 | AL12: 2 | AN12: =SUM(I12:AM12) -> 37 | AO12: 240000 | AP12: =AN12*AO12 -> 8880000
A13: 8 | B13: 김대환 | C13: 861013-1652817 | D13: 배관공 | E13: 010-7523-3699 | F13: 농협 | G13: 김대환 | H13: 669-02-331305 | I13: 2 | J13: 2 | K13: 2 | L13: 2 | O13: 2 | P13: 2 | Q13: 2 | R13: 2 | S13: 2 | V13: 1 | W13: 2 | X13: 2 | Y13: 2 | Z13: 2 | AC13: 2 | AD13: 2 | AJ13: 2 | AK13: 2 | AL13: 2 | AN13: =SUM(I13:AM13) -> 37 | AO13: 240000 | AP13: =AN13*AO13 -> 8880000
A14: 9 | B14: 김재일 | C14: 700429-1846715 | D14: 보통인부 | E14: 010-2700-6160 | F14: 토스뱅크 | G14: 김재일 | H14: 1002-5523-2883 | I14: 1.5 | J14: 1.5 | K14: 1 | L14: 1 | AN14: =SUM(I14:AM14) -> 5 | AO14: 170000 | AP14: =AN14*AO14 -> 850000
A15: 10 | B15: 김택수 | C15: 751221-1663222 | D15: 보통인부 | E15: 010-7942-1751 | F15: 우리 | G15: 김택수 | H15: 1002-339-327014 | I15: 2 | J15: 2 | K15: 2 | L15: 2 | AN15: =SUM(I15:AM15) -> 8 | AO15: 160000 | AP15: =AN15*AO15 -> 1280000
A16: 11 | B16: 김무열 | C16: 690417-1041629 | D16: 배관공 | E16: 010-4797-4619 | F16: 농협 | G16: 김무열 | H16: 170189-56-105161 | I16: 1.5 | J16: 1.5 | K16: 1 | L16: 1 | M16: 1 | O16: 1 | P16: 1.5 | Q16: 1 | R16: 1.5 | S16: 1 | T16: 0.5 | V16: 1 | W16: 1.5 | X16: 1 | Y16: 1.5 | Z16: 1 | AA16: 1 | AC16: 1.5 | AD16: 1 | AE16: 1 | AJ16: 1 | AK16: 1 | AL16: 2 | AN16: =SUM(I16:AM16) -> 27 | AO16: 240000 | AP16: =AN16*AO16 -> 6480000
A17: 12 | B17: 김민재 | C17: 940217-1474315 | D17: 배관공 | E17: 010-9961-0647 | F17: 국민 | G17: 김민재 | H17: 240801-04-477184 | I17: 1.5 | J17: 1.5 | K17: 1 | L17: 1 | M17: 1 | O17: 1 | P17: 1.5 | Q17: 1 | R17: 1.5 | S17: 1 | T17: 1 | V17: 1 | W17: 1.5 | X17: 1 | Y17: 1.5 | Z17: 1 | AA17: 1 | AC17: 1.5 | AD17: 1 | AE17: 1 | AJ17: 1 | AK17: 1.5 | AL17: 1 | AN17: =SUM(I17:AM17) -> 27 | AO17: 230000 | AP17: =AN17*AO17 -> 6210000
A18: 13 | B18: 김상수 | C18: 760616-1535318 | D18: 보통인부 | E18: 010-4812-3459 | F18: 농협 | G18: 김상수 | H18: 351-0468-2919-93 | I18: 1.5 | J18: 1.5 | K18: 1 | L18: 1 | M18: 1 | O18: 1 | P18: 1.5 | Q18: 1 | R18: 1.5 | S18: 1 | V18: 1 | W18: 1.5 | X18: 1 | Y18: 1.5 | Z18: 1 | AA18: 1 | AC18: 1.5 | AD18: 1 | AE18: 1 | AJ18: 1 | AK18: 1.5 | AL18: 1 | AN18: =SUM(I18:AM18) -> 26 | AO18: 160000 | AP18: =AN18*AO18 -> 4160000
A19: 14 | B19: 김세관 | C19: 860815-1912515 | D19: 도비공 | E19: 010-4171-9729 | F19: 카카오뱅크 | G19: 김세관 | H19: 3333-08-5239539 | I19: 2 | J19: 2 | K19: 2 | L19: 2 | O19: 2 | P19: 2 | Q19: 2 | R19: 2 | S19: 2 | W19: 1.5 | X19: 1 | Y19: 1.5 | Z19: 1 | AA19: 1 | AC19: 1.5 | AD19: 1 | AE19: 0.5 | AJ19: 1 | AK19: 1.5 | AL19: 1 | AN19: =SUM(I19:AM19) -> 30.5 | AO19: 200000 | AP19: =AN19*AO19 -> 6100000
A20: 15 | B20: 김세영 | C20: 710324-1026013 | D20: 보통인부 | E20: 010-9087-3534 | F20: 신한 | G20: 김세영 | H20: 110-461-373992 | I20: 1.5 | J20: 1.5 | K20: 1 | L20: 1 | M20: 1 | O20: 1 | P20: 1.5 | Q20: 1 | R20: 1.5 | S20: 1 | T20: 1 | V20: 1 | W20: 1.5 | X20: 1 | Z20: 1 | AA20: 1 | AC20: 1.5 | AD20: 1 | AE20: 1 | AJ20: 1 | AK20: 1 | AL20: 1 | AN20: =SUM(I20:AM20) -> 25 | AO20: 160000 | AP20: =AN20*AO20 -> 4000000
A21: 16 | B21: 김세한 | C21: 721013-1067215 | D21: 보통인부 | E21: 010-8848-5060 | F21: 하나 | G21: 김세한 | H21: 298-910970-10507 | I21: 2 | J21: 2 | K21: 2 | L21: 2 | O21: 2 | P21: 2 | Q21: 2 | R21: 2 | S21: 2 | V21: 1 | W21: 2 | X21: 2 | Y21: 2 | Z21: 2 | AC21: 2 | AD21: 2 | AJ21: 2 | AK21: 2 | AL21: 2 | AN21: =SUM(I21:AM21) -> 37 | AO21: 160000 | AP21: =AN21*AO21 -> 5920000
A22: 17 | B22: 김슬기 | C22: 940216-2476212 | D22: 보통인부 | E22: 010-4565-0216 | F22: 카카오뱅크 | G22: 김슬기 | H22: 3333-26-1255102 | I22: 1.5 | J22: 1.5 | K22: 1 | L22: 1 | M22: 1 | O22: 1 | P22: 1.5 | Q22: 1 | R22: 1.5 | V22: 1 | W22: 1.5 | Y22: 1.5 | Z22: 1 | AA22: 1 | AC22: 1.5 | AD22: 1 | AJ22: 1 | AK22: 1.5 | AL22: 1 | AN22: =SUM(I22:AM22) -> 23 | AO22: 150000 | AP22: =AN22*AO22 -> 3450000
A23: 18 | B23: 김영도 | C23: 701220-1623625 | D23: 보통인부 | E23: 010-9839-3839 | F23: 국민 | G23: 김영도 | H23: 916401-01-366618 | I23: 1.5 | J23: 1.5 | K23: 1 | L23: 1 | O23: 1 | P23: 1.5 | Q23: 1 | R23: 1.5 | S23: 1 | T23: 1 | V23: 1 | W23: 1.5 | X23: 1 | Z23: 1 | AA23: 1 | AC23: 1.5 | AD23: 1 | AE23: 1 | AJ23: 1 | AK23: 1.5 | AL23: 1 | AN23: =SUM(I23:AM23) -> 24.5 | AO23: 160000 | AP23: =AN23*AO23 -> 3920000
A24: 19 | B24: 김용기 | C24: 860712-1036817 | D24: 배관공 | E24: 010-2222-3295 | F24: 국민 | G24: 김용기 | H24: 442802-01-189872 | I24: 2 | J24: 2 | K24: 2 | L24: 2 | O24: 2 | P24: 2 | Q24: 2 | R24: 2 | S24: 2 | V24: 1 | W24: 0.5 | Y24: 2 | Z24: 2 | AC24: 2 | AD24: 2 | AJ24: 2 | AK24: 2 | AL24: 2 | AN24: =SUM(I24:AM24) -> 33.5 | AO24: 220000 | AP24: =AN24*AO24 -> 7370000
A25: 20 | B25: 김의찬 | C25: 810916-1090421 | D25: 보통인부 | E25: 010-7748-9382 | F25: 국민 | G25: 김의찬 | H25: 121802-04-157456 | I25: 2 | J25: 2 | K25: 2 | L25: 2 | O25: 2 | P25: 2 | Q25: 2 | R25: 2 | S25: 2 | V25: 1 | W25: 2 | X25: 2 | Y25: 2 | Z25: 2 | AC25: 2 | AD25: 2 | AJ25: 2 | AK25: 2 | AL25: 2 | AN25: =SUM(I25:AM25) -> 37 | AO25: 170000 | AP25: =AN25*AO25 -> 6290000
A26: 21 | B26: 김재윤 | C26: 861216-1157613 | D26: 용접공 | E26: 010-3955-1110 | F26: 신한 | G26: 김재윤 | H26: 110-305-768530 | I26: 2 | J26: 2 | K26: 2 | L26: 2 | O26: 2 | P26: 2 | Q26: 2 | R26: 2 | S26: 2 | V26: 1 | W26: 2 | X26: 2 | Y26: 2 | Z26: 2 | AC26: 2 | AD26: 2 | AJ26: 2 | AK26: 2 | AL26: 2 | AN26: =SUM(I26:AM26) -> 37 | AO26: 250000 | AP26: =AN26*AO26 -> 9250000
A27: 22 | B27: 정의승 | C27: 881019-1199017 | D27: 배관공 | E27: 010-2486-1411 | F27: 국민 | G27: 정의승 | H27: 91024861411 | I27: 2 | K27: 2 | L27: 2 | AN27: =SUM(I27:AM27) -> 6 | AO27: 230000 | AP27: =AN27*AO27 -> 1380000
A28: 23 | B28: 김정규 | C28: 821122-1047416 | D28: 보통인부 | E28: 010-3240-6194 | F28: 국민 | G28: 김정규 | H28: 757101-04-044154 | I28: 2 | J28: 2 | K28: 2 | L28: 2 | O28: 2 | P28: 2 | Q28: 2 | R28: 2 | S28: 2 | V28: 1 | W28: 2 | X28: 2 | Y28: 2 | Z28: 2 | AJ28: 0.25 | AN28: =SUM(I28:AM28) -> 27.25 | AO28: 160000 | AP28: =AN28*AO28 -> 4360000
A29: 24 | B29: 김정인 | C29: 911224-1235320 | D29: 용접공 | E29: 010-3175-7994 | F29: 기업 | G29: 김정인 | H29: 010-3175-7994 | I29: 1 | J29: 2 | K29: 2 | L29: 2 | O29: 2 | P29: 2 | Q29: 2 | R29: 2 | S29: 2 | V29: 1 | W29: 2 | X29: 2 | Y29: 2 | Z29: 2 | AC29: 2 | AD29: 2 | AJ29: 2 | AK29: 2 | AL29: 2 | AN29: =SUM(I29:AM29) -> 36 | AO29: 250000 | AP29: =AN29*AO29 -> 9000000
A30: 25 | B30: 김종완 | C30: 740404-1471013 | D30: 배관공 | E30: 010-9983-3546 | F30: 우리 | G30: 김종완 | H30: 1006-001-448823 | I30: 1.5 | J30: 1.5 | K30: 1 | L30: 1 | M30: 1 | O30: 1 | P30: 1.5 | Q30: 1 | R30: 1.5 | S30: 1 | T30: 1 | V30: 1 | W30: 1.5 | X30: 1 | Y30: 1.5 | Z30: 1 | AA30: 1 | AC30: 1.5 | AD30: 1 | AE30: 1 | AJ30: 1 | AK30: 1 | AL30: 2 | AN30: =SUM(I30:AM30) -> 27.5 | AO30: 210000 | AP30: =AN30*AO30 -> 5775000
A31: 26 | B31: 김주연 | C31: 930719-1113812 | D31: 보통인부 | E31: 010-4729-7217 | F31: 농협 | G31: 김주연 | H31: 351-0768-6263-33 | I31: 2 | J31: 2 | K31: 2 | L31: 2 | O31: 2 | P31: 2 | Q31: 2 | R31: 2 | S31: 2 | V31: 1 | W31: 2 | X31: 2 | Y31: 2 | Z31: 2 | AC31: 2 | AD31: 2 | AJ31: 2 | AK31: 2 | AL31: 2 | AN31: =SUM(I31:AM31) -> 37 | AO31: 160000 | AP31: =AN31*AO31 -> 5920000
A32: 27 | B32: 김지민 | C32: 930707-1150011 | D32: 배관공 | E32: 010-8000-2457 | F32: 카카오뱅크 | G32: 김지민 | H32: 3333-13-9046173 | I32: 2 | J32: 2 | K32: 2 | L32: 2 | O32: 2 | P32: 2 | Q32: 2 | R32: 2 | V32: 1 | W32: 1.5 | X32: 1 | Y32: 1.5 | Z32: 1 | AA32: 1 | AC32: 1.5 | AD32: 1 | AE32: 1 | AJ32: 1 | AK32: 1.5 | AL32: 1 | AN32: =SUM(I32:AM32) -> 30 | AO32: 220000 | AP32: =AN32*AO32 -> 6600000
A33: 28 | B33: 김지성 | C33: 040726-3071113 | D33: 보통인부 | E33: 010-3116-4011 | F33: 신한 | G33: 김지성 | H33: 110-522-521550 | I33: 2 | J33: 2 | K33: 2 | L33: 2 | O33: 2 | P33: 2 | Q33: 2 | R33: 2 | S33: 2 | V33: 1 | W33: 1.5 | X33: 1 | Y33: 2 | Z33: 2 | AC33: 2 | AD33: 2 | AJ33: 2 | AK33: 2 | AL33: 2 | AN33: =SUM(I33:AM33) -> 35.5 | AO33: 150000 | AP33: =AN33*AO33 -> 5325000
A34: 29 | B34: 김진 | C34: 840728-1235014 | D34: 공사보조 | E34: 010-6246-4588 | F34: 기업 | G34: 김진 | H34: 458-013758-02-012 | I34: 2 | J34: 2 | K34: 2 | L34: 2 | O34: 2 | P34: 2 | Q34: 2 | R34: 2 | S34: 2 | V34: 1 | W34: 1.5 | X34: 1 | Y34: 1.5 | Z34: 1 | AA34: 1 | AC34: 1.5 | AD34: 1 | AE34: 1 | AJ34: 1 | AK34: 1.5 | AL34: 1 | AN34: =SUM(I34:AM34) -> 32 | AO34: 240000 | AP34: =AN34*AO34 -> 7680000
A35: 30 | B35: 김진재 | C35: 921012-1122616 | D35: 배관공 | E35: 010-5578-4437 | F35: 신한 | G35: 김진재 | H35: 110-331-408388 | I35: 1.5 | J35: 1.5 | K35: 1 | L35: 1 | M35: 0.375 | O35: 1 | P35: 1.5 | Q35: 1 | R35: 1.5 | S35: 1 | T35: 0.875 | V35: 1 | W35: 1.5 | X35: 1 | Y35: 1.5 | Z35: 1 | AA35: 1 | AC35: 1.375 | AD35: 1 | AE35: 1 | AJ35: 1 | AK35: 1.5 | AN35: =SUM(I35:AM35) -> 25.125 | AO35: 200000 | AP35: =AN35*AO35 -> 5025000
A36: 31 | B36: 김치헌 | C36: 790914-1567115 | D36: 배관공 | E36: 010-4191-6886 | F36: 국민 | G36: 김치헌 | H36: 257602-04-003063 | I36: 2 | J36: 2 | K36: 2 | L36: 2 | O36: 2 | P36: 2 | Q36: 2 | R36: 2 | S36: 2 | V36: 1 | W36: 2 | X36: 2 | Y36: 2 | Z36: 2 | AC36: 2 | AD36: 2 | AJ36: 2 | AK36: 2 | AL36: 2 | AN36: =SUM(I36:AM36) -> 37 | AO36: 250000 | AP36: =AN36*AO36 -> 9250000
A37: 32 | B37: 김태우 | C37: 730301-1675418 | D37: 보통인부 | E37: 010-3821-9392 | F37: 기업 | G37: 김태우 | H37: 186-100034-02-016 | I37: 2 | J37: 2 | K37: 2 | L37: 2 | O37: 2 | P37: 2 | Q37: 2 | R37: 2 | S37: 2 | V37: 1 | W37: 1.5 | X37: 1 | Y37: 2 | Z37: 2 | AC37: 2 | AD37: 2 | AJ37: 2 | AK37: 2 | AL37: 2 | AN37: =SUM(I37:AM37) -> 35.5 | AO37: 160000 | AP37: =AN37*AO37 -> 5680000
A38: 33 | B38: 천성욱 | C38: 800328-1113122 | D38: 보통인부 | E38: 010-6684-0888 | F38: 새마을금고 | G38: 천성욱 | H38: 9003-2816-2519-9 | I38: 2 | J38: 2 | K38: 2 | L38: 2 | AN38: =SUM(I38:AM38) -> 8 | AO38: 170000 | AP38: =AN38*AO38 -> 1360000
A39: 34 | B39: 최준 | C39: 881115-1663713 | D39: 용접공 | E39: 010-9290-1488 | F39: 신한 | G39: 최준 | H39: 110-447-944425 | I39: 2 | J39: 2 | K39: 2 | L39: 2 | AN39: =SUM(I39:AM39) -> 8 | AO39: 240000 | AP39: =AN39*AO39 -> 1920000
A40: 35 | B40: 김현중 | C40: 920608-1476210 | D40: 보통인부 | E40: 010-8304-4458 | F40: 국민 | G40: 김현중 | H40: 742102-00-113592 | I40: 1.5 | J40: 1.5 | K40: 1 | L40: 1 | M40: 1 | O40: 1 | P40: 1.5 | Q40: 1 | R40: 1.5 | S40: 1 | T40: 1 | V40: 1 | W40: 1.5 | Y40: 1.5 | Z40: 1 | AA40: 1 | AC40: 1.5 | AD40: 1 | AJ40: 1 | AK40: 1.5 | AL40: 1 | AN40: =SUM(I40:AM40) -> 25 | AO40: 180000 | AP40: =AN40*AO40 -> 4500000
A41: 36 | B41: 강은천 | C41: 740803-1155526 | D41: 배관공 | E41: 010-5131-8640 | F41: 하나 | G41: 강은천 | H41: 226-910131-79107 | I41: 2 | J41: 2 | K41: 2 | L41: 2 | O41: 2 | AN41: =SUM(I41:AM41) -> 10 | AO41: 210000 | AP41: =AN41*AO41 -> 2100000
...

Sheet 숙소임차료
A1: 숙소 임차료
A2: No. | B2: 납부일 | C2: 구분 | D2: 품명 | E2: 주소 | F2: 호수 | G2: 수량 | H2: 사용인원 | I2: 임차료 | J2: 비 고
I3: =SUM(I4:I35) -> 48610000 | L3: 입력해야하는 항목 외 수정 금지
A4: 1 | B4: 46295 | C4: KC대납 임대료 | D4: 숙소임대료(09월분) | E4: 평택시 함박산11길 9-1 202호 | F4: 202호 | G4: 1 | H4: 6 | I4: 1650000 | J4: KC 대납 | L4: 납부일
A5: 2 | B5: 46295 | C5: KC대납 임대료 | D5: 숙소임대료(09월분) | E5: 평택시 함박산3길 11 301호 | F5: 301호 | G5: 1 | H5: 6 | I5: 1900000 | J5: KC 대납 | L5: 구분
A6: 3 | B6: 46295 | C6: KC대납 임대료 | D6: 숙소임대료(09월분) | E6: 평택시 고덕여염16길 115 202호 | F6: 202호 | G6: 1 | H6: 6 | I6: 1400000 | J6: KC 대납 | L6: 품명
A7: 4 | B7: 46295 | C7: KC대납 임대료 | D7: 숙소임대료(09월분) | E7: 평택시 함박산9길 26 201호 | F7: 201호 | G7: 1 | H7: 6 | I7: 1800000 | J7: KC 대납 | L7: 주소
A8: 5 | B8: 46295 | C8: KC대납 임대료 | D8: 숙소임대료(09월분) | E8: 평택시 함박산1길 50 401호 | F8: 401호 | G8: 1 | H8: 6 | I8: 1700000 | J8: KC 대납 | L8: 호수
A9: 6 | B9: 46295 | C9: KC대납 임대료 | D9: 숙소임대료(09월분) | E9: 평택시 함박산4길 3 301호 | F9: 301호 | G9: 1 | H9: 6 | I9: 1530000 | J9: KC 대납 | L9: 수량
A10: 7 | B10: 46295 | C10: KC대납 임대료 | D10: 숙소임대료(09월분) | E10: 평택시 고덕여염16길 71 302호 | F10: 302호 | G10: 1 | H10: 6 | I10: 900000 | J10: KC 대납 | L10: 사용인원
A11: 8 | B11: 46295 | C11: KC대납 임대료 | D11: 숙소임대료(09월분) | E11: 평택시 고덕국제4길 60-10 202호 | F11: 202호 | G11: 1 | H11: 6 | I11: 1650000 | J11: KC 대납
A12: 9 | B12: 46295 | C12: KC대납 임대료 | D12: 숙소임대료(09월분) | E12: 평택시 함박산2길 11 302호 | F12: 302호 | G12: 1 | H12: 6 | I12: 1500000 | J12: KC 대납 | L12: ■ 구분은 [KC대납 임대료 및 임대료] 이외 항목은 입력금지
A13: 10 | B13: 46295 | C13: KC대납 임대료 | D13: 숙소임대료(09월분) | E13: 평택시 함박산8길 13 201호 | F13: 201호 | G13: 1 | H13: 6 | I13: 1650000 | J13: KC 대납
A14: 11 | B14: 46295 | C14: KC대납 임대료 | D14: 숙소임대료(09월분) | E14: 평택시 고덕여염6길 199 301호 | F14: 301호 | G14: 1 | H14: 6 | I14: 1600000 | J14: KC 대납
A15: 12 | B15: 46295 | C15: KC대납 임대료 | D15: 숙소임대료(09월분) | E15: 평택시 함박산2길 16 201호 | F15: 201호 | G15: 1 | H15: 6 | I15: 1500000 | J15: KC 대납
A16: 13 | B16: 46295 | C16: KC대납 임대료 | D16: 숙소임대료(09월분) | E16: 평택시 함박산3길 11 202호 | F16: 202호 | G16: 1 | H16: 6 | I16: 1800000 | J16: KC 대납
A17: 14 | B17: 46295 | C17: KC대납 임대료 | D17: 숙소임대료(09월분) | E17: 평택시 함박산4길 28 301호 | F17: 301호 | G17: 1 | H17: 6 | I17: 1600000 | J17: KC 대납
A18: 15 | B18: 46295 | C18: KC대납 임대료 | D18: 숙소임대료(09월분) | E18: 평택시 함박산1길 49 202호 | F18: 202호 | G18: 1 | H18: 4 | I18: 1630000 | J18: KC 대납
A19: 16 | B19: 46295 | C19: KC대납 임대료 | D19: 숙소임대료(09월분) | E19: 평택시 고덕국제3길 103 202호 | F19: 202호 | G19: 1 | H19: 6 | I19: 1050000 | J19: KC 대납
A20: 17 | B20: 46295 | C20: KC대납 임대료 | D20: 숙소임대료(09월분) | E20: 평택시 고덕여염12길 10 201호 | F20: 201호 | G20: 1 | H20: 6 | I20: 1600000 | J20: KC 대납
A21: 18 | B21: 46295 | C21: KC대납 임대료 | D21: 숙소임대료(09월분) | E21: 평택시 함박산2길 32-2 202호 | F21: 202호 | G21: 1 | H21: 6 | I21: 1550000 | J21: KC 대납
A22: 19 | B22: 46295 | C22: KC대납 임대료 | D22: 숙소임대료(09월분) | E22: 평택시 함박산2길 30 201호 | F22: 201호 | G22: 1 | H22: 6 | I22: 1550000 | J22: KC 대납
A23: 20 | B23: 46295 | C23: KC대납 임대료 | D23: 숙소임대료(09월분) | E23: 평택시 함박산2길 16-1 301호 | F23: 301호 | G23: 1 | H23: 6 | I23: 1550000 | J23: KC 대납
A24: 21 | B24: 46295 | C24: KC대납 임대료 | D24: 숙소임대료(09월분) | E24: 평택시 함박산1길 23 201호 | F24: 201호 | G24: 1 | H24: 6 | I24: 1550000 | J24: KC 대납
... A35: 32 | B35: 46295 | C35: KC대납 임대료 | D35: 숙소임대료(09월분) | E35: 평택시 고덕갈평10길 34 301호 | F35: 301호 | G35: 1 | H35: 6 | I35: 1500000 | J35: KC 대납

Sheet 숙소관리비
A1: 숙소 관리비
A2: No. | B2: 납부일 | C2: 구분 | D2: 품명 | E2: 주소 | F2: 호수 | G2: 수량 | H2: 사용인원 | I2: 관리비 | J2: 비 고
I3: =SUM(I4:I104) -> 5108770
A4: 1 | B4: 46295 | C4: KC대납 관리비 | D4: 숙소수도세(09월분) | E4: 평택시 함박산11길 9-1 202호 | F4: 202호 | G4: 1 | H4: 6 | I4: 23660 | J4: KC 대납
A5: 2 | B5: 46295 | C5: KC대납 관리비 | D5: 숙소가스료(09월분) | E5: 평택시 함박산11길 9-1 202호 | F5: 202호 | G5: 1 | H5: 6 | I5: 혹서기로 격월고지 | J5: KC 대납
A6: 3 | B6: 46295 | C6: KC대납 관리비 | D6: 숙소전기료(09월분) | E6: 평택시 함박산11길 9-1 202호 | F6: 202호 | G6: 1 | H6: 6 | I6: 62870 | J6: KC 대납
A7: 4 | B7: 46295 | C7: KC대납 관리비 | D7: 숙소수도세(09월분) | E7: 평택시 함박산3길 11 301호 | F7: 301호 | G7: 1 | H7: 6 | I7: 8100 | J7: KC 대납
A8: 5 | B8: 46295 | C8: KC대납 관리비 | D8: 숙소가스료(09월분) | E8: 평택시 함박산3길 11 301호 | F8: 301호 | G8: 1 | H8: 6 | I8: 혹서기로 격월고지 | J8: KC 대납
A9: 6 | B9: 46295 | C9: KC대납 관리비 | D9: 숙소전기료(09월분) | E9: 평택시 함박산3길 11 301호 | F9: 301호 | G9: 1 | H9: 6 | I9: 210480 | J9: KC 대납
A10: 7 | B10: 46295 | C10: KC대납 관리비 | D10: 숙소수도세(09월분) | E10: 평택시 고덕여염16길 115 202호 | F10: 202호 | G10: 1 | H10: 6 | I10: 8100 | J10: KC 대납
A11: 8 | B11: 46295 | C11: KC대납 관리비 | D11: 숙소가스료(09월분) | E11: 평택시 고덕여염16길 115 202호 | F11: 202호 | G11: 1 | H11: 6 | I11: 혹서기로 격월고지 | J11: KC 대납
A12: 9 | B12: 46295 | C12: KC대납 관리비 | D12: 숙소전기료(09월분) | E12: 평택시 고덕여염16길 115 202호 | F12: 202호 | G12: 1 | H12: 6 | I12: 27520 | J12: KC 대납
A13: 10 | B13: 46295 | C13: KC대납 관리비 | D13: 숙소수도세(09월분) | E13: 평택시 함박산9길 26 201호 | F13: 201호 | G13: 1 | H13: 6 | I13: 27130 | J13: KC 대납
A14: 11 | B14: 46295 | C14: KC대납 관리비 | D14: 숙소가스료(09월분) | E14: 평택시 함박산9길 26 201호 | F14: 201호 | G14: 1 | H14: 6 | I14: 혹서기로 격월고지 | J14: KC 대납
A15: 12 | B15: 46295 | C15: KC대납 관리비 | D15: 숙소전기료(09월분) | E15: 평택시 함박산9길 26 201호 | F15: 201호 | G15: 1 | H15: 6 | I15: 39900 | J15: KC 대납
A16: 13 | B16: 46295 | C16: KC대납 관리비 | D16: 숙소수도세(09월분) | E16: 평택시 함박산1길 50 401호 | F16: 401호 | G16: 1 | H16: 6 | I16: 28850 | J16: KC 대납
A17: 14 | B17: 46295 | C17: KC대납 관리비 | D17: 숙소가스료(09월분) | E17: 평택시 함박산1길 50 401호 | F17: 401호 | G17: 1 | H17: 6 | I17: 혹서기로 격월고지 | J17: KC 대납
A18: 15 | B18: 46295 | C18: KC대납 관리비 | D18: 숙소전기료(09월분) | E18: 평택시 함박산1길 50 401호 | F18: 401호 | G18: 1 | H18: 6 | I18: 155100 | J18: KC 대납
A19: 16 | B19: 46295 | C19: KC대납 관리비 | D19: 숙소수도세(09월분) | E19: 평택시 함박산4길 3 301호 | F19: 301호 | G19: 1 | H19: 6 | I19: 익월청구 | J19: KC 대납
A20: 17 | B20: 46295 | C20: KC대납 관리비 | D20: 숙소가스료(09월분) | E20: 평택시 함박산4길 3 301호 | F20: 301호 | G20: 1 | H20: 6 | I20: 혹서기로 격월고지 | J20: KC 대납
A21: 18 | B21: 46295 | C21: KC대납 관리비 | D21: 숙소전기료(09월분) | E21: 평택시 함박산4길 3 301호 | F21: 301호 | G21: 1 | H21: 6 | I21: 27440 | J21: KC 대납
A22: 19 | B22: 46295 | C22: KC대납 관리비 | D22: 숙소수도세(09월분) | E22: 평택시 고덕여염16길 71 302호 | F22: 302호 | G22: 1 | H22: 6 | I22: 1200 | J22: KC 대납
A23: 20 | B23: 46295 | C23: KC대납 관리비 | D23: 숙소가스료(09월분) | E23: 평택시 고덕여염16길 71 302호 | F23: 302호 | G23: 1 | H23: 6 | I23: 혹서기로 격월고지 | J23: KC 대납
A24: 21 | B24: 46295 | C24: KC대납 관리비 | D24: 숙소전기료(09월분) | E24: 평택시 고덕여염16길 71 302호 | F24: 302호 | G24: 1 | H24: 6 | I24: 익월청구 | J24: KC 대납
A25: 22 | B25: 46295 | C25: KC대납 관리비 | D25: 숙소수도세(09월분) | E25: 평택시 고덕국제4길 60-10 202호 | F25: 202호 | G25: 1 | H25: 6 | I25: 20210 | J25: KC 대납
A26: 23 | B26: 46295 | C26: KC대납 관리비 | D26: 숙소가스료(09월분) | E26: 평택시 고덕국제4길 60-10 202호 | F26: 202호 | G26: 1 | H26: 6 | I26: 혹서기로 격월고지 | J26: KC 대납
A27: 24 | B27: 46295 | C27: KC대납 관리비 | D27: 숙소전기료(09월분) | E27: 평택시 고덕국제4길 60-10 202호 | F27: 202호 | G27: 1 | H27: 6 | I27: 165210 | J27: KC 대납
A28: 25 | B28: 46295 | C28: KC대납 관리비 | D28: 숙소수도세(09월분) | E28: 평택시 함박산2길 11 302호 | F28: 302호 | G28: 1 | H28: 6 | I28: 1530 | J28: KC 대납
A29: 26 | B29: 46295 | C29: KC대납 관리비 | D29: 숙소가스료(09월분) | E29: 평택시 함박산2길 11 302호 | F29: 302호 | G29: 1 | H29: 6 | I29: 혹서기로 격월고지 | J29: KC 대납
A30: 27 | B30: 46295 | C30: KC대납 관리비 | D30: 숙소전기료(09월분) | E30: 평택시 함박산2길 11 302호 | F30: 302호 | G30: 1 | H30: 6 | I30: 91760 | J30: KC 대납
A31: 28 | B31: 46295 | C31: KC대납 관리비 | D31: 숙소수도세(09월분) | E31: 평택시 함박산8길 13 201호 | F31: 201호 | G31: 1 | H31: 6 | I31: 25390 | J31: KC 대납
A32: 29 | B32: 46295 | C32: KC대납 관리비 | D32: 숙소가스료(09월분) | E32: 평택시 함박산8길 13 201호 | F32: 201호 | G32: 1 | H32: 6 | I32: 혹서기로 격월고지 | J32: KC 대납
A33: 30 | B33: 46295 | C33: KC대납 관리비 | D33: 숙소전기료(09월분) | E33: 평택시 함박산8길 13 201호 | F33: 201호 | G33: 1 | H33: 6 | I33: 161230 | J33: KC 대납
A34: 31 | B34: 46295 | C34: KC대납 관리비 | D34: 숙소수도세(09월분) | E34: 평택시 고덕여염6길 199 301호 | F34: 301호 | G34: 1 | H34: 6 | I34: 20210 | J34: KC 대납
A35: 32 | B35: 46295 | C35: KC대납 관리비 | D35: 숙소가스료(09월분) | E35: 평택시 고덕여염6길 199 301호 | F35: 301호 | G35: 1 | H35: 6 | I35: 혹서기로 격월고지 | J35: KC 대납
A36: 33 | B36: 46295 | C36: KC대납 관리비 | D36: 숙소전기료(09월분) | E36: 평택시 고덕여염6길 199 301호 | F36: 301호 | G36: 1 | H36: 6 | I36: 29180 | J36: KC 대납
A37: 34 | B37: 46295 | C37: KC대납 관리비 | D37: 숙소수도세(09월분) | E37: 평택시 함박산2길 16 201호 | F37: 201호 | G37: 1 | H37: 6 | I37: 15020 | J37: KC 대납
A38: 35 | B38: 46295 | C38: KC대납 관리비 | D38: 숙소가스료(09월분) | E38: 평택시 함박산2길 16 201호 | F38: 201호 | G38: 1 | H38: 6 | I38: 혹서기로 격월고지 | J38: KC 대납
A39: 36 | B39: 46295 | C39: KC대납 관리비 | D39: 숙소전기료(09월분) | E39: 평택시 함박산2길 16 201호 | F39: 201호 | G39: 1 | H39: 6 | I39: 8260 | J39: KC 대납
A40: 37 | B40: 46295 | C40: KC대납 관리비 | D40: 숙소수도세(09월분) | E40: 평택시 함박산3길 11 202호 | F40: 202호 | G40: 1 | H40: 6 | I40: 22160 | J40: KC 대납
...

Sheet 식대비용
A1: 식대 비용
A2: No. | B2: 납부일 | C2: 구분 | D2: 품명 | E2: 거래처명 | F2: 수량 | G2: 식수인원 | H2: 단가 | I2: 합 계 | J2: 비 고
I3: =SUM(I4:I5) -> 50466045 | L3: 입력해야하는 항목 외 수정 금지
A4: 1 | B4: 46295 | C4: KC대납 식대 | D4: 기술인및관리자 (현장 식당) | E4: 포세카 | F4: 3283 | G4: 99 | H4: 6181.82 | I4: 20247045 | J4: KC 대납 | L4: 입력항목
A5: 2 | B5: 46295 | C5: KC대납 식대 | D5: 기술인및관리자 (현장 식당) | E5: 밥심 | F5: 4317 | G5: 127 | H5: 7000 | I5: =F5*H5 -> 30219000 | J5: KC 대납 | L5: 납부일
L6: 구분
L7: 품명
L8: 거래처명
L9: 수량
L10: 식수인원
L11: 단가
L13: ■ 구분은 [KC대납 식대 및 식대] 이외 항목은 입력금지

Sheet 기타비용
A1: 기타 비용
A2: No. | B2: 구매일 | C2: 구분 | D2: 품명 | E2: 거래처명 | F2: 수량 | G2: 단가 | H2: 합계 | I2: 비고
H3: =SUM(H4:H34) -> 923200 | K3: 입력해야하는 항목 외 수정 금지
A4: 1 | B4: 46268 | C4: 소모품비 | D4: 고무플러그 [220V [진흥]] | E4: 미래공구 | F4: 10 | G4: 3200 | H4: =F4*G4 -> 32000 | I4: 거래명세서 첨부 | K4: 입력항목
A5: 2 | B5: 46268 | C5: 소모품비 | D5: 다이아몬드줄 [160mm,반원 [삼익]] | E5: 미래공구 | F5: 5 | G5: 6500 | H5: =F5*G5 -> 32500 | I5: 거래명세서 첨부 | K5: 납부일
A6: 3 | B6: 46272 | C6: 소모품비 | D6: PVC망 [공간7MM,폭이4자*9M] | E6: 미래공구 | F6: 3 | G6: 53100 | H6: =F6*G6 -> 159300 | I6: 거래명세서 첨부 | K6: 구분
A7: 4 | B7: 46273 | C7: 소모품비 | D7: 낙상경보기부품 [풀피리,대] | E7: 미래공구 | F7: 500 | G7: 100 | H7: =F7*G7 -> 50000 | I7: 거래명세서 첨부 | K7: 품명
A8: 5 | B8: 46273 | C8: 소모품비 | D8: 밴드쏘날 [1640*13*0.65-14T [WESPA]] | E8: 미래공구 | F8: 10 | G8: 12000 | H8: =F8*G8 -> 120000 | I8: 거래명세서 첨부 | K8: 거래처명
A9: 6 | B9: 46273 | C9: 소모품비 | D9: 마대 [PP,신재 [국산/HNS]] | E9: 미래공구 | F9: 50 | G9: 500 | H9: =F9*G9 -> 25000 | I9: 거래명세서 첨부 | K9: 수량
A10: 7 | B10: 46273 | C10: 소모품비 | D10: 마대 [수입,90kg,100L,75*110 [SWS]] | E10: 미래공구 | F10: 100 | G10: 300 | H10: =F10*G10 -> 30000 | I10: 거래명세서 첨부 | K10: 식수인원
A11: 8 | B11: 46273 | C11: 소모품비 | D11: 페인트붓 [1" [동양]] | E11: 미래공구 | F11: 5 | G11: 1500 | H11: =F11*G11 -> 7500 | I11: 거래명세서 첨부 | K11: 단가
A12: 9 | B12: 46273 | C12: 소모품비 | D12: 제트브로치(PROCUT) [14*35L [우창]] | E12: 미래공구 | F12: 2 | G12: 31000 | H12: =F12*G12 -> 62000 | I12: 거래명세서 첨부
A13: 10 | B13: 46273 | C13: 소모품비 | D13: 파이롯트핀 [6.34*90L(12~17) [우창]] | E13: 미래공구 | F13: 2 | G13: 4100 | H13: =F13*G13 -> 8200 | I13: 거래명세서 첨부 | K13: ■ 구분은 [KC대납 식대 및 식대] 이외 항목은 입력금지
A14: 11 | B14: 46274 | C14: 소모품비 | D14: PP로프 [6mm*100m [SWS]] | E14: 미래공구 | F14: 1 | G14: 10300 | H14: =F14*G14 -> 10300 | I14: 거래명세서 첨부
A15: 12 | B15: 46274 | C15: 소모품비 | D15: 낙상경보기부품 [풀피리] | E15: 미래공구 | F15: 20 | G15: 100 | H15: =F15*G15 -> 2000 | I15: 거래명세서 첨부
A16: 13 | B16: 46274 | C16: 소모품비 | D16: 마대 [수입,90kg,100L,75*110 [SWS]] | E16: 미래공구 | F16: 100 | G16: 300 | H16: =F16*G16 -> 30000 | I16: 거래명세서 첨부
A17: 14 | B17: 46274 | C17: 소모품비 | D17: 번호열쇠 [XD-40,4열 [자커]] | E17: 미래공구 | F17: 10 | G17: 3600 | H17: =F17*G17 -> 36000 | I17: 거래명세서 첨부
A18: 15 | B18: 46274 | C18: 소모품비 | D18: 방청유 [WD-40,360ML [BEX]] | E18: 미래공구 | F18: 2 | G18: 5500 | H18: =F18*G18 -> 11000 | I18: 거래명세서 첨부
A19: 16 | B19: 46275 | C19: 소모품비 | D19: 수세미 [MIGHTY BLUE PAD,녹색 [3M]] | E19: 미래공구 | F19: 10 | G19: 1100 | H19: =F19*G19 -> 11000 | I19: 거래명세서 첨부
A20: 17 | B20: 46275 | C20: 소모품비 | D20: 네임펜 [양면,흑색,12개 [모나미]] | E20: 미래공구 | F20: 3 | G20: 12400 | H20: =F20*G20 -> 37200 | I20: 거래명세서 첨부
A21: 18 | B21: 46276 | C21: 소모품비 | D21: 용접검사거울 [SM-914 [스마토]] | E21: 미래공구 | F21: 2 | G21: 4700 | H21: =F21*G21 -> 9400 | I21: 거래명세서 첨부
A22: 19 | B22: 46281 | C22: 소모품비 | D22: 알곤토치헤드 [350A,플렉시블,CT-35F,CTX [크레토스]] | E22: 미래공구 | F22: 3 | G22: 10500 | H22: =F22*G22 -> 31500 | I22: 거래명세서 첨부
A23: 20 | B23: 46281 | C23: 소모품비 | D23: 마대 [PP,신재 [국산/HNS]] | E23: 미래공구 | F23: 50 | G23: 500 | H23: =F23*G23 -> 25000 | I23: 거래명세서 첨부
A24: 21 | B24: 46281 | C24: 소모품비 | D24: 양면테이프 [50mm*6m,핫멧트 [HNS]] | E24: 미래공구 | F24: 10 | G24: 900 | H24: =F24*G24 -> 9000 | I24: 거래명세서 첨부
A25: 22 | B25: 46282 | C25: 소모품비 | D25: 수리비,레이져레벨기 [RX20,수직,수평,코어 [코텐]] | E25: 미래공구 | F25: 1 | G25: 30000 | H25: =F25*G25 -> 30000 | I25: 거래명세서 첨부
... A34: 31 | B34: 46293 | C34: 소모품비 | D34: 에폭시접착제 [매직스틱,다목적용,114G,CTX [엑시아]] | E34: 미래공구 | F34: 5 | G34: 8500 | H34: =F34*G34 -> 42500 | I34: 거래명세서 첨부

Sheet 서명란
B2: 현 장 확 인 | C2: 소 장 | E2: (서명)
C3: 공 사 | E3: (서명)
C4: 공 무 | E4: (서명)
G6: 사 업 부 | H6: Frontier 사업부 GNP 본부장 | I6: BOC 센터장 | J6: Frontier 사업부장
L8: 본 사 | M8: 담 당 | N8: 검 토 | O8: 검 토
Q11: 구 분 | R11: 확 인
Q12: 품 질 | R12: O O O (인)
Q13: 공 무 | R13: O O O (인)

Sheet DIA-INCH
B3: SIZE
B4: A(mm) | C4: Inch
B5: 8A | C5: 0.25
B6: 15A | C6: 0.5
B7: 20A | C7: 0.75
B8: 25A | C8: 1
B9: 32A | C9: 1.25
B10: 40A | C10: 1.5
B11: 50A | C11: 2
B12: 65A | C12: 2.5
B13: 80A | C13: 3
B14: 100A | C14: 4
B15: 110A | C15: 4
B16: 125A | C16: 5
... B27: 550A | C27: 22
