Workbook

Sheet 용역청구서 표지
B4: 용 역 청 구 서
B7: P4 Ph2 GAS&PCW 1공구
C8: S26-001
C14: 2026년 07월
C15: 대성이엔지

Sheet 용역 청구서(갑지)
A1: 용 역 청 구 서
A3: 1 | B3: 공 사 명 | C3: : | D3: ='용역청구서 표지'!$B$7 -> P4 Ph2 GAS&PCW 1공구 | E3: ='용역청구서 표지'!$C$8 -> S26-001
A4: 2 | B4: 공 종 | C4: : | D4: 외주용역(M/M부분)
A5: 3 | B5: 계 약 금 액 | C5: : | D5: =ROUNDUP(E5,0) -> 0 | E5: =집계장!J23 -> 0 | F5: (VAT 별도)
A6: 4 | B6: 누 계 기 성 금 액 | C6: : | D6: =ROUNDUP(E6,0) -> 152100000 | E6: =E7+E13 -> 152100000 | F6: (VAT 별도)
A7: 5 | B7: 전 회 기 성 금 액 | C7: : | D7: =ROUNDUP(E7,0) -> 0 | E7: 0 | F7: (VAT 별도)
A8: 6 | B8: 금 회 기 성 금 액 | C8: : | D8: =ROUNDUP(E8,0) -> 152100000 | E8: =집계장!I23 -> 152100000 | F8: (VAT 별도)
A9: 7 | B9: 선 금 액 | C9: : | D9: =ROUNDUP(E9,0) -> 30000000 | E9: =집계장!L21 -> 30000000 | F9: (VAT 별도)
A10: 8 | B10: 선 금 전 회 공 제 | C10: : | D10: =ROUNDUP(E10,0) -> 0 | E10: =집계장!H21 -> 0 | F10: (VAT 별도)
A11: 9 | B11: 선 금 금 회 공 제 | C11: : | D11: =ROUNDUP(E11,0) -> 0 | E11: =집계장!G21 -> 0 | F11: (VAT 별도)
A12: 10 | B12: 선 금 잔 여 금 액 | C12: : | D12: =ROUNDUP(E12,0) -> 0 | E12: =집계장!M21 -> 0 | F12: (VAT 별도)
A13: 11 | B13: 금 회 청 구 금 액 | C13: : | D13: =ROUNDUP(E13,0) -> 152100000 | E13: =집계장!G23 -> 152100000 | F13: (VAT 별도)
A14: 12 | B14: 잔 여 기 성 금 액 | C14: : | D14: =ROUNDUP(E14,0) -> 0 | F14: (VAT 별도)
A15: 13 | B15: 공 정 율 | C15: : | D15: 1
A16: 14 | B16: 청 구 공 사 기 간 | C16: : | D16: 2026. 07. 01 ~ 2026. 07. 31
B18: 위 공사의 하도급에 있어서 공사설계도서, 시방서,품질관리 기준 및 약정대로 시공 되었음을 확인하오며. 만약 귀사의 현장담당의 검사에
B19: 관하여 하자가 발견된 때에는 즉시 실액배상 또는 재 시공할것을 서약하고 이에 기성 청구서를 제출합니다.
B20: 상기건과 관련하여 본 청구 이전까지의 모든 대금은 수령하였음을 확약합니다.
F21: 작 성 일 : 2026 년 07 월 31 일
F23: 상 호 : | G23: 대성이엔지
B24: ※첨 부 : 기성내역서 1부. | F24: 주 소 : | G24: 경기도 파주시 파주읍 주라위길 380
F25: 대표이사 : | G25: 정 성 기 | I25: (인)
D26: ㈜케이씨이앤씨 귀하

Sheet 용역 내역서(을지)
A1: 용 역 내 역 서
A2: P4 Ph4 GAS 1공구 마감공사 | G2: 단위 : 원
A3: 품 명 | B3: 규 격 | C3: 단위 | D3: 단 가 | E3: 금 회 청 구
E4: 수 량 | F4: 금 액 | G4: 비 고
A5: 고급기술인 | B5: S+ | C5: M/M | D5: 1400000 | E5: 1 | F5: =D5*E5 -> 1400000
A6: 고급기술인 | B6: S | C6: M/M | D6: 1200000 | F6: =D6*E6 -> 0
A7: 중급기술인 | B7: A+ | C7: M/M | D7: 1000000 | F7: =D7*E7 -> 0
A8: 중급기술인 | B8: A | C8: M/M | D8: 900000 | F8: =D8*E8 -> 0
A9: 중급기술인 | B9: B+ | C9: M/M | D9: 800000 | F9: =D9*E9 -> 0
A10: 중급기술인 | B10: B | C10: M/M | D10: 700000 | F10: =D10*E10 -> 0
A11: 초급 기술인 | B11: C | C11: M/M | D11: 600000 | F11: =D11*E11 -> 0
A13: 인센티브 | E13: 0.01 | F13: =SUM(F5:F11)*E13 -> 14000
A15: 총 계 | E15: =SUM(E5:E11) -> 1 | F15: =SUM(F5:F13) -> 1414000

Sheet 내역서(을지)
A1: 용 역 내 역 서
A2: =집계장!B2 -> P4 Ph2 GAS&PCW 1공구 | G2: 단위 : 원
A3: 품 명 | B3: 규 격 | C3: 단위 | D3: 단 가 | E3: 금 회 청 구 | G3: 비 고
E4: 수 량 | F4: 금 액
A5: 고급기술인 | B5: S+ | C5: M/M | D5: 1400000 | E5: 8 | F5: =D5*E5 -> 11200000
A6: 고급기술인 | B6: S | C6: M/M | D6: 1200000 | E6: 2 | F6: =D6*E6 -> 2400000
A7: 중급기술인 | B7: A+ | C7: M/M | D7: 1000000 | E7: 6 | F7: =D7*E7 -> 6000000
A8: 중급기술인 | B8: A | C8: M/M | D8: 900000 | E8: 1 | F8: =D8*E8 -> 900000
A9: 중급기술인 | B9: B+ | C9: M/M | D9: 800000 | E9: 4 | F9: =D9*E9 -> 3200000
A10: 중급기술인 | B10: B | C10: M/M | D10: 700000 | E10: 9 | F10: =D10*E10 -> 6300000
A11: 초급기술인 | B11: C | C11: M/M | D11: 600000 | F11: =D11*E11 -> 0
A27: 총 계 | E27: =SUM(E5:E11) -> 30 | F27: =SUM(F5:F26) -> 30000000

Sheet 집계장
B2: ='용역청구서 표지'!$B$7 -> P4 Ph2 GAS&PCW 1공구
M3: ='용역청구서 표지'!$C$15 -> 대성이엔지
B4: 구분 | C4: 내역 | D4: 단위 | E4: 수량 | F4: 단가 | G4: 합계 | H4: 전회기성 | I4: 금회기성 | J4: 누계기성 | K4: 비 고
B5: 1. 물량 | C5: WELDING POINT | D5: D/I | E5: =SUM('물량 내역서'!$J$6:$J$28) -> 3011 | F5: =G5/E5 -> 475000 | G5: =SUM('물량 내역서'!$K$6:$K$28) -> 1430225000 | H5: 1626162500 | I5: =G5 -> 1430225000 | J5: =H5+I5 -> 3056387500
C6: VALVE 설치비 | D6: EA | E6: =SUM('물량 내역서'!$J$29:$J$51) -> 0 | F6: =G6/E6 -> #DIV/0! | G6: =SUM('물량 내역서'!$K$29:$K$51) -> 0 | H6: 0 | I6: =G6 -> 0 | J6: =H6+I6 -> 0
C7: 인원 실투입 | D7: M/D | E7: ='근로내역 (07월)'!AN205 -> 0 | F7: 0 | G7: =E7*F7 -> 0 | H7: 0 | I7: =G7 -> 0 | J7: =H7+I7 -> 0
B8: 소 계 | C8: 물량 | G8: =SUM(G5:G7) -> 1430225000 | H8: =SUM(H5:H7) -> 1626162500 | I8: =G8 -> 1430225000 | J8: =H8+I8 -> 3056387500
B9: 2. 노무비 | C9: 직접노무비 | D9: 式 | E9: ='근로내역 (07월)'!AN193 -> 5868.8125 | F9: =G9/E9 -> 192680.91 | G9: ='근로내역 (07월)'!AP206 -> 1130808125 | H9: 1501806250 | I9: =G9 -> 1130808125 | J9: =H9+I9 -> 2632614375
B10: 3. 숙소 및 식대 | C10: 임대료+관리비 | D10: 式 | E10: =SUM(숙소임차료!H4:H6)+SUM(숙소관리비!H4:H8) -> 48 | F10: =G10/E10 -> 1429566.9 | G10: =숙소임차료!I3+숙소관리비!I3 -> 68619210 | H10: 139397160 | I10: =G10 -> 68619210 | J10: =H10+I10 -> 208016370
C11: 식대 | D11: 式 | E11: =SUM(식대비용!G4:G4) -> 132 | F11: =G11/E11 -> 499474.86 | G11: =식대비용!I3 -> 65930682 | H11: 107133818 | I11: =G11 -> 65930682 | J11: =H11+I11 -> 173064500
B12: 4. 기타 공제 내역 | D12: 式 | F12: 0 | G12: =E12*F12 -> 0 | I12: =G12 -> 0 | J12: =H12+I12 -> 0
B13: 소 계 | C13: 공제 | G13: =SUM(G9:G12) -> 1265358017 | H13: =SUM(H9:H12) -> 1748337228 | I13: =G13 -> 1265358017 | J13: =H13+I13 -> 3013695245
B14: 합 계 | C14: 기성 (물량-공제) | G14: =G8-G13 -> 164866983 | H14: =H8-H13 -> -122174728 | I14: =G14 -> 164866983 | J14: =H14+I14 -> 42692255
B15: 5. 유보금 | C15: 기성금*XX% | D15: 式 | G15: 12692255 | I15: =G15 -> 12692255 | J15: =H15+I15 -> 12692255
B16: 6. 유보금 차액 | C16: 전회 누계유보금 | D16: 式 | I16: =G16 -> 0 | J16: =H16+I16 -> 0
B17: 7. NEGO | C17: NEGO | D17: 式 | I17: =G17 -> 0
B18: 8. 선지급금 | D18: 式 | H18: 30000000 | I18: =G18 -> 0 | J18: 30000000
B19: 총 계 | C19: 최종기성 | G19: =G14-G15-G16-G17-G18 -> 152174728 | H19: =H14+H15+H16+H17-H18 -> -152174728 | I19: =G19 -> 152174728 | J19: =H19+I19 -> 0
B20: 선급금 | C20: 선수공제 | D20: 式 | G20: 0 | I20: =G20 -> 0 | J20: =H20+I20 -> 0 | L20: 지급 선급금 | M20: 선급금 차액
C21: 단수정리 | D21: 式 | G21: =ROUNDDOWN(G20,-5) -> 0 | I21: =G21 -> 0 | J21: =H21+I21 -> 0 | K21: 만 단위 이하 절사 | L21: =H18 -> 30000000
B22: 공제 후 실 지급액 | G22: =G19-G21 -> 152174728 | H22: =H19-H21 -> -152174728 | I22: =G22 -> 152174728 | J22: =H22+I22 -> 0
B23: 세금계산서 기준 | G23: =ROUNDDOWN(G22,-5) -> 152100000 | H23: =ROUNDDOWN(H22,-5) -> -152100000 | I23: =G23 -> 152100000 | J23: =ROUNDDOWN(J22,-5) -> 0 | K23: 만 단위 이하 절사
B24: TERMS AND CONDITIONS | E24: NOTE
B25: 1. 납 기 : KCEnC 지정 납기로 별도 협의 하에 결정하는 것으로 함.
B26: 2. 지불조건 : KCEnC 지불 조건에 따름.
B27: 3. 유효기간 : 기성 제출일로 부터 30일 이내

Sheet 물량 내역서
A1: 2026년 (07)월 물량 내역서
A2: ='용역청구서 표지'!$B$7 -> P4 Ph2 GAS&PCW 1공구 | M2: 단위 : 원
A3: 품 명 | B3: 규 격 | C3: 단위 | D3: W/P 수량 | E3: 단 가 | F3: 계 약 내 역 | H3: 전 회 누 계 물 량 | J3: 금 회 물 량 | L3: 누 계 물 량
F4: D/I 수량 | G4: 금액 | H4: D/I 수량 | I4: 금액 | J4: D/I 수량 | K4: 금액 | L4: D/I 수량 | M4: 금액
A6: WEDING POINT | B6: 8A | C6: POINT | D6: 0 | E6: 475000 | F6: =L6 -> 0 | G6: =M6 -> 0 | J6: =$D6*'DIA-INCH'!$C5 -> 0 | K6: =$E6*$J6 -> 0 | L6: =H6+J6 -> 0 | M6: =I6+K6 -> 0
A7: WEDING POINT | B7: 15A | C7: POINT | D7: 0 | E7: 475000 | F7: =L7 -> 0 | G7: =M7 -> 0 | J7: =$D7*'DIA-INCH'!$C6 -> 0 | K7: =$E7*$J7 -> 0 | L7: =H7+J7 -> 0 | M7: =I7+K7 -> 0
A8: WEDING POINT | B8: 20A | C8: POINT | D8: 0 | E8: 475000 | F8: =L8 -> 0 | G8: =M8 -> 0 | J8: =$D8*'DIA-INCH'!$C7 -> 0 | K8: =$E8*$J8 -> 0 | L8: =H8+J8 -> 0 | M8: =I8+K8 -> 0
A9: WEDING POINT | B9: 25A | C9: POINT | D9: 307 | E9: 475000 | F9: =L9 -> 574 | G9: =M9 -> 272650000 | H9: 267 | I9: 126825000 | J9: =$D9*'DIA-INCH'!$C8 -> 307 | K9: =$E9*$J9 -> 145825000 | L9: =H9+J9 -> 574 | M9: =I9+K9 -> 272650000
A10: WEDING POINT | B10: 32A | C10: POINT | D10: 0 | E10: 475000 | F10: =L10 -> 0 | G10: =M10 -> 0 | H10: 0 | I10: 0 | J10: =$D10*'DIA-INCH'!$C9 -> 0 | K10: =$E10*$J10 -> 0 | L10: =H10+J10 -> 0 | M10: =I10+K10 -> 0
A11: WEDING POINT | B11: 40A | C11: POINT | D11: 224 | E11: 475000 | F11: =L11 -> 573 | G11: =M11 -> 272175000 | H11: 237 | I11: 112575000 | J11: =$D11*'DIA-INCH'!$C10 -> 336 | K11: =$E11*$J11 -> 159600000 | L11: =H11+J11 -> 573 | M11: =I11+K11 -> 272175000
A12: WEDING POINT | B12: 50A | C12: POINT | D12: 62 | E12: 475000 | F12: =L12 -> 352 | G12: =M12 -> 167200000 | H12: 228 | I12: 108300000 | J12: =$D12*'DIA-INCH'!$C11 -> 124 | K12: =$E12*$J12 -> 58900000 | L12: =H12+J12 -> 352 | M12: =I12+K12 -> 167200000
A13: WEDING POINT | B13: 65A | C13: POINT | D13: 166 | E13: 475000 | F13: =L13 -> 592.5 | G13: =M13 -> 281437500 | H13: 177.5 | I13: 84312500 | J13: =$D13*'DIA-INCH'!$C12 -> 415 | K13: =$E13*$J13 -> 197125000 | L13: =H13+J13 -> 592.5 | M13: =I13+K13 -> 281437500
A14: WEDING POINT | B14: 80A | C14: POINT | D14: 74 | E14: 475000 | F14: =L14 -> 384 | G14: =M14 -> 182400000 | H14: 162 | I14: 76950000 | J14: =$D14*'DIA-INCH'!$C13 -> 222 | K14: =$E14*$J14 -> 105450000 | L14: =H14+J14 -> 384 | M14: =I14+K14 -> 182400000
A15: WEDING POINT | B15: 100A | C15: POINT | D15: 51 | E15: 475000 | F15: =L15 -> 608 | G15: =M15 -> 288800000 | H15: 404 | I15: 191900000 | J15: =$D15*'DIA-INCH'!$C14 -> 204 | K15: =$E15*$J15 -> 96900000 | L15: =H15+J15 -> 608 | M15: =I15+K15 -> 288800000
A16: WEDING POINT | B16: 110A | C16: POINT | D16: 0 | E16: 475000 | F16: =L16 -> 0 | G16: =M16 -> 0 | H16: 0 | I16: 0 | J16: =$D16*'DIA-INCH'!$C15 -> 0 | K16: =$E16*$J16 -> 0 | L16: =H16+J16 -> 0 | M16: =I16+K16 -> 0
A17: WEDING POINT | B17: 125A | C17: POINT | D17: 207 | E17: 475000 | F17: =L17 -> 1935 | G17: =M17 -> 919125000 | H17: 900 | I17: 427500000 | J17: =$D17*'DIA-INCH'!$C16 -> 1035 | K17: =$E17*$J17 -> 491625000 | L17: =H17+J17 -> 1935 | M17: =I17+K17 -> 919125000
A18: WEDING POINT | B18: 150A | C18: POINT | D18: 0 | E18: 475000 | F18: =L18 -> 0 | G18: =M18 -> 0 | H18: 0 | I18: 0 | J18: =$D18*'DIA-INCH'!$C17 -> 0 | K18: =$E18*$J18 -> 0 | L18: =H18+J18 -> 0 | M18: =I18+K18 -> 0
A19: WEDING POINT | B19: 175A | C19: POINT | D19: 0 | E19: 475000 | F19: =L19 -> 0 | G19: =M19 -> 0 | H19: 0 | I19: 0 | J19: =$D19*'DIA-INCH'!$C18 -> 0 | K19: =$E19*$J19 -> 0 | L19: =H19+J19 -> 0 | M19: =I19+K19 -> 0
A20: WEDING POINT | B20: 200A | C20: POINT | D20: 42 | E20: 475000 | F20: =L20 -> 1384 | G20: =M20 -> 657400000 | H20: 1048 | I20: 497800000 | J20: =$D20*'DIA-INCH'!$C19 -> 336 | K20: =$E20*$J20 -> 159600000 | L20: =H20+J20 -> 1384 | M20: =I20+K20 -> 657400000
A21: WEDING POINT | B21: 225A | C21: POINT | D21: 0 | E21: 475000 | F21: =L21 -> 0 | G21: =M21 -> 0 | J21: =$D21*'DIA-INCH'!$C20 -> 0 | K21: =$E21*$J21 -> 0 | L21: =H21+J21 -> 0 | M21: =I21+K21 -> 0
A22: WEDING POINT | B22: 250A | C22: POINT | D22: 2 | E22: 475000 | F22: =L22 -> 20 | G22: =M22 -> 9500000 | J22: =$D22*'DIA-INCH'!$C21 -> 20 | K22: =$E22*$J22 -> 9500000 | L22: =H22+J22 -> 20 | M22: =I22+K22 -> 9500000
A23: WEDING POINT | B23: 300A | C23: POINT | D23: 1 | E23: 475000 | F23: =L23 -> 12 | G23: =M23 -> 5700000 | J23: =$D23*'DIA-INCH'!$C22 -> 12 | K23: =$E23*$J23 -> 5700000 | L23: =H23+J23 -> 12 | M23: =I23+K23 -> 5700000
A24: WEDING POINT | B24: 350A | C24: POINT | D24: 0 | E24: 475000 | F24: =L24 -> 0 | G24: =M24 -> 0 | J24: =$D24*'DIA-INCH'!$C23 -> 0 | K24: =$E24*$J24 -> 0 | L24: =H24+J24 -> 0 | M24: =I24+K24 -> 0
A25: WEDING POINT | B25: 400A | C25: POINT | D25: 0 | E25: 475000 | F25: =L25 -> 0 | G25: =M25 -> 0 | J25: =$D25*'DIA-INCH'!$C24 -> 0 | K25: =$E25*$J25 -> 0 | L25: =H25+J25 -> 0 | M25: =I25+K25 -> 0
A26: WEDING POINT | B26: 450A | C26: POINT | D26: 0 | E26: 475000 | F26: =L26 -> 0 | G26: =M26 -> 0 | J26: =$D26*'DIA-INCH'!$C25 -> 0 | K26: =$E26*$J26 -> 0 | L26: =H26+J26 -> 0 | M26: =I26+K26 -> 0
A27: WEDING POINT | B27: 500A | C27: POINT | D27: 0 | E27: 475000 | F27: =L27 -> 0 | G27: =M27 -> 0 | J27: =$D27*'DIA-INCH'!$C26 -> 0 | K27: =$E27*$J27 -> 0 | L27: =H27+J27 -> 0 | M27: =I27+K27 -> 0
A28: WEDING POINT | B28: 550A | C28: POINT | D28: 0 | E28: 475000 | F28: =L28 -> 0 | G28: =M28 -> 0 | J28: =$D28*'DIA-INCH'!$C27 -> 0 | K28: =$E28*$J28 -> 0 | L28: =H28+J28 -> 0 | M28: =I28+K28 -> 0
A29: VALVE 설치비 | B29: 8A | C29: EA | D29: 0 | E29: =$E$32*'DIA-INCH'!$C5 -> 12500 | F29: =L29 -> 0 | G29: =M29 -> 0 | J29: =D29 -> 0 | K29: =$J29*$E29 -> 0 | L29: =H29+J29 -> 0 | M29: =I29+K29 -> 0
A30: VALVE 설치비 | B30: 15A | C30: EA | E30: =$E$32*'DIA-INCH'!$C6 -> 25000 | F30: =L30 -> 0 | G30: =M30 -> 0 | J30: =D30 -> 0 | K30: =$J30*$E30 -> 0 | L30: =H30+J30 -> 0 | M30: =I30+K30 -> 0
A31: VALVE 설치비 | B31: 20A | C31: EA | E31: =$E$32*'DIA-INCH'!$C7 -> 37500 | F31: =L31 -> 0 | G31: =M31 -> 0 | J31: =D31 -> 0 | K31: =$J31*$E31 -> 0 | L31: =H31+J31 -> 0 | M31: =I31+K31 -> 0
A32: VALVE 설치비 | B32: 25A | C32: EA | E32: 50000 | F32: =L32 -> 0 | G32: =M32 -> 0 | J32: =D32 -> 0 | K32: =$J32*$E32 -> 0 | L32: =H32+J32 -> 0 | M32: =I32+K32 -> 0
A33: VALVE 설치비 | B33: 32A | C33: EA | E33: =$E$32*'DIA-INCH'!$C9 -> 62500 | F33: =L33 -> 0 | G33: =M33 -> 0 | J33: =D33 -> 0 | K33: =$J33*$E33 -> 0 | L33: =H33+J33 -> 0 | M33: =I33+K33 -> 0
A34: VALVE 설치비 | B34: 40A | C34: EA | E34: =$E$32*'DIA-INCH'!$C10 -> 75000 | F34: =L34 -> 0 | G34: =M34 -> 0 | J34: =D34 -> 0 | K34: =$J34*$E34 -> 0 | L34: =H34+J34 -> 0 | M34: =I34+K34 -> 0
A35: VALVE 설치비 | B35: 50A | C35: EA | E35: =$E$32*'DIA-INCH'!$C11 -> 100000 | F35: =L35 -> 0 | G35: =M35 -> 0 | J35: =D35 -> 0 | K35: =$J35*$E35 -> 0 | L35: =H35+J35 -> 0 | M35: =I35+K35 -> 0
A36: VALVE 설치비 | B36: 65A | C36: EA | E36: =$E$32*'DIA-INCH'!$C12 -> 125000 | F36: =L36 -> 0 | G36: =M36 -> 0 | J36: =D36 -> 0 | K36: =$J36*$E36 -> 0 | L36: =H36+J36 -> 0 | M36: =I36+K36 -> 0
A37: VALVE 설치비 | B37: 80A | C37: EA | E37: =$E$32*'DIA-INCH'!$C13 -> 150000 | F37: =L37 -> 0 | G37: =M37 -> 0 | J37: =D37 -> 0 | K37: =$J37*$E37 -> 0 | L37: =H37+J37 -> 0 | M37: =I37+K37 -> 0
A38: VALVE 설치비 | B38: 100A | C38: EA | E38: =$E$32*'DIA-INCH'!$C14 -> 200000 | F38: =L38 -> 0 | G38: =M38 -> 0 | J38: =D38 -> 0 | K38: =$J38*$E38 -> 0 | L38: =H38+J38 -> 0 | M38: =I38+K38 -> 0
A39: VALVE 설치비 | B39: 110A | C39: EA | E39: =$E$32*'DIA-INCH'!$C15 -> 200000 | F39: =L39 -> 0 | G39: =M39 -> 0 | J39: =D39 -> 0 | K39: =$J39*$E39 -> 0 | L39: =H39+J39 -> 0 | M39: =I39+K39 -> 0
A40: VALVE 설치비 | B40: 125A | C40: EA | E40: =$E$32*'DIA-INCH'!$C16 -> 250000 | F40: =L40 -> 0 | G40: =M40 -> 0 | J40: =D40 -> 0 | K40: =$J40*$E40 -> 0 | L40: =H40+J40 -> 0 | M40: =I40+K40 -> 0
A41: VALVE 설치비 | B41: 150A | C41: EA | E41: =$E$32*'DIA-INCH'!$C17 -> 300000 | F41: =L41 -> 0 | G41: =M41 -> 0 | J41: =D41 -> 0 | K41: =$J41*$E41 -> 0 | L41: =H41+J41 -> 0 | M41: =I41+K41 -> 0
...

Sheet 근로내역 (07월)
A1: 2026년 ( 07 )월 일용 노무비명세서 | AH1: 현장명 | AM1: ='용역청구서 표지'!$B$7 -> P4 Ph2 GAS&PCW 1공구
AH2: 현장소장 | AM2: 조 수 원
AH3: 잡코드 | AM3: ='용역청구서 표지'!$C$8 -> S26-001
A5: 번호 | B5: 성명 | C5: 주민등록번호 | D5: 직종 | E5: 연락처(H.P) | F5: 은행명 | G5: 예금주 | H5: 계좌번호 | I5: 1 | J5: 2 | K5: 3 | L5: 4 | M5: 5 | N5: 6 | O5: 7 | P5: 8 | Q5: 9 | R5: 10 | S5: 11 | T5: 12 | U5: 13 | V5: 14 | W5: 15 | X5: 16 | Y5: 17 | Z5: 18 | AA5: 19 | AB5: 20 | AC5: 21 | AD5: 22 | AE5: 23 | AF5: 24 | AG5: 25 | AH5: 26 | AI5: 27 | AJ5: 28 | AK5: 29 | AL5: 30 | AM5: 31 | AN5: 공수 | AO5: 단가 | AP5: 총액
A6: 1 | B6: 강경호 | C6: 931011-1072918 | D6: 공사보조 | E6: 010-5396-5444 | F6: 신한 | G6: 강경호 | H6: 110-371-147243 | N6: 0.6875 | W6: 0.5 | X6: 1 | Y6: 1.3125 | AB6: 1 | AC6: 1.5 | AD6: 1 | AE6: 1.5 | AF6: 1 | AI6: 2 | AJ6: 2.25 | AK6: 2 | AL6: 2 | AM6: 2 | AN6: =SUM(I6:AM6) -> 19.75 | AO6: 180000 | AP6: =AN6*AO6 -> 3555000
A7: 2 | B7: 강동우 | C7: 810127-1026118 | D7: 공사보조 | E7: 010-5289-5546 | F7: 기업 | G7: 강동우 | H7: 186-094740-01-017 | I7: 2 | J7: 2 | N7: 2 | O7: 2 | P7: 2 | Q7: 2 | R7: 2 | U7: 2 | V7: 2 | W7: 2 | X7: 2 | AB7: 2 | AC7: 2 | AE7: 2 | AF7: 2 | AI7: 2 | AJ7: 2 | AK7: 2 | AL7: 2 | AM7: 2 | AN7: =SUM(I7:AM7) -> 40 | AO7: 240000 | AP7: =AN7*AO7 -> 9600000
A8: 3 | B8: 강상진 | C8: 990405-1637612 | D8: 보통인부 | E8: 010-5947-6218 | F8: 국민 | G8: 강상진 | H8: 944502-00-393239 | U8: 0.6875 | V8: 1.125 | X8: 0.625 | Y8: 1.5 | AC8: 1.5 | AD8: 1 | AE8: 1.5 | AF8: 1 | AG8: 1 | AJ8: 1.5 | AK8: 1 | AL8: 1.5 | AM8: 1 | AN8: =SUM(I8:AM8) -> 14.9375 | AO8: 160000 | AP8: =AN8*AO8 -> 2390000
A9: 4 | B9: 강은천 | C9: 740803-1155526 | D9: 배관공 | E9: 010-5131-8640 | F9: 하나 | G9: 강은천 | H9: 226-910131-79107 | I9: 2 | J9: 2 | K9: 2 | N9: 2 | O9: 2 | P9: 2 | Q9: 2 | R9: 2 | U9: 2 | V9: 2 | W9: 2 | X9: 2 | AC9: 2 | AD9: 2 | AE9: 2 | AF9: 2 | AI9: 2 | AJ9: 2 | AK9: 2 | AL9: 2 | AM9: 2 | AN9: =SUM(I9:AM9) -> 42 | AO9: 210000 | AP9: =AN9*AO9 -> 8820000
A10: 5 | B10: 강인기 | C10: 020528-3912419 | D10: 보통인부 | E10: 010-9325-6120 | F10: 농협 | G10: 강인기 | H10: 352-1618-5074-53 | I10: 2 | J10: 2 | K10: 2 | N10: 2 | O10: 2 | P10: 2 | Q10: 2 | R10: 2 | U10: 2 | V10: 2 | W10: 2 | X10: 2 | AB10: 2 | AC10: 2 | AD10: 2 | AE10: 2 | AF10: 2 | AI10: 2 | AJ10: 2 | AK10: 2 | AL10: 2 | AM10: 2 | AN10: =SUM(I10:AM10) -> 44 | AO10: 160000 | AP10: =AN10*AO10 -> 7040000
A11: 6 | B11: 강채연 | C11: 980703-2192257 | D11: 보통인부 | E11: 010-5725-9067 | F11: 국민 | G11: 강채연 | H11: 399102-04-168176 | I11: 1 | J11: 1.5 | K11: 1 | L11: 1 | N11: 1 | O11: 1.5 | P11: 1 | Q11: 1.5 | R11: 1 | S11: 1 | Y11: 1.5 | Z11: 1 | AB11: 1 | AC11: 1.5 | AD11: 1 | AE11: 1.5 | AF11: 0.875 | AG11: 1 | AI11: 1 | AJ11: 1.5 | AK11: 1 | AL11: 1.5 | AM11: 1 | AN11: =SUM(I11:AM11) -> 26.875 | AO11: 150000 | AP11: =AN11*AO11 -> 4031250
A12: 7 | B12: 강희수 | C12: 730210-1029411 | D12: 도비공 | E12: 010-9561-6101 | F12: 신한 | G12: 강희수 | H12: 110-490-486591 | I12: 2 | J12: 2 | K12: 2 | N12: 2 | O12: 2 | P12: 2 | Q12: 2 | R12: 2 | U12: 2 | V12: 2 | W12: 2 | X12: 2 | AB12: 2 | AC12: 2 | AD12: 2 | AE12: 2 | AF12: 2 | AI12: 2 | AJ12: 2 | AK12: 2 | AL12: 2 | AM12: 2 | AN12: =SUM(I12:AM12) -> 44 | AO12: 210000 | AP12: =AN12*AO12 -> 9240000
A13: 8 | B13: 고문희 | C13: 740220-2162312 | D13: 보통인부 | E13: 010-2831-9053 | F13: 우리 | G13: 고문희 | H13: 1002-759-441898 | I13: 1 | J13: 1.5 | K13: 1 | L13: 1 | N13: 2 | O13: 2 | P13: 2 | Q13: 2 | R13: 2 | U13: 2 | V13: 2 | W13: 2 | X13: 2 | AB13: 2 | AC13: 2 | AD13: 2 | AE13: 2 | AN13: =SUM(I13:AM13) -> 30.5 | AO13: 150000 | AP13: =AN13*AO13 -> 4575000
A14: 9 | B14: 공덕표 | C14: 700720-1841616 | D14: 보통인부 | E14: 010-9167-8097 | F14: 국민 | G14: 공덕표 | H14: 842401-01-592574 | AB14: 0.6875 | AC14: 1.125 | AE14: 0.75 | AF14: 1 | AI14: 1 | AJ14: 1.5 | AK14: 0.5 | AN14: =SUM(I14:AM14) -> 6.5625 | AO14: 160000 | AP14: =AN14*AO14 -> 1050000
A15: 10 | B15: 구문정 | C15: 681118-2567718 | D15: 보통인부 | E15: 010-8180-1166 | F15: 농협 | G15: 구문정 | H15: 302-0278-3068-51 | I15: 1 | J15: 1.5 | L15: 1 | N15: 1 | O15: 1.5 | P15: 1 | Q15: 1.5 | R15: 1 | AN15: =SUM(I15:AM15) -> 9.5 | AO15: 150000 | AP15: =AN15*AO15 -> 1425000
A16: 11 | B16: 구윤하 | C16: 680130-2162814 | D16: 보통인부 | E16: 010-3259-2177 | F16: 하나 | G16: 구윤하 | H16: 206-910258-60907 | J16: 1.5 | K16: 1 | L16: 1 | N16: 1 | O16: 1.5 | P16: 1 | Q16: 1.5 | R16: 0.5 | U16: 1 | V16: 1 | W16: 1 | AN16: =SUM(I16:AM16) -> 12 | AO16: 150000 | AP16: =AN16*AO16 -> 1800000
A17: 12 | B17: 권국진 | C17: 690215-1017539 | D17: 보통인부 | E17: 010-4346-0215 | F17: 국민 | G17: 권국진 | H17: 357-21-0173-310 | N17: 0.6875 | O17: 1.125 | Q17: 0.625 | R17: 1 | U17: 1 | V17: 1.5 | W17: 1 | X17: 1.5 | Y17: 1.5 | Z17: 1 | AB17: 0.5 | AC17: 2 | AD17: 2 | AE17: 2 | AF17: 2 | AI17: 2 | AJ17: 2 | AK17: 2 | AL17: 2 | AM17: 2 | AN17: =SUM(I17:AM17) -> 29.4375 | AO17: 170000 | AP17: =AN17*AO17 -> 5004375
A18: 13 | B18: 권도훈 | C18: 991206-1353015 | D18: 보통인부 | E18: 010-5871-9352 | F18: 국민 | G18: 권도훈 | H18: 411801-04-442755 | AB18: 0.6875 | AC18: 1.125 | AE18: 0.75 | AF18: 1 | AI18: 1 | AJ18: 1.5 | AK18: 1 | AL18: 1.5 | AM18: 1 | AN18: =SUM(I18:AM18) -> 9.5625 | AO18: 160000 | AP18: =AN18*AO18 -> 1530000
A19: 14 | B19: 권두현 | C19: 830922-1657014 | D19: 용접공 | E19: 010-2231-4274 | F19: 새마을금고 | G19: 권두현 | H19: 9004-0039-5082-5 | I19: 1 | J19: 1.5 | K19: 1 | N19: 1 | O19: 1.5 | Q19: 1.5 | R19: 1 | U19: 1 | V19: 1.5 | W19: 1 | X19: 1.5 | Y19: 1.5 | AC19: 2 | AD19: 2 | AE19: 2 | AF19: 2 | AI19: 2 | AJ19: 2 | AK19: 2 | AL19: 2 | AM19: 2 | AN19: =SUM(I19:AM19) -> 33 | AO19: 250000 | AP19: =AN19*AO19 -> 8250000
A20: 15 | B20: 권중섭 | C20: 830806-1697210 | D20: 배관공 | E20: 010-9742-9790 | F20: 신한 | G20: 권중섭 | H20: 110-430-392742 | I20: 2 | J20: 2 | K20: 2 | N20: 2 | O20: 2 | P20: 2 | Q20: 2 | R20: 2 | U20: 1 | V20: 2 | W20: 2 | X20: 2 | AB20: 2 | AC20: 2 | AD20: 2 | AE20: 2 | AF20: 2 | AI20: 2 | AJ20: 2 | AK20: 2 | AL20: 2 | AM20: 2 | AN20: =SUM(I20:AM20) -> 43 | AO20: 240000 | AP20: =AN20*AO20 -> 10320000
A21: 16 | B21: 기정태 | C21: 761027-1535918 | D21: 보통인부 | E21: 010-6333-7295 | F21: 산림조합 | G21: 기정태 | H21: 512-13-0012018 | AB21: 0.6875 | AC21: 1.125 | AE21: 0.75 | AF21: 1 | AI21: 1 | AJ21: 1.5 | AK21: 1 | AL21: 1.5 | AM21: 1 | AN21: =SUM(I21:AM21) -> 9.5625 | AO21: 160000 | AP21: =AN21*AO21 -> 1530000
A22: 17 | B22: 김대건 | C22: 750225-1037523 | D22: 배관공 | E22: 010-8399-8169 | F22: 국민 | G22: 김대건 | H22: 452501-01-146387 | I22: 1 | J22: 1.5 | K22: 1 | L22: 1 | N22: 1 | O22: 1.5 | P22: 0.875 | Q22: 1.5 | R22: 1 | S22: 1 | U22: 2 | V22: 2 | W22: 2 | X22: 2 | AB22: 2 | AC22: 2 | AD22: 2 | AE22: 2 | AF22: 2 | AI22: 2 | AJ22: 2 | AK22: 2 | AL22: 2 | AM22: 2 | AN22: =SUM(I22:AM22) -> 39.375 | AO22: 220000 | AP22: =AN22*AO22 -> 8662500
A23: 18 | B23: 김대욱 | C23: 890712-1058810 | D23: 용접공 | E23: 010-3646-9962 | F23: 신한 | G23: 김대욱 | H23: 110-248-997659 | I23: 2 | J23: 2 | K23: 2 | N23: 2 | O23: 2 | P23: 2 | Q23: 2 | R23: 2 | U23: 2 | V23: 2 | W23: 2 | X23: 2 | AB23: 2 | AC23: 2 | AD23: 2 | AE23: 2 | AF23: 2 | AI23: 2 | AJ23: 2 | AK23: 2 | AL23: 2 | AM23: 2 | AN23: =SUM(I23:AM23) -> 44 | AO23: 240000 | AP23: =AN23*AO23 -> 10560000
A24: 19 | B24: 김대환 | C24: 861013-1652817 | D24: 배관공 | E24: 010-7523-3699 | F24: 농협 | G24: 김대환 | H24: 669-02-331305 | I24: 2 | J24: 2 | K24: 2 | N24: 2 | O24: 2 | P24: 2 | Q24: 2 | R24: 2 | U24: 2 | V24: 2 | W24: 2 | X24: 2 | AB24: 2 | AC24: 2 | AD24: 2 | AE24: 2 | AF24: 2 | AI24: 2 | AJ24: 2 | AK24: 2 | AL24: 2 | AM24: 2 | AN24: =SUM(I24:AM24) -> 44 | AO24: 240000 | AP24: =AN24*AO24 -> 10560000
A25: 20 | B25: 김도윤 | C25: 980306-1774616 | D25: 보통인부 | E25: 010-8024-3113 | F25: 카카오 | G25: 김도윤 | H25: 3333-17-8490304 | N25: 0.6875 | O25: 1.125 | Q25: 0.625 | R25: 1 | U25: 1 | V25: 1.5 | W25: 1 | X25: 1.5 | Y25: 1.5 | Z25: 1 | AB25: 1 | AC25: 1.5 | AD25: 1 | AE25: 1.5 | AF25: 1 | AN25: =SUM(I25:AM25) -> 16.9375 | AO25: 150000 | AP25: =AN25*AO25 -> 2540625
A26: 21 | B26: 김동욱 | C26: 810302-1830628 | D26: 배관공 | E26: 010-5022-0444 | F26: 농협 | G26: 김동욱 | H26: 302-5022-0444-11 | I26: 2 | J26: 2 | K26: 2 | N26: 2 | O26: 2 | P26: 2 | Q26: 2 | R26: 2 | U26: 2 | V26: 2 | AB26: 2 | AC26: 2 | AD26: 2 | AE26: 2 | AF26: 2 | AN26: =SUM(I26:AM26) -> 30 | AO26: 210000 | AP26: =AN26*AO26 -> 6300000
A27: 22 | B27: 김마태 | C27: 830224-1912010 | D27: 배관공 | E27: 010-2725-6089 | F27: 기업 | G27: 김마태 | H27: 175-073189-01-013 | I27: 2 | J27: 2 | K27: 2 | N27: 2 | O27: 2 | P27: 2 | Q27: 2 | R27: 2 | U27: 2 | V27: 2 | X27: 2 | AB27: 2 | AC27: 2 | AD27: 2 | AE27: 2 | AF27: 2 | AI27: 2 | AJ27: 2 | AK27: 2 | AL27: 2 | AM27: 2 | AN27: =SUM(I27:AM27) -> 42 | AO27: 250000 | AP27: =AN27*AO27 -> 10500000
A28: 23 | B28: 김명진 | C28: 960625-1106422 | D28: 보통인부 | E28: 010-2029-3976 | F28: 국민 | G28: 김명진 | H28: 101401-04-172575 | N28: 0.6875 | O28: 1.125 | Q28: 0.625 | R28: 1 | U28: 1 | V28: 1.5 | W28: 1 | X28: 1.5 | Y28: 1.5 | Z28: 1 | AC28: 2 | AD28: 2 | AE28: 2 | AF28: 2 | AI28: 2 | AJ28: 2 | AK28: 2 | AL28: 2 | AM28: 2 | AN28: =SUM(I28:AM28) -> 28.9375 | AO28: 160000 | AP28: =AN28*AO28 -> 4630000
A29: 24 | B29: 김민재 | C29: 940217-1474315 | D29: 배관공 | E29: 010-9961-0647 | F29: 국민 | G29: 김민재 | H29: 240801-04-477184 | I29: 1 | J29: 1.5 | K29: 1 | L29: 1 | N29: 1 | O29: 0.5 | P29: 1 | Q29: 1.5 | R29: 1 | S29: 0.875 | U29: 1 | V29: 1.5 | W29: 1 | X29: 1.5 | Y29: 1.5 | Z29: 0.125 | AB29: 1 | AC29: 1.5 | AD29: 1 | AE29: 1.5 | AF29: 1 | AG29: 1 | AI29: 1 | AJ29: 1.5 | AK29: 1 | AL29: 1.5 | AM29: 1 | AN29: =SUM(I29:AM29) -> 30 | AO29: 230000 | AP29: =AN29*AO29 -> 6900000
A30: 25 | B30: 김민지 | C30: 850908-2661019 | D30: 보통인부 | E30: 010-3173-2826 | F30: 국민 | G30: 김민지 | H30: 240801-04-433155 | I30: 2 | J30: 2 | K30: 2 | N30: 2 | O30: 2 | P30: 2 | Q30: 2 | R30: 2 | U30: 0.5 | V30: 2 | W30: 2 | X30: 2 | AB30: 2 | AC30: 2 | AD30: 2 | AE30: 2 | AF30: 2 | AI30: 2 | AJ30: 2 | AK30: 2 | AL30: 2 | AM30: 2 | AN30: =SUM(I30:AM30) -> 42.5 | AO30: 150000 | AP30: =AN30*AO30 -> 6375000
A31: 26 | B31: 김상덕 | C31: 700819-1454911 | D31: 도비공 | E31: 010-7133-1786 | F31: 농협 | G31: 김상덕 | H31: 356-0915-2372-03 | I31: 1 | J31: 1.5 | K31: 1 | L31: 1 | N31: 1 | O31: 1.5 | P31: 1 | Q31: 1.5 | R31: 1 | S31: 1 | U31: 1 | V31: 1.5 | W31: 1 | X31: 1.5 | Y31: 1.5 | Z31: 1 | AB31: 1 | AC31: 1.5 | AD31: 1 | AE31: 1.5 | AF31: 1 | AG31: 1 | AN31: =SUM(I31:AM31) -> 26 | AO31: 220000 | AP31: =AN31*AO31 -> 5720000
A32: 27 | B32: 김상수 | C32: 760616-1535318 | D32: 보통인부 | E32: 010-4812-3459 | F32: 농협 | G32: 김상수 | H32: 351-0468-2919-93 | N32: 0.6875 | O32: 1.125 | AE32: 0.75 | AF32: 1 | AJ32: 1.5 | AK32: 1 | AL32: 1.5 | AM32: 1 | AN32: =SUM(I32:AM32) -> 8.5625 | AO32: 160000 | AP32: =AN32*AO32 -> 1370000
A33: 28 | B33: 김상협 | C33: 830218-1011315 | D33: 안전보조 | E33: 010-6891-5399 | F33: 국민 | G33: 김상협 | H33: 847501-00-029520 | I33: 1 | J33: 1.5 | K33: 1 | L33: 1 | N33: 1 | O33: 1.5 | P33: 0.75 | Q33: 1.5 | R33: 1 | S33: 1 | U33: 2 | V33: 2 | W33: 2 | X33: 2 | AB33: 2 | AC33: 2 | AD33: 2 | AE33: 2 | AF33: 2 | AJ33: 2 | AK33: 2 | AL33: 2 | AM33: 2 | AN33: =SUM(I33:AM33) -> 37.25 | AO33: 190000 | AP33: =AN33*AO33 -> 7077500
A34: 29 | B34: 김성화 | C34: 731015-1650916 | D34: 보통인부 | E34: 010-8743-5551 | F34: 국민 | G34: 김성화 | H34: 055202-04-122285 | I34: 0.5 | K34: 1 | L34: 1 | N34: 1 | O34: 1.5 | P34: 1 | Q34: 1.5 | R34: 1 | S34: 1 | V34: 1.5 | W34: 1 | X34: 1.5 | Y34: 1.5 | Z34: 1 | AB34: 1 | AN34: =SUM(I34:AM34) -> 17 | AO34: 160000 | AP34: =AN34*AO34 -> 2720000
A35: 30 | B35: 김성환 | C35: 861202-1005916 | D35: 보통인부 | E35: 010-7334-3400 | F35: 신한 | G35: 김성환 | H35: 110-447-207320 | I35: 1 | K35: 1 | N35: 1 | O35: 1.5 | P35: 1 | Q35: 1.5 | R35: 1 | S35: 1 | U35: 1 | W35: 1 | X35: 1.5 | Y35: 1.5 | AN35: =SUM(I35:AM35) -> 14 | AO35: 170000 | AP35: =AN35*AO35 -> 2380000
A36: 31 | B36: 김세관 | C36: 860815-1912515 | D36: 도비공 | E36: 010-4171-9729 | F36: 카카오 | G36: 김세관 | H36: 3333-08-5239539 | N36: 0.6875 | O36: 1.125 | P36: 0.5 | Q36: 0.625 | R36: 1 | U36: 1 | V36: 1.5 | W36: 1 | X36: 1.5 | Y36: 1.5 | Z36: 1 | AC36: 2 | AD36: 2 | AE36: 2 | AF36: 2 | AI36: 2 | AJ36: 2 | AK36: 2 | AL36: 2 | AM36: 2 | AN36: =SUM(I36:AM36) -> 29.4375 | AO36: 200000 | AP36: =AN36*AO36 -> 5887500
A37: 32 | B37: 김세한 | C37: 721013-1067215 | D37: 보통인부 | E37: 010-8848-5060 | F37: 하나 | G37: 김세한 | H37: 298-910970-10507 | I37: 2 | J37: 2 | K37: 2 | N37: 2 | O37: 2 | P37: 2 | Q37: 2 | R37: 2 | U37: 2 | V37: 2 | W37: 2 | X37: 2 | AB37: 2 | AC37: 2 | AD37: 2 | AE37: 2 | AF37: 2 | AI37: 2 | AJ37: 2 | AK37: 2 | AL37: 2 | AM37: 2 | AN37: =SUM(I37:AM37) -> 44 | AO37: 160000 | AP37: =AN37*AO37 -> 7040000
A38: 33 | B38: 김슬기 | C38: 940216-2476212 | D38: 보통인부 | E38: 010-4565-0216 | F38: 카카오 | G38: 김슬기 | H38: 3333-26-1255102 | N38: 0.6875 | O38: 1.125 | Q38: 0.625 | R38: 1 | U38: 1 | V38: 1.5 | W38: 1 | X38: 1 | Y38: 1.5 | Z38: 1 | AB38: 1 | AC38: 1.5 | AD38: 1 | AE38: 1.5 | AF38: 1 | AG38: 1 | AI38: 1 | AJ38: 1.5 | AK38: 1 | AL38: 1.5 | AM38: 0.5 | AN38: =SUM(I38:AM38) -> 22.9375 | AO38: 150000 | AP38: =AN38*AO38 -> 3440625
A39: 34 | B39: 김용기 | C39: 860712-1036817 | D39: 배관공 | E39: 010-2222-3295 | F39: 국민 | G39: 김용기 | H39: 442802-01-189872 | I39: 1 | J39: 1.5 | K39: 1 | L39: 1 | N39: 1 | O39: 1.5 | P39: 1 | Q39: 1.5 | R39: 1 | S39: 1 | U39: 2 | V39: 2 | W39: 2 | X39: 2 | AB39: 2 | AC39: 2 | AD39: 2 | AE39: 2 | AF39: 2 | AI39: 2 | AJ39: 2 | AK39: 2 | AL39: 2 | AM39: 2 | AN39: =SUM(I39:AM39) -> 39.5 | AO39: 220000 | AP39: =AN39*AO39 -> 8690000
A40: 35 | B40: 김의찬 | C40: 810916-1090421 | D40: 보통인부 | E40: 010-7748-9382 | F40: 국민 | G40: 김의찬 | H40: 121802-04-157456 | I40: 2 | J40: 2 | K40: 2 | N40: 2 | O40: 2 | P40: 2 | Q40: 2 | R40: 2 | U40: 2 | V40: 2 | W40: 2 | X40: 2 | AB40: 2 | AC40: 2 | AD40: 2 | AE40: 2 | AF40: 2 | AI40: 2 | AJ40: 2 | AK40: 2 | AL40: 2 | AM40: 2 | AN40: =SUM(I40:AM40) -> 44 | AO40: 170000 | AP40: =AN40*AO40 -> 7480000
A41: 36 | B41: 김재윤 | C41: 861216-1157613 | D41: 용접공 | E41: 010-3955-1110 | F41: 신한 | G41: 김재윤 | H41: 110-305-768530 | I41: 2 | J41: 2 | K41: 2 | N41: 2 | O41: 2 | P41: 2 | Q41: 2 | R41: 2 | U41: 2 | V41: 2 | W41: 2 | X41: 2 | AB41: 2 | AC41: 2 | AD41: 2 | AE41: 2 | AF41: 2 | AI41: 2 | AJ41: 2 | AK41: 2 | AL41: 2 | AM41: 2 | AN41: =SUM(I41:AM41) -> 44 | AO41: 250000 | AP41: =AN41*AO41 -> 11000000
...

Sheet 숙소임차료
A1: 숙소 임차료
A2: No. | B2: 납부일 | C2: 구분 | D2: 품명 | E2: 주소 | F2: 호수 | G2: 수량 | H2: 사용인원 | I2: 임차료 | J2: 비 고
I3: =SUM(I4:I44) -> 65210000 | L3: 입력해야하는 항목 외 수정 금지
A4: 1 | B4: 46234 | C4: KC대납 임대료 | D4: 숙소임대료(07월분) | E4: 평택시 고덕여염12길 27 401호 | F4: 401호 | G4: 1 | H4: 6 | I4: 1400000 | J4: KC 대납 | L4: 납부일
A5: 2 | B5: 46234 | C5: KC대납 임대료 | D5: 숙소임대료(07월분) | E5: 평택시 고덕여염11길 149 202호 | F5: 202호 | G5: 1 | H5: 6 | I5: 1900000 | J5: KC 대납 | L5: 구분
A6: 3 | B6: 46234 | C6: KC대납 임대료 | D6: 숙소임대료(07월분) | E6: 평택시 함박산1길 50 401호 | F6: 401호 | G6: 1 | H6: 6 | I6: 1700000 | J6: KC 대납 | L6: 품명
A7: 4 | B7: 46234 | C7: KC대납 임대료 | D7: 숙소임대료(07월분) | E7: 평택시 함박산4길 3 301호 | F7: 301호 | G7: 1 | H7: 6 | I7: 1530000 | J7: KC 대납 | L7: 주소
A8: 5 | B8: 46234 | C8: KC대납 임대료 | D8: 숙소임대료(07월분) | E8: 평택시 고덕갈평10길 40 202호 | F8: 202호 | G8: 1 | H8: 6 | I8: 1600000 | J8: KC 대납 | L8: 호수
A9: 6 | B9: 46234 | C9: KC대납 임대료 | D9: 숙소임대료(07월분) | E9: 평택시 함박산3길 37 301호 | F9: 301호 | G9: 1 | H9: 6 | I9: 1600000 | J9: KC 대납 | L9: 수량
A10: 7 | B10: 46234 | C10: KC대납 임대료 | D10: 숙소임대료(07월분) | E10: 평택시 함박산9길 28 401호(복층) | F10: 복층) | G10: 1 | H10: 6 | I10: 2000000 | J10: KC 대납 | L10: 사용인원
A11: 8 | B11: 46234 | C11: KC대납 임대료 | D11: 숙소임대료(07월분) | E11: 평택시 함박산12길 35 301호 | F11: 301호 | G11: 1 | H11: 6 | I11: 1800000 | J11: KC 대납
A12: 9 | B12: 46234 | C12: KC대납 임대료 | D12: 숙소임대료(07월분) | E12: 평택시 함박산1길 34 201호 | F12: 201호 | G12: 1 | H12: 6 | I12: 1700000 | J12: KC 대납 | L12: ■ 구분은 [KC대납 임대료 및 임대료] 이외 항목은 입력금지
A13: 10 | B13: 46234 | C13: KC대납 임대료 | D13: 숙소임대료(07월분) | E13: 평택시 고덕국제4길 60-16 202호 | F13: 202호 | G13: 1 | H13: 6 | I13: 1600000 | J13: KC 대납
A14: 11 | B14: 46234 | C14: KC대납 임대료 | D14: 숙소임대료(07월분) | E14: 평택시 고덕여염16길 113 202호 | F14: 202호 | G14: 1 | H14: 6 | I14: 1900000 | J14: KC 대납
A15: 12 | B15: 46234 | C15: KC대납 임대료 | D15: 숙소임대료(07월분) | E15: 평택시 고덕여염6길 199 202호 | F15: 202호 | G15: 1 | H15: 6 | I15: 1800000 | J15: KC 대납
A16: 13 | B16: 46234 | C16: KC대납 임대료 | D16: 숙소임대료(07월분) | E16: 평택시 함박산1길 34 301호 | F16: 301호 | G16: 1 | H16: 6 | I16: 1700000 | J16: KC 대납
A17: 14 | B17: 46234 | C17: KC대납 임대료 | D17: 숙소임대료(07월분) | E17: 평택시 함박산9길 26 202호 | F17: 202호 | G17: 1 | H17: 6 | I17: 1600000 | J17: KC 대납
A18: 15 | B18: 46234 | C18: KC대납 임대료 | D18: 숙소임대료(07월분) | E18: 평택시 함박산11길 9-1 202호 | F18: 202호 | G18: 1 | H18: 6 | I18: 1650000 | J18: KC 대납
A19: 16 | B19: 46234 | C19: KC대납 임대료 | D19: 숙소임대료(07월분) | E19: 평택시 함박산3길 11 301호 | F19: 301호 | G19: 1 | H19: 6 | I19: 1900000 | J19: KC 대납
A20: 17 | B20: 46234 | C20: KC대납 임대료 | D20: 숙소임대료(07월분) | E20: 평택시 고덕여염16길 115 202호 | F20: 202호 | G20: 1 | H20: 4 | I20: 1400000 | J20: KC 대납
A21: 18 | B21: 46234 | C21: KC대납 임대료 | D21: 숙소임대료(07월분) | E21: 평택시 함박산9길 26 201호 | F21: 201호 | G21: 1 | H21: 6 | I21: 1800000 | J21: KC 대납
A22: 19 | B22: 46234 | C22: KC대납 임대료 | D22: 숙소임대료(07월분) | E22: 평택시 고덕국제4길 60-10 202호 | F22: 202호 | G22: 1 | H22: 6 | I22: 1650000 | J22: KC 대납
A23: 20 | B23: 46234 | C23: KC대납 임대료 | D23: 숙소임대료(07월분) | E23: 평택시 함박산2길 11 302호 | F23: 302호 | G23: 1 | H23: 6 | I23: 1500000 | J23: KC 대납
A24: 21 | B24: 46234 | C24: KC대납 임대료 | D24: 숙소임대료(07월분) | E24: 평택시 함박산8길 13 201호 | F24: 201호 | G24: 1 | H24: 6 | I24: 1650000 | J24: KC 대납
... A44: 41 | B44: 46234 | C44: KC대납 임대료 | D44: 숙소임대료(07월분) | E44: 평택시 고덕여염11길 14 202호 | F44: 202호 | G44: 1 | H44: 4 | I44: 1300000 | J44: KC 대납

Sheet 숙소관리비
A1: 숙소 관리비
A2: No. | B2: 납부일 | C2: 구분 | D2: 품명 | E2: 주소 | F2: 호수 | G2: 수량 | H2: 사용인원 | I2: 관리비 | J2: 비 고
I3: =SUM(I4:I127) -> 3409210
A4: 1 | B4: 46234 | C4: KC대납 관리비 | D4: 숙소수도세(07월분) | E4: 평택시 고덕여염12길 27 401호 | F4: 401호 | G4: 1 | H4: 6 | I4: 익월청구 | J4: KC 대납
A5: 2 | B5: - | C5: KC대납 관리비 | D5: 숙소가스료(07월분) | E5: 평택시 고덕여염12길 27 401호 | F5: 401호 | G5: 1 | H5: 6 | I5: 혹서기로 익월고지 | J5: KC 대납
A6: 3 | B6: 46234 | C6: KC대납 관리비 | D6: 숙소전기료(07월분) | E6: 평택시 고덕여염12길 27 401호 | F6: 401호 | G6: 1 | H6: 6 | I6: 6890 | J6: KC 대납
A7: 4 | B7: 46234 | C7: KC대납 관리비 | D7: 숙소수도세(07월분) | E7: 평택시 고덕여염11길 149 202호 | F7: 202호 | G7: 1 | H7: 6 | I7: 14870 | J7: KC 대납
A8: 5 | B8: - | C8: KC대납 관리비 | D8: 숙소가스료(07월분) | E8: 평택시 고덕여염11길 149 202호 | F8: 202호 | G8: 1 | H8: 6 | I8: 혹서기로 익월고지 | J8: KC 대납
A9: 6 | B9: 46234 | C9: KC대납 관리비 | D9: 숙소전기료(07월분) | E9: 평택시 고덕여염11길 149 202호 | F9: 202호 | G9: 1 | H9: 6 | I9: 48730 | J9: KC 대납
A10: 7 | B10: 46234 | C10: KC대납 관리비 | D10: 숙소수도세(07월분) | E10: 평택시 함박산1길 50 401호 | F10: 401호 | G10: 1 | H10: 6 | I10: 28850 | J10: KC 대납
A11: 8 | B11: - | C11: KC대납 관리비 | D11: 숙소가스료(07월분) | E11: 평택시 함박산1길 50 401호 | F11: 401호 | G11: 1 | H11: 6 | I11: 혹서기로 익월고지 | J11: KC 대납
A12: 9 | B12: 46234 | C12: KC대납 관리비 | D12: 숙소전기료(07월분) | E12: 평택시 함박산1길 50 401호 | F12: 401호 | G12: 1 | H12: 6 | I12: 130100 | J12: KC 대납
A13: 10 | B13: 46234 | C13: KC대납 관리비 | D13: 숙소수도세(07월분) | E13: 평택시 함박산4길 3 301호 | F13: 301호 | G13: 1 | H13: 6 | I13: 익월청구 | J13: KC 대납
A14: 11 | B14: - | C14: KC대납 관리비 | D14: 숙소가스료(07월분) | E14: 평택시 함박산4길 3 301호 | F14: 301호 | G14: 1 | H14: 6 | I14: 혹서기로 익월고지 | J14: KC 대납
A15: 12 | B15: 46234 | C15: KC대납 관리비 | D15: 숙소전기료(07월분) | E15: 평택시 함박산4길 3 301호 | F15: 301호 | G15: 1 | H15: 6 | I15: 30010 | J15: KC 대납
A16: 13 | B16: 46234 | C16: KC대납 관리비 | D16: 숙소수도세(07월분) | E16: 평택시 고덕갈평10길 40 202호 | F16: 202호 | G16: 1 | H16: 6 | I16: 32310 | J16: KC 대납
A17: 14 | B17: - | C17: KC대납 관리비 | D17: 숙소가스료(07월분) | E17: 평택시 고덕갈평10길 40 202호 | F17: 202호 | G17: 1 | H17: 6 | I17: 혹서기로 익월고지 | J17: KC 대납
A18: 15 | B18: 46234 | C18: KC대납 관리비 | D18: 숙소전기료(07월분) | E18: 평택시 고덕갈평10길 40 202호 | F18: 202호 | G18: 1 | H18: 6 | I18: 49810 | J18: KC 대납
A19: 16 | B19: 46234 | C19: KC대납 관리비 | D19: 숙소수도세(07월분) | E19: 평택시 함박산3길 37 301호 | F19: 301호 | G19: 1 | H19: 6 | I19: 47870 | J19: KC 대납
A20: 17 | B20: - | C20: KC대납 관리비 | D20: 숙소가스료(07월분) | E20: 평택시 함박산3길 37 301호 | F20: 301호 | G20: 1 | H20: 6 | I20: 혹서기로 익월고지 | J20: KC 대납
A21: 18 | B21: 46234 | C21: KC대납 관리비 | D21: 숙소전기료(07월분) | E21: 평택시 함박산3길 37 301호 | F21: 301호 | G21: 1 | H21: 6 | I21: 83710 | J21: KC 대납
A22: 19 | B22: 46234 | C22: KC대납 관리비 | D22: 숙소수도세(07월분) | E22: 평택시 함박산9길 28 401호(복층) | F22: 복층) | G22: 1 | H22: 6 | I22: 18480 | J22: KC 대납
A23: 20 | B23: - | C23: KC대납 관리비 | D23: 숙소가스료(07월분) | E23: 평택시 함박산9길 28 401호(복층) | F23: 복층) | G23: 1 | H23: 6 | I23: 혹서기로 익월고지 | J23: KC 대납
A24: 21 | B24: 46234 | C24: KC대납 관리비 | D24: 숙소전기료(07월분) | E24: 평택시 함박산9길 28 401호(복층) | F24: 복층) | G24: 1 | H24: 6 | I24: 59770 | J24: KC 대납
A25: 22 | B25: 46234 | C25: KC대납 관리비 | D25: 숙소수도세(07월분) | E25: 평택시 함박산12길 35 301호 | F25: 301호 | G25: 1 | H25: 6 | I25: 익월청구 | J25: KC 대납
A26: 23 | B26: - | C26: KC대납 관리비 | D26: 숙소가스료(07월분) | E26: 평택시 함박산12길 35 301호 | F26: 301호 | G26: 1 | H26: 6 | I26: 혹서기로 익월고지 | J26: KC 대납
A27: 24 | B27: 46234 | C27: KC대납 관리비 | D27: 숙소전기료(07월분) | E27: 평택시 함박산12길 35 301호 | F27: 301호 | G27: 1 | H27: 6 | I27: 43430 | J27: KC 대납
A28: 25 | B28: 46234 | C28: KC대납 관리비 | D28: 숙소수도세(07월분) | E28: 평택시 함박산1길 34 201호 | F28: 201호 | G28: 1 | H28: 6 | I28: 360 | J28: KC 대납
A29: 26 | B29: - | C29: KC대납 관리비 | D29: 숙소가스료(07월분) | E29: 평택시 함박산1길 34 201호 | F29: 201호 | G29: 1 | H29: 6 | I29: 혹서기로 익월고지 | J29: KC 대납
A30: 27 | B30: 46234 | C30: KC대납 관리비 | D30: 숙소전기료(07월분) | E30: 평택시 함박산1길 34 201호 | F30: 201호 | G30: 1 | H30: 6 | I30: 57280 | J30: KC 대납
A31: 28 | B31: 46234 | C31: KC대납 관리비 | D31: 숙소수도세(07월분) | E31: 평택시 고덕국제4길 60-16 202호 | F31: 202호 | G31: 1 | H31: 6 | I31: 18480 | J31: KC 대납
A32: 29 | B32: - | C32: KC대납 관리비 | D32: 숙소가스료(07월분) | E32: 평택시 고덕국제4길 60-16 202호 | F32: 202호 | G32: 1 | H32: 6 | I32: 혹서기로 익월고지 | J32: KC 대납
A33: 30 | B33: 46234 | C33: KC대납 관리비 | D33: 숙소전기료(07월분) | E33: 평택시 고덕국제4길 60-16 202호 | F33: 202호 | G33: 1 | H33: 6 | I33: 58480 | J33: KC 대납
A34: 31 | B34: 46234 | C34: KC대납 관리비 | D34: 숙소수도세(07월분) | E34: 평택시 고덕여염16길 113 202호 | F34: 202호 | G34: 1 | H34: 6 | I34: 2920 | J34: KC 대납
A35: 32 | B35: - | C35: KC대납 관리비 | D35: 숙소가스료(07월분) | E35: 평택시 고덕여염16길 113 202호 | F35: 202호 | G35: 1 | H35: 6 | I35: 혹서기로 익월고지 | J35: KC 대납
A36: 33 | B36: 46234 | C36: KC대납 관리비 | D36: 숙소전기료(07월분) | E36: 평택시 고덕여염16길 113 202호 | F36: 202호 | G36: 1 | H36: 6 | I36: 68670 | J36: KC 대납
A37: 34 | B37: 46234 | C37: KC대납 관리비 | D37: 숙소수도세(07월분) | E37: 평택시 고덕여염6길 199 202호 | F37: 202호 | G37: 1 | H37: 6 | I37: 21940 | J37: KC 대납
A38: 35 | B38: - | C38: KC대납 관리비 | D38: 숙소가스료(07월분) | E38: 평택시 고덕여염6길 199 202호 | F38: 202호 | G38: 1 | H38: 6 | I38: 혹서기로 익월고지 | J38: KC 대납
A39: 36 | B39: 46234 | C39: KC대납 관리비 | D39: 숙소전기료(07월분) | E39: 평택시 고덕여염6길 199 202호 | F39: 202호 | G39: 1 | H39: 6 | I39: 86210 | J39: KC 대납
A40: 37 | B40: 46234 | C40: KC대납 관리비 | D40: 숙소수도세(07월분) | E40: 평택시 함박산1길 34 301호 | F40: 301호 | G40: 1 | H40: 6 | I40: 23660 | J40: KC 대납
...

Sheet 식대비용
A1: 식대 비용
A2: No. | B2: 납부일 | C2: 구분 | D2: 품명 | E2: 거래처명 | F2: 수량 | G2: 식수인원 | H2: 단가 | I2: 합 계 | J2: 비 고
I3: =SUM(I4:I5) -> 65930682 | L3: 입력해야하는 항목 외 수정 금지
A4: 1 | B4: 46234 | C4: KC대납 식대 | D4: 기술인및관리자 (현장 식당) | E4: 포세카 | F4: 4151 | G4: 132 | H4: 6181.82 | I4: 25568682 | J4: KC 대납 | L4: 입력항목
A5: 2 | B5: 46228 | C5: KC대납 식대 | D5: 기술인및관리자 (현장 식당) | E5: 밥심 | F5: 5766 | G5: 161 | H5: 7000 | I5: =F5*H5 -> 40362000 | J5: KC 대납 | L5: 납부일
L6: 구분
L7: 품명
L8: 거래처명
L9: 수량
L10: 식수인원
L11: 단가
L13: ■ 구분은 [KC대납 식대 및 식대] 이외 항목은 입력금지

Sheet 기타비용
A1: 기타 비용
A2: No. | B2: 구매일 | C2: 구분 | D2: 품명 | E2: 거래처명 | F2: 수량 | G2: 단가 | H2: 합계 | I2: 비고
H3: =SUM(H4:H138) -> 6415800 | K3: 입력해야하는 항목 외 수정 금지
A4: 1 | B4: 46204 | C4: 소모품비 | D4: 가위 [SB-P300,CTX [세신]] | E4: 미래공구 | F4: 10 | G4: 4500 | H4: =F4*G4 -> 45000 | I4: 거래명세서 첨부 | K4: 입력항목
A5: 2 | B5: 46204 | C5: 소모품비 | D5: 가위집 [PVC [AK]] | E5: 미래공구 | F5: 10 | G5: 2100 | H5: =F5*G5 -> 21000 | I5: 거래명세서 첨부 | K5: 납부일
A6: 3 | B6: 46204 | C6: 소모품비 | D6: 안전칼 [SK-4 [올파]] | E6: 미래공구 | F6: 5 | G6: 5700 | H6: =F6*G6 -> 28500 | I6: 거래명세서 첨부 | K6: 구분
A7: 4 | B7: 46204 | C7: 소모품비 | D7: 다이아몬드줄 [10",스텐 [수입]] | E7: 미래공구 | F7: 5 | G7: 6500 | H7: =F7*G7 -> 32500 | I7: 거래명세서 첨부 | K7: 품명
A8: 5 | B8: 46205 | C8: 소모품비 | D8: 타이어커버 [소,323*100,12*4,JCPT0807,JCPT0807AC용] | E8: 미래공구 | F8: 3 | G8: 16000 | H8: =F8*G8 -> 48000 | I8: 거래명세서 첨부 | K8: 거래처명
A9: 6 | B9: 46205 | C9: 소모품비 | D9: 보루 [5KG,면 [백호]] | E9: 미래공구 | F9: 1 | G9: 12000 | H9: =F9*G9 -> 12000 | I9: 거래명세서 첨부 | K9: 수량
A10: 7 | B10: 46205 | C10: 소모품비 | D10: 마대 [수입,90kg,100L [HNS]] | E10: 미래공구 | F10: 100 | G10: 300 | H10: =F10*G10 -> 30000 | I10: 거래명세서 첨부 | K10: 식수인원
A11: 8 | B11: 46205 | C11: 소모품비 | D11: 방우플러그 [YSP1603,녹색 [코엘]] | E11: 미래공구 | F11: 5 | G11: 5400 | H11: =F11*G11 -> 27000 | I11: 거래명세서 첨부 | K11: 단가
A12: 9 | B12: 46205 | C12: 소모품비 | D12: 방우콘센트 [2구,20A [코엘]] | E12: 미래공구 | F12: 4 | G12: 24300 | H12: =F12*G12 -> 97200 | I12: 거래명세서 첨부
A13: 10 | B13: 46205 | C13: 소모품비 | D13: 실리콘오링 [26Q*9R,적색 [수입]] | E13: 미래공구 | F13: 4 | G13: 1800 | H13: =F13*G13 -> 7200 | I13: 거래명세서 첨부 | K13: ■ 구분은 [KC대납 식대 및 식대] 이외 항목은 입력금지
A14: 11 | B14: 46206 | C14: 소모품비 | D14: 스텝드릴 [5-35,Co8%,원형생크 [블랑코]] | E14: 미래공구 | F14: 2 | G14: 23200 | H14: =F14*G14 -> 46400 | I14: 거래명세서 첨부
A15: 12 | B15: 46206 | C15: 소모품비 | D15: 케이블타이 [300mm(1봉=500개),백색 [HNS]] | E15: 미래공구 | F15: 3 | G15: 13000 | H15: =F15*G15 -> 39000 | I15: 거래명세서 첨부
A16: 13 | B16: 46206 | C16: 소모품비 | D16: 어스클램프 [CEC-500A,CTX [크레토스]] | E16: 미래공구 | F16: 2 | G16: 20800 | H16: =F16*G16 -> 41600 | I16: 거래명세서 첨부
A17: 14 | B17: 46206 | C17: 소모품비 | D17: 스패너 [35mm [MIDAS]] | E17: 미래공구 | F17: 2 | G17: 8600 | H17: =F17*G17 -> 17200 | I17: 거래명세서 첨부
A18: 15 | B18: 46206 | C18: 소모품비 | D18: PP로프 [6mm*100m [SW]] | E18: 미래공구 | F18: 1 | G18: 10300 | H18: =F18*G18 -> 10300 | I18: 거래명세서 첨부
A19: 16 | B19: 46206 | C19: 소모품비 | D19: 낙상경보기 [200*90 [3S]] | E19: 미래공구 | F19: 12 | G19: 4000 | H19: =F19*G19 -> 48000 | I19: 거래명세서 첨부
A20: 17 | B20: 46206 | C20: 소모품비 | D20: 낙상경보기부품 [풀피리] | E20: 미래공구 | F20: 10 | G20: 100 | H20: =F20*G20 -> 1000 | I20: 거래명세서 첨부
A21: 18 | B21: 46209 | C21: 소모품비 | D21: 실내화주머니 [배낭형,고급 [수입]] | E21: 미래공구 | F21: 74 | G21: 4000 | H21: =F21*G21 -> 296000 | I21: 거래명세서 첨부
A22: 19 | B22: 46209 | C22: 소모품비 | D22: 수평 [자석,MML-100 [SB]] | E22: 미래공구 | F22: 1 | G22: 11100 | H22: =F22*G22 -> 11100 | I22: 거래명세서 첨부
A23: 20 | B23: 46209 | C23: 소모품비 | D23: 가위 [SB-P300,CTX [세신]] | E23: 미래공구 | F23: 10 | G23: 4500 | H23: =F23*G23 -> 45000 | I23: 거래명세서 첨부
A24: 21 | B24: 46209 | C24: 소모품비 | D24: 가위집 [PVC [AK]] | E24: 미래공구 | F24: 10 | G24: 2100 | H24: =F24*G24 -> 21000 | I24: 거래명세서 첨부
A25: 22 | B25: 46210 | C25: 소모품비 | D25: 롱비트소켓 [11*110mm [황금손]] | E25: 미래공구 | F25: 1 | G25: 5400 | H25: =F25*G25 -> 5400 | I25: 거래명세서 첨부
... A138: 135 | B138: 46234 | C138: 소모품비 | D138: 네임펜 [양면,흑색,12개 [모나미]] | E138: 미래공구 | F138: 1 | G138: 12400 | H138: =F138*G138 -> 12400 | I138: 거래명세서 첨부

Sheet 서명란
B2: 현 장 확 인 | C2: 소 장 | E2: (서명)
C3: 공 사 | E3: (서명)
C4: 공 무 | E4: (서명)
G6: 사 업 부 | H6: Frontier 사업부 GNP 본부장 | I6: BOC 센터장 | J6: Frontier 사업부장
L8: 본 사 | M8: 담 당 | N8: 검 토 | O8: 검 토
Q11: 구 분 | R11: 확 인
Q12: 품 질 | R12: O O O (인)
Q13: 공 무 | R13: O O O (인)

Sheet DIA-INCH
B3: SIZE
B4: A(mm) | C4: Inch
B5: 8A | C5: 0.25
B6: 15A | C6: 0.5
B7: 20A | C7: 0.75
B8: 25A | C8: 1
B9: 32A | C9: 1.25
B10: 40A | C10: 1.5
B11: 50A | C11: 2
B12: 65A | C12: 2.5
B13: 80A | C13: 3
B14: 100A | C14: 4
B15: 110A | C15: 4
B16: 125A | C16: 5
... B27: 550A | C27: 22
