Workbook

Sheet 용역청구서 표지
B4: 용 역 청 구 서
B7: P4 Ph2 GAS&PCW 1공구
C8: S26-001
C14: 2026년 04월
C15: 대성이엔지

Sheet 용역 청구서(갑지)
A1: 용 역 청 구 서
A3: 1 | B3: 공 사 명 | C3: : | D3: ='용역청구서 표지'!$B$7 -> P4 Ph2 GAS&PCW 1공구 | E3: ='용역청구서 표지'!$C$8 -> S26-001
A4: 2 | B4: 공 종 | C4: : | D4: 외주용역(M/M부분)
A5: 3 | B5: 계 약 금 액 | C5: : | D5: =ROUNDUP(E5,0) -> 30000000 | E5: =집계장!J25 -> 30000000 | F5: (VAT 별도)
A6: 4 | B6: 누 계 기 성 금 액 | C6: : | D6: =ROUNDUP(E6,0) -> 30000000 | E6: =E7+E13 -> 30000000 | F6: (VAT 별도)
A7: 5 | B7: 전 회 기 성 금 액 | C7: : | D7: =ROUNDUP(E7,0) -> 0 | E7: 0 | F7: (VAT 별도)
A8: 6 | B8: 금 회 기 성 금 액 | C8: : | D8: =ROUNDUP(E8,0) -> 30000000 | E8: =집계장!I25 -> 30000000 | F8: (VAT 별도)
A9: 7 | B9: 선 금 액 | C9: : | D9: =ROUNDUP(E9,0) -> 0 | E9: =집계장!L23 -> 0 | F9: (VAT 별도)
A10: 8 | B10: 선 금 전 회 공 제 | C10: : | D10: =ROUNDUP(E10,0) -> 0 | E10: =집계장!H23 -> 0 | F10: (VAT 별도)
A11: 9 | B11: 선 금 금 회 공 제 | C11: : | D11: =ROUNDUP(E11,0) -> 0 | E11: =집계장!G23 -> 0 | F11: (VAT 별도)
A12: 10 | B12: 선 금 잔 여 금 액 | C12: : | D12: =ROUNDUP(E12,0) -> 0 | E12: =집계장!M23 -> 0 | F12: (VAT 별도)
A13: 11 | B13: 금 회 청 구 금 액 | C13: : | D13: =ROUNDUP(E13,0) -> 30000000 | E13: =집계장!G25 -> 30000000 | F13: (VAT 별도)
A14: 12 | B14: 잔 여 기 성 금 액 | C14: : | D14: =ROUNDUP(E14,0) -> 0 | F14: (VAT 별도)
A15: 13 | B15: 공 정 율 | C15: : | D15: 1
A16: 14 | B16: 청 구 공 사 기 간 | C16: : | D16: 2026. 04. 01 ~ 2026. 04. 30
B18: 위 공사의 하도급에 있어서 공사설계도서, 시방서,품질관리 기준 및 약정대로 시공 되었음을 확인하오며. 만약 귀사의 현장담당의 검사에
B19: 관하여 하자가 발견된 때에는 즉시 실액배상 또는 재 시공할것을 서약하고 이에 기성 청구서를 제출합니다.
B20: 상기건과 관련하여 본 청구 이전까지의 모든 대금은 수령하였음을 확약합니다.
F21: 작 성 일 : 2026 년 04 월 30일
F23: 상 호 : | G23: 대성이엔지
B24: ※첨 부 : 기성내역서 1부. | F24: 주 소 : | G24: 경기도 파주시 파주읍 주라위길 380
F25: 대표이사 : | G25: 정 성 기 | I25: (인)
D26: ㈜케이씨이앤씨 귀하

Sheet 용역 내역서(을지)
A1: 용 역 내 역 서
A2: P4 Ph4 GAS 1공구 마감공사 | G2: 단위 : 원
A3: 품 명 | B3: 규 격 | C3: 단위 | D3: 단 가 | E3: 금 회 청 구
E4: 수 량 | F4: 금 액 | G4: 비 고
A5: 고급기술인 | B5: S+ | C5: M/M | D5: 1400000 | E5: 1 | F5: =D5*E5 -> 1400000
A6: 고급기술인 | B6: S | C6: M/M | D6: 1200000 | F6: =D6*E6 -> 0
A7: 중급기술인 | B7: A+ | C7: M/M | D7: 1000000 | F7: =D7*E7 -> 0
A8: 중급기술인 | B8: A | C8: M/M | D8: 900000 | F8: =D8*E8 -> 0
A9: 중급기술인 | B9: B+ | C9: M/M | D9: 800000 | F9: =D9*E9 -> 0
A10: 중급기술인 | B10: B | C10: M/M | D10: 700000 | F10: =D10*E10 -> 0
A11: 초급 기술인 | B11: C | C11: M/M | D11: 600000 | F11: =D11*E11 -> 0
A13: 인센티브 | E13: 0.01 | F13: =SUM(F5:F11)*E13 -> 14000
A15: 총 계 | E15: =SUM(E5:E11) -> 1 | F15: =SUM(F5:F13) -> 1414000

Sheet 내역서(을지)
A1: 용 역 내 역 서
A2: =집계장!B2 -> P4 Ph2 GAS&PCW 1공구 | G2: 단위 : 원
A3: 품 명 | B3: 규 격 | C3: 단위 | D3: 단 가 | E3: 금 회 청 구 | G3: 비 고
E4: 수 량 | F4: 금 액
A5: 고급기술인 | B5: S+ | C5: M/M | D5: 1400000 | E5: 8 | F5: =D5*E5 -> 11200000
A6: 고급기술인 | B6: S | C6: M/M | D6: 1200000 | E6: 2 | F6: =D6*E6 -> 2400000
A7: 중급기술인 | B7: A+ | C7: M/M | D7: 1000000 | E7: 6 | F7: =D7*E7 -> 6000000
A8: 중급기술인 | B8: A | C8: M/M | D8: 900000 | E8: 1 | F8: =D8*E8 -> 900000
A9: 중급기술인 | B9: B+ | C9: M/M | D9: 800000 | E9: 4 | F9: =D9*E9 -> 3200000
A10: 중급기술인 | B10: B | C10: M/M | D10: 700000 | E10: 9 | F10: =D10*E10 -> 6300000
A11: 초급기술인 | B11: C | C11: M/M | D11: 600000 | F11: =D11*E11 -> 0
A27: 총 계 | E27: =SUM(E5:E11) -> 30 | F27: =SUM(F5:F26) -> 30000000

Sheet 집계장
B2: ='용역청구서 표지'!$B$7 -> P4 Ph2 GAS&PCW 1공구
M3: ='용역청구서 표지'!$C$15 -> 대성이엔지
B4: 구분 | C4: 내역 | D4: 단위 | E4: 수량 | F4: 단가 | G4: 합계 | H4: 전회기성 | I4: 금회기성 | J4: 누계기성 | K4: 비 고
B5: 1. 물량 | C5: WELDING POINT | D5: D/I | E5: =SUM('물량 내역서'!$J$6:$J$28) -> 550 | F5: =G5/E5 -> 475000 | G5: =SUM('물량 내역서'!$K$6:$K$28) -> 261250000 | H5: 0 | I5: =G5 -> 261250000 | J5: =H5+I5 -> 261250000
C6: VALVE 설치비 | D6: EA | E6: =SUM('물량 내역서'!$J$29:$J$51) -> 0 | F6: =G6/E6 -> #DIV/0! | G6: =SUM('물량 내역서'!$K$29:$K$51) -> 0 | H6: 0 | I6: =G6 -> 0 | J6: =H6+I6 -> 0
C7: 인원 실투입 | D7: M/D | E7: ='근로내역 (04월)'!AN83 -> 0 | F7: 0 | G7: =E7*F7 -> 0 | H7: 0 | I7: =G7 -> 0 | J7: =H7+I7 -> 0
B8: 소 계 | C8: 물량 | G8: =SUM(G5:G7) -> 261250000 | I8: =G8 -> 261250000 | J8: =H8+I8 -> 261250000
B9: 2. 노무비 | C9: 직접노무비 | D9: 式 | E9: ='근로내역 (04월)'!AN71 -> 1328.3125 | F9: =G9/E9 -> 194712.75 | G9: ='근로내역 (04월)'!AP71 -> 258639375 | H9: 112889375 | I9: =G9 -> 258639375 | J9: =H9+I9 -> 371528750
B10: 3. 숙소 및 식대 | C10: 임대료+관리비 | D10: 式 | E10: =SUM(숙소임차료!H4:H6)+SUM(숙소관리비!H4:H8) -> 37 | F10: =G10/E10 -> 676798.38 | G10: =숙소임차료!I3+숙소관리비!I3 -> 25041540 | H10: 18330000 | I10: =G10 -> 25041540 | J10: =H10+I10 -> 43371540 | O10: =+I10+I11 -> 44574676
C11: 식대 | D11: 式 | E11: =SUM(식대비용!G4:G4) -> 56 | F11: =G11/E11 -> 348806 | G11: =식대비용!I3 -> 19533136 | H11: 7940818 | I11: =G11 -> 19533136 | J11: =H11+I11 -> 27473954
B12: 4. 기타 공제 내역 | D12: 式 | F12: 0 | G12: =E12*F12 -> 0 | I12: =G12 -> 0 | J12: =H12+I12 -> 0
B13: 소 계 | C13: 공제 | G13: =SUM(G9:G12) -> 303214051 | H13: =SUM(H9:H12) -> 139160193 | I13: =G13 -> 303214051 | J13: =H13+I13 -> 442374244 | K13: 전월 적자 기성액 (139,160,193원)
B14: 합 계 | C14: 기성 (물량-공제) | G14: =G8-G13 -> -41964051 | H14: =H8-H13 -> -139160193 | I14: =G14 -> -41964051 | J14: =H14+I14 -> -181124244
B15: 5. 유보금 | C15: 기성금*XX% | D15: 式 | I15: =G15 -> 0 | J15: =H15+I15 -> 0
B16: 6. 유보금 차액 | C16: 전회 누계유보금 | D16: 式 | I16: =G16 -> 0 | J16: =H16+I16 -> 0
B17: 7. NEGO | C17: NEGO | D17: 式 | I17: =G17 -> 0
B18: 총 계 | C18: 최종기성 | G18: =G14+G15+G16+G17 -> -41964051 | H18: =H14+H15+H16+H17 -> -139160193 | I18: =I14+I15+I16+I17 -> -41964051 | J18: =J14+J15+J16+J17 -> -181124244
B19: 8. 기타지급운영비 | C19: 기타지급 운영비 | D19: 式 | E19: =SUM('물량 내역서'!$J$6:$J$28) -> 550 | F19: =G19/E19 -> 383862.26 | G19: =211200000-75756 -> 211124244 | I19: =G19 -> 211124244 | J19: =H19+I19 -> 211124244 | K19: (익월 기성 차감 예정)
C20: 누계 적자기성액 | D20: 式 | G20: -139160193 | I20: =G20 -> -139160193 | J20: =H20+I20 -> -139160193
B21: 소 계 | G21: =SUM(G19:G20) -> 71964051 | H21: =SUM(H19) -> 0 | I21: =SUM(I19:I20) -> 71964051 | J21: =SUM(J19:J20) -> 71964051
B22: 선급금 | C22: 선수공제 | D22: 式 | G22: 0 | I22: =G22 -> 0 | J22: =H22+I22 -> 0 | L22: 지급 선급금 | M22: 선급금 차액
C23: 단수정리 | D23: 式 | G23: =ROUNDDOWN(G22,-5) -> 0 | I23: =G23 -> 0 | J23: =H23+I23 -> 0 | K23: 만 단위 이하 절사
B24: 공제 후 실 지급액 | G24: =G18-G23 -> -41964051 | H24: =H18-H23 -> -139160193 | I24: =I18-I23 -> -41964051 | J24: =J18-J23 -> -181124244
B25: 세금계산서 기준 | G25: =G24+G21 -> 30000000 | H25: =ROUNDDOWN(H24+H21,-5) -> -139100000 | I25: =I24+I21 -> 30000000 | J25: =ROUNDDOWN(J24+J19,-5) -> 30000000 | K25: 만 단위 이하 절사
B26: TERMS AND CONDITIONS | E26: NOTE
B27: 1. 납 기 : KCEnC 지정 납기로 별도 협의 하에 결정하는 것으로 함.
B28: 2. 지불조건 : KCEnC 지불 조건에 따름.
B29: 3. 유효기간 : 기성 제출일로 부터 30일 이내

Sheet 물량 내역서
A1: 2026년 (04)월 물량 내역서
A2: ='용역청구서 표지'!$B$7 -> P4 Ph2 GAS&PCW 1공구 | M2: 단위 : 원
A3: 품 명 | B3: 규 격 | C3: 단위 | D3: W/P 수량 | E3: 단 가 | F3: 계 약 내 역 | H3: 전 회 누 계 물 량 | J3: 금 회 물 량 | L3: 누 계 물 량
F4: D/I 수량 | G4: 금액 | H4: D/I 수량 | I4: 금액 | J4: D/I 수량 | K4: 금액 | L4: D/I 수량 | M4: 금액
A6: WEDING POINT | B6: 8A | C6: POINT | E6: 475000 | F6: =L6 -> 0 | G6: =M6 -> 0 | J6: =$D6*'DIA-INCH'!$C5 -> 0 | K6: =$E6*$J6 -> 0 | L6: =H6+J6 -> 0 | M6: =I6+K6 -> 0
A7: WEDING POINT | B7: 15A | C7: POINT | E7: 475000 | F7: =L7 -> 0 | G7: =M7 -> 0 | J7: =$D7*'DIA-INCH'!$C6 -> 0 | K7: =$E7*$J7 -> 0 | L7: =H7+J7 -> 0 | M7: =I7+K7 -> 0
A8: WEDING POINT | B8: 20A | C8: POINT | E8: 475000 | F8: =L8 -> 0 | G8: =M8 -> 0 | J8: =$D8*'DIA-INCH'!$C7 -> 0 | K8: =$E8*$J8 -> 0 | L8: =H8+J8 -> 0 | M8: =I8+K8 -> 0
A9: WEDING POINT | B9: 25A | C9: POINT | E9: 475000 | F9: =L9 -> 0 | G9: =M9 -> 0 | J9: =$D9*'DIA-INCH'!$C8 -> 0 | K9: =$E9*$J9 -> 0 | L9: =H9+J9 -> 0 | M9: =I9+K9 -> 0
A10: WEDING POINT | B10: 32A | C10: POINT | E10: 475000 | F10: =L10 -> 0 | G10: =M10 -> 0 | J10: =$D10*'DIA-INCH'!$C9 -> 0 | K10: =$E10*$J10 -> 0 | L10: =H10+J10 -> 0 | M10: =I10+K10 -> 0
A11: WEDING POINT | B11: 40A | C11: POINT | E11: 475000 | F11: =L11 -> 0 | G11: =M11 -> 0 | J11: =$D11*'DIA-INCH'!$C10 -> 0 | K11: =$E11*$J11 -> 0 | L11: =H11+J11 -> 0 | M11: =I11+K11 -> 0
A12: WEDING POINT | B12: 50A | C12: POINT | D12: 83 | E12: 475000 | F12: =L12 -> 166 | G12: =M12 -> 78850000 | J12: =$D12*'DIA-INCH'!$C11 -> 166 | K12: =$E12*$J12 -> 78850000 | L12: =H12+J12 -> 166 | M12: =I12+K12 -> 78850000
A13: WEDING POINT | B13: 65A | C13: POINT | E13: 475000 | F13: =L13 -> 0 | G13: =M13 -> 0 | J13: =$D13*'DIA-INCH'!$C12 -> 0 | K13: =$E13*$J13 -> 0 | L13: =H13+J13 -> 0 | M13: =I13+K13 -> 0
A14: WEDING POINT | B14: 80A | C14: POINT | E14: 475000 | F14: =L14 -> 0 | G14: =M14 -> 0 | J14: =$D14*'DIA-INCH'!$C13 -> 0 | K14: =$E14*$J14 -> 0 | L14: =H14+J14 -> 0 | M14: =I14+K14 -> 0
A15: WEDING POINT | B15: 100A | C15: POINT | D15: 66 | E15: 475000 | F15: =L15 -> 264 | G15: =M15 -> 125400000 | J15: =$D15*'DIA-INCH'!$C14 -> 264 | K15: =$E15*$J15 -> 125400000 | L15: =H15+J15 -> 264 | M15: =I15+K15 -> 125400000
A16: WEDING POINT | B16: 110A | C16: POINT | E16: 475000 | F16: =L16 -> 0 | G16: =M16 -> 0 | J16: =$D16*'DIA-INCH'!$C15 -> 0 | K16: =$E16*$J16 -> 0 | L16: =H16+J16 -> 0 | M16: =I16+K16 -> 0
A17: WEDING POINT | B17: 125A | C17: POINT | E17: 475000 | F17: =L17 -> 0 | G17: =M17 -> 0 | J17: =$D17*'DIA-INCH'!$C16 -> 0 | K17: =$E17*$J17 -> 0 | L17: =H17+J17 -> 0 | M17: =I17+K17 -> 0
A18: WEDING POINT | B18: 150A | C18: POINT | E18: 475000 | F18: =L18 -> 0 | G18: =M18 -> 0 | J18: =$D18*'DIA-INCH'!$C17 -> 0 | K18: =$E18*$J18 -> 0 | L18: =H18+J18 -> 0 | M18: =I18+K18 -> 0
A19: WEDING POINT | B19: 175A | C19: POINT | E19: 475000 | F19: =L19 -> 0 | G19: =M19 -> 0 | J19: =$D19*'DIA-INCH'!$C18 -> 0 | K19: =$E19*$J19 -> 0 | L19: =H19+J19 -> 0 | M19: =I19+K19 -> 0
A20: WEDING POINT | B20: 200A | C20: POINT | D20: 15 | E20: 475000 | F20: =L20 -> 120 | G20: =M20 -> 57000000 | J20: =$D20*'DIA-INCH'!$C19 -> 120 | K20: =$E20*$J20 -> 57000000 | L20: =H20+J20 -> 120 | M20: =I20+K20 -> 57000000
A21: WEDING POINT | B21: 225A | C21: POINT | E21: 475000 | F21: =L21 -> 0 | G21: =M21 -> 0 | J21: =$D21*'DIA-INCH'!$C20 -> 0 | K21: =$E21*$J21 -> 0 | L21: =H21+J21 -> 0 | M21: =I21+K21 -> 0
A22: WEDING POINT | B22: 250A | C22: POINT | E22: 475000 | F22: =L22 -> 0 | G22: =M22 -> 0 | J22: =$D22*'DIA-INCH'!$C21 -> 0 | K22: =$E22*$J22 -> 0 | L22: =H22+J22 -> 0 | M22: =I22+K22 -> 0
A23: WEDING POINT | B23: 300A | C23: POINT | E23: 475000 | F23: =L23 -> 0 | G23: =M23 -> 0 | J23: =$D23*'DIA-INCH'!$C22 -> 0 | K23: =$E23*$J23 -> 0 | L23: =H23+J23 -> 0 | M23: =I23+K23 -> 0
A24: WEDING POINT | B24: 350A | C24: POINT | E24: 475000 | F24: =L24 -> 0 | G24: =M24 -> 0 | J24: =$D24*'DIA-INCH'!$C23 -> 0 | K24: =$E24*$J24 -> 0 | L24: =H24+J24 -> 0 | M24: =I24+K24 -> 0
A25: WEDING POINT | B25: 400A | C25: POINT | E25: 475000 | F25: =L25 -> 0 | G25: =M25 -> 0 | J25: =$D25*'DIA-INCH'!$C24 -> 0 | K25: =$E25*$J25 -> 0 | L25: =H25+J25 -> 0 | M25: =I25+K25 -> 0
A26: WEDING POINT | B26: 450A | C26: POINT | E26: 475000 | F26: =L26 -> 0 | G26: =M26 -> 0 | J26: =$D26*'DIA-INCH'!$C25 -> 0 | K26: =$E26*$J26 -> 0 | L26: =H26+J26 -> 0 | M26: =I26+K26 -> 0
A27: WEDING POINT | B27: 500A | C27: POINT | E27: 475000 | F27: =L27 -> 0 | G27: =M27 -> 0 | J27: =$D27*'DIA-INCH'!$C26 -> 0 | K27: =$E27*$J27 -> 0 | L27: =H27+J27 -> 0 | M27: =I27+K27 -> 0
A28: WEDING POINT | B28: 550A | C28: POINT | E28: 475000 | F28: =L28 -> 0 | G28: =M28 -> 0 | J28: =$D28*'DIA-INCH'!$C27 -> 0 | K28: =$E28*$J28 -> 0 | L28: =H28+J28 -> 0 | M28: =I28+K28 -> 0
A29: VALVE 설치비 | B29: 8A | C29: EA | E29: =$E$32*'DIA-INCH'!$C5 -> 12500 | F29: =L29 -> 0 | G29: =M29 -> 0 | J29: =D29 -> 0 | K29: =$J29*$E29 -> 0 | L29: =H29+J29 -> 0 | M29: =I29+K29 -> 0
A30: VALVE 설치비 | B30: 15A | C30: EA | E30: =$E$32*'DIA-INCH'!$C6 -> 25000 | F30: =L30 -> 0 | G30: =M30 -> 0 | J30: =D30 -> 0 | K30: =$J30*$E30 -> 0 | L30: =H30+J30 -> 0 | M30: =I30+K30 -> 0
A31: VALVE 설치비 | B31: 20A | C31: EA | E31: =$E$32*'DIA-INCH'!$C7 -> 37500 | F31: =L31 -> 0 | G31: =M31 -> 0 | J31: =D31 -> 0 | K31: =$J31*$E31 -> 0 | L31: =H31+J31 -> 0 | M31: =I31+K31 -> 0
A32: VALVE 설치비 | B32: 25A | C32: EA | E32: 50000 | F32: =L32 -> 0 | G32: =M32 -> 0 | J32: =D32 -> 0 | K32: =$J32*$E32 -> 0 | L32: =H32+J32 -> 0 | M32: =I32+K32 -> 0
A33: VALVE 설치비 | B33: 32A | C33: EA | E33: =$E$32*'DIA-INCH'!$C9 -> 62500 | F33: =L33 -> 0 | G33: =M33 -> 0 | J33: =D33 -> 0 | K33: =$J33*$E33 -> 0 | L33: =H33+J33 -> 0 | M33: =I33+K33 -> 0
A34: VALVE 설치비 | B34: 40A | C34: EA | E34: =$E$32*'DIA-INCH'!$C10 -> 75000 | F34: =L34 -> 0 | G34: =M34 -> 0 | J34: =D34 -> 0 | K34: =$J34*$E34 -> 0 | L34: =H34+J34 -> 0 | M34: =I34+K34 -> 0
A35: VALVE 설치비 | B35: 50A | C35: EA | E35: =$E$32*'DIA-INCH'!$C11 -> 100000 | F35: =L35 -> 0 | G35: =M35 -> 0 | J35: =D35 -> 0 | K35: =$J35*$E35 -> 0 | L35: =H35+J35 -> 0 | M35: =I35+K35 -> 0
A36: VALVE 설치비 | B36: 65A | C36: EA | E36: =$E$32*'DIA-INCH'!$C12 -> 125000 | F36: =L36 -> 0 | G36: =M36 -> 0 | J36: =D36 -> 0 | K36: =$J36*$E36 -> 0 | L36: =H36+J36 -> 0 | M36: =I36+K36 -> 0
A37: VALVE 설치비 | B37: 80A | C37: EA | E37: =$E$32*'DIA-INCH'!$C13 -> 150000 | F37: =L37 -> 0 | G37: =M37 -> 0 | J37: =D37 -> 0 | K37: =$J37*$E37 -> 0 | L37: =H37+J37 -> 0 | M37: =I37+K37 -> 0
A38: VALVE 설치비 | B38: 100A | C38: EA | E38: =$E$32*'DIA-INCH'!$C14 -> 200000 | F38: =L38 -> 0 | G38: =M38 -> 0 | J38: =D38 -> 0 | K38: =$J38*$E38 -> 0 | L38: =H38+J38 -> 0 | M38: =I38+K38 -> 0
A39: VALVE 설치비 | B39: 110A | C39: EA | E39: =$E$32*'DIA-INCH'!$C15 -> 200000 | F39: =L39 -> 0 | G39: =M39 -> 0 | J39: =D39 -> 0 | K39: =$J39*$E39 -> 0 | L39: =H39+J39 -> 0 | M39: =I39+K39 -> 0
A40: VALVE 설치비 | B40: 125A | C40: EA | E40: =$E$32*'DIA-INCH'!$C16 -> 250000 | F40: =L40 -> 0 | G40: =M40 -> 0 | J40: =D40 -> 0 | K40: =$J40*$E40 -> 0 | L40: =H40+J40 -> 0 | M40: =I40+K40 -> 0
A41: VALVE 설치비 | B41: 150A | C41: EA | E41: =$E$32*'DIA-INCH'!$C17 -> 300000 | F41: =L41 -> 0 | G41: =M41 -> 0 | J41: =D41 -> 0 | K41: =$J41*$E41 -> 0 | L41: =H41+J41 -> 0 | M41: =I41+K41 -> 0
...

Sheet 근로내역 (04월)
A1: 2026년 ( 04 )월 일용 노무비명세서 | AH1: 현장명 | AM1: ='용역청구서 표지'!$B$7 -> P4 Ph2 GAS&PCW 1공구
AH2: 현장소장 | AM2: 조 수 원
AH3: 잡코드 | AM3: ='용역청구서 표지'!$C$8 -> S26-001
A5: 번호 | B5: 성명 | C5: 주민등록번호 | D5: 직종 | E5: 연락처(H.P) | F5: 은행명 | G5: 예금주 | H5: 계좌번호 | I5: 1 | J5: 2 | K5: 3 | L5: 4 | M5: 5 | N5: 6 | O5: 7 | P5: 8 | Q5: 9 | R5: 10 | S5: 11 | T5: 12 | U5: 13 | V5: 14 | W5: 15 | X5: 16 | Y5: 17 | Z5: 18 | AA5: 19 | AB5: 20 | AC5: 21 | AD5: 22 | AE5: 23 | AF5: 24 | AG5: 25 | AH5: 26 | AI5: 27 | AJ5: 28 | AK5: 29 | AL5: 30 | AM5: 31 | AN5: 공수 | AO5: 단가 | AP5: 총액
A6: 1 | B6: 강민석 | C6: 000819-3823434 | D6: 보통인부 | E6: 010-4796-2063 | F6: 신한 | G6: 강민석 | H6: 110-552-336273 | I6: 1 | J6: 1.5 | K6: 1 | AN6: =SUM(I6:AM6) -> 3.5 | AO6: 160000 | AP6: =AN6*AO6 -> 560000
A7: 2 | B7: 강채연 | C7: 980703-2192257 | D7: 보통인부 | E7: 010-5725-9067 | F7: 국민 | G7: 강채연 | H7: 399102-04-168176 | AB7: 0.6875 | AC7: 0.625 | AE7: 1 | AF7: 1 | AI7: 1 | AJ7: 1.5 | AK7: 1 | AL7: 1.5 | AN7: =SUM(I7:AM7) -> 8.3125 | AO7: 150000 | AP7: =AN7*AO7 -> 1246875
A8: 3 | B8: 강희수 | C8: 730210-1029411 | D8: 도비공 | E8: 010-9561-6101 | F8: 신한 | G8: 강희수 | H8: 110-490-486591 | I8: 1 | J8: 1.5 | K8: 1 | L8: 1 | N8: 1 | O8: 1.5 | P8: 1 | Q8: 1.5 | R8: 1 | U8: 1 | V8: 1.5 | W8: 1 | X8: 1.5 | Y8: 1 | Z8: 1 | AB8: 1 | AC8: 1.5 | AD8: 1 | AF8: 1 | AI8: 1 | AJ8: 1.5 | AK8: 1 | AL8: 1.5 | AN8: =SUM(I8:AM8) -> 27 | AO8: 210000 | AP8: =AN8*AO8 -> 5670000
A9: 4 | B9: 구윤하 | C9: 680130-2162814 | D9: 보통인부 | E9: 010-3259-2177 | F9: 하나 | G9: 구윤하 | H9: 206-910258-60907 | N9: 0.4375 | P9: 1 | Q9: 1.5 | R9: 1 | U9: 1 | V9: 1.5 | W9: 1 | X9: 1.5 | Y9: 1 | Z9: 1 | AB9: 1 | AC9: 1.5 | AD9: 1 | AF9: 1 | AG9: 1 | AI9: 1 | AJ9: 1.5 | AK9: 1 | AL9: 1.5 | AN9: =SUM(I9:AM9) -> 21.4375 | AO9: 150000 | AP9: =AN9*AO9 -> 3215625
A10: 5 | B10: 권중섭 | C10: 830806-1697210 | D10: 배관공 | E10: 010-9742-9790 | F10: 신한 | G10: 권중섭 | H10: 110-430-392742 | AB10: 0.6875 | AC10: 1.125 | AD10: 0.5 | AE10: 0.5 | AF10: 1 | AI10: 1 | AJ10: 1.5 | AK10: 1 | AL10: 1.5 | AN10: =SUM(I10:AM10) -> 8.8125 | AO10: 230000 | AP10: =AN10*AO10 -> 2026875
A11: 6 | B11: 김금성 | C11: 870118-1162639 | D11: 보통인부 | E11: 010-5125-5154 | F11: 농협 | G11: 김금성 | H11: 351-1130-0614-23 | I11: 1 | J11: 1.5 | K11: 1 | L11: 1 | N11: 1 | O11: 1.5 | P11: 0.5 | Q11: 1.5 | R11: 1 | S11: 1 | U11: 1 | V11: 1.5 | W11: 1 | X11: 1.5 | Y11: 1 | Z11: 0.5 | AC11: 1.5 | AD11: 1 | AF11: 1 | AG11: 0.5 | AI11: 1 | AJ11: 1.5 | AK11: 1 | AL11: 1.5 | AN11: =SUM(I11:AM11) -> 26.5 | AO11: 160000 | AP11: =AN11*AO11 -> 4240000
A12: 7 | B12: 김동욱 | C12: 810302-1830628 | D12: 배관공 | E12: 010-5022-0444 | F12: 농협 | G12: 김동욱 | H12: 302-5022-0444-11 | I12: 1 | J12: 1.5 | K12: 1 | L12: 1 | N12: 1 | O12: 1.5 | P12: 1 | Q12: 1.5 | R12: 1 | U12: 1 | V12: 1.5 | W12: 1 | X12: 1.5 | Y12: 1 | Z12: 1 | AB12: 1 | AC12: 1.5 | AD12: 1 | AE12: 1.5 | AF12: 1 | AG12: 1 | AI12: 1 | AJ12: 0.125 | AK12: 1 | AL12: 1.5 | AN12: =SUM(I12:AM12) -> 28.125 | AO12: 210000 | AP12: =AN12*AO12 -> 5906250
A13: 8 | B13: 김마태 | C13: 830224-1912010 | D13: 배관공 | E13: 010-2725-6089 | F13: 기업 | G13: 김마태 | H13: 175-073189-01-013 | I13: 1 | J13: 1.5 | K13: 1 | L13: 1 | N13: 1 | O13: 1.5 | P13: 1 | R13: 1 | S13: 1 | U13: 1 | V13: 1.5 | W13: 1 | X13: 1.5 | Y13: 1 | Z13: 1 | AB13: 1 | AC13: 1.5 | AD13: 1 | AE13: 1.5 | AF13: 1 | AI13: 1 | AJ13: 1.5 | AK13: 1 | AL13: 1.5 | AN13: =SUM(I13:AM13) -> 28 | AO13: 240000 | AP13: =AN13*AO13 -> 6720000
A14: 9 | B14: 김승태 | C14: 720112-1019646 | D14: 보통인부 | E14: 010-7166-5282 | F14: 토스뱅크 | G14: 김승태 | H14: 1000-2078-6151 | I14: 1 | J14: 1.5 | K14: 1 | L14: 1 | N14: 1 | O14: 1.5 | P14: 1 | Q14: 1.5 | R14: 1 | AN14: =SUM(I14:AM14) -> 10.5 | AO14: 160000 | AP14: =AN14*AO14 -> 1680000
A15: 10 | B15: 김윤호 | C15: 900519-1066917 | D15: 보통인부 | E15: 010-6371-4420 | F15: 카카오뱅크 | G15: 김윤호 | H15: 3333-13-2754524 | I15: 0.8125 | N15: 1 | AN15: =SUM(I15:AM15) -> 1.8125 | AO15: 160000 | AP15: =AN15*AO15 -> 290000
A16: 11 | B16: 김의찬 | C16: 810916-1090421 | D16: 보통인부 | E16: 010-7748-9382 | F16: 국민 | G16: 김의찬 | H16: 121802-04-157456 | N16: 0.4375 | P16: 1 | Q16: 1.5 | R16: 1 | S16: 1 | U16: 1 | V16: 1.5 | W16: 1 | X16: 1.5 | Y16: 1 | Z16: 1 | AB16: 1 | AC16: 1.5 | AD16: 0.5 | AE16: 1.5 | AF16: 1 | AG16: 1 | AI16: 1 | AJ16: 1.5 | AK16: 1 | AL16: 1.5 | AN16: =SUM(I16:AM16) -> 23.4375 | AO16: 170000 | AP16: =AN16*AO16 -> 3984375
A17: 12 | B17: 김정규 | C17: 821122-1047416 | D17: 보통인부 | E17: 010-3240-6194 | F17: 국민 | G17: 김정규 | H17: 757101-04-044154 | U17: 0.4375 | W17: 1 | X17: 1.5 | Y17: 1 | AB17: 1 | AC17: 1.5 | AD17: 0.875 | AE17: 1.5 | AF17: 1 | AI17: 1 | AJ17: 1.5 | AK17: 1 | AL17: 1.5 | AN17: =SUM(I17:AM17) -> 14.8125 | AO17: 160000 | AP17: =AN17*AO17 -> 2370000
A18: 13 | B18: 김정인 | C18: 911224-1235320 | D18: 용접공 | E18: 010-3175-7994 | F18: 기업 | G18: 김정인 | H18: 010-3175-7994 | I18: 1 | J18: 1.5 | K18: 1 | L18: 1 | N18: 1 | O18: 1.5 | P18: 1 | Q18: 1.5 | R18: 1 | S18: 1 | U18: 1 | V18: 1.5 | W18: 1 | X18: 1.5 | Y18: 1 | AB18: 1 | AC18: 1.5 | AD18: 1 | AE18: 1.5 | AF18: 1 | AG18: 1 | AI18: 1 | AJ18: 1.5 | AK18: 1 | AL18: 1.5 | AN18: =SUM(I18:AM18) -> 29.5 | AO18: 240000 | AP18: =AN18*AO18 -> 7080000
A19: 14 | B19: 김지민 | C19: 930707-1150011 | D19: 배관공 | E19: 010-8000-2457 | F19: 카카오뱅크 | G19: 김지민 | H19: 3333-13-9046173 | N19: 0.9375 | O19: 1 | P19: 1 | Q19: 1.5 | R19: 1 | U19: 1 | V19: 1.5 | W19: 1 | X19: 1.5 | Y19: 1 | Z19: 1 | AB19: 0.75 | AC19: 1.5 | AD19: 1 | AE19: 1.5 | AF19: 1 | AG19: 1 | AI19: 1 | AJ19: 1.5 | AK19: 1 | AL19: 1.5 | AN19: =SUM(I19:AM19) -> 24.1875 | AO19: 220000 | AP19: =AN19*AO19 -> 5321250
A20: 15 | B20: 김진 | C20: 840728-1235014 | D20: 공사보조 | E20: 010-6246-4588 | F20: 기업 | G20: 김진 | H20: 458-013758-02-012 | I20: 1 | J20: 1.5 | K20: 1 | L20: 1 | N20: 1 | O20: 1.5 | P20: 1 | Q20: 1.5 | R20: 1 | U20: 1 | V20: 1.5 | W20: 1 | X20: 1.5 | Y20: 1 | Z20: 1 | AB20: 1 | AC20: 1.5 | AD20: 1 | AE20: 0.25 | AF20: 1 | AG20: 1 | AI20: 1 | AJ20: 1.5 | AK20: 1 | AL20: 1.5 | AN20: =SUM(I20:AM20) -> 28.25 | AO20: 240000 | AP20: =AN20*AO20 -> 6780000
A21: 16 | B21: 김치헌 | C21: 790914-1567115 | D21: 배관공 | E21: 010-4191-6886 | F21: 국민 | G21: 김치헌 | H21: 257602-04-003063 | I21: 1 | J21: 1.5 | K21: 1 | L21: 1 | N21: 1 | O21: 1.5 | P21: 1 | Q21: 1.5 | R21: 1 | U21: 1 | V21: 1.5 | W21: 1 | X21: 1.5 | Y21: 1 | Z21: 1 | AB21: 1 | AC21: 1.5 | AD21: 1 | AE21: 1.5 | AF21: 1 | AI21: 1 | AJ21: 1.5 | AK21: 1 | AL21: 1.5 | AN21: =SUM(I21:AM21) -> 28.5 | AO21: 240000 | AP21: =AN21*AO21 -> 6840000
A22: 17 | B22: 김택수 | C22: 751221-1663222 | D22: 보통인부 | E22: 010-7942-1751 | F22: 우리 | G22: 김택수 | H22: 1002-339-327014 | N22: 0.4375 | P22: 1 | Q22: 1.5 | R22: 1 | S22: 1 | U22: 1 | V22: 1.5 | W22: 1 | X22: 1.5 | Y22: 1 | Z22: 1 | AB22: 1 | AC22: 1.5 | AD22: 1 | AE22: 1.5 | AF22: 1 | AG22: 1 | AI22: 1 | AJ22: 1.5 | AK22: 1 | AL22: 1.5 | AN22: =SUM(I22:AM22) -> 23.9375 | AO22: 160000 | AP22: =AN22*AO22 -> 3830000
A23: 18 | B23: 김형태 | C23: 700430-1069427 | D23: 도비공 | E23: 010-3186-7175 | F23: 농협 | G23: 김형태 | H23: 352-1156-5484-53 | I23: 1 | J23: 1.5 | K23: 1 | L23: 1 | N23: 1 | O23: 1.5 | P23: 1 | Q23: 1.5 | R23: 1 | S23: 1 | U23: 1 | V23: 1.5 | W23: 1 | X23: 1.5 | Y23: 1 | Z23: 1 | AB23: 1 | AC23: 1.5 | AD23: 1 | AF23: 1 | AG23: 1 | AI23: 1 | AJ23: 1.5 | AK23: 1 | AL23: 1.5 | AN23: =SUM(I23:AM23) -> 29 | AO23: 180000 | AP23: =AN23*AO23 -> 5220000
A24: 19 | B24: 김희강 | C24: 010617-3234118 | D24: 보통인부 | E24: 010-7728-5274 | F24: 우리 | G24: 김희강 | H24: 1002-564-210008 | N24: 0.4375 | P24: 1 | U24: 1 | V24: 1.5 | Y24: 1 | Z24: 1 | AB24: 1 | AC24: 1.5 | AE24: 1.5 | AF24: 1 | AG24: 1 | AI24: 1 | AJ24: 1.5 | AK24: 1 | AN24: =SUM(I24:AM24) -> 15.4375 | AO24: 160000 | AP24: =AN24*AO24 -> 2470000
A25: 20 | B25: 남현빈 | C25: 990907-1842410 | D25: 배관공 | E25: 010-7131-4342 | F25: 카카오뱅크 | G25: 남현빈 | H25: 3333-13-8378173 | I25: 1 | J25: 1.5 | K25: 1 | L25: 1 | N25: 1 | O25: 1.5 | P25: 1 | R25: 1 | S25: 1 | U25: 1 | V25: 1.5 | W25: 1 | X25: 1.5 | Y25: 1 | AB25: 1 | AC25: 1.5 | AD25: 1 | AE25: 1.5 | AF25: 1 | AG25: 1 | AI25: 1 | AJ25: 1.5 | AK25: 1 | AL25: 1.5 | AN25: =SUM(I25:AM25) -> 28 | AO25: 190000 | AP25: =AN25*AO25 -> 5320000
A26: 21 | B26: 박지원 | C26: 960502-1784039 | D26: 배관공 | E26: 010-2498-2025 | F26: 국민 | G26: 박지원 | H26: 737302-01-193557 | AB26: 0.6875 | AC26: 1.125 | AD26: 0.5 | AE26: 0.5 | AF26: 1 | AI26: 1 | AJ26: 1.5 | AK26: 1 | AL26: 1.5 | AN26: =SUM(I26:AM26) -> 8.8125 | AO26: 230000 | AP26: =AN26*AO26 -> 2026875
A27: 22 | B27: 박혁 | C27: 741010-1241714 | D27: 배관공 | E27: 010 4943-6825 | F27: 국민 | G27: 박혁 | H27: 502901-01-043350 | AB27: 0.6875 | AC27: 1.125 | AD27: 0.5 | AE27: 0.5 | AF27: 1 | AI27: 1 | AJ27: 0.125 | AK27: 1 | AL27: 1.5 | AN27: =SUM(I27:AM27) -> 7.4375 | AO27: 230000 | AP27: =AN27*AO27 -> 1710625
A28: 23 | B28: 배찬영 | C28: 771214 -1906312 | D28: 보통인부 | E28: 010-8896-7746 | F28: 농협 | G28: 배찬영 | H28: 352-1366-3636-53 | I28: 0.8125 | N28: 1 | O28: 1.5 | P28: 1 | Q28: 1.5 | R28: 1 | S28: 0.4375 | U28: 1 | V28: 1.5 | W28: 1 | X28: 1.5 | Y28: 1 | Z28: 0.5 | AB28: 1 | AC28: 1.5 | AD28: 1 | AF28: 1 | AG28: 0.5 | AI28: 1 | AJ28: 1.5 | AK28: 1 | AL28: 1.5 | AN28: =SUM(I28:AM28) -> 23.75 | AO28: 160000 | AP28: =AN28*AO28 -> 3800000
A29: 24 | B29: 빈상원 | C29: 810410-1522211 | D29: 보통인부 | E29: 010-8778-9123 | F29: 신협 | G29: 빈상원 | H29: 137-012-596819 | I29: 1 | J29: 1.5 | AN29: =SUM(I29:AM29) -> 2.5 | AO29: 160000 | AP29: =AN29*AO29 -> 400000
A30: 25 | B30: 서지우 | C30: 720416-2101811 | D30: 보통인부 | E30: 010-5120-0531 | F30: 국민 | G30: 서지우 | H30: 781601-00-100125 | AB30: 0.6875 | AC30: 0.625 | AE30: 1 | AF30: 1 | AI30: 1 | AJ30: 1.5 | AN30: =SUM(I30:AM30) -> 5.8125 | AO30: 150000 | AP30: =AN30*AO30 -> 871875
A31: 26 | B31: 석임수 | C31: 911020-1685317 | D31: 안전보조 | E31: 010-4183-1119 | F31: 하나 | G31: 석임수 | H31: 238-910260-47407 | I31: 1 | J31: 1.5 | K31: 1 | L31: 1 | N31: 1 | O31: 1.5 | P31: 1 | Q31: 1.5 | R31: 1 | S31: 0.5 | U31: 1 | V31: 1.5 | W31: 1 | X31: 1.5 | Y31: 1 | Z31: 1 | AB31: 1 | AC31: 1.5 | AD31: 1 | AE31: 1.5 | AF31: 1 | AI31: 1 | AJ31: 1.5 | AK31: 1 | AL31: 1.5 | AN31: =SUM(I31:AM31) -> 29 | AO31: 190000 | AP31: =AN31*AO31 -> 5510000
A32: 27 | B32: 성지현 | C32: 861110-1351114 | D32: 보통인부 | E32: 010-9197-9732 | F32: 카카오뱅크 | G32: 성지현 | H32: 3333-01-9967097 | I32: 1 | J32: 1.5 | K32: 1 | L32: 1 | N32: 1 | O32: 1.5 | P32: 1 | Q32: 1.5 | R32: 1 | S32: 1 | U32: 1 | V32: 1.5 | W32: 1 | X32: 1.5 | Y32: 1 | Z32: 1 | AB32: 1 | AC32: 1.5 | AD32: 1 | AE32: 1.5 | AF32: 1 | AG32: 1 | AI32: 1 | AJ32: 1.5 | AK32: 1 | AL32: 1.5 | AN32: =SUM(I32:AM32) -> 30.5 | AO32: 230000 | AP32: =AN32*AO32 -> 7015000
A33: 28 | B33: 신경진 | C33: 880103-1105818 | D33: 용접공 | E33: 010-6540-2229 | F33: 기업 | G33: 신경진 | H33: 010-6540-2229 | U33: 0.9375 | V33: 0.5 | W33: 1 | X33: 1.5 | Y33: 1 | AB33: 1 | AC33: 1.5 | AD33: 1 | AE33: 1.5 | AF33: 1 | AG33: 1 | AI33: 1 | AJ33: 1.5 | AK33: 1 | AL33: 1.5 | AN33: =SUM(I33:AM33) -> 16.9375 | AO33: 240000 | AP33: =AN33*AO33 -> 4065000
A34: 29 | B34: 신민철 | C34: 830814-1183120 | D34: 공사보조 | E34: 010-7706-5000 | F34: 기업 | G34: 신민철 | H34: 289-082628-01-018 | I34: 1 | J34: 1.5 | K34: 1 | L34: 1 | N34: 1 | O34: 1.5 | P34: 1 | Q34: 1.375 | R34: 1 | S34: 1 | U34: 1 | V34: 1.5 | W34: 1 | X34: 1.5 | Y34: 1 | AB34: 1 | AC34: 1.5 | AD34: 1 | AE34: 0.25 | AF34: 1 | AG34: 1 | AI34: 1 | AJ34: 1.5 | AK34: 1 | AL34: 1.5 | AN34: =SUM(I34:AM34) -> 28.125 | AO34: 220000 | AP34: =AN34*AO34 -> 6187500
A35: 30 | B35: 심완 | C35: 870602-1417011 | D35: 용접공 | E35: 010-5101-6010 | F35: 기업 | G35: 심완 | H35: 507-027831-01-010 | AB35: 0.6875 | AC35: 1.125 | AD35: 0.5 | AE35: 0.5 | AF35: 1 | AI35: 1 | AJ35: 1.5 | AK35: 1 | AN35: =SUM(I35:AM35) -> 7.3125 | AO35: 240000 | AP35: =AN35*AO35 -> 1755000
A36: 31 | B36: 안수현 | C36: 970206-2728016 | D36: 용접공 | E36: 010-5045-9210 | F36: 하나 | G36: 안수현 | H36: 292-910293-88807 | U36: 0.9375 | V36: 0.5 | W36: 1 | X36: 1.5 | Y36: 1 | AB36: 1 | AC36: 1.5 | AD36: 1 | AE36: 1.5 | AF36: 1 | AG36: 1 | AI36: 1 | AJ36: 1.5 | AK36: 1 | AL36: 1.5 | AN36: =SUM(I36:AM36) -> 16.9375 | AO36: 240000 | AP36: =AN36*AO36 -> 4065000
A37: 32 | B37: 양정운 | C37: 821019-1449616 | D37: 공사보조 | E37: 010-3641-8181 | F37: 농협 | G37: 양정운 | H37: 302-1350-3060-51 | I37: 1 | J37: 1.5 | K37: 1 | L37: 1 | N37: 1 | O37: 1.5 | P37: 1 | R37: 1 | S37: 1 | U37: 1 | V37: 1.5 | W37: 1 | X37: 1.5 | Y37: 1 | AB37: 1 | AC37: 1.5 | AD37: 1 | AE37: 1.5 | AF37: 1 | AG37: 1 | AI37: 1 | AJ37: 1.5 | AK37: 1 | AL37: 1.5 | AN37: =SUM(I37:AM37) -> 28 | AO37: 250000 | AP37: =AN37*AO37 -> 7000000
A38: 33 | B38: 양정인 | C38: 810207-1455012 | D38: 보통인부 | E38: 010-8824-6401 | F38: 국민 | G38: 양정인 | H38: 472301-04-019277 | I38: 1 | J38: 1.5 | K38: 1 | L38: 1 | N38: 1 | O38: 1.5 | P38: 1 | Q38: 1.5 | R38: 1 | S38: 1 | U38: 1 | V38: 1.5 | W38: 1 | X38: 1.5 | Y38: 1 | Z38: 1 | AB38: 1 | AC38: 1.5 | AD38: 1 | AE38: 1.5 | AF38: 0.875 | AG38: 1 | AI38: 1 | AJ38: 1.5 | AK38: 1 | AL38: 1.5 | AN38: =SUM(I38:AM38) -> 30.375 | AO38: 170000 | AP38: =AN38*AO38 -> 5163750
A39: 34 | B39: 연승렬 | C39: 700216-1011916 | D39: 보통인부 | E39: 010-8098-3356 | F39: 기업 | G39: 연승렬 | H39: 186-086062-01-011 | I39: 1 | J39: 1.5 | K39: 0.5 | N39: 1 | O39: 1.5 | P39: 1 | Q39: 1.5 | R39: 1 | S39: 1 | U39: 1 | V39: 1.5 | X39: 1.5 | Y39: 1 | Z39: 1 | AB39: 1 | AC39: 1.5 | AD39: 1 | AF39: 1 | AG39: 0.8125 | AI39: 1 | AJ39: 1.5 | AK39: 1 | AL39: 1.5 | AN39: =SUM(I39:AM39) -> 26.3125 | AO39: 160000 | AP39: =AN39*AO39 -> 4210000
A40: 35 | B40: 옥유정 | C40: 850715-2093511 | D40: 보통인부 | E40: 010-2313-8731 | F40: 카카오뱅크 | G40: 옥유정 | H40: 3333-17-6983150 | I40: 1 | J40: 1.5 | K40: 1 | N40: 1 | O40: 1.5 | P40: 1 | R40: 1 | U40: 0.5 | V40: 1.5 | W40: 1 | X40: 1.5 | Y40: 1 | AB40: 1 | AC40: 1.5 | AD40: 1 | AF40: 1 | AI40: 1 | AJ40: 1.5 | AK40: 1 | AL40: 1.5 | AN40: =SUM(I40:AM40) -> 23 | AO40: 150000 | AP40: =AN40*AO40 -> 3450000
A41: 36 | B41: 윤대성 | C41: 870228-1800810 | D41: 용접공 | E41: 010-6690-3570 | F41: 신한 | G41: 윤대성 | H41: 110-404-264147 | U41: 0.9375 | W41: 1 | X41: 1.5 | Y41: 1 | AB41: 1 | AC41: 1.5 | AD41: 1 | AE41: 1.5 | AF41: 1 | AG41: 1 | AI41: 1 | AJ41: 1.5 | AK41: 1 | AL41: 1.5 | AN41: =SUM(I41:AM41) -> 16.4375 | AO41: 240000 | AP41: =AN41*AO41 -> 3945000
...

Sheet 숙소임차료
A1: 숙소 임차료
A2: No. | B2: 납부일 | C2: 구분 | D2: 품명 | E2: 주소 | F2: 호수 | G2: 수량 | H2: 사용인원 | I2: 임차료 | J2: 비 고
I3: =SUM(I4:I17) -> 23280000 | L3: 입력해야하는 항목 외 수정 금지
A4: 1 | B4: 46142 | C4: KC대납 임대료 | D4: 숙소임대료(04월분) | E4: 고덕갈평10길 40, 301호 | F4: 301호 | G4: 1 | H4: 6 | I4: 1600000 | J4: KC 대납 | L4: 납부일
A5: 2 | B5: 46142 | C5: KC대납 임대료 | D5: 숙소임대료(04월분) | E5: 함박산1길 50, 401호 | F5: 401호 | G5: 1 | H5: 6 | I5: 1700000 | J5: KC 대납 | L5: 구분
A6: 3 | B6: 46142 | C6: KC대납 임대료 | D6: 숙소임대료(04월분) | E6: 함박산4길 3, 301호 | F6: 301호 | G6: 1 | H6: 6 | I6: 1530000 | J6: KC 대납 | L6: 품명
A7: 4 | B7: 46142 | C7: KC대납 임대료 | D7: 숙소임대료(04월분) | E7: 고덕여염11길 14, 202호 | F7: 202호 | G7: 1 | H7: 4 | I7: 1300000 | J7: KC 대납 | L7: 주소
A8: 5 | B8: 46142 | C8: KC대납 임대료 | D8: 숙소임대료(04월분) | E8: 함박산3길37, 301호 | F8: 301호 | G8: 1 | H8: 6 | I8: 1600000 | J8: KC 대납 | L8: 호수
A9: 6 | B9: 46142 | C9: KC대납 임대료 | D9: 숙소임대료(04월분) | E9: 함박산9길28, 401호(복층) | F9: 401호 | G9: 1 | H9: 6 | I9: 2000000 | J9: KC 대납 | L9: 수량
A10: 7 | B10: 46142 | C10: KC대납 임대료 | D10: 숙소임대료(04월분) | E10: 고덕국제4길 60-16 202호 | F10: 202호 | G10: 1 | H10: 6 | I10: 1600000 | J10: KC 대납 | L10: 사용인원
A11: 8 | B11: 46142 | C11: KC대납 임대료 | D11: 숙소임대료(04월분) | E11: 고덕여염11길 149, 202호 | F11: 202호 | G11: 1 | H11: 6 | I11: 1900000 | J11: KC 대납
A12: 9 | B12: 46142 | C12: KC대납 임대료 | D12: 숙소임대료(04월분) | E12: 고덕여염6길 199 202호 | F12: 202호 | G12: 1 | H12: 6 | I12: 1800000 | J12: KC 대납 | L12: ■ 구분은 [KC대납 임대료 및 임대료] 이외 항목은 입력금지
A13: 10 | B13: 46142 | C13: KC대납 임대료 | D13: 숙소임대료(04월분) | E13: 함박산1길 34 301호 | F13: 301호 | G13: 1 | H13: 6 | I13: 1700000 | J13: KC 대납
A14: 11 | B14: 46142 | C14: KC대납 임대료 | D14: 숙소임대료(04월분) | E14: 함박산9길26, 202호 | F14: 202호 | G14: 1 | H14: 4 | I14: 1600000 | J14: KC 대납
A15: 12 | B15: 46142 | C15: KC대납 임대료 | D15: 숙소임대료(04월분) | E15: 함박산 11길 9-1, 202호 | F15: 202호 | G15: 1 | H15: 6 | I15: 1650000 | J15: KC 대납
A16: 13 | B16: 46142 | C16: KC대납 임대료 | D16: 숙소임대료(04월분) | E16: 함박산 3길 11, 301호 | F16: 301호 | G16: 1 | H16: 6 | I16: 1900000 | J16: KC 대납
A17: 14 | B17: 46142 | C17: KC대납 임대료 | D17: 숙소임대료(04월분) | E17: 고덕여염16길115, 202호 | F17: 202호 | G17: 1 | H17: 4 | I17: 1400000 | J17: KC 대납

Sheet 숙소관리비
A1: 숙소 관리비
A2: No. | B2: 납부일 | C2: 구분 | D2: 품명 | E2: 주소 | F2: 호수 | G2: 수량 | H2: 사용인원 | I2: 관리비 | J2: 비 고
I3: =SUM(I4:I45) -> 1761540
A4: 1 | B4: 46142 | C4: KC대납 관리비 | D4: 숙소수도세(04월분) | E4: 고덕갈평10길 40, 301호 | F4: 301호 | G4: 1 | H4: 3 | I4: 2100 | J4: KC 대납
A5: 2 | B5: 46142 | C5: KC대납 관리비 | D5: 숙소가스료(04월분) | E5: 고덕갈평10길 40, 301호 | F5: 301호 | G5: 1 | H5: 3 | I5: 194420 | J5: KC 대납
A6: 3 | B6: 46142 | C6: KC대납 관리비 | D6: 숙소전기료(04월분) | E6: 고덕갈평10길 40, 301호 | F6: 301호 | G6: 1 | H6: 3 | I6: 37730 | J6: KC 대납
A7: 4 | B7: 46142 | C7: KC대납 관리비 | D7: 숙소수도세(04월분) | E7: 함박산1길 50, 401호 | F7: 401호 | G7: 1 | H7: 5 | I7: 16750 | J7: KC 대납
A8: 5 | B8: 46142 | C8: KC대납 관리비 | D8: 숙소가스료(04월분) | E8: 함박산1길 50, 401호 | F8: 401호 | G8: 1 | H8: 5 | I8: 256300 | J8: KC 대납
A9: 6 | B9: 46142 | C9: KC대납 관리비 | D9: 숙소전기료(04월분) | E9: 함박산1길 50, 401호 | F9: 401호 | G9: 1 | H9: 5 | I9: 71390 | J9: KC 대납
A10: 7 | B10: 46142 | C10: KC대납 관리비 | D10: 숙소수도세(04월분) | E10: 함박산4길 3, 301호 | F10: 301호 | G10: 1 | H10: 6 | I10: 공용수도 | J10: KC 대납
A11: 8 | B11: 46142 | C11: KC대납 관리비 | D11: 숙소가스료(04월분) | E11: 함박산4길 3, 301호 | F11: 301호 | G11: 1 | H11: 6 | I11: 125310 | J11: KC 대납
A12: 9 | B12: 46142 | C12: KC대납 관리비 | D12: 숙소전기료(04월분) | E12: 함박산4길 3, 301호 | F12: 301호 | G12: 1 | H12: 6 | I12: 49530 | J12: KC 대납
A13: 10 | B13: 46142 | C13: KC대납 관리비 | D13: 숙소수도세(04월분) | E13: 고덕여염11길 14, 202호 | F13: 202호 | G13: 1 | H13: 4 | I13: 익월청구예정 | J13: KC 대납
A14: 11 | B14: 46142 | C14: KC대납 관리비 | D14: 숙소가스료(04월분) | E14: 고덕여염11길 14, 202호 | F14: 202호 | G14: 1 | H14: 4 | I14: 148140 | J14: KC 대납
A15: 12 | B15: 46142 | C15: KC대납 관리비 | D15: 숙소전기료(04월분) | E15: 고덕여염11길 14, 202호 | F15: 202호 | G15: 1 | H15: 4 | I15: 40490 | J15: KC 대납
A16: 13 | B16: 46142 | C16: KC대납 관리비 | D16: 숙소수도세(04월분) | E16: 함박산3길37, 301호 | F16: 301호 | G16: 1 | H16: 6 | I16: 1200 | J16: KC 대납
A17: 14 | B17: 46142 | C17: KC대납 관리비 | D17: 숙소가스료(04월분) | E17: 함박산3길37, 301호 | F17: 301호 | G17: 1 | H17: 6 | I17: 157440 | J17: KC 대납
A18: 15 | B18: 46142 | C18: KC대납 관리비 | D18: 숙소전기료(04월분) | E18: 함박산3길37, 301호 | F18: 301호 | G18: 1 | H18: 6 | I18: 38740 | J18: KC 대납
A19: 16 | B19: 46142 | C19: KC대납 관리비 | D19: 숙소수도세(04월분) | E19: 함박산9길28, 401호(복층) | F19: 401호 | G19: 1 | H19: 4 | I19: 익월청구예정 | J19: KC 대납
A20: 17 | B20: 46142 | C20: KC대납 관리비 | D20: 숙소가스료(04월분) | E20: 함박산9길28, 401호(복층) | F20: 401호 | G20: 1 | H20: 4 | I20: 199270 | J20: KC 대납
A21: 18 | B21: 46142 | C21: KC대납 관리비 | D21: 숙소전기료(04월분) | E21: 함박산9길28, 401호(복층) | F21: 401호 | G21: 1 | H21: 4 | I21: 49400 | J21: KC 대납
A22: 19 | B22: 46142 | C22: KC대납 관리비 | D22: 숙소수도세(04월분) | E22: 고덕국제4길 60-16 202호 | F22: 202호 | G22: 1 | H22: 4 | I22: 익월청구예정 | J22: KC 대납
A23: 20 | B23: 46142 | C23: KC대납 관리비 | D23: 숙소가스료(04월분) | E23: 고덕국제4길 60-16 202호 | F23: 202호 | G23: 1 | H23: 4 | I23: 95670 | J23: KC 대납
A24: 21 | B24: 46142 | C24: KC대납 관리비 | D24: 숙소전기료(04월분) | E24: 고덕국제4길 60-16 202호 | F24: 202호 | G24: 1 | H24: 4 | I24: 익월청구예정 | J24: KC 대납
A25: 22 | B25: 46142 | C25: KC대납 관리비 | D25: 숙소수도세(04월분) | E25: 고덕여염11길 149, 202호 | F25: 202호 | G25: 1 | H25: 4 | I25: 1050 | J25: KC 대납
A26: 23 | B26: 46142 | C26: KC대납 관리비 | D26: 숙소가스료(04월분) | E26: 고덕여염11길 149, 202호 | F26: 202호 | G26: 1 | H26: 4 | I26: 97780 | J26: KC 대납
A27: 24 | B27: 46142 | C27: KC대납 관리비 | D27: 숙소전기료(04월분) | E27: 고덕여염11길 149, 202호 | F27: 202호 | G27: 1 | H27: 4 | I27: 19520 | J27: KC 대납
A28: 25 | B28: 46142 | C28: KC대납 관리비 | D28: 숙소수도세(04월분) | E28: 고덕여염6길 199 202호 | F28: 202호 | G28: 1 | H28: 5 | I28: 익월청구예정 | J28: KC 대납
A29: 26 | B29: 46142 | C29: KC대납 관리비 | D29: 숙소가스료(04월분) | E29: 고덕여염6길 199 202호 | F29: 202호 | G29: 1 | H29: 5 | I29: 46700 | J29: KC 대납
A30: 27 | B30: 46142 | C30: KC대납 관리비 | D30: 숙소전기료(04월분) | E30: 고덕여염6길 199 202호 | F30: 202호 | G30: 1 | H30: 5 | I30: 익월청구예정 | J30: KC 대납
A31: 28 | B31: 46142 | C31: KC대납 관리비 | D31: 숙소수도세(04월분) | E31: 함박산1길 34 301호 | F31: 301호 | G31: 1 | H31: 5 | I31: 익월청구예정 | J31: KC 대납
A32: 29 | B32: 46142 | C32: KC대납 관리비 | D32: 숙소가스료(04월분) | E32: 함박산1길 34 301호 | F32: 301호 | G32: 1 | H32: 5 | I32: 77580 | J32: KC 대납
A33: 30 | B33: 46142 | C33: KC대납 관리비 | D33: 숙소전기료(04월분) | E33: 함박산1길 34 301호 | F33: 301호 | G33: 1 | H33: 5 | I33: 익월청구예정 | J33: KC 대납
A34: 31 | B34: 46142 | C34: KC대납 관리비 | D34: 숙소수도세(04월분) | E34: 함박산9길26, 202호 | F34: 202호 | G34: 1 | H34: 6 | I34: 1200 | J34: KC 대납
A35: 32 | B35: 46142 | C35: KC대납 관리비 | D35: 숙소가스료(04월분) | E35: 함박산9길26, 202호 | F35: 202호 | G35: 1 | H35: 6 | I35: 9300 | J35: KC 대납
A36: 33 | B36: 46142 | C36: KC대납 관리비 | D36: 숙소전기료(04월분) | E36: 함박산9길26, 202호 | F36: 202호 | G36: 1 | H36: 6 | I36: 익월청구예정 | J36: KC 대납
A37: 34 | B37: 46142 | C37: KC대납 관리비 | D37: 숙소수도세(04월분) | E37: 함박산 11길 9-1, 202호 | F37: 202호 | G37: 1 | H37: 6 | I37: 익월청구예정 | J37: KC 대납
A38: 35 | B38: 46142 | C38: KC대납 관리비 | D38: 숙소가스료(04월분) | E38: 함박산 11길 9-1, 202호 | F38: 202호 | G38: 1 | H38: 6 | I38: 1450 | J38: KC 대납
A39: 36 | B39: 46142 | C39: KC대납 관리비 | D39: 숙소전기료(04월분) | E39: 함박산 11길 9-1, 202호 | F39: 202호 | G39: 1 | H39: 6 | I39: 익월청구예정 | J39: KC 대납
A40: 37 | B40: 46142 | C40: KC대납 관리비 | D40: 숙소수도세(04월분) | E40: 함박산 3길 11, 301호 | F40: 301호 | G40: 1 | H40: 6 | I40: 익월청구예정 | J40: KC 대납
...

Sheet 식대비용
A1: 식대 비용
A2: No. | B2: 납부일 | C2: 구분 | D2: 품명 | E2: 거래처명 | F2: 수량 | G2: 식수인원 | H2: 단가 | I2: 합 계 | J2: 비 고
I3: =SUM(I4:I5) -> 19533136 | L3: 입력해야하는 항목 외 수정 금지
A4: 1 | B4: 46142 | C4: KC대납 식대 | D4: 기술인및관리자 (현장 식당) | E4: 포세카 | F4: 1452 | G4: 56 | H4: 6181.82 | I4: 8928136 | J4: KC 대납 | L4: 입력항목
A5: 2 | B5: 46142 | C5: KC대납 식대 | D5: 기술인및관리자 (현장 식당) | E5: 밥심 | F5: 1515 | G5: 57 | H5: 7000 | I5: =F5*H5 -> 10605000 | J5: KC 대납 | L5: 납부일
L6: 구분
L7: 품명
L8: 거래처명
L9: 수량
L10: 식수인원
L11: 단가
L13: ■ 구분은 [KC대납 식대 및 식대] 이외 항목은 입력금지

Sheet 기타비용
A1: 기타 비용
A2: No. | B2: 구매일 | C2: 구분 | D2: 품명 | E2: 거래처명 | F2: 수량 | G2: 단가 | H2: 합계 | I2: 비고
H3: =SUM(H4:H62) -> 5181000 | K3: 입력해야하는 항목 외 수정 금지
A4: 1 | B4: 46118 | C4: 소모품비 | D4: [수리]보쉬 GDX19V-180(3) [좌우레바/엔빌스프링] | E4: 미래공구 | F4: 1 | G4: 13000 | H4: =F4*G4 -> 13000 | I4: 거래명세서 첨부 | K4: 입력항목
A5: 2 | B5: 46118 | C5: 소모품비 | D5: [수리]보쉬 GDX19V-180(4) [엔빌스프링] | E5: 미래공구 | F5: 1 | G5: 6700 | H5: =F5*G5 -> 6700 | I5: 거래명세서 첨부 | K5: 납부일
A6: 3 | B6: 46118 | C6: 소모품비 | D6: [수리]보쉬 GDX19V-200(7) [비트제거/엔빌스프링] | E6: 미래공구 | F6: 1 | G6: 18900 | H6: =F6*G6 -> 18900 | I6: 거래명세서 첨부 | K6: 구분
A7: 4 | B7: 46119 | C7: 소모품비 | D7: 절연테이프 [19*10m,검정,CTX [금성]] | E7: 미래공구 | F7: 20 | G7: 400 | H7: =F7*G7 -> 8000 | I7: 거래명세서 첨부 | K7: 품명
A8: 5 | B8: 46120 | C8: 소모품비 | D8: 청보호랩 [500mm*150m,40mic [AS]] | E8: 미래공구 | F8: 8 | G8: 19800 | H8: =F8*G8 -> 158400 | I8: 거래명세서 첨부 | K8: 거래처명
A9: 6 | B9: 46120 | C9: 소모품비 | D9: 에폭시접착제 [매직스틱,다목적용,114G,CTX [엑시아]] | E9: 미래공구 | F9: 4 | G9: 7100 | H9: =F9*G9 -> 28400 | I9: 거래명세서 첨부 | K9: 수량
A10: 7 | B10: 46120 | C10: 소모품비 | D10: 귀마개 [1100,끈없음,200개 [3M]] | E10: 미래공구 | F10: 1 | G10: 40000 | H10: =F10*G10 -> 40000 | I10: 거래명세서 첨부 | K10: 식수인원
A11: 8 | B11: 46120 | C11: 소모품비 | D11: 레이저거리측정기 [SABER mini [맥파이]] | E11: 미래공구 | F11: 1 | G11: 55400 | H11: =F11*G11 -> 55400 | I11: 거래명세서 첨부 | K11: 단가
A12: 9 | B12: 46121 | C12: 소모품비 | D12: 우의 [일회용,크래커,백색 [SW]] | E12: 미래공구 | F12: 15 | G12: 600 | H12: =F12*G12 -> 9000 | I12: 거래명세서 첨부
A13: 10 | B13: 46121 | C13: 소모품비 | D13: 가위집 [PVC [AK]] | E13: 미래공구 | F13: 7 | G13: 2100 | H13: =F13*G13 -> 14700 | I13: 거래명세서 첨부 | K13: ■ 구분은 [KC대납 식대 및 식대] 이외 항목은 입력금지
A14: 11 | B14: 46121 | C14: 소모품비 | D14: 컷쏘날 [S1122BF,철재,바이메탈,5개입 [보쉬]] | E14: 미래공구 | F14: 2 | G14: 19000 | H14: =F14*G14 -> 38000 | I14: 거래명세서 첨부
A15: 12 | B15: 46121 | C15: 소모품비 | D15: 장갑클립 [일반형] | E15: 미래공구 | F15: 30 | G15: 1400 | H15: =F15*G15 -> 42000 | I15: 거래명세서 첨부
A16: 13 | B16: 46122 | C16: 소모품비 | D16: 체인컷쏘날 [200*8T(4"),골드 61503,5개입 [아사다]] | E16: 미래공구 | F16: 2 | G16: 127600 | H16: =F16*G16 -> 255200 | I16: 거래명세서 첨부
A17: 14 | B17: 46122 | C17: 소모품비 | D17: 체인컷쏘날 [320*8T(4"),골드 61507,5개입 [아사다]] | E17: 미래공구 | F17: 1 | G17: 162400 | H17: =F17*G17 -> 162400 | I17: 거래명세서 첨부
A18: 15 | B18: 46122 | C18: 소모품비 | D18: PP로프 [16mm*100m [HNS]] | E18: 미래공구 | F18: 6 | G18: 50400 | H18: =F18*G18 -> 302400 | I18: 거래명세서 첨부
A19: 16 | B19: 46122 | C19: 소모품비 | D19: 가위 [SB-P300,CTX [세신]] | E19: 미래공구 | F19: 1 | G19: 4500 | H19: =F19*G19 -> 4500 | I19: 거래명세서 첨부
A20: 17 | B20: 46122 | C20: 소모품비 | D20: 드라이버비트 [OTP-065,PH2*65L(+) [오토코]] | E20: 미래공구 | F20: 2 | G20: 900 | H20: =F20*G20 -> 1800 | I20: 거래명세서 첨부
A21: 18 | B21: 46122 | C21: 소모품비 | D21: 청보호랩 [500mm*150m,40mic [AS]] | E21: 미래공구 | F21: 4 | G21: 19800 | H21: =F21*G21 -> 79200 | I21: 거래명세서 첨부
A22: 19 | B22: 46125 | C22: 소모품비 | D22: 수리비,레이저레벨기 [RX20,축수리,모터1개 교환,센서수리,수평/수직교정] | E22: 미래공구 | F22: 1 | G22: 59000 | H22: =F22*G22 -> 59000 | I22: 거래명세서 첨부
A23: 20 | B23: 46125 | C23: 소모품비 | D23: 건전지 [AA,2개 [벡셀]] | E23: 미래공구 | F23: 60 | G23: 900 | H23: =F23*G23 -> 54000 | I23: 거래명세서 첨부
A24: 21 | B24: 46125 | C24: 소모품비 | D24: 케이블타이 [300mm(1봉=500개),백색 [HNS]] | E24: 미래공구 | F24: 2 | G24: 11700 | H24: =F24*G24 -> 23400 | I24: 거래명세서 첨부
A25: 22 | B25: 46125 | C25: 소모품비 | D25: 직쏘날 [301CD,5개 [보쉬]] | E25: 미래공구 | F25: 1 | G25: 9300 | H25: =F25*G25 -> 9300 | I25: 거래명세서 첨부
... A62: 59 | B62: 46115 | C62: 소모품비 | D62: 열쇠 [400L,LONG,CTX [금강산업]] | E62: 미래공구 | F62: 8 | G62: 4000 | H62: =F62*G62 -> 32000 | I62: 거래명세서 첨부

Sheet 서명란
B2: 현 장 확 인 | C2: 소 장 | E2: (서명)
C3: 공 사 | E3: (서명)
C4: 공 무 | E4: (서명)
G6: 사 업 부 | H6: Frontier 사업부 GNP 본부장 | I6: BOC 센터장 | J6: Frontier 사업부장
L8: 본 사 | M8: 담 당 | N8: 검 토 | O8: 검 토
Q11: 구 분 | R11: 확 인
Q12: 품 질 | R12: O O O (인)
Q13: 공 무 | R13: O O O (인)

Sheet DIA-INCH
B3: SIZE
B4: A(mm) | C4: Inch
B5: 8A | C5: 0.25
B6: 15A | C6: 0.5
B7: 20A | C7: 0.75
B8: 25A | C8: 1
B9: 32A | C9: 1.25
B10: 40A | C10: 1.5
B11: 50A | C11: 2
B12: 65A | C12: 2.5
B13: 80A | C13: 3
B14: 100A | C14: 4
B15: 110A | C15: 4
B16: 125A | C16: 5
... B27: 550A | C27: 22
