Workbook

Sheet 용역청구서 표지
B4: 용 역 청 구 서
B7: P4 Ph2 GAS&PCW 1공구
C8: S26-001
C14: 2026년 05월
C15: 대성이엔지

Sheet 용역 청구서(갑지)
A1: 용 역 청 구 서
A3: 1 | B3: 공 사 명 | C3: : | D3: ='용역청구서 표지'!$B$7 -> P4 Ph2 GAS&PCW 1공구 | E3: ='용역청구서 표지'!$C$8 -> S26-001
A4: 2 | B4: 공 종 | C4: : | D4: 외주용역(M/M부분)
A5: 3 | B5: 계 약 금 액 | C5: : | D5: =ROUNDUP(E5,0) -> -174338537 | E5: =집계장!J25 -> -174338537 | F5: (VAT 별도)
A6: 4 | B6: 누 계 기 성 금 액 | C6: : | D6: =ROUNDUP(E6,0) -> 0 | E6: =E7+E13 -> 0 | F6: (VAT 별도)
A7: 5 | B7: 전 회 기 성 금 액 | C7: : | D7: =ROUNDUP(E7,0) -> 0 | E7: 0 | F7: (VAT 별도)
A8: 6 | B8: 금 회 기 성 금 액 | C8: : | D8: =ROUNDUP(E8,0) -> -174338537 | E8: =집계장!I25 -> -174338537 | F8: (VAT 별도)
A9: 7 | B9: 선 금 액 | C9: : | D9: =ROUNDUP(E9,0) -> 0 | E9: =집계장!L23 -> 0 | F9: (VAT 별도)
A10: 8 | B10: 선 금 전 회 공 제 | C10: : | D10: =ROUNDUP(E10,0) -> 0 | E10: =집계장!H23 -> 0 | F10: (VAT 별도)
A11: 9 | B11: 선 금 금 회 공 제 | C11: : | D11: =ROUNDUP(E11,0) -> 0 | E11: =집계장!G23 -> 0 | F11: (VAT 별도)
A12: 10 | B12: 선 금 잔 여 금 액 | C12: : | D12: =ROUNDUP(E12,0) -> 0 | E12: =집계장!M23 -> 0 | F12: (VAT 별도)
A13: 11 | B13: 금 회 청 구 금 액 | C13: : | D13: =ROUNDUP(E13,0) -> 0 | E13: 0 | F13: (VAT 별도)
A14: 12 | B14: 잔 여 기 성 금 액 | C14: : | D14: =ROUNDUP(E14,0) -> 0 | F14: (VAT 별도)
A15: 13 | B15: 공 정 율 | C15: : | D15: 1
A16: 14 | B16: 청 구 공 사 기 간 | C16: : | D16: 2026. 05. 01 ~ 2026. 05. 31
B18: 위 공사의 하도급에 있어서 공사설계도서, 시방서,품질관리 기준 및 약정대로 시공 되었음을 확인하오며. 만약 귀사의 현장담당의 검사에
B19: 관하여 하자가 발견된 때에는 즉시 실액배상 또는 재 시공할것을 서약하고 이에 기성 청구서를 제출합니다.
B20: 상기건과 관련하여 본 청구 이전까지의 모든 대금은 수령하였음을 확약합니다.
F21: 작 성 일 : 2026 년 05 월 31 일
F23: 상 호 : | G23: 대성이엔지
B24: ※첨 부 : 기성내역서 1부. | F24: 주 소 : | G24: 경기도 파주시 파주읍 주라위길 380
F25: 대표이사 : | G25: 정 성 기 | I25: (인)
D26: ㈜케이씨이앤씨 귀하

Sheet 용역 내역서(을지)
A1: 용 역 내 역 서
A2: P4 Ph4 GAS 1공구 마감공사 | G2: 단위 : 원
A3: 품 명 | B3: 규 격 | C3: 단위 | D3: 단 가 | E3: 금 회 청 구
E4: 수 량 | F4: 금 액 | G4: 비 고
A5: 고급기술인 | B5: S+ | C5: M/M | D5: 1400000 | E5: 1 | F5: =D5*E5 -> 1400000
A6: 고급기술인 | B6: S | C6: M/M | D6: 1200000 | F6: =D6*E6 -> 0
A7: 중급기술인 | B7: A+ | C7: M/M | D7: 1000000 | F7: =D7*E7 -> 0
A8: 중급기술인 | B8: A | C8: M/M | D8: 900000 | F8: =D8*E8 -> 0
A9: 중급기술인 | B9: B+ | C9: M/M | D9: 800000 | F9: =D9*E9 -> 0
A10: 중급기술인 | B10: B | C10: M/M | D10: 700000 | F10: =D10*E10 -> 0
A11: 초급 기술인 | B11: C | C11: M/M | D11: 600000 | F11: =D11*E11 -> 0
A13: 인센티브 | E13: 0.01 | F13: =SUM(F5:F11)*E13 -> 14000
A15: 총 계 | E15: =SUM(E5:E11) -> 1 | F15: =SUM(F5:F13) -> 1414000

Sheet 내역서(을지)
A1: 용 역 내 역 서
A2: =집계장!B2 -> P4 Ph2 GAS&PCW 1공구 | G2: 단위 : 원
A3: 품 명 | B3: 규 격 | C3: 단위 | D3: 단 가 | E3: 금 회 청 구 | G3: 비 고
E4: 수 량 | F4: 금 액
A5: 고급기술인 | B5: S+ | C5: M/M | D5: 1400000 | E5: 8 | F5: =D5*E5 -> 11200000
A6: 고급기술인 | B6: S | C6: M/M | D6: 1200000 | E6: 2 | F6: =D6*E6 -> 2400000
A7: 중급기술인 | B7: A+ | C7: M/M | D7: 1000000 | E7: 6 | F7: =D7*E7 -> 6000000
A8: 중급기술인 | B8: A | C8: M/M | D8: 900000 | E8: 1 | F8: =D8*E8 -> 900000
A9: 중급기술인 | B9: B+ | C9: M/M | D9: 800000 | E9: 4 | F9: =D9*E9 -> 3200000
A10: 중급기술인 | B10: B | C10: M/M | D10: 700000 | E10: 9 | F10: =D10*E10 -> 6300000
A11: 초급기술인 | B11: C | C11: M/M | D11: 600000 | F11: =D11*E11 -> 0
A27: 총 계 | E27: =SUM(E5:E11) -> 30 | F27: =SUM(F5:F26) -> 30000000

Sheet 집계장
B2: ='용역청구서 표지'!$B$7 -> P4 Ph2 GAS&PCW 1공구
M3: ='용역청구서 표지'!$C$15 -> 대성이엔지
B4: 구분 | C4: 내역 | D4: 단위 | E4: 수량 | F4: 단가 | G4: 합계 | H4: 전회기성 | I4: 금회기성 | J4: 누계기성 | K4: 비 고
B5: 1. 물량 | C5: WELDING POINT | D5: D/I | E5: =SUM('물량 내역서'!$J$6:$J$28) -> 1047.5 | F5: =G5/E5 -> 475000 | G5: =SUM('물량 내역서'!$K$6:$K$28) -> 497562500 | H5: 261250000 | I5: =G5 -> 497562500 | J5: =H5+I5 -> 758812500
C6: VALVE 설치비 | D6: EA | E6: =SUM('물량 내역서'!$J$29:$J$51) -> 0 | F6: =G6/E6 -> #DIV/0! | G6: =SUM('물량 내역서'!$K$29:$K$51) -> 0 | H6: 0 | I6: =G6 -> 0 | J6: =H6+I6 -> 0
C7: 인원 실투입 | D7: M/D | E7: ='근로내역 (05월)'!AN113 -> 0 | F7: 0 | G7: =E7*F7 -> 0 | H7: 0 | I7: =G7 -> 0 | J7: =H7+I7 -> 0
B8: 소 계 | C8: 물량 | G8: =SUM(G5:G7) -> 497562500 | H8: 261250000 | I8: =G8 -> 497562500 | J8: =H8+I8 -> 758812500
B9: 2. 노무비 | C9: 직접노무비 | D9: 式 | E9: ='근로내역 (05월)'!AN101 -> 2013.375 | F9: =G9/E9 -> 191877.44 | G9: ='근로내역 (05월)'!AP101 -> 386321250 | H9: 371528750 | I9: =G9 -> 386321250 | J9: =H9+I9 -> 757850000
B10: 3. 숙소 및 식대 | C10: 임대료+관리비 | D10: 式 | E10: =SUM(숙소임차료!H4:H6)+SUM(숙소관리비!H4:H8) -> 38 | F10: =G10/E10 -> 1166046.6 | G10: =숙소임차료!I3+숙소관리비!I3 -> 44309770 | H10: 43371540 | I10: =G10 -> 44309770 | J10: =H10+I10 -> 87681310 | O10: =+I10+I11 -> 74455543
C11: 식대 | D11: 式 | E11: =SUM(식대비용!G4:G4) -> 90 | F11: =G11/E11 -> 334953.03 | G11: =식대비용!I3 -> 30145773 | H11: 27473954 | I11: =G11 -> 30145773 | J11: =H11+I11 -> 57619727
B12: 4. 기타 공제 내역 | D12: 式 | F12: 0 | G12: =E12*F12 -> 0 | I12: =G12 -> 0 | J12: =H12+I12 -> 0
B13: 소 계 | C13: 공제 | G13: =SUM(G9:G12) -> 460776793 | H13: =SUM(H9:H12) -> 442374244 | I13: =G13 -> 460776793 | J13: =H13+I13 -> 903151037 | K13: 전월 적자 기성액 (139,160,193원)
B14: 합 계 | C14: 기성 (물량-공제) | G14: =G8-G13 -> 36785707 | H14: =H8-H13 -> -181124244 | I14: =G14 -> 36785707 | J14: =H14+I14 -> -144338537
B15: 5. 유보금 | C15: 기성금*XX% | D15: 式 | I15: =G15 -> 0 | J15: =H15+I15 -> 0
B16: 6. 유보금 차액 | C16: 전회 누계유보금 | D16: 式 | J16: =H16+I16 -> 0
B17: 7. NEGO | C17: NEGO | D17: 式 | I17: =G17 -> 0 | J17: =H17+I17 -> 0
B18: 총 계 | C18: 최종기성 | G18: =G14+G15+G16+G17 -> 36785707 | H18: =H14+H15+H16+H17 -> -181124244 | I18: =I14+I15+I16+I17 -> 36785707 | J18: =J14+J15+J16+J17 -> -144338537
B19: 8. 기타지급운영비 | C19: 기타지급 운영비 | D19: 式 | E19: =SUM('물량 내역서'!$J$6:$J$28) -> 1047.5 | F19: =G19/E19 -> 201550.59 | G19: 211124244 | H19: -30000000 | J19: =H19+G19 -> 181124244
C20: 누계 적자기성액 | D20: 式 | G20: -211124244 | I20: =G20 -> -211124244 | J20: =H20+G20 -> -211124244
B21: 소 계 | G21: =SUM(G19:G20) -> 0 | H21: =SUM(H19:H20) -> -30000000 | I21: =SUM(I19:I20) -> -211124244 | J21: =SUM(J19:J20) -> -30000000
B22: 선급금 | C22: 선수공제 | D22: 式 | I22: =G22 -> 0 | J22: =H22+I22 -> 0 | L22: 지급 선급금 | M22: 선급금 차액
C23: 단수정리 | D23: 式 | G23: =ROUNDDOWN(G22,-5) -> 0 | I23: =G23 -> 0 | J23: =H23+I23 -> 0 | K23: 만 단위 이하 절사
B24: 공제 후 실 지급액 | G24: =G18-G23 -> 36785707 | H24: =H18-H23 -> -181124244 | I24: =I18-I23 -> 36785707 | J24: =J18-J23 -> -144338537
B25: 세금계산서 기준 | G25: =G24+G21 -> 36785707 | H25: =H24+H21 -> -211124244 | I25: =I24+I21 -> -174338537 | J25: =J24+J21 -> -174338537 | K25: 만 단위 이하 절사
B26: TERMS AND CONDITIONS | E26: NOTE
B27: 1. 납 기 : KCEnC 지정 납기로 별도 협의 하에 결정하는 것으로 함.
B28: 2. 지불조건 : KCEnC 지불 조건에 따름.
B29: 3. 유효기간 : 기성 제출일로 부터 30일 이내

Sheet 물량 내역서
A1: 2026년 (05)월 물량 내역서
A2: ='용역청구서 표지'!$B$7 -> P4 Ph2 GAS&PCW 1공구 | M2: 단위 : 원
A3: 품 명 | B3: 규 격 | C3: 단위 | D3: W/P 수량 | E3: 단 가 | F3: 계 약 내 역 | H3: 전 회 누 계 물 량 | J3: 금 회 물 량 | L3: 누 계 물 량
F4: D/I 수량 | G4: 금액 | H4: D/I 수량 | I4: 금액 | J4: D/I 수량 | K4: 금액 | L4: D/I 수량 | M4: 금액
A6: WEDING POINT | B6: 8A | C6: POINT | E6: 475000 | F6: =L6 -> 0 | G6: =M6 -> 0 | J6: =$D6*'DIA-INCH'!$C5 -> 0 | K6: =$E6*$J6 -> 0 | L6: =H6+J6 -> 0 | M6: =I6+K6 -> 0
A7: WEDING POINT | B7: 15A | C7: POINT | E7: 475000 | F7: =L7 -> 0 | G7: =M7 -> 0 | J7: =$D7*'DIA-INCH'!$C6 -> 0 | K7: =$E7*$J7 -> 0 | L7: =H7+J7 -> 0 | M7: =I7+K7 -> 0
A8: WEDING POINT | B8: 20A | C8: POINT | E8: 475000 | F8: =L8 -> 0 | G8: =M8 -> 0 | J8: =$D8*'DIA-INCH'!$C7 -> 0 | K8: =$E8*$J8 -> 0 | L8: =H8+J8 -> 0 | M8: =I8+K8 -> 0
A9: WEDING POINT | B9: 25A | C9: POINT | D9: 173 | E9: 475000 | F9: =L9 -> 173 | G9: =M9 -> 82175000 | J9: =$D9*'DIA-INCH'!$C8 -> 173 | K9: =$E9*$J9 -> 82175000 | L9: =H9+J9 -> 173 | M9: =I9+K9 -> 82175000
A10: WEDING POINT | B10: 32A | C10: POINT | E10: 475000 | F10: =L10 -> 0 | G10: =M10 -> 0 | J10: =$D10*'DIA-INCH'!$C9 -> 0 | K10: =$E10*$J10 -> 0 | L10: =H10+J10 -> 0 | M10: =I10+K10 -> 0
A11: WEDING POINT | B11: 40A | C11: POINT | D11: 51 | E11: 475000 | F11: =L11 -> 76.5 | G11: =M11 -> 36337500 | J11: =$D11*'DIA-INCH'!$C10 -> 76.5 | K11: =$E11*$J11 -> 36337500 | L11: =H11+J11 -> 76.5 | M11: =I11+K11 -> 36337500
A12: WEDING POINT | B12: 50A | C12: POINT | D12: 11 | E12: 475000 | F12: =L12 -> 188 | G12: =M12 -> 89300000 | H12: 166 | I12: 78850000 | J12: =$D12*'DIA-INCH'!$C11 -> 22 | K12: =$E12*$J12 -> 10450000 | L12: =H12+J12 -> 188 | M12: =I12+K12 -> 89300000
A13: WEDING POINT | B13: 65A | C13: POINT | D13: 6 | E13: 475000 | F13: =L13 -> 15 | G13: =M13 -> 7125000 | J13: =$D13*'DIA-INCH'!$C12 -> 15 | K13: =$E13*$J13 -> 7125000 | L13: =H13+J13 -> 15 | M13: =I13+K13 -> 7125000
A14: WEDING POINT | B14: 80A | C14: POINT | D14: 38 | E14: 475000 | F14: =L14 -> 114 | G14: =M14 -> 54150000 | J14: =$D14*'DIA-INCH'!$C13 -> 114 | K14: =$E14*$J14 -> 54150000 | L14: =H14+J14 -> 114 | M14: =I14+K14 -> 54150000
A15: WEDING POINT | B15: 100A | C15: POINT | D15: 16 | E15: 475000 | F15: =L15 -> 328 | G15: =M15 -> 155800000 | H15: 264 | I15: 125400000 | J15: =$D15*'DIA-INCH'!$C14 -> 64 | K15: =$E15*$J15 -> 30400000 | L15: =H15+J15 -> 328 | M15: =I15+K15 -> 155800000
A16: WEDING POINT | B16: 110A | C16: POINT | E16: 475000 | F16: =L16 -> 0 | G16: =M16 -> 0 | J16: =$D16*'DIA-INCH'!$C15 -> 0 | K16: =$E16*$J16 -> 0 | L16: =H16+J16 -> 0 | M16: =I16+K16 -> 0
A17: WEDING POINT | B17: 125A | C17: POINT | D17: 67 | E17: 475000 | F17: =L17 -> 335 | G17: =M17 -> 159125000 | J17: =$D17*'DIA-INCH'!$C16 -> 335 | K17: =$E17*$J17 -> 159125000 | L17: =H17+J17 -> 335 | M17: =I17+K17 -> 159125000
A18: WEDING POINT | B18: 150A | C18: POINT | E18: 475000 | F18: =L18 -> 0 | G18: =M18 -> 0 | J18: =$D18*'DIA-INCH'!$C17 -> 0 | K18: =$E18*$J18 -> 0 | L18: =H18+J18 -> 0 | M18: =I18+K18 -> 0
A19: WEDING POINT | B19: 175A | C19: POINT | E19: 475000 | F19: =L19 -> 0 | G19: =M19 -> 0 | J19: =$D19*'DIA-INCH'!$C18 -> 0 | K19: =$E19*$J19 -> 0 | L19: =H19+J19 -> 0 | M19: =I19+K19 -> 0
A20: WEDING POINT | B20: 200A | C20: POINT | D20: 31 | E20: 475000 | F20: =L20 -> 368 | G20: =M20 -> 174800000 | H20: 120 | I20: 57000000 | J20: =$D20*'DIA-INCH'!$C19 -> 248 | K20: =$E20*$J20 -> 117800000 | L20: =H20+J20 -> 368 | M20: =I20+K20 -> 174800000
A21: WEDING POINT | B21: 225A | C21: POINT | E21: 475000 | F21: =L21 -> 0 | G21: =M21 -> 0 | J21: =$D21*'DIA-INCH'!$C20 -> 0 | K21: =$E21*$J21 -> 0 | L21: =H21+J21 -> 0 | M21: =I21+K21 -> 0
A22: WEDING POINT | B22: 250A | C22: POINT | E22: 475000 | F22: =L22 -> 0 | G22: =M22 -> 0 | J22: =$D22*'DIA-INCH'!$C21 -> 0 | K22: =$E22*$J22 -> 0 | L22: =H22+J22 -> 0 | M22: =I22+K22 -> 0
A23: WEDING POINT | B23: 300A | C23: POINT | E23: 475000 | F23: =L23 -> 0 | G23: =M23 -> 0 | J23: =$D23*'DIA-INCH'!$C22 -> 0 | K23: =$E23*$J23 -> 0 | L23: =H23+J23 -> 0 | M23: =I23+K23 -> 0
A24: WEDING POINT | B24: 350A | C24: POINT | E24: 475000 | F24: =L24 -> 0 | G24: =M24 -> 0 | J24: =$D24*'DIA-INCH'!$C23 -> 0 | K24: =$E24*$J24 -> 0 | L24: =H24+J24 -> 0 | M24: =I24+K24 -> 0
A25: WEDING POINT | B25: 400A | C25: POINT | E25: 475000 | F25: =L25 -> 0 | G25: =M25 -> 0 | J25: =$D25*'DIA-INCH'!$C24 -> 0 | K25: =$E25*$J25 -> 0 | L25: =H25+J25 -> 0 | M25: =I25+K25 -> 0
A26: WEDING POINT | B26: 450A | C26: POINT | E26: 475000 | F26: =L26 -> 0 | G26: =M26 -> 0 | J26: =$D26*'DIA-INCH'!$C25 -> 0 | K26: =$E26*$J26 -> 0 | L26: =H26+J26 -> 0 | M26: =I26+K26 -> 0
A27: WEDING POINT | B27: 500A | C27: POINT | E27: 475000 | F27: =L27 -> 0 | G27: =M27 -> 0 | J27: =$D27*'DIA-INCH'!$C26 -> 0 | K27: =$E27*$J27 -> 0 | L27: =H27+J27 -> 0 | M27: =I27+K27 -> 0
A28: WEDING POINT | B28: 550A | C28: POINT | E28: 475000 | F28: =L28 -> 0 | G28: =M28 -> 0 | J28: =$D28*'DIA-INCH'!$C27 -> 0 | K28: =$E28*$J28 -> 0 | L28: =H28+J28 -> 0 | M28: =I28+K28 -> 0
A29: VALVE 설치비 | B29: 8A | C29: EA | E29: =$E$32*'DIA-INCH'!$C5 -> 12500 | F29: =L29 -> 0 | G29: =M29 -> 0 | J29: =D29 -> 0 | K29: =$J29*$E29 -> 0 | L29: =H29+J29 -> 0 | M29: =I29+K29 -> 0
A30: VALVE 설치비 | B30: 15A | C30: EA | E30: =$E$32*'DIA-INCH'!$C6 -> 25000 | F30: =L30 -> 0 | G30: =M30 -> 0 | J30: =D30 -> 0 | K30: =$J30*$E30 -> 0 | L30: =H30+J30 -> 0 | M30: =I30+K30 -> 0
A31: VALVE 설치비 | B31: 20A | C31: EA | E31: =$E$32*'DIA-INCH'!$C7 -> 37500 | F31: =L31 -> 0 | G31: =M31 -> 0 | J31: =D31 -> 0 | K31: =$J31*$E31 -> 0 | L31: =H31+J31 -> 0 | M31: =I31+K31 -> 0
A32: VALVE 설치비 | B32: 25A | C32: EA | E32: 50000 | F32: =L32 -> 0 | G32: =M32 -> 0 | J32: =D32 -> 0 | K32: =$J32*$E32 -> 0 | L32: =H32+J32 -> 0 | M32: =I32+K32 -> 0
A33: VALVE 설치비 | B33: 32A | C33: EA | E33: =$E$32*'DIA-INCH'!$C9 -> 62500 | F33: =L33 -> 0 | G33: =M33 -> 0 | J33: =D33 -> 0 | K33: =$J33*$E33 -> 0 | L33: =H33+J33 -> 0 | M33: =I33+K33 -> 0
A34: VALVE 설치비 | B34: 40A | C34: EA | E34: =$E$32*'DIA-INCH'!$C10 -> 75000 | F34: =L34 -> 0 | G34: =M34 -> 0 | J34: =D34 -> 0 | K34: =$J34*$E34 -> 0 | L34: =H34+J34 -> 0 | M34: =I34+K34 -> 0
A35: VALVE 설치비 | B35: 50A | C35: EA | E35: =$E$32*'DIA-INCH'!$C11 -> 100000 | F35: =L35 -> 0 | G35: =M35 -> 0 | J35: =D35 -> 0 | K35: =$J35*$E35 -> 0 | L35: =H35+J35 -> 0 | M35: =I35+K35 -> 0
A36: VALVE 설치비 | B36: 65A | C36: EA | E36: =$E$32*'DIA-INCH'!$C12 -> 125000 | F36: =L36 -> 0 | G36: =M36 -> 0 | J36: =D36 -> 0 | K36: =$J36*$E36 -> 0 | L36: =H36+J36 -> 0 | M36: =I36+K36 -> 0
A37: VALVE 설치비 | B37: 80A | C37: EA | E37: =$E$32*'DIA-INCH'!$C13 -> 150000 | F37: =L37 -> 0 | G37: =M37 -> 0 | J37: =D37 -> 0 | K37: =$J37*$E37 -> 0 | L37: =H37+J37 -> 0 | M37: =I37+K37 -> 0
A38: VALVE 설치비 | B38: 100A | C38: EA | E38: =$E$32*'DIA-INCH'!$C14 -> 200000 | F38: =L38 -> 0 | G38: =M38 -> 0 | J38: =D38 -> 0 | K38: =$J38*$E38 -> 0 | L38: =H38+J38 -> 0 | M38: =I38+K38 -> 0
A39: VALVE 설치비 | B39: 110A | C39: EA | E39: =$E$32*'DIA-INCH'!$C15 -> 200000 | F39: =L39 -> 0 | G39: =M39 -> 0 | J39: =D39 -> 0 | K39: =$J39*$E39 -> 0 | L39: =H39+J39 -> 0 | M39: =I39+K39 -> 0
A40: VALVE 설치비 | B40: 125A | C40: EA | E40: =$E$32*'DIA-INCH'!$C16 -> 250000 | F40: =L40 -> 0 | G40: =M40 -> 0 | J40: =D40 -> 0 | K40: =$J40*$E40 -> 0 | L40: =H40+J40 -> 0 | M40: =I40+K40 -> 0
A41: VALVE 설치비 | B41: 150A | C41: EA | E41: =$E$32*'DIA-INCH'!$C17 -> 300000 | F41: =L41 -> 0 | G41: =M41 -> 0 | J41: =D41 -> 0 | K41: =$J41*$E41 -> 0 | L41: =H41+J41 -> 0 | M41: =I41+K41 -> 0
...

Sheet 근로내역 (05월)
A1: 2026년 ( 05 )월 일용 노무비명세서 | AH1: 현장명 | AM1: ='용역청구서 표지'!$B$7 -> P4 Ph2 GAS&PCW 1공구
AH2: 현장소장 | AM2: 조 수 원
AH3: 잡코드 | AM3: ='용역청구서 표지'!$C$8 -> S26-001
A5: 번호 | B5: 성명 | C5: 주민등록번호 | D5: 직종 | E5: 연락처(H.P) | F5: 은행명 | G5: 예금주 | H5: 계좌번호 | I5: 1 | J5: 2 | K5: 3 | L5: 4 | M5: 5 | N5: 6 | O5: 7 | P5: 8 | Q5: 9 | R5: 10 | S5: 11 | T5: 12 | U5: 13 | V5: 14 | W5: 15 | X5: 16 | Y5: 17 | Z5: 18 | AA5: 19 | AB5: 20 | AC5: 21 | AD5: 22 | AE5: 23 | AF5: 24 | AG5: 25 | AH5: 26 | AI5: 27 | AJ5: 28 | AK5: 29 | AL5: 30 | AM5: 31 | AN5: 공수 | AO5: 단가 | AP5: 총액
A6: 1 | B6: 강채연 | C6: 980703-2192257 | D6: 보통인부 | E6: 010-5725-9067 | F6: 국민 | G6: 강채연 | H6: 399102-04-168176 | J6: 1 | L6: 1 | M6: 1.5 | N6: 1 | O6: 1.25 | P6: 1 | Q6: 1 | S6: 1 | T6: 1.5 | U6: 1 | V6: 1.5 | W6: 1 | X6: 1 | Z6: 1 | AA6: 1.5 | AB6: 1 | AC6: 1.5 | AD6: 1 | AE6: 0.75 | AG6: 1.5 | AH6: 1.5 | AI6: 1 | AJ6: 0.5 | AK6: 1 | AN6: =SUM(I6:AM6) -> 27 | AO6: 150000 | AP6: =AN6*AO6 -> 4050000
A7: 2 | B7: 강희수 | C7: 730210-1029411 | D7: 도비공 | E7: 010-9561-6101 | F7: 신한 | G7: 강희수 | H7: 110-490-486591 | L7: 0.5 | M7: 1.5 | N7: 0.5 | O7: 1.5 | P7: 1 | Q7: 1 | S7: 1 | T7: 1.5 | U7: 1 | V7: 1.5 | W7: 0.5 | X7: 1 | Z7: 1 | AA7: 1.5 | AB7: 1 | AC7: 1.5 | AD7: 1 | AG7: 1.5 | AH7: 1.5 | AI7: 1 | AJ7: 1.5 | AK7: 1 | AN7: =SUM(I7:AM7) -> 25 | AO7: 210000 | AP7: =AN7*AO7 -> 5250000
A8: 3 | B8: 구문정 | C8: 681118-2567718 | D8: 보통인부 | E8: 010-8180-1166 | F8: 농협 | G8: 구문정 | H8: 302-0278-3068-51 | L8: 0.6875 | M8: 1.125 | O8: 0.75 | P8: 1 | S8: 1 | T8: 1.5 | U8: 1 | V8: 1.5 | W8: 1 | X8: 1 | Z8: 1 | AA8: 1.5 | AB8: 1 | AC8: 1.5 | AD8: 1 | AE8: 0.75 | AG8: 1.5 | AH8: 1.5 | AI8: 1 | AJ8: 1.5 | AK8: 1 | AN8: =SUM(I8:AM8) -> 23.8125 | AO8: 150000 | AP8: =AN8*AO8 -> 3571875
A9: 4 | B9: 구윤하 | C9: 680130-2162814 | D9: 보통인부 | E9: 010-3259-2177 | F9: 하나 | G9: 구윤하 | H9: 206-910258-60907 | J9: 1 | L9: 1 | M9: 1.5 | N9: 1 | O9: 1.5 | P9: 1 | S9: 1 | T9: 1.5 | U9: 0.5 | V9: 1.5 | W9: 1 | X9: 1 | Z9: 1 | AA9: 1.5 | AB9: 1 | AC9: 1.5 | AD9: 1 | AE9: 0.75 | AG9: 1.5 | AH9: 1.5 | AI9: 1 | AJ9: 1.5 | AN9: =SUM(I9:AM9) -> 25.75 | AO9: 150000 | AP9: =AN9*AO9 -> 3862500
A10: 5 | B10: 권중섭 | C10: 830806-1697210 | D10: 배관공 | E10: 010-9742-9790 | F10: 신한 | G10: 권중섭 | H10: 110-430-392742 | L10: 1 | M10: 1.5 | N10: 1 | O10: 1.5 | P10: 1 | S10: 1 | T10: 1.5 | U10: 1 | V10: 1.5 | W10: 1 | X10: 1 | Z10: 1 | AA10: 1.5 | AB10: 0.875 | AC10: 1.5 | AD10: 1 | AE10: 0.75 | AG10: 1.5 | AH10: 1.5 | AI10: 1 | AJ10: 1.5 | AK10: 1 | AN10: =SUM(I10:AM10) -> 26.125 | AO10: 230000 | AP10: =AN10*AO10 -> 6008750
A11: 6 | B11: 김금성 | C11: 870118-1162639 | D11: 보통인부 | E11: 010-5125-5154 | F11: 농협 | G11: 김금성 | H11: 351-1130-0614-23 | M11: 1.5 | N11: 1 | O11: 1.5 | P11: 1 | Q11: 0.25 | S11: 1 | T11: 1.5 | U11: 1 | V11: 1.5 | W11: 1 | Z11: 0.5 | AB11: 1 | AC11: 1.5 | AD11: 1 | AG11: 1.5 | AN11: =SUM(I11:AM11) -> 16.75 | AO11: 160000 | AP11: =AN11*AO11 -> 2680000
A12: 7 | B12: 김동욱 | C12: 810302-1830628 | D12: 배관공 | E12: 010-5022-0444 | F12: 농협 | G12: 김동욱 | H12: 302-5022-0444-11 | L12: 1 | M12: 1.5 | N12: 1 | O12: 1.5 | P12: 1 | Q12: 1 | S12: 1 | T12: 1.5 | U12: 1 | V12: 1.5 | W12: 1 | X12: 1 | Z12: 1 | AA12: 1.5 | AB12: 1 | AC12: 1.5 | AD12: 1 | AG12: 1.5 | AH12: 1.5 | AI12: 1 | AJ12: 1.5 | AK12: 1 | AN12: =SUM(I12:AM12) -> 26.5 | AO12: 210000 | AP12: =AN12*AO12 -> 5565000
A13: 8 | B13: 김마태 | C13: 830224-1912010 | D13: 배관공 | E13: 010-2725-6089 | F13: 기업 | G13: 김마태 | H13: 175-073189-01-013 | J13: 1 | L13: 1 | M13: 1.5 | N13: 1 | O13: 1.5 | P13: 1 | Q13: 1 | S13: 1 | T13: 1.5 | V13: 1.5 | W13: 1 | X13: 1 | Z13: 1 | AA13: 1.5 | AB13: 1 | AC13: 1.5 | AD13: 1 | AG13: 1.5 | AH13: 1.5 | AI13: 1 | AJ13: 1.5 | AK13: 1 | AN13: =SUM(I13:AM13) -> 26.5 | AO13: 250000 | AP13: =AN13*AO13 -> 6625000
A14: 9 | B14: 김민지 | C14: 850908-2661019 | D14: 보통인부 | E14: 010-3173-2826 | F14: 국민 | G14: 김민지 | H14: 240801-04-433155 | L14: 0.6875 | M14: 1.125 | O14: 0.75 | P14: 1 | S14: 1 | T14: 1.5 | U14: 1 | V14: 1.5 | W14: 1 | Z14: 1 | AA14: 1.5 | AB14: 1 | AC14: 1.5 | AD14: 1 | AE14: 0.75 | AG14: 1.5 | AH14: 1.5 | AI14: 1 | AJ14: 1.5 | AK14: 1 | AN14: =SUM(I14:AM14) -> 22.8125 | AO14: 150000 | AP14: =AN14*AO14 -> 3421875
A15: 10 | B15: 김의찬 | C15: 810916-1090421 | D15: 보통인부 | E15: 010-7748-9382 | F15: 국민 | G15: 김의찬 | H15: 121802-04-157456 | L15: 1 | M15: 1.5 | N15: 1 | O15: 1.5 | P15: 1 | Q15: 1 | S15: 1 | T15: 1.5 | U15: 1 | V15: 1.5 | W15: 1 | X15: 1 | Z15: 1 | AA15: 1.5 | AB15: 1 | AC15: 1.5 | AD15: 1 | AE15: 0.75 | AG15: 1.5 | AH15: 1.5 | AI15: 1 | AJ15: 1.5 | AK15: 1 | AN15: =SUM(I15:AM15) -> 27.25 | AO15: 170000 | AP15: =AN15*AO15 -> 4632500
A16: 11 | B16: 김재윤 | C16: 861216-1157613 | D16: 용접공 | E16: 010-3955-1110 | F16: 신한 | G16: 김재윤 | H16: 110-305-768530 | L16: 0.6875 | M16: 1.125 | N16: 0.5 | O16: 0.5 | P16: 1 | S16: 1 | T16: 1.5 | U16: 1 | V16: 1.5 | W16: 1 | X16: 1 | Z16: 1 | AA16: 1.5 | AB16: 1 | AC16: 1.5 | AD16: 1 | AE16: 0.75 | AG16: 1.5 | AH16: 1.5 | AI16: 1 | AJ16: 1.5 | AK16: 1 | AN16: =SUM(I16:AM16) -> 24.0625 | AO16: 240000 | AP16: =AN16*AO16 -> 5775000
A17: 12 | B17: 김정규 | C17: 821122-1047416 | D17: 보통인부 | E17: 010-3240-6194 | F17: 국민 | G17: 김정규 | H17: 757101-04-044154 | J17: 1 | L17: 1 | M17: 1.5 | N17: 1 | O17: 1.5 | P17: 1 | S17: 1 | U17: 1 | V17: 1.5 | W17: 1 | X17: 1 | Z17: 1 | AA17: 1.5 | AB17: 1 | AC17: 1.5 | AD17: 1 | AE17: 0.5 | AG17: 1.5 | AH17: 1.5 | AI17: 1 | AJ17: 1.5 | AK17: 1 | AN17: =SUM(I17:AM17) -> 25.5 | AO17: 160000 | AP17: =AN17*AO17 -> 4080000
A18: 13 | B18: 김정인 | C18: 911224-1235320 | D18: 용접공 | E18: 010-3175-7994 | F18: 기업 | G18: 김정인 | H18: 010-3175-7994 | L18: 1 | M18: 1.5 | N18: 1 | O18: 1.5 | P18: 1 | Q18: 1 | S18: 1 | T18: 1.5 | U18: 1 | V18: 1.5 | W18: 1 | Z18: 1 | AA18: 1.5 | AB18: 1 | AC18: 1.5 | AD18: 1 | AE18: 0.75 | AG18: 1.5 | AH18: 1.5 | AI18: 1 | AJ18: 1.5 | AK18: 0.875 | AN18: =SUM(I18:AM18) -> 26.125 | AO18: 250000 | AP18: =AN18*AO18 -> 6531250
A19: 14 | B19: 김지민 | C19: 930707-1150011 | D19: 배관공 | E19: 010-8000-2457 | F19: 카카오뱅크 | G19: 김지민 | H19: 3333-13-9046173 | J19: 1 | L19: 1 | M19: 1.5 | N19: 1 | O19: 1.5 | P19: 1 | Q19: 1 | S19: 1 | T19: 1.5 | U19: 1 | V19: 1.5 | W19: 1 | Z19: 0.875 | AA19: 1.5 | AB19: 1 | AC19: 1.5 | AD19: 1 | AE19: 0.75 | AG19: 1.5 | AH19: 1.5 | AI19: 1 | AJ19: 1.5 | AK19: 1 | AN19: =SUM(I19:AM19) -> 27.125 | AO19: 220000 | AP19: =AN19*AO19 -> 5967500
A20: 15 | B20: 김진 | C20: 840728-1235014 | D20: 공사보조 | E20: 010-6246-4588 | F20: 기업 | G20: 김진 | H20: 458-013758-02-012 | L20: 1 | M20: 1.5 | N20: 1 | O20: 1.5 | P20: 1 | Q20: 1 | S20: 1 | T20: 1.5 | U20: 1 | V20: 1.5 | W20: 1 | X20: 0.5 | Z20: 1 | AA20: 1.5 | AB20: 1 | AC20: 1.5 | AD20: 1 | AE20: 0.75 | AG20: 1.5 | AH20: 1.5 | AI20: 1 | AJ20: 1.5 | AK20: 1 | AL20: 0.375 | AN20: =SUM(I20:AM20) -> 27.125 | AO20: 240000 | AP20: =AN20*AO20 -> 6510000
A21: 16 | B21: 김치헌 | C21: 790914-1567115 | D21: 배관공 | E21: 010-4191-6886 | F21: 국민 | G21: 김치헌 | H21: 257602-04-003063 | J21: 1 | L21: 1 | M21: 1.5 | N21: 1 | O21: 1.5 | P21: 1 | S21: 1 | T21: 1.5 | U21: 1 | V21: 1.5 | W21: 1 | X21: 1 | Z21: 1 | AA21: 1.5 | AB21: 1 | AC21: 1.5 | AD21: 1 | AE21: 0.75 | AG21: 1.5 | AH21: 1.5 | AI21: 1 | AJ21: 1.5 | AK21: 1 | AN21: =SUM(I21:AM21) -> 27.25 | AO21: 250000 | AP21: =AN21*AO21 -> 6812500
A22: 17 | B22: 김택수 | C22: 751221-1663222 | D22: 보통인부 | E22: 010-7942-1751 | F22: 우리 | G22: 김택수 | H22: 1002-339-327014 | L22: 1 | M22: 1.5 | N22: 1 | O22: 1.5 | P22: 1 | Q22: 1 | S22: 1 | T22: 1.5 | U22: 1 | V22: 1.5 | W22: 1 | X22: 1 | Z22: 1 | AA22: 1.5 | AB22: 1 | AC22: 1.5 | AD22: 1 | AE22: 0.75 | AG22: 1.5 | AH22: 1.5 | AI22: 1 | AJ22: 1.5 | AK22: 1 | AN22: =SUM(I22:AM22) -> 27.25 | AO22: 160000 | AP22: =AN22*AO22 -> 4360000
A23: 18 | B23: 김형태 | C23: 700430-1069427 | D23: 도비공 | E23: 010-3186-7175 | F23: 농협 | G23: 김형태 | H23: 352-1156-5484-53 | J23: 1 | L23: 1 | M23: 1.5 | N23: 1 | O23: 1.5 | P23: 1 | Q23: 1 | S23: 1 | T23: 1.5 | U23: 1 | V23: 1.5 | W23: 1 | X23: 1 | Z23: 1 | AA23: 1.5 | AB23: 1 | AC23: 1.5 | AD23: 1 | AE23: 0.75 | AG23: 1.5 | AH23: 1.5 | AI23: 1 | AJ23: 1.5 | AK23: 1 | AN23: =SUM(I23:AM23) -> 28.25 | AO23: 180000 | AP23: =AN23*AO23 -> 5085000
A24: 19 | B24: 김희강 | C24: 010617-3234118 | D24: 보통인부 | E24: 010-7728-5274 | F24: 우리 | G24: 김희강 | H24: 1002-564-210008 | L24: 1 | M24: 1.5 | N24: 1 | O24: 1.5 | P24: 1 | Q24: 1 | S24: 1 | T24: 1.5 | U24: 1 | V24: 1.5 | W24: 1 | X24: 1 | Z24: 1 | AA24: 1.5 | AB24: 1 | AC24: 1.5 | AD24: 1 | AE24: 0.75 | AG24: 1.5 | AH24: 1.5 | AI24: 1 | AJ24: 1.5 | AK24: 1 | AN24: =SUM(I24:AM24) -> 27.25 | AO24: 160000 | AP24: =AN24*AO24 -> 4360000
A25: 20 | B25: 남현빈 | C25: 990907-1842410 | D25: 배관공 | E25: 010-7131-4342 | F25: 카카오뱅크 | G25: 남현빈 | H25: 3333-13-8378173 | J25: 1 | L25: 1 | M25: 1.5 | N25: 1 | O25: 0.5 | P25: 1 | Q25: 1 | S25: 1 | T25: 1.5 | U25: 1 | V25: 1.5 | W25: 1 | Z25: 1 | AA25: 1.5 | AB25: 1 | AC25: 1.5 | AD25: 1 | AE25: 0.75 | AG25: 1.5 | AH25: 1.5 | AI25: 1 | AJ25: 1.5 | AK25: 1 | AN25: =SUM(I25:AM25) -> 26.25 | AO25: 190000 | AP25: =AN25*AO25 -> 4987500
A26: 21 | B26: 박도현 | C26: 810129-1102111 | D26: 보통인부 | E26: 010-8927-0083 | F26: 국민 | G26: 박도현 | H26: 960102-01-425739 | L26: 0.6875 | M26: 1.125 | O26: 0.5 | P26: 1 | S26: 1 | T26: 1.5 | U26: 1 | V26: 1.5 | W26: 1 | X26: 1 | Z26: 1 | AA26: 1.5 | AB26: 1 | AC26: 1.5 | AD26: 1 | AE26: 0.75 | AG26: 1.5 | AH26: 1.5 | AI26: 1 | AJ26: 0.25 | AK26: 1 | AN26: =SUM(I26:AM26) -> 22.3125 | AO26: 160000 | AP26: =AN26*AO26 -> 3570000
A27: 22 | B27: 박지원 | C27: 960502-1784039 | D27: 배관공 | E27: 010-2498-2025 | F27: 국민 | G27: 박지원 | H27: 737302-01-193557 | L27: 1 | M27: 1.5 | N27: 1 | O27: 1.5 | P27: 1 | Q27: 1 | S27: 1 | T27: 1.5 | U27: 1 | V27: 1.5 | W27: 1 | X27: 1 | Z27: 1 | AA27: 1.5 | AB27: 1 | AC27: 1.5 | AD27: 1 | AE27: 0.75 | AG27: 1.5 | AH27: 1.5 | AI27: 1 | AJ27: 1.5 | AK27: 1 | AN27: =SUM(I27:AM27) -> 27.25 | AO27: 230000 | AP27: =AN27*AO27 -> 6267500
A28: 23 | B28: 박혁 | C28: 741010-1241714 | D28: 배관공 | E28: 010 4943-6825 | F28: 국민 | G28: 박혁 | H28: 502901-01-043350 | L28: 1 | M28: 1.5 | N28: 1 | O28: 1.5 | P28: 1 | S28: 1 | T28: 1.5 | U28: 1 | V28: 0.5 | AN28: =SUM(I28:AM28) -> 10 | AO28: 230000 | AP28: =AN28*AO28 -> 2300000
A29: 24 | B29: 배찬영 | C29: 771214 -1906312 | D29: 보통인부 | E29: 010-8896-7746 | F29: 농협 | G29: 배찬영 | H29: 352-1366-3636-53 | L29: 1 | M29: 1.5 | N29: 1 | O29: 1.5 | P29: 1 | Q29: 0.375 | S29: 1 | T29: 1.5 | U29: 1 | V29: 1.5 | Z29: 1 | AA29: 1.5 | AB29: 1 | AC29: 1.5 | AD29: 1 | AE29: 0.5 | AG29: 1.5 | AH29: 1.5 | AI29: 1 | AJ29: 1.5 | AK29: 1 | AN29: =SUM(I29:AM29) -> 24.375 | AO29: 160000 | AP29: =AN29*AO29 -> 3900000
A30: 25 | B30: 석임수 | C30: 911020-1685317 | D30: 안전보조 | E30: 010-4183-1119 | F30: 하나 | G30: 석임수 | H30: 238-910260-47407 | J30: 1 | L30: 1 | M30: 1.5 | N30: 1 | O30: 1.5 | P30: 1 | S30: 1 | T30: 1.5 | U30: 1 | V30: 1.5 | W30: 1 | X30: 1 | Z30: 1 | AA30: 1.5 | AB30: 1 | AC30: 1.5 | AD30: 1 | AE30: 0.8125 | AG30: 1.5 | AH30: 1.5 | AI30: 1 | AJ30: 1.5 | AK30: 1 | AL30: 0.375 | AN30: =SUM(I30:AM30) -> 27.6875 | AO30: 190000 | AP30: =AN30*AO30 -> 5260625
A31: 26 | B31: 성지현 | C31: 861110-1351114 | D31: 보통인부 | E31: 010-9197-9732 | F31: 카카오뱅크 | G31: 성지현 | H31: 3333-01-9967097 | J31: 1 | L31: 1 | M31: 1.5 | N31: 1 | O31: 1.375 | P31: 1 | S31: 1 | T31: 1.5 | U31: 1 | V31: 1.5 | W31: 1 | X31: 1 | Z31: 1 | AA31: 1.5 | AB31: 1 | AC31: 1.5 | AD31: 1 | AE31: 0.75 | AG31: 1.5 | AH31: 1.5 | AI31: 1 | AJ31: 1.5 | AK31: 1 | AN31: =SUM(I31:AM31) -> 27.125 | AO31: 230000 | AP31: =AN31*AO31 -> 6238750
A32: 27 | B32: 신경진 | C32: 880103-1105818 | D32: 용접공 | E32: 010-6540-2229 | F32: 기업 | G32: 신경진 | H32: 010-6540-2229 | J32: 1 | L32: 1 | M32: 1.5 | N32: 1 | O32: 1.5 | P32: 1 | Q32: 1 | S32: 1 | T32: 1.5 | U32: 1 | V32: 1.5 | W32: 1 | X32: 1 | Z32: 1 | AA32: 1.5 | AB32: 1 | AC32: 1.5 | AD32: 1 | AE32: 0.75 | AG32: 1.5 | AH32: 1.5 | AI32: 1 | AJ32: 1.5 | AK32: 1 | AN32: =SUM(I32:AM32) -> 28.25 | AO32: 240000 | AP32: =AN32*AO32 -> 6780000
A33: 28 | B33: 신민철 | C33: 830814-1183120 | D33: 공사보조 | E33: 010-7706-5000 | F33: 기업 | G33: 신민철 | H33: 289-082628-01-018 | J33: 1 | L33: 1 | M33: 1.5 | N33: 0.625 | O33: 0.75 | P33: 1 | Q33: 1 | S33: 1 | T33: 1.5 | U33: 1 | V33: 1.5 | W33: 1 | Z33: 1 | AA33: 1.5 | AB33: 1 | AC33: 1.5 | AD33: 1 | AE33: 0.8125 | AG33: 1.5 | AH33: 1.5 | AI33: 1 | AJ33: 1.5 | AK33: 1 | AL33: 0.375 | AN33: =SUM(I33:AM33) -> 26.5625 | AO33: 220000 | AP33: =AN33*AO33 -> 5843750
A34: 29 | B34: 신주현 | C34: 810227-1063429 | D34: 배관공 | E34: 010-4763-4454 | F34: 신한 | G34: 신주현 | H34: 110-377-748020 | L34: 0.6875 | M34: 1.125 | N34: 0.5 | O34: 0.625 | P34: 1 | S34: 1 | T34: 1.5 | U34: 1 | V34: 1.5 | W34: 1 | X34: 1 | Z34: 1 | AA34: 1.5 | AB34: 1 | AC34: 1.5 | AD34: 1 | AE34: 0.75 | AG34: 1.5 | AH34: 1.5 | AI34: 1 | AJ34: 1.5 | AK34: 1 | AN34: =SUM(I34:AM34) -> 24.1875 | AO34: 190000 | AP34: =AN34*AO34 -> 4595625
A35: 30 | B35: 심완 | C35: 870602-1417011 | D35: 용접공 | E35: 010-5101-6010 | F35: 기업 | G35: 심완 | H35: 507-027831-01-010 | J35: 1 | L35: 0.875 | M35: 1.5 | N35: 1 | O35: 1.5 | P35: 1 | Q35: 1 | S35: 1 | T35: 1.5 | U35: 1 | V35: 1.5 | W35: 1 | X35: 1 | Z35: 1 | AA35: 1.5 | AB35: 1 | AC35: 1.5 | AD35: 1 | AE35: 0.75 | AG35: 1.5 | AH35: 1.5 | AI35: 1 | AJ35: 1.5 | AK35: 1 | AN35: =SUM(I35:AM35) -> 28.125 | AO35: 240000 | AP35: =AN35*AO35 -> 6750000
A36: 31 | B36: 안수현 | C36: 970206-2728016 | D36: 용접공 | E36: 010-5045-9210 | F36: 하나 | G36: 안수현 | H36: 292-910293-88807 | J36: 1 | L36: 1 | M36: 1.5 | N36: 1 | O36: 1.5 | P36: 1 | Q36: 1 | S36: 1 | T36: 1.5 | U36: 1 | V36: 1.5 | W36: 1 | Z36: 1 | AA36: 1.5 | AB36: 1 | AC36: 1.5 | AD36: 1 | AG36: 1.5 | AJ36: 1 | AN36: =SUM(I36:AM36) -> 22.5 | AO36: 240000 | AP36: =AN36*AO36 -> 5400000
A37: 32 | B37: 양정운 | C37: 821019-1449616 | D37: 공사보조 | E37: 010-3641-8181 | F37: 농협 | G37: 양정운 | H37: 302-1350-3060-51 | J37: 1 | L37: 1 | M37: 1.5 | N37: 1 | O37: 1.5 | P37: 1 | Q37: 1 | S37: 1 | T37: 1.5 | U37: 0.5 | V37: 1.5 | W37: 1 | X37: 1 | Z37: 1 | AA37: 1.5 | AB37: 1 | AC37: 1.5 | AD37: 1 | AE37: 0.8125 | AG37: 1.5 | AH37: 1.5 | AI37: 1 | AJ37: 1 | AK37: 1 | AL37: 0.375 | AN37: =SUM(I37:AM37) -> 27.6875 | AO37: 250000 | AP37: =AN37*AO37 -> 6921875
A38: 33 | B38: 양정인 | C38: 810207-1455012 | D38: 보통인부 | E38: 010-8824-6401 | F38: 국민 | G38: 양정인 | H38: 472301-04-019277 | J38: 1 | L38: 1 | M38: 1.5 | N38: 1 | O38: 1.5 | P38: 1 | Q38: 1 | S38: 1 | T38: 1.5 | U38: 1 | V38: 1.5 | W38: 1 | X38: 1 | Z38: 1 | AA38: 1.5 | AB38: 1 | AC38: 1.5 | AD38: 1 | AE38: 0.75 | AG38: 1.5 | AH38: 1.5 | AI38: 1 | AJ38: 1.5 | AK38: 1 | AN38: =SUM(I38:AM38) -> 28.25 | AO38: 170000 | AP38: =AN38*AO38 -> 4802500
A39: 34 | B39: 연승렬 | C39: 700216-1011916 | D39: 보통인부 | E39: 010-8098-3356 | F39: 기업 | G39: 연승렬 | H39: 186-086062-01-011 | J39: 0.5 | L39: 1 | M39: 1.5 | O39: 1.5 | P39: 1 | Q39: 1 | S39: 1 | T39: 1.5 | U39: 1 | V39: 1.5 | W39: 1 | X39: 0.5 | Z39: 1 | AA39: 1.5 | AB39: 1 | AC39: 1.5 | AD39: 1 | AE39: 0.75 | AG39: 1.5 | AH39: 1.5 | AI39: 1 | AJ39: 1.5 | AK39: 1 | AN39: =SUM(I39:AM39) -> 26.25 | AO39: 160000 | AP39: =AN39*AO39 -> 4200000
A40: 35 | B40: 오경미 | C40: 800326-2783516 | D40: 보통인부 | E40: 010-2433-1425 | F40: 카카오뱅크 | G40: 오경미 | H40: 3333-08-9261688 | L40: 0.6875 | M40: 1.125 | O40: 0.75 | P40: 1 | S40: 1 | T40: 1.5 | W40: 1 | Z40: 1 | AA40: 1.5 | AB40: 1 | AD40: 1 | AE40: 0.75 | AG40: 1.5 | AH40: 1.5 | AI40: 1 | AJ40: 1.5 | AK40: 1 | AN40: =SUM(I40:AM40) -> 18.8125 | AO40: 150000 | AP40: =AN40*AO40 -> 2821875
A41: 36 | B41: 옥유정 | C41: 850715-2093511 | D41: 보통인부 | E41: 010-2313-8731 | F41: 카카오뱅크 | G41: 옥유정 | H41: 3333-17-6983150 | L41: 1 | M41: 1.5 | N41: 1 | O41: 1.5 | P41: 1 | Q41: 0.5 | S41: 1 | T41: 1.5 | U41: 1 | V41: 1.5 | W41: 1 | Z41: 1 | AA41: 1.5 | AB41: 1 | AC41: 1.5 | AD41: 1 | AG41: 1.5 | AH41: 1.5 | AI41: 1 | AJ41: 1.5 | AK41: 1 | AN41: =SUM(I41:AM41) -> 25 | AO41: 150000 | AP41: =AN41*AO41 -> 3750000
...

Sheet 숙소임차료
A1: 숙소 임차료
A2: No. | B2: 납부일 | C2: 구분 | D2: 품명 | E2: 주소 | F2: 호수 | G2: 수량 | H2: 사용인원 | I2: 임차료 | J2: 비 고
I3: =SUM(I4:I29) -> 42980000 | L3: 입력해야하는 항목 외 수정 금지
A4: 1 | B4: 46173 | C4: KC대납 임대료 | D4: 숙소임대료(05월분) | E4: 평택시 고덕갈평9길 57 302호 | F4: 302호 | G4: 1 | H4: 4 | I4: 1200000 | J4: KC 대납 | L4: 납부일
A5: 2 | B5: 46173 | C5: KC대납 임대료 | D5: 숙소임대료(05월분) | E5: 평택시 고덕갈평10길 40 301호 | F5: 301호 | G5: 1 | H5: 6 | I5: 1600000 | J5: KC 대납 | L5: 구분
A6: 3 | B6: 46173 | C6: KC대납 임대료 | D6: 숙소임대료(05월분) | E6: 평택시 고덕여염11길 14 202호 | F6: 202호 | G6: 1 | H6: 4 | I6: 1300000 | J6: KC 대납 | L6: 품명
A7: 4 | B7: 46173 | C7: KC대납 임대료 | D7: 숙소임대료(05월분) | E7: 평택시 함박산1길 50 401호 | F7: 401호 | G7: 1 | H7: 6 | I7: 1700000 | J7: KC 대납 | L7: 주소
A8: 5 | B8: 46173 | C8: KC대납 임대료 | D8: 숙소임대료(05월분) | E8: 평택시 함박산4길 3 301호 | F8: 301호 | G8: 1 | H8: 6 | I8: 1530000 | J8: KC 대납 | L8: 호수
A9: 6 | B9: 46173 | C9: KC대납 임대료 | D9: 숙소임대료(05월분) | E9: 평택시 함박산3길 37 301호 | F9: 301호 | G9: 1 | H9: 6 | I9: 1600000 | J9: KC 대납 | L9: 수량
A10: 7 | B10: 46173 | C10: KC대납 임대료 | D10: 숙소임대료(05월분) | E10: 평택시 함박산9길 28 401호(복층) | F10: 복층) | G10: 1 | H10: 6 | I10: 2000000 | J10: KC 대납 | L10: 사용인원
A11: 8 | B11: 46173 | C11: KC대납 임대료 | D11: 숙소임대료(05월분) | E11: 평택시 함박산12길 35 301호 | F11: 301호 | G11: 1 | H11: 6 | I11: 1800000 | J11: KC 대납
A12: 9 | B12: 46173 | C12: KC대납 임대료 | D12: 숙소임대료(05월분) | E12: 평택시 함박산1길 34 201호 | F12: 201호 | G12: 1 | H12: 6 | I12: 1700000 | J12: KC 대납 | L12: ■ 구분은 [KC대납 임대료 및 임대료] 이외 항목은 입력금지
A13: 10 | B13: 46173 | C13: KC대납 임대료 | D13: 숙소임대료(05월분) | E13: 평택시 고덕여염11길 149 202호 | F13: 202호 | G13: 1 | H13: 6 | I13: 1900000 | J13: KC 대납
A14: 11 | B14: 46173 | C14: KC대납 임대료 | D14: 숙소임대료(05월분) | E14: 평택시 고덕국제4길 60-16 202호 | F14: 202호 | G14: 1 | H14: 6 | I14: 1600000 | J14: KC 대납
A15: 12 | B15: 46173 | C15: KC대납 임대료 | D15: 숙소임대료(05월분) | E15: 평택시 고덕여염16길 113 202호 | F15: 202호 | G15: 1 | H15: 6 | I15: 1900000 | J15: KC 대납
A16: 13 | B16: 46173 | C16: KC대납 임대료 | D16: 숙소임대료(05월분) | E16: 평택시 고덕여염6길 199 202호 | F16: 202호 | G16: 1 | H16: 6 | I16: 1800000 | J16: KC 대납
A17: 14 | B17: 46173 | C17: KC대납 임대료 | D17: 숙소임대료(05월분) | E17: 평택시 함박산1길 34 301호 | F17: 301호 | G17: 1 | H17: 6 | I17: 1700000 | J17: KC 대납
A18: 15 | B18: 46173 | C18: KC대납 임대료 | D18: 숙소임대료(05월분) | E18: 평택시 함박산9길 26 202호 | F18: 202호 | G18: 1 | H18: 6 | I18: 1600000 | J18: KC 대납
A19: 16 | B19: 46173 | C19: KC대납 임대료 | D19: 숙소임대료(05월분) | E19: 평택시 함박산11길 9-1 202호 | F19: 202호 | G19: 1 | H19: 6 | I19: 1650000 | J19: KC 대납
A20: 17 | B20: 46173 | C20: KC대납 임대료 | D20: 숙소임대료(05월분) | E20: 평택시 함박산3길 11 301호 | F20: 301호 | G20: 1 | H20: 6 | I20: 1900000 | J20: KC 대납
A21: 18 | B21: 46173 | C21: KC대납 임대료 | D21: 숙소임대료(05월분) | E21: 평택시 고덕여염16길 115 202호 | F21: 202호 | G21: 1 | H21: 4 | I21: 1400000 | J21: KC 대납
A22: 19 | B22: 46173 | C22: KC대납 임대료 | D22: 숙소임대료(05월분) | E22: 평택시 함박산9길 26 201호 | F22: 201호 | G22: 1 | H22: 6 | I22: 1800000 | J22: KC 대납
A23: 20 | B23: 46173 | C23: KC대납 임대료 | D23: 숙소임대료(05월분) | E23: 평택시 고덕국제4길 60-10 202호 | F23: 202호 | G23: 1 | H23: 6 | I23: 1650000 | J23: KC 대납
A24: 21 | B24: 46173 | C24: KC대납 임대료 | D24: 숙소임대료(05월분) | E24: 평택시 함박산 2길 11 302호 | F24: 302호 | G24: 1 | H24: 6 | I24: 1500000 | J24: KC 대납
... A29: 26 | B29: 46173 | C29: KC대납 임대료 | D29: 숙소임대료(05월분) | E29: 평택시 함박산4길 28 301호 | F29: 301호 | G29: 1 | H29: 6 | I29: 1600000 | J29: KC 대납

Sheet 숙소관리비
A1: 숙소 관리비
A2: No. | B2: 납부일 | C2: 구분 | D2: 품명 | E2: 주소 | F2: 호수 | G2: 수량 | H2: 사용인원 | I2: 관리비 | J2: 비 고
I3: =SUM(I4:I81) -> 1329770
A4: 1 | B4: 46173 | C4: KC대납 관리비 | D4: 숙소수도세(05월분) | E4: 평택시 고덕갈평9길 57 302호 | F4: 302호 | G4: 1 | H4: 4 | I4: 익월발생예정 | J4: KC 대납
A5: 2 | B5: 46173 | C5: KC대납 관리비 | D5: 숙소가스료(05월분) | E5: 평택시 고덕갈평9길 57 302호 | F5: 302호 | G5: 1 | H5: 4 | I5: 익월발생예정 | J5: KC 대납
A6: 3 | B6: 46173 | C6: KC대납 관리비 | D6: 숙소전기료(05월분) | E6: 평택시 고덕갈평9길 57 302호 | F6: 302호 | G6: 1 | H6: 4 | I6: 익월발생예정 | J6: KC 대납
A7: 4 | B7: 46173 | C7: KC대납 관리비 | D7: 숙소수도세(05월분) | E7: 평택시 고덕갈평10길 40 301호 | F7: 301호 | G7: 1 | H7: 6 | I7: 4500 | J7: KC 대납
A8: 5 | B8: 46173 | C8: KC대납 관리비 | D8: 숙소가스료(05월분) | E8: 평택시 고덕갈평10길 40 301호 | F8: 301호 | G8: 1 | H8: 6 | I8: 61890 | J8: KC 대납
A9: 6 | B9: 46173 | C9: KC대납 관리비 | D9: 숙소전기료(05월분) | E9: 평택시 고덕갈평10길 40 301호 | F9: 301호 | G9: 1 | H9: 6 | I9: 24360 | J9: KC 대납
A10: 7 | B10: 46173 | C10: KC대납 관리비 | D10: 숙소수도세(05월분) | E10: 평택시 고덕여염11길 14 202호 | F10: 202호 | G10: 1 | H10: 6 | I10: 27010 | J10: KC 대납
A11: 8 | B11: 46173 | C11: KC대납 관리비 | D11: 숙소가스료(05월분) | E11: 평택시 고덕여염11길 14 202호 | F11: 202호 | G11: 1 | H11: 6 | I11: 44200 | J11: KC 대납
A12: 9 | B12: 46173 | C12: KC대납 관리비 | D12: 숙소전기료(05월분) | E12: 평택시 고덕여염11길 14 202호 | F12: 202호 | G12: 1 | H12: 6 | I12: 24960 | J12: KC 대납
A13: 10 | B13: 46173 | C13: KC대납 관리비 | D13: 숙소수도세(05월분) | E13: 평택시 함박산1길 50 401호 | F13: 401호 | G13: 1 | H13: 6 | I13: 62360 | J13: KC 대납
A14: 11 | B14: 46173 | C14: KC대납 관리비 | D14: 숙소가스료(05월분) | E14: 평택시 함박산1길 50 401호 | F14: 401호 | G14: 1 | H14: 6 | I14: 62080 | J14: KC 대납
A15: 12 | B15: 46173 | C15: KC대납 관리비 | D15: 숙소전기료(05월분) | E15: 평택시 함박산1길 50 401호 | F15: 401호 | G15: 1 | H15: 6 | I15: 26470 | J15: KC 대납
A16: 13 | B16: 46173 | C16: KC대납 관리비 | D16: 숙소수도세(05월분) | E16: 평택시 함박산4길 3 301호 | F16: 301호 | G16: 1 | H16: 6 | I16: 46140 | J16: KC 대납
A17: 14 | B17: 46173 | C17: KC대납 관리비 | D17: 숙소가스료(05월분) | E17: 평택시 함박산4길 3 301호 | F17: 301호 | G17: 1 | H17: 6 | I17: 73360 | J17: KC 대납
A18: 15 | B18: 46173 | C18: KC대납 관리비 | D18: 숙소전기료(05월분) | E18: 평택시 함박산4길 3 301호 | F18: 301호 | G18: 1 | H18: 6 | I18: 44970 | J18: KC 대납
... A25: 22 | B25: 46173 | C25: KC대납 관리비 | D25: 숙소수도세(05월분) | E25: 평택시 함박산12길 35 301호 | F25: 301호 | G25: 1 | H25: 6 | I25: 22640 | J25: KC 대납
A26: 23 | B26: 46173 | C26: KC대납 관리비 | D26: 숙소가스료(05월분) | E26: 평택시 함박산12길 35 301호 | F26: 301호 | G26: 1 | H26: 6 | I26: 익월발생예정 | J26: KC 대납
A27: 24 | B27: 46173 | C27: KC대납 관리비 | D27: 숙소전기료(05월분) | E27: 평택시 함박산12길 35 301호 | F27: 301호 | G27: 1 | H27: 6 | I27: 27520 | J27: KC 대납
A28: 25 | B28: 46173 | C28: KC대납 관리비 | D28: 숙소수도세(05월분) | E28: 평택시 함박산1길 34 201호 | F28: 201호 | G28: 1 | H28: 6 | I28: 익월발생예정 | J28: KC 대납
A29: 26 | B29: 46173 | C29: KC대납 관리비 | D29: 숙소가스료(05월분) | E29: 평택시 함박산1길 34 201호 | F29: 201호 | G29: 1 | H29: 6 | I29: 익월발생예정 | J29: KC 대납
A30: 27 | B30: 46173 | C30: KC대납 관리비 | D30: 숙소전기료(05월분) | E30: 평택시 함박산1길 34 201호 | F30: 201호 | G30: 1 | H30: 6 | I30: 익월발생예정 | J30: KC 대납
A31: 28 | B31: 46173 | C31: KC대납 관리비 | D31: 숙소수도세(05월분) | E31: 평택시 고덕여염11길 149 202호 | F31: 202호 | G31: 1 | H31: 6 | I31: 0 | J31: KC 대납
A32: 29 | B32: 46173 | C32: KC대납 관리비 | D32: 숙소가스료(05월분) | E32: 평택시 고덕여염11길 149 202호 | F32: 202호 | G32: 1 | H32: 6 | I32: 58800 | J32: KC 대납
A33: 30 | B33: 46173 | C33: KC대납 관리비 | D33: 숙소전기료(05월분) | E33: 평택시 고덕여염11길 149 202호 | F33: 202호 | G33: 1 | H33: 6 | I33: 0 | J33: KC 대납
A34: 31 | B34: 46173 | C34: KC대납 관리비 | D34: 숙소수도세(05월분) | E34: 평택시 고덕국제4길 60-16 202호 | F34: 202호 | G34: 1 | H34: 6 | I34: 11020 | J34: KC 대납
A35: 32 | B35: 46173 | C35: KC대납 관리비 | D35: 숙소가스료(05월분) | E35: 평택시 고덕국제4길 60-16 202호 | F35: 202호 | G35: 1 | H35: 6 | I35: 49290 | J35: KC 대납
A36: 33 | B36: 46173 | C36: KC대납 관리비 | D36: 숙소전기료(05월분) | E36: 평택시 고덕국제4길 60-16 202호 | F36: 202호 | G36: 1 | H36: 6 | I36: 43350 | J36: KC 대납
A37: 34 | B37: 46173 | C37: KC대납 관리비 | D37: 숙소수도세(05월분) | E37: 평택시 고덕여염16길 113 202호 | F37: 202호 | G37: 1 | H37: 6 | I37: 익월발생예정 | J37: KC 대납
A38: 35 | B38: 46173 | C38: KC대납 관리비 | D38: 숙소가스료(05월분) | E38: 평택시 고덕여염16길 113 202호 | F38: 202호 | G38: 1 | H38: 6 | I38: 익월발생예정 | J38: KC 대납
A39: 36 | B39: 46173 | C39: KC대납 관리비 | D39: 숙소전기료(05월분) | E39: 평택시 고덕여염16길 113 202호 | F39: 202호 | G39: 1 | H39: 6 | I39: 익월발생예정 | J39: KC 대납
A40: 37 | B40: 46173 | C40: KC대납 관리비 | D40: 숙소수도세(05월분) | E40: 평택시 고덕여염6길 199 202호 | F40: 202호 | G40: 1 | H40: 6 | I40: 2400 | J40: KC 대납
A41: 38 | B41: 46173 | C41: KC대납 관리비 | D41: 숙소가스료(05월분) | E41: 평택시 고덕여염6길 199 202호 | F41: 202호 | G41: 1 | H41: 6 | I41: 71170 | J41: KC 대납
A42: 39 | B42: 46173 | C42: KC대납 관리비 | D42: 숙소전기료(05월분) | E42: 평택시 고덕여염6길 199 202호 | F42: 202호 | G42: 1 | H42: 6 | I42: 33390 | J42: KC 대납
A43: 40 | B43: 46173 | C43: KC대납 관리비 | D43: 숙소수도세(05월분) | E43: 평택시 함박산1길 34 301호 | F43: 301호 | G43: 1 | H43: 6 | I43: 18480 | J43: KC 대납
A44: 41 | B44: 46173 | C44: KC대납 관리비 | D44: 숙소가스료(05월분) | E44: 평택시 함박산1길 34 301호 | F44: 301호 | G44: 1 | H44: 6 | I44: 32340 | J44: KC 대납
A45: 42 | B45: 46173 | C45: KC대납 관리비 | D45: 숙소전기료(05월분) | E45: 평택시 함박산1길 34 301호 | F45: 301호 | G45: 1 | H45: 6 | I45: 41760 | J45: KC 대납
A46: 43 | B46: 46173 | C46: KC대납 관리비 | D46: 숙소수도세(05월분) | E46: 평택시 함박산9길 26 202호 | F46: 202호 | G46: 1 | H46: 6 | I46: 1200 | J46: KC 대납
...

Sheet 식대비용
A1: 식대 비용
A2: No. | B2: 납부일 | C2: 구분 | D2: 품명 | E2: 거래처명 | F2: 수량 | G2: 식수인원 | H2: 단가 | I2: 합 계 | J2: 비 고
I3: =SUM(I4:I5) -> 30145773 | L3: 입력해야하는 항목 외 수정 금지
A4: 1 | B4: 46173 | C4: KC대납 식대 | D4: 기술인및관리자 (현장 식당) | E4: 포세카 | F4: 2676 | G4: 90 | H4: 6181.82 | I4: 16516773 | J4: KC 대납 | L4: 입력항목
A5: 2 | B5: 46173 | C5: KC대납 식대 | D5: 기술인및관리자 (현장 식당) | E5: 밥심 | F5: 1947 | G5: 79 | H5: 7000 | I5: =F5*H5 -> 13629000 | J5: KC 대납 | L5: 납부일
L6: 구분
L7: 품명
L8: 거래처명
L9: 수량
L10: 식수인원
L11: 단가
L13: ■ 구분은 [KC대납 식대 및 식대] 이외 항목은 입력금지

Sheet 기타비용
A1: 기타 비용
A2: No. | B2: 구매일 | C2: 구분 | D2: 품명 | E2: 거래처명 | F2: 수량 | G2: 단가 | H2: 합계 | I2: 비고
H3: =SUM(H4:H83) -> 5565200 | K3: 입력해야하는 항목 외 수정 금지
A4: 1 | B4: 46148 | C4: 소모품비 | D4: 번호열쇠 [XD-40,4열 [자커]] | E4: 미래공구 | F4: 10 | G4: 3600 | H4: =F4*G4 -> 36000 | I4: 거래명세서 첨부 | K4: 입력항목
A5: 2 | B5: 46148 | C5: 소모품비 | D5: 알곤게이지 [KX-3 [코리아나]] | E5: 미래공구 | F5: 4 | G5: 20000 | H5: =F5*G5 -> 80000 | I5: 거래명세서 첨부 | K5: 납부일
A6: 3 | B6: 46148 | C6: 소모품비 | D6: 장갑클립 [일반형] | E6: 미래공구 | F6: 20 | G6: 1400 | H6: =F6*G6 -> 28000 | I6: 거래명세서 첨부 | K6: 구분
A7: 4 | B7: 46148 | C7: 소모품비 | D7: 티브러쉬 [75*6.스텐 [동양]] | E7: 미래공구 | F7: 10 | G7: 4500 | H7: =F7*G7 -> 45000 | I7: 거래명세서 첨부 | K7: 품명
A8: 5 | B8: 46148 | C8: 소모품비 | D8: 밴드쏘날 [1140*13*0.65-14T [WESPA]] | E8: 미래공구 | F8: 10 | G8: 8500 | H8: =F8*G8 -> 85000 | I8: 거래명세서 첨부 | K8: 거래처명
A9: 6 | B9: 46148 | C9: 소모품비 | D9: 다이아몬드줄 [180mm,평 [삼익]] | E9: 미래공구 | F9: 5 | G9: 7800 | H9: =F9*G9 -> 39000 | I9: 거래명세서 첨부 | K9: 수량
A10: 7 | B10: 46148 | C10: 소모품비 | D10: 다이아몬드줄 [180mm,반원 [삼익]] | E10: 미래공구 | F10: 5 | G10: 7800 | H10: =F10*G10 -> 39000 | I10: 거래명세서 첨부 | K10: 식수인원
A11: 8 | B11: 46148 | C11: 소모품비 | D11: 줄 [10",반원 [삼익]] | E11: 미래공구 | F11: 5 | G11: 18100 | H11: =F11*G11 -> 90500 | I11: 거래명세서 첨부 | K11: 단가
A12: 9 | B12: 46149 | C12: 소모품비 | D12: 추페이퍼 [100mm(2"),KELCO [3M]] | E12: 미래공구 | F12: 20 | G12: 3600 | H12: =F12*G12 -> 72000 | I12: 거래명세서 첨부
A13: 10 | B13: 46149 | C13: 소모품비 | D13: 쇼바 [BY4-365-10kg [부영]] | E13: 미래공구 | F13: 4 | G13: 10000 | H13: =F13*G13 -> 40000 | I13: 거래명세서 첨부 | K13: ■ 구분은 [KC대납 식대 및 식대] 이외 항목은 입력금지
A14: 11 | B14: 46149 | C14: 소모품비 | D14: 쇼바브라켓 [BY4-BK-1,평자 [부영]] | E14: 미래공구 | F14: 4 | G14: 1700 | H14: =F14*G14 -> 6800 | I14: 거래명세서 첨부
A15: 12 | B15: 46149 | C15: 소모품비 | D15: 쇼바브라켓 [BY4-BK-2,ㄱ자 [부영]] | E15: 미래공구 | F15: 4 | G15: 2000 | H15: =F15*G15 -> 8000 | I15: 거래명세서 첨부
A16: 13 | B16: 46149 | C16: 소모품비 | D16: 하이스드릴 [5.0mm [와이지원]] | E16: 미래공구 | F16: 5 | G16: 1900 | H16: =F16*G16 -> 9500 | I16: 거래명세서 첨부
A17: 14 | B17: 46149 | C17: 소모품비 | D17: 물파스 [90ML [현대약품]] | E17: 미래공구 | F17: 5 | G17: 3500 | H17: =F17*G17 -> 17500 | I17: 거래명세서 첨부
A18: 15 | B18: 46149 | C18: 소모품비 | D18: 귀마개 [1100,끈없음,200개 [3M]] | E18: 미래공구 | F18: 1 | G18: 40000 | H18: =F18*G18 -> 40000 | I18: 거래명세서 첨부
A19: 16 | B19: 46149 | C19: 소모품비 | D19: 케이블타이 [300mm(1봉=500개),백색 [HNS]] | E19: 미래공구 | F19: 2 | G19: 11700 | H19: =F19*G19 -> 23400 | I19: 거래명세서 첨부
A20: 17 | B20: 46149 | C20: 소모품비 | D20: 건전지 [AA,2개 [벡셀]] | E20: 미래공구 | F20: 36 | G20: 900 | H20: =F20*G20 -> 32400 | I20: 거래명세서 첨부
A21: 18 | B21: 46149 | C21: 소모품비 | D21: PP로프 [6mm*100m [HNS]] | E21: 미래공구 | F21: 1 | G21: 9600 | H21: =F21*G21 -> 9600 | I21: 거래명세서 첨부
A22: 19 | B22: 46149 | C22: 소모품비 | D22: 번호열쇠 [XD-40,4열 [자커]] | E22: 미래공구 | F22: 10 | G22: 3600 | H22: =F22*G22 -> 36000 | I22: 거래명세서 첨부
A23: 20 | B23: 46153 | C23: 소모품비 | D23: 검교정비,레이저레벨 [코라스성적서 [코텐]] | E23: 미래공구 | F23: 6 | G23: 280000 | H23: =F23*G23 -> 1680000 | I23: 거래명세서 첨부
A24: 21 | B24: 46153 | C24: 소모품비 | D24: 수리비,레이저레벨기 [코텐,RX20,유리교체] | E24: 미래공구 | F24: 1 | G24: 36000 | H24: =F24*G24 -> 36000 | I24: 거래명세서 첨부
A25: 22 | B25: 46153 | C25: 소모품비 | D25: 네임펜 [양면,흑색,12개 [모나미]] | E25: 미래공구 | F25: 2 | G25: 12400 | H25: =F25*G25 -> 24800 | I25: 거래명세서 첨부
... A83: 80 | B83: 46171 | C83: 소모품비 | D83: 알곤스위치 [스위치(뒷선300mm),CTX [크레토스]] | E83: 미래공구 | F83: 6 | G83: 2900 | H83: =F83*G83 -> 17400 | I83: 거래명세서 첨부

Sheet 서명란
B2: 현 장 확 인 | C2: 소 장 | E2: (서명)
C3: 공 사 | E3: (서명)
C4: 공 무 | E4: (서명)
G6: 사 업 부 | H6: Frontier 사업부 GNP 본부장 | I6: BOC 센터장 | J6: Frontier 사업부장
L8: 본 사 | M8: 담 당 | N8: 검 토 | O8: 검 토
Q11: 구 분 | R11: 확 인
Q12: 품 질 | R12: O O O (인)
Q13: 공 무 | R13: O O O (인)

Sheet DIA-INCH
B3: SIZE
B4: A(mm) | C4: Inch
B5: 8A | C5: 0.25
B6: 15A | C6: 0.5
B7: 20A | C7: 0.75
B8: 25A | C8: 1
B9: 32A | C9: 1.25
B10: 40A | C10: 1.5
B11: 50A | C11: 2
B12: 65A | C12: 2.5
B13: 80A | C13: 3
B14: 100A | C14: 4
B15: 110A | C15: 4
B16: 125A | C16: 5
... B27: 550A | C27: 22
