Workbook

Sheet 용역청구서 표지
B4: 제( 1 )회 기 성 청 구 서
B7: P4 Ph2 GAS&PWC 1공구 배관공사 (FAB)
C8: S26-001
C15: 2026년 3월
C20: 대성이엔지

Sheet 용역 청구서(갑지)
A1: 용 역 청 구 서
A3: 1 | B3: 공 사 명 | C3: : | D3: ='용역청구서 표지'!$B$7 -> P4 Ph2 GAS&PWC 1공구 배관공사 (FAB) | E3: ='용역청구서 표지'!$C$8 -> S26-001
A4: 2 | B4: 공 종 | C4: : | D4: 외주용역(M/M부분)
A5: 3 | B5: 계 약 금 액 | C5: : | D5: =ROUNDUP(E5,0) -> 0 | E5: =집계장!I23 -> 0 | F5: (VAT 별도)
A6: 4 | B6: 누 계 기 성 금 액 | C6: : | D6: =ROUNDUP(E6,0) -> 0 | E6: =E7+E13 -> 0 | F6: (VAT 별도)
A7: 5 | B7: 전 회 기 성 금 액 | C7: : | D7: =ROUNDUP(E7,0) -> 0 | E7: =집계장!G23 -> 0 | F7: (VAT 별도)
A8: 6 | B8: 금 회 기 성 금 액 | C8: : | D8: =ROUNDUP(E8,0) -> -139160193 | E8: =집계장!F19 -> -139160193 | F8: (VAT 별도)
A9: 7 | B9: 선 금 액 | C9: : | D9: =ROUNDUP(E9,0) -> 0 | E9: =집계장!K21 -> 0 | F9: (VAT 별도)
A10: 8 | B10: 선 금 전 회 공 제 | C10: : | D10: =ROUNDUP(E10,0) -> 0 | E10: =집계장!G21 -> 0 | F10: (VAT 별도)
A11: 9 | B11: 선 금 금 회 공 제 | C11: : | D11: =ROUNDUP(E11,0) -> 0 | E11: =집계장!F21 -> 0 | F11: (VAT 별도)
A12: 10 | B12: 선 금 잔 여 금 액 | C12: : | D12: =ROUNDUP(E12,0) -> 0 | E12: =집계장!L21 -> 0 | F12: (VAT 별도)
A13: 11 | B13: 금 회 청 구 금 액 | C13: : | D13: =ROUNDUP(E13,0) -> 0 | E13: =집계장!F23 -> 0 | F13: (VAT 별도)
A14: 12 | B14: 잔 여 기 성 금 액 | C14: : | D14: =ROUNDUP(E14,0) -> 0 | E14: =집계장!F18 -> 0 | F14: (VAT 별도)
A15: 13 | B15: 공 정 율 | C15: : | D15: 1
A16: 14 | B16: 청 구 공 사 기 간 | C16: : | D16: 2026. 03. 03 ~ 2026. 03. 31
B18: 위 공사의 하도급에 있어서 공사설계도서, 시방서,품질관리 기준 및 약정대로 시공 되었음을 확인하오며. 만약 귀사의 현장담당의 검사에
B19: 관하여 하자가 발견된 때에는 즉시 실액배상 또는 재 시공할것을 서약하고 이에 기성 청구서를 제출합니다.
B20: 상기건과 관련하여 본 청구 이전까지의 모든 대금은 수령하였음을 확약합니다.
F21: 작 성 일 : 2026 년 03 월 31일
F23: 상 호 : | G23: 대성이엔지
B24: ※첨 부 : 기성내역서 1부. | F24: 주 소 : | G24: 경기도 파주시 파주읍 주라위길 380
F25: 대표이사 : | G25: 정 성 기 | I25: (인)
D26: ㈜케이씨이앤씨 귀하

Sheet 용역 내역서(을지)
A1: 용 역 내 역 서
A2: P4 Ph4 GAS 1공구 마감공사 | G2: 단위 : 원
A3: 품 명 | B3: 규 격 | C3: 단위 | D3: 단 가 | E3: 금 회 청 구
E4: 수 량 | F4: 금 액 | G4: 비 고
A5: 고급기술인 | B5: S+ | C5: M/M | D5: 1400000 | E5: 1 | F5: =D5*E5 -> 1400000
A6: 고급기술인 | B6: S | C6: M/M | D6: 1200000 | F6: =D6*E6 -> 0
A7: 중급기술인 | B7: A+ | C7: M/M | D7: 1000000 | F7: =D7*E7 -> 0
A8: 중급기술인 | B8: A | C8: M/M | D8: 900000 | F8: =D8*E8 -> 0
A9: 중급기술인 | B9: B+ | C9: M/M | D9: 800000 | F9: =D9*E9 -> 0
A10: 중급기술인 | B10: B | C10: M/M | D10: 700000 | F10: =D10*E10 -> 0
A11: 초급 기술인 | B11: C | C11: M/M | D11: 600000 | F11: =D11*E11 -> 0
A13: 인센티브 | E13: 0.01 | F13: =SUM(F5:F11)*E13 -> 14000
A15: 총 계 | E15: =SUM(E5:E11) -> 1 | F15: =SUM(F5:F13) -> 1414000

Sheet 내역서(을지)
A1: 용 역 내 역 서
A2: =집계장!A1 -> P4 Ph2 GAS&PWC 1공구 배관공사 (FAB) | G2: 단위 : 원
A3: 품 명 | B3: 규 격 | C3: 단위 | D3: 단 가 | E3: 금 회 청 구 | G3: 비 고
E4: 수 량 | F4: 금 액
A5: 고급기술인 | B5: S+ | C5: M/M | D5: 1400000 | F5: =D5*E5 -> 0
A6: 고급기술인 | B6: S | C6: M/M | D6: 1200000 | F6: =D6*E6 -> 0
A7: 중급기술인 | B7: A+ | C7: M/M | D7: 1000000 | F7: =D7*E7 -> 0
A8: 중급기술인 | B8: A | C8: M/M | D8: 900000 | F8: =D8*E8 -> 0
A9: 중급기술인 | B9: B+ | C9: M/M | D9: 800000 | F9: =D9*E9 -> 0
A10: 중급기술인 | B10: B | C10: M/M | D10: 700000 | F10: =D10*E10 -> 0
A11: 초급기술인 | B11: C | C11: M/M | D11: 600000 | F11: =D11*E11 -> 0
A27: 총 계 | E27: =SUM(E5:E11) -> 0 | F27: =SUM(F5:F26) -> 0

Sheet 집계장
A1: ='용역청구서 표지'!$B$7 -> P4 Ph2 GAS&PWC 1공구 배관공사 (FAB)
L2: ='용역청구서 표지'!$C$15 -> 2026년 3월
A3: 구분 | B3: 내역 | C3: 단위 | D3: 수량 | E3: 단가 | F3: 합계 | G3: 전회기성 | H3: 금회기성 | I3: 누계기성 | J3: 비 고
A4: 1. 물량 | B4: WELDING POINT | C4: D/I | D4: =SUM('물량 내역서'!$J$5:$J$27) -> 0 | E4: =F4/D4 -> #DIV/0! | F4: =SUM('물량 내역서'!$K$5:$K$27) -> 0 | H4: =F4 -> 0 | I4: =G4+H4 -> 0
B5: VALVE 설치비 | C5: EA | D5: =SUM('물량 내역서'!$J$28:$J$50) -> 0 | E5: =F5/D5 -> #DIV/0! | F5: =SUM('물량 내역서'!$K$28:$K$50) -> 0 | H5: =F5 -> 0 | I5: =G5+H5 -> 0
B6: 인원 실투입 | C6: M/D | D6: ='근로내역 (03월)'!AN47 -> 0 | E6: =F6/D6 -> #DIV/0! | F6: ='근로내역 (03월)'!AP47 -> 0 | G6: 0 | H6: =F6 -> 0 | I6: =G6+H6 -> 0
A7: 2. 기타비용 | C7: 式 | D7: 1 | F7: =D7*E7 -> 0 | G7: 0 | H7: =F7 -> 0 | I7: =G7+H7 -> 0
A8: 소 계 | B8: 물량 | F8: =SUM(F4:F7) -> 0 | H8: =F8 -> 0 | I8: =G8+H8 -> 0
A9: 3. 노무비 | B9: 직접노무비 | C9: 式 | D9: ='근로내역 (03월)'!AN42 -> 582.25 | E9: =F9/D9 -> 193884.71 | F9: ='근로내역 (03월)'!AP42 -> 112889375 | H9: =F9 -> 112889375 | I9: =G9+H9 -> 112889375
A10: 4. 숙소 및 식대 | B10: 임대료+관리비 | C10: 式 | D10: =SUM(숙소임차료!H4:H6)+SUM(숙소관리비!H4:H8) -> 37 | E10: =F10/D10 -> 495405.41 | F10: =숙소임차료!I3+숙소관리비!I3 -> 18330000 | H10: =F10 -> 18330000 | I10: =G10+H10 -> 18330000
B11: 식대 | C11: 式 | D11: =SUM(식대비용!G4:G4) -> 30 | E11: =F11/D11 -> 264693.93 | F11: =식대비용!I3 -> 7940818 | H11: =F11 -> 7940818 | I11: =G11+H11 -> 7940818
A12: 5. 기타 공제 내역 | C12: 式 | E12: 0 | F12: =D12*E12 -> 0 | H12: =F12 -> 0 | I12: =G12+H12 -> 0
A13: 소 계 | B13: 공제 | F13: =SUM(F9:F12) -> 139160193 | H13: =F13 -> 139160193 | I13: =G13+H13 -> 139160193
A14: 합 계 | B14: 기성 (물량-공제) | F14: =F8-F13 -> -139160193 | H14: =F14 -> -139160193 | I14: =G14+H14 -> -139160193
A15: 6. 유보금 | B15: 기성금*XX% | C15: 式 | H15: =F15 -> 0 | I15: =G15+H15 -> 0
A16: 7. 유보금 차액 | B16: 전회 누계유보금+적자 기성액 | C16: 式 | H16: =F16 -> 0 | I16: =G16+H16 -> 0
A17: 8. NEGO | B17: NEGO | C17: 式 | H17: =F17 -> 0 | I17: =G17+H17 -> 0
A18: 9. 보류금액 | C18: 式 | H18: =F18 -> 0 | I18: =G18+H18 -> 0 | J18: 3월분 보류금액(97,963,959)
A19: 총 계 | B19: 최종기성 | F19: =F14-F15-F16-F17-F18 -> -139160193 | H19: =F19 -> -139160193 | I19: =G19+H19 -> -139160193
A20: 선급금 | B20: 선수공제 | C20: 式 | H20: =F20 -> 0 | I20: =G20+H20 -> 0 | K20: 지급 선급금 | L20: 선급금 차액
B21: 단수정리 | C21: 式 | F21: =ROUNDDOWN(F20,-5) -> 0 | H21: =F21 -> 0 | I21: =G21+H21 -> 0 | J21: 만 단위 이하 절사 | K21: 0 | L21: =K21-I21 -> 0
A22: 공제 후 실 지급액 | F22: =F21 -> 0 | H22: =F22 -> 0 | I22: =G22+H22 -> 0
A23: 세금계산서 기준 | F23: =ROUNDDOWN(F22,-5) -> 0 | H23: =F23 -> 0 | I23: =G23+H23 -> 0 | J23: 만 단위 이하 절사
A24: TERMS AND CONDITIONS | D24: NOTE
A25: 1. 납 기 : KCEnC 지정 납기로 별도 협의 하에 결정하는 것으로 함.
A26: 2. 지불조건 : KCEnC 지불 조건에 따름.
A27: 3. 유효기간 : 기성 제출일로 부터 30일 이내

Sheet 물량 내역서
A1: 2026년 (03)월 물량 내역서
A2: ='용역청구서 표지'!$B$7 -> P4 Ph2 GAS&PWC 1공구 배관공사 (FAB) | M2: 단위 : 원
A3: 품 명 | B3: 규 격 | C3: 단위 | D3: W/P 수량 | E3: 단 가 | F3: 계 약 내 역 | H3: 전 회 누 계 물 량 | J3: 금 회 물 량 | L3: 누 계 물 량
F4: D/I 수량 | G4: 금액 | H4: D/I 수량 | I4: 금액 | J4: D/I 수량 | K4: 금액 | L4: D/I 수량 | M4: 금액
A5: WEDING POINT | B5: 8A | C5: POINT | E5: 475000 | F5: =L5 -> 0 | G5: =M5 -> 0 | J5: =$D5*'DIA-INCH'!$C5 -> 0 | K5: =$E5*$J5 -> 0 | L5: =H5+J5 -> 0 | M5: =I5+K5 -> 0
A6: WEDING POINT | B6: 15A | C6: POINT | E6: 475000 | F6: =L6 -> 0 | G6: =M6 -> 0 | J6: =$D6*'DIA-INCH'!$C6 -> 0 | K6: =$E6*$J6 -> 0 | L6: =H6+J6 -> 0 | M6: =I6+K6 -> 0
A7: WEDING POINT | B7: 20A | C7: POINT | E7: 475000 | F7: =L7 -> 0 | G7: =M7 -> 0 | J7: =$D7*'DIA-INCH'!$C7 -> 0 | K7: =$E7*$J7 -> 0 | L7: =H7+J7 -> 0 | M7: =I7+K7 -> 0
A8: WEDING POINT | B8: 25A | C8: POINT | E8: 475000 | F8: =L8 -> 0 | G8: =M8 -> 0 | J8: =$D8*'DIA-INCH'!$C8 -> 0 | K8: =$E8*$J8 -> 0 | L8: =H8+J8 -> 0 | M8: =I8+K8 -> 0
A9: WEDING POINT | B9: 32A | C9: POINT | E9: 475000 | F9: =L9 -> 0 | G9: =M9 -> 0 | J9: =$D9*'DIA-INCH'!$C9 -> 0 | K9: =$E9*$J9 -> 0 | L9: =H9+J9 -> 0 | M9: =I9+K9 -> 0
A10: WEDING POINT | B10: 40A | C10: POINT | E10: 475000 | F10: =L10 -> 0 | G10: =M10 -> 0 | J10: =$D10*'DIA-INCH'!$C10 -> 0 | K10: =$E10*$J10 -> 0 | L10: =H10+J10 -> 0 | M10: =I10+K10 -> 0
A11: WEDING POINT | B11: 50A | C11: POINT | E11: 475000 | F11: =L11 -> 0 | G11: =M11 -> 0 | J11: =$D11*'DIA-INCH'!$C11 -> 0 | K11: =$E11*$J11 -> 0 | L11: =H11+J11 -> 0 | M11: =I11+K11 -> 0
A12: WEDING POINT | B12: 65A | C12: POINT | E12: 475000 | F12: =L12 -> 0 | G12: =M12 -> 0 | J12: =$D12*'DIA-INCH'!$C12 -> 0 | K12: =$E12*$J12 -> 0 | L12: =H12+J12 -> 0 | M12: =I12+K12 -> 0
A13: WEDING POINT | B13: 80A | C13: POINT | E13: 475000 | F13: =L13 -> 0 | G13: =M13 -> 0 | J13: =$D13*'DIA-INCH'!$C13 -> 0 | K13: =$E13*$J13 -> 0 | L13: =H13+J13 -> 0 | M13: =I13+K13 -> 0
A14: WEDING POINT | B14: 100A | C14: POINT | E14: 475000 | F14: =L14 -> 0 | G14: =M14 -> 0 | J14: =$D14*'DIA-INCH'!$C14 -> 0 | K14: =$E14*$J14 -> 0 | L14: =H14+J14 -> 0 | M14: =I14+K14 -> 0
A15: WEDING POINT | B15: 110A | C15: POINT | E15: 475000 | F15: =L15 -> 0 | G15: =M15 -> 0 | J15: =$D15*'DIA-INCH'!$C15 -> 0 | K15: =$E15*$J15 -> 0 | L15: =H15+J15 -> 0 | M15: =I15+K15 -> 0
A16: WEDING POINT | B16: 125A | C16: POINT | E16: 475000 | F16: =L16 -> 0 | G16: =M16 -> 0 | J16: =$D16*'DIA-INCH'!$C16 -> 0 | K16: =$E16*$J16 -> 0 | L16: =H16+J16 -> 0 | M16: =I16+K16 -> 0
... A27: WEDING POINT | B27: 550A | C27: POINT | E27: 475000 | F27: =L27 -> 0 | G27: =M27 -> 0 | J27: =$D27*'DIA-INCH'!$C27 -> 0 | K27: =$E27*$J27 -> 0 | L27: =H27+J27 -> 0 | M27: =I27+K27 -> 0
A28: VALVE 설치비 | B28: 8A | C28: EA | E28: =$E$31*'DIA-INCH'!$C5 -> 12500 | F28: =L28 -> 0 | G28: =M28 -> 0 | J28: =D28 -> 0 | K28: =$J28*$E28 -> 0 | L28: =H28+J28 -> 0 | M28: =I28+K28 -> 0
A29: VALVE 설치비 | B29: 15A | C29: EA | E29: =$E$31*'DIA-INCH'!$C6 -> 25000 | F29: =L29 -> 0 | G29: =M29 -> 0 | J29: =D29 -> 0 | K29: =$J29*$E29 -> 0 | L29: =H29+J29 -> 0 | M29: =I29+K29 -> 0
A30: VALVE 설치비 | B30: 20A | C30: EA | E30: =$E$31*'DIA-INCH'!$C7 -> 37500 | F30: =L30 -> 0 | G30: =M30 -> 0 | J30: =D30 -> 0 | K30: =$J30*$E30 -> 0 | L30: =H30+J30 -> 0 | M30: =I30+K30 -> 0
A31: VALVE 설치비 | B31: 25A | C31: EA | E31: 50000 | F31: =L31 -> 0 | G31: =M31 -> 0 | J31: =D31 -> 0 | K31: =$J31*$E31 -> 0 | L31: =H31+J31 -> 0 | M31: =I31+K31 -> 0
A32: VALVE 설치비 | B32: 32A | C32: EA | E32: =$E$31*'DIA-INCH'!$C9 -> 62500 | F32: =L32 -> 0 | G32: =M32 -> 0 | J32: =D32 -> 0 | K32: =$J32*$E32 -> 0 | L32: =H32+J32 -> 0 | M32: =I32+K32 -> 0
A33: VALVE 설치비 | B33: 40A | C33: EA | E33: =$E$31*'DIA-INCH'!$C10 -> 75000 | F33: =L33 -> 0 | G33: =M33 -> 0 | J33: =D33 -> 0 | K33: =$J33*$E33 -> 0 | L33: =H33+J33 -> 0 | M33: =I33+K33 -> 0
A34: VALVE 설치비 | B34: 50A | C34: EA | E34: =$E$31*'DIA-INCH'!$C11 -> 100000 | F34: =L34 -> 0 | G34: =M34 -> 0 | J34: =D34 -> 0 | K34: =$J34*$E34 -> 0 | L34: =H34+J34 -> 0 | M34: =I34+K34 -> 0
A35: VALVE 설치비 | B35: 65A | C35: EA | E35: =$E$31*'DIA-INCH'!$C12 -> 125000 | F35: =L35 -> 0 | G35: =M35 -> 0 | J35: =D35 -> 0 | K35: =$J35*$E35 -> 0 | L35: =H35+J35 -> 0 | M35: =I35+K35 -> 0
A36: VALVE 설치비 | B36: 80A | C36: EA | E36: =$E$31*'DIA-INCH'!$C13 -> 150000 | F36: =L36 -> 0 | G36: =M36 -> 0 | J36: =D36 -> 0 | K36: =$J36*$E36 -> 0 | L36: =H36+J36 -> 0 | M36: =I36+K36 -> 0
A37: VALVE 설치비 | B37: 100A | C37: EA | E37: =$E$31*'DIA-INCH'!$C14 -> 200000 | F37: =L37 -> 0 | G37: =M37 -> 0 | J37: =D37 -> 0 | K37: =$J37*$E37 -> 0 | L37: =H37+J37 -> 0 | M37: =I37+K37 -> 0
A38: VALVE 설치비 | B38: 110A | C38: EA | E38: =$E$31*'DIA-INCH'!$C15 -> 200000 | F38: =L38 -> 0 | G38: =M38 -> 0 | J38: =D38 -> 0 | K38: =$J38*$E38 -> 0 | L38: =H38+J38 -> 0 | M38: =I38+K38 -> 0
A39: VALVE 설치비 | B39: 125A | C39: EA | E39: =$E$31*'DIA-INCH'!$C16 -> 250000 | F39: =L39 -> 0 | G39: =M39 -> 0 | J39: =D39 -> 0 | K39: =$J39*$E39 -> 0 | L39: =H39+J39 -> 0 | M39: =I39+K39 -> 0
A40: VALVE 설치비 | B40: 150A | C40: EA | E40: =$E$31*'DIA-INCH'!$C17 -> 300000 | F40: =L40 -> 0 | G40: =M40 -> 0 | J40: =D40 -> 0 | K40: =$J40*$E40 -> 0 | L40: =H40+J40 -> 0 | M40: =I40+K40 -> 0
A41: VALVE 설치비 | B41: 175A | C41: EA | E41: =$E$31*'DIA-INCH'!$C18 -> 350000 | F41: =L41 -> 0 | G41: =M41 -> 0 | J41: =D41 -> 0 | K41: =$J41*$E41 -> 0 | L41: =H41+J41 -> 0 | M41: =I41+K41 -> 0
A42: VALVE 설치비 | B42: 200A | C42: EA | E42: =$E$31*'DIA-INCH'!$C19 -> 400000 | F42: =L42 -> 0 | G42: =M42 -> 0 | J42: =D42 -> 0 | K42: =$J42*$E42 -> 0 | L42: =H42+J42 -> 0 | M42: =I42+K42 -> 0
A43: VALVE 설치비 | B43: 225A | C43: EA | E43: =$E$31*'DIA-INCH'!$C20 -> 450000 | F43: =L43 -> 0 | G43: =M43 -> 0 | J43: =D43 -> 0 | K43: =$J43*$E43 -> 0 | L43: =H43+J43 -> 0 | M43: =I43+K43 -> 0
... A50: VALVE 설치비 | B50: 550A | C50: EA | E50: =$E$31*'DIA-INCH'!$C27 -> 1100000 | F50: =L50 -> 0 | G50: =M50 -> 0 | J50: =D50 -> 0 | K50: =$J50*$E50 -> 0 | L50: =H50+J50 -> 0 | M50: =I50+K50 -> 0
A51: 합 계 | F51: =SUM(F5:F50) -> 0 | G51: =SUM(G5:G50) -> 0 | H51: =SUM(H5:H50) -> 0 | I51: =SUM(I5:I50) -> 0 | J51: =SUM(J5:J50) -> 0 | K51: =SUM(K5:K50) -> 0 | L51: =SUM(L5:L50) -> 0 | M51: =SUM(M5:M50) -> 0

Sheet 근로내역 (03월)
A1: 2026년 ( 03 )월 일용 노무비명세서 | AH1: 현장명 | AM1: ='용역청구서 표지'!$B$7 -> P4 Ph2 GAS&PWC 1공구 배관공사 (FAB)
AH2: 현장소장 | AM2: 조 수 원
AH3: 잡코드 | AM3: ='용역청구서 표지'!$C$8 -> S26-001
A5: 번호 | B5: 성명 | C5: 주민등록번호 | D5: 직종 | E5: 연락처(H.P) | F5: 은행명 | G5: 예금주 | H5: 계좌번호 | I5: 1 | J5: 2 | K5: 3 | L5: 4 | M5: 5 | N5: 6 | O5: 7 | P5: 8 | Q5: 9 | R5: 10 | S5: 11 | T5: 12 | U5: 13 | V5: 14 | W5: 15 | X5: 16 | Y5: 17 | Z5: 18 | AA5: 19 | AB5: 20 | AC5: 21 | AD5: 22 | AE5: 23 | AF5: 24 | AG5: 25 | AH5: 26 | AI5: 27 | AJ5: 28 | AK5: 29 | AL5: 30 | AM5: 31 | AN5: 공수 | AO5: 단가 | AP5: 총액
A6: 1 | B6: 강민석 | C6: 000819-3823434 | D6: 보통인부 | E6: 010-4796-2063 | F6: 신한 | G6: 강민석 | H6: 110-552-336273 | K6: 0.4375 | L6: 0.375 | M6: 1 | N6: 1 | Q6: 1 | R6: 1 | S6: 1 | V6: 1 | X6: 1 | Y6: 1 | Z6: 1 | AA6: 1.5 | AB6: 1 | AC6: 1 | AE6: 1 | AF6: 1 | AG6: 1 | AH6: 1 | AI6: 1 | AL6: 0.5 | AN6: =SUM(I6:AM6) -> 18.8125 | AO6: 160000 | AP6: =AN6*AO6 -> 3010000
A7: 2 | B7: 강희수 | C7: 730210-1029411 | D7: 도비공 | E7: 010-9561-6101 | F7: 신한 | G7: 강희수 | H7: 110-490-486591 | AE7: 0.4375 | AF7: 0.25 | AG7: 1 | AH7: 1 | AI7: 1 | AL7: 1 | AM7: 1.5 | AN7: =SUM(I7:AM7) -> 6.1875 | AO7: 210000 | AP7: =AN7*AO7 -> 1299375
A8: 3 | B8: 김금성 | C8: 870118-1162639 | D8: 보통인부 | E8: 010-5125-5154 | F8: 농협 | G8: 김금성 | H8: 351-1130-0614-23 | AE8: 0.4375 | AG8: 1 | AH8: 1 | AI8: 1 | AL8: 1 | AM8: 1.5 | AN8: =SUM(I8:AM8) -> 5.9375 | AO8: 160000 | AP8: =AN8*AO8 -> 950000
A9: 4 | B9: 김동욱 | C9: 810302-1830628 | D9: 배관공 | E9: 010-5022-0444 | F9: 농협 | G9: 김동욱 | H9: 302-5022-0444-11 | K9: 0.9375 | L9: 0.375 | M9: 1 | N9: 1 | Q9: 1 | R9: 1 | S9: 1 | T9: 1 | U9: 1 | V9: 1 | X9: 1 | Y9: 1 | Z9: 1 | AA9: 1.5 | AB9: 1 | AC9: 1 | AE9: 1 | AF9: 1.5 | AG9: 1 | AH9: 0.75 | AL9: 1 | AM9: 1.5 | AN9: =SUM(I9:AM9) -> 22.5625 | AO9: 210000 | AP9: =AN9*AO9 -> 4738125
A10: 5 | B10: 김마태 | C10: 830224-1912010 | D10: 배관공 | E10: 010-2725-6089 | F10: 기업 | G10: 김마태 | H10: 175-073189-01-013 | Q10: 0.9375 | S10: 1 | T10: 1 | U10: 1 | X10: 0.5 | Y10: 1 | Z10: 1 | AA10: 1.5 | AB10: 1 | AC10: 1 | AE10: 1 | AF10: 1.5 | AG10: 1 | AH10: 1.5 | AI10: 1 | AJ10: 1 | AL10: 1 | AM10: 1.5 | AN10: =SUM(I10:AM10) -> 19.4375 | AO10: 240000 | AP10: =AN10*AO10 -> 4665000
A11: 6 | B11: 김승태 | C11: 720112-1019646 | D11: 보통인부 | E11: 010-7166-5282 | F11: 토스뱅크 | G11: 김승태 | H11: 1000-2078-6151 | Q11: 0.4375 | AG11: 1 | AH11: 1 | AI11: 1 | AL11: 1 | AM11: 1.5 | AN11: =SUM(I11:AM11) -> 5.9375 | AO11: 160000 | AP11: =AN11*AO11 -> 950000
A12: 7 | B12: 김정인 | C12: 911224-1235320 | D12: 용접공 | E12: 010-3175-7994 | F12: 기업 | G12: 김정인 | H12: 010-3175-7994 | X12: 0.9375 | Y12: 0.5 | Z12: 1 | AA12: 1 | AB12: 1 | AE12: 1 | AG12: 1 | AH12: 1.5 | AI12: 1 | AJ12: 1 | AL12: 1 | AM12: 1.5 | AN12: =SUM(I12:AM12) -> 12.4375 | AO12: 240000 | AP12: =AN12*AO12 -> 2985000
A13: 8 | B13: 김진 | C13: 840728-1235014 | D13: 공사보조 | E13: 010-6246-4588 | F13: 기업 | G13: 김진 | H13: 458-013758-02-012 | AF13: 0.5 | AG13: 1 | AH13: 1.5 | AI13: 1 | AJ13: 1 | AL13: 1 | AM13: 1.5 | AN13: =SUM(I13:AM13) -> 7.5 | AO13: 240000 | AP13: =AN13*AO13 -> 1800000
A14: 9 | B14: 김치헌 | C14: 790914-1567115 | D14: 배관공 | E14: 010-4191-6886 | F14: 국민 | G14: 김치헌 | H14: 257602-04-003063 | Q14: 0.9375 | S14: 1 | T14: 1 | U14: 1 | X14: 1 | Y14: 1 | Z14: 1 | AA14: 1.5 | AB14: 1 | AC14: 1 | AE14: 1 | AF14: 1.5 | AG14: 1 | AH14: 1.5 | AI14: 1 | AL14: 1 | AM14: 1.5 | AN14: =SUM(I14:AM14) -> 18.9375 | AO14: 240000 | AP14: =AN14*AO14 -> 4545000
A15: 10 | B15: 김형태 | C15: 700430-1069427 | D15: 도비공 | E15: 010-3186-7175 | F15: 농협 | G15: 김형태 | H15: 352-1156-5484-53 | Q15: 0.4375 | S15: 1 | T15: 1 | U15: 1 | X15: 1 | Y15: 1 | Z15: 1 | AA15: 1.5 | AB15: 1 | AC15: 1 | AE15: 1 | AF15: 1.5 | AG15: 1 | AH15: 1.5 | AI15: 1 | AL15: 1 | AM15: 1.5 | AN15: =SUM(I15:AM15) -> 18.4375 | AO15: 180000 | AP15: =AN15*AO15 -> 3318750
A16: 11 | B16: 남현빈 | C16: 990907-1842410 | D16: 배관공 | E16: 010-7131-4342 | F16: 카카오뱅크 | G16: 남현빈 | H16: 3333-13-8378173 | X16: 0.9375 | Y16: 1 | Z16: 1 | AA16: 1 | AB16: 1 | AE16: 1 | AF16: 1.5 | AG16: 1 | AH16: 1.5 | AI16: 1 | AJ16: 1 | AL16: 1 | AM16: 1.5 | AN16: =SUM(I16:AM16) -> 14.4375 | AO16: 190000 | AP16: =AN16*AO16 -> 2743125
A17: 12 | B17: 빈상원 | C17: 810410-1522211 | D17: 보통인부 | E17: 010-8778-9123 | F17: 신협 | G17: 빈상원 | H17: 137-012-596819 | Q17: 0.4375 | S17: 1 | T17: 1 | U17: 1 | X17: 1 | Y17: 1 | Z17: 1 | AA17: 1.5 | AB17: 1 | AC17: 1 | AE17: 1 | AF17: 1.5 | AG17: 1 | AH17: 1.5 | AI17: 1 | AJ17: 1 | AL17: 1 | AM17: 1.5 | AN17: =SUM(I17:AM17) -> 19.4375 | AO17: 160000 | AP17: =AN17*AO17 -> 3110000
A18: 13 | B18: 석임수 | C18: 911020-1685317 | D18: 안전보조 | E18: 010-4183-1119 | F18: 하나 | G18: 석임수 | H18: 238-910260-47407 | AG18: 1 | AH18: 1.5 | AI18: 1 | AJ18: 1 | AL18: 1 | AM18: 1.5 | AN18: =SUM(I18:AM18) -> 7 | AO18: 190000 | AP18: =AN18*AO18 -> 1330000
A19: 14 | B19: 성지현 | C19: 861110-1351114 | D19: 보통인부 | E19: 010-9197-9732 | F19: 카카오뱅크 | G19: 성지현 | H19: 3333-01-9967097 | AE19: 0.4375 | AG19: 1 | AH19: 1.5 | AI19: 1 | AL19: 1 | AM19: 1.5 | AN19: =SUM(I19:AM19) -> 6.4375 | AO19: 230000 | AP19: =AN19*AO19 -> 1480625
A20: 15 | B20: 신민철 | C20: 830814-1183120 | D20: 공사보조 | E20: 010-7706-5000 | F20: 기업 | G20: 신민철 | H20: 289-082628-01-018 | S20: 1 | T20: 1 | U20: 1 | V20: 1 | X20: 1 | Y20: 1 | Z20: 1 | AA20: 1.5 | AB20: 1 | AC20: 1 | AE20: 1 | AF20: 1.5 | AG20: 1 | AH20: 1.5 | AI20: 1 | AL20: 1 | AM20: 1.5 | AN20: =SUM(I20:AM20) -> 19 | AO20: 220000 | AP20: =AN20*AO20 -> 4180000
A21: 16 | B21: 양정운 | C21: 821019-1449616 | D21: 공사보조 | E21: 010-3641-8181 | F21: 농협 | G21: 양정운 | H21: 302-1350-3060-51 | AG21: 1 | AH21: 1.5 | AI21: 1 | AJ21: 1 | AL21: 1 | AM21: 1.5 | AN21: =SUM(I21:AM21) -> 7 | AO21: 250000 | AP21: =AN21*AO21 -> 1750000
A22: 17 | B22: 양정인 | C22: 810207-1455012 | D22: 보통인부 | E22: 010-8824-6401 | F22: 국민 | G22: 양정인 | H22: 472301-04-019277 | X22: 0.4375 | Z22: 1 | AA22: 1 | AB22: 1 | AE22: 1 | AF22: 1.5 | AG22: 1 | AH22: 1.5 | AI22: 1 | AJ22: 1 | AL22: 1 | AM22: 1.5 | AN22: =SUM(I22:AM22) -> 12.9375 | AO22: 170000 | AP22: =AN22*AO22 -> 2199375
A23: 18 | B23: 연승렬 | C23: 700216-1011916 | D23: 보통인부 | E23: 010-8098-3356 | F23: 기업 | G23: 연승렬 | H23: 186-086062-01-011 | Q23: 0.4375 | S23: 1 | T23: 1 | U23: 1 | X23: 0.375 | Y23: 1 | Z23: 1 | AA23: 1.5 | AB23: 1 | AE23: 1 | AF23: 1.5 | AG23: 1 | AH23: 1.5 | AI23: 1 | AL23: 1 | AM23: 1.5 | AN23: =SUM(I23:AM23) -> 16.8125 | AO23: 160000 | AP23: =AN23*AO23 -> 2690000
A24: 19 | B24: 옥유정 | C24: 850715-2093511 | D24: 보통인부 | E24: 010-2313-8731 | F24: 카카오뱅크 | G24: 옥유정 | H24: 3333-17-6983150 | Q24: 0.4375 | S24: 1 | T24: 1 | U24: 1 | X24: 1 | Y24: 1 | Z24: 1 | AA24: 1.5 | AB24: 1 | AE24: 1 | AF24: 1.5 | AG24: 1 | AH24: 1.5 | AI24: 1 | AL24: 1 | AM24: 1.5 | AN24: =SUM(I24:AM24) -> 17.4375 | AO24: 150000 | AP24: =AN24*AO24 -> 2615625
A25: 20 | B25: 이강남 | C25: 750810-1106711 | D25: 보통인부 | E25: 010-2369-7579 | F25: 우체국 | G25: 이강남 | H25: 102319-02-095386 | K25: 0.4375 | L25: 0.375 | M25: 1 | N25: 1 | Q25: 1 | R25: 1 | S25: 1 | T25: 1 | U25: 1 | V25: 1 | X25: 1 | Z25: 1 | AA25: 1.5 | AB25: 1 | AC25: 1 | AF25: 1.5 | AG25: 1 | AH25: 1.5 | AI25: 1 | AJ25: 1 | AL25: 1 | AM25: 1.5 | AN25: =SUM(I25:AM25) -> 22.8125 | AO25: 160000 | AP25: =AN25*AO25 -> 3650000
A26: 21 | B26: 이백창 | C26: 761016-1110611 | D26: 보통인부 | E26: 010-9815-0818 | F26: NH투자증권 | G26: 이백창 | H26: 207-01-565429 | Q26: 0.4375 | S26: 1 | T26: 1 | U26: 1 | X26: 1 | Y26: 1 | Z26: 1 | AA26: 1.5 | AB26: 1 | AC26: 1 | AE26: 1 | AF26: 1.5 | AG26: 1 | AH26: 1.5 | AI26: 1 | AJ26: 1 | AL26: 1 | AM26: 1.5 | AN26: =SUM(I26:AM26) -> 19.4375 | AO26: 170000 | AP26: =AN26*AO26 -> 3304375
A27: 22 | B27: 이상덕 | C27: 730801-1545424 | D27: 공사보조 | E27: 010-2495-1870 | F27: 기업 | G27: 이상덕 | H27: 183-015807-01020 | M27: 1 | N27: 1 | Q27: 1 | R27: 0.875 | S27: 1 | T27: 1 | U27: 1 | V27: 1 | X27: 1 | Y27: 1 | Z27: 1 | AA27: 1.5 | AB27: 1 | AC27: 1 | AE27: 1 | AF27: 1.5 | AG27: 1 | AH27: 1.5 | AI27: 1 | AL27: 1 | AM27: 1.5 | AN27: =SUM(I27:AM27) -> 22.875 | AO27: 270000 | AP27: =AN27*AO27 -> 6176250
A28: 23 | B28: 이수빈 | C28: 940912-1105528 | D28: 안전보조 | E28: 010-7774-4872 | F28: 국민 | G28: 이수빈 | H28: 110802-04-289399 | AF28: 0.5 | AG28: 1 | AH28: 1.5 | AI28: 1 | AL28: 1 | AM28: 1.5 | AN28: =SUM(I28:AM28) -> 6.5 | AO28: 180000 | AP28: =AN28*AO28 -> 1170000
A29: 24 | B29: 이진 | C29: 900815-1066311 | D29: 보통인부 | E29: 010-8738-7072 | F29: 국민 | G29: 이진 | H29: 757102-04-212989 | Q29: 0.4375 | S29: 1 | T29: 1 | U29: 1 | X29: 1 | Y29: 1 | Z29: 1 | AA29: 1.5 | AB29: 1 | AE29: 1 | AF29: 1.5 | AG29: 1 | AH29: 1.5 | AI29: 1 | AJ29: 1 | AL29: 1 | AM29: 1.5 | AN29: =SUM(I29:AM29) -> 18.4375 | AO29: 200000 | AP29: =AN29*AO29 -> 3687500
A30: 25 | B30: 이희준 | C30: 840808-1002416 | D30: 공사보조 | E30: 010-7612-6003 | F30: 토스뱅크 | G30: 이희준 | H30: 1000-3396-8736 | K30: 0.4375 | L30: 0.625 | M30: 1 | N30: 1 | Q30: 1 | R30: 1 | S30: 1 | T30: 1 | U30: 1 | X30: 0.625 | Y30: 1 | Z30: 1 | AA30: 1.375 | AB30: 1 | AC30: 1 | AE30: 1 | AF30: 1.5 | AG30: 1 | AH30: 1.5 | AI30: 1 | AL30: 1 | AM30: 1.5 | AN30: =SUM(I30:AM30) -> 22.5625 | AO30: 230000 | AP30: =AN30*AO30 -> 5189375
A31: 26 | B31: 정춘식 | C31: 870321-1050411 | D31: 배관공 | E31: 010-3413-8703 | F31: 농협 | G31: 정춘식 | H31: 352-1195-1823-93 | X31: 0.9375 | Z31: 1 | AA31: 1 | AB31: 1 | AE31: 1 | AF31: 1.5 | AG31: 1 | AH31: 1.5 | AI31: 1 | AL31: 1 | AM31: 1.5 | AN31: =SUM(I31:AM31) -> 12.4375 | AO31: 230000 | AP31: =AN31*AO31 -> 2860625
A32: 27 | B32: 조봉연 | C32: 911016-1030818 | D32: 보통인부 | E32: 010-7608-9991 | F32: 카카오뱅크 | G32: 조봉연 | H32: 3333-17-3476329 | K32: 0.4375 | L32: 0.375 | M32: 1 | Q32: 1 | R32: 1 | S32: 1 | T32: 1 | U32: 1 | Y32: 1 | Z32: 1 | AA32: 1.5 | AB32: 1 | AC32: 1 | AE32: 0.5 | AF32: 1.5 | AG32: 1 | AH32: 1.5 | AI32: 1 | AL32: 1 | AM32: 1.5 | AN32: =SUM(I32:AM32) -> 20.3125 | AO32: 160000 | AP32: =AN32*AO32 -> 3250000
A33: 28 | B33: 조영래 | C33: 690909-1458513 | D33: 도비공 | E33: 010-5345-0591 | F33: 국민 | G33: 조영래 | H33: 078-24-0643-341 | K33: 0.4375 | L33: 0.625 | M33: 1 | N33: 1 | Q33: 1 | R33: 1 | S33: 1 | T33: 1 | U33: 1 | X33: 1 | Y33: 1 | Z33: 1 | AA33: 1.5 | AB33: 1 | AC33: 1 | AE33: 1 | AF33: 1.5 | AG33: 1 | AH33: 1.5 | AI33: 1 | AM33: 1.5 | AN33: =SUM(I33:AM33) -> 22.0625 | AO33: 210000 | AP33: =AN33*AO33 -> 4633125
A34: 29 | B34: 최대용 | C34: 760327-1842514 | D34: 보통인부 | E34: 010-2264-7990 | F34: 하나 | G34: 최대용 | H34: 354-910341-40407 | Q34: 0.4375 | S34: 1 | T34: 1 | U34: 1 | X34: 1 | Y34: 1 | Z34: 1 | AA34: 1.5 | AB34: 1 | AE34: 1 | AF34: 1.5 | AG34: 1 | AH34: 1.5 | AI34: 1 | AL34: 1 | AM34: 1.5 | AN34: =SUM(I34:AM34) -> 17.4375 | AO34: 170000 | AP34: =AN34*AO34 -> 2964375
A35: 30 | B35: 최원석 | C35: 791023-1065216 | D35: 배관공 | E35: 010-6307-9819 | F35: 국민 | G35: 최원석 | H35: 604401-01-239264 | K35: 0.9375 | L35: 0.375 | M35: 1 | N35: 1 | Q35: 1 | R35: 1 | S35: 1 | T35: 1 | U35: 1 | V35: 1 | X35: 1 | Y35: 1 | Z35: 1 | AA35: 1.5 | AB35: 1 | AE35: 1 | AF35: 1.5 | AG35: 1 | AH35: 1.5 | AI35: 1 | AJ35: 1 | AL35: 1 | AM35: 1.5 | AN35: =SUM(I35:AM35) -> 24.3125 | AO35: 230000 | AP35: =AN35*AO35 -> 5591875
A36: 31 | B36: 최형권 | C36: 820625-1411930 | D36: 보통인부 | E36: 010-3121-3146 | F36: 우리 | G36: 최형권 | H36: 1002-337-154871 | Q36: 0.4375 | S36: 1 | T36: 1 | U36: 1 | X36: 1 | Y36: 1 | Z36: 1 | AA36: 1.5 | AB36: 1 | AC36: 1 | AE36: 1 | AF36: 1.5 | AG36: 1 | AH36: 1.5 | AI36: 1 | AJ36: 1 | AL36: 1 | AM36: 1.5 | AN36: =SUM(I36:AM36) -> 19.4375 | AO36: 170000 | AP36: =AN36*AO36 -> 3304375
A37: 32 | B37: 하성호 | C37: 770108-1468427 | D37: 배관공 | E37: 010-8962-6247 | F37: 신한 | G37: 하성호 | H37: 110-175-083529 | Q37: 0.9375 | R37: 1 | Z37: 1 | AA37: 1 | AB37: 1 | AE37: 1 | AF37: 1.5 | AG37: 1 | AH37: 1.5 | AI37: 1 | AJ37: 1 | AL37: 1 | AM37: 1.5 | AN37: =SUM(I37:AM37) -> 14.4375 | AO37: 190000 | AP37: =AN37*AO37 -> 2743125
A38: 33 | B38: 허남일 | C38: 771202-1452815 | D38: 도비공 | E38: 010-8096-7102 | F38: 우체국 | G38: 허남일 | H38: 312363-02-228401 | K38: 0.4375 | L38: 0.625 | M38: 1 | N38: 1 | Q38: 1 | R38: 1 | S38: 1 | T38: 1 | U38: 1 | X38: 1 | Y38: 1 | Z38: 0.5 | AA38: 1.5 | AB38: 1 | AC38: 1 | AE38: 1 | AF38: 1.5 | AG38: 1 | AH38: 1.5 | AI38: 1 | AJ38: 1 | AL38: 1 | AM38: 1.5 | AN38: =SUM(I38:AM38) -> 23.5625 | AO38: 180000 | AP38: =AN38*AO38 -> 4241250
A39: 34 | B39: 황동우 | C39: 770113-1558817 | D39: 도비공 | E39: 010-2360-6689 | F39: 국민 | G39: 황동우 | H39: 688801-00-122509 | K39: 0.4375 | L39: 0.625 | M39: 1 | N39: 1 | Q39: 1 | R39: 1 | S39: 1 | T39: 1 | U39: 1 | X39: 1 | Y39: 1 | Z39: 1 | AA39: 1.5 | AB39: 1 | AC39: 1 | AE39: 1 | AF39: 1.5 | AG39: 1 | AH39: 1.5 | AI39: 1 | AL39: 1 | AM39: 1.5 | AN39: =SUM(I39:AM39) -> 23.0625 | AO39: 190000 | AP39: =AN39*AO39 -> 4381875
A40: 35 | B40: 황민일 | C40: 030404-3253526 | D40: 보통인부 | E40: 010-5539-7068 | F40: 신한 | G40: 황민일 | H40: 110-512-016280 | K40: 0.4375 | L40: 0.375 | M40: 1 | N40: 1 | Q40: 1 | R40: 1 | S40: 1 | T40: 1 | X40: 1 | Y40: 1 | Z40: 1 | AA40: 1.5 | AB40: 1 | AC40: 1 | AE40: 1 | AF40: 1.5 | AG40: 1 | AH40: 1.5 | AI40: 1 | AL40: 1 | AM40: 1.5 | AN40: =SUM(I40:AM40) -> 21.8125 | AO40: 150000 | AP40: =AN40*AO40 -> 3271875
A41: 36 | B41: 황순일 | C41: 960117-1254015 | D41: 보통인부 | E41: 010-3900-7068 | F41: 기업 | G41: 황순일 | H41: 010-3900-7068 | K41: 0.4375 | L41: 0.375 | S41: 0.75 | X41: 1 | Y41: 1 | AB41: 1 | AC41: 1 | AE41: 1 | AF41: 1.5 | AG41: 1 | AH41: 1.5 | AI41: 1 | AL41: 1 | AM41: 1.5 | AN41: =SUM(I41:AM41) -> 14.0625 | AO41: 150000 | AP41: =AN41*AO41 -> 2109375
...

Sheet 숙소임차료
A1: 숙소 임차료
A2: No. | B2: 납부일 | C2: 구분 | D2: 품명 | E2: 주소 | F2: 호수 | G2: 수량 | H2: 사용인원 | I2: 임차료 | J2: 비 고
I3: =SUM(I4:I14) -> 18330000 | L3: 입력해야하는 항목 외 수정 금지
A4: 1 | B4: 46112 | C4: KC대납 임대료 | D4: 숙소임대료(03월분) | E4: 고덕갈평10길 40, 301호 | F4: 301호 | G4: 1 | H4: 6 | I4: 1600000 | J4: KC 대납 | L4: 납부일
A5: 2 | B5: 46112 | C5: KC대납 임대료 | D5: 숙소임대료(03월분) | E5: 함박산1길 50, 401호 | F5: 401호 | G5: 1 | H5: 6 | I5: 1700000 | J5: KC 대납 | L5: 구분
A6: 3 | B6: 46112 | C6: KC대납 임대료 | D6: 숙소임대료(03월분) | E6: 함박산4길 3, 301호 | F6: 301호 | G6: 1 | H6: 6 | I6: 1530000 | J6: KC 대납 | L6: 품명
A7: 4 | B7: 46112 | C7: KC대납 임대료 | D7: 숙소임대료(03월분) | E7: 고덕여염11길 14, 202호 | F7: 202호 | G7: 1 | H7: 4 | I7: 1300000 | J7: KC 대납 | L7: 주소
A8: 5 | B8: 46112 | C8: KC대납 임대료 | D8: 숙소임대료(03월분) | E8: 함박산3길37, 301호 | F8: 301호 | G8: 1 | H8: 6 | I8: 1600000 | J8: KC 대납 | L8: 호수
A9: 6 | B9: 46112 | C9: KC대납 임대료 | D9: 숙소임대료(03월분) | E9: 함박산9길28, 401호(복층) | F9: 401호 | G9: 1 | H9: 6 | I9: 2000000 | J9: KC 대납 | L9: 수량
A10: 7 | B10: 46112 | C10: KC대납 임대료 | D10: 숙소임대료(03월분) | E10: 고덕국제4길 60-16 202호 | F10: 202호 | G10: 1 | H10: 6 | I10: 1600000 | J10: KC 대납 | L10: 사용인원
A11: 8 | B11: 46112 | C11: KC대납 임대료 | D11: 숙소임대료(03월분) | E11: 고덕여염11길 149, 202호 | F11: 202호 | G11: 1 | H11: 6 | I11: 1900000 | J11: KC 대납
A12: 9 | B12: 46112 | C12: KC대납 임대료 | D12: 숙소임대료(03월분) | E12: 고덕여염6길 199 202호 | F12: 202호 | G12: 1 | H12: 6 | I12: 1800000 | J12: KC 대납 | L12: ■ 구분은 [KC대납 임대료 및 임대료] 이외 항목은 입력금지
A13: 10 | B13: 46112 | C13: KC대납 임대료 | D13: 숙소임대료(03월분) | E13: 함박산1길 34 301호 | F13: 301호 | G13: 1 | H13: 6 | I13: 1700000 | J13: KC 대납
A14: 11 | B14: 46112 | C14: KC대납 임대료 | D14: 숙소임대료(03월분) | E14: 함박산9길26, 202호 | F14: 202호 | G14: 1 | H14: 4 | I14: 1600000 | J14: KC 대납

Sheet 숙소관리비
A1: 숙소 관리비
A2: No. | B2: 납부일 | C2: 구분 | D2: 품명 | E2: 주소 | F2: 호수 | G2: 수량 | H2: 사용인원 | I2: 관리비 | J2: 비 고
I3: =SUM(I4:I36) -> 0
A4: 1 | C4: KC대납 관리비 | D4: 숙소수도세(03월분) | E4: 고덕갈평10길 40, 301호 | F4: 301호 | G4: 1 | H4: 3 | I4: 익월청구예정 | J4: KC 대납
A5: 2 | C5: KC대납 관리비 | D5: 숙소가스료(03월분) | E5: 고덕갈평10길 40, 301호 | F5: 301호 | G5: 1 | H5: 3 | I5: 익월청구예정 | J5: KC 대납
A6: 3 | C6: KC대납 관리비 | D6: 숙소전기료(03월분) | E6: 고덕갈평10길 40, 301호 | F6: 301호 | G6: 1 | H6: 3 | I6: 익월청구예정 | J6: KC 대납
A7: 4 | C7: KC대납 관리비 | D7: 숙소수도세(03월분) | E7: 함박산1길 50, 401호 | F7: 401호 | G7: 1 | H7: 5 | I7: 익월청구예정 | J7: KC 대납
A8: 5 | C8: KC대납 관리비 | D8: 숙소가스료(03월분) | E8: 함박산1길 50, 401호 | F8: 401호 | G8: 1 | H8: 5 | I8: 익월청구예정 | J8: KC 대납
A9: 6 | C9: KC대납 관리비 | D9: 숙소전기료(03월분) | E9: 함박산1길 50, 401호 | F9: 401호 | G9: 1 | H9: 5 | I9: 익월청구예정 | J9: KC 대납
A10: 7 | C10: KC대납 관리비 | D10: 숙소수도세(03월분) | E10: 함박산4길 3, 301호 | F10: 301호 | G10: 1 | H10: 6 | I10: 익월청구예정 | J10: KC 대납
A11: 8 | C11: KC대납 관리비 | D11: 숙소가스료(03월분) | E11: 함박산4길 3, 301호 | F11: 301호 | G11: 1 | H11: 6 | I11: 익월청구예정 | J11: KC 대납
A12: 9 | C12: KC대납 관리비 | D12: 숙소전기료(03월분) | E12: 함박산4길 3, 301호 | F12: 301호 | G12: 1 | H12: 6 | I12: 익월청구예정 | J12: KC 대납
A13: 10 | C13: KC대납 관리비 | D13: 숙소수도세(03월분) | E13: 고덕여염11길 14, 202호 | F13: 202호 | G13: 1 | H13: 4 | I13: 익월청구예정 | J13: KC 대납
A14: 11 | C14: KC대납 관리비 | D14: 숙소가스료(03월분) | E14: 고덕여염11길 14, 202호 | F14: 202호 | G14: 1 | H14: 4 | I14: 익월청구예정 | J14: KC 대납
A15: 12 | C15: KC대납 관리비 | D15: 숙소전기료(03월분) | E15: 고덕여염11길 14, 202호 | F15: 202호 | G15: 1 | H15: 4 | I15: 익월청구예정 | J15: KC 대납
... A36: 33 | C36: KC대납 관리비 | D36: 숙소전기료(03월분) | E36: 함박산9길26, 202호 | F36: 202호 | G36: 1 | H36: 6 | I36: 익월청구예정 | J36: KC 대납

Sheet 식대비용
A1: 식대 비용
A2: No. | B2: 납부일 | C2: 구분 | D2: 품명 | E2: 거래처명 | F2: 수량 | G2: 식수인원 | H2: 단가 | I2: 합 계 | J2: 비 고
I3: =SUM(I4:I5) -> 7940818 | L3: 입력해야하는 항목 외 수정 금지
A4: 1 | B4: 46112 | C4: KC대납 식대 | D4: 기술인및관리자 (현장 식당) | E4: 포세카 | F4: 432 | G4: 30 | H4: 6181.82 | I4: 2655818 | J4: KC 대납 | L4: 입력항목
A5: 2 | B5: 46112 | C5: KC대납 식대 | D5: 기술인및관리자 (현장 식당) | E5: 밥심 | F5: 755 | G5: 30 | H5: 7000 | I5: =F5*H5 -> 5285000 | J5: KC 대납 | L5: 납부일
L6: 구분
L7: 품명
L8: 거래처명
L9: 수량
L10: 식수인원
L11: 단가
L13: ■ 구분은 [KC대납 식대 및 식대] 이외 항목은 입력금지

Sheet 기타비용
A1: 기타 비용
A2: No. | B2: 구매일 | C2: 구분 | D2: 품명 | E2: 거래처명 | F2: 수량 | G2: 단가 | H2: 합계 | I2: 비고
H3: =SUM(H4:H37) -> 975900 | K3: 입력해야하는 항목 외 수정 금지
A4: 1 | B4: 46086 | C4: 소모품비 | D4: 케이블타이 [200mm(1봉=1000개),백색 [HNS]] | E4: 미래공구 | F4: 1 | G4: 12400 | H4: =F4*G4 -> 12400 | I4: 거래명세서 첨부 | K4: 입력항목
A5: 2 | B5: 46086 | C5: 소모품비 | D5: 가위 [SB-P300,CTX [세신]] | E5: 미래공구 | F5: 1 | G5: 4500 | H5: =F5*G5 -> 4500 | I5: 거래명세서 첨부 | K5: 납부일
A6: 3 | B6: 46091 | C6: 소모품비 | D6: 보루 [5KG,면 [백호]] | E6: 미래공구 | F6: 1 | G6: 12000 | H6: =F6*G6 -> 12000 | I6: 거래명세서 첨부 | K6: 구분
A7: 4 | B7: 46091 | C7: 소모품비 | D7: 청보호랩 [500mm*150m [다성]] | E7: 미래공구 | F7: 4 | G7: 18000 | H7: =F7*G7 -> 72000 | I7: 거래명세서 첨부 | K7: 품명
A8: 5 | B8: 46091 | C8: 소모품비 | D8: 보드마카 [흑색,12개 [모나미]] | E8: 미래공구 | F8: 2 | G8: 7000 | H8: =F8*G8 -> 14000 | I8: 거래명세서 첨부 | K8: 거래처명
A9: 6 | B9: 46091 | C9: 소모품비 | D9: 번호열쇠 [XD-40,4열 [자커]] | E9: 미래공구 | F9: 2 | G9: 3500 | H9: =F9*G9 -> 7000 | I9: 거래명세서 첨부 | K9: 수량
A10: 7 | B10: 46091 | C10: 소모품비 | D10: 물파스 [90ML [현대약품]] | E10: 미래공구 | F10: 2 | G10: 3500 | H10: =F10*G10 -> 7000 | I10: 거래명세서 첨부 | K10: 식수인원
A11: 8 | B11: 46092 | C11: 소모품비 | D11: 라인테이프 [50*30,PURPLE [A1]] | E11: 미래공구 | F11: 10 | G11: 2800 | H11: =F11*G11 -> 28000 | I11: 거래명세서 첨부 | K11: 단가
A12: 9 | B12: 46092 | C12: 소모품비 | D12: 절연테이프 [19*10m,검정,CTX [금성]] | E12: 미래공구 | F12: 20 | G12: 400 | H12: =F12*G12 -> 8000 | I12: 거래명세서 첨부
A13: 10 | B13: 46092 | C13: 소모품비 | D13: 단프라시트 [청색,900*1800*3T,플로베니아 [HNS]] | E13: 미래공구 | F13: 1 | G13: 2600 | H13: =F13*G13 -> 2600 | I13: 거래명세서 첨부 | K13: ■ 구분은 [KC대납 식대 및 식대] 이외 항목은 입력금지
A14: 11 | B14: 46093 | C14: 소모품비 | D14: PP로프 [10mm [HNS]] | E14: 미래공구 | F14: 1 | G14: 14900 | H14: =F14*G14 -> 14900 | I14: 거래명세서 첨부
A15: 12 | B15: 46093 | C15: 소모품비 | D15: 단프라시트 [청색,900*1800*3T,플로베니아 [HNS]] | E15: 미래공구 | F15: 5 | G15: 2600 | H15: =F15*G15 -> 13000 | I15: 거래명세서 첨부
A16: 13 | B16: 46093 | C16: 소모품비 | D16: 양면테이프 [50mm*6m,핫멧트 [HNS]] | E16: 미래공구 | F16: 50 | G16: 800 | H16: =F16*G16 -> 40000 | I16: 거래명세서 첨부
A17: 14 | B17: 46093 | C17: 소모품비 | D17: 양면테이프 [25mm*6m,핫멧트 [HNS]] | E17: 미래공구 | F17: 20 | G17: 400 | H17: =F17*G17 -> 8000 | I17: 거래명세서 첨부
A18: 15 | B18: 46094 | C18: 소모품비 | D18: 체인 [4mm,CTX [KBC]] | E18: 미래공구 | F18: 12 | G18: 1000 | H18: =F18*G18 -> 12000 | I18: 거래명세서 첨부
A19: 16 | B19: 46094 | C19: 소모품비 | D19: 번호열쇠 [XD-40,4열 [자커]] | E19: 미래공구 | F19: 4 | G19: 3600 | H19: =F19*G19 -> 14400 | I19: 거래명세서 첨부
A20: 17 | B20: 46098 | C20: 소모품비 | D20: 건전지 [AAA,2개 [벡셀]] | E20: 미래공구 | F20: 48 | G20: 900 | H20: =F20*G20 -> 43200 | I20: 거래명세서 첨부
A21: 18 | B21: 46099 | C21: 소모품비 | D21: 철근절단비트 [MSRC-18 [모스툴]] | E21: 미래공구 | F21: 5 | G21: 33000 | H21: =F21*G21 -> 165000 | I21: 거래명세서 첨부
A22: 19 | B22: 46099 | C22: 소모품비 | D22: 수평 [자석,MML-100 [SB]] | E22: 미래공구 | F22: 2 | G22: 10000 | H22: =F22*G22 -> 20000 | I22: 거래명세서 첨부
A23: 20 | B23: 46099 | C23: 소모품비 | D23: 충전후레쉬 [K2202,충전건전지포함 [수입]] | E23: 미래공구 | F23: 2 | G23: 24000 | H23: =F23*G23 -> 48000 | I23: 거래명세서 첨부
A24: 21 | B24: 46099 | C24: 소모품비 | D24: 레이저포인트 [A11,그린 [수입]] | E24: 미래공구 | F24: 2 | G24: 17000 | H24: =F24*G24 -> 34000 | I24: 거래명세서 첨부
A25: 22 | B25: 46104 | C25: 소모품비 | D25: 순간접착제 [401,20g,CTX [록타이트]] | E25: 미래공구 | F25: 1 | G25: 3400 | H25: =F25*G25 -> 3400 | I25: 거래명세서 첨부
... A37: 34 | B37: 46112 | C37: 소모품비 | D37: 피스복 [아야지도장복,투피스,3XL [수입/SW]] | E37: 미래공구 | F37: 3 | G37: 14800 | H37: =F37*G37 -> 44400 | I37: 거래명세서 첨부

Sheet 서명란
B2: 현 장 확 인 | C2: 소 장 | E2: (서명)
C3: 공 사 | E3: (서명)
C4: 공 무 | E4: (서명)
G6: 사 업 부 | H6: Frontier 사업부 GNP 본부장 | I6: BOC 센터장 | J6: Frontier 사업부장
L8: 본 사 | M8: 담 당 | N8: 검 토 | O8: 검 토
Q11: 구 분 | R11: 확 인
Q12: 품 질 | R12: O O O (인)
Q13: 공 무 | R13: O O O (인)

Sheet DIA-INCH
B3: SIZE
B4: A(mm) | C4: Inch
B5: 8A | C5: 0.25
B6: 15A | C6: 0.5
B7: 20A | C7: 0.75
B8: 25A | C8: 1
B9: 32A | C9: 1.25
B10: 40A | C10: 1.5
B11: 50A | C11: 2
B12: 65A | C12: 2.5
B13: 80A | C13: 3
B14: 100A | C14: 4
B15: 110A | C15: 4
B16: 125A | C16: 5
... B27: 550A | C27: 22
