Workbook
Name _: #REF!
Name _: #REF!
Name _??_??_?C?g??: #REF!
Name _??_??_?C?g??: #REF!
Name ___DAT5: #REF!
Name ___QQ123: #REF!
Name __DAT11: #REF!
Name __DAT21: #REF!
Name __DAT22: #REF!
Name __DAT23: #REF!
Name __DAT24: #REF!
Name __DAT25: #REF!
Name __DAT26: #REF!
Name __DAT27: #REF!
Name __DAT28: #REF!
Name __P3: #REF!
Name __P4: #REF!
Name __P5: #REF!
Name __P6: #REF!
Name __PP1: #REF!
Name _0101__장비_설치공사: #REF!
Name _0201__소화_장비설치공사: #REF!
Name _1: #REF!
Name _1: #REF!
Name _1._PANEL_BD.__LP___1: #REF!
Name _1._옥외배관및장비설치공사: #REF!
Name _1_3_0Crite: #REF!
Name _10A_61: #N/A
Name _10A_62: #N/A
Name _10A_63: #N/A
Name _10A_64: #N/A
Name _10A_65: #N/A
Name _10A_66: #N/A
Name _10A_67: #N/A
Name _10A_68: #N/A
Name _10A_69: #N/A
Name _10A_70: #N/A
Name _10A_71: #N/A
Name _10A_72: #N/A
Name _10A_73: #N/A
Name _10A_74: #N/A
Name _10A_75: #N/A
Name _10A_76: #N/A
Name _10A_77: #N/A
Name _10A_78: #N/A
Name _10A_79: #N/A
Name _10A_80: #N/A
Name _10A_81: #N/A
Name _10A_82: #N/A
Name _10A_83: #N/A
Name _10A_84: #N/A
Name _10A_85: #N/A
Name _10A_86: #N/A
Name _10A_87: #N/A
Name _10A_88: #N/A
Name _10A_89: #N/A
Name _10A_90: #N/A
Name _10B_61: #N/A
Name _10B_62: #N/A
Name _10B_63: #N/A

Sheet 용역청구서 표지
B4: 용 역 청 구 서
B7: P4 Ph4 GAS 1공구 마감공사
C8: S25-004
C14: 2026년 04월
C15: ㈜태성하이텍

Sheet 용역 청구서(갑지)
A1: 용 역 청 구 서
A3: 1 | B3: 공 사 명 | C3: : | D3: ='용역청구서 표지'!$B$7 -> P4 Ph4 GAS 1공구 마감공사 | E3: ='용역청구서 표지'!$C$8 -> S25-004
A4: 2 | B4: 공 종 | C4: : | D4: 외주용역(M/M부분)
A5: 3 | B5: 계 약 금 액 | C5: : | D5: =ROUNDUP(E5,0) -> 520000000 | E5: =집계장!I22 -> 520000000 | F5: (VAT 별도)
A6: 4 | B6: 누 계 기 성 금 액 | C6: : | D6: =ROUNDUP(E6,0) -> 520000000 | E6: =E7+E13 -> 520000000 | F6: (VAT 별도)
A7: 5 | B7: 전 회 기 성 금 액 | C7: : | D7: =ROUNDUP(E7,0) -> 120000000 | E7: =집계장!G22 -> 120000000 | F7: (VAT 별도)
A8: 6 | B8: 금 회 기 성 금 액 | C8: : | D8: =ROUNDUP(E8,0) -> 400000000 | E8: =집계장!F22 -> 400000000 | F8: (VAT 별도)
A9: 7 | B9: 선 금 액 | C9: : | D9: =ROUNDUP(E9,0) -> 0 | E9: =집계장!K20 -> 0 | F9: (VAT 별도)
A10: 8 | B10: 선 금 전 회 공 제 | C10: : | D10: =ROUNDUP(E10,0) -> 0 | E10: =집계장!G20 -> 0 | F10: (VAT 별도)
A11: 9 | B11: 선 금 금 회 공 제 | C11: : | D11: =ROUNDUP(E11,0) -> 0 | E11: =집계장!F20 -> 0 | F11: (VAT 별도)
A12: 10 | B12: 선 금 잔 여 금 액 | C12: : | D12: =ROUNDUP(E12,0) -> 0 | E12: =집계장!L20 -> 0 | F12: (VAT 별도)
A13: 11 | B13: 금 회 청 구 금 액 | C13: : | D13: =ROUNDUP(E13,0) -> 400000000 | E13: =집계장!F22 -> 400000000 | F13: (VAT 별도)
A14: 12 | B14: 잔 여 기 성 금 액 | C14: : | D14: =ROUNDUP(E14,0) -> 0 | E14: =집계장!I16 -> 0 | F14: (VAT 별도)
A15: 13 | B15: 공 정 율 | C15: : | D15: 1
A16: 14 | B16: 청 구 공 사 기 간 | C16: : | D16: 2026. 04. 01 ~ 2026. 04. 30
B18: 위 공사의 하도급에 있어서 공사설계도서, 시방서,품질관리 기준 및 약정대로 시공 되었음을 확인하오며. 만약 귀사의 현장담당의 검사에
B19: 관하여 하자가 발견된 때에는 즉시 실액배상 또는 재 시공할것을 서약하고 이에 기성 청구서를 제출합니다.
B20: 상기건과 관련하여 본 청구 이전까지의 모든 대금은 수령하였음을 확약합니다.
F21: 작 성 일 : 2026 년 04 월 30 일
F23: 상 호 : | G23: ㈜ 태성하이텍
B24: ※첨 부 : 기성내역서 1부. | F24: 주 소 : | G24: 경기도 용인시 처인구 남사면 봉명리 73-1
F25: 대표이사 : | G25: 유 태 진 | I25: (인)
D26: ㈜케이씨이앤씨 귀하

Sheet 용역 내역서(을지)
A1: 용 역 내 역 서
A2: P4 Ph4 GAS 1공구 마감공사 | G2: 단위 : 원
A3: 품 명 | B3: 규 격 | C3: 단위 | D3: 단 가 | E3: 금 회 청 구
E4: 수 량 | F4: 금 액 | G4: 비 고
A5: 고급기술인 | B5: S+ | C5: M/M | D5: 1400000 | E5: 1 | F5: =D5*E5 -> 1400000
A6: 고급기술인 | B6: S | C6: M/M | D6: 1200000 | F6: =D6*E6 -> 0
A7: 중급기술인 | B7: A+ | C7: M/M | D7: 1000000 | F7: =D7*E7 -> 0
A8: 중급기술인 | B8: A | C8: M/M | D8: 900000 | F8: =D8*E8 -> 0
A9: 중급기술인 | B9: B+ | C9: M/M | D9: 800000 | F9: =D9*E9 -> 0
A10: 중급기술인 | B10: B | C10: M/M | D10: 700000 | F10: =D10*E10 -> 0
A11: 초급 기술인 | B11: C | C11: M/M | D11: 600000 | F11: =D11*E11 -> 0
A13: 인센티브 | E13: 0.01 | F13: =SUM(F5:F11)*E13 -> 14000
A15: 총 계 | E15: =SUM(E5:E11) -> 1 | F15: =SUM(F5:F13) -> 1414000

Sheet 내역서(을지)
A1: 용 역 내 역 서
A2: P4 Ph4 GAS 1공구 마감공사 | G2: 단위 : 원
A3: 품 명 | B3: 규 격 | C3: 단위 | D3: 단 가 | E3: 금 회 청 구 | G3: 비 고
E4: 수 량 | F4: 금 액
A5: 고급기술인 | B5: S+ | C5: M/M | D5: 1400000 | E5: 70 | F5: =D5*E5 -> 98000000
A6: 고급기술인 | B6: S | C6: M/M | D6: 1200000 | E6: 40 | F6: =D6*E6 -> 48000000
A7: 중급기술인 | B7: A+ | C7: M/M | D7: 1000000 | E7: 100 | F7: =D7*E7 -> 100000000
A8: 중급기술인 | B8: A | C8: M/M | D8: 900000 | E8: 100 | F8: =D8*E8 -> 90000000
A9: 중급기술인 | B9: B+ | C9: M/M | D9: 800000 | E9: 80 | F9: =D9*E9 -> 64000000
A10: 중급기술인 | B10: B | C10: M/M | D10: 700000 | F10: =D10*E10 -> 0
A11: 초급기술인 | B11: C | C11: M/M | D11: 600000 | F11: =D11*E11 -> 0
A13: 인센티브 | E13: 0 | F13: =SUM(F5:F11)*E13 -> 0
A17: 총 계 | E17: =SUM(E5:E16) -> 390 | F17: =SUM(F5:F16) -> 400000000

Sheet 집계장
A1: ='용역청구서 표지'!$B$7 -> P4 Ph4 GAS 1공구 마감공사
L2: ='용역청구서 표지'!$C$15 -> ㈜태성하이텍
A3: 구분 | B3: 내역 | C3: 단위 | D3: 수량 | E3: 단가 | F3: 합계 | G3: 전회기성 | H3: 금회기성 | I3: 누계기성 | J3: 비 고
A4: 1. 물량 | B4: WELDING POINT | C4: D/I | D4: =SUM('물량 내역서'!$J$5:$J$27) -> 2571.5 | E4: =F4/D4 -> 437000 | F4: =SUM('물량 내역서'!$K$5:$K$27) -> 1123745500 | G4: 2999786500 | H4: =F4 -> 1123745500 | I4: =G4+H4 -> 4123532000
B5: VALVE 설치비 | C5: EA | D5: =SUM('물량 내역서'!$J$28:$J$50) -> 83 | E5: =F5/D5 -> 149698.8 | F5: =SUM('물량 내역서'!$K$28:$K$50) -> 12425000 | G5: 26818750 | H5: =F5 -> 12425000 | I5: =G5+H5 -> 39243750
B6: 인원 실투입 | C6: M/D | D6: ='근로내역 (04월)'!AN129 -> 0 | E6: =F6/D6 -> #DIV/0! | F6: ='근로내역 (04월)'!AP129 -> 0 | G6: 0 | H6: =F6 -> 0 | I6: =G6+H6 -> 0
A7: 2. 기타비용 | C7: 式 | E7: 0 | F7: 586606403 | G7: 0 | H7: =F7 -> 586606403 | I7: =G7+H7 -> 586606403 | J7: 납기준수비 지급
A8: 소 계 | B8: 물량 | F8: =SUM(F4:F7) -> 1722776903 | G8: =SUM(G4:G7) -> 3026605250 | H8: =F8 -> 1722776903 | I8: =G8+H8 -> 4749382153
A9: 3. 노무비 | B9: 직접노무비 | C9: 式 | D9: ='근로내역 (04월)'!AN130 -> 3642.5 | E9: =F9/D9 -> 185052.16 | F9: ='근로내역 (04월)'!AP130 -> 674052500 | G9: 1894886250 | H9: =F9 -> 674052500 | I9: =G9+H9 -> 2568938750
A10: 4. 숙소 및 식대 | B10: 임대료+관리비 | C10: 式 | D10: =SUM(숙소임차료!H4:H8)+SUM(숙소관리비!H4:H8) -> 0 | E10: =F10/D10 -> #DIV/0! | F10: =숙소임차료!I3+숙소관리비!I3 -> 25806300 | G10: 83864823 | H10: =F10 -> 25806300 | I10: =G10+H10 -> 1.0967112e+08 | M10: =+H10+H11 -> 76290480
B11: 식대 | C11: 式 | D11: =SUM(식대비용!G4:G9) -> 0 | E11: =F11/D11 -> #DIV/0! | F11: =식대비용!I3 -> 50484180 | G11: 128529910 | H11: =F11 -> 50484180 | I11: =G11+H11 -> 179014090
A12: 5. 기타 공제 내역 | C12: 式 | E12: 0 | F12: =D12*E12 -> 0 | G12: 0 | H12: =F12 -> 0 | I12: =G12+H12 -> 0
A13: 소 계 | B13: 공제 | F13: =SUM(F9:F12) -> 750342980 | G13: =SUM(G9:G12) -> 2.107281e+09 | H13: =F13 -> 750342980 | I13: =G13+H13 -> 2.857624e+09
A14: 합 계 | B14: 기성 (물량-공제) | F14: =F8-F13 -> 972433923 | G14: =G8-G13 -> 9.1932427e+08 | H14: =F14 -> 972433923 | I14: =G14+H14 -> 1.8917582e+09
A15: 6. 유보금 | B15: 기성금*XX% | C15: 式 | F15: 572400000 | G15: 799272449 | H15: =F15 -> 572400000 | I15: =G15+H15 -> 1371672449
A16: 7. 유보금 차액 | B16: 전회 누계유보금+적자 기성액 | C16: 式 | H16: =F16 -> 0 | I16: =G16+H16 -> 0
A17: 8. NEGO | B17: NEGO | C17: 式 | H17: =F17 -> 0 | I17: =G17+H17 -> 0
A18: 총 계 | B18: 최종기성 | F18: =F14-F15-F16-F17 -> 400033923 | G18: =G14-G15-G16-G17 -> 1.2005182e+08 | H18: =F18 -> 400033923 | I18: =G18+H18 -> 5.2008574e+08
A19: 선급금 | B19: 선수공제 | C19: 式 | G19: 0 | H19: =F19 -> 0 | I19: =G19+H19 -> 0 | K19: 지급 선급금 | L19: 선급금 차액
B20: 단수정리 | C20: 式 | F20: =ROUNDDOWN(F19,-5) -> 0 | H20: =F20 -> 0 | I20: =G20+H20 -> 0 | J20: 만 단위 이하 절사 | K20: 0 | L20: =K20-I20 -> 0
A21: 공제 후 실 지급액 | F21: =F18-F20 -> 400033923 | G21: =G18-G19 -> 1.2005182e+08 | H21: =F21 -> 400033923 | I21: =G21+H21 -> 5.2008574e+08
A22: 세금계산서 기준 | F22: =ROUNDDOWN(F21,-5) -> 400000000 | G22: =ROUNDDOWN(G21,-5) -> 120000000 | H22: =F22 -> 400000000 | I22: =G22+H22 -> 520000000 | J22: 만 단위 이하 절사
A23: TERMS AND CONDITIONS | D23: NOTE
A24: 1. 납 기 : KCEnC 지정 납기로 별도 협의 하에 결정하는 것으로 함.
A25: 2. 지불조건 : KCEnC 지불 조건에 따름.
A26: 3. 유효기간 : 기성 제출일로 부터 30일 이내

Sheet 물량 내역서
A1: 2026년 (04)월 물량 내역서
A2: ='용역청구서 표지'!$B$7 -> P4 Ph4 GAS 1공구 마감공사 | M2: 단위 : 원
A3: 품 명 | B3: 규 격 | C3: 단위 | D3: W/P 수량 | E3: 단 가 | F3: 계 약 내 역 | H3: 전 회 누 계 물 량 | J3: 금 회 물 량 | L3: 누 계 물 량
F4: D/I 수량 | G4: 금액 | H4: D/I 수량 | I4: 금액 | J4: D/I 수량 | K4: 금액 | L4: D/I 수량 | M4: 금액
A5: WEDING POINT | B5: 8A | C5: POINT | D5: 0 | E5: 437000 | F5: =L5 -> 0 | G5: =M5 -> 0 | H5: 0 | I5: 0 | J5: =$D5*'DIA-INCH'!$C5 -> 0 | K5: =$E5*$J5 -> 0 | L5: =H5+J5 -> 0 | M5: =I5+K5 -> 0
A6: WEDING POINT | B6: 15A | C6: POINT | D6: 0 | E6: 437000 | F6: =L6 -> 0 | G6: =M6 -> 0 | H6: 0 | I6: 0 | J6: =$D6*'DIA-INCH'!$C6 -> 0 | K6: =$E6*$J6 -> 0 | L6: =H6+J6 -> 0 | M6: =I6+K6 -> 0
A7: WEDING POINT | B7: 20A | C7: POINT | D7: 0 | E7: 437000 | F7: =L7 -> 0 | G7: =M7 -> 0 | H7: 0 | I7: 0 | J7: =$D7*'DIA-INCH'!$C7 -> 0 | K7: =$E7*$J7 -> 0 | L7: =H7+J7 -> 0 | M7: =I7+K7 -> 0
A8: WEDING POINT | B8: 25A | C8: POINT | D8: 174 | E8: 437000 | F8: =L8 -> 695 | G8: =M8 -> 303715000 | H8: 521 | I8: 227677000 | J8: =$D8*'DIA-INCH'!$C8 -> 174 | K8: =$E8*$J8 -> 76038000 | L8: =H8+J8 -> 695 | M8: =I8+K8 -> 303715000
A9: WEDING POINT | B9: 32A | C9: POINT | D9: 0 | E9: 437000 | F9: =L9 -> 0 | G9: =M9 -> 0 | H9: 0 | I9: 0 | J9: =$D9*'DIA-INCH'!$C9 -> 0 | K9: =$E9*$J9 -> 0 | L9: =H9+J9 -> 0 | M9: =I9+K9 -> 0
A10: WEDING POINT | B10: 40A | C10: POINT | D10: 115 | E10: 437000 | F10: =L10 -> 298.5 | G10: =M10 -> 130444500 | H10: 126 | I10: 55062000 | J10: =$D10*'DIA-INCH'!$C10 -> 172.5 | K10: =$E10*$J10 -> 75382500 | L10: =H10+J10 -> 298.5 | M10: =I10+K10 -> 130444500
A11: WEDING POINT | B11: 50A | C11: POINT | D11: 61 | E11: 437000 | F11: =L11 -> 658 | G11: =M11 -> 287546000 | H11: 536 | I11: 234232000 | J11: =$D11*'DIA-INCH'!$C11 -> 122 | K11: =$E11*$J11 -> 53314000 | L11: =H11+J11 -> 658 | M11: =I11+K11 -> 287546000
A12: WEDING POINT | B12: 65A | C12: POINT | D12: 110 | E12: 437000 | F12: =L12 -> 537.5 | G12: =M12 -> 234887500 | H12: 262.5 | I12: 114712500 | J12: =$D12*'DIA-INCH'!$C12 -> 275 | K12: =$E12*$J12 -> 120175000 | L12: =H12+J12 -> 537.5 | M12: =I12+K12 -> 234887500
A13: WEDING POINT | B13: 80A | C13: POINT | D13: 26 | E13: 437000 | F13: =L13 -> 441 | G13: =M13 -> 192717000 | H13: 363 | I13: 158631000 | J13: =$D13*'DIA-INCH'!$C13 -> 78 | K13: =$E13*$J13 -> 34086000 | L13: =H13+J13 -> 441 | M13: =I13+K13 -> 192717000
A14: WEDING POINT | B14: 100A | C14: POINT | D14: 97 | E14: 437000 | F14: =L14 -> 968 | G14: =M14 -> 423016000 | H14: 580 | I14: 253460000 | J14: =$D14*'DIA-INCH'!$C14 -> 388 | K14: =$E14*$J14 -> 169556000 | L14: =H14+J14 -> 968 | M14: =I14+K14 -> 423016000
A15: WEDING POINT | B15: 110A | C15: POINT | D15: 0 | E15: 437000 | F15: =L15 -> 0 | G15: =M15 -> 0 | H15: 0 | I15: 0 | J15: =$D15*'DIA-INCH'!$C15 -> 0 | K15: =$E15*$J15 -> 0 | L15: =H15+J15 -> 0 | M15: =I15+K15 -> 0
A16: WEDING POINT | B16: 125A | C16: POINT | D16: 138 | E16: 437000 | F16: =L16 -> 2230 | G16: =M16 -> 974510000 | H16: 1540 | I16: 672980000 | J16: =$D16*'DIA-INCH'!$C16 -> 690 | K16: =$E16*$J16 -> 301530000 | L16: =H16+J16 -> 2230 | M16: =I16+K16 -> 974510000
... A21: WEDING POINT | B21: 250A | C21: POINT | D21: 16 | E21: 437000 | F21: =L21 -> 890 | G21: =M21 -> 388930000 | H21: 730 | I21: 319010000 | J21: =$D21*'DIA-INCH'!$C21 -> 160 | K21: =$E21*$J21 -> 69920000 | L21: =H21+J21 -> 890 | M21: =I21+K21 -> 388930000
A22: WEDING POINT | B22: 300A | C22: POINT | D22: 27 | E22: 437000 | F22: =L22 -> 1836 | G22: =M22 -> 802332000 | H22: 1512 | I22: 660744000 | J22: =$D22*'DIA-INCH'!$C22 -> 324 | K22: =$E22*$J22 -> 141588000 | L22: =H22+J22 -> 1836 | M22: =I22+K22 -> 802332000 | N22: =+E23/$E$31 -> 4.9942857
A23: WEDING POINT | B23: 350A | C23: POINT | D23: 0 | E23: 437000 | F23: =L23 -> 0 | G23: =M23 -> 0 | H23: 0 | I23: 0 | J23: =$D23*'DIA-INCH'!$C23 -> 0 | K23: =$E23*$J23 -> 0 | L23: =H23+J23 -> 0 | M23: =I23+K23 -> 0
A24: WEDING POINT | B24: 400A | C24: POINT | D24: 0 | E24: 437000 | F24: =L24 -> 0 | G24: =M24 -> 0 | H24: 0 | I24: 0 | J24: =$D24*'DIA-INCH'!$C24 -> 0 | K24: =$E24*$J24 -> 0 | L24: =H24+J24 -> 0 | M24: =I24+K24 -> 0
A25: WEDING POINT | B25: 450A | C25: POINT | D25: 0 | E25: 437000 | F25: =L25 -> 0 | G25: =M25 -> 0 | H25: 0 | I25: 0 | J25: =$D25*'DIA-INCH'!$C25 -> 0 | K25: =$E25*$J25 -> 0 | L25: =H25+J25 -> 0 | M25: =I25+K25 -> 0
A26: WEDING POINT | B26: 500A | C26: POINT | D26: 0 | E26: 437000 | F26: =L26 -> 0 | G26: =M26 -> 0 | H26: 0 | I26: 0 | J26: =$D26*'DIA-INCH'!$C26 -> 0 | K26: =$E26*$J26 -> 0 | L26: =H26+J26 -> 0 | M26: =I26+K26 -> 0
A27: WEDING POINT | B27: 550A | C27: POINT | D27: 0 | E27: 437000 | F27: =L27 -> 0 | G27: =M27 -> 0 | H27: 0 | I27: 0 | J27: =$D27*'DIA-INCH'!$C27 -> 0 | K27: =$E27*$J27 -> 0 | L27: =H27+J27 -> 0 | M27: =I27+K27 -> 0
A28: VALVE 설치비 | B28: 8A | C28: EA | D28: 0 | E28: =$E$31*'DIA-INCH'!$C5 -> 21875 | F28: =L28 -> 0 | G28: =M28 -> 0 | H28: 0 | I28: 0 | J28: =D28 -> 0 | K28: =$J28*$E28 -> 0 | L28: =H28+J28 -> 0 | M28: =I28+K28 -> 0
A29: VALVE 설치비 | B29: 15A | C29: EA | D29: 0 | E29: =$E$31*'DIA-INCH'!$C6 -> 43750 | F29: =L29 -> 0 | G29: =M29 -> 0 | H29: 0 | I29: 0 | J29: =D29 -> 0 | K29: =$J29*$E29 -> 0 | L29: =H29+J29 -> 0 | M29: =I29+K29 -> 0
A30: VALVE 설치비 | B30: 20A | C30: EA | D30: 0 | E30: =$E$31*'DIA-INCH'!$C7 -> 65625 | F30: =L30 -> 0 | G30: =M30 -> 0 | H30: 0 | I30: 0 | J30: =D30 -> 0 | K30: =$J30*$E30 -> 0 | L30: =H30+J30 -> 0 | M30: =I30+K30 -> 0
A31: VALVE 설치비 | B31: 25A | C31: EA | D31: 48 | E31: 87500 | F31: =L31 -> 122 | G31: =M31 -> 10675000 | H31: 74 | I31: 6475000 | J31: =D31 -> 48 | K31: =$J31*$E31 -> 4200000 | L31: =H31+J31 -> 122 | M31: =I31+K31 -> 10675000 | N31: =+$E$31/E31 -> 1 | O31: =+N31*J31 -> 48
A32: VALVE 설치비 | B32: 32A | C32: EA | D32: 0 | E32: =$E$31*'DIA-INCH'!$C9 -> 109375 | F32: =L32 -> 84 | G32: =M32 -> 9187500 | H32: 84 | I32: 9187500 | J32: =D32 -> 0 | K32: =$J32*$E32 -> 0 | L32: =H32+J32 -> 84 | M32: =I32+K32 -> 9187500 | N32: =+E32/$E$31 -> 1.25 | O32: =+N32*J32 -> 0
A33: VALVE 설치비 | B33: 40A | C33: EA | D33: 18 | E33: =$E$31*'DIA-INCH'!$C10 -> 131250 | F33: =L33 -> 20 | G33: =M33 -> 2625000 | H33: 2 | I33: 262500 | J33: =D33 -> 18 | K33: =$J33*$E33 -> 2362500 | L33: =H33+J33 -> 20 | M33: =I33+K33 -> 2625000 | N33: =+E33/$E$31 -> 1.5 | O33: =+N33*J33 -> 27
A34: VALVE 설치비 | B34: 50A | C34: EA | D34: 3 | E34: =$E$31*'DIA-INCH'!$C11 -> 175000 | F34: =L34 -> 11 | G34: =M34 -> 1925000 | H34: 8 | I34: 1400000 | J34: =D34 -> 3 | K34: =$J34*$E34 -> 525000 | L34: =H34+J34 -> 11 | M34: =I34+K34 -> 1925000 | N34: =+E34/$E$31 -> 2 | O34: =+N34*J34 -> 6
A35: VALVE 설치비 | B35: 65A | C35: EA | D35: 2 | E35: =$E$31*'DIA-INCH'!$C12 -> 218750 | F35: =L35 -> 9 | G35: =M35 -> 1968750 | H35: 7 | I35: 1531250 | J35: =D35 -> 2 | K35: =$J35*$E35 -> 437500 | L35: =H35+J35 -> 9 | M35: =I35+K35 -> 1968750 | N35: =+E35/$E$31 -> 2.5 | O35: =+N35*J35 -> 5
A36: VALVE 설치비 | B36: 80A | C36: EA | D36: 2 | E36: =$E$31*'DIA-INCH'!$C13 -> 262500 | F36: =L36 -> 3 | G36: =M36 -> 787500 | H36: 1 | I36: 262500 | J36: =D36 -> 2 | K36: =$J36*$E36 -> 525000 | L36: =H36+J36 -> 3 | M36: =I36+K36 -> 787500 | N36: =+E36/$E$31 -> 3 | O36: =+N36*J36 -> 6
A37: VALVE 설치비 | B37: 100A | C37: EA | D37: 0 | E37: =$E$31*'DIA-INCH'!$C14 -> 350000 | F37: =L37 -> 0 | G37: =M37 -> 0 | H37: 0 | I37: 0 | J37: =D37 -> 0 | K37: =$J37*$E37 -> 0 | L37: =H37+J37 -> 0 | M37: =I37+K37 -> 0 | O37: =+N37*J37 -> 0
A38: VALVE 설치비 | B38: 110A | C38: EA | D38: 0 | E38: =$E$31*'DIA-INCH'!$C15 -> 350000 | F38: =L38 -> 0 | G38: =M38 -> 0 | H38: 0 | I38: 0 | J38: =D38 -> 0 | K38: =$J38*$E38 -> 0 | L38: =H38+J38 -> 0 | M38: =I38+K38 -> 0 | O38: =+N38*J38 -> 0
A39: VALVE 설치비 | B39: 125A | C39: EA | D39: 10 | E39: =$E$31*'DIA-INCH'!$C16 -> 437500 | F39: =L39 -> 24 | G39: =M39 -> 10500000 | H39: 14 | I39: 6125000 | J39: =D39 -> 10 | K39: =$J39*$E39 -> 4375000 | L39: =H39+J39 -> 24 | M39: =I39+K39 -> 10500000 | N39: =+E39/$E$31 -> 5 | O39: =+N39*J39 -> 50
A40: VALVE 설치비 | B40: 150A | C40: EA | D40: 0 | E40: =$E$31*'DIA-INCH'!$C17 -> 525000 | F40: =L40 -> 0 | G40: =M40 -> 0 | H40: 0 | I40: 0 | J40: =D40 -> 0 | K40: =$J40*$E40 -> 0 | L40: =H40+J40 -> 0 | M40: =I40+K40 -> 0 | O40: =+N40*J40 -> 0
A41: VALVE 설치비 | B41: 175A | C41: EA | D41: 0 | E41: =$E$31*'DIA-INCH'!$C18 -> 612500 | F41: =L41 -> 0 | G41: =M41 -> 0 | H41: 0 | I41: 0 | J41: =D41 -> 0 | K41: =$J41*$E41 -> 0 | L41: =H41+J41 -> 0 | M41: =I41+K41 -> 0 | O41: =+N41*J41 -> 0
A42: VALVE 설치비 | B42: 200A | C42: EA | D42: 0 | E42: =$E$31*'DIA-INCH'!$C19 -> 700000 | F42: =L42 -> 1 | G42: =M42 -> 700000 | H42: 1 | I42: 700000 | J42: =D42 -> 0 | K42: =$J42*$E42 -> 0 | L42: =H42+J42 -> 1 | M42: =I42+K42 -> 700000 | N42: =+E42/$E$31 -> 8 | O42: =+N42*J42 -> 0
A43: VALVE 설치비 | B43: 225A | C43: EA | D43: 0 | E43: =$E$31*'DIA-INCH'!$C20 -> 787500 | F43: =L43 -> 0 | G43: =M43 -> 0 | H43: 0 | I43: 0 | J43: =D43 -> 0 | K43: =$J43*$E43 -> 0 | L43: =H43+J43 -> 0 | M43: =I43+K43 -> 0 | O43: =+N43*J43 -> 0
A44: VALVE 설치비 | B44: 250A | C44: EA | D44: 0 | E44: =$E$31*'DIA-INCH'!$C21 -> 875000 | F44: =L44 -> 1 | G44: =M44 -> 875000 | H44: 1 | I44: 875000 | J44: =D44 -> 0 | K44: =$J44*$E44 -> 0 | L44: =H44+J44 -> 1 | M44: =I44+K44 -> 875000 | N44: =+E44/$E$31 -> 10 | O44: =+N44*J44 -> 0
...

Sheet 근로내역 (04월)
A1: 2026년 ( 04 )월 일용 노무비명세서 | AH1: 현장명 | AM1: ='용역청구서 표지'!$B$7 -> P4 Ph4 GAS 1공구 마감공사
AH2: 현장소장 | AM2: 장규철
AH3: 잡코드 | AM3: ='용역청구서 표지'!$C$8 -> S25-004
A5: 번호 | B5: 성명 | C5: 주민등록번호 | D5: 직종 | E5: 연락처(H.P) | F5: 은행명 | G5: 예금주 | H5: 계좌번호 | I5: 1 | J5: 2 | K5: 3 | L5: 4 | M5: 5 | N5: 6 | O5: 7 | P5: 8 | Q5: 9 | R5: 10 | S5: 11 | T5: 12 | U5: 13 | V5: 14 | W5: 15 | X5: 16 | Y5: 17 | Z5: 18 | AA5: 19 | AB5: 20 | AC5: 21 | AD5: 22 | AE5: 23 | AF5: 24 | AG5: 25 | AH5: 26 | AI5: 27 | AJ5: 28 | AK5: 29 | AL5: 30 | AN5: 공수 | AO5: 단가 | AP5: 총액
A6: 1 | B6: 강경섭 | C6: 781225-1392311 | D6: 공사보조 | E6: 010-2573-6379 | F6: 농협 | G6: 강경섭 | H6: 356-0973-5567-73 | I6: 2 | J6: 2 | K6: 2 | N6: 2 | O6: 2 | P6: 2 | Q6: 2 | R6: 2 | U6: 2 | V6: 2 | W6: 2 | X6: 1.5 | Y6: 2 | AB6: 2 | AC6: 2 | AD6: 2 | AE6: 2 | AF6: 1.75 | AI6: 2 | AJ6: 2 | AK6: 2 | AN6: =SUM(I6:AM6) -> 41.25 | AO6: 230000 | AP6: =AN6*AO6 -> 9487500
A7: 2 | B7: 강동근 | C7: 960219-1406218 | D7: 보통인부 | E7: 010-5555-5945 | F7: 신한 | G7: 강동근 | H7: 110-444-941185 | J7: 1.5 | K7: 1.5 | P7: 1.5 | Q7: 1.5 | R7: 1.5 | S7: 1 | U7: 1.5 | V7: 1.5 | X7: 1.5 | Y7: 1.5 | AB7: 1.5 | AD7: 1 | AE7: 1.5 | AF7: 0.5 | AI7: 1.5 | AJ7: 1.5 | AK7: 1.5 | AN7: =SUM(I7:AM7) -> 23.5 | AO7: 150000 | AP7: =AN7*AO7 -> 3525000
A8: 3 | B8: 강우형 | C8: 000830-3484718 | D8: 보통인부 | E8: 010-7963-4799 | F8: 토스 | G8: 강우형 | H8: 1002-2019-2812 | I8: 0.75 | J8: 1 | K8: 1.5 | L8: 1 | P8: 1.5 | Q8: 1.25 | R8: 1.5 | S8: 0.375 | V8: 1.5 | W8: 1 | X8: 1.5 | Y8: 1.5 | AC8: 1.5 | AD8: 1 | AF8: 1.5 | AI8: 1.5 | AJ8: 1.5 | AK8: 1.5 | AL8: 1.5 | AN8: =SUM(I8:AM8) -> 24.375 | AO8: 150000 | AP8: =AN8*AO8 -> 3656250
A9: 4 | B9: 강원태 | C9: 920818-1240811 | D9: 보통인부 | E9: 010-9205-4684 | F9: 기업 | G9: 강원태 | H9: 186-075475-01-013 | I9: 1.5 | J9: 1.5 | K9: 1.5 | L9: 1 | N9: 1.5 | O9: 1.5 | P9: 1.5 | Q9: 1.5 | R9: 1.5 | S9: 0.5 | U9: 1.5 | V9: 1.5 | W9: 1 | X9: 1.5 | Y9: 1.5 | Z9: 0.5 | AB9: 1.5 | AC9: 1.5 | AD9: 1 | AE9: 1.5 | AF9: 1.5 | AI9: 1.5 | AJ9: 1.5 | AK9: 1.5 | AL9: 1.5 | AN9: =SUM(I9:AM9) -> 34 | AO9: 160000 | AP9: =AN9*AO9 -> 5440000
A10: 5 | B10: 강인수 | C10: 690511-1067622 | D10: 보통인부 | E10: 010-2486-6843 | F10: 부산 | G10: 강인수 | H10: 112-2027-3566-01 | I10: 1.5 | J10: 1.5 | K10: 1.5 | L10: 1 | N10: 1.5 | O10: 1.5 | P10: 1.5 | Q10: 1.5 | R10: 1.5 | S10: 1 | U10: 1.5 | V10: 1.5 | W10: 1 | X10: 1.5 | Y10: 1.5 | AN10: =SUM(I10:AM10) -> 21 | AO10: 160000 | AP10: =AN10*AO10 -> 3360000
A11: 6 | B11: 강희재 | C11: 940122-1491011 | D11: 공사보조 | E11: 010-9127-3784 | F11: 신한 | G11: 강희재 | H11: 110-404-502876 | I11: 1.5 | J11: 1.5 | K11: 1.5 | L11: 1 | N11: 1.5 | O11: 1.5 | P11: 1.5 | Q11: 1.5 | R11: 1.5 | S11: 1 | U11: 1.5 | V11: 1.5 | W11: 1 | X11: 1.5 | Y11: 1.5 | Z11: 1 | AB11: 1.5 | AC11: 1.5 | AD11: 1 | AE11: 1.5 | AF11: 1.5 | AG11: 0.5 | AI11: 1.5 | AJ11: 1.5 | AK11: 1.5 | AL11: 1.75 | AN11: =SUM(I11:AM11) -> 35.75 | AO11: 230000 | AP11: =AN11*AO11 -> 8222500
A12: 7 | B12: 고인걸 | C12: 960204-1106615 | D12: 보통인부 | E12: 010-4088-9424 | F12: 기업 | G12: 고인걸 | H12: 157-194203-01-015 | O12: 0.75 | Q12: 1 | R12: 1.5 | U12: 1.25 | V12: 1.5 | W12: 1 | X12: 1.5 | Y12: 1.5 | AB12: 1.5 | AD12: 1 | AE12: 1.5 | AF12: 0.375 | AG12: 1 | AI12: 1.5 | AJ12: 1.5 | AN12: =SUM(I12:AM12) -> 18.375 | AO12: 160000 | AP12: =AN12*AO12 -> 2940000
A13: 8 | B13: 곽명재 | C13: 800514-1894915 | D13: 용접공 | E13: 010-9232-3215 | F13: 농협 | G13: 곽명재 | H13: 312-0172-2596-61 | I13: 2 | K13: 2 | N13: 2 | O13: 2 | P13: 2 | Q13: 2 | R13: 2 | U13: 2 | W13: 2 | X13: 2 | Y13: 2 | AB13: 2 | AC13: 2 | AD13: 2 | AE13: 2 | AF13: 2 | AI13: 2 | AJ13: 2 | AK13: 2 | AN13: =SUM(I13:AM13) -> 38 | AO13: 240000 | AP13: =AN13*AO13 -> 9120000
A14: 9 | B14: 권혁만 | C14: 770319-1772710 | D14: 보통인부 | E14: 010-9084-0127 | F14: 기업 | G14: 권혁만 | H14: 530-023847-01-014 | I14: 1.5 | J14: 1.5 | K14: 1.5 | AN14: =SUM(I14:AM14) -> 4.5 | AO14: 180000 | AP14: =AN14*AO14 -> 810000
A15: 10 | B15: 김강현 | C15: 910414-1031829 | D15: 보통인부 | E15: 010-6733-7963 | F15: 신한 | G15: 김강현 | H15: 110-302-846665 | I15: 1.5 | J15: 1.5 | K15: 1.5 | L15: 1 | N15: 1.5 | O15: 1.5 | P15: 1.5 | Q15: 1.5 | R15: 1.5 | S15: 0.5 | U15: 1.5 | V15: 1.5 | W15: 1 | X15: 1.5 | Y15: 1.5 | Z15: 1 | AB15: 1.5 | AC15: 1.5 | AD15: 1 | AE15: 1.5 | AF15: 1.5 | AG15: 1 | AI15: 1.5 | AJ15: 1.5 | AK15: 1.5 | AL15: 1.5 | AN15: =SUM(I15:AM15) -> 35.5 | AO15: 190000 | AP15: =AN15*AO15 -> 6745000
A16: 11 | B16: 김경태 | C16: 901120-1588112 | D16: 보통인부 | E16: 010-9538-3223 | F16: 국민 | G16: 김경태 | H16: 99538322358 | I16: 2 | J16: 2 | K16: 2 | N16: 2 | O16: 2 | P16: 2 | Q16: 2 | R16: 2 | U16: 2 | V16: 2 | W16: 2 | X16: 2 | Y16: 2 | AB16: 2 | AC16: 2 | AD16: 2 | AE16: 2 | AF16: 2 | AI16: 2 | AJ16: 2 | AK16: 2 | AN16: =SUM(I16:AM16) -> 42 | AO16: 140000 | AP16: =AN16*AO16 -> 5880000
A17: 12 | B17: 김광동 | C17: 930520-1692511 | D17: 보통인부 | E17: 010-4348-0266 | F17: 국민 | G17: 김광동 | H17: 926102-01-496205 | I17: 1.5 | J17: 1.5 | K17: 1.5 | L17: 0.5 | N17: 1.5 | O17: 1.5 | P17: 1.5 | Q17: 1.5 | R17: 1.5 | S17: 1 | U17: 1.5 | V17: 1.5 | W17: 1 | X17: 1.5 | Y17: 1.5 | Z17: 1 | AB17: 1.5 | AC17: 1.5 | AD17: 1 | AE17: 1.5 | AF17: 1.5 | AI17: 1.5 | AJ17: 1.5 | AK17: 1.5 | AL17: 1.5 | AN17: =SUM(I17:AM17) -> 34.5 | AO17: 150000 | AP17: =AN17*AO17 -> 5175000
A18: 13 | B18: 김귀훈 | C18: 820528-1001326 | D18: 보통인부 | E18: 010-4789-0798 | F18: 신한 | G18: 김귀훈 | H18: 110-290-207123 | I18: 1.5 | J18: 1.5 | K18: 1.5 | N18: 1.5 | P18: 1.5 | Q18: 1.5 | R18: 1.5 | S18: 0.5 | AN18: =SUM(I18:AM18) -> 11 | AO18: 170000 | AP18: =AN18*AO18 -> 1870000
A19: 14 | B19: 김기진 | C19: 871020-1850315 | D19: 보통인부 | E19: 010-6613-2156 | F19: 농협 | G19: 김기진 | H19: 937-12-468305 | I19: 2 | J19: 2 | K19: 2 | N19: 2 | O19: 2 | P19: 2 | Q19: 2 | R19: 2 | U19: 2 | V19: 2 | W19: 2 | X19: 2 | Y19: 2 | AB19: 2 | AC19: 2 | AD19: 2 | AE19: 2 | AF19: 2 | AI19: 2 | AJ19: 2 | AK19: 2 | AN19: =SUM(I19:AM19) -> 42 | AO19: 160000 | AP19: =AN19*AO19 -> 6720000
A20: 15 | B20: 김동민 | C20: 840606-1768018 | D20: 용접공 | E20: 010-3804-2432 | F20: 신한 | G20: 김동민 | H20: 110-408-565589 | I20: 2 | J20: 2 | K20: 2 | N20: 2 | O20: 2 | P20: 2 | Q20: 2 | R20: 2 | U20: 2 | V20: 2 | W20: 2 | X20: 2 | Y20: 2 | AB20: 2 | AC20: 2 | AD20: 2 | AE20: 2 | AF20: 2 | AI20: 2 | AJ20: 2 | AK20: 2 | AN20: =SUM(I20:AM20) -> 42 | AO20: 240000 | AP20: =AN20*AO20 -> 10080000
A21: 16 | B21: 김동열 | C21: 920815-1331213 | D21: 안전보조 | E21: 010-2426-3254 | F21: 새마을 | G21: 김동열 | H21: 9003-2999-8313-9 | I21: 1.5 | J21: 1.5 | K21: 1.5 | N21: 1.5 | O21: 1 | Q21: 1.5 | R21: 1.5 | S21: 1 | U21: 1.5 | V21: 1.5 | W21: 1 | X21: 1.5 | Y21: 1.5 | AB21: 1.5 | AC21: 1.5 | AD21: 1 | AE21: 1.5 | AF21: 1.5 | AG21: 1 | AI21: 1.5 | AJ21: 1.5 | AK21: 1.5 | AL21: 1.5 | AN21: =SUM(I21:AM21) -> 32 | AO21: 210000 | AP21: =AN21*AO21 -> 6720000
A22: 17 | B22: 김동준 | C22: 981003-1558112 | D22: 배관공 | E22: 010-9930-1495 | F22: 카카오 | G22: 김동준 | H22: 3333-16-2421842 | I22: 2 | J22: 2 | K22: 2 | N22: 2 | O22: 2 | P22: 2 | Q22: 2 | R22: 2 | U22: 2 | V22: 2 | W22: 2 | X22: 2 | Y22: 2 | AB22: 2 | AC22: 2 | AD22: 2 | AF22: 2 | AI22: 2 | AJ22: 2 | AN22: =SUM(I22:AM22) -> 38 | AO22: 180000 | AP22: =AN22*AO22 -> 6840000
A23: 18 | B23: 김명수 | C23: 001211-3823418 | D23: 보통인부 | E23: 010-5797-6473 | F23: 국민 | G23: 김명수 | H23: 944502-00-579965 | I23: 1.5 | J23: 1.5 | K23: 1.5 | L23: 1 | N23: 1.5 | P23: 1.5 | Q23: 1.5 | R23: 1.5 | S23: 1 | U23: 1.5 | V23: 1.5 | W23: 1 | X23: 1.5 | Y23: 1.5 | Z23: 1 | AB23: 1.5 | AC23: 1.5 | AD23: 1 | AE23: 1.5 | AF23: 1.5 | AI23: 1.5 | AJ23: 1.5 | AK23: 1.5 | AL23: 1.5 | AN23: =SUM(I23:AM23) -> 33.5 | AO23: 150000 | AP23: =AN23*AO23 -> 5025000
A24: 19 | B24: 김선광 | C24: 880728-1903519 | D24: 용접공 | E24: 010-4560-3710 | F24: 신한 | G24: 김선광 | H24: 110-214-578576 | I24: 2 | J24: 2 | K24: 2 | N24: 2 | O24: 2 | P24: 2 | Q24: 2 | R24: 2 | U24: 2 | V24: 2 | X24: 2 | Y24: 2 | AB24: 2 | AC24: 2 | AD24: 2 | AE24: 2 | AF24: 2 | AI24: 2 | AJ24: 2 | AK24: 2 | AN24: =SUM(I24:AM24) -> 40 | AO24: 240000 | AP24: =AN24*AO24 -> 9600000
A25: 20 | B25: 김성인 | C25: 781127-1567319 | D25: 배관공 | E25: 010-8336-3710 | F25: 우체국 | G25: 김성인 | H25: 503904-02-235538 | I25: 2 | J25: 2 | K25: 2 | N25: 2 | O25: 2 | P25: 2 | Q25: 2 | R25: 2 | U25: 2 | V25: 2 | W25: 2 | X25: 2 | Y25: 2 | AB25: 2 | AD25: 2 | AE25: 2 | AF25: 2 | AI25: 2 | AJ25: 2 | AK25: 2 | AN25: =SUM(I25:AM25) -> 40 | AO25: 230000 | AP25: =AN25*AO25 -> 9200000
A26: 21 | B26: 김성준 | C26: 961016-1179611 | D26: 보통인부 | E26: 010-7732-6708 | F26: 국민 | G26: 김성준 | H26: 166102-04-160013 | I26: 2 | J26: 2 | K26: 2 | N26: 2 | O26: 2 | P26: 2 | Q26: 2 | R26: 2 | U26: 2 | V26: 2 | W26: 2 | X26: 2 | Y26: 2 | AB26: 2 | AC26: 2 | AD26: 2 | AE26: 2 | AF26: 2 | AN26: =SUM(I26:AM26) -> 36 | AO26: 160000 | AP26: =AN26*AO26 -> 5760000
A27: 22 | B27: 김성중 | C27: 911126-1043210 | D27: 보통인부 | E27: 010-3777-9825 | F27: 기업 | G27: 김성중 | H27: 118-149246-01-011 | I27: 1.5 | J27: 1.5 | K27: 1.5 | L27: 1 | N27: 1.5 | O27: 1.5 | P27: 1.5 | Q27: 1.5 | R27: 1.5 | S27: 1 | U27: 1.5 | V27: 1.5 | W27: 1 | X27: 1.5 | Y27: 1.5 | Z27: 1 | AB27: 1.5 | AC27: 1.5 | AD27: 1 | AE27: 1.5 | AG27: 0.5 | AI27: 1.375 | AJ27: 1.5 | AK27: 1.5 | AL27: 1.5 | AN27: =SUM(I27:AM27) -> 33.875 | AO27: 150000 | AP27: =AN27*AO27 -> 5081250
A28: 23 | B28: 김승진 | C28: 751018-1332839 | D28: 안전보조 | E28: 010-4742-4181 | F28: 신한 | G28: 김승진 | H28: 110-338-273904 | I28: 0.75 | J28: 0.25 | K28: 1 | N28: 1.25 | O28: 0.5 | P28: 1.25 | Q28: 1.125 | U28: 1.25 | V28: 1.25 | W28: 1 | X28: 0.875 | Y28: 1.125 | AB28: 1.25 | AC28: 1.375 | AD28: 0.75 | AI28: 1.125 | AJ28: 1.25 | AK28: 1.125 | AL28: 0.75 | AN28: =SUM(I28:AM28) -> 19.25 | AO28: 270000 | AP28: =AN28*AO28 -> 5197500
A29: 24 | B29: 김양근 | C29: 930824-1030929 | D29: 용접공 | E29: 010-2301-4979 | F29: 신한 | G29: 김양근 | H29: 110-349-207217 | J29: 1.5 | K29: 1.5 | L29: 1 | N29: 1.5 | O29: 1 | P29: 1.5 | Q29: 1.25 | R29: 1.5 | U29: 1.5 | V29: 1.5 | W29: 1 | X29: 1.5 | Z29: 1 | AB29: 1.5 | AC29: 1.5 | AD29: 1 | AF29: 1.5 | AI29: 1.5 | AJ29: 1.5 | AK29: 1.5 | AL29: 1.5 | AN29: =SUM(I29:AM29) -> 28.75 | AO29: 240000 | AP29: =AN29*AO29 -> 6900000
A30: 25 | B30: 김영광 | C30: 920704-1860718 | D30: 공무보조 | E30: 010-7704-1777 | F30: 기업 | G30: 김영광 | H30: 580-022392-01-010 | I30: 1.5 | J30: 1.5 | K30: 1.375 | L30: 0.875 | N30: 1.5 | O30: 1.5 | P30: 1.125 | Q30: 1.5 | R30: 1.5 | U30: 1.5 | V30: 1.5 | W30: 1 | X30: 1.375 | Y30: 1.5 | Z30: 0.875 | AB30: 1.5 | AC30: 1.5 | AD30: 1 | AE30: 1.5 | AF30: 1.375 | AG30: 1 | AI30: 1.5 | AJ30: 1.5 | AK30: 1.5 | AL30: 1.25 | AN30: =SUM(I30:AM30) -> 33.75 | AO30: 200000 | AP30: =AN30*AO30 -> 6750000
A31: 26 | B31: 김영철 | C31: 720622-1921415 | D31: 배관공 | E31: 010-3884-4513 | F31: 새마을 | G31: 김영철 | H31: 9003-2504-8199-8 | I31: 1.5 | J31: 1.5 | K31: 1.5 | L31: 1 | N31: 1.5 | O31: 1.5 | P31: 1.5 | Q31: 1.5 | R31: 1.5 | S31: 1 | U31: 1.5 | X31: 1.5 | Y31: 1.5 | AB31: 1.5 | AC31: 1.5 | AD31: 1 | AE31: 1.5 | AF31: 1.5 | AG31: 1 | AI31: 1.5 | AJ31: 1.5 | AK31: 1.5 | AL31: 1.5 | AN31: =SUM(I31:AM31) -> 32.5 | AO31: 210000 | AP31: =AN31*AO31 -> 6825000
A32: 27 | B32: 김윤하 | C32: 860417-1348219 | D32: 배관공 | E32: 010-4807-9031 | F32: 국민 | G32: 김윤하 | H32: 263102-04-214815 | I32: 1.5 | J32: 1.5 | K32: 1.5 | L32: 1 | N32: 1.5 | O32: 1.5 | P32: 1.5 | Q32: 1.5 | R32: 1.5 | S32: 1 | U32: 1.5 | V32: 1.5 | W32: 1 | X32: 1.5 | Y32: 1.5 | Z32: 0.5 | AB32: 1.5 | AC32: 1.5 | AD32: 0.875 | AE32: 1.5 | AF32: 1.5 | AG32: 1 | AI32: 1.5 | AJ32: 1.5 | AK32: 1.5 | AL32: 1.5 | AN32: =SUM(I32:AM32) -> 35.375 | AO32: 210000 | AP32: =AN32*AO32 -> 7428750
A33: 28 | B33: 김재관 | C33: 910814-1661010 | D33: 보통인부 | E33: 010-7532-8645 | F33: 농협 | G33: 김재관 | H33: 645014-56-068999 | O33: 0.75 | Q33: 1 | R33: 1.5 | U33: 1.5 | V33: 1.5 | W33: 1 | X33: 1.5 | Y33: 1.5 | AC33: 1.5 | AD33: 1 | AE33: 1.5 | AF33: 1.5 | AI33: 1.5 | AJ33: 1.5 | AK33: 1.5 | AL33: 0.5 | AN33: =SUM(I33:AM33) -> 20.75 | AO33: 150000 | AP33: =AN33*AO33 -> 3112500
A34: 29 | B34: 김재호 | C34: 740417-1691211 | D34: 배관공 | E34: 010-7903-8334 | F34: 수협 | G34: 김재호 | H34: 0010-2858-8334 | I34: 1.5 | J34: 1.5 | K34: 1.5 | L34: 1 | N34: 1.5 | O34: 1.5 | P34: 1.5 | Q34: 1.5 | R34: 1.5 | S34: 1 | U34: 1.5 | V34: 1.5 | W34: 1 | X34: 1 | Y34: 1.5 | Z34: 1 | AB34: 1.5 | AC34: 1.5 | AD34: 1 | AE34: 1.5 | AF34: 1.5 | AG34: 1 | AI34: 1.5 | AJ34: 1.5 | AK34: 1.5 | AL34: 1 | AN34: =SUM(I34:AM34) -> 35 | AO34: 230000 | AP34: =AN34*AO34 -> 8050000
A35: 30 | B35: 김정천 | C35: 010314-3837113 | D35: 보통인부 | E35: 010-2210-3629 | F35: 카카오 | G35: 김정천 | H35: 3333-14-2904871 | I35: 0.75 | Q35: 1 | R35: 1.5 | S35: 1 | U35: 1.5 | V35: 1.5 | W35: 0.875 | X35: 1.5 | Y35: 1.5 | Z35: 0.875 | AB35: 1.5 | AC35: 1.5 | AD35: 1 | AF35: 1.5 | AG35: 0.875 | AI35: 1.25 | AJ35: 1.25 | AK35: 1.5 | AL35: 0.5 | AN35: =SUM(I35:AM35) -> 22.875 | AO35: 150000 | AP35: =AN35*AO35 -> 3431250
A36: 31 | B36: 김태훈 | C36: 810515-1814611 | D36: 보통인부 | E36: 010-5844-3098 | F36: 농협 | G36: 김태훈 | H36: 793-12-097221 | I36: 1.5 | J36: 1.5 | K36: 1.5 | L36: 1 | N36: 1.5 | O36: 1.5 | P36: 1.5 | Q36: 1.5 | R36: 1.5 | U36: 1.5 | V36: 1.5 | W36: 1 | X36: 1.5 | Y36: 1.5 | AB36: 1.5 | AC36: 1.5 | AD36: 1 | AE36: 1.5 | AF36: 1.5 | AG36: 1 | AI36: 1.5 | AK36: 1.5 | AL36: 1.5 | AN36: =SUM(I36:AM36) -> 32.5 | AO36: 150000 | AP36: =AN36*AO36 -> 4875000
A37: 32 | B37: 김현규 | C37: 921116-1163211 | D37: 공사보조 | E37: 010-9150-0018 | F37: 국민 | G37: 김현규 | H37: 920302-01-333030 | I37: 1.375 | J37: 1.5 | K37: 1.5 | L37: 1 | N37: 1.5 | O37: 1.5 | P37: 1.5 | Q37: 1.5 | R37: 1.5 | U37: 1.5 | V37: 1.5 | W37: 1 | X37: 1.5 | Y37: 1.5 | Z37: 1 | AB37: 1.5 | AC37: 1.5 | AD37: 1 | AE37: 1.5 | AF37: 1.5 | AG37: 1 | AI37: 1.5 | AJ37: 1.5 | AK37: 1.5 | AL37: 1.75 | AN37: =SUM(I37:AM37) -> 35.125 | AO37: 170000 | AP37: =AN37*AO37 -> 5971250
A38: 33 | B38: 김현수 | C38: 960703-1675511 | D38: 보통인부 | E38: 010-7760-4917 | F38: IM뱅크 | G38: 김현수 | H38: 143-13-132971 | I38: 2 | J38: 2 | K38: 2 | N38: 2 | O38: 2 | P38: 2 | Q38: 2 | U38: 2 | V38: 2 | W38: 2 | X38: 2 | Y38: 2 | AC38: 2 | AD38: 2 | AE38: 2 | AF38: 2 | AI38: 2 | AJ38: 2 | AK38: 2 | AN38: =SUM(I38:AM38) -> 38 | AO38: 160000 | AP38: =AN38*AO38 -> 6080000
A39: 34 | B39: 김현재 | C39: 700202-1057315 | D39: 보통인부 | E39: 010-9062-6693 | F39: 국민 | G39: 김현재 | H39: 040001-04-096857 | I39: 1.5 | J39: 1.5 | K39: 1.5 | L39: 0.5 | N39: 1.5 | O39: 1.5 | P39: 1.5 | Q39: 1.5 | R39: 1.5 | U39: 1.5 | V39: 1.5 | W39: 1 | Y39: 1.5 | Z39: 1 | AB39: 1.5 | AC39: 1.5 | AD39: 1 | AE39: 1.5 | AF39: 1.5 | AG39: 0.5 | AI39: 1.5 | AJ39: 1.5 | AK39: 1.5 | AL39: 1.5 | AN39: =SUM(I39:AM39) -> 32.5 | AO39: 160000 | AP39: =AN39*AO39 -> 5200000
A40: 35 | B40: 김형식 | C40: 910612-1075819 | D40: 보통인부 | E40: 010-7340-6771 | F40: 기업 | G40: 김형식 | H40: 052-096995-01-018 | O40: 0.75 | Q40: 1 | R40: 1.5 | U40: 1.5 | V40: 1.5 | W40: 0.5 | X40: 1.5 | Y40: 1.5 | AB40: 1.5 | AC40: 1.5 | AD40: 1 | AE40: 1.5 | AI40: 1.5 | AJ40: 1.5 | AK40: 1.5 | AL40: 1.5 | AN40: =SUM(I40:AM40) -> 21.25 | AO40: 150000 | AP40: =AN40*AO40 -> 3187500
A41: 36 | B41: 남희수 | C41: 741212-1068534 | D41: 보통인부 | E41: 010-8994-9296 | F41: 국민 | G41: 남희수 | H41: 547201-01-029724 | I41: 1.5 | J41: 1.5 | K41: 1.5 | L41: 1 | N41: 1.5 | O41: 1.5 | P41: 1.5 | Q41: 1.5 | R41: 1.5 | S41: 1 | U41: 1.5 | V41: 1.5 | W41: 1 | X41: 1.5 | Y41: 1.5 | Z41: 1 | AB41: 1.5 | AC41: 1.5 | AD41: 1 | AE41: 1.5 | AF41: 1.5 | AG41: 1 | AI41: 1.5 | AJ41: 1.5 | AK41: 1.5 | AL41: 1.5 | AN41: =SUM(I41:AM41) -> 36 | AO41: 160000 | AP41: =AN41*AO41 -> 5760000
...

Sheet 용접기자재
A1: 용접 기자재
A2: No | B2: 구매일 | C2: 구분 | D2: 품명 | E2: 규격 | F2: 거래처명 | G2: 발주수량 | H2: 단가 | I2: 합계 | J2: 비고
I3: =ROUND(SUM(I4:I82),) -> 659700
A4: =ROW()-3 -> 1 | B4: 46121 | C4: 소모성자재 | D4: 알곤용접봉 | E4: [TGC316L.2.4mm,5kg [조선선재]] | F4: 미래공구 | G4: 1 | H4: 89500 | I4: 89500 | L4: 입력해야하는 항목 외 수정 금지
A5: =ROW()-3 -> 2 | B5: 46125 | C5: 소모성자재 | D5: 알곤용접봉 | E5: [TGC316L.2.4mm,5kg [조선선재]] | F5: 미래공구 | G5: 1 | H5: 89500 | I5: 89500 | L5: 입력항목
A6: =ROW()-3 -> 3 | B6: 46128 | C6: 소모성자재 | D6: 텅스텐봉 | E6: [3.2Q,10개,란탄2%,CTX [크레토스]] | F6: 미래공구 | G6: 3 | H6: 95900 | I6: 287700 | L6: 구매일
A7: =ROW()-3 -> 4 | B7: 46135 | C7: 소모성자재 | D7: 알곤용접봉 | E7: [TGC308L.2.4mm,5kg [조선선재]] | F7: 미래공구 | G7: 2 | H7: 71500 | I7: 143000 | L7: 구분
A8: =ROW()-3 -> 5 | B8: 46135 | C8: 소모성자재 | D8: 용접유리 | E8: [2T,투명,CTX [크레토스]] | F8: 미래공구 | G8: 10 | H8: 100 | I8: 1000 | L8: 품명
A9: =ROW()-3 -> 6 | B9: 46139 | C9: 소모성자재 | D9: 알곤토치헤드 | E9: [350A,플렉시블,CT-35F,CTX [크레토스]] | F9: 미래공구 | G9: 5 | H9: 9800 | I9: 49000 | L9: 규격
L10: 거래처명
L11: 발주수량
L12: 단가
L14: ■ 구분은 [소모성자재, 공구, 임대(공구), 안전용품, 비품] 이외 항목은 입력금지

Sheet 배관기자재
A1: 배관 기자재
A2: No | B2: 구매일 | C2: 구분 | D2: 품명 | E2: 규격 | F2: 거래처명 | G2: 발주수량 | H2: 단가 | I2: 합계 | J2: 비고
I3: =ROUND(SUM(I4:I66),) -> 2583673 | L3: 입력해야하는 항목 외 수정 금지
A4: =ROW()-3 -> 1 | B4: 46120 | C4: 소모성자재 | D4: 스포츠백팩 | F4: 11번가 | G4: 100 | H4: 840.90909 | I4: 84090.909 | L4: 입력항목
A5: =ROW()-3 -> 2 | B5: 46133 | C5: 소모성자재 | D5: NBR 코팅장갑 | E5: M | F5: 네이버파이낸셜(주) | G5: 35 | H5: 667.27273 | I5: 23354.545 | L5: 구매일
A6: =ROW()-3 -> 3 | B6: 46141 | C6: 안전용품 | D6: 헤드랜턴 | E6: G016-m5 | F6: 네이버파이낸셜(주) | G6: 5 | H6: 4236.3636 | I6: 21181.818 | L6: 구분
A7: =ROW()-3 -> 4 | B7: 46125 | C7: 소모성자재 | D7: 라인테이프 | E7: 48mm*30m | F7: 마루한길 | G7: 100 | H7: 1800 | I7: 180000 | L7: 품명
A8: =ROW()-3 -> 5 | B8: 46139 | C8: 소모성자재 | D8: 라인테이프 | E8: 48mm*30m | F8: 마루한길 | G8: 50 | H8: 1800 | I8: 90000 | L8: 규격
A9: =ROW()-3 -> 6 | B9: 46113 | C9: 소모성자재 | D9: 낙상경보기 | E9: [200*90 [3S]] | F9: 미래공구 | G9: 20 | H9: 4000 | I9: 80000 | L9: 거래처명
A10: =ROW()-3 -> 7 | B10: 46113 | C10: 소모성자재 | D10: 안전커버 | E10: [마그네틱드릴보호커버,PMD3530용(#104),CTX [UDT]] | F10: 미래공구 | G10: 2 | H10: 6100 | I10: 12200 | L10: 발주수량
A11: =ROW()-3 -> 8 | B11: 46114 | C11: 소모성자재 | D11: 마대 | E11: [수입,정80kg,80L [SW]] | F11: 미래공구 | G11: 200 | H11: 300 | I11: 60000 | L11: 단가
A12: =ROW()-3 -> 9 | B12: 46114 | C12: 소모성자재 | D12: 쇼바 | E12: [BY4-500-20kg(=C1K3500200) [부영]] | F12: 미래공구 | G12: 2 | H12: 12000 | I12: 24000
A13: =ROW()-3 -> 10 | B13: 46114 | C13: 소모성자재 | D13: 쇼바브라켓 | E13: [BY4-BK-1,평자 [부영]] | F13: 미래공구 | G13: 2 | H13: 1700 | I13: 3400 | N13: ■ 구분은 [소모성자재, 공구, 임대(공구), 안전용품, 비품] 이외 항목은 입력금지
A14: =ROW()-3 -> 11 | B14: 46114 | C14: 소모성자재 | D14: 쇼바브라켓 | E14: [BY4-BK-2,ㄱ자 [부영]] | F14: 미래공구 | G14: 2 | H14: 2000 | I14: 4000
A15: =ROW()-3 -> 12 | B15: 46115 | C15: 소모성자재 | D15: 수세미 | E15: [MIGHTY BLUE PAD,녹색 [3M]] | F15: 미래공구 | G15: 10 | H15: 1200 | I15: 12000
A16: =ROW()-3 -> 13 | B16: 46119 | C16: 소모성자재 | D16: 평브러쉬 | E16: [4",스텐 [동양]] | F16: 미래공구 | G16: 30 | H16: 3500 | I16: 105000
A17: =ROW()-3 -> 14 | B17: 46119 | C17: 소모성자재 | D17: 밴드쏘부품 | E17: [손잡이(RB-180II용),6"용 [록스]] | F17: 미래공구 | G17: 1 | H17: 25700 | I17: 25700
A18: =ROW()-3 -> 15 | B18: 46121 | C18: 소모성자재 | D18: 마대 | E18: [PP,신재 [국산/HNS]] | F18: 미래공구 | G18: 20 | H18: 400 | I18: 8000
A19: =ROW()-3 -> 16 | B19: 46121 | C19: 소모성자재 | D19: 밴드쏘고무링 | E19: [R-180용,6" [록스]] | F19: 미래공구 | G19: 3 | H19: 13000 | I19: 39000
A20: =ROW()-3 -> 17 | B20: 46121 | C20: 소모성자재 | D20: 튜브컷터날 | E20: [7.0028(7.0031용) [로덴베르거]] | F20: 미래공구 | G20: 3 | H20: 8400 | I20: 25200
A21: =ROW()-3 -> 18 | B21: 46121 | C21: 소모성자재 | D21: 튜브컷터날 | E21: [TCBC105 [슈퍼]] | F21: 미래공구 | G21: 3 | H21: 10000 | I21: 30000
A22: =ROW()-3 -> 19 | B22: 46122 | C22: 소모성자재 | D22: 포장용비닐 | E22: [700*0.045T*440m [국산]] | F22: 미래공구 | G22: 1 | H22: 89500 | I22: 89500
A23: =ROW()-3 -> 20 | B23: 46122 | C23: 소모성자재 | D23: 컷쏘날 | E23: [S1122BF,철재,바이메탈,5개입 [보쉬]] | F23: 미래공구 | G23: 10 | H23: 19000 | I23: 190000
A24: =ROW()-3 -> 21 | B24: 46122 | C24: 소모성자재 | D24: 컷쏘날 | E24: [S922BF,철재,바이메탈,5개입 [보쉬]] | F24: 미래공구 | G24: 10 | H24: 14500 | I24: 145000
A25: =ROW()-3 -> 22 | B25: 46122 | C25: 소모성자재 | D25: 공캔 | E25: [4L,뚜껑미포함 [수입/SW]] | F25: 미래공구 | G25: 5 | H25: 2500 | I25: 12500
... A51: =ROW()-3 -> 48 | B51: 46142 | C51: 소모성자재 | D51: 실리콘 | E51: [아이보리 [신에츠]] | F51: 미래공구 | G51: 1 | H51: 1700 | I51: 1700
A52: =ROW()-3 -> 49 | B52: 46129 | C52: 소모성자재 | D52: 탭 | F52: 진위공구철물 | G52: 1 | H52: 55000 | I52: 55000
A53: =ROW()-3 -> 50 | B53: 46129 | C53: 소모성자재 | D53: AA 건전지 | F53: 쿠팡㈜ | G53: 2 | H53: 11581.818 | I53: 23163.636
A54: =ROW()-3 -> 51 | B54: 46129 | C54: 소모성자재 | D54: AA 건전지 | F54: 쿠팡㈜ | G54: 3 | H54: 11566.667 | I54: 34700
A55: =ROW()-3 -> 52 | B55: 46139 | C55: 안전용품 | D55: 손전등 라이트 | F55: 쿠팡㈜ | G55: 4 | H55: 6795.4545 | I55: 27181.818

Sheet 숙소임차료
A1: 숙소 임차료
A2: No. | B2: 납부일 | C2: 구분 | D2: 품명 | E2: 주소 | F2: 호수 | G2: 수량 | H2: 사용인원 | I2: 임차료 | J2: 비 고
I3: =SUM(I4:I25) -> 21500000 | L3: 입력해야하는 항목 외 수정 금지
A4: =ROW()-3 -> 1 | B4: 46142 | C4: KC대납 임대료 | D4: 숙소임대료(4월분) | E4: 함박산1길 16 | F4: 301호 | G4: 1 | I4: =800000 -> 800000 | J4: KC 대납 | L4: 납부일
A5: =ROW()-3 -> 2 | B5: 46142 | C5: KC대납 임대료 | D5: 숙소임대료(4월분) | E5: 함박산8길 37 | F5: 302호 | G5: 1 | I5: =800000 -> 800000 | J5: KC 대납 | L5: 구분
A6: =ROW()-3 -> 3 | B6: 46142 | C6: KC대납 임대료 | D6: 숙소임대료(4월분) | E6: 고덕여염11길 85 | F6: 202호 | G6: 1 | I6: =850000 -> 850000 | J6: KC 대납 | L6: 품명
A7: =ROW()-3 -> 4 | B7: 46142 | C7: KC대납 임대료 | D7: 숙소임대료(4월분) | E7: 함박산9길 8-1 | F7: 201호 | G7: 1 | I7: =850000 -> 850000 | J7: KC 대납 | L7: 주소
A8: =ROW()-3 -> 5 | B8: 46142 | C8: KC대납 임대료 | D8: 숙소임대료(4월분) | E8: 함박산12길 8-10 | F8: 301호 | G8: 1 | I8: =950000 -> 950000 | J8: KC 대납 | L8: 호수
A9: =ROW()-3 -> 6 | B9: 46142 | C9: KC대납 임대료 | D9: 숙소임대료(4월분) | E9: 함박산10길 19 | F9: 201호 | G9: 1 | I9: =1000000 -> 1000000 | J9: KC 대납 | L9: 수량
A10: =ROW()-3 -> 7 | B10: 46142 | C10: KC대납 임대료 | D10: 숙소임대료(4월분) | E10: 함박산10길 19 | F10: 301호 | G10: 1 | I10: =1000000 -> 1000000 | J10: KC 대납 | L10: 사용인원
A11: =ROW()-3 -> 8 | B11: 46142 | C11: KC대납 임대료 | D11: 숙소임대료(4월분) | E11: 고덕여염6길 108 | F11: 302호 | G11: 1 | I11: =1000000 -> 1000000 | J11: KC 대납
A12: =ROW()-3 -> 9 | B12: 46142 | C12: KC대납 임대료 | D12: 숙소임대료(4월분) | E12: 고덕여염5길 23-16 | F12: 402호 | G12: 1 | I12: =850000 -> 850000 | J12: KC 대납 | L12: ■ 구분은 [KC대납 임대료 및 임대료] 이외 항목은 입력금지
A13: =ROW()-3 -> 10 | B13: 46142 | C13: KC대납 임대료 | D13: 숙소임대료(4월분) | E13: 고덕여염12길 92 | F13: 202호 | G13: 1 | I13: =850000 -> 850000 | J13: KC 대납
A14: =ROW()-3 -> 11 | B14: 46142 | C14: KC대납 임대료 | D14: 숙소임대료(4월분) | E14: 고덕여염16길 32 | F14: 202호 | G14: 1 | I14: =850000 -> 850000 | J14: KC 대납
A15: =ROW()-3 -> 12 | B15: 46142 | C15: KC대납 임대료 | D15: 숙소임대료(4월분) | E15: 고덕여염 5길 15-10 | F15: 301호 | G15: 1 | I15: =1000000 -> 1000000 | J15: KC 대납
A16: =ROW()-3 -> 13 | B16: 46142 | C16: KC대납 임대료 | D16: 숙소임대료(4월분) | E16: 고덕여염 5길 15-10 | F16: 201호 | G16: 1 | I16: =1000000 -> 1000000 | J16: KC 대납
A17: =ROW()-3 -> 14 | B17: 46142 | C17: KC대납 임대료 | D17: 숙소임대료(4월분) | E17: 고덕여염 5길 15-10 | F17: 202호 | G17: 1 | I17: =1000000 -> 1000000 | J17: KC 대납
A18: =ROW()-3 -> 15 | B18: 46142 | C18: KC대납 임대료 | D18: 숙소임대료(4월분) | E18: 고덕 갈평10길 67 | F18: 201호 | G18: 1 | I18: =950000 -> 950000 | J18: KC 대납
A19: =ROW()-3 -> 16 | B19: 46142 | C19: KC대납 임대료 | D19: 숙소임대료(4월분) | E19: 고덕 갈평10길 102 | F19: 302호 | G19: 1 | I19: =950000 -> 950000 | J19: KC 대납
A20: =ROW()-3 -> 17 | B20: 46142 | C20: KC대납 임대료 | D20: 숙소임대료(4월분) | E20: 고덕 갈평9길 43 | F20: 202호 | G20: 1 | I20: =1000000 -> 1000000 | J20: KC 대납
A21: =ROW()-3 -> 18 | B21: 46142 | C21: KC대납 임대료 | D21: 숙소임대료(4월분) | E21: 함박산2길 32-2 | F21: 201호 | G21: 1 | I21: =1000000 -> 1000000 | J21: KC 대납
A22: =ROW()-3 -> 19 | B22: 46142 | C22: KC대납 임대료 | D22: 숙소임대료(4월분) | E22: 함박산8길 36-2 | F22: 301호 | G22: 1 | I22: =1100000 -> 1100000 | J22: KC 대납
A23: =ROW()-3 -> 20 | B23: 46142 | C23: KC대납 임대료 | D23: 숙소임대료(4월분) | E23: 고덕갈평7길 61 | F23: 301호 | G23: 1 | I23: =1100000 -> 1100000 | J23: KC 대납
A24: =ROW()-3 -> 21 | B24: 46142 | C24: KC대납 임대료 | D24: 숙소임대료(4월분) | E24: 함박산4길 20 | F24: 202호 | G24: 1 | I24: =1100000 -> 1100000 | J24: KC 대납
A25: =ROW()-3 -> 22 | B25: 46142 | C25: KC대납 임대료 | D25: 숙소임대료(4월분) | E25: 함박산1길 51 | F25: 301호 | G25: 1 | I25: =1500000 -> 1500000 | J25: KC 대납

Sheet 숙소관리비
A1: 숙소 관리비
A2: No. | B2: 납부일 | C2: 구분 | D2: 품명 | E2: 주소 | F2: 호수 | G2: 수량 | H2: 사용인원 | I2: 임차료 | J2: 비 고
I3: =SUM(I4:I71) -> 4306300
A4: =ROW()-3 -> 1 | B4: 46142 | C4: 관리비 | D4: 숙소전기요금(4월) | E4: 함박산1길 16 | F4: 301호 | G4: 1 | I4: 31460
A5: =ROW()-3 -> 2 | B5: 46142 | C5: 관리비 | D5: 숙소전기요금(4월) | E5: 함박산8길 37 | F5: 302호 | G5: 1 | I5: 22700
A6: =ROW()-3 -> 3 | B6: 46142 | C6: 관리비 | D6: 숙소전기요금(4월) | E6: 고덕여염11길 85 | F6: 202호 | G6: 1 | I6: 21790
A7: =ROW()-3 -> 4 | B7: 46142 | C7: 관리비 | D7: 숙소전기요금(4월) | E7: 함박산9길 8-1 | F7: 201호 | G7: 1 | I7: 23000
A8: =ROW()-3 -> 5 | B8: 46142 | C8: 관리비 | D8: 숙소전기요금(4월) | E8: 함박산12길 8-10 | F8: 301호 | G8: 1 | I8: 34760
A9: =ROW()-3 -> 6 | B9: 46142 | C9: 관리비 | D9: 숙소전기요금(4월) | E9: 함박산10길 19 | F9: 201호 | G9: 1 | I9: 22760
A10: =ROW()-3 -> 7 | B10: 46142 | C10: 관리비 | D10: 숙소전기요금(4월) | E10: 함박산10길 19 | F10: 301호 | G10: 1 | I10: 21100
A11: =ROW()-3 -> 8 | B11: 46142 | C11: 관리비 | D11: 숙소전기요금(4월) | E11: 고덕여염6길 108 | F11: 302호 | G11: 1 | I11: 33280
A12: =ROW()-3 -> 9 | B12: 46142 | C12: 관리비 | D12: 숙소전기요금(4월) | E12: 고덕여염5길 23-16 | F12: 402호 | G12: 1 | I12: 19070
A13: =ROW()-3 -> 10 | B13: 46142 | C13: 관리비 | D13: 숙소전기요금(4월) | E13: 고덕여염12길 92 | F13: 202호 | G13: 1 | I13: 16500
A14: =ROW()-3 -> 11 | B14: 46142 | C14: 관리비 | D14: 숙소전기요금(4월) | E14: 고덕여염16길 32 | F14: 202호 | G14: 1 | I14: 59750
A15: =ROW()-3 -> 12 | B15: 46142 | C15: 관리비 | D15: 숙소전기요금(4월) | E15: 고덕여염 5길 15-10 | F15: 301호 | G15: 1 | I15: 25110
... A71: =ROW()-3 -> 68 | B71: 46142 | C71: 관리비 | D71: 숙소수도요금(4월) | E71: 함박산1길 51 | F71: 301호 | G71: 1 | I71: 11420

Sheet 식대비용
A1: 식대 비용
A2: No. | B2: 납부일 | C2: 구분 | D2: 품명 | E2: 거래처명 | F2: 수량 | G2: 식수인원 | H2: 단가 | I2: 합 계 | J2: 비 고
I3: =SUM(I4:I10) -> 50484180 | L3: 입력해야하는 항목 외 수정 금지
A4: =ROW()-3 -> 1 | B4: 46137 | C4: KC대납 식대 | D4: 기술인및관리자 (현장 식당) | E4: 태정위드유 주식회사 | F4: 1 | H4: 1675545 | I4: =F4*H4 -> 1675545 | J4: KC 대납 | L4: 입력항목
A5: =ROW()-3 -> 2 | B5: 46137 | C5: KC대납 식대 | D5: 기술인및관리자 (현장 식당) | E5: 다모아한식뷔페 | F5: 85 | H5: 7000 | I5: =F5*H5 -> 595000 | J5: KC 대납 | L5: 납부일
A6: =ROW()-3 -> 3 | B6: 46137 | C6: KC대납 식대 | D6: 기술인및관리자 (현장 식당) | E6: 영미손김밥 | F6: 1 | H6: 1464545 | I6: =F6*H6 -> 1464545 | J6: KC 대납 | L6: 구분
A7: =ROW()-3 -> 4 | B7: 46137 | C7: KC대납 식대 | D7: 기술인및관리자 (현장 식당) | E7: 옛날장터 | F7: 6341 | H7: 7000 | I7: =F7*H7 -> 44387000 | J7: KC 대납 | L7: 품명
A8: =ROW()-3 -> 5 | B8: 46137 | C8: KC대납 식대 | D8: 기술인및관리자 (현장 식당) | E8: 은주네한식뷔페 | F8: 80 | H8: 7000 | I8: =F8*H8 -> 560000 | J8: KC 대납 | L8: 거래처명
A9: =ROW()-3 -> 6 | B9: 46137 | C9: KC대납 식대 | D9: 기술인및관리자 (현장 식당) | E9: 삼성김밥 | F9: 1 | H9: 1487545 | I9: =F9*H9 -> 1487545 | J9: KC 대납 | L9: 수량
A10: =ROW()-3 -> 7 | B10: 46137 | C10: KC대납 식대 | D10: 기술인및관리자 (현장 식당) | E10: 한솥 | F10: 1 | H10: 314545 | I10: =F10*H10 -> 314545 | J10: KC 대납 | L10: 식수인원
A11: =ROW()-3 -> 8 | B11: 46142 | C11: 식대 | E11: 법인카드 | F11: 1 | H11: 2112545 | I11: =F11*H11 -> 2112545 | L11: 단가
L13: ■ 구분은 [KC대납 식대 및 식대] 이외 항목은 입력금지

Sheet 기타비용
A1: 기타 비용
A2: No. | B2: 구매일 | C2: 구분 | D2: 품명 | E2: 거래처명 | F2: 수량 | G2: 단가 | H2: 합계 | I2: 비고
H3: =SUM(H4:H23) -> 3324027.3 | K3: 입력해야하는 항목 외 수정 금지
A4: =ROW()-3 -> 1 | B4: 46114 | C4: 차량유류대 | D4: 85어 5471 포터2 | E4: (주)소모 칠곡주유소 | F4: 1 | G4: 63636.364 | H4: =F4*G4 -> 63636.364 | K4: 입력항목
A5: =ROW()-3 -> 2 | B5: 46118 | C5: 차량유류대 | D5: 85어 5471 포터2 | E5: 남사농업협동조합 | F5: 1 | G5: 63636.364 | H5: =F5*G5 -> 63636.364 | K5: 구매일
A6: =ROW()-3 -> 3 | B6: 46120 | C6: 차량유류대 | D6: 85어 5471 포터2 | E6: (주)소모 칠곡주유소 | F6: 1 | G6: 63636.364 | H6: =F6*G6 -> 63636.364 | K6: 구분
A7: =ROW()-3 -> 4 | B7: 46122 | C7: 차량유류대 | D7: 85어 5471 포터2 | E7: (주)소모 칠곡주유소 | F7: 1 | G7: 63636.364 | H7: =F7*G7 -> 63636.364 | K7: 품명
A8: =ROW()-3 -> 5 | B8: 46122 | C8: 차량유류대 | D8: 85어 5471 포터2 | E8: (주)소모 칠곡주유소 | F8: 1 | G8: 9090.9091 | H8: =F8*G8 -> 9090.9091 | K8: 거래처명
A9: =ROW()-3 -> 6 | B9: 46126 | C9: 차량유류대 | D9: 85어 5471 포터2 | E9: SB새벽주유소 | F9: 1 | G9: 63636.364 | H9: =F9*G9 -> 63636.364 | K9: 수량
A10: =ROW()-3 -> 7 | B10: 46128 | C10: 차량유류대 | D10: 85어 5471 포터2 | E10: (주)소모 칠곡주유소 | F10: 1 | G10: 63636.364 | H10: =F10*G10 -> 63636.364 | K10: 단가
A11: =ROW()-3 -> 8 | B11: 46132 | C11: 차량유류대 | D11: 85어 5471 포터2 | E11: 남사농업협동조합 | F11: 1 | G11: 63636.364 | H11: =F11*G11 -> 63636.364
A12: =ROW()-3 -> 9 | B12: 46134 | C12: 차량유류대 | D12: 85어 5471 포터2 | E12: 남사농업협동조합 | F12: 1 | G12: 63636.364 | H12: =F12*G12 -> 63636.364 | K12: ■ 구분은 [사무용품, 소모품비, 법인카드] 이외 항목은 입력금지
A13: =ROW()-3 -> 10 | B13: 46137 | C13: 차량유류대 | D13: 85어 5471 포터2 | E13: 남사농업협동조합 | F13: 1 | G13: 63636.364 | H13: =F13*G13 -> 63636.364
A14: =ROW()-3 -> 11 | B14: 46140 | C14: 차량유류대 | D14: 85어 5471 포터2 | E14: 남사농업협동조합 | F14: 1 | G14: 63636.364 | H14: =F14*G14 -> 63636.364
A15: =ROW()-3 -> 12 | B15: 46129 | C15: 소모성자재 | D15: 85어5471 엔진오일 | E15: 공임나라 평택진위점 | F15: 1 | G15: 110000 | H15: =F15*G15 -> 110000
A16: =ROW()-3 -> 13 | B16: 46139 | C16: 소모성자재 | D16: 85어 5471 수리비 | E16: 공임나라 평택진위점 | F16: 1 | G16: 1981818.2 | H16: =F16*G16 -> 1981818.2
A17: =ROW()-3 -> 14 | B17: 46136 | C17: 소모성자재 | D17: 복합기 토너 | E17: 위프린트 | F17: 4 | G17: 91125 | H17: =F17*G17 -> 364500
A18: =ROW()-3 -> 15 | B18: 46121 | C18: 소모성자재 | D18: 네임펜 | E18: 쿠팡㈜ | F18: 24 | G18: 727.27273 | H18: =F18*G18 -> 17454.545
A19: =ROW()-3 -> 16 | B19: 46121 | C19: 소모성자재 | D19: 보드마카 | E19: 쿠팡㈜ | F19: 24 | G19: 348.48485 | H19: =F19*G19 -> 8363.6364
A20: =ROW()-3 -> 17 | B20: 46125 | C20: 소모성자재 | D20: A3 코팅지 | E20: 쿠팡㈜ | F20: 6 | G20: 13545.455 | H20: =F20*G20 -> 81272.727
A21: =ROW()-3 -> 18 | B21: 46125 | C21: 소모성자재 | D21: 페인트 마카 | E21: 쿠팡㈜ | F21: 24 | G21: 713.63636 | H21: =F21*G21 -> 17127.273
A22: =ROW()-3 -> 19 | B22: 46135 | C22: 소모성자재 | D22: 네임펜 | E22: 쿠팡㈜ | F22: 24 | G22: 493.93939 | H22: =F22*G22 -> 11854.545
A23: =ROW()-3 -> 20 | B23: 46140 | C23: 비품 | D23: 선풍기 | E23: 쿠팡㈜ | F23: 2 | G23: 43090.909 | H23: =F23*G23 -> 86181.818

Sheet 서명란
B2: 현 장 확 인 | C2: 소 장 | E2: (서명)
C3: 공 사 | E3: (서명)
C4: 공 무 | E4: (서명)
G6: 사 업 부 | H6: Frontier 사업부 GNP 본부장 | I6: BOC 센터장 | J6: Frontier 사업부장
L8: 본 사 | M8: 담 당 | N8: 검 토 | O8: 검 토
Q11: 구 분 | R11: 확 인
Q12: 품 질 | R12: O O O (인)
Q13: 공 무 | R13: O O O (인)

Sheet DIA-INCH
B3: SIZE
B4: A(mm) | C4: Inch
B5: 8A | C5: 0.25
B6: 15A | C6: 0.5
B7: 20A | C7: 0.75
B8: 25A | C8: 1
B9: 32A | C9: 1.25
B10: 40A | C10: 1.5
B11: 50A | C11: 2
B12: 65A | C12: 2.5
B13: 80A | C13: 3
B14: 100A | C14: 4
B15: 110A | C15: 4
B16: 125A | C16: 5
... B27: 550A | C27: 22
