Workbook
Name _: #REF!
Name _: #REF!
Name _: #REF!
Name _??_??_?C?g??: #REF!
Name _??_??_?C?g??: #REF!
Name _??_??_?C?g??: #REF!
Name ___DAT1: [1]원본!#REF!
Name ___DAT1: [1]원본!#REF!
Name ___DAT1: [1]원본!#REF!
Name ___DAT10: [1]원본!#REF!
Name ___DAT10: [1]원본!#REF!
Name ___DAT10: [1]원본!#REF!
Name ___DAT12: [1]원본!#REF!
Name ___DAT12: [1]원본!#REF!
Name ___DAT12: [1]원본!#REF!
Name ___DAT13: [1]원본!#REF!
Name ___DAT13: [1]원본!#REF!
Name ___DAT13: [1]원본!#REF!
Name ___DAT14: [1]원본!#REF!
Name ___DAT14: [1]원본!#REF!
Name ___DAT14: [1]원본!#REF!
Name ___DAT15: [1]원본!#REF!
Name ___DAT15: [1]원본!#REF!
Name ___DAT15: [1]원본!#REF!
Name ___DAT16: [1]원본!#REF!
Name ___DAT16: [1]원본!#REF!
Name ___DAT16: [1]원본!#REF!
Name ___DAT17: [1]원본!#REF!
Name ___DAT17: [1]원본!#REF!
Name ___DAT17: [1]원본!#REF!
Name ___DAT18: [1]원본!#REF!
Name ___DAT18: [1]원본!#REF!
Name ___DAT18: [1]원본!#REF!
Name ___DAT19: [1]원본!#REF!
Name ___DAT19: [1]원본!#REF!
Name ___DAT19: [1]원본!#REF!
Name ___DAT2: [1]원본!#REF!
Name ___DAT2: [1]원본!#REF!
Name ___DAT2: [1]원본!#REF!
Name ___DAT20: [1]원본!#REF!
Name ___DAT20: [1]원본!#REF!
Name ___DAT20: [1]원본!#REF!
Name ___DAT3: [1]원본!#REF!
Name ___DAT3: [1]원본!#REF!
Name ___DAT3: [1]원본!#REF!
Name ___DAT4: [1]원본!#REF!
Name ___DAT4: [1]원본!#REF!
Name ___DAT4: [1]원본!#REF!
Name ___DAT5: #REF!
Name ___DAT5: #REF!
Name ___DAT5: #REF!
Name ___DAT6: [1]원본!#REF!
Name ___DAT6: [1]원본!#REF!
Name ___DAT6: [1]원본!#REF!
Name ___DAT7: [1]원본!#REF!
Name ___DAT7: [1]원본!#REF!
Name ___DAT7: [1]원본!#REF!
Name ___DAT8: [1]원본!#REF!
Name ___DAT8: [1]원본!#REF!
Name ___DAT8: [1]원본!#REF!

Sheet 용역청구서 표지
B4: 용 역 청 구 서
B7: P4 Ph4 GAS 1공구 마감공사
C8: S25-004
C14: 2026년 07월
C15: ㈜리도시스템

Sheet 용역 청구서(갑지)
A1: 용 역 청 구 서
A3: 1 | B3: 공 사 명 | C3: : | D3: ='용역청구서 표지'!$B$7 -> P4 Ph4 GAS 1공구 마감공사 | E3: ='용역청구서 표지'!$C$8 -> S25-004
A4: 2 | B4: 공 종 | C4: : | D4: 외주용역(M/M부분)
A5: 3 | B5: 계 약 금 액 | C5: : | D5: =ROUNDUP(E5,0) -> 510000000 | E5: =집계장!I23 -> 510000000 | F5: (VAT 별도)
A6: 4 | B6: 누 계 기 성 금 액 | C6: : | D6: =ROUNDUP(E6,0) -> 510000000 | E6: =E7+E13 -> 510000000 | F6: (VAT 별도)
A7: 5 | B7: 전 회 기 성 금 액 | C7: : | D7: =ROUNDUP(E7,0) -> 360000000 | E7: =집계장!G23 -> 360000000 | F7: (VAT 별도)
A8: 6 | B8: 금 회 기 성 금 액 | C8: : | D8: =ROUNDUP(E8,0) -> 150000000 | E8: =집계장!F23 -> 150000000 | F8: (VAT 별도)
A9: 7 | B9: 선 금 액 | C9: : | D9: =ROUNDUP(E9,0) -> 0 | E9: =집계장!K21 -> 0 | F9: (VAT 별도)
A10: 8 | B10: 선 금 전 회 공 제 | C10: : | D10: =ROUNDUP(E10,0) -> 0 | E10: =집계장!G21 -> 0 | F10: (VAT 별도)
A11: 9 | B11: 선 금 금 회 공 제 | C11: : | D11: =ROUNDUP(E11,0) -> 0 | E11: =집계장!F21 -> 0 | F11: (VAT 별도)
A12: 10 | B12: 선 금 잔 여 금 액 | C12: : | D12: =ROUNDUP(E12,0) -> 0 | E12: =집계장!L21 -> 0 | F12: (VAT 별도)
A13: 11 | B13: 금 회 청 구 금 액 | C13: : | D13: =ROUNDUP(E13,0) -> 150000000 | E13: =집계장!F23 -> 150000000 | F13: (VAT 별도)
A14: 12 | B14: 잔 여 기 성 금 액 | C14: : | D14: =ROUNDUP(E14,0) -> 0 | E14: 0 | F14: (VAT 별도)
A15: 13 | B15: 공 정 율 | C15: : | D15: 1
A16: 14 | B16: 청 구 공 사 기 간 | C16: : | D16: 2026. 07. 01 ~ 2026. 07. 31
B18: 위 공사의 하도급에 있어서 공사설계도서, 시방서,품질관리 기준 및 약정대로 시공 되었음을 확인하오며. 만약 귀사의 현장담당의 검사에
B19: 관하여 하자가 발견된 때에는 즉시 실액배상 또는 재 시공할것을 서약하고 이에 기성 청구서를 제출합니다.
B20: 상기건과 관련하여 본 청구 이전까지의 모든 대금은 수령하였음을 확약합니다.
F21: 작 성 일 : 2026년 07월 31일
F23: 상 호 : | G23: ㈜ 리도시스템
B24: ※첨 부 : 기성내역서 1부. | F24: 주 소 : | G24: 충남 천안시 직산읍 군서2길 20, 1층
F25: 대표이사 : | G25: 김 용 근 | I25: (인)
D26: ㈜케이씨이앤씨 귀하

Sheet 용역 내역서(을지)
A1: 용 역 내 역 서
A2: P4 Ph4 GAS 1공구 마감공사 | G2: 단위 : 원
A3: 품 명 | B3: 규 격 | C3: 단위 | D3: 단 가 | E3: 금 회 청 구
E4: 수 량 | F4: 금 액 | G4: 비 고
A5: 고급기술인 | B5: S+ | C5: M/M | D5: 1400000 | E5: 1 | F5: =D5*E5 -> 1400000
A6: 고급기술인 | B6: S | C6: M/M | D6: 1200000 | F6: =D6*E6 -> 0
A7: 중급기술인 | B7: A+ | C7: M/M | D7: 1000000 | F7: =D7*E7 -> 0
A8: 중급기술인 | B8: A | C8: M/M | D8: 900000 | F8: =D8*E8 -> 0
A9: 중급기술인 | B9: B+ | C9: M/M | D9: 800000 | F9: =D9*E9 -> 0
A10: 중급기술인 | B10: B | C10: M/M | D10: 700000 | F10: =D10*E10 -> 0
A11: 초급 기술인 | B11: C | C11: M/M | D11: 600000 | F11: =D11*E11 -> 0
A13: 인센티브 | E13: 0.01 | F13: =SUM(F5:F11)*E13 -> 14000
A15: 총 계 | E15: =SUM(E5:E11) -> 1 | F15: =SUM(F5:F13) -> 1414000

Sheet 내역서(을지)
B1: 용 역 내 역 서
B2: P4 Ph4 GAS 1공구 마감공사 | H2: 단위 : 원
B3: 품 명 | C3: 규 격 | D3: 단위 | E3: 단 가 | F3: 금 회 청 구 | H3: 비 고
F4: 수 량 | G4: 금 액
B5: 고급기술인 | C5: S+ | D5: M/M | E5: 1400000 | F5: 25 | G5: =E5*F5 -> 35000000
B6: 고급기술인 | C6: S | D6: M/M | E6: 1200000 | F6: 25 | G6: =E6*F6 -> 30000000
B7: 중급기술인 | C7: A+ | D7: M/M | E7: 1000000 | F7: 25 | G7: =E7*F7 -> 25000000
B8: 중급기술인 | C8: A | D8: M/M | E8: 900000 | F8: 20 | G8: =E8*F8 -> 18000000
B9: 중급기술인 | C9: B+ | D9: M/M | E9: 800000 | F9: 20 | G9: =E9*F9 -> 16000000
B10: 중급기술인 | C10: B | D10: M/M | E10: 700000 | F10: 20 | G10: =E10*F10 -> 14000000
B11: 초급기술인 | C11: C | D11: M/M | E11: 600000 | F11: 20 | G11: =E11*F11 -> 12000000
B13: 인센티브 | F13: 0 | G13: =SUM(G5:G11)*F13 -> 0
B20: 총 계 | F20: =SUM(F5:F11) -> 155 | G20: =SUM(G5:G19) -> 150000000

Sheet 집계장
A1: ='용역청구서 표지'!$B$7 -> P4 Ph4 GAS 1공구 마감공사
L2: ='용역청구서 표지'!$C$15 -> ㈜리도시스템
A3: 구분 | B3: 내역 | C3: 단위 | D3: 수량 | E3: 단가 | F3: 합계 | G3: 전회기성 | H3: 금회기성 | I3: 누계기성 | J3: 비 고
A4: 1. 물량 | B4: WELDING POINT | C4: D/I | D4: =SUM('물량 내역서'!$J$5:$J$27) -> 298 | E4: =F4/D4 -> 435000 | F4: =SUM('물량 내역서'!$K$5:$K$27) -> 129630000 | G4: 3241402500 | H4: =F4 -> 129630000 | I4: =G4+H4 -> 3371032500
B5: VALVE 설치비 | C5: EA | D5: =SUM('물량 내역서'!$J$28:$J$50) -> 168 | E5: =F5/D5 -> 68500 | F5: =SUM('물량 내역서'!$K$28:$K$50) -> 11508000 | G5: 24043500 | H5: =F5 -> 11508000 | I5: =G5+H5 -> 35551500
B6: 인원 실투입 | C6: M/D | F6: ='근로내역 (7월)'!AP106 -> 0 | H6: =F6 -> 0 | I6: =G6+H6 -> 0
A7: 2. 기타비용 | B7: 기타 ISSUE | C7: 式 | D7: 2 | F7: 623565119 | G7: 16188351 | H7: =F7 -> 623565119 | I7: =G7+H7 -> 639753470 | J7: 추가정산 ITEM 지급
B8: 기타지급 운영비 | C8: 式 | D8: 336.375 | E8: 187981 | F8: =ROUND(D8*E8,0) -> 63232109 | G8: 440434784 | H8: =F8 -> 63232109 | I8: =G8+H8 -> 503666893 | J8: 납기준수비 지급
A9: 소 계 | B9: 물량 | F9: =SUM(F4:F8) -> 827935228 | G9: =SUM(G4:G8) -> 3722069135 | H9: =SUM(H4:H8) -> 827935228 | I9: =SUM(I4:I8) -> 4550004363
A10: 3. 노무비 | B10: 직접노무비 | C10: 式 | D10: ='근로내역 (7월)'!AN107 -> 2074.6875 | E10: =F10/D10 -> 187280.31 | F10: ='근로내역 (7월)'!AP107 -> 388548125 | G10: 2985246875 | H10: =F10 -> 388548125 | I10: =G10+H10 -> 3373795000
A11: 4. 숙소 및 식대 | B11: 임대료+관리비 | C11: 式 | D11: =SUM(숙소임차료!H4:H11)+SUM(숙소관리비!H4:H17) -> 41 | E11: =F11/D11 -> 279687.39 | F11: =숙소임차료!I3+숙소관리비!I3 -> 11467183 | G11: 52055358 | H11: =F11 -> 11467183 | I11: =G11+H11 -> 63522541
B12: 식대 | C12: 式 | D12: =SUM(식대비용!G4:G7) -> 84 | E12: =F12/D12 -> 408190.48 | F12: =식대비용!I3 -> 34288000 | G12: 269359818 | H12: =F12 -> 34288000 | I12: =G12+H12 -> 303647818
A13: 5. 기타 공제 내역 | C13: 式
A14: 소 계 | B14: 공제 | F14: =SUM(F10:F12) -> 434303308 | G14: =SUM(G10:G13) -> 3306662051 | H14: =SUM(H10:H13) -> 434303308 | I14: =SUM(I10:I13) -> 3740965359
A15: 합 계 | B15: 기성 (물량-공제) | F15: =F9-F14 -> 393631920 | G15: =G9-G14 -> 415407084 | H15: =H9-H14 -> 393631920 | I15: =I9-I14 -> 809039004
A16: 6. 유보금 | B16: 기성금*XX% | C16: 式 | F16: 243600000 | G16: 55300000 | H16: =F16 -> 243600000 | I16: =G16+H16 -> 298900000
A17: 7. 유보금 차액 | B17: 전회 누계유보금+적자 기성액 | C17: 式 | H17: =F17 -> 0
A18: 8. NEGO | B18: NEGO | C18: 式 | H18: =F18 -> 0 | I18: =G18+H18 -> 0
A19: 총 계 | B19: 최종기성 | F19: =F15-F16+F17+F18 -> 150031920 | G19: =G15-G16+G17+G18 -> 360107084 | H19: =H15-H16+H17+H18 -> 150031920 | I19: =I15-I16+I17+I18 -> 510139004
A20: 선급금 | B20: 선수공제 | C20: 式 | H20: =F20 -> 0 | I20: =G20+H20 -> 0 | K20: 지급 선급금 | L20: 선급금 차액
B21: 단수정리 | C21: 式 | H21: =F21 -> 0 | I21: =G21+H21 -> 0 | J21: 만 단위 이하 절사
A22: 공제 후 실 지급액 | F22: =F19 -> 150031920 | G22: =G19 -> 360107084 | H22: =H19 -> 150031920 | I22: =G22+H22 -> 510139004
A23: 세금계산서 기준 | F23: =ROUNDDOWN(F22,-5) -> 150000000 | G23: 360000000 | H23: =ROUNDDOWN(H22,-5) -> 150000000 | I23: =G23+H23 -> 510000000 | J23: 만 단위 이하 절사
A24: TERMS AND CONDITIONS | D24: NOTE
A25: 1. 납 기 : KCEnC 지정 납기로 별도 협의 하에 결정하는 것으로 함.
A26: 2. 지불조건 : KCEnC 지불 조건에 따름.
A27: 3. 유효기간 : 기성 제출일로 부터 30일 이내

Sheet 물량 내역서
A1: 2026년 (07)월 물량 내역서
A2: ='용역청구서 표지'!$B$7 -> P4 Ph4 GAS 1공구 마감공사 | M2: 단위 : 원
A3: 품 명 | B3: 규 격 | C3: 단위 | D3: W/P 수량 | E3: 단 가 | F3: 계 약 내 역 | H3: 전 회 누 계 물 량 | J3: 금 회 물 량 | L3: 누 계 물 량
F4: D/I 수량 | G4: 금액 | H4: D/I 수량 | I4: 금액 | J4: D/I 수량 | K4: 금액 | L4: D/I 수량 | M4: 금액
A5: WEDING POINT | B5: 8A | C5: POINT | D5: 0 | E5: 435000 | F5: =L5 -> 0 | G5: =M5 -> 0 | I5: =E5*H5 -> 0 | J5: =$D5*'DIA-INCH'!$C5 -> 0 | K5: =$E5*$J5 -> 0 | L5: =H5+J5 -> 0 | M5: =I5+K5 -> 0
A6: WEDING POINT | B6: 15A | C6: POINT | D6: 0 | E6: 435000 | F6: =L6 -> 0 | G6: =M6 -> 0 | I6: =E6*H6 -> 0 | J6: =$D6*'DIA-INCH'!$C6 -> 0 | K6: =$E6*$J6 -> 0 | L6: =H6+J6 -> 0 | M6: =I6+K6 -> 0
A7: WEDING POINT | B7: 20A | C7: POINT | D7: 0 | E7: 435000 | F7: =L7 -> 0 | G7: =M7 -> 0 | I7: =E7*H7 -> 0 | J7: =$D7*'DIA-INCH'!$C7 -> 0 | K7: =$E7*$J7 -> 0 | L7: =H7+J7 -> 0 | M7: =I7+K7 -> 0
A8: WEDING POINT | B8: 25A | C8: POINT | D8: 274 | E8: 435000 | F8: =L8 -> 707 | G8: =M8 -> 307545000 | H8: 433 | I8: =E8*H8 -> 188355000 | J8: =$D8*'DIA-INCH'!$C8 -> 274 | K8: =$E8*$J8 -> 119190000 | L8: =H8+J8 -> 707 | M8: =I8+K8 -> 307545000
A9: WEDING POINT | B9: 32A | C9: POINT | E9: 435000 | F9: =L9 -> 0 | G9: =M9 -> 0 | I9: =E9*H9 -> 0 | J9: =$D9*'DIA-INCH'!$C9 -> 0 | K9: =$E9*$J9 -> 0 | L9: =H9+J9 -> 0 | M9: =I9+K9 -> 0
A10: WEDING POINT | B10: 40A | C10: POINT | D10: 16 | E10: 435000 | F10: =L10 -> 651 | G10: =M10 -> 283185000 | H10: 627 | I10: =E10*H10 -> 272745000 | J10: =$D10*'DIA-INCH'!$C10 -> 24 | K10: =$E10*$J10 -> 10440000 | L10: =H10+J10 -> 651 | M10: =I10+K10 -> 283185000
A11: WEDING POINT | B11: 50A | C11: POINT | E11: 435000 | F11: =L11 -> 650 | G11: =M11 -> 282750000 | H11: 650 | I11: =E11*H11 -> 282750000 | J11: =$D11*'DIA-INCH'!$C11 -> 0 | K11: =$E11*$J11 -> 0 | L11: =H11+J11 -> 650 | M11: =I11+K11 -> 282750000
A12: WEDING POINT | B12: 65A | C12: POINT | E12: 435000 | F12: =L12 -> 792.5 | G12: =M12 -> 344737500 | H12: 792.5 | I12: =E12*H12 -> 344737500 | J12: =$D12*'DIA-INCH'!$C12 -> 0 | K12: =$E12*$J12 -> 0 | L12: =H12+J12 -> 792.5 | M12: =I12+K12 -> 344737500
A13: WEDING POINT | B13: 80A | C13: POINT | E13: 435000 | F13: =L13 -> 228 | G13: =M13 -> 99180000 | H13: 228 | I13: =E13*H13 -> 99180000 | J13: =$D13*'DIA-INCH'!$C13 -> 0 | K13: =$E13*$J13 -> 0 | L13: =H13+J13 -> 228 | M13: =I13+K13 -> 99180000
A14: WEDING POINT | B14: 100A | C14: POINT | E14: 435000 | F14: =L14 -> 1556 | G14: =M14 -> 676860000 | H14: 1556 | I14: =E14*H14 -> 676860000 | J14: =$D14*'DIA-INCH'!$C14 -> 0 | K14: =$E14*$J14 -> 0 | L14: =H14+J14 -> 1556 | M14: =I14+K14 -> 676860000
A15: WEDING POINT | B15: 110A | C15: POINT | E15: 435000 | F15: =L15 -> 0 | G15: =M15 -> 0 | I15: =E15*H15 -> 0 | J15: =$D15*'DIA-INCH'!$C15 -> 0 | K15: =$E15*$J15 -> 0 | L15: =H15+J15 -> 0 | M15: =I15+K15 -> 0
A16: WEDING POINT | B16: 125A | C16: POINT | E16: 435000 | F16: =L16 -> 2645 | G16: =M16 -> 1150575000 | H16: 2645 | I16: =E16*H16 -> 1150575000 | J16: =$D16*'DIA-INCH'!$C16 -> 0 | K16: =$E16*$J16 -> 0 | L16: =H16+J16 -> 2645 | M16: =I16+K16 -> 1150575000
A17: WEDING POINT | B17: 150A | C17: POINT | E17: 435000 | F17: =L17 -> 114 | G17: =M17 -> 49590000 | H17: 114 | I17: =E17*H17 -> 49590000 | J17: =$D17*'DIA-INCH'!$C17 -> 0 | K17: =$E17*$J17 -> 0 | L17: =H17+J17 -> 114 | M17: =I17+K17 -> 49590000
A18: WEDING POINT | B18: 175A | C18: POINT | E18: 435000 | F18: =L18 -> 0 | G18: =M18 -> 0 | I18: =E18*H18 -> 0 | J18: =$D18*'DIA-INCH'!$C18 -> 0 | K18: =$E18*$J18 -> 0 | L18: =H18+J18 -> 0 | M18: =I18+K18 -> 0
A19: WEDING POINT | B19: 200A | C19: POINT | E19: 435000 | F19: =L19 -> 320 | G19: =M19 -> 139200000 | H19: 320 | I19: =E19*H19 -> 139200000 | J19: =$D19*'DIA-INCH'!$C19 -> 0 | K19: =$E19*$J19 -> 0 | L19: =H19+J19 -> 320 | M19: =I19+K19 -> 139200000
A20: WEDING POINT | B20: 225A | C20: POINT | E20: 435000 | F20: =L20 -> 0 | G20: =M20 -> 0 | I20: =E20*H20 -> 0 | J20: =$D20*'DIA-INCH'!$C20 -> 0 | K20: =$E20*$J20 -> 0 | L20: =H20+J20 -> 0 | M20: =I20+K20 -> 0
A21: WEDING POINT | B21: 250A | C21: POINT | E21: 435000 | F21: =L21 -> 50 | G21: =M21 -> 21750000 | H21: 50 | I21: =E21*H21 -> 21750000 | J21: =$D21*'DIA-INCH'!$C21 -> 0 | K21: =$E21*$J21 -> 0 | L21: =H21+J21 -> 50 | M21: =I21+K21 -> 21750000
A22: WEDING POINT | B22: 300A | C22: POINT | E22: 435000 | F22: =L22 -> 36 | G22: =M22 -> 15660000 | H22: 36 | I22: =E22*H22 -> 15660000 | J22: =$D22*'DIA-INCH'!$C22 -> 0 | K22: =$E22*$J22 -> 0 | L22: =H22+J22 -> 36 | M22: =I22+K22 -> 15660000
A23: WEDING POINT | B23: 350A | C23: POINT | E23: 435000 | F23: =L23 -> 0 | G23: =M23 -> 0 | I23: =E23*H23 -> 0 | J23: =$D23*'DIA-INCH'!$C23 -> 0 | K23: =$E23*$J23 -> 0 | L23: =H23+J23 -> 0 | M23: =I23+K23 -> 0
A24: WEDING POINT | B24: 400A | C24: POINT | E24: 435000 | F24: =L24 -> 0 | G24: =M24 -> 0 | I24: =E24*H24 -> 0 | J24: =$D24*'DIA-INCH'!$C24 -> 0 | K24: =$E24*$J24 -> 0 | L24: =H24+J24 -> 0 | M24: =I24+K24 -> 0
A25: WEDING POINT | B25: 450A | C25: POINT | E25: 435000 | F25: =L25 -> 0 | G25: =M25 -> 0 | I25: =E25*H25 -> 0 | J25: =$D25*'DIA-INCH'!$C25 -> 0 | K25: =$E25*$J25 -> 0 | L25: =H25+J25 -> 0 | M25: =I25+K25 -> 0
A26: WEDING POINT | B26: 500A | C26: POINT | E26: 435000 | F26: =L26 -> 0 | G26: =M26 -> 0 | I26: =E26*H26 -> 0 | J26: =$D26*'DIA-INCH'!$C26 -> 0 | K26: =$E26*$J26 -> 0 | L26: =H26+J26 -> 0 | M26: =I26+K26 -> 0
A27: WEDING POINT | B27: 550A | C27: POINT | E27: 435000 | F27: =L27 -> 0 | G27: =M27 -> 0 | I27: =E27*H27 -> 0 | J27: =$D27*'DIA-INCH'!$C27 -> 0 | K27: =$E27*$J27 -> 0 | L27: =H27+J27 -> 0 | M27: =I27+K27 -> 0
A28: VALVE 설치비 | B28: 8A | C28: EA | E28: =$E$31*'DIA-INCH'!$C5 -> 17125 | F28: =L28 -> 0 | G28: =M28 -> 0 | I28: =E28*H28 -> 0 | J28: =D28 -> 0 | K28: =$J28*$E28 -> 0 | L28: =H28+J28 -> 0 | M28: =I28+K28 -> 0
A29: VALVE 설치비 | B29: 15A | C29: EA | E29: =$E$31*'DIA-INCH'!$C6 -> 34250 | F29: =L29 -> 0 | G29: =M29 -> 0 | I29: =E29*H29 -> 0 | J29: =D29 -> 0 | K29: =$J29*$E29 -> 0 | L29: =H29+J29 -> 0 | M29: =I29+K29 -> 0
A30: VALVE 설치비 | B30: 20A | C30: EA | E30: =$E$31*'DIA-INCH'!$C7 -> 51375 | F30: =L30 -> 0 | G30: =M30 -> 0 | I30: =E30*H30 -> 0 | J30: =D30 -> 0 | K30: =$J30*$E30 -> 0 | L30: =H30+J30 -> 0 | M30: =I30+K30 -> 0
A31: VALVE 설치비 | B31: 25A | C31: EA | D31: 168 | E31: 68500 | F31: =L31 -> 174 | G31: =M31 -> 11919000 | H31: 6 | I31: =E31*H31 -> 411000 | J31: =D31 -> 168 | K31: =$J31*$E31 -> 11508000 | L31: =H31+J31 -> 174 | M31: =I31+K31 -> 11919000
A32: VALVE 설치비 | B32: 32A | C32: EA | E32: =$E$31*'DIA-INCH'!$C9 -> 85625 | F32: =L32 -> 24 | G32: =M32 -> 2055000 | H32: 24 | I32: =E32*H32 -> 2055000 | J32: =D32 -> 0 | K32: =$J32*$E32 -> 0 | L32: =H32+J32 -> 24 | M32: =I32+K32 -> 2055000
A33: VALVE 설치비 | B33: 40A | C33: EA | E33: =$E$31*'DIA-INCH'!$C10 -> 102750 | F33: =L33 -> 74 | G33: =M33 -> 7603500 | H33: 74 | I33: =E33*H33 -> 7603500 | J33: =D33 -> 0 | K33: =$J33*$E33 -> 0 | L33: =H33+J33 -> 74 | M33: =I33+K33 -> 7603500
A34: VALVE 설치비 | B34: 50A | C34: EA | E34: =$E$31*'DIA-INCH'!$C11 -> 137000 | F34: =L34 -> 9 | G34: =M34 -> 1233000 | H34: 9 | I34: =E34*H34 -> 1233000 | J34: =D34 -> 0 | K34: =$J34*$E34 -> 0 | L34: =H34+J34 -> 9 | M34: =I34+K34 -> 1233000
A35: VALVE 설치비 | B35: 65A | C35: EA | E35: =$E$31*'DIA-INCH'!$C12 -> 171250 | F35: =L35 -> 0 | G35: =M35 -> 0 | I35: =E35*H35 -> 0 | J35: =D35 -> 0 | K35: =$J35*$E35 -> 0 | L35: =H35+J35 -> 0 | M35: =I35+K35 -> 0
A36: VALVE 설치비 | B36: 80A | C36: EA | E36: =$E$31*'DIA-INCH'!$C13 -> 205500 | F36: =L36 -> 10 | G36: =M36 -> 2055000 | H36: 10 | I36: =E36*H36 -> 2055000 | J36: =D36 -> 0 | K36: =$J36*$E36 -> 0 | L36: =H36+J36 -> 10 | M36: =I36+K36 -> 2055000
A37: VALVE 설치비 | B37: 100A | C37: EA | E37: =$E$31*'DIA-INCH'!$C14 -> 274000 | F37: =L37 -> 10 | G37: =M37 -> 2740000 | H37: 10 | I37: =E37*H37 -> 2740000 | J37: =D37 -> 0 | K37: =$J37*$E37 -> 0 | L37: =H37+J37 -> 10 | M37: =I37+K37 -> 2740000
A38: VALVE 설치비 | B38: 110A | C38: EA | E38: =$E$31*'DIA-INCH'!$C15 -> 274000 | F38: =L38 -> 0 | G38: =M38 -> 0 | I38: =E38*H38 -> 0 | J38: =D38 -> 0 | K38: =$J38*$E38 -> 0 | L38: =H38+J38 -> 0 | M38: =I38+K38 -> 0
A39: VALVE 설치비 | B39: 125A | C39: EA | E39: =$E$31*'DIA-INCH'!$C16 -> 342500 | F39: =L39 -> 22 | G39: =M39 -> 7535000 | H39: 22 | I39: =E39*H39 -> 7535000 | J39: =D39 -> 0 | K39: =$J39*$E39 -> 0 | L39: =H39+J39 -> 22 | M39: =I39+K39 -> 7535000
A40: VALVE 설치비 | B40: 150A | C40: EA | E40: =$E$31*'DIA-INCH'!$C17 -> 411000 | F40: =L40 -> 1 | G40: =M40 -> 411000 | H40: 1 | I40: =E40*H40 -> 411000 | J40: =D40 -> 0 | K40: =$J40*$E40 -> 0 | L40: =H40+J40 -> 1 | M40: =I40+K40 -> 411000
...

Sheet 근로내역 (7월)
A1: 2026년 ( 07 )월 일용 노무비명세서 | AH1: 현장명 | AM1: ='용역청구서 표지'!$B$7 -> P4 Ph4 GAS 1공구 마감공사
AH2: 현장소장 | AM2: 장규철
AH3: 잡코드 | AM3: ='용역청구서 표지'!$C$8 -> S25-004
A5: 번호 | B5: 성명 | C5: 주민등록번호 | D5: 직종 | E5: 연락처(H.P) | F5: 은행명 | G5: 예금주 | H5: 계좌번호 | I5: 1 | J5: 2 | K5: 3 | L5: 4 | M5: 5 | N5: 6 | O5: 7 | P5: 8 | Q5: 9 | R5: 10 | S5: 11 | T5: 12 | U5: 13 | V5: 14 | W5: 15 | X5: 16 | Y5: 17 | Z5: 18 | AA5: 19 | AB5: 20 | AC5: 21 | AD5: 22 | AE5: 23 | AF5: 24 | AG5: 25 | AH5: 26 | AI5: 27 | AJ5: 28 | AK5: 29 | AL5: 30 | AM5: 31 | AN5: 공수 | AO5: 단가 | AP5: 총액
A6: 1 | B6: 국관호 | C6: 860809-1085219 | D6: 배관공 | E6: 010-4121-9703 | F6: 하나 | G6: 국관호 | H6: 265-891181-88607 | I6: 1.5 | J6: 1.5 | K6: 1.5 | L6: 1 | N6: 1.5 | O6: 1.5 | P6: 1.5 | Q6: 1.5 | R6: 1.5 | S6: 1 | U6: 1.5 | V6: 1 | W6: 0.75 | AN6: =SUM(I6:AM6) -> 17.25 | AO6: 230000 | AP6: =AN6*AO6 -> 3967500
A7: 2 | B7: 김경택 | C7: 720611-1031034 | D7: 배관공 | E7: 010-3284-5703 | F7: 우리 | G7: 김경택 | H7: 139-08-042914 | P7: 1 | AN7: =SUM(I7:AM7) -> 1 | AO7: 220000 | AP7: =AN7*AO7 -> 220000
A8: 3 | B8: 김기수 | C8: 670925-1788311 | D8: 보통인부 | E8: 010-8748-6402 | F8: 신한 | G8: 김기수 | H8: 110-395-269363 | I8: 1.5 | J8: 1.5 | K8: 1.5 | L8: 1 | P8: 1.5 | Q8: 1.5 | R8: 1.5 | S8: 1 | W8: 2 | X8: 2 | Y8: 1.5 | Z8: 1 | AB8: 2 | AC8: 2 | AD8: 2 | AE8: 2 | AF8: 1 | AI8: 1 | AJ8: 1 | AK8: 1 | AL8: 1 | AM8: 1 | AN8: =SUM(I8:AM8) -> 31.5 | AO8: 150000 | AP8: =AN8*AO8 -> 4725000
A9: 4 | B9: 김기열 | C9: 980624-1020013 | D9: 보통인부 | E9: 010-5801-1602 | F9: 우리 | G9: 김기열 | H9: 1002-955-483076 | I9: 1.5 | J9: 1.5 | K9: 1.5 | L9: 0.875 | N9: 1.5 | O9: 1.5 | P9: 1.5 | Q9: 1.5 | R9: 1.5 | AN9: =SUM(I9:AM9) -> 12.875 | AO9: 150000 | AP9: =AN9*AO9 -> 1931250
A10: 5 | B10: 김덕주 | C10: 690607-1237512 | D10: 보통인부 | E10: 010-4727-6932 | F10: 우리 | G10: 김덕주 | H10: 1002-641-697004 | I10: 1.5 | J10: 1.5 | K10: 1.5 | N10: 1.5 | O10: 1.5 | P10: 1.5 | Q10: 1.5 | R10: 1.5 | U10: 1.5 | V10: 2 | W10: 2 | X10: 2 | Y10: 1.5 | AB10: 2 | AC10: 2 | AD10: 2 | AE10: 2 | AF10: 1 | AN10: =SUM(I10:AM10) -> 30 | AO10: 160000 | AP10: =AN10*AO10 -> 4800000
A11: 6 | B11: 김도훈 | C11: 921029-1127516 | D11: 용접공 | E11: 010-8506-3952 | F11: 우리 | G11: 김도훈 | H11: 1002-044-533435 | I11: 1.5 | J11: 1.5 | K11: 1.5 | AN11: =SUM(I11:AM11) -> 4.5 | AO11: 240000 | AP11: =AN11*AO11 -> 1080000
A12: 7 | B12: 김도훈 | C12: 811123-1847011 | D12: 배관공 | E12: 010-2780-2424 | F12: 카카오 | G12: 김도훈 | H12: 3333-03-0267267 | U12: 1.5 | V12: 2 | W12: 2 | X12: 2 | Y12: 1.5 | Z12: 1 | AB12: 2 | AC12: 2 | AD12: 2 | AE12: 2 | AF12: 1 | AI12: 1 | AJ12: 1 | AK12: 1 | AL12: 1 | AM12: 1 | AN12: =SUM(I12:AM12) -> 24 | AO12: 200000 | AP12: =AN12*AO12 -> 4800000
A13: 8 | B13: 김동성 | C13: 801129-1670913 | D13: 보통인부 | E13: 010-6479-6009 | F13: 국민 | G13: 김동성 | H13: 645901-04-120115 | I13: 1.5 | K13: 1.5 | L13: 1 | N13: 1.5 | O13: 1.5 | P13: 1.5 | Y13: 1.5 | Z13: 1 | AB13: 2 | AC13: 2 | AD13: 2 | AE13: 2 | AF13: 1 | AI13: 1 | AJ13: 1 | AK13: 1 | AL13: 1 | AM13: 1 | AN13: =SUM(I13:AM13) -> 25 | AO13: 150000 | AP13: =AN13*AO13 -> 3750000
A14: 9 | B14: 김동현 | C14: 940909-1158612 | D14: 용접공 | E14: 010-2576-5831 | F14: 카카오 | G14: 김동현 | H14: 3333-09-0796-912 | I14: 1.5 | J14: 1.375 | K14: 1.5 | N14: 1.5 | O14: 1.5 | P14: 1.5 | AN14: =SUM(I14:AM14) -> 8.875 | AO14: 240000 | AP14: =AN14*AO14 -> 2130000
A15: 10 | B15: 김민준 | C15: 750121-1923111 | D15: 배관공 | E15: 010-3144-7011 | F15: 우리 | G15: 김민준 | H15: 1002-346-022419 | I15: 1.5 | J15: 1.5 | K15: 1 | N15: 0.5 | O15: 1.5 | P15: 1.5 | Q15: 1.5 | R15: 1.5 | S15: 0.5 | U15: 1.5 | V15: 2 | W15: 2 | AN15: =SUM(I15:AM15) -> 16.5 | AO15: 220000 | AP15: =AN15*AO15 -> 3630000
A16: 11 | B16: 김민환 | C16: 750913-1633014 | D16: 안전보조 | E16: 010-4603-8523 | F16: 우리 | G16: 김민환 | H16: 1002-152-759347 | I16: 1.5 | J16: 1.5 | K16: 1.5 | L16: 1 | N16: 1.5 | O16: 1.5 | P16: 1.5 | Q16: 1.5 | R16: 1.5 | S16: 0.5 | U16: 1.5 | V16: 2 | W16: 2 | X16: 1.875 | Y16: 1.5 | Z16: 1 | AB16: 2 | AC16: 2 | AD16: 2 | AN16: =SUM(I16:AM16) -> 29.375 | AO16: 220000 | AP16: =AN16*AO16 -> 6462500
A17: 12 | B17: 김상진 | C17: 681128-1001110 | D17: 용접공 | E17: 010-9027-0494 | F17: 농협 | G17: 김상진 | H17: 011-12-089996 | I17: 1.5 | J17: 1.5 | K17: 1.5 | L17: 1 | N17: 1.5 | O17: 1.5 | P17: 1.5 | Q17: 1.5 | R17: 1.5 | S17: 1 | U17: 1.5 | V17: 2 | W17: 2 | X17: 2 | Y17: 1.3125 | Z17: 1 | AB17: 2 | AC17: 2 | AD17: 2 | AE17: 2 | AF17: 1 | AI17: 1 | AJ17: 1 | AK17: 1 | AL17: 1 | AM17: 1 | AN17: =SUM(I17:AM17) -> 37.8125 | AO17: 240000 | AP17: =AN17*AO17 -> 9075000
A18: 13 | B18: 김선우 | C18: 851017-1063211 | D18: 공사보조 | E18: 010-2290-6800 | F18: 신한 | G18: 김선우 | H18: 110-478-054318 | I18: 1 | J18: 0.25 | K18: 1 | L18: 0.25 | N18: 1 | O18: 1 | P18: 1 | Q18: 0.25 | R18: 1 | S18: 0.375 | U18: 1.25 | V18: 1.25 | W18: 1.5 | Y18: 1.5 | Z18: 0.75 | AB18: 1.75 | AC18: 2 | AD18: 1.75 | AE18: 1.75 | AF18: 0.5 | AN18: =SUM(I18:AM18) -> 21.125 | AO18: 250000 | AP18: =AN18*AO18 -> 5281250
A19: 14 | B19: 김선환 | C19: 850509-1952012 | D19: 보통인부 | E19: 010-7920-3744 | F19: 하나 | G19: 김선환 | H19: 378-890980-95007 | N19: 1 | O19: 1 | P19: 1.5 | Q19: 1.5 | R19: 1.5 | S19: 1 | U19: 1.5 | V19: 2 | W19: 2 | X19: 2 | Y19: 1.5 | Z19: 1 | AB19: 2 | AC19: 2 | AD19: 2 | AE19: 2 | AF19: 1 | AN19: =SUM(I19:AM19) -> 26.5 | AO19: 160000 | AP19: =AN19*AO19 -> 4240000
A20: 15 | B20: 김세광 | C20: 810301-1469515 | D20: 보통인부 | E20: 010-5690-6691 | F20: 우체국 | G20: 김세광 | H20: 104968-02-139365 | N20: 1 | O20: 1 | P20: 1.5 | Q20: 1.5 | R20: 1.5 | S20: 1 | U20: 1.5 | V20: 2 | W20: 2 | X20: 2 | Y20: 1.5 | Z20: 1 | AB20: 2 | AC20: 2 | AD20: 2 | AE20: 2 | AF20: 1 | AN20: =SUM(I20:AM20) -> 26.5 | AO20: 160000 | AP20: =AN20*AO20 -> 4240000
A21: 16 | B21: 김세훈 | C21: 760320-1249920 | D21: 보통인부 | E21: 010-4798-5262 | F21: 새마을 | G21: 김세훈 | H21: 9003-2663-8104-5 | I21: 1.5 | J21: 1.5 | K21: 1.5 | L21: 1 | N21: 1.5 | O21: 1.5 | P21: 1.5 | Q21: 1.5 | R21: 1.5 | U21: 1.5 | W21: 2 | X21: 2 | Y21: 1.5 | AN21: =SUM(I21:AM21) -> 20 | AO21: 150000 | AP21: =AN21*AO21 -> 3000000
A22: 17 | B22: 김슬기 | C22: 860203-1051819 | D22: 보통인부 | E22: 010-2200-4561 | F22: 케이뱅크 | G22: 김슬기 | H22: 100-188-670019 | I22: 1.5 | J22: 1.5 | K22: 1.5 | L22: 1 | N22: 1.5 | O22: 1.5 | P22: 1.5 | Q22: 1.5 | R22: 1.5 | S22: 1 | U22: 1.5 | V22: 2 | W22: 2 | X22: 2 | Y22: 1.5 | Z22: 1 | AB22: 2 | AC22: 2 | AD22: 2 | AE22: 2 | AF22: 1 | AI22: 1 | AJ22: 1 | AK22: 1 | AL22: 1 | AM22: 1 | AN22: =SUM(I22:AM22) -> 38 | AO22: 220000 | AP22: =AN22*AO22 -> 8360000
A23: 18 | B23: 김용호 | C23: 800821-1823911 | D23: 용접공 | E23: 010-8661-3999 | F23: 기업 | G23: 김용호 | H23: 175-057885-01-012 | I23: 1 | J23: 1 | L23: 1 | N23: 1.5 | O23: 1.5 | P23: 1.5 | Q23: 1.5 | R23: 1.5 | S23: 1 | U23: 1.5 | V23: 2 | W23: 2 | X23: 2 | Y23: 1.5 | AB23: 2 | AC23: 2 | AD23: 2 | AE23: 2 | AF23: 1 | AJ23: 1 | AK23: 1 | AL23: 1 | AM23: 1 | AN23: =SUM(I23:AM23) -> 33.5 | AO23: 240000 | AP23: =AN23*AO23 -> 8040000
A24: 19 | B24: 김은규 | C24: 681105-1788311 | D24: 도비공 | E24: 010-3505-9062 | F24: 농협 | G24: 김은규 | H24: 351-0941-0263-23 | I24: 1.5 | J24: 1.5 | K24: 1.5 | N24: 1.5 | O24: 1.5 | P24: 1.5 | Q24: 1.5 | R24: 1.5 | S24: 1 | U24: 1.5 | V24: 2 | W24: 2 | X24: 2 | Y24: 1.5 | Z24: 1 | AB24: 2 | AC24: 2 | AD24: 2 | AE24: 2 | AF24: 1 | AI24: 1 | AJ24: 1 | AK24: 1 | AL24: 1 | AM24: 1 | AN24: =SUM(I24:AM24) -> 37 | AO24: 220000 | AP24: =AN24*AO24 -> 8140000
A25: 20 | B25: 김재홍 | C25: 900222-1069719 | D25: 용접공 | E25: 010-4345-0747 | F25: 하나 | G25: 김재홍 | H25: 354-910259-36007 | I25: 1.5 | J25: 1.5 | K25: 1.5 | L25: 1 | N25: 1.5 | O25: 1.5 | P25: 1.5 | Q25: 1.5 | R25: 1.5 | S25: 1 | AN25: =SUM(I25:AM25) -> 14 | AO25: 240000 | AP25: =AN25*AO25 -> 3360000
A26: 21 | B26: 김정자 | C26: 691109-2581611 | D26: 보통인부 | E26: 010-8347-1457 | F26: 농협 | G26: 김정자 | H26: 352-0865-6722-63 | I26: 1.5 | J26: 1.5 | K26: 1.5 | L26: 1 | N26: 1.5 | O26: 1.5 | P26: 1.5 | Q26: 1.5 | R26: 1.5 | S26: 1 | U26: 1.5 | V26: 2 | W26: 2 | X26: 2 | Y26: 1.5 | Z26: 1 | AB26: 2 | AC26: 2 | AD26: 2 | AE26: 2 | AF26: 1 | AI26: 1 | AJ26: 1 | AK26: 1 | AL26: 1 | AM26: 1 | AN26: =SUM(I26:AM26) -> 38 | AO26: 180000 | AP26: =AN26*AO26 -> 6840000
A27: 22 | B27: 김종현 | C27: 890726-1840614 | D27: 보통인부 | E27: 010-9043-1270 | F27: 농협 | G27: 김종현 | H27: 302-0263-4416-11 | U27: 1 | V27: 2 | W27: 2 | X27: 2 | Y27: 1.5 | Z27: 1 | AB27: 2 | AC27: 2 | AD27: 2 | AE27: 2 | AF27: 1 | AI27: 1 | AJ27: 1 | AK27: 1 | AL27: 1 | AM27: 1 | AN27: =SUM(I27:AM27) -> 23.5 | AO27: 160000 | AP27: =AN27*AO27 -> 3760000
A28: 23 | B28: 노원근 | C28: 820805-1079718 | D28: 용접공 | E28: 010-4125-3419 | F28: 우리 | G28: 노원근 | H28: 1002-533-431855 | I28: 1.5 | J28: 1.5 | K28: 1.5 | L28: 1 | N28: 1.5 | O28: 1.5 | P28: 1.5 | Q28: 1.5 | R28: 1.5 | S28: 1 | U28: 1.5 | V28: 2 | W28: 2 | X28: 2 | Y28: 1.5 | Z28: 1 | AB28: 2 | AC28: 2 | AD28: 2 | AE28: 2 | AF28: 1 | AN28: =SUM(I28:AM28) -> 33 | AO28: 240000 | AP28: =AN28*AO28 -> 7920000
A29: 24 | B29: 민충기 | C29: 890114-1064910 | D29: 배관공 | E29: 010-9418-9998 | F29: 기업 | G29: 민충기 | H29: 074-066516-01-021 | I29: 1.5 | J29: 1.5 | K29: 1.5 | L29: 1 | N29: 1.5 | O29: 1.5 | P29: 1.5 | Q29: 1.5 | R29: 1.5 | U29: 1.5 | V29: 2 | W29: 2 | X29: 2 | Y29: 1.5 | Z29: 1 | AC29: 2 | AD29: 2 | AE29: 2 | AF29: 1 | AN29: =SUM(I29:AM29) -> 30 | AO29: 230000 | AP29: =AN29*AO29 -> 6900000
A30: 25 | B30: 박재형 | C30: 770621-1645910 | D30: 배관공 | E30: 010-7763-2808 | F30: 기업 | G30: 박재형 | H30: 565-077418-01-011 | I30: 1.5 | J30: 1.5 | K30: 1.5 | L30: 1 | N30: 1.5 | O30: 1.5 | P30: 1.5 | Q30: 1.5 | R30: 1.5 | S30: 1 | U30: 1.5 | V30: 2 | W30: 2 | X30: 2 | Y30: 1.5 | AN30: =SUM(I30:AM30) -> 23 | AO30: 210000 | AP30: =AN30*AO30 -> 4830000
A31: 26 | B31: 박재형 | C31: 780518-1114329 | D31: 공사보조 | E31: 010-3849-5386 | F31: 국민 | G31: 박재형 | H31: 669502-04-161746 | I31: 1.5 | J31: 1.5 | K31: 1.5 | L31: 1 | N31: 1.5 | O31: 1.5 | P31: 1.5 | Q31: 1.5 | R31: 1.5 | AN31: =SUM(I31:AM31) -> 13 | AO31: 230000 | AP31: =AN31*AO31 -> 2990000
A32: 27 | B32: 배정인 | C32: 721210-2804318 | D32: 보통인부 | E32: 010-9931-1244 | F32: 농협 | G32: 배정인 | H32: 825114-51-173269 | I32: 1.5 | J32: 1.5 | K32: 1.5 | L32: 1 | N32: 1.5 | O32: 1.5 | P32: 1.5 | Q32: 1.5 | R32: 1.5 | S32: 1 | U32: 1.5 | V32: 2 | W32: 2 | AN32: =SUM(I32:AM32) -> 19.5 | AO32: 145000 | AP32: =AN32*AO32 -> 2827500
A33: 28 | B33: 백승환 | C33: 881116-1169113 | D33: 보통인부 | E33: 010-8295-2124 | F33: 기업 | G33: 백승환 | H33: 507-050714-01-015 | I33: 1.5 | J33: 1.5 | K33: 1.5 | N33: 1.5 | O33: 1.5 | P33: 1.5 | Q33: 1.5 | R33: 1 | S33: 1 | U33: 1.5 | V33: 2 | W33: 2 | X33: 2 | Y33: 1.5 | Z33: 1 | AB33: 2 | AC33: 2 | AD33: 2 | AE33: 2 | AF33: 1 | AI33: 0.5 | AJ33: 1 | AK33: 1 | AL33: 1 | AM33: 0.5 | AN33: =SUM(I33:AM33) -> 35.5 | AO33: 210000 | AP33: =AN33*AO33 -> 7455000
A34: 29 | B34: 서종우 | C34: 870720-1231413 | D34: 배관공 | E34: 010-3385-1756 | F34: 국민 | G34: 서종우 | H34: 543001-01-444969 | I34: 1.5 | K34: 1.5 | L34: 1 | N34: 1.5 | O34: 1.5 | P34: 1.5 | Q34: 1.5 | R34: 1.5 | U34: 1.5 | V34: 2 | W34: 2 | X34: 2 | Y34: 1.5 | AB34: 2 | AC34: 0.5 | AN34: =SUM(I34:AM34) -> 23 | AO34: 180000 | AP34: =AN34*AO34 -> 4140000
A35: 30 | B35: 서지원 | C35: 691219-2347938 | D35: 보통인부 | E35: 010-8926-1379 | F35: 신협 | G35: 서지원 | H35: 132-144-773776 | I35: 1.5 | J35: 1.5 | K35: 1.5 | L35: 1 | N35: 1.5 | O35: 1.5 | P35: 1.5 | AN35: =SUM(I35:AM35) -> 10 | AO35: 140000 | AP35: =AN35*AO35 -> 1400000
A36: 31 | B36: 서혁재 | C36: 950114-1533115 | D36: 보통인부 | E36: 010-4352-0652 | F36: 카카오 | G36: 서혁재 | H36: 3333-05-4978116 | I36: 1.5 | J36: 1.5 | N36: 1.5 | O36: 1.5 | Q36: 1.5 | R36: 1.5 | S36: 1 | U36: 1.5 | V36: 2 | W36: 2 | X36: 2 | AC36: 2 | AD36: 1.875 | AE36: 0.5 | AN36: =SUM(I36:AM36) -> 21.875 | AO36: 150000 | AP36: =AN36*AO36 -> 3281250
A37: 32 | B37: 손동섭 | C37: 700908-1108719 | D37: 배관공 | E37: 010-3842-1987 | F37: 부산 | G37: 손동섭 | H37: 067-12-025943-0 | N37: 1.5 | O37: 1.5 | P37: 1.5 | Q37: 1.5 | R37: 1.5 | U37: 1.5 | V37: 2 | W37: 2 | X37: 2 | Y37: 1.5 | Z37: 1 | AB37: 2 | AC37: 2 | AD37: 2 | AE37: 2 | AF37: 1 | AI37: 1 | AJ37: 1 | AK37: 1 | AL37: 1 | AM37: 1 | AN37: =SUM(I37:AM37) -> 31.5 | AO37: 200000 | AP37: =AN37*AO37 -> 6300000
A38: 33 | B38: 송성준 | C38: 960508-1580519 | D38: 배관공 | E38: 010-3928-7599 | F38: 농협 | G38: 송성준 | H38: 351-0768-8014-63 | P38: 1 | Q38: 1 | R38: 1.5 | S38: 1 | U38: 1.5 | V38: 2 | W38: 2 | X38: 2 | Y38: 1.5 | AB38: 2 | AC38: 2 | AD38: 2 | AE38: 2 | AF38: 1 | AN38: =SUM(I38:AM38) -> 22.5 | AO38: 200000 | AP38: =AN38*AO38 -> 4500000
A39: 34 | B39: 신상오 | C39: 670328-1010118 | D39: 배관공 | E39: 010-4946-2704 | F39: 신한 | G39: 신상오 | H39: 110-177-897619 | I39: 1.5 | J39: 1.5 | K39: 1.5 | L39: 1 | N39: 1.5 | O39: 1.5 | P39: 1.5 | Q39: 1.5 | R39: 1.5 | S39: 1 | U39: 1.5 | V39: 2 | W39: 2 | X39: 2 | Y39: 1.5 | AB39: 2 | AC39: 2 | AD39: 2 | AE39: 2 | AF39: 1 | AN39: =SUM(I39:AM39) -> 32 | AO39: 230000 | AP39: =AN39*AO39 -> 7360000
A40: 35 | B40: 신희철 | C40: 750521-1668918 | D40: 보통인부 | E40: 010-9142-6672 | F40: 농협 | G40: 신희철 | H40: 352-1712-6057-53 | U40: 1 | V40: 2 | W40: 2 | Y40: 1.5 | Z40: 1 | AB40: 2 | AC40: 2 | AN40: =SUM(I40:AM40) -> 11.5 | AO40: 160000 | AP40: =AN40*AO40 -> 1840000
A41: 36 | B41: 심지웅 | C41: 890309-1057416 | D41: 안전보조 | E41: 010-5432-3705 | F41: 기업 | G41: 심지웅 | H41: 682-040341-01-012 | I41: 1 | J41: 1 | K41: 1.5 | N41: 1.5 | O41: 1.5 | P41: 1.5 | Q41: 1.5 | R41: 1.5 | S41: 1 | U41: 1.5 | V41: 2 | W41: 2 | X41: 2 | Y41: 1.5 | Z41: 1 | AB41: 2 | AC41: 2 | AD41: 2 | AE41: 2 | AF41: 1 | AI41: 1 | AJ41: 1 | AK41: 1 | AL41: 1 | AM41: 1 | AN41: =SUM(I41:AM41) -> 36 | AO41: 180000 | AP41: =AN41*AO41 -> 6480000
...

Sheet 숙소임차료
A1: 숙소 임차료
A2: No. | B2: 납부일 | C2: 구분 | D2: 품명 | E2: 주소 | F2: 호수 | G2: 수량 | H2: 사용인원 | I2: 임차료 | J2: 비 고
I3: =SUM(I4:I11) -> 8840323 | L3: 입력해야하는 항목 외 수정 금지
A4: 1 | B4: 46234 | C4: KC대납 임대료 | D4: 숙소임대료(7월분) | E4: 경기도 평택시 고덕여염12길 12 201호 | F4: 201호 | G4: 1 | H4: 4 | I4: 900000 | J4: KC 대납 | L4: 납부일
A5: 2 | B5: 46234 | C5: KC대납 임대료 | D5: 숙소임대료(7월분) | E5: 경기도 평택시 고덕여염8길 71 302호 | F5: 302호 | G5: 1 | H5: 5 | I5: 1290323 | J5: KC 대납 | L5: 구분
A6: 3 | B6: 46229 | C6: KC대납 임대료 | D6: 숙소임대료(7월분) | E6: 경기도 평택시 고덕갈평10길 145, 301호 | F6: 301호 | G6: 1 | H6: 0 | I6: 1425806 | J6: KC 대납 | L6: 품명
A7: 4 | B7: 46234 | C7: KC대납 임대료 | D7: 숙소임대료(7월분) | E7: 경기도 평택시 고덕여염12길 12 301호 | F7: 301호 | G7: 1 | H7: 0 | I7: 900000 | J7: KC 대납 | L7: 주소
A8: 5 | B8: 46234 | C8: KC대납 임대료 | D8: 숙소임대료(7월분) | E8: 경기도 평택시 고덕여염16길 71 302호 | F8: 302호 | G8: 1 | H8: 0 | I8: 900000 | J8: KC 대납 | L8: 호수
A9: 6 | B9: 46234 | C9: KC대납 임대료 | D9: 숙소임대료(7월분) | E9: 경기도 평택시 고덕여염9길 51 814호 | F9: 814호 | G9: 1 | H9: 2 | I9: 550000 | J9: KC 대납 | L9: 수량
A10: 7 | B10: 46234 | C10: KC대납 임대료 | D10: 숙소임대료(7월분) | E10: 경기도 평택시 함박산4길 13 202호 | F10: 202호 | G10: 1 | H10: 5 | I10: 1174194 | J10: KC 대납 | L10: 사용인원
A11: 8 | B11: 46234 | C11: KC대납 임대료 | D11: 숙소임대료(7월분) | E11: 경기도 평택시 고덕갈평7길 19, 302호 | F11: 302호 | G11: 1 | H11: 5 | I11: 1700000 | J11: KC 대납
A12: 9 | B12: 46234 | C12: 임대료 | D12: 창고임대료(7월분) | E12: 경기도 평택시 고덕면 방축리 671-5 1동 | F12: 1동 | G12: 1 | I12: 2000000 | L12: ■ 구분은 [KC대납 임대료 및 임대료] 이외 항목은 입력금지
A13: 10 | B13: 46234 | C13: 임대료 | D13: 사무실임대료(7월분) | E13: 경기도 평택시 모곡동 447-1 | F13: 806,807호 | G13: 1 | I13: 600000

Sheet 숙소관리비
A1: 숙소 관리비
A2: No. | B2: 납부일 | C2: 구분 | D2: 품명 | E2: 주소 | F2: 호수 | G2: 수량 | H2: 사용인원 | I2: 임차료 | J2: 비 고
I3: =SUM(I4:I15) -> 2626860
A4: 1 | B4: 46234 | C4: KC대납 관리비 | D4: 숙소수도세(7월분) | E4: 경기도 평택시 고덕여염12길 12 201호 | F4: 201호 | G4: 1 | H4: 4 | I4: 20210 | J4: KC대납
A5: 2 | B5: 46234 | C5: KC대납 관리비 | D5: 숙소수도세(7월분) | E5: 경기도 평택시 고덕여염12길 12 301호 | F5: 301호 | G5: 1 | H5: 0 | I5: 66890 | J5: KC대납
A6: 3 | B6: 46234 | C6: KC대납 관리비 | D6: 숙소수도세(7월분) | E6: 경기도 평택시 고덕여염16길 71 302호 | F6: 302호 | G6: 1 | H6: 0 | I6: 32310 | J6: KC대납
A7: 4 | B7: 46234 | C7: KC대납 관리비 | D7: 숙소수도세(7월분) | E7: 경기도 평택시 고덕갈평7길 19, 302호 | F7: 302호 | G7: 1 | H7: 5 | I7: 25390 | J7: KC대납
A8: 5 | B8: 46234 | C8: KC대납 관리비 | D8: 숙소관리비(7월분) | E8: 경기도 평택시 고덕여염9길 51 814호 | F8: 814호 | G8: 1 | H8: 2 | I8: 168870 | J8: KC대납
A9: 6 | B9: 46234 | C9: KC대납 관리비 | D9: 숙소전기료(7월분) | E9: 경기도 평택시 고덕여염12길 12 201호 | F9: 201호 | G9: 1 | H9: 4 | I9: 58220 | J9: KC대납
A10: 7 | B10: 46234 | C10: KC대납 관리비 | D10: 숙소전기료(7월분) | E10: 경기도 평택시 고덕여염12길 12 301호 | F10: 301호 | G10: 1 | H10: 0 | I10: 108340 | J10: KC대납
A11: 8 | B11: 46234 | C11: KC대납 관리비 | D11: 숙소전기료(7월분) | E11: 경기도 평택시 고덕여염16길 71 302호 | F11: 302호 | G11: 1 | H11: 0 | I11: 42710 | J11: KC대납
A12: 9 | B12: 46234 | C12: KC대납 관리비 | D12: 숙소전기료(7월분) | E12: 경기도 평택시 고덕갈평7길 19, 302호 | F12: 302호 | G12: 1 | H12: 5 | I12: 53370 | J12: KC대납
A13: 10 | B13: 46229 | C13: KC대납 퇴실정산비 | D13: 숙소 퇴실 | E13: 경기도 평택시 고덕갈평10길 145, 301호 | F13: 301호 | G13: 1 | H13: 0 | I13: 639580 | J13: KC대납
A14: 11 | B14: 46234 | C14: KC대납 퇴실정산비 | D14: 숙소 퇴실 | E14: 경기도 평택시 고덕여염12길 12 301호 | F14: 301호 | G14: 1 | H14: 0 | I14: 849990 | J14: KC대납
A15: 12 | B15: 46234 | C15: KC대납 퇴실정산비 | D15: 숙소 퇴실 | E15: 경기도 평택시 고덕여염16길 71 302호 | F15: 302호 | G15: 1 | H15: 0 | I15: 560980 | J15: KC대납
A16: 15 | B16: 46234 | C16: 관리비 | D16: 사무실관리비(7월분) | E16: 경기도 평택시 모곡동 447-1 | F16: 806호 | G16: 1 | I16: 236470
A17: 16 | B17: 46234 | C17: 관리비 | D17: 사무실관리비(7월분) | E17: 경기도 평택시 모곡동 447-1 | F17: 807호 | G17: 1 | I17: 164920

Sheet 식대비용
A1: 식대 비용
A2: No. | B2: 납부일 | C2: 구분 | D2: 품명 | E2: 거래처명 | F2: 수량 | G2: 식수인원 | H2: 단가 | I2: 합 계 | J2: 비 고
I3: =SUM(I4:I9) -> 34288000 | L3: 입력해야하는 항목 외 수정 금지
A4: 1 | B4: 46234 | C4: KC대납 식대 | D4: 기술인및관리자 (현장 식당) | E4: 다모아 한식뷔페 | F4: 1 | G4: 84 | H4: 34288000 | I4: =H4 -> 34288000 | L4: 입력항목
L5: 납부일
L6: 구분
L7: 품명
L8: 거래처명
L9: 수량
L10: 식수인원
L11: 단가
L13: ■ 구분은 [KC대납 식대 및 식대] 이외 항목은 입력금지

Sheet 기타비용
A1: 기타 비용
A2: No. | B2: 구매일 | C2: 구분 | D2: 품명 | E2: 거래처명 | F2: 수량 | G2: 단가 | H2: 합계 | I2: 비고
H3: =SUM(H4:H7) -> 6153764 | K3: 입력해야하는 항목 외 수정 금지
A4: 1 | B4: 46234 | C4: 사무용품 | D4: 현장서류 및 문구류 | E4: 오피스플랜 | F4: 1 | G4: 267570 | H4: =G4 -> 267570 | K4: 입력항목
A5: 2 | B5: 46234 | C5: 소모품비 | D5: 현장 기자재 | E5: 세일종합공구 | F5: 1 | G5: 748000 | H5: =G5 -> 748000 | K5: 납부일
A6: 3 | B6: 46234 | C6: 소모품비 | D6: 현장 기자재 (기타) | E6: 영수증 | H6: =G6 -> 0 | K6: 구분
A7: 4 | B7: 46234 | C7: 법인카드 | D7: 법인카드 사용료 | E7: BC카드 | F7: 1 | G7: 5138194 | H7: =G7 -> 5138194 | K7: 품명
K8: 거래처명
K9: 수량
K10: 식수인원
K11: 단가
K13: ■ 구분은 [KC대납 식대 및 식대] 이외 항목은 입력금지

Sheet LOSS
B5: ■ 평택 P4_Ph4 GAS 1공구_FAB LOSS 기록대장_리도 | R5: 25년10월 | S5: 25년11월 | T5: 25년12월 | U5: 26년01월 | V5: 26년02월 | W5: 26년03월 | X5: 26년04월 | Y5: 26년05월 | Z5: 26년06월 | AA5: 26년07월
P6: 작성일 : 2025-12--18 | R6: 193438 | S6: 195968
B7: No. | C7: 공구 | D7: 업체 | E7: 구분 | F7: 내용 | G7: 작업구간 | H7: 날짜 | I7: 시간 | J7: 분 | K7: LOSS M/D | L7: 작업인원 | M7: M/D 합계 | N7: 월 평균단가 | O7: LOSS 금액 | P7: 비 고
B8: 1 | C8: FAB | D8: 리도 | E8: 발주처 요청사항 | F8: 중대재해발생으로 인한 발주처 요청으로 자체 특별교육 및 작업 중단으로 인한 양중 차대 비용 | G8: 현장 전 구간 | H8: 45959 | I8: 09:00~11:00 | J8: 120 | K8: 0.25 | L8: 19 | M8: =K8*L8 -> 4.75 | N8: 193438 | O8: =M8*N8 -> 918830.5 | Q8: 25년 10월
B9: 2 | C9: FAB | D9: 리도 | E9: 발주처 요청사항 | F9: 중대재해발생으로 인한 발주처 요청으로 기술인 특별교육 | G9: 현장 안전교육장, KC 안전교육장 | H9: 25-10-30~31 | I9: 30일12:00~14:00,15:00~17:00 31일07:00~09:00,10:00~12:00 | J9: 960 | K9: 2 | L9: 20 | M9: =K9*L9 -> 40 | N9: 193438 | O9: =M9*N9 -> 7737520 | Q9: 25년 10월
B10: 3 | C10: FAB | D10: 리도 | E10: 공법변경 | F10: MODULE 배관설치용 컨베이어 시범 도입으로 인한 시녕회 관련 준비 및 진행 | G10: KCENC 공도 외부 SHOP | H10: 26-02-20~26 | I10: 07:00~17:00 | O10: 3910000 | Q10: 26년 03월
B11: 4 | C11: FAB | D11: 리도 | E11: 발주처 요청사항 | F11: 현장 내 컨베이어 도입 준비 작업 및 시연회 | G11: 현장 FAB 구간 | H11: 46084 | I11: 07:40~10:30,13:50~18:10 | O11: 591000 | Q11: 26년 03월
B12: 5 | C12: FAB | D12: 리도 | E12: 발주처 요청사항 | F12: 현장 내 컨베이어 도입 준비 작업 및 시연회 | G12: 현장 FAB 구간 | H12: 46085 | I12: 07:40~10:50,13:10~15:50 | O12: 1071000 | Q12: 26년 03월
B13: 6 | C13: FAB | D13: 리도 | E13: 발주처 요청사항 | F13: SPOOL(배관) 품질 관련하여 용접 TEST 및 시연회 | G13: KCENC 동항 샵장 | H13: 46100 | I13: 07:00~11:00 | J13: 240 | L13: 1 | O13: 120000 | Q13: 26년 05월
B14: 7 | C14: FAB | D14: 리도 | E14: 발주처 요청사항 | F14: 미탑제 된 MODULE 내 탑제용 SPOOL 제작 | G14: KCENC 동항 외부 샵장 | H14: 2026-03-24 ~2026-03-27 | I14: 21:00~07:00 (철야) | J14: 1920 | L14: 1 | O14: 1840000 | Q14: 26년 05월
B15: 8 | C15: FAB | D15: 리도 | E15: 발주처 요청사항 | F15: 세보 북확장 지원) LATERAL ,2차 브릿지 배관 자동용접 | G15: 6F N~M/53열 | H15: 2026-06-18 ~2026-06-29 | L15: 15 | O15: N/A | Q15: 26년 06월
B16: 2025년 10월 LOSS 합계 | M16: =SUM(M8:M9) -> 44.75 | O16: =SUM(O8:O15) -> 16188350
B17: 총 합 계 | M17: =M16 -> 44.75 | O17: =O16 -> 16188350

Sheet 서명란
B2: 현 장 확 인 | C2: 소 장 | E2: (서명)
C3: 공 사 | E3: (서명)
C4: 공 무 | E4: (서명)
G6: 사 업 부 | H6: Frontier 사업부 GNP 본부장 | I6: BOC 센터장 | J6: Frontier 사업부장
L8: 본 사 | M8: 담 당 | N8: 검 토 | O8: 검 토
Q11: 구 분 | R11: 확 인
Q12: 품 질 | R12: O O O (인)
Q13: 공 무 | R13: O O O (인)

Sheet DIA-INCH
B3: SIZE
B4: A(mm) | C4: Inch
B5: 8A | C5: 0.25
B6: 15A | C6: 0.5
B7: 20A | C7: 0.75
B8: 25A | C8: 1
B9: 32A | C9: 1.25
B10: 40A | C10: 1.5
B11: 50A | C11: 2
B12: 65A | C12: 2.5
B13: 80A | C13: 3
B14: 100A | C14: 4
B15: 110A | C15: 4
B16: 125A | C16: 5
... B27: 550A | C27: 22
