Workbook
Name _: #REF!
Name _: #REF!
Name _: #REF!
Name _??_??_?C?g??: #REF!
Name _??_??_?C?g??: #REF!
Name _??_??_?C?g??: #REF!
Name ___DAT1: [1]원본!#REF!
Name ___DAT1: [1]원본!#REF!
Name ___DAT1: [1]원본!#REF!
Name ___DAT10: [1]원본!#REF!
Name ___DAT10: [1]원본!#REF!
Name ___DAT10: [1]원본!#REF!
Name ___DAT12: [1]원본!#REF!
Name ___DAT12: [1]원본!#REF!
Name ___DAT12: [1]원본!#REF!
Name ___DAT13: [1]원본!#REF!
Name ___DAT13: [1]원본!#REF!
Name ___DAT13: [1]원본!#REF!
Name ___DAT14: [1]원본!#REF!
Name ___DAT14: [1]원본!#REF!
Name ___DAT14: [1]원본!#REF!
Name ___DAT15: [1]원본!#REF!
Name ___DAT15: [1]원본!#REF!
Name ___DAT15: [1]원본!#REF!
Name ___DAT16: [1]원본!#REF!
Name ___DAT16: [1]원본!#REF!
Name ___DAT16: [1]원본!#REF!
Name ___DAT17: [1]원본!#REF!
Name ___DAT17: [1]원본!#REF!
Name ___DAT17: [1]원본!#REF!
Name ___DAT18: [1]원본!#REF!
Name ___DAT18: [1]원본!#REF!
Name ___DAT18: [1]원본!#REF!
Name ___DAT19: [1]원본!#REF!
Name ___DAT19: [1]원본!#REF!
Name ___DAT19: [1]원본!#REF!
Name ___DAT2: [1]원본!#REF!
Name ___DAT2: [1]원본!#REF!
Name ___DAT2: [1]원본!#REF!
Name ___DAT20: [1]원본!#REF!
Name ___DAT20: [1]원본!#REF!
Name ___DAT20: [1]원본!#REF!
Name ___DAT3: [1]원본!#REF!
Name ___DAT3: [1]원본!#REF!
Name ___DAT3: [1]원본!#REF!
Name ___DAT4: [1]원본!#REF!
Name ___DAT4: [1]원본!#REF!
Name ___DAT4: [1]원본!#REF!
Name ___DAT5: #REF!
Name ___DAT5: #REF!
Name ___DAT5: #REF!
Name ___DAT6: [1]원본!#REF!
Name ___DAT6: [1]원본!#REF!
Name ___DAT6: [1]원본!#REF!
Name ___DAT7: [1]원본!#REF!
Name ___DAT7: [1]원본!#REF!
Name ___DAT7: [1]원본!#REF!
Name ___DAT8: [1]원본!#REF!
Name ___DAT8: [1]원본!#REF!
Name ___DAT8: [1]원본!#REF!

Sheet 용역청구서 표지
B4: 용 역 청 구 서
B7: P4 Ph4 GAS 1공구 마감공사
C8: S25-004
C14: 2026년 09월
C15: ㈜리도시스템

Sheet 용역 청구서(갑지)
A1: 용 역 청 구 서
A3: 1 | B3: 공 사 명 | C3: : | D3: ='용역청구서 표지'!$B$7 -> P4 Ph4 GAS 1공구 마감공사 | E3: ='용역청구서 표지'!$C$8 -> S25-004
A4: 2 | B4: 공 종 | C4: : | D4: 외주용역(M/M부분)
A5: 3 | B5: 계 약 금 액 | C5: : | D5: =ROUNDUP(E5,0) -> 727400000 | E5: =집계장!I23 -> 727400000 | F5: (VAT 별도)
A6: 4 | B6: 누 계 기 성 금 액 | C6: : | D6: =ROUNDUP(E6,0) -> 727400000 | E6: =E7+E13 -> 727400000 | F6: (VAT 별도)
A7: 5 | B7: 전 회 기 성 금 액 | C7: : | D7: =ROUNDUP(E7,0) -> 660000000 | E7: =집계장!G23 -> 660000000 | F7: (VAT 별도)
A8: 6 | B8: 금 회 기 성 금 액 | C8: : | D8: =ROUNDUP(E8,0) -> 67400000 | E8: =집계장!F23 -> 67400000 | F8: (VAT 별도)
A9: 7 | B9: 선 금 액 | C9: : | D9: =ROUNDUP(E9,0) -> 0 | E9: =집계장!K21 -> 0 | F9: (VAT 별도)
A10: 8 | B10: 선 금 전 회 공 제 | C10: : | D10: =ROUNDUP(E10,0) -> 0 | E10: =집계장!G21 -> 0 | F10: (VAT 별도)
A11: 9 | B11: 선 금 금 회 공 제 | C11: : | D11: =ROUNDUP(E11,0) -> 0 | E11: =집계장!F21 -> 0 | F11: (VAT 별도)
A12: 10 | B12: 선 금 잔 여 금 액 | C12: : | D12: =ROUNDUP(E12,0) -> 0 | E12: =집계장!L21 -> 0 | F12: (VAT 별도)
A13: 11 | B13: 금 회 청 구 금 액 | C13: : | D13: =ROUNDUP(E13,0) -> 67400000 | E13: =집계장!F23 -> 67400000 | F13: (VAT 별도)
A14: 12 | B14: 잔 여 기 성 금 액 | C14: : | D14: =ROUNDUP(E14,0) -> 0 | E14: 0 | F14: (VAT 별도)
A15: 13 | B15: 공 정 율 | C15: : | D15: 1
A16: 14 | B16: 청 구 공 사 기 간 | C16: : | D16: 2026. 09. 01 ~ 2026. 09. 30
B18: 위 공사의 하도급에 있어서 공사설계도서, 시방서,품질관리 기준 및 약정대로 시공 되었음을 확인하오며. 만약 귀사의 현장담당의 검사에
B19: 관하여 하자가 발견된 때에는 즉시 실액배상 또는 재 시공할것을 서약하고 이에 기성 청구서를 제출합니다.
B20: 상기건과 관련하여 본 청구 이전까지의 모든 대금은 수령하였음을 확약합니다.
F21: 작 성 일 : 2026년 09월 30일
F23: 상 호 : | G23: ㈜ 리도시스템
B24: ※첨 부 : 기성내역서 1부. | F24: 주 소 : | G24: 충남 천안시 직산읍 군서2길 20, 1층
F25: 대표이사 : | G25: 김 용 근 | I25: (인)
D26: ㈜케이씨이앤씨 귀하

Sheet 용역 내역서(을지)
A1: 용 역 내 역 서
A2: P4 Ph4 GAS 1공구 마감공사 | G2: 단위 : 원
A3: 품 명 | B3: 규 격 | C3: 단위 | D3: 단 가 | E3: 금 회 청 구
E4: 수 량 | F4: 금 액 | G4: 비 고
A5: 고급기술인 | B5: S+ | C5: M/M | D5: 1400000 | E5: 1 | F5: =D5*E5 -> 1400000
A6: 고급기술인 | B6: S | C6: M/M | D6: 1200000 | F6: =D6*E6 -> 0
A7: 중급기술인 | B7: A+ | C7: M/M | D7: 1000000 | F7: =D7*E7 -> 0
A8: 중급기술인 | B8: A | C8: M/M | D8: 900000 | F8: =D8*E8 -> 0
A9: 중급기술인 | B9: B+ | C9: M/M | D9: 800000 | F9: =D9*E9 -> 0
A10: 중급기술인 | B10: B | C10: M/M | D10: 700000 | F10: =D10*E10 -> 0
A11: 초급 기술인 | B11: C | C11: M/M | D11: 600000 | F11: =D11*E11 -> 0
A13: 인센티브 | E13: 0.01 | F13: =SUM(F5:F11)*E13 -> 14000
A15: 총 계 | E15: =SUM(E5:E11) -> 1 | F15: =SUM(F5:F13) -> 1414000

Sheet 내역서(을지)
A1: 용 역 내 역 서
A2: P4 Ph4 GAS 1공구 마감공사 | G2: 단위 : 원
A3: 품 명 | B3: 규 격 | C3: 단위 | D3: 단 가 | E3: 금 회 청 구 | G3: 비 고
E4: 수 량 | F4: 금 액
A5: 고급기술인 | B5: S+ | C5: M/M | D5: 1400000 | E5: 21 | F5: =D5*E5 -> 29400000
A6: 고급기술인 | B6: S | C6: M/M | D6: 1200000 | E6: 20 | F6: =D6*E6 -> 24000000
A7: 중급기술인 | B7: A+ | C7: M/M | D7: 1000000 | E7: 14 | F7: =D7*E7 -> 14000000
A8: 중급기술인 | B8: A | C8: M/M | D8: 900000 | F8: =D8*E8 -> 0
A9: 중급기술인 | B9: B+ | C9: M/M | D9: 800000 | F9: =D9*E9 -> 0
A10: 중급기술인 | B10: B | C10: M/M | D10: 700000 | F10: =D10*E10 -> 0
A11: 초급기술인 | B11: C | C11: M/M | D11: 600000 | F11: =D11*E11 -> 0
A13: 인센티브 | E13: 0 | F13: =SUM(F5:F11)*E13 -> 0
A16: 총 계 | E16: =SUM(E5:E11) -> 55 | F16: =SUM(F5:F15) -> 67400000

Sheet 집계장
A1: ='용역청구서 표지'!$B$7 -> P4 Ph4 GAS 1공구 마감공사
L2: ='용역청구서 표지'!$C$15 -> ㈜리도시스템
A3: 구분 | B3: 내역 | C3: 단위 | D3: 수량 | E3: 단가 | F3: 합계 | G3: 전회기성 | H3: 금회기성 | I3: 누계기성 | J3: 비 고
A4: 1. 물량 | B4: WELDING POINT | C4: D/I | G4: 3371032500 | H4: =F4 -> 0 | I4: =G4+H4 -> 3371032500
B5: VALVE 설치비 | C5: EA | G5: 35551500 | H5: =F5 -> 0 | I5: =G5+H5 -> 35551500
B6: 인원 실투입 | C6: M/D | G6: 0 | H6: =F6 -> 0 | I6: =G6+H6 -> 0
A7: 2. 기타비용 | B7: 기타 ISSUE | C7: 式 | G7: 639753470 | H7: =F7 -> 0 | I7: =G7+H7 -> 639753470 | J7: 추가정산 ITEM 지급
B8: 기타지급 운영비 | C8: 式 | G8: 503666893 | H8: =F8 -> 0 | I8: =G8+H8 -> 503666893 | J8: 납기준수비 지급
A9: 소 계 | B9: 물량 | F9: =SUM(F4:F8) -> 0 | G9: =SUM(G4:G8) -> 4550004363 | H9: =SUM(H4:H8) -> 0 | I9: =SUM(I4:I8) -> 4550004363
A10: 3. 노무비 | B10: 직접노무비 | C10: 式 | D10: 0 | G10: 3434876250 | H10: =F10 -> 0 | I10: =G10+H10 -> 3434876250
A11: 4. 숙소 및 식대 | B11: 임대료+관리비 | C11: 式 | D11: =SUM(숙소임차료!I4:I4)+SUM(숙소관리비!I4:I6) -> 0 | F11: =숙소임차료!J3+숙소관리비!J3 -> 1371460 | G11: 70610451 | H11: =F11 -> 1371460 | I11: =G11+H11 -> 71981911
B12: 식대 | C12: 式 | D12: =SUM(식대비용!G4:G7) -> 0 | G12: 315511818 | H12: =F12 -> 0 | I12: =G12+H12 -> 315511818
A13: 5. 기타 공제 내역 | C13: 式
A14: 소 계 | B14: 공제 | F14: =SUM(F10:F12) -> 1371460 | G14: =SUM(G10:G13) -> 3820998519 | H14: =SUM(H10:H13) -> 1371460 | I14: =SUM(I10:I13) -> 3822369979
A15: 합 계 | B15: 기성 (물량-공제) | F15: =F9-F14 -> -1371460 | G15: =G9-G14 -> 729005844 | H15: =H9-H14 -> -1371460 | I15: =I9-I14 -> 727634384
A16: 6. 유보금 | B16: 기성금*XX% | C16: 式 | F16: -68800000 | G16: 68800000 | H16: =F16 -> -68800000 | I16: =G16+H16 -> 0
A17: 7. 유보금 차액 | B17: 전회 누계유보금+적자 기성액 | C17: 式 | H17: =F17 -> 0
A18: 8. NEGO | B18: NEGO | C18: 式 | H18: =F18 -> 0 | I18: =G18+H18 -> 0
A19: 총 계 | B19: 최종기성 | F19: =F15-F16-F17-F18 -> 67428540 | G19: =G15-G16+G17+G18 -> 660205844 | H19: =H15-H16+H17+H18 -> 67428540 | I19: =I15-I16+I17+I18 -> 727634384
A20: 선급금 | B20: 선수공제 | C20: 式 | H20: =F20 -> 0 | I20: =G20+H20 -> 0 | K20: 지급 선급금 | L20: 선급금 차액
B21: 단수정리 | C21: 式 | H21: =F21 -> 0 | I21: =G21+H21 -> 0 | J21: 만 단위 이하 절사
A22: 공제 후 실 지급액 | F22: =F19 -> 67428540 | G22: =G19 -> 660205844 | H22: =H19 -> 67428540 | I22: =G22+H22 -> 727634384
A23: 세금계산서 기준 | F23: =ROUNDDOWN(F22,-5) -> 67400000 | G23: 660000000 | H23: =ROUNDDOWN(H22,-5) -> 67400000 | I23: =G23+H23 -> 727400000 | J23: 만 단위 이하 절사
A24: TERMS AND CONDITIONS | D24: NOTE
A25: 1. 납 기 : KCEnC 지정 납기로 별도 협의 하에 결정하는 것으로 함.
A26: 2. 지불조건 : KCEnC 지불 조건에 따름.
A27: 3. 유효기간 : 기성 제출일로 부터 30일 이내

Sheet 물량 내역서
A1: 2026년 (08)월 물량 내역서
A2: ='용역청구서 표지'!$B$7 -> P4 Ph4 GAS 1공구 마감공사 | M2: 단위 : 원
A3: 품 명 | B3: 규 격 | C3: 단위 | D3: W/P 수량 | E3: 단 가 | F3: 계 약 내 역 | H3: 전 회 누 계 물 량 | J3: 금 회 물 량 | L3: 누 계 물 량
F4: D/I 수량 | G4: 금액 | H4: D/I 수량 | I4: 금액 | J4: D/I 수량 | K4: 금액 | L4: D/I 수량 | M4: 금액
A5: WEDING POINT | B5: 8A | C5: POINT | D5: 0 | E5: 435000 | F5: =L5 -> 0 | G5: =M5 -> 0 | I5: =E5*H5 -> 0 | J5: =$D5*'DIA-INCH'!$C5 -> 0 | K5: =$E5*$J5 -> 0 | L5: =H5+J5 -> 0 | M5: =I5+K5 -> 0
A6: WEDING POINT | B6: 15A | C6: POINT | D6: 0 | E6: 435000 | F6: =L6 -> 0 | G6: =M6 -> 0 | I6: =E6*H6 -> 0 | J6: =$D6*'DIA-INCH'!$C6 -> 0 | K6: =$E6*$J6 -> 0 | L6: =H6+J6 -> 0 | M6: =I6+K6 -> 0
A7: WEDING POINT | B7: 20A | C7: POINT | D7: 0 | E7: 435000 | F7: =L7 -> 0 | G7: =M7 -> 0 | I7: =E7*H7 -> 0 | J7: =$D7*'DIA-INCH'!$C7 -> 0 | K7: =$E7*$J7 -> 0 | L7: =H7+J7 -> 0 | M7: =I7+K7 -> 0
A8: WEDING POINT | B8: 25A | C8: POINT | E8: 435000 | F8: =L8 -> 433 | G8: =M8 -> 188355000 | H8: 433 | I8: =E8*H8 -> 188355000 | J8: =$D8*'DIA-INCH'!$C8 -> 0 | K8: =$E8*$J8 -> 0 | L8: =H8+J8 -> 433 | M8: =I8+K8 -> 188355000
A9: WEDING POINT | B9: 32A | C9: POINT | E9: 435000 | F9: =L9 -> 0 | G9: =M9 -> 0 | I9: =E9*H9 -> 0 | J9: =$D9*'DIA-INCH'!$C9 -> 0 | K9: =$E9*$J9 -> 0 | L9: =H9+J9 -> 0 | M9: =I9+K9 -> 0
A10: WEDING POINT | B10: 40A | C10: POINT | E10: 435000 | F10: =L10 -> 627 | G10: =M10 -> 272745000 | H10: 627 | I10: =E10*H10 -> 272745000 | J10: =$D10*'DIA-INCH'!$C10 -> 0 | K10: =$E10*$J10 -> 0 | L10: =H10+J10 -> 627 | M10: =I10+K10 -> 272745000
A11: WEDING POINT | B11: 50A | C11: POINT | E11: 435000 | F11: =L11 -> 650 | G11: =M11 -> 282750000 | H11: 650 | I11: =E11*H11 -> 282750000 | J11: =$D11*'DIA-INCH'!$C11 -> 0 | K11: =$E11*$J11 -> 0 | L11: =H11+J11 -> 650 | M11: =I11+K11 -> 282750000
A12: WEDING POINT | B12: 65A | C12: POINT | E12: 435000 | F12: =L12 -> 792.5 | G12: =M12 -> 344737500 | H12: 792.5 | I12: =E12*H12 -> 344737500 | J12: =$D12*'DIA-INCH'!$C12 -> 0 | K12: =$E12*$J12 -> 0 | L12: =H12+J12 -> 792.5 | M12: =I12+K12 -> 344737500
A13: WEDING POINT | B13: 80A | C13: POINT | E13: 435000 | F13: =L13 -> 228 | G13: =M13 -> 99180000 | H13: 228 | I13: =E13*H13 -> 99180000 | J13: =$D13*'DIA-INCH'!$C13 -> 0 | K13: =$E13*$J13 -> 0 | L13: =H13+J13 -> 228 | M13: =I13+K13 -> 99180000
A14: WEDING POINT | B14: 100A | C14: POINT | E14: 435000 | F14: =L14 -> 1556 | G14: =M14 -> 676860000 | H14: 1556 | I14: =E14*H14 -> 676860000 | J14: =$D14*'DIA-INCH'!$C14 -> 0 | K14: =$E14*$J14 -> 0 | L14: =H14+J14 -> 1556 | M14: =I14+K14 -> 676860000
A15: WEDING POINT | B15: 110A | C15: POINT | E15: 435000 | F15: =L15 -> 0 | G15: =M15 -> 0 | I15: =E15*H15 -> 0 | J15: =$D15*'DIA-INCH'!$C15 -> 0 | K15: =$E15*$J15 -> 0 | L15: =H15+J15 -> 0 | M15: =I15+K15 -> 0
A16: WEDING POINT | B16: 125A | C16: POINT | E16: 435000 | F16: =L16 -> 2645 | G16: =M16 -> 1150575000 | H16: 2645 | I16: =E16*H16 -> 1150575000 | J16: =$D16*'DIA-INCH'!$C16 -> 0 | K16: =$E16*$J16 -> 0 | L16: =H16+J16 -> 2645 | M16: =I16+K16 -> 1150575000
A17: WEDING POINT | B17: 150A | C17: POINT | E17: 435000 | F17: =L17 -> 114 | G17: =M17 -> 49590000 | H17: 114 | I17: =E17*H17 -> 49590000 | J17: =$D17*'DIA-INCH'!$C17 -> 0 | K17: =$E17*$J17 -> 0 | L17: =H17+J17 -> 114 | M17: =I17+K17 -> 49590000
A18: WEDING POINT | B18: 175A | C18: POINT | E18: 435000 | F18: =L18 -> 0 | G18: =M18 -> 0 | I18: =E18*H18 -> 0 | J18: =$D18*'DIA-INCH'!$C18 -> 0 | K18: =$E18*$J18 -> 0 | L18: =H18+J18 -> 0 | M18: =I18+K18 -> 0
A19: WEDING POINT | B19: 200A | C19: POINT | E19: 435000 | F19: =L19 -> 320 | G19: =M19 -> 139200000 | H19: 320 | I19: =E19*H19 -> 139200000 | J19: =$D19*'DIA-INCH'!$C19 -> 0 | K19: =$E19*$J19 -> 0 | L19: =H19+J19 -> 320 | M19: =I19+K19 -> 139200000
A20: WEDING POINT | B20: 225A | C20: POINT | E20: 435000 | F20: =L20 -> 0 | G20: =M20 -> 0 | I20: =E20*H20 -> 0 | J20: =$D20*'DIA-INCH'!$C20 -> 0 | K20: =$E20*$J20 -> 0 | L20: =H20+J20 -> 0 | M20: =I20+K20 -> 0
A21: WEDING POINT | B21: 250A | C21: POINT | E21: 435000 | F21: =L21 -> 50 | G21: =M21 -> 21750000 | H21: 50 | I21: =E21*H21 -> 21750000 | J21: =$D21*'DIA-INCH'!$C21 -> 0 | K21: =$E21*$J21 -> 0 | L21: =H21+J21 -> 50 | M21: =I21+K21 -> 21750000
A22: WEDING POINT | B22: 300A | C22: POINT | E22: 435000 | F22: =L22 -> 36 | G22: =M22 -> 15660000 | H22: 36 | I22: =E22*H22 -> 15660000 | J22: =$D22*'DIA-INCH'!$C22 -> 0 | K22: =$E22*$J22 -> 0 | L22: =H22+J22 -> 36 | M22: =I22+K22 -> 15660000
A23: WEDING POINT | B23: 350A | C23: POINT | E23: 435000 | F23: =L23 -> 0 | G23: =M23 -> 0 | I23: =E23*H23 -> 0 | J23: =$D23*'DIA-INCH'!$C23 -> 0 | K23: =$E23*$J23 -> 0 | L23: =H23+J23 -> 0 | M23: =I23+K23 -> 0
A24: WEDING POINT | B24: 400A | C24: POINT | E24: 435000 | F24: =L24 -> 0 | G24: =M24 -> 0 | I24: =E24*H24 -> 0 | J24: =$D24*'DIA-INCH'!$C24 -> 0 | K24: =$E24*$J24 -> 0 | L24: =H24+J24 -> 0 | M24: =I24+K24 -> 0
A25: WEDING POINT | B25: 450A | C25: POINT | E25: 435000 | F25: =L25 -> 0 | G25: =M25 -> 0 | I25: =E25*H25 -> 0 | J25: =$D25*'DIA-INCH'!$C25 -> 0 | K25: =$E25*$J25 -> 0 | L25: =H25+J25 -> 0 | M25: =I25+K25 -> 0
A26: WEDING POINT | B26: 500A | C26: POINT | E26: 435000 | F26: =L26 -> 0 | G26: =M26 -> 0 | I26: =E26*H26 -> 0 | J26: =$D26*'DIA-INCH'!$C26 -> 0 | K26: =$E26*$J26 -> 0 | L26: =H26+J26 -> 0 | M26: =I26+K26 -> 0
A27: WEDING POINT | B27: 550A | C27: POINT | E27: 435000 | F27: =L27 -> 0 | G27: =M27 -> 0 | I27: =E27*H27 -> 0 | J27: =$D27*'DIA-INCH'!$C27 -> 0 | K27: =$E27*$J27 -> 0 | L27: =H27+J27 -> 0 | M27: =I27+K27 -> 0
A28: VALVE 설치비 | B28: 8A | C28: EA | E28: =$E$31*'DIA-INCH'!$C5 -> 17125 | F28: =L28 -> 0 | G28: =M28 -> 0 | I28: =E28*H28 -> 0 | J28: =D28 -> 0 | K28: =$J28*$E28 -> 0 | L28: =H28+J28 -> 0 | M28: =I28+K28 -> 0
A29: VALVE 설치비 | B29: 15A | C29: EA | E29: =$E$31*'DIA-INCH'!$C6 -> 34250 | F29: =L29 -> 0 | G29: =M29 -> 0 | I29: =E29*H29 -> 0 | J29: =D29 -> 0 | K29: =$J29*$E29 -> 0 | L29: =H29+J29 -> 0 | M29: =I29+K29 -> 0
A30: VALVE 설치비 | B30: 20A | C30: EA | E30: =$E$31*'DIA-INCH'!$C7 -> 51375 | F30: =L30 -> 0 | G30: =M30 -> 0 | I30: =E30*H30 -> 0 | J30: =D30 -> 0 | K30: =$J30*$E30 -> 0 | L30: =H30+J30 -> 0 | M30: =I30+K30 -> 0
A31: VALVE 설치비 | B31: 25A | C31: EA | E31: 68500 | F31: =L31 -> 6 | G31: =M31 -> 411000 | H31: 6 | I31: =E31*H31 -> 411000 | J31: =D31 -> 0 | K31: =$J31*$E31 -> 0 | L31: =H31+J31 -> 6 | M31: =I31+K31 -> 411000
A32: VALVE 설치비 | B32: 32A | C32: EA | E32: =$E$31*'DIA-INCH'!$C9 -> 85625 | F32: =L32 -> 24 | G32: =M32 -> 2055000 | H32: 24 | I32: =E32*H32 -> 2055000 | J32: =D32 -> 0 | K32: =$J32*$E32 -> 0 | L32: =H32+J32 -> 24 | M32: =I32+K32 -> 2055000
A33: VALVE 설치비 | B33: 40A | C33: EA | E33: =$E$31*'DIA-INCH'!$C10 -> 102750 | F33: =L33 -> 74 | G33: =M33 -> 7603500 | H33: 74 | I33: =E33*H33 -> 7603500 | J33: =D33 -> 0 | K33: =$J33*$E33 -> 0 | L33: =H33+J33 -> 74 | M33: =I33+K33 -> 7603500
A34: VALVE 설치비 | B34: 50A | C34: EA | E34: =$E$31*'DIA-INCH'!$C11 -> 137000 | F34: =L34 -> 9 | G34: =M34 -> 1233000 | H34: 9 | I34: =E34*H34 -> 1233000 | J34: =D34 -> 0 | K34: =$J34*$E34 -> 0 | L34: =H34+J34 -> 9 | M34: =I34+K34 -> 1233000
A35: VALVE 설치비 | B35: 65A | C35: EA | E35: =$E$31*'DIA-INCH'!$C12 -> 171250 | F35: =L35 -> 0 | G35: =M35 -> 0 | I35: =E35*H35 -> 0 | J35: =D35 -> 0 | K35: =$J35*$E35 -> 0 | L35: =H35+J35 -> 0 | M35: =I35+K35 -> 0
A36: VALVE 설치비 | B36: 80A | C36: EA | E36: =$E$31*'DIA-INCH'!$C13 -> 205500 | F36: =L36 -> 10 | G36: =M36 -> 2055000 | H36: 10 | I36: =E36*H36 -> 2055000 | J36: =D36 -> 0 | K36: =$J36*$E36 -> 0 | L36: =H36+J36 -> 10 | M36: =I36+K36 -> 2055000
A37: VALVE 설치비 | B37: 100A | C37: EA | E37: =$E$31*'DIA-INCH'!$C14 -> 274000 | F37: =L37 -> 10 | G37: =M37 -> 2740000 | H37: 10 | I37: =E37*H37 -> 2740000 | J37: =D37 -> 0 | K37: =$J37*$E37 -> 0 | L37: =H37+J37 -> 10 | M37: =I37+K37 -> 2740000
A38: VALVE 설치비 | B38: 110A | C38: EA | E38: =$E$31*'DIA-INCH'!$C15 -> 274000 | F38: =L38 -> 0 | G38: =M38 -> 0 | I38: =E38*H38 -> 0 | J38: =D38 -> 0 | K38: =$J38*$E38 -> 0 | L38: =H38+J38 -> 0 | M38: =I38+K38 -> 0
A39: VALVE 설치비 | B39: 125A | C39: EA | E39: =$E$31*'DIA-INCH'!$C16 -> 342500 | F39: =L39 -> 22 | G39: =M39 -> 7535000 | H39: 22 | I39: =E39*H39 -> 7535000 | J39: =D39 -> 0 | K39: =$J39*$E39 -> 0 | L39: =H39+J39 -> 22 | M39: =I39+K39 -> 7535000
A40: VALVE 설치비 | B40: 150A | C40: EA | E40: =$E$31*'DIA-INCH'!$C17 -> 411000 | F40: =L40 -> 1 | G40: =M40 -> 411000 | H40: 1 | I40: =E40*H40 -> 411000 | J40: =D40 -> 0 | K40: =$J40*$E40 -> 0 | L40: =H40+J40 -> 1 | M40: =I40+K40 -> 411000
...

Sheet 숙소임차료
B1: 숙소 임차료
B2: No. | C2: 납부일 | D2: 구분 | E2: 품명 | F2: 주소 | G2: 호수 | H2: 수량 | I2: 사용인원 | J2: 임차료 | K2: 비 고
J3: =SUM(J4:J4) -> 120000 | M3: 입력해야하는 항목 외 수정 금지
B4: 1 | C4: 46295 | D4: KC대납 임대료 | E4: 숙소임대료(9월분) | F4: 경기도 평택시 고덕여염12길 12 | G4: 201호 | H4: 1 | I4: 퇴실 | J4: 120000 | K4: KC 대납 | M4: 납부일

Sheet 숙소관리비
B1: 숙소 관리비
B2: No. | C2: 납부일 | D2: 구분 | E2: 품명 | F2: 주소 | G2: 호수 | H2: 수량 | I2: 사용인원 | J2: 임차료 | K2: 비 고
J3: =SUM(J4:J6) -> 1251460
B4: 1 | C4: 46237 | D4: KC대납 관리비 | E4: 퇴실정산 (9월분) | F4: 경기도 평택시 고덕여염12길 12 | G4: 201호 | H4: 1 | I4: 퇴실 | J4: =112130+330000 -> 442130 | K4: KC대납
B5: 2 | C5: 46239 | D5: KC대납 관리비 | E5: 퇴실정산 (9월분) | F5: 경기도 평택시 함박산3길 39 | G5: 301호 | H5: 1 | I5: 퇴실 | J5: =227310+300000+100000 -> 627310 | K5: KC대납
B6: 3 | C6: 46239 | D6: KC대납 관리비 | E6: 퇴실정산 (9월분) | F6: 헤리움시그니어 814호 | G6: 814호 | H6: 1 | I6: 퇴실 | J6: 182020 | K6: KC대납

Sheet 식대비용
A1: 식대 비용
A2: No. | B2: 납부일 | C2: 구분 | D2: 품명 | E2: 거래처명 | F2: 수량 | G2: 식수인원 | H2: 단가 | I2: 합 계 | J2: 비 고
I3: =SUM(I4:I9) -> 0 | L3: 입력해야하는 항목 외 수정 금지
L4: 입력항목
L5: 납부일
L6: 구분
L7: 품명
L8: 거래처명
L9: 수량
L10: 식수인원
L11: 단가
L13: ■ 구분은 [KC대납 식대 및 식대] 이외 항목은 입력금지

Sheet 기타비용
A1: 기타 비용
A2: No. | B2: 구매일 | C2: 구분 | D2: 품명 | E2: 거래처명 | F2: 수량 | G2: 단가 | H2: 합계 | I2: 비고
H3: =SUM(H4:H7) -> 0 | K3: 입력해야하는 항목 외 수정 금지
K4: 입력항목
K5: 납부일
K6: 구분
K7: 품명
K8: 거래처명
K9: 수량
K10: 식수인원
K11: 단가
K13: ■ 구분은 [KC대납 식대 및 식대] 이외 항목은 입력금지

Sheet LOSS
B5: ■ 평택 P4_Ph4 GAS 1공구_FAB LOSS 기록대장_리도 | R5: 25년10월 | S5: 25년11월 | T5: 25년12월 | U5: 26년01월 | V5: 26년02월 | W5: 26년03월 | X5: 26년04월 | Y5: 26년05월 | Z5: 26년06월 | AA5: 26년07월
P6: 작성일 : 2025-12--18 | R6: 193438 | S6: 195968
B7: No. | C7: 공구 | D7: 업체 | E7: 구분 | F7: 내용 | G7: 작업구간 | H7: 날짜 | I7: 시간 | J7: 분 | K7: LOSS M/D | L7: 작업인원 | M7: M/D 합계 | N7: 월 평균단가 | O7: LOSS 금액 | P7: 비 고
B8: 1 | C8: FAB | D8: 리도 | E8: 발주처 요청사항 | F8: 중대재해발생으로 인한 발주처 요청으로 자체 특별교육 및 작업 중단으로 인한 양중 차대 비용 | G8: 현장 전 구간 | H8: 45959 | I8: 09:00~11:00 | J8: 120 | K8: 0.25 | L8: 19 | M8: =K8*L8 -> 4.75 | N8: 193438 | O8: =M8*N8 -> 918830.5 | Q8: 25년 10월
B9: 2 | C9: FAB | D9: 리도 | E9: 발주처 요청사항 | F9: 중대재해발생으로 인한 발주처 요청으로 기술인 특별교육 | G9: 현장 안전교육장, KC 안전교육장 | H9: 25-10-30~31 | I9: 30일12:00~14:00,15:00~17:00 31일07:00~09:00,10:00~12:00 | J9: 960 | K9: 2 | L9: 20 | M9: =K9*L9 -> 40 | N9: 193438 | O9: =M9*N9 -> 7737520 | Q9: 25년 10월
B10: 3 | C10: FAB | D10: 리도 | E10: 공법변경 | F10: MODULE 배관설치용 컨베이어 시범 도입으로 인한 시녕회 관련 준비 및 진행 | G10: KCENC 공도 외부 SHOP | H10: 26-02-20~26 | I10: 07:00~17:00 | O10: 3910000 | Q10: 26년 03월
B11: 4 | C11: FAB | D11: 리도 | E11: 발주처 요청사항 | F11: 현장 내 컨베이어 도입 준비 작업 및 시연회 | G11: 현장 FAB 구간 | H11: 46084 | I11: 07:40~10:30,13:50~18:10 | O11: 591000 | Q11: 26년 03월
B12: 5 | C12: FAB | D12: 리도 | E12: 발주처 요청사항 | F12: 현장 내 컨베이어 도입 준비 작업 및 시연회 | G12: 현장 FAB 구간 | H12: 46085 | I12: 07:40~10:50,13:10~15:50 | O12: 1071000 | Q12: 26년 03월
B13: 6 | C13: FAB | D13: 리도 | E13: 발주처 요청사항 | F13: SPOOL(배관) 품질 관련하여 용접 TEST 및 시연회 | G13: KCENC 동항 샵장 | H13: 46100 | I13: 07:00~11:00 | J13: 240 | L13: 1 | O13: 120000 | Q13: 26년 05월
B14: 7 | C14: FAB | D14: 리도 | E14: 발주처 요청사항 | F14: 미탑제 된 MODULE 내 탑제용 SPOOL 제작 | G14: KCENC 동항 외부 샵장 | H14: 2026-03-24 ~2026-03-27 | I14: 21:00~07:00 (철야) | J14: 1920 | L14: 1 | O14: 1840000 | Q14: 26년 05월
B15: 8 | C15: FAB | D15: 리도 | E15: 발주처 요청사항 | F15: 세보 북확장 지원) LATERAL ,2차 브릿지 배관 자동용접 | G15: 6F N~M/53열 | H15: 2026-06-18 ~2026-06-29 | L15: 15 | O15: N/A | Q15: 26년 06월
B16: 2025년 10월 LOSS 합계 | M16: =SUM(M8:M9) -> 44.75 | O16: =SUM(O8:O15) -> 16188350
B17: 총 합 계 | M17: =M16 -> 44.75 | O17: =O16 -> 16188350

Sheet 서명란
B2: 현 장 확 인 | C2: 소 장 | E2: (서명)
C3: 공 사 | E3: (서명)
C4: 공 무 | E4: (서명)
G6: 사 업 부 | H6: Frontier 사업부 GNP 본부장 | I6: BOC 센터장 | J6: Frontier 사업부장
L8: 본 사 | M8: 담 당 | N8: 검 토 | O8: 검 토
Q11: 구 분 | R11: 확 인
Q12: 품 질 | R12: O O O (인)
Q13: 공 무 | R13: O O O (인)

Sheet DIA-INCH
B3: SIZE
B4: A(mm) | C4: Inch
B5: 8A | C5: 0.25
B6: 15A | C6: 0.5
B7: 20A | C7: 0.75
B8: 25A | C8: 1
B9: 32A | C9: 1.25
B10: 40A | C10: 1.5
B11: 50A | C11: 2
B12: 65A | C12: 2.5
B13: 80A | C13: 3
B14: 100A | C14: 4
B15: 110A | C15: 4
B16: 125A | C16: 5
... B27: 550A | C27: 22
