Workbook

Sheet 용역청구서 표지
B4: 용 역 청 구 서
B7: P4 Ph4 GAS 1공구 마감공사
C8: S25-004
C14: 2025년 12월
C15: ㈜태성하이텍

Sheet 용역 청구서(갑지)
A1: 용 역 청 구 서
A3: 1 | B3: 공 사 명 | C3: : | D3: ='용역청구서 표지'!$B$7 -> P4 Ph4 GAS 1공구 마감공사 | E3: ='용역청구서 표지'!$C$8 -> S25-004
A4: 2 | B4: 공 종 | C4: : | D4: 외주용역(M/M부분)
A5: 3 | B5: 계 약 금 액 | C5: : | D5: =ROUNDUP(E5,0) -> -163700000 | E5: =집계장!I22 -> -163700000 | F5: (VAT 별도)
A6: 4 | B6: 누 계 기 성 금 액 | C6: : | D6: =ROUNDUP(E6,0) -> -163700000 | E6: =E7+E13 -> -163700000 | F6: (VAT 별도)
A7: 5 | B7: 전 회 기 성 금 액 | C7: : | D7: =ROUNDUP(E7,0) -> -15000000 | E7: =집계장!G22 -> -15000000 | F7: (VAT 별도)
A8: 6 | B8: 금 회 기 성 금 액 | C8: : | D8: =ROUNDUP(E8,0) -> -148781008 | E8: =집계장!F18 -> -1.4878101e+08 | F8: (VAT 별도)
A9: 7 | B9: 선 금 액 | C9: : | D9: =ROUNDUP(E9,0) -> 0 | E9: =집계장!K20 -> 0 | F9: (VAT 별도)
A10: 8 | B10: 선 금 전 회 공 제 | C10: : | D10: =ROUNDUP(E10,0) -> 0 | E10: =집계장!G20 -> 0 | F10: (VAT 별도)
A11: 9 | B11: 선 금 금 회 공 제 | C11: : | D11: =ROUNDUP(E11,0) -> 0 | E11: =집계장!F20 -> 0 | F11: (VAT 별도)
A12: 10 | B12: 선 금 잔 여 금 액 | C12: : | D12: =ROUNDUP(E12,0) -> 0 | E12: =집계장!L20 -> 0 | F12: (VAT 별도)
A13: 11 | B13: 금 회 청 구 금 액 | C13: : | D13: =ROUNDUP(E13,0) -> -148700000 | E13: =집계장!F22 -> -148700000 | F13: (VAT 별도)
A14: 12 | B14: 잔 여 기 성 금 액 | C14: : | D14: =ROUNDUP(E14,0) -> 0 | E14: =집계장!I16 -> 0 | F14: (VAT 별도)
A15: 13 | B15: 공 정 율 | C15: : | D15: 1
A16: 14 | B16: 청 구 공 사 기 간 | C16: : | D16: 2025. 12. 01 ~ 2025. 12. 31
B18: 위 공사의 하도급에 있어서 공사설계도서, 시방서,품질관리 기준 및 약정대로 시공 되었음을 확인하오며. 만약 귀사의 현장담당의 검사에
B19: 관하여 하자가 발견된 때에는 즉시 실액배상 또는 재 시공할것을 서약하고 이에 기성 청구서를 제출합니다.
B20: 상기건과 관련하여 본 청구 이전까지의 모든 대금은 수령하였음을 확약합니다.
F21: 작 성 일 : 2025 년 12 월 31 일
F23: 상 호 : | G23: ㈜ 태성하이텍
B24: ※첨 부 : 기성내역서 1부. | F24: 주 소 : | G24: 경기도 용인시 처인구 남사면 봉명리 73-1
F25: 대표이사 : | G25: 유 태 진 | I25: (인)
D26: ㈜케이씨이앤씨 귀하

Sheet 용역 내역서(을지)
A1: 용 역 내 역 서
A2: P4 Ph4 GAS 1공구 마감공사 | G2: 단위 : 원
A3: 품 명 | B3: 규 격 | C3: 단위 | D3: 단 가 | E3: 금 회 청 구
E4: 수 량 | F4: 금 액 | G4: 비 고
A5: 고급기술인 | B5: S+ | C5: M/M | D5: 1400000 | E5: 1 | F5: =D5*E5 -> 1400000
A6: 고급기술인 | B6: S | C6: M/M | D6: 1200000 | F6: =D6*E6 -> 0
A7: 중급기술인 | B7: A+ | C7: M/M | D7: 1000000 | F7: =D7*E7 -> 0
A8: 중급기술인 | B8: A | C8: M/M | D8: 900000 | F8: =D8*E8 -> 0
A9: 중급기술인 | B9: B+ | C9: M/M | D9: 800000 | F9: =D9*E9 -> 0
A10: 중급기술인 | B10: B | C10: M/M | D10: 700000 | F10: =D10*E10 -> 0
A11: 초급 기술인 | B11: C | C11: M/M | D11: 600000 | F11: =D11*E11 -> 0
A13: 인센티브 | E13: 0.01 | F13: =SUM(F5:F11)*E13 -> 14000
A15: 총 계 | E15: =SUM(E5:E11) -> 1 | F15: =SUM(F5:F13) -> 1414000

Sheet 집계장
A1: ='용역청구서 표지'!$B$7 -> P4 Ph4 GAS 1공구 마감공사
L2: ='용역청구서 표지'!$C$15 -> ㈜태성하이텍
A3: 구분 | B3: 내역 | C3: 단위 | D3: 수량 | E3: 단가 | F3: 합계 | G3: 전회기성 | H3: 금회기성 | I3: 누계기성 | J3: 비 고
A4: 1. 물량 | B4: WELDING POINT | C4: D/I | D4: =SUM('물량 내역서'!$J$5:$J$27) -> 0 | E4: =F4/D4 -> #DIV/0! | F4: =SUM('물량 내역서'!$K$5:$K$27) -> 0 | H4: =F4 -> 0 | I4: =G4+H4 -> 0
B5: VALVE 설치비 | C5: EA | D5: =SUM('물량 내역서'!$J$28:$J$50) -> 0 | E5: =F5/D5 -> #DIV/0! | F5: =SUM('물량 내역서'!$K$28:$K$50) -> 0 | H5: =F5 -> 0 | I5: =G5+H5 -> 0
B6: 인원 실투입 | C6: M/D | D6: ='근로내역 (12월)'!AN68 -> 0 | E6: =F6/D6 -> #DIV/0! | F6: ='근로내역 (12월)'!AP68 -> 0 | H6: =F6 -> 0 | I6: =G6+H6 -> 0
A7: 2. 기타비용 | C7: 式 | E7: 0 | F7: =D7*E7 -> 0 | H7: =F7 -> 0 | I7: =G7+H7 -> 0
A8: 소 계 | B8: 물량 | F8: =SUM(F4:F7) -> 0 | H8: =F8 -> 0 | I8: =G8+H8 -> 0
A9: 3. 노무비 | B9: 직접노무비 | C9: 式 | D9: ='근로내역 (12월)'!AN69 -> 697.125 | E9: =F9/D9 -> 189720.28 | F9: ='근로내역 (12월)'!AP69 -> 132258750 | G9: 13716250 | H9: =F9 -> 132258750 | I9: =G9+H9 -> 145975000
A10: 4. 숙소 및 식대 | B10: 임대료+관리비 | C10: 式 | D10: =SUM(숙소임차료!H4:H8)+SUM(숙소관리비!H4:H8) -> 0 | E10: =F10/D10 -> #DIV/0! | F10: =숙소임차료!I3+숙소관리비!I3 -> 7330984.5 | G10: 666666.67 | H10: =F10 -> 7330984.5 | I10: =G10+H10 -> 7997651.2
B11: 식대 | C11: 式 | D11: =SUM(식대비용!G4:G9) -> 1139 | E11: =F11/D11 -> 8069.5988 | F11: =식대비용!I3 -> 9191273 | G11: 681818 | H11: =F11 -> 9191273 | I11: =G11+H11 -> 9873091
A12: 5. 기타 공제 내역 | C12: 式 | E12: 0 | F12: =D12*E12 -> 0 | H12: =F12 -> 0 | I12: =G12+H12 -> 0
A13: 소 계 | B13: 공제 | F13: =SUM(F9:F12) -> 1.4878101e+08 | G13: =SUM(G9:G12) -> 15064735 | H13: =F13 -> 1.4878101e+08 | I13: =G13+H13 -> 1.6384574e+08
A14: 합 계 | B14: 기성 (물량-공제) | F14: =F8-F13 -> -1.4878101e+08 | G14: =G8-G13 -> -15064735 | H14: =F14 -> -1.4878101e+08 | I14: =G14+H14 -> -1.6384574e+08
A15: 6. 유보금 | B15: 기성금*XX% | C15: 式 | H15: =F15 -> 0 | I15: =G15+H15 -> 0
A16: 7. 유보금 차액 | B16: 전회 누계유보금+적자 기성액 | C16: 式 | H16: =F16 -> 0 | I16: =G16+H16 -> 0
A17: 8. NEGO | B17: NEGO | C17: 式 | H17: =F17 -> 0 | I17: =G17+H17 -> 0
A18: 총 계 | B18: 최종기성 | F18: =F14-F15-F16-F17 -> -1.4878101e+08 | G18: =G14 -> -15064735 | H18: =F18 -> -1.4878101e+08 | I18: =G18+H18 -> -1.6384574e+08
A19: 선급금 | B19: 선수공제 | C19: 式 | H19: =F19 -> 0 | I19: =G19+H19 -> 0 | K19: 지급 선급금 | L19: 선급금 차액
B20: 단수정리 | C20: 式 | F20: =ROUNDDOWN(F19,-5) -> 0 | H20: =F20 -> 0 | I20: =G20+H20 -> 0 | J20: 만 단위 이하 절사 | K20: 0 | L20: =K20-I20 -> 0
A21: 공제 후 실 지급액 | F21: =F18-F20 -> -1.4878101e+08 | G21: =G18 -> -15064735 | H21: =F21 -> -1.4878101e+08 | I21: =G21+H21 -> -1.6384574e+08
A22: 세금계산서 기준 | F22: =ROUNDDOWN(F21,-5) -> -148700000 | G22: =ROUNDDOWN(G21,-5) -> -15000000 | H22: =F22 -> -148700000 | I22: =G22+H22 -> -163700000 | J22: 만 단위 이하 절사
A23: TERMS AND CONDITIONS | D23: NOTE
A24: 1. 납 기 : KCEnC 지정 납기로 별도 협의 하에 결정하는 것으로 함.
A25: 2. 지불조건 : KCEnC 지불 조건에 따름.
A26: 3. 유효기간 : 기성 제출일로 부터 30일 이내

Sheet 물량 내역서
A1: 2025년 (12)월 물량 내역서
A2: ='용역청구서 표지'!$B$7 -> P4 Ph4 GAS 1공구 마감공사 | M2: 단위 : 원
A3: 품 명 | B3: 규 격 | C3: 단위 | D3: W/P 수량 | E3: 단 가 | F3: 계 약 내 역 | H3: 전 회 누 계 물 량 | J3: 금 회 물 량 | L3: 누 계 물 량
F4: D/I 수량 | G4: 금액 | H4: D/I 수량 | I4: 금액 | J4: D/I 수량 | K4: 금액 | L4: D/I 수량 | M4: 금액
A5: WEDING POINT | B5: 8A | C5: POINT | D5: 0 | E5: 437000 | F5: =L5 -> 0 | G5: =M5 -> 0 | J5: =$D5*'DIA-INCH'!$C5 -> 0 | K5: =$E5*$J5 -> 0 | L5: =H5+J5 -> 0 | M5: =I5+K5 -> 0
A6: WEDING POINT | B6: 15A | C6: POINT | D6: 0 | E6: 437000 | F6: =L6 -> 0 | G6: =M6 -> 0 | J6: =$D6*'DIA-INCH'!$C6 -> 0 | K6: =$E6*$J6 -> 0 | L6: =H6+J6 -> 0 | M6: =I6+K6 -> 0
A7: WEDING POINT | B7: 20A | C7: POINT | D7: 0 | E7: 437000 | F7: =L7 -> 0 | G7: =M7 -> 0 | J7: =$D7*'DIA-INCH'!$C7 -> 0 | K7: =$E7*$J7 -> 0 | L7: =H7+J7 -> 0 | M7: =I7+K7 -> 0
A8: WEDING POINT | B8: 25A | C8: POINT | D8: 0 | E8: 437000 | F8: =L8 -> 0 | G8: =M8 -> 0 | J8: =$D8*'DIA-INCH'!$C8 -> 0 | K8: =$E8*$J8 -> 0 | L8: =H8+J8 -> 0 | M8: =I8+K8 -> 0
A9: WEDING POINT | B9: 32A | C9: POINT | D9: 0 | E9: 437000 | F9: =L9 -> 0 | G9: =M9 -> 0 | J9: =$D9*'DIA-INCH'!$C9 -> 0 | K9: =$E9*$J9 -> 0 | L9: =H9+J9 -> 0 | M9: =I9+K9 -> 0
A10: WEDING POINT | B10: 40A | C10: POINT | D10: 0 | E10: 437000 | F10: =L10 -> 0 | G10: =M10 -> 0 | J10: =$D10*'DIA-INCH'!$C10 -> 0 | K10: =$E10*$J10 -> 0 | L10: =H10+J10 -> 0 | M10: =I10+K10 -> 0
A11: WEDING POINT | B11: 50A | C11: POINT | D11: 0 | E11: 437000 | F11: =L11 -> 0 | G11: =M11 -> 0 | J11: =$D11*'DIA-INCH'!$C11 -> 0 | K11: =$E11*$J11 -> 0 | L11: =H11+J11 -> 0 | M11: =I11+K11 -> 0
A12: WEDING POINT | B12: 65A | C12: POINT | D12: 0 | E12: 437000 | F12: =L12 -> 0 | G12: =M12 -> 0 | J12: =$D12*'DIA-INCH'!$C12 -> 0 | K12: =$E12*$J12 -> 0 | L12: =H12+J12 -> 0 | M12: =I12+K12 -> 0
A13: WEDING POINT | B13: 80A | C13: POINT | D13: 0 | E13: 437000 | F13: =L13 -> 0 | G13: =M13 -> 0 | J13: =$D13*'DIA-INCH'!$C13 -> 0 | K13: =$E13*$J13 -> 0 | L13: =H13+J13 -> 0 | M13: =I13+K13 -> 0
A14: WEDING POINT | B14: 100A | C14: POINT | D14: 0 | E14: 437000 | F14: =L14 -> 0 | G14: =M14 -> 0 | J14: =$D14*'DIA-INCH'!$C14 -> 0 | K14: =$E14*$J14 -> 0 | L14: =H14+J14 -> 0 | M14: =I14+K14 -> 0
A15: WEDING POINT | B15: 110A | C15: POINT | D15: 0 | E15: 437000 | F15: =L15 -> 0 | G15: =M15 -> 0 | J15: =$D15*'DIA-INCH'!$C15 -> 0 | K15: =$E15*$J15 -> 0 | L15: =H15+J15 -> 0 | M15: =I15+K15 -> 0
A16: WEDING POINT | B16: 125A | C16: POINT | D16: 0 | E16: 437000 | F16: =L16 -> 0 | G16: =M16 -> 0 | J16: =$D16*'DIA-INCH'!$C16 -> 0 | K16: =$E16*$J16 -> 0 | L16: =H16+J16 -> 0 | M16: =I16+K16 -> 0
... A27: WEDING POINT | B27: 550A | C27: POINT | D27: 0 | E27: 437000 | F27: =L27 -> 0 | G27: =M27 -> 0 | J27: =$D27*'DIA-INCH'!$C27 -> 0 | K27: =$E27*$J27 -> 0 | L27: =H27+J27 -> 0 | M27: =I27+K27 -> 0
A28: VALVE 설치비 | B28: 8A | C28: EA | D28: 0 | E28: =$E$31*'DIA-INCH'!$C5 -> 21875 | F28: =L28 -> 0 | G28: =M28 -> 0 | J28: =D28 -> 0 | K28: =$J28*$E28 -> 0 | L28: =H28+J28 -> 0 | M28: =I28+K28 -> 0
A29: VALVE 설치비 | B29: 15A | C29: EA | D29: 0 | E29: =$E$31*'DIA-INCH'!$C6 -> 43750 | F29: =L29 -> 0 | G29: =M29 -> 0 | J29: =D29 -> 0 | K29: =$J29*$E29 -> 0 | L29: =H29+J29 -> 0 | M29: =I29+K29 -> 0
A30: VALVE 설치비 | B30: 20A | C30: EA | D30: 0 | E30: =$E$31*'DIA-INCH'!$C7 -> 65625 | F30: =L30 -> 0 | G30: =M30 -> 0 | J30: =D30 -> 0 | K30: =$J30*$E30 -> 0 | L30: =H30+J30 -> 0 | M30: =I30+K30 -> 0
A31: VALVE 설치비 | B31: 25A | C31: EA | D31: 0 | E31: 87500 | F31: =L31 -> 0 | G31: =M31 -> 0 | J31: =D31 -> 0 | K31: =$J31*$E31 -> 0 | L31: =H31+J31 -> 0 | M31: =I31+K31 -> 0
A32: VALVE 설치비 | B32: 32A | C32: EA | D32: 0 | E32: =$E$31*'DIA-INCH'!$C9 -> 109375 | F32: =L32 -> 0 | G32: =M32 -> 0 | J32: =D32 -> 0 | K32: =$J32*$E32 -> 0 | L32: =H32+J32 -> 0 | M32: =I32+K32 -> 0
A33: VALVE 설치비 | B33: 40A | C33: EA | D33: 0 | E33: =$E$31*'DIA-INCH'!$C10 -> 131250 | F33: =L33 -> 0 | G33: =M33 -> 0 | J33: =D33 -> 0 | K33: =$J33*$E33 -> 0 | L33: =H33+J33 -> 0 | M33: =I33+K33 -> 0
A34: VALVE 설치비 | B34: 50A | C34: EA | D34: 0 | E34: =$E$31*'DIA-INCH'!$C11 -> 175000 | F34: =L34 -> 0 | G34: =M34 -> 0 | J34: =D34 -> 0 | K34: =$J34*$E34 -> 0 | L34: =H34+J34 -> 0 | M34: =I34+K34 -> 0
A35: VALVE 설치비 | B35: 65A | C35: EA | D35: 0 | E35: =$E$31*'DIA-INCH'!$C12 -> 218750 | F35: =L35 -> 0 | G35: =M35 -> 0 | J35: =D35 -> 0 | K35: =$J35*$E35 -> 0 | L35: =H35+J35 -> 0 | M35: =I35+K35 -> 0
A36: VALVE 설치비 | B36: 80A | C36: EA | D36: 0 | E36: =$E$31*'DIA-INCH'!$C13 -> 262500 | F36: =L36 -> 0 | G36: =M36 -> 0 | J36: =D36 -> 0 | K36: =$J36*$E36 -> 0 | L36: =H36+J36 -> 0 | M36: =I36+K36 -> 0
A37: VALVE 설치비 | B37: 100A | C37: EA | D37: 0 | E37: =$E$31*'DIA-INCH'!$C14 -> 350000 | F37: =L37 -> 0 | G37: =M37 -> 0 | J37: =D37 -> 0 | K37: =$J37*$E37 -> 0 | L37: =H37+J37 -> 0 | M37: =I37+K37 -> 0
A38: VALVE 설치비 | B38: 110A | C38: EA | D38: 0 | E38: =$E$31*'DIA-INCH'!$C15 -> 350000 | F38: =L38 -> 0 | G38: =M38 -> 0 | J38: =D38 -> 0 | K38: =$J38*$E38 -> 0 | L38: =H38+J38 -> 0 | M38: =I38+K38 -> 0
A39: VALVE 설치비 | B39: 125A | C39: EA | D39: 0 | E39: =$E$31*'DIA-INCH'!$C16 -> 437500 | F39: =L39 -> 0 | G39: =M39 -> 0 | J39: =D39 -> 0 | K39: =$J39*$E39 -> 0 | L39: =H39+J39 -> 0 | M39: =I39+K39 -> 0
A40: VALVE 설치비 | B40: 150A | C40: EA | D40: 0 | E40: =$E$31*'DIA-INCH'!$C17 -> 525000 | F40: =L40 -> 0 | G40: =M40 -> 0 | J40: =D40 -> 0 | K40: =$J40*$E40 -> 0 | L40: =H40+J40 -> 0 | M40: =I40+K40 -> 0
A41: VALVE 설치비 | B41: 175A | C41: EA | D41: 0 | E41: =$E$31*'DIA-INCH'!$C18 -> 612500 | F41: =L41 -> 0 | G41: =M41 -> 0 | J41: =D41 -> 0 | K41: =$J41*$E41 -> 0 | L41: =H41+J41 -> 0 | M41: =I41+K41 -> 0
A42: VALVE 설치비 | B42: 200A | C42: EA | D42: 0 | E42: =$E$31*'DIA-INCH'!$C19 -> 700000 | F42: =L42 -> 0 | G42: =M42 -> 0 | J42: =D42 -> 0 | K42: =$J42*$E42 -> 0 | L42: =H42+J42 -> 0 | M42: =I42+K42 -> 0
A43: VALVE 설치비 | B43: 225A | C43: EA | D43: 0 | E43: =$E$31*'DIA-INCH'!$C20 -> 787500 | F43: =L43 -> 0 | G43: =M43 -> 0 | J43: =D43 -> 0 | K43: =$J43*$E43 -> 0 | L43: =H43+J43 -> 0 | M43: =I43+K43 -> 0
... A50: VALVE 설치비 | B50: 550A | C50: EA | D50: 0 | E50: =$E$31*'DIA-INCH'!$C27 -> 1925000 | F50: =L50 -> 0 | G50: =M50 -> 0 | J50: =D50 -> 0 | K50: =$J50*$E50 -> 0 | L50: =H50+J50 -> 0 | M50: =I50+K50 -> 0
A51: 합 계 | F51: =SUM(F5:F50) -> 0 | G51: =SUM(G5:G50) -> 0 | H51: =SUM(H5:H50) -> 0 | I51: =SUM(I5:I50) -> 0 | J51: =SUM(J5:J50) -> 0 | K51: =SUM(K5:K50) -> 0 | L51: =SUM(L5:L50) -> 0 | M51: =SUM(M5:M50) -> 0

Sheet 근로내역 (12월)
A1: 2025년 ( 12 )월 일용 노무비명세서 | AH1: 현장명 | AM1: ='용역청구서 표지'!$B$7 -> P4 Ph4 GAS 1공구 마감공사
AH2: 현장소장 | AM2: 장규철
AH3: 잡코드 | AM3: ='용역청구서 표지'!$C$8 -> S25-004
A5: 번호 | B5: 성명 | C5: 주민등록번호 | D5: 직종 | E5: 연락처(H.P) | F5: 은행명 | G5: 예금주 | H5: 계좌번호 | I5: 1 | J5: 2 | K5: 3 | L5: 4 | M5: 5 | N5: 6 | O5: 7 | P5: 8 | Q5: 9 | R5: 10 | S5: 11 | T5: 12 | U5: 13 | V5: 14 | W5: 15 | X5: 16 | Y5: 17 | Z5: 18 | AA5: 19 | AB5: 20 | AC5: 21 | AD5: 22 | AE5: 23 | AF5: 24 | AG5: 25 | AH5: 26 | AI5: 27 | AJ5: 28 | AK5: 29 | AL5: 30 | AM5: 31 | AN5: 공수 | AO5: 단가 | AP5: 총액
A6: 1 | B6: 강경섭 | C6: 781225-1392311 | D6: 공사보조 | E6: 010-2573-6379 | F6: 농협 | G6: 강경섭 | H6: 356-0973-5567-73 | P6: 0.625 | R6: 0.5 | S6: 1 | T6: 1 | W6: 1 | X6: 1 | Y6: 1 | Z6: 1 | AA6: 1 | AD6: 1 | AE6: 1 | AF6: 1 | AH6: 1 | AK6: 1 | AL6: 1 | AM6: 1 | AN6: =SUM(I6:AM6) -> 15.125 | AO6: 230000 | AP6: =AN6*AO6 -> 3478750
A7: 2 | B7: 고종진 | C7: 790213-1912022 | D7: 용접공 | E7: 010-7478-4040 | F7: 국민 | G7: 고종진 | H7: 120-21-0593-080 | P7: 0.875 | R7: 1 | S7: 1 | T7: 1 | W7: 1 | X7: 1 | Y7: 1 | Z7: 1 | AA7: 1 | AD7: 1 | AE7: 1 | AF7: 1 | AH7: 1 | AK7: 1 | AL7: 1 | AM7: 1 | AN7: =SUM(I7:AM7) -> 15.875 | AO7: 240000 | AP7: =AN7*AO7 -> 3810000
A8: 3 | B8: 권혁만 | C8: 770319-1772710 | D8: 보통인부 | E8: 010-9084-0127 | F8: 기업 | G8: 권혁만 | H8: 530-023847-01-014 | W8: 0.625 | Y8: 1 | Z8: 1 | AD8: 1 | AE8: 1 | AF8: 1 | AK8: 1 | AL8: 1 | AM8: 1 | AN8: =SUM(I8:AM8) -> 8.625 | AO8: 180000 | AP8: =AN8*AO8 -> 1552500
A9: 4 | B9: 김강현 | C9: 910414-1031829 | D9: 보통인부 | E9: 010-6733-7963 | F9: 신한 | G9: 김강현 | H9: 110-302-846665 | I9: 0.625 | K9: 1 | L9: 1 | M9: 1 | P9: 1 | Q9: 1 | R9: 1 | S9: 1 | T9: 1 | W9: 1 | X9: 1 | Y9: 1 | Z9: 1 | AA9: 1 | AD9: 1 | AE9: 1 | AF9: 1 | AH9: 1 | AK9: 1 | AL9: 1 | AM9: 1 | AN9: =SUM(I9:AM9) -> 20.625 | AO9: 180000 | AP9: =AN9*AO9 -> 3712500
A10: 5 | B10: 김경태 | C10: 901120-1588112 | D10: 보통인부 | E10: 010-9538-3223 | F10: 국민 | G10: 김경태 | H10: 99538322358 | W10: 0.625 | Y10: 1 | Z10: 1 | AA10: 1 | AD10: 1 | AE10: 1 | AF10: 1 | AH10: 1 | AI10: 1 | AK10: 1 | AL10: 1 | AM10: 1 | AN10: =SUM(I10:AM10) -> 11.625 | AO10: 140000 | AP10: =AN10*AO10 -> 1627500
A11: 6 | B11: 김기진 | C11: 871020-1850315 | D11: 보통인부 | E11: 010-6613-2156 | F11: 농협 | G11: 김기진 | H11: 937-12-468305 | W11: 0.625 | Y11: 1 | Z11: 1 | AA11: 1 | AD11: 1 | AE11: 1 | AF11: 1 | AH11: 1 | AI11: 1 | AK11: 1 | AL11: 1 | AM11: 1 | AN11: =SUM(I11:AM11) -> 11.625 | AO11: 150000 | AP11: =AN11*AO11 -> 1743750
A12: 7 | B12: 김동민 | C12: 840606-1768018 | D12: 용접공 | E12: 010-3804-2432 | F12: 신한 | G12: 김동민 | H12: 110-408-565589 | W12: 0.875 | Y12: 1 | Z12: 0.875 | AA12: 1 | AD12: 1 | AE12: 1 | AF12: 1 | AH12: 1 | AK12: 1 | AL12: 1 | AM12: 1 | AN12: =SUM(I12:AM12) -> 10.75 | AO12: 230000 | AP12: =AN12*AO12 -> 2472500
A13: 8 | B13: 김동준 | C13: 981003-1558112 | D13: 배관공 | E13: 010-9930-1495 | F13: 카카오 | G13: 김동준 | H13: 3333-16-2421842 | W13: 0.875 | X13: 1 | Y13: 1 | Z13: 1 | AA13: 1 | AE13: 1 | AF13: 1 | AH13: 1 | AI13: 1 | AK13: 1 | AL13: 1 | AM13: 1 | AN13: =SUM(I13:AM13) -> 11.875 | AO13: 170000 | AP13: =AN13*AO13 -> 2018750
A14: 9 | B14: 김선광 | C14: 880728-1903519 | D14: 용접공 | E14: 010-4560-3710 | F14: 신한 | G14: 김선광 | H14: 110-214-578576 | W14: 0.875 | X14: 0.5 | Y14: 1 | Z14: 1 | AA14: 1 | AD14: 1 | AE14: 1 | AF14: 1 | AH14: 1 | AK14: 1 | AL14: 1 | AM14: 1 | AN14: =SUM(I14:AM14) -> 11.375 | AO14: 230000 | AP14: =AN14*AO14 -> 2616250
A15: 10 | B15: 김성인 | C15: 781127-1567319 | D15: 배관공 | E15: 010-8336-3710 | F15: 우체국 | G15: 김성인 | H15: 503904-02-235538 | P15: 0.875 | R15: 1 | S15: 1 | T15: 1 | W15: 1 | X15: 1 | Z15: 1 | AA15: 1 | AD15: 1 | AE15: 1 | AF15: 1 | AH15: 1 | AK15: 1 | AL15: 1 | AM15: 1 | AN15: =SUM(I15:AM15) -> 14.875 | AO15: 220000 | AP15: =AN15*AO15 -> 3272500
A16: 11 | B16: 김승진 | C16: 751018-1332839 | D16: 안전보조 | E16: 010-4742-4181 | F16: 신한 | G16: 김승진 | H16: 110-338-273904 | P16: 0.625 | R16: 0.5 | S16: 1 | T16: 1 | W16: 1 | X16: 1 | Y16: 1 | Z16: 0.625 | AA16: 1 | AD16: 1 | AE16: 0.625 | AF16: 1 | AH16: 0.875 | AI16: 0.5 | AK16: 1 | AM16: 0.875 | AN16: =SUM(I16:AM16) -> 13.625 | AO16: 270000 | AP16: =AN16*AO16 -> 3678750
A17: 12 | B17: 김영광 | C17: 920704-1860718 | D17: 관리보조 | E17: 010-7704-1777 | F17: 기업 | G17: 김영광 | H17: 580-022392-01-010 | I17: 1 | J17: 0.875 | K17: 1 | L17: 1 | M17: 0.875 | P17: 1 | Q17: 1 | R17: 1 | S17: 1 | T17: 1 | W17: 1 | X17: 1 | Y17: 1 | Z17: 1 | AA17: 1 | AD17: 1 | AE17: 1 | AF17: 1 | AH17: 1 | AI17: 0.625 | AK17: 1 | AL17: 1 | AM17: 1 | AN17: =SUM(I17:AM17) -> 22.375 | AO17: 200000 | AP17: =AN17*AO17 -> 4475000
A18: 13 | B18: 김영성 | C18: 840504-1490016 | D18: 보통인부 | E18: 010-9000-8225 | F18: 우리 | G18: 김영성 | H18: 1002-544-971422 | I18: 1 | J18: 1 | K18: 1 | L18: 0.5 | AN18: =SUM(I18:AM18) -> 3.5 | AO18: 150000 | AP18: =AN18*AO18 -> 525000
A19: 14 | B19: 김정희 | C19: 720420-1068511 | D19: 배관공 | E19: 010-3331-3464 | F19: 국민 | G19: 김정희 | H19: 437201-04-035555 | W19: 0.875 | Y19: 1 | Z19: 0.875 | AA19: 1 | AD19: 1 | AE19: 1 | AF19: 1 | AH19: 1 | AK19: 1 | AL19: 1 | AM19: 1 | AN19: =SUM(I19:AM19) -> 10.75 | AO19: 220000 | AP19: =AN19*AO19 -> 2365000
A20: 15 | B20: 김진배 | C20: 711024-1074212 | D20: 보통인부 | E20: 010-3591-7832 | F20: 카카오 | G20: 김진배 | H20: 3333-15-8524-783 | P20: 0.625 | R20: 1 | W20: 1 | X20: 1 | Y20: 1 | Z20: 1 | AD20: 1 | AE20: 1 | AF20: 1 | AH20: 1 | AK20: 1 | AL20: 1 | AM20: 1 | AN20: =SUM(I20:AM20) -> 12.625 | AO20: 150000 | AP20: =AN20*AO20 -> 1893750
A21: 16 | B21: 김태훈 | C21: 810515-1814611 | D21: 보통인부 | E21: 010-5844-3098 | F21: 농협 | G21: 김태훈 | H21: 793-12-097221 | P21: 0.625 | R21: 1 | S21: 1 | T21: 1 | W21: 1 | X21: 1 | Y21: 1 | Z21: 1 | AA21: 1 | AD21: 1 | AE21: 1 | AF21: 1 | AH21: 1 | AK21: 1 | AL21: 1 | AM21: 1 | AN21: =SUM(I21:AM21) -> 15.625 | AO21: 150000 | AP21: =AN21*AO21 -> 2343750
A22: 17 | B22: 김현수 | C22: 960703-1675511 | D22: 보통인부 | E22: 010-7760-4917 | F22: 대구 | G22: 김현수 | H22: 143-13132-971 | W22: 0.625 | Y22: 1 | AA22: 1 | AD22: 0.875 | AE22: 1 | AF22: 1 | AH22: 1 | AK22: 1 | AL22: 1 | AM22: 1 | AN22: =SUM(I22:AM22) -> 9.5 | AO22: 160000 | AP22: =AN22*AO22 -> 1520000
A23: 18 | B23: 노성열 | C23: 710302-1394629 | D23: 보통인부 | E23: 010-6400-2762 | F23: 국민 | G23: 노성열 | H23: 401-21-0741-250 | W23: 0.625 | Y23: 1 | Z23: 0.875 | AA23: 1 | AD23: 1 | AE23: 1 | AF23: 1 | AH23: 1 | AK23: 1 | AL23: 1 | AM23: 1 | AN23: =SUM(I23:AM23) -> 10.5 | AO23: 150000 | AP23: =AN23*AO23 -> 1575000
A24: 19 | B24: 도남철 | C24: 681003-1683610 | D24: 보통인부 | E24: 010-3734-2196 | F24: 우체국 | G24: 도남철 | H24: 110009971120 | P24: 0.625 | AN24: =SUM(I24:AM24) -> 0.625 | AO24: 150000 | AP24: =AN24*AO24 -> 93750
A25: 20 | B25: 문상훈 | C25: 920426-1052111 | D25: 보통인부 | E25: 010-9992-5659 | F25: 신한 | G25: 문상훈 | H25: 110-422-363557 | P25: 0.625 | R25: 1 | S25: 1 | AN25: =SUM(I25:AM25) -> 2.625 | AO25: 150000 | AP25: =AN25*AO25 -> 393750
A26: 21 | B26: 박민우 | C26: 841026-1531716 | D26: 배관공 | E26: 010-4768-4757 | F26: 국민 | G26: 박민우 | H26: 673002-01-201903 | W26: 0.875 | Y26: 1 | Z26: 1 | AA26: 0.875 | AD26: 1 | AE26: 1 | AF26: 1 | AH26: 1 | AK26: 1 | AL26: 1 | AM26: 1 | AN26: =SUM(I26:AM26) -> 10.75 | AO26: 220000 | AP26: =AN26*AO26 -> 2365000
A27: 22 | B27: 박성근 | C27: 850811-1526610 | D27: 배관공 | E27: 010-9463-2277 | F27: 농협 | G27: 박성근 | H27: 352-0406-9764-83 | P27: 0.875 | R27: 1 | S27: 1 | T27: 1 | W27: 1 | Y27: 1 | Z27: 1 | AA27: 1 | AD27: 1 | AE27: 1 | AF27: 1 | AH27: 1 | AI27: 1 | AK27: 1 | AL27: 1 | AM27: 1 | AN27: =SUM(I27:AM27) -> 15.875 | AO27: 210000 | AP27: =AN27*AO27 -> 3333750
A28: 23 | B28: 박안서 | C28: 810228-1469327 | D28: 용접공 | E28: 010-3690-0417 | F28: 우리 | G28: 박안서 | H28: 1002-040-987874 | W28: 0.875 | Y28: 1 | Z28: 1 | AA28: 1 | AD28: 1 | AE28: 1 | AF28: 1 | AK28: 1 | AL28: 1 | AM28: 1 | AN28: =SUM(I28:AM28) -> 9.875 | AO28: 230000 | AP28: =AN28*AO28 -> 2271250
A29: 24 | B29: 박주영 | C29: 730810-1457613 | D29: 배관공 | E29: 010-3356-9406 | F29: 하나 | G29: 박주영 | H29: 130-910013-37908 | W29: 0.875 | X29: 1 | Y29: 1 | Z29: 1 | AA29: 0.875 | AD29: 1 | AE29: 1 | AF29: 1 | AK29: 1 | AL29: 1 | AM29: 1 | AN29: =SUM(I29:AM29) -> 10.75 | AO29: 210000 | AP29: =AN29*AO29 -> 2257500
A30: 25 | B30: 박준호 | C30: 900513-1536215 | D30: 공사보조 | E30: 010-5204-1034 | F30: 농협 | G30: 박준호 | H30: 302-0135-6903-51 | I30: 1 | J30: 1 | K30: 1 | L30: 1 | M30: 1 | P30: 1 | Q30: 1 | R30: 1 | S30: 1 | T30: 1 | W30: 1 | X30: 1 | Y30: 0.875 | Z30: 1 | AA30: 1 | AD30: 1 | AE30: 1 | AF30: 1 | AH30: 1 | AI30: 1 | AK30: 1 | AL30: 1 | AM30: 1 | AN30: =SUM(I30:AM30) -> 22.875 | AO30: 230000 | AP30: =AN30*AO30 -> 5261250
A31: 26 | B31: 박태진 | C31: 750405-1773126 | D31: 배관공 | E31: 010-4090-1447 | F31: 카카오 | G31: 박태진 | H31: 3333055010135 | W31: 0.875 | X31: 1 | Y31: 1 | Z31: 1 | AA31: 1 | AD31: 1 | AE31: 1 | AF31: 1 | AH31: 1 | AK31: 1 | AL31: 1 | AM31: 1 | AN31: =SUM(I31:AM31) -> 11.875 | AO31: 220000 | AP31: =AN31*AO31 -> 2612500
A32: 27 | B32: 백승배 | C32: 850323-1520514 | D32: 도비공 | E32: 010-8113-3288 | F32: 우체국 | G32: 백승배 | H32: 402057 02 369681 | P32: 0.625 | R32: 1 | S32: 1 | T32: 1 | W32: 1 | X32: 1 | Z32: 1 | AA32: 1 | AD32: 1 | AE32: 1 | AF32: 1 | AH32: 0.5 | AK32: 1 | AL32: 1 | AM32: 1 | AN32: =SUM(I32:AM32) -> 14.125 | AO32: 190000 | AP32: =AN32*AO32 -> 2683750
A33: 28 | B33: 서주석 | C33: 670215-1386321 | D33: 보통인부 | E33: 010-4514-8042 | F33: 농협 | G33: 서주석 | H33: 352-1129-4746-73 | W33: 0.625 | Y33: 1 | Z33: 1 | AA33: 1 | AD33: 1 | AE33: 1 | AF33: 1 | AH33: 1 | AK33: 1 | AL33: 1 | AM33: 1 | AN33: =SUM(I33:AM33) -> 10.625 | AO33: 160000 | AP33: =AN33*AO33 -> 1700000
A34: 29 | B34: 손성훈 | C34: 921031-1616911 | D34: 안전보조 | E34: 010-5855-1497 | F34: 카카오 | G34: 손성훈 | H34: 3333-05-8926193 | I34: 1 | J34: 1 | K34: 1 | L34: 1 | M34: 1 | P34: 1 | Q34: 1 | R34: 1 | S34: 1 | T34: 1 | W34: 1 | X34: 1 | Y34: 1 | Z34: 1 | AA34: 1 | AD34: 1 | AE34: 1 | AF34: 1 | AH34: 0.5 | AN34: =SUM(I34:AM34) -> 18.5 | AO34: 190000 | AP34: =AN34*AO34 -> 3515000
A35: 30 | B35: 송상엽 | C35: 820530-1167417 | D35: 보통인부 | E35: 010-3142-8904 | F35: 하나 | G35: 송상엽 | H35: 349-910362-94907 | W35: 0.625 | Y35: 1 | Z35: 1 | AA35: 1 | AD35: 1 | AE35: 1 | AF35: 1 | AH35: 1 | AK35: 1 | AL35: 1 | AM35: 1 | AN35: =SUM(I35:AM35) -> 10.625 | AO35: 200000 | AP35: =AN35*AO35 -> 2125000
A36: 31 | B36: 송용기 | C36: 980114-1811111 | D36: 보통인부 | E36: 010-9473-9352 | F36: 농협 | G36: 송용기 | H36: 3522287062093 | W36: 0.625 | Y36: 1 | Z36: 1 | AA36: 1 | AD36: 1 | AE36: 1 | AF36: 0.875 | AH36: 1 | AI36: 1 | AK36: 1 | AL36: 1 | AM36: 1 | AN36: =SUM(I36:AM36) -> 11.5 | AO36: 150000 | AP36: =AN36*AO36 -> 1725000
A37: 32 | B37: 신준호 | C37: 860115-1063914 | D37: 보통인부 | E37: 010-7628-6061 | F37: 우리 | G37: 신준호 | H37: 1002-735-727923 | I37: 1 | K37: 1 | L37: 1 | M37: 1 | P37: 1 | Q37: 1 | R37: 1 | S37: 1 | T37: 1 | W37: 1 | X37: 1 | Y37: 1 | Z37: 1 | AA37: 1 | AD37: 1 | AE37: 1 | AF37: 1 | AH37: 1 | AI37: 1 | AK37: 1 | AL37: 1 | AM37: 1 | AN37: =SUM(I37:AM37) -> 22 | AO37: 150000 | AP37: =AN37*AO37 -> 3300000
A38: 33 | B38: 안수민 | C38: 900220-1083010 | D38: 보통인부 | E38: 010-5250-9814 | F38: 새마을 | G38: 안수민 | H38: 8010525098140 | W38: 0.625 | Y38: 1 | Z38: 1 | AA38: 1 | AE38: 1 | AF38: 1 | AH38: 0.25 | AK38: 1 | AL38: 1 | AM38: 1 | AN38: =SUM(I38:AM38) -> 8.875 | AO38: 150000 | AP38: =AN38*AO38 -> 1331250
A39: 34 | B39: 오별이 | C39: 931014-2253511 | D39: 보통인부 | E39: 010-5027-6760 | F39: 국민 | G39: 오별이 | H39: 253402-04-197247 | I39: 1 | J39: 1 | K39: 1 | L39: 1 | M39: 1 | P39: 1 | Q39: 1 | R39: 1 | S39: 1 | T39: 1 | W39: 1 | X39: 1 | Y39: 1 | Z39: 1 | AA39: 1 | AD39: 1 | AE39: 1 | AF39: 1 | AH39: 1 | AI39: 1 | AK39: 1 | AL39: 1 | AM39: 1 | AN39: =SUM(I39:AM39) -> 23 | AO39: 150000 | AP39: =AN39*AO39 -> 3450000
A40: 35 | B40: 이관창 | C40: 740707-1262013 | D40: 보통인부 | E40: 010-5385-2305 | F40: 농협 | G40: 이관창 | H40: 167-02-743383 | P40: 0.625 | R40: 1 | S40: 1 | T40: 1 | W40: 1 | X40: 1 | Y40: 1 | Z40: 1 | AA40: 1 | AD40: 1 | AE40: 1 | AF40: 1 | AH40: 1 | AK40: 1 | AL40: 1 | AM40: 1 | AN40: =SUM(I40:AM40) -> 15.625 | AO40: 160000 | AP40: =AN40*AO40 -> 2500000
A41: 36 | B41: 이상범 | C41: 860701-1070519 | D41: 배관공 | E41: 010-2221-9310 | F41: 농협 | G41: 이상범 | H41: 352-2141557483 | W41: 0.875 | Y41: 1 | Z41: 1 | AA41: 1 | AD41: 1 | AE41: 1 | AF41: 1 | AH41: 1 | AI41: 1 | AK41: 1 | AL41: 1 | AM41: 1 | AN41: =SUM(I41:AM41) -> 11.875 | AO41: 230000 | AP41: =AN41*AO41 -> 2731250
...

Sheet 용접기자재
A1: 용접 기자재
A2: No | B2: 구매일 | C2: 구분 | D2: 품명 | E2: 규격 | F2: 거래처명 | G2: 발주수량 | H2: 단가 | I2: 합계 | J2: 비고
I3: =ROUND(SUM(I4:I19),) -> 865000
A4: =ROW()-3 -> 1 | B4: 46002 | C4: 소모성자재 | D4: 흑유리 | E4: #10 [크레토스] | F4: 미래공구 | G4: 6 | H4: 500 | I4: 3000 | L4: 입력해야하는 항목 외 수정 금지
A5: =ROW()-3 -> 2 | B5: 46002 | C5: 소모성자재 | D5: 텅스텐봉 | E5: 2.4Q,10개,란탄2% [크레토스] | F5: 미래공구 | G5: 2 | H5: 21000 | I5: 42000 | L5: 입력항목
A6: =ROW()-3 -> 3 | B6: 46002 | C6: 소모성자재 | D6: 텅스텐봉 | E6: 3.2Q,10개,란탄2% [크레토스] | F6: 미래공구 | G6: 2 | H6: 37000 | I6: 74000 | L6: 구매일
A7: =ROW()-3 -> 4 | B7: 46002 | C7: 소모성자재 | D7: 알곤콜렛척 | E7: 2.4Q,350A,변형 [크레토스] | F7: 미래공구 | G7: 10 | H7: 500 | I7: 5000 | L7: 구분
A8: =ROW()-3 -> 5 | B8: 46002 | C8: 소모성자재 | D8: 알곤세라믹 | E8: 350A-8mm(#5)YJ-35,변형 [크레토스] | F8: 미래공구 | G8: 10 | H8: 600 | I8: 6000 | L8: 품명
A9: =ROW()-3 -> 6 | B9: 46002 | C9: 소모성자재 | D9: 알곤세라믹 | E9: 350A-15mm(#10B)YJ-35,변형 [크레토스] | F9: 미래공구 | G9: 10 | H9: 600 | I9: 6000 | L9: 규격
A10: =ROW()-3 -> 7 | B10: 46003 | C10: 소모성자재 | D10: 알곤세라믹 | E10: 350A-8mm(#5)YJ-35,변형 [크레토스] | F10: 미래공구 | G10: 10 | H10: 600 | I10: 6000 | L10: 거래처명
A11: =ROW()-3 -> 8 | B11: 46003 | C11: 소모성자재 | D11: 용접유리 | E11: 2T,투명 [크레토스] | F11: 미래공구 | G11: 10 | H11: 100 | I11: 1000 | L11: 발주수량
A12: =ROW()-3 -> 9 | B12: 46003 | C12: 소모성자재 | D12: 실리콘오링 | E12: 25SQ*9R,적색 | F12: 미래공구 | G12: 20 | H12: 1800 | I12: 36000 | L12: 단가
A13: =ROW()-3 -> 10 | B13: 46008 | C13: 소모성자재 | D13: 알곤용접봉 | E13: TGC316L.2.4mm,5kg [조선선재] | F13: 미래공구 | G13: 2 | H13: 89500 | I13: 179000
A14: =ROW()-3 -> 11 | B14: 46008 | C14: 소모성자재 | D14: 알곤용접봉 | E14: TGC316.2.0mm,5kg [조선선재] | F14: 미래공구 | G14: 1 | H14: 85500 | I14: 85500 | L14: ■ 구분은 [소모성자재, 공구, 임대(공구), 안전용품, 비품] 이외 항목은 입력금지
A15: =ROW()-3 -> 12 | B15: 46008 | C15: 소모성자재 | D15: 알곤용접봉 | E15: TGC308L.2.4mm,5kg [조선선재] | F15: 미래공구 | G15: 2 | H15: 71500 | I15: 143000
A16: =ROW()-3 -> 13 | B16: 46008 | C16: 소모성자재 | D16: 알곤용접봉 | E16: TGC308L.2.0mm,5kg [조선선재] | F16: 미래공구 | G16: 1 | H16: 80000 | I16: 80000
A17: =ROW()-3 -> 14 | B17: 46008 | C17: 소모성자재 | D17: 알곤용접봉 | E17: TGC50S.2.4mm,5kg [조선선재] | F17: 미래공구 | G17: 1 | H17: 24500 | I17: 24500
A18: =ROW()-3 -> 15 | B18: 46017 | C18: 소모성자재 | D18: 텅스텐봉 | E18: 2.4Q,10개,란탄2% [크레토스] | F18: 미래공구 | G18: 3 | H18: 21000 | I18: 63000
A19: =ROW()-3 -> 16 | B19: 46017 | C19: 소모성자재 | D19: 텅스텐봉 | E19: 3.2Q,10개,란탄2% [크레토스] | F19: 미래공구 | G19: 3 | H19: 37000 | I19: 111000

Sheet 배관기자재
A1: 배관 기자재
A2: No | B2: 구매일 | C2: 구분 | D2: 품명 | E2: 규격 | F2: 거래처명 | G2: 발주수량 | H2: 단가 | I2: 합계 | J2: 비고
I3: =ROUND(SUM(I4:I60),) -> 3096709 | L3: 입력해야하는 항목 외 수정 금지
A4: =ROW()-3 -> 1 | B4: 45995 | C4: 소모성자재 | D4: 디월트 충전로타리햄머집진기 | E4: DWH205DH | F4: 네이버파이낸셜㈜ | G4: 1 | H4: 120909 | I4: 120909 | L4: 입력항목
A5: =ROW()-3 -> 2 | B5: 46002 | C5: 소모성자재 | D5: 투명지퍼백 | E5: 25*35 | F5: 네이버파이낸셜㈜ | G5: 500 | H5: 59.909091 | I5: 29954.545 | L5: 구매일
A6: =ROW()-3 -> 3 | B6: 46007 | C6: 소모성자재 | D6: 접지확인테스터 | F6: 네이버파이낸셜㈜ | G6: 2 | H6: 11500 | I6: 23000 | L6: 구분
A7: =ROW()-3 -> 4 | B7: 46014 | C7: 소모성자재 | D7: NBR 코팅장갑 | E7: L | F7: 네이버파이낸셜㈜ | G7: 100 | H7: 594.90909 | I7: 59490.909 | L7: 품명
A8: =ROW()-3 -> 5 | B8: 46387 | C8: 소모성자재 | D8: 청보호테이프 | E8: 500mm*4롤 | F8: 네이버파이낸셜㈜ | G8: 1 | H8: 40909.091 | I8: 40909.091 | L8: 규격
A9: =ROW()-3 -> 6 | B9: 45993 | C9: 소모성자재 | D9: 철근절단비트 | E9: 17MM,SDS PLUS일체형 [모스툴] | F9: 미래공구 | G9: 5 | H9: 32000 | I9: 160000 | L9: 거래처명
A10: =ROW()-3 -> 7 | B10: 46002 | C10: 소모성자재 | D10: 어스클램프 | E10: CEC-500A [크레토스] | F10: 미래공구 | G10: 2 | H10: 16700 | I10: 33400 | L10: 발주수량
A11: =ROW()-3 -> 8 | B11: 46002 | C11: 소모성자재 | D11: 알곤게이지 | E11: KX-3 [코리아나] | F11: 미래공구 | G11: 3 | H11: 20000 | I11: 60000 | L11: 단가
A12: =ROW()-3 -> 9 | B12: 46002 | C12: 소모성자재 | D12: 수세미 | E12: MIGHTY BLUE PAD,녹색 [3M] | F12: 미래공구 | G12: 10 | H12: 1200 | I12: 12000
A13: =ROW()-3 -> 10 | B13: 46002 | C13: 소모성자재 | D13: 철근절단비트 | E13: 17MM,SDS PLUS일체형 [모스툴] | F13: 미래공구 | G13: 2 | H13: 32000 | I13: 64000 | L13: ■ 구분은 [소모성자재, 공구, 임대(공구), 안전용품, 비품] 이외 항목은 입력금지
A14: =ROW()-3 -> 11 | B14: 46002 | C14: 소모성자재 | D14: 검교정비,레이저레벨 | E14: SL-443D,코라스성적서 | F14: 미래공구 | G14: 1 | H14: 320000 | I14: 320000
A15: =ROW()-3 -> 12 | B15: 46002 | C15: 소모성자재 | D15: 검교정비,레이저레벨 | E15: K10G,코라스성적서 | F15: 미래공구 | G15: 1 | H15: 280000 | I15: 280000
A16: =ROW()-3 -> 13 | B16: 46002 | C16: 소모성자재 | D16: 검교정비,레이저레벨 | E16: GX10,코라스성적서 [코텐] | F16: 미래공구 | G16: 1 | H16: 280000 | I16: 280000
A17: =ROW()-3 -> 14 | B17: 46003 | C17: 소모성자재 | D17: 단프라시트 | E17: 900*1800*3T,플로베니아,청색 | F17: 미래공구 | G17: 4 | H17: 2500 | I17: 10000
A18: =ROW()-3 -> 15 | B18: 46003 | C18: 소모성자재 | D18: 티브러쉬 | E18: 50*6,스텐 | F18: 미래공구 | G18: 20 | H18: 4500 | I18: 90000
A19: =ROW()-3 -> 16 | B19: 46003 | C19: 소모성자재 | D19: 티브러쉬 | E19: 75*6,스텐 | F19: 미래공구 | G19: 20 | H19: 4500 | I19: 90000
A20: =ROW()-3 -> 17 | B20: 46003 | C20: 소모성자재 | D20: 다이아몬드줄 | E20: 180MM,반원 [삼익] | F20: 미래공구 | G20: 10 | H20: 7800 | I20: 78000
A21: =ROW()-3 -> 18 | B21: 46003 | C21: 소모성자재 | D21: 다이아몬드줄 | E21: 160MM,반원 [삼익] | F21: 미래공구 | G21: 10 | H21: 6500 | I21: 65000
A22: =ROW()-3 -> 19 | B22: 46003 | C22: 소모성자재 | D22: 방우플러그 | E22: YSP1603,녹색,유성 [AK] | F22: 미래공구 | G22: 5 | H22: 4800 | I22: 24000
A23: =ROW()-3 -> 20 | B23: 46007 | C23: 소모성자재 | D23: 번호열쇠 | E23: 4열,XD-40 [자커] | F23: 미래공구 | G23: 20 | H23: 3500 | I23: 70000
A24: =ROW()-3 -> 21 | B24: 46007 | C24: 소모성자재 | D24: 양면테이프 | E24: 50MM*6M [핫멧트] | F24: 미래공구 | G24: 10 | H24: 800 | I24: 8000
A25: =ROW()-3 -> 22 | B25: 46007 | C25: 소모성자재 | D25: 밀폐용기 | E25: 6.3L(투명) | F25: 미래공구 | G25: 5 | H25: 5000 | I25: 25000
... A58: =ROW()-3 -> 55 | B58: 46387 | C58: 소모성자재 | D58: 낙상방지대 | E58: 200*90 [쓰리에스코리아] | F58: 미래공구 | G58: 20 | H58: 4000 | I58: 80000
A59: =ROW()-3 -> 56 | B59: 46008 | C59: 소모성자재 | D59: 티엘 키 복사 | F59: 에이스열쇠도장 | G59: 1 | H59: 54545.455 | I59: 54545.455
A60: =ROW()-3 -> 57 | B60: 46007 | C60: 소모성자재 | D60: 레이저 | F60: 쿠팡㈜ | G60: 2 | H60: 10000 | I60: 20000

Sheet 숙소임차료
A1: 숙소 임차료
A2: No. | B2: 납부일 | C2: 구분 | D2: 품명 | E2: 주소 | F2: 호수 | G2: 수량 | H2: 사용인원 | I2: 임차료 | J2: 비 고
I3: =SUM(I4:I14) -> 6758064.5 | L3: 입력해야하는 항목 외 수정 금지
A4: =ROW()-3 -> 1 | B4: 46022 | C4: KC대납 임대료 | D4: 숙소임대료(12월분) | E4: 경기도 평택시 함박산1길 16 | F4: 301호 | G4: 1 | I4: =800000 -> 800000 | J4: KC 대납 | L4: 납부일
A5: =ROW()-3 -> 2 | B5: 46022 | C5: KC대납 임대료 | D5: 숙소임대료(12월분) | E5: 경기도 평택시 함박산8길 37 | F5: 302호 | G5: 1 | I5: =800000 -> 800000 | J5: KC 대납 | L5: 구분
A6: =ROW()-3 -> 3 | B6: 46022 | C6: KC대납 임대료 | D6: 숙소임대료(12월분) | E6: 고덕여염11길 85 | F6: 202호 | G6: 1 | I6: =850000/31*26 -> 712903.23 | J6: KC 대납 | L6: 품명
A7: =ROW()-3 -> 4 | B7: 46022 | C7: KC대납 임대료 | D7: 숙소임대료(12월분) | E7: 함박산9길 8-1 | F7: 201호 | G7: 1 | I7: =850000/31*26 -> 712903.23 | J7: KC 대납 | L7: 주소
A8: =ROW()-3 -> 5 | B8: 46022 | C8: KC대납 임대료 | D8: 숙소임대료(12월분) | E8: 함박산12길 8-10 | F8: 301호 | G8: 1 | I8: =950000/31*26 -> 796774.19 | J8: KC 대납 | L8: 호수
A9: =ROW()-3 -> 6 | B9: 46022 | C9: KC대납 임대료 | D9: 숙소임대료(12월분) | E9: 함박산10길 19 | F9: 201호 | G9: 1 | I9: =1000000/31*19 -> 612903.23 | J9: KC 대납 | L9: 수량
A10: =ROW()-3 -> 7 | B10: 46022 | C10: KC대납 임대료 | D10: 숙소임대료(12월분) | E10: 함박산10길 19 | F10: 301호 | G10: 1 | I10: =1000000/31*19 -> 612903.23 | J10: KC 대납 | L10: 사용인원
A11: =ROW()-3 -> 8 | B11: 46022 | C11: KC대납 임대료 | D11: 숙소임대료(12월분) | E11: 고덕여염6길 108 | F11: 302호 | G11: 1 | I11: =1000000/31*19 -> 612903.23 | J11: KC 대납
A12: =ROW()-3 -> 9 | B12: 46022 | C12: KC대납 임대료 | D12: 숙소임대료(12월분) | E12: 고덕여염5길 23-16 | F12: 402호 | G12: 1 | I12: =850000/31*19 -> 520967.74 | J12: KC 대납 | L12: ■ 구분은 [KC대납 임대료 및 임대료] 이외 항목은 입력금지
A13: =ROW()-3 -> 10 | B13: 46022 | C13: KC대납 임대료 | D13: 숙소임대료(12월분) | E13: 고덕여염12길 92 | F13: 202호 | G13: 1 | I13: =850000/31*19 -> 520967.74 | J13: KC 대납
A14: =ROW()-3 -> 11 | B14: 46022 | C14: KC대납 임대료 | D14: 숙소임대료(12월분) | E14: 고덕여염16길 32 | F14: 202호 | G14: 1 | I14: =850000/31*2 -> 54838.71 | J14: KC 대납

Sheet 숙소관리비
A1: 숙소 관리비
A2: No. | B2: 납부일 | C2: 구분 | D2: 품명 | E2: 주소 | F2: 호수 | G2: 수량 | H2: 사용인원 | I2: 임차료 | J2: 비 고
I3: =SUM(I4:I15) -> 572920
A4: =ROW()-3 -> 1 | B4: 46022 | C4: 관리비 | D4: 숙소전기요금(12월) | E4: 경기도 평택시 함박산1길 16 | F4: 301호 | G4: 1 | I4: 22210
A5: =ROW()-3 -> 2 | B5: 46022 | C5: 관리비 | D5: 숙소전기요금(12월) | E5: 함박산9길 8-1 | F5: 201호 | G5: 1 | I5: 11740
A6: =ROW()-3 -> 3 | B6: 46022 | C6: 관리비 | D6: 숙소전기요금(12월) | E6: 고덕여염5길 23-16 | F6: 402호 | G6: 1 | I6: 14360
A7: =ROW()-3 -> 4 | B7: 46022 | C7: 관리비 | D7: 숙소도시가스(12월) | E7: 경기도 평택시 함박산1길 16 | F7: 301호 | G7: 1 | I7: 91960
A8: =ROW()-3 -> 5 | B8: 46022 | C8: 관리비 | D8: 숙소도시가스(12월) | E8: 경기도 평택시 함박산8길 37 | F8: 302호 | G8: 1 | I8: 81560
A9: =ROW()-3 -> 6 | B9: 46022 | C9: 관리비 | D9: 숙소도시가스(12월) | E9: 고덕여염11길 85 | F9: 202호 | G9: 1 | I9: 89720
A10: =ROW()-3 -> 7 | B10: 46022 | C10: 관리비 | D10: 숙소도시가스(12월) | E10: 함박산9길 8-1 | F10: 201호 | G10: 1 | I10: 68730
A11: =ROW()-3 -> 8 | B11: 46022 | C11: 관리비 | D11: 숙소도시가스(12월) | E11: 함박산12길 8-10 | F11: 301호 | G11: 1 | I11: 75020
A12: =ROW()-3 -> 9 | B12: 46022 | C12: 관리비 | D12: 숙소도시가스(12월) | E12: 고덕여염5길 23-16 | F12: 402호 | G12: 1 | I12: 82440
A13: =ROW()-3 -> 10 | B13: 46022 | C13: 관리비 | D13: 숙소도시가스(12월) | E13: 고덕여염12길 92 | F13: 202호 | G13: 1 | I13: 32780
A14: =ROW()-3 -> 11 | B14: 46022 | C14: 관리비 | D14: 숙소수도요금(12월) | E14: 경기도 평택시 함박산1길 16 | F14: 301호 | G14: 1 | I14: 1200
A15: =ROW()-3 -> 12 | B15: 46022 | C15: 관리비 | D15: 숙소수도요금(12월) | E15: 경기도 평택시 함박산8길 37 | F15: 302호 | G15: 1 | I15: 1200

Sheet 식대비용
A1: 식대 비용
A2: No. | B2: 납부일 | C2: 구분 | D2: 품명 | E2: 거래처명 | F2: 수량 | G2: 식수인원 | H2: 단가 | I2: 합 계 | J2: 비 고
I3: =SUM(I4:I7) -> 9191273 | L3: 입력해야하는 항목 외 수정 금지
A4: =ROW()-3 -> 1 | B4: 46016 | C4: KC대납 식대 | D4: 기술인및관리자 (현장 식당) | E4: 다모아한식뷔페 | F4: 1 | G4: 41 | H4: 7000 | I4: =G4*H4 -> 287000 | J4: KC 대납 | L4: 입력항목
A5: =ROW()-3 -> 2 | B5: 46016 | C5: KC대납 식대 | D5: 기술인및관리자 (현장 식당) | E5: 영미손김밥 | F5: 1 | G5: 1 | H5: 1232273 | I5: =G5*H5 -> 1232273 | J5: KC 대납 | L5: 납부일
A6: =ROW()-3 -> 3 | B6: 46016 | C6: KC대납 식대 | D6: 기술인및관리자 (현장 식당) | E6: 옛날장터 | F6: 1 | G6: 1051 | H6: 7000 | I6: =G6*H6 -> 7357000 | J6: KC 대납 | L6: 구분
A7: =ROW()-3 -> 4 | B7: 46016 | C7: KC대납 식대 | D7: 기술인및관리자 (현장 식당) | E7: 은주네한식뷔페 | F7: 1 | G7: 45 | H7: 7000 | I7: =G7*H7 -> 315000 | J7: KC 대납 | L7: 품명
A8: =ROW()-3 -> 5 | B8: 46022 | C8: 식대 | E8: 법인카드 | F8: 1 | G8: 1 | H8: 2327013 | I8: =G8*H8 -> 2327013 | L8: 거래처명
L9: 수량
L10: 식수인원
L11: 단가
L13: ■ 구분은 [KC대납 식대 및 식대] 이외 항목은 입력금지

Sheet 기타비용
A1: 기타 비용
A2: No. | B2: 구매일 | C2: 구분 | D2: 품명 | E2: 거래처명 | F2: 수량 | G2: 단가 | H2: 합계 | I2: 비고
H3: =SUM(H4:H39) -> 1639324.3 | K3: 입력해야하는 항목 외 수정 금지
A4: =ROW()-3 -> 1 | B4: 45996 | C4: 차량유류대 | D4: 85어 5471 포터2 | E4: 남사농업협동조합 | F4: 1 | G4: 54545.455 | H4: =F4*G4 -> 54545.455 | K4: 입력항목
A5: =ROW()-3 -> 2 | B5: 46000 | C5: 차량유류대 | D5: 85어 5471 포터2 | E5: (주)에이치케이하이웨 | F5: 1 | G5: 54545.455 | H5: =F5*G5 -> 54545.455 | K5: 구매일
A6: =ROW()-3 -> 3 | B6: 46002 | C6: 차량유류대 | D6: 85어 5471 포터2 | E6: (주)소모 칠곡주유소 | F6: 1 | G6: 54545.455 | H6: =F6*G6 -> 54545.455 | K6: 구분
A7: =ROW()-3 -> 4 | B7: 46003 | C7: 차량유류대 | D7: 85어 5471 포터2 | E7: (주)소모 칠곡주유소 | F7: 1 | G7: 54545.455 | H7: =F7*G7 -> 54545.455 | K7: 품명
A8: =ROW()-3 -> 5 | B8: 46007 | C8: 차량유류대 | D8: 85어 5471 포터2 | E8: (주)소모 칠곡주유소 | F8: 1 | G8: 54545.455 | H8: =F8*G8 -> 54545.455 | K8: 거래처명
A9: =ROW()-3 -> 6 | B9: 46009 | C9: 차량유류대 | D9: 85어 5471 포터2 | E9: (주)소모 칠곡주유소 | F9: 1 | G9: 63636.364 | H9: =F9*G9 -> 63636.364 | K9: 수량
A10: =ROW()-3 -> 7 | B10: 46014 | C10: 차량유류대 | D10: 85어 5471 포터2 | E10: (주)소모 칠곡주유소 | F10: 1 | G10: 63636.364 | H10: =F10*G10 -> 63636.364 | K10: 단가
A11: =ROW()-3 -> 8 | B11: 46020 | C11: 차량유류대 | D11: 85어 5471 포터2 | E11: (주)소모 칠곡주유소 | F11: 1 | G11: 63636.364 | H11: =F11*G11 -> 63636.364
A12: =ROW()-3 -> 9 | B12: 46022 | C12: 차량유류대 | D12: 85어 5471 포터2 | E12: (주)소모 칠곡주유소 | F12: 1 | G12: 63636.364 | H12: =F12*G12 -> 63636.364 | K12: ■ 구분은 [사무용품, 소모품비, 법인카드] 이외 항목은 입력금지
A13: =ROW()-3 -> 10 | B13: 46002 | C13: 소모품비 | D13: A4 용지 | E13: G마켓 | F13: 10 | G13: 17575.455 | H13: 175754.55
A14: =ROW()-3 -> 11 | B14: 46009 | C14: 소모품비 | D14: 라벨테이프 | E14: 네이버파이낸셜㈜ | F14: 5 | G14: 4727.2727 | H14: 23636.364
A15: =ROW()-3 -> 12 | B15: 46002 | C15: 소모품비 | D15: 라벨지 | E15: 아이라벨 | F15: 350 | G15: 274.02597 | H15: 95909.091
A16: =ROW()-3 -> 13 | B16: 46002 | C16: 소모품비 | D16: 라벨지 | E16: 아이라벨 | F16: 300 | G16: 268.18182 | H16: 80454.545
A17: =ROW()-3 -> 14 | B17: 45992 | C17: 소모품비 | D17: 복합기 토너 | E17: 위프린트 | F17: 4 | G17: 86624.25 | H17: 346497
A18: =ROW()-3 -> 15 | B18: 45999 | C18: 소모품비 | D18: 종이봉투 | E18: 주식회사 아성다이소 | F18: 1 | G18: 181.81818 | H18: 181.81818
A19: =ROW()-3 -> 16 | B19: 45999 | C19: 소모품비 | D19: 지우개 | E19: 주식회사 아성다이소 | F19: 1 | G19: 909.09091 | H19: 909.09091
A20: =ROW()-3 -> 17 | B20: 45999 | C20: 사무용품 | D20: 제침기, 커터칼 | E20: 주식회사 아성다이소 | F20: 1 | G20: 909.09091 | H20: 909.09091
A21: =ROW()-3 -> 18 | B21: 45999 | C21: 사무용품 | D21: 계산기 | E21: 주식회사 아성다이소 | F21: 5 | G21: 2727.2727 | H21: 13636.364
A22: =ROW()-3 -> 19 | B22: 45999 | C22: 소모품비 | D22: 볼펜 | E22: 주식회사 아성다이소 | F22: 2 | G22: 909.09091 | H22: 1818.1818
A23: =ROW()-3 -> 20 | B23: 45996 | C23: 사무용품 | D23: 멀티탭 | E23: 쿠팡㈜ | F23: 2 | G23: 28000 | H23: 56000
A24: =ROW()-3 -> 21 | B24: 46000 | C24: 소모품비 | D24: AAA + AA 건전지 | E24: 쿠팡㈜ | F24: 100 | G24: 178.27273 | H24: 17827.273
... A39: =ROW()-3 -> 36 | B39: 46385 | C39: 소모품비 | D39: AA 건전지 | E39: 쿠팡㈜ | F39: 5 | G39: 16890.909 | H39: 84454.545

Sheet 서명란
B2: 현 장 확 인 | C2: 소 장 | E2: (서명)
C3: 공 사 | E3: (서명)
C4: 공 무 | E4: (서명)
G6: 사 업 부 | H6: Frontier 사업부 GNP 본부장 | I6: BOC 센터장 | J6: Frontier 사업부장
L8: 본 사 | M8: 담 당 | N8: 검 토 | O8: 검 토
Q11: 구 분 | R11: 확 인
Q12: 품 질 | R12: O O O (인)
Q13: 공 무 | R13: O O O (인)

Sheet DIA-INCH
B3: SIZE
B4: A(mm) | C4: Inch
B5: 8A | C5: 0.25
B6: 15A | C6: 0.5
B7: 20A | C7: 0.75
B8: 25A | C8: 1
B9: 32A | C9: 1.25
B10: 40A | C10: 1.5
B11: 50A | C11: 2
B12: 65A | C12: 2.5
B13: 80A | C13: 3
B14: 100A | C14: 4
B15: 110A | C15: 4
B16: 125A | C16: 5
... B27: 550A | C27: 22
