Workbook
Name _: #REF!
Name _: #REF!
Name _??_??_?C?g??: #REF!
Name _??_??_?C?g??: #REF!
Name ___DAT5: #REF!
Name ___QQ123: #REF!
Name __DAT11: #REF!
Name __DAT21: #REF!
Name __DAT22: #REF!
Name __DAT23: #REF!
Name __DAT24: #REF!
Name __DAT25: #REF!
Name __DAT26: #REF!
Name __DAT27: #REF!
Name __DAT28: #REF!
Name __P3: #REF!
Name __P4: #REF!
Name __P5: #REF!
Name __P6: #REF!
Name __PP1: #REF!
Name _0101__장비_설치공사: #REF!
Name _0201__소화_장비설치공사: #REF!
Name _1: #REF!
Name _1: #REF!
Name _1._PANEL_BD.__LP___1: #REF!
Name _1._옥외배관및장비설치공사: #REF!
Name _1_3_0Crite: #REF!
Name _10A_61: #N/A
Name _10A_62: #N/A
Name _10A_63: #N/A
Name _10A_64: #N/A
Name _10A_65: #N/A
Name _10A_66: #N/A
Name _10A_67: #N/A
Name _10A_68: #N/A
Name _10A_69: #N/A
Name _10A_70: #N/A
Name _10A_71: #N/A
Name _10A_72: #N/A
Name _10A_73: #N/A
Name _10A_74: #N/A
Name _10A_75: #N/A
Name _10A_76: #N/A
Name _10A_77: #N/A
Name _10A_78: #N/A
Name _10A_79: #N/A
Name _10A_80: #N/A
Name _10A_81: #N/A
Name _10A_82: #N/A
Name _10A_83: #N/A
Name _10A_84: #N/A
Name _10A_85: #N/A
Name _10A_86: #N/A
Name _10A_87: #N/A
Name _10A_88: #N/A
Name _10A_89: #N/A
Name _10A_90: #N/A
Name _10B_61: #N/A
Name _10B_62: #N/A
Name _10B_63: #N/A

Sheet 용역청구서 표지
B4: 용 역 청 구 서
B7: P4 Ph4 GAS 1공구 마감공사
C8: S25-004
C14: 2026년 05월
C15: ㈜태성하이텍

Sheet 용역 청구서(갑지)
A1: 용 역 청 구 서
A3: 1 | B3: 공 사 명 | C3: : | D3: ='용역청구서 표지'!$B$7 -> P4 Ph4 GAS 1공구 마감공사 | E3: ='용역청구서 표지'!$C$8 -> S25-004
A4: 2 | B4: 공 종 | C4: : | D4: 외주용역(M/M부분)
A5: 3 | B5: 계 약 금 액 | C5: : | D5: =ROUNDUP(E5,0) -> 820000000 | E5: =집계장!I22 -> 820000000 | F5: (VAT 별도)
A6: 4 | B6: 누 계 기 성 금 액 | C6: : | D6: =ROUNDUP(E6,0) -> 820000000 | E6: =E7+E13 -> 820000000 | F6: (VAT 별도)
A7: 5 | B7: 전 회 기 성 금 액 | C7: : | D7: =ROUNDUP(E7,0) -> 520000000 | E7: =집계장!G22 -> 520000000 | F7: (VAT 별도)
A8: 6 | B8: 금 회 기 성 금 액 | C8: : | D8: =ROUNDUP(E8,0) -> 300000000 | E8: =집계장!F22 -> 300000000 | F8: (VAT 별도)
A9: 7 | B9: 선 금 액 | C9: : | D9: =ROUNDUP(E9,0) -> 0 | E9: =집계장!K20 -> 0 | F9: (VAT 별도)
A10: 8 | B10: 선 금 전 회 공 제 | C10: : | D10: =ROUNDUP(E10,0) -> 0 | E10: =집계장!G20 -> 0 | F10: (VAT 별도)
A11: 9 | B11: 선 금 금 회 공 제 | C11: : | D11: =ROUNDUP(E11,0) -> 0 | E11: =집계장!F20 -> 0 | F11: (VAT 별도)
A12: 10 | B12: 선 금 잔 여 금 액 | C12: : | D12: =ROUNDUP(E12,0) -> 0 | E12: =집계장!L20 -> 0 | F12: (VAT 별도)
A13: 11 | B13: 금 회 청 구 금 액 | C13: : | D13: =ROUNDUP(E13,0) -> 300000000 | E13: =집계장!F22 -> 300000000 | F13: (VAT 별도)
A14: 12 | B14: 잔 여 기 성 금 액 | C14: : | D14: =ROUNDUP(E14,0) -> 0 | E14: =집계장!I16 -> 0 | F14: (VAT 별도)
A15: 13 | B15: 공 정 율 | C15: : | D15: 1
A16: 14 | B16: 청 구 공 사 기 간 | C16: : | D16: 2026. 05. 01 ~ 2026. 05. 31
B18: 위 공사의 하도급에 있어서 공사설계도서, 시방서,품질관리 기준 및 약정대로 시공 되었음을 확인하오며. 만약 귀사의 현장담당의 검사에
B19: 관하여 하자가 발견된 때에는 즉시 실액배상 또는 재 시공할것을 서약하고 이에 기성 청구서를 제출합니다.
B20: 상기건과 관련하여 본 청구 이전까지의 모든 대금은 수령하였음을 확약합니다.
F21: 작 성 일 : 2026 년 05 월 31 일
F23: 상 호 : | G23: ㈜ 태성하이텍
B24: ※첨 부 : 기성내역서 1부. | F24: 주 소 : | G24: 경기도 용인시 처인구 남사면 봉명리 73-1
F25: 대표이사 : | G25: 유 태 진 | I25: (인)
D26: ㈜케이씨이앤씨 귀하

Sheet 용역 내역서(을지)
A1: 용 역 내 역 서
A2: P4 Ph4 GAS 1공구 마감공사 | G2: 단위 : 원
A3: 품 명 | B3: 규 격 | C3: 단위 | D3: 단 가 | E3: 금 회 청 구
E4: 수 량 | F4: 금 액 | G4: 비 고
A5: 고급기술인 | B5: S+ | C5: M/M | D5: 1400000 | E5: 1 | F5: =D5*E5 -> 1400000
A6: 고급기술인 | B6: S | C6: M/M | D6: 1200000 | F6: =D6*E6 -> 0
A7: 중급기술인 | B7: A+ | C7: M/M | D7: 1000000 | F7: =D7*E7 -> 0
A8: 중급기술인 | B8: A | C8: M/M | D8: 900000 | F8: =D8*E8 -> 0
A9: 중급기술인 | B9: B+ | C9: M/M | D9: 800000 | F9: =D9*E9 -> 0
A10: 중급기술인 | B10: B | C10: M/M | D10: 700000 | F10: =D10*E10 -> 0
A11: 초급 기술인 | B11: C | C11: M/M | D11: 600000 | F11: =D11*E11 -> 0
A13: 인센티브 | E13: 0.01 | F13: =SUM(F5:F11)*E13 -> 14000
A15: 총 계 | E15: =SUM(E5:E11) -> 1 | F15: =SUM(F5:F13) -> 1414000

Sheet 내역서(을지)
A1: 용 역 내 역 서
A2: P4 Ph4 GAS 1공구 마감공사 | G2: 단위 : 원
A3: 품 명 | B3: 규 격 | C3: 단위 | D3: 단 가 | E3: 금 회 청 구 | G3: 비 고
E4: 수 량 | F4: 금 액
A5: 고급기술인 | B5: S+ | C5: M/M | D5: 1400000 | E5: 50 | F5: =D5*E5 -> 70000000
A6: 고급기술인 | B6: S | C6: M/M | D6: 1200000 | E6: 50 | F6: =D6*E6 -> 60000000
A7: 중급기술인 | B7: A+ | C7: M/M | D7: 1000000 | E7: 50 | F7: =D7*E7 -> 50000000
A8: 중급기술인 | B8: A | C8: M/M | D8: 900000 | E8: 40 | F8: =D8*E8 -> 36000000
A9: 중급기술인 | B9: B+ | C9: M/M | D9: 800000 | E9: 40 | F9: =D9*E9 -> 32000000
A10: 중급기술인 | B10: B | C10: M/M | D10: 700000 | E10: 40 | F10: =D10*E10 -> 28000000
A11: 초급기술인 | B11: C | C11: M/M | D11: 600000 | E11: 40 | F11: =D11*E11 -> 24000000
A13: 인센티브 | E13: 0 | F13: =SUM(F5:F11)*E13 -> 0
A16: 총 계 | E16: =SUM(E5:E15) -> 310 | F16: =SUM(F5:F15) -> 300000000

Sheet 집계장
A1: ='용역청구서 표지'!$B$7 -> P4 Ph4 GAS 1공구 마감공사
L2: ='용역청구서 표지'!$C$15 -> ㈜태성하이텍
A3: 구분 | B3: 내역 | C3: 단위 | D3: 수량 | E3: 단가 | F3: 합계 | G3: 전회기성 | H3: 금회기성 | I3: 누계기성 | J3: 비 고
A4: 1. 물량 | B4: WELDING POINT | C4: D/I | D4: =SUM('물량 내역서'!$K$5:$K$27) -> 2327.5 | E4: =F4/D4 -> 437000 | F4: =SUM('물량 내역서'!$L$5:$L$27) -> 1017117500 | G4: 4123532000 | H4: =F4 -> 1017117500 | I4: =G4+H4 -> 5140649500
B5: VALVE 설치비 | C5: EA | D5: =SUM('물량 내역서'!$K$28:$K$50) -> 22 | E5: =F5/D5 -> 226704.55 | F5: =SUM('물량 내역서'!$L$28:$L$50) -> 4987500 | G5: 39243750 | H5: =F5 -> 4987500 | I5: =G5+H5 -> 44231250
B6: 인원 실투입 | C6: M/D | D6: ='근로내역 (05월)'!AN105 -> 0 | E6: =F6/D6 -> #DIV/0! | F6: ='근로내역 (05월)'!AP105 -> 0 | G6: 0 | H6: =F6 -> 0 | I6: =G6+H6 -> 0
A7: 2. 기타비용 | C7: 式 | D7: 527.563 | E7: 187981 | F7: =D7*E7 -> 99171820 | G7: 586606403 | H7: =F7 -> 99171820 | I7: =G7+H7 -> 6.8577822e+08 | J7: 납기준수비 지급
A8: 소 계 | B8: 물량 | F8: =SUM(F4:F7) -> 1.1212768e+09 | G8: =SUM(G4:G7) -> 4749382153 | H8: =F8 -> 1.1212768e+09 | I8: =G8+H8 -> 5.870659e+09
A9: 3. 노무비 | B9: 직접노무비 | C9: 式 | D9: ='근로내역 (05월)'!AN106 -> 2833.625 | E9: =F9/D9 -> 185232.7 | F9: ='근로내역 (05월)'!AP106 -> 524880000 | G9: 2568938750 | H9: =F9 -> 524880000 | I9: =G9+H9 -> 3093818750
A10: 4. 숙소 및 식대 | B10: 임대료+관리비 | C10: 式 | D10: =SUM(숙소임차료!H4:H8)+SUM(숙소관리비!H4:H8) -> 0 | E10: =F10/D10 -> #DIV/0! | F10: =숙소임차료!I3+숙소관리비!I3 -> 19572432 | G10: 109671123 | H10: =F10 -> 19572432 | I10: =G10+H10 -> 1.2924355e+08
B11: 식대 | C11: 式 | D11: =SUM(식대비용!G4:G9) -> 0 | E11: =F11/D11 -> #DIV/0! | F11: =식대비용!I3 -> 34475819 | G11: 179014090 | H11: =F11 -> 34475819 | I11: =G11+H11 -> 213489909
A12: 5. 기타 공제 내역 | C12: 式 | E12: 0 | F12: =D12*E12 -> 0 | G12: 0 | H12: =F12 -> 0 | I12: =G12+H12 -> 0
A13: 소 계 | B13: 공제 | F13: =SUM(F9:F12) -> 5.7892825e+08 | G13: =SUM(G9:G12) -> 2857623963 | H13: =F13 -> 5.7892825e+08 | I13: =G13+H13 -> 3.4365522e+09
A14: 합 계 | B14: 기성 (물량-공제) | F14: =F8-F13 -> 5.4234857e+08 | G14: =G8-G13 -> 1891758190 | H14: =F14 -> 5.4234857e+08 | I14: =G14+H14 -> 2.4341068e+09
A15: 6. 유보금 | B15: 기성금*XX% | C15: 式 | F15: 242300000 | G15: 1371672449 | H15: =F15 -> 242300000 | I15: =G15+H15 -> 1613972449
A16: 7. 유보금 차액 | B16: 전회 누계유보금+적자 기성액 | C16: 式 | H16: =F16 -> 0 | I16: =G16+H16 -> 0
A17: 8. NEGO | B17: NEGO | C17: 式 | H17: =F17 -> 0 | I17: =G17+H17 -> 0
A18: 총 계 | B18: 최종기성 | F18: =F14-F15-F16-F17 -> 3.0004857e+08 | G18: =G14-G15-G16-G17 -> 520085741 | H18: =F18 -> 3.0004857e+08 | I18: =G18+H18 -> 8.2013431e+08
A19: 선급금 | B19: 선수공제 | C19: 式 | G19: 0 | H19: =F19 -> 0 | I19: =G19+H19 -> 0 | K19: 지급 선급금 | L19: 선급금 차액
B20: 단수정리 | C20: 式 | F20: =ROUNDDOWN(F19,-5) -> 0 | H20: =F20 -> 0 | I20: =G20+H20 -> 0 | J20: 만 단위 이하 절사 | K20: 0 | L20: =K20-I20 -> 0
A21: 공제 후 실 지급액 | F21: =F18-F20 -> 3.0004857e+08 | G21: =G18-G19 -> 520085741 | H21: =F21 -> 3.0004857e+08 | I21: =G21+H21 -> 8.2013431e+08
A22: 세금계산서 기준 | F22: =ROUNDDOWN(F21,-5) -> 300000000 | G22: =ROUNDDOWN(G21,-5) -> 520000000 | H22: =F22 -> 300000000 | I22: =G22+H22 -> 820000000 | J22: 만 단위 이하 절사
A23: TERMS AND CONDITIONS | D23: NOTE
A24: 1. 납 기 : KCEnC 지정 납기로 별도 협의 하에 결정하는 것으로 함.
A25: 2. 지불조건 : KCEnC 지불 조건에 따름.
A26: 3. 유효기간 : 기성 제출일로 부터 30일 이내

Sheet 물량 내역서
B1: 2026년 (05)월 물량 내역서
B2: ='용역청구서 표지'!$B$7 -> P4 Ph4 GAS 1공구 마감공사 | N2: 단위 : 원
B3: 품 명 | C3: 규 격 | D3: 단위 | E3: W/P 수량 | F3: 단 가 | G3: 계 약 내 역 | I3: 전 회 누 계 물 량 | K3: 금 회 물 량 | M3: 누 계 물 량
G4: D/I 수량 | H4: 금액 | I4: D/I 수량 | J4: 금액 | K4: D/I 수량 | L4: 금액 | M4: D/I 수량 | N4: 금액
B5: WEDING POINT | C5: 8A | D5: POINT | E5: 0 | F5: 437000 | G5: =M5 -> 0 | H5: =N5 -> 0 | I5: 0 | J5: 0 | K5: =$E5*'DIA-INCH'!$C5 -> 0 | L5: =$F5*$K5 -> 0 | M5: =I5+K5 -> 0 | N5: =J5+L5 -> 0
B6: WEDING POINT | C6: 15A | D6: POINT | E6: 0 | F6: 437000 | G6: =M6 -> 0 | H6: =N6 -> 0 | I6: 0 | J6: 0 | K6: =$E6*'DIA-INCH'!$C6 -> 0 | L6: =$F6*$K6 -> 0 | M6: =I6+K6 -> 0 | N6: =J6+L6 -> 0
B7: WEDING POINT | C7: 20A | D7: POINT | E7: 0 | F7: 437000 | G7: =M7 -> 0 | H7: =N7 -> 0 | I7: 0 | J7: 0 | K7: =$E7*'DIA-INCH'!$C7 -> 0 | L7: =$F7*$K7 -> 0 | M7: =I7+K7 -> 0 | N7: =J7+L7 -> 0
B8: WEDING POINT | C8: 25A | D8: POINT | E8: 219 | F8: 437000 | G8: =M8 -> 904 | H8: =N8 -> 395048000 | I8: =696-11 -> 685 | J8: 299345000 | K8: =$E8*'DIA-INCH'!$C8 -> 219 | L8: =$F8*$K8 -> 95703000 | M8: =I8+K8 -> 904 | N8: =J8+L8 -> 395048000
B9: WEDING POINT | C9: 32A | D9: POINT | E9: 0 | F9: 437000 | G9: =M9 -> 0 | H9: =N9 -> 0 | I9: 0 | J9: 0 | K9: =$E9*'DIA-INCH'!$C9 -> 0 | L9: =$F9*$K9 -> 0 | M9: =I9+K9 -> 0 | N9: =J9+L9 -> 0
B10: WEDING POINT | C10: 40A | D10: POINT | E10: 58 | F10: 437000 | G10: =M10 -> 385.5 | H10: =N10 -> 168463500 | I10: 298.5 | J10: 130444500 | K10: =$E10*'DIA-INCH'!$C10 -> 87 | L10: =$F10*$K10 -> 38019000 | M10: =I10+K10 -> 385.5 | N10: =J10+L10 -> 168463500
B11: WEDING POINT | C11: 50A | D11: POINT | E11: 121 | F11: 437000 | G11: =M11 -> 900 | H11: =N11 -> 393300000 | I11: 658 | J11: 287546000 | K11: =$E11*'DIA-INCH'!$C11 -> 242 | L11: =$F11*$K11 -> 105754000 | M11: =I11+K11 -> 900 | N11: =J11+L11 -> 393300000
B12: WEDING POINT | C12: 65A | D12: POINT | E12: 61 | F12: 437000 | G12: =M12 -> 690 | H12: =N12 -> 301530000 | I12: 537.5 | J12: 234887500 | K12: =$E12*'DIA-INCH'!$C12 -> 152.5 | L12: =$F12*$K12 -> 66642500 | M12: =I12+K12 -> 690 | N12: =J12+L12 -> 301530000
B13: WEDING POINT | C13: 80A | D13: POINT | E13: 59 | F13: 437000 | G13: =M13 -> 624 | H13: =N13 -> 272688000 | I13: 447 | J13: 195339000 | K13: =$E13*'DIA-INCH'!$C13 -> 177 | L13: =$F13*$K13 -> 77349000 | M13: =I13+K13 -> 624 | N13: =J13+L13 -> 272688000
B14: WEDING POINT | C14: 100A | D14: POINT | E14: 80 | F14: 437000 | G14: =M14 -> 1292 | H14: =N14 -> 564604000 | I14: 972 | J14: 424764000 | K14: =$E14*'DIA-INCH'!$C14 -> 320 | L14: =$F14*$K14 -> 139840000 | M14: =I14+K14 -> 1292 | N14: =J14+L14 -> 564604000
B15: WEDING POINT | C15: 110A | D15: POINT | E15: 0 | F15: 437000 | G15: =M15 -> 0 | H15: =N15 -> 0 | I15: 0 | J15: 0 | K15: =$E15*'DIA-INCH'!$C15 -> 0 | L15: =$F15*$K15 -> 0 | M15: =I15+K15 -> 0 | N15: =J15+L15 -> 0
B16: WEDING POINT | C16: 125A | D16: POINT | E16: 102 | F16: 437000 | G16: =M16 -> 2740 | H16: =N16 -> 1197380000 | I16: 2230 | J16: 974510000 | K16: =$E16*'DIA-INCH'!$C16 -> 510 | L16: =$F16*$K16 -> 222870000 | M16: =I16+K16 -> 2740 | N16: =J16+L16 -> 1197380000
B17: WEDING POINT | C17: 150A | D17: POINT | E17: 0 | F17: 437000 | G17: =M17 -> 138 | H17: =N17 -> 60306000 | I17: 138 | J17: 60306000 | K17: =$E17*'DIA-INCH'!$C17 -> 0 | L17: =$F17*$K17 -> 0 | M17: =I17+K17 -> 138 | N17: =J17+L17 -> 60306000
B18: WEDING POINT | C18: 175A | D18: POINT | E18: 0 | F18: 437000 | G18: =M18 -> 0 | H18: =N18 -> 0 | I18: 0 | J18: 0 | K18: =$E18*'DIA-INCH'!$C18 -> 0 | L18: =$F18*$K18 -> 0 | M18: =I18+K18 -> 0 | N18: =J18+L18 -> 0
B19: WEDING POINT | C19: 200A | D19: POINT | E19: 18 | F19: 437000 | G19: =M19 -> 888 | H19: =N19 -> 388056000 | I19: 744 | J19: 325128000 | K19: =$E19*'DIA-INCH'!$C19 -> 144 | L19: =$F19*$K19 -> 62928000 | M19: =I19+K19 -> 888 | N19: =J19+L19 -> 388056000
B20: WEDING POINT | C20: 225A | D20: POINT | E20: 0 | F20: 437000 | G20: =M20 -> 0 | H20: =N20 -> 0 | I20: 0 | J20: 0 | K20: =$E20*'DIA-INCH'!$C20 -> 0 | L20: =$F20*$K20 -> 0 | M20: =I20+K20 -> 0 | N20: =J20+L20 -> 0
... B27: WEDING POINT | C27: 550A | D27: POINT | E27: 0 | F27: 437000 | G27: =M27 -> 0 | H27: =N27 -> 0 | I27: 0 | J27: 0 | K27: =$E27*'DIA-INCH'!$C27 -> 0 | L27: =$F27*$K27 -> 0 | M27: =I27+K27 -> 0 | N27: =J27+L27 -> 0
B28: VALVE 설치비 | C28: 8A | D28: EA | E28: 0 | F28: =$F$31*'DIA-INCH'!$C5 -> 21875 | G28: =M28 -> 0 | H28: =N28 -> 0 | I28: 0 | J28: 0 | K28: =E28 -> 0 | L28: =$K28*$F28 -> 0 | M28: =I28+K28 -> 0 | N28: =J28+L28 -> 0
B29: VALVE 설치비 | C29: 15A | D29: EA | E29: 0 | F29: =$F$31*'DIA-INCH'!$C6 -> 43750 | G29: =M29 -> 0 | H29: =N29 -> 0 | I29: 0 | J29: 0 | K29: =E29 -> 0 | L29: =$K29*$F29 -> 0 | M29: =I29+K29 -> 0 | N29: =J29+L29 -> 0
B30: VALVE 설치비 | C30: 20A | D30: EA | E30: 0 | F30: =$F$31*'DIA-INCH'!$C7 -> 65625 | G30: =M30 -> 0 | H30: =N30 -> 0 | I30: 0 | J30: 0 | K30: =E30 -> 0 | L30: =$K30*$F30 -> 0 | M30: =I30+K30 -> 0 | N30: =J30+L30 -> 0
B31: VALVE 설치비 | C31: 25A | D31: EA | E31: 8 | F31: 87500 | G31: =M31 -> 130 | H31: =N31 -> 11375000 | I31: 122 | J31: 10675000 | K31: =E31 -> 8 | L31: =$K31*$F31 -> 700000 | M31: =I31+K31 -> 130 | N31: =J31+L31 -> 11375000
B32: VALVE 설치비 | C32: 32A | D32: EA | E32: 0 | F32: =$F$31*'DIA-INCH'!$C9 -> 109375 | G32: =M32 -> 84 | H32: =N32 -> 9187500 | I32: 84 | J32: 9187500 | K32: =E32 -> 0 | L32: =$K32*$F32 -> 0 | M32: =I32+K32 -> 84 | N32: =J32+L32 -> 9187500
B33: VALVE 설치비 | C33: 40A | D33: EA | E33: 2 | F33: =$F$31*'DIA-INCH'!$C10 -> 131250 | G33: =M33 -> 22 | H33: =N33 -> 2887500 | I33: 20 | J33: 2625000 | K33: =E33 -> 2 | L33: =$K33*$F33 -> 262500 | M33: =I33+K33 -> 22 | N33: =J33+L33 -> 2887500
B34: VALVE 설치비 | C34: 50A | D34: EA | E34: 2 | F34: =$F$31*'DIA-INCH'!$C11 -> 175000 | G34: =M34 -> 13 | H34: =N34 -> 2275000 | I34: 11 | J34: 1925000 | K34: =E34 -> 2 | L34: =$K34*$F34 -> 350000 | M34: =I34+K34 -> 13 | N34: =J34+L34 -> 2275000
B35: VALVE 설치비 | C35: 65A | D35: EA | E35: 0 | F35: =$F$31*'DIA-INCH'!$C12 -> 218750 | G35: =M35 -> 9 | H35: =N35 -> 1968750 | I35: 9 | J35: 1968750 | K35: =E35 -> 0 | L35: =$K35*$F35 -> 0 | M35: =I35+K35 -> 9 | N35: =J35+L35 -> 1968750
B36: VALVE 설치비 | C36: 80A | D36: EA | E36: 4 | F36: =$F$31*'DIA-INCH'!$C13 -> 262500 | G36: =M36 -> 7 | H36: =N36 -> 1837500 | I36: 3 | J36: 787500 | K36: =E36 -> 4 | L36: =$K36*$F36 -> 1050000 | M36: =I36+K36 -> 7 | N36: =J36+L36 -> 1837500
B37: VALVE 설치비 | C37: 100A | D37: EA | E37: 1 | F37: =$F$31*'DIA-INCH'!$C14 -> 350000 | G37: =M37 -> 1 | H37: =N37 -> 350000 | I37: 0 | J37: 0 | K37: =E37 -> 1 | L37: =$K37*$F37 -> 350000 | M37: =I37+K37 -> 1 | N37: =J37+L37 -> 350000
B38: VALVE 설치비 | C38: 110A | D38: EA | E38: 0 | F38: =$F$31*'DIA-INCH'!$C15 -> 350000 | G38: =M38 -> 0 | H38: =N38 -> 0 | I38: 0 | J38: 0 | K38: =E38 -> 0 | L38: =$K38*$F38 -> 0 | M38: =I38+K38 -> 0 | N38: =J38+L38 -> 0
B39: VALVE 설치비 | C39: 125A | D39: EA | E39: 4 | F39: =$F$31*'DIA-INCH'!$C16 -> 437500 | G39: =M39 -> 28 | H39: =N39 -> 12250000 | I39: 24 | J39: 10500000 | K39: =E39 -> 4 | L39: =$K39*$F39 -> 1750000 | M39: =I39+K39 -> 28 | N39: =J39+L39 -> 12250000
B40: VALVE 설치비 | C40: 150A | D40: EA | E40: 1 | F40: =$F$31*'DIA-INCH'!$C17 -> 525000 | G40: =M40 -> 1 | H40: =N40 -> 525000 | I40: 0 | J40: 0 | K40: =E40 -> 1 | L40: =$K40*$F40 -> 525000 | M40: =I40+K40 -> 1 | N40: =J40+L40 -> 525000
B41: VALVE 설치비 | C41: 175A | D41: EA | E41: 0 | F41: =$F$31*'DIA-INCH'!$C18 -> 612500 | G41: =M41 -> 0 | H41: =N41 -> 0 | I41: 0 | J41: 0 | K41: =E41 -> 0 | L41: =$K41*$F41 -> 0 | M41: =I41+K41 -> 0 | N41: =J41+L41 -> 0
B42: VALVE 설치비 | C42: 200A | D42: EA | E42: 0 | F42: =$F$31*'DIA-INCH'!$C19 -> 700000 | G42: =M42 -> 1 | H42: =N42 -> 700000 | I42: 1 | J42: 700000 | K42: =E42 -> 0 | L42: =$K42*$F42 -> 0 | M42: =I42+K42 -> 1 | N42: =J42+L42 -> 700000
B43: VALVE 설치비 | C43: 225A | D43: EA | E43: 0 | F43: =$F$31*'DIA-INCH'!$C20 -> 787500 | G43: =M43 -> 0 | H43: =N43 -> 0 | I43: 0 | J43: 0 | K43: =E43 -> 0 | L43: =$K43*$F43 -> 0 | M43: =I43+K43 -> 0 | N43: =J43+L43 -> 0
... B50: VALVE 설치비 | C50: 550A | D50: EA | E50: 0 | F50: =$F$31*'DIA-INCH'!$C27 -> 1925000 | G50: =M50 -> 0 | H50: =N50 -> 0 | I50: 0 | J50: 0 | K50: =E50 -> 0 | L50: =$K50*$F50 -> 0 | M50: =I50+K50 -> 0 | N50: =J50+L50 -> 0
B51: 합 계 | G51: =SUM(G5:G50) -> 12060.5 | H51: =SUM(H5:H50) -> 5184880750 | I51: =SUM(I5:I50) -> 9711 | J51: =SUM(J5:J50) -> 4162775750 | K51: =SUM(K5:K50) -> 2349.5 | L51: =SUM(L5:L50) -> 1022105000 | M51: =SUM(M5:M50) -> 12060.5 | N51: =SUM(N5:N50) -> 5184880750

Sheet 근로내역 (05월)
A1: 2026년 ( 05 )월 일용 노무비명세서 | AH1: 현장명 | AM1: ='용역청구서 표지'!$B$7 -> P4 Ph4 GAS 1공구 마감공사
AH2: 현장소장 | AM2: 장규철
AH3: 잡코드 | AM3: ='용역청구서 표지'!$C$8 -> S25-004
A5: 번호 | B5: 성명 | C5: 주민등록번호 | D5: 직종 | E5: 연락처(H.P) | F5: 은행명 | G5: 예금주 | H5: 계좌번호 | I5: 1 | J5: 2 | K5: 3 | L5: 4 | M5: 5 | N5: 6 | O5: 7 | P5: 8 | Q5: 9 | R5: 10 | S5: 11 | T5: 12 | U5: 13 | V5: 14 | W5: 15 | X5: 16 | Y5: 17 | Z5: 18 | AA5: 19 | AB5: 20 | AC5: 21 | AD5: 22 | AE5: 23 | AF5: 24 | AG5: 25 | AH5: 26 | AI5: 27 | AJ5: 28 | AK5: 29 | AL5: 30 | AN5: 공수 | AO5: 단가 | AP5: 총액
A6: 1 | B6: 강경섭 | C6: 781225-1392311 | D6: 공사보조 | E6: 010-2573-6379 | F6: 농협 | G6: 강경섭 | H6: 356-0973-5567-73 | M6: 2 | N6: 2 | O6: 2 | P6: 2 | S6: 2 | T6: 2 | U6: 2 | V6: 2 | W6: 2 | AN6: =SUM(I6:AM6) -> 18 | AO6: 230000 | AP6: =AN6*AO6 -> 4140000
A7: 2 | B7: 강동근 | C7: 960219-1406218 | D7: 보통인부 | E7: 010-5555-5945 | F7: 신한 | G7: 강동근 | H7: 110-444-941185 | N7: 1.5 | P7: 1.5 | T7: 1.5 | U7: 1.5 | V7: 2 | W7: 0.5 | Z7: 1 | AA7: 1 | AB7: 1 | AD7: 2 | AG7: 1.5 | AH7: 2 | AI7: 2 | AK7: 2 | AN7: =SUM(I7:AM7) -> 21 | AO7: 150000 | AP7: =AN7*AO7 -> 3150000
A8: 3 | B8: 강우형 | C8: 000830-3484718 | D8: 보통인부 | E8: 010-7963-4799 | F8: 토스 | G8: 강우형 | H8: 1002-2019-2812 | N8: 1.5 | O8: 1.5 | P8: 1.5 | S8: 1.5 | T8: 1.5 | U8: 0.5 | V8: 2 | X8: 1 | Z8: 1 | AA8: 0.625 | AB8: 1 | AC8: 2 | AD8: 2 | AH8: 2 | AJ8: 2 | AK8: 2 | AN8: =SUM(I8:AM8) -> 23.625 | AO8: 150000 | AP8: =AN8*AO8 -> 3543750
A9: 4 | B9: 강원태 | C9: 920818-1240811 | D9: 보통인부 | E9: 010-9205-4684 | F9: 기업 | G9: 강원태 | H9: 186-075475-01-013 | L9: 1.5 | N9: 1.5 | O9: 1.5 | P9: 1.5 | S9: 1.5 | T9: 1.5 | U9: 1.5 | V9: 2 | W9: 2 | X9: 1 | Z9: 1 | AA9: 1 | AB9: 1 | AC9: 2 | AD9: 2 | AE9: 1 | AH9: 1.875 | AI9: 2 | AJ9: 2 | AK9: 2 | AL9: 1 | AN9: =SUM(I9:AM9) -> 32.375 | AO9: 160000 | AP9: =AN9*AO9 -> 5180000
A10: 5 | B10: 강희재 | C10: 940122-1491011 | D10: 공사보조 | E10: 010-9127-3784 | F10: 신한 | G10: 강희재 | H10: 110-404-502876 | L10: 1.5 | N10: 1.5 | O10: 1.5 | P10: 1.5 | Q10: 1 | S10: 1.5 | T10: 1.5 | U10: 1.5 | V10: 2 | W10: 2 | X10: 1 | Z10: 1 | AA10: 1 | AB10: 1 | AC10: 2 | AD10: 2 | AE10: 1 | AG10: 1.5 | AH10: 2 | AI10: 2 | AJ10: 2 | AK10: 2 | AL10: 1 | AN10: =SUM(I10:AM10) -> 35 | AO10: 230000 | AP10: =AN10*AO10 -> 8050000
A11: 6 | B11: 곽명재 | C11: 800514-1894915 | D11: 용접공 | E11: 010-9232-3215 | F11: 농협 | G11: 곽명재 | H11: 312-0172-2596-61 | L11: 2.5 | M11: 2 | N11: 2 | O11: 2 | P11: 2 | S11: 2 | T11: 2 | U11: 2 | V11: 2 | W11: 1.75 | AA11: 1 | AB11: 1 | AC11: 2 | AD11: 2 | AE11: 1 | AG11: 1.5 | AH11: 2 | AI11: 2 | AJ11: 2 | AK11: 2 | AL11: 0.5 | AN11: =SUM(I11:AM11) -> 37.25 | AO11: 240000 | AP11: =AN11*AO11 -> 8940000
A12: 7 | B12: 김강현 | C12: 910414-1031829 | D12: 보통인부 | E12: 010-6733-7963 | F12: 신한 | G12: 김강현 | H12: 110-302-846665 | L12: 1.5 | N12: 1.5 | O12: 1.5 | P12: 1.5 | Q12: 1 | S12: 1.5 | T12: 1.5 | U12: 1.5 | V12: 2 | W12: 2 | X12: 1 | Z12: 1 | AA12: 1 | AB12: 1 | AC12: 2 | AD12: 2 | AE12: 1 | AG12: 1.5 | AH12: 2 | AI12: 2 | AJ12: 2 | AK12: 2 | AL12: 1 | AN12: =SUM(I12:AM12) -> 35 | AO12: 190000 | AP12: =AN12*AO12 -> 6650000
A13: 8 | B13: 김경태 | C13: 901120-1588112 | D13: 보통인부 | E13: 010-9538-3223 | F13: 국민 | G13: 김경태 | H13: 99538322358 | L13: 2.5 | M13: 2 | N13: 2 | O13: 2 | P13: 2 | S13: 2 | T13: 2 | U13: 2 | V13: 2 | W13: 2 | Z13: 1 | AA13: 1 | AB13: 1 | AC13: 2 | AD13: 2 | AE13: 1 | AG13: 1.5 | AH13: 2 | AI13: 2 | AJ13: 2 | AK13: 2 | AL13: 1 | AN13: =SUM(I13:AM13) -> 39 | AO13: 140000 | AP13: =AN13*AO13 -> 5460000
A14: 9 | B14: 김광동 | C14: 930520-1692511 | D14: 보통인부 | E14: 010-4348-0266 | F14: 국민 | G14: 김광동 | H14: 926102-01-496205 | L14: 1.5 | N14: 1.5 | O14: 1.5 | P14: 1.5 | Q14: 1 | S14: 1.5 | T14: 1.5 | U14: 1.5 | V14: 2 | W14: 2 | X14: 1 | Z14: 1 | AA14: 1 | AB14: 1 | AC14: 2 | AD14: 2 | AG14: 1.5 | AH14: 2 | AI14: 2 | AJ14: 2 | AK14: 2 | AL14: 1 | AN14: =SUM(I14:AM14) -> 34 | AO14: 150000 | AP14: =AN14*AO14 -> 5100000
A15: 10 | B15: 김기진 | C15: 871020-1850315 | D15: 보통인부 | E15: 010-6613-2156 | F15: 농협 | G15: 김기진 | H15: 937-12-468305 | L15: 2.5 | M15: 2 | N15: 2 | O15: 2 | P15: 2 | S15: 2 | T15: 2 | U15: 2 | V15: 2 | W15: 2 | Z15: 1 | AA15: 1 | AB15: 1 | AC15: 2 | AD15: 2 | AG15: 1.5 | AH15: 2 | AI15: 2 | AJ15: 2 | AK15: 2 | AL15: 1 | AN15: =SUM(I15:AM15) -> 38 | AO15: 160000 | AP15: =AN15*AO15 -> 6080000
A16: 11 | B16: 김동민 | C16: 840606-1768018 | D16: 용접공 | E16: 010-3804-2432 | F16: 신한 | G16: 김동민 | H16: 110-408-565589 | L16: 1.5 | N16: 1.5 | O16: 1.375 | P16: 1.5 | Q16: 1 | S16: 2 | T16: 2 | U16: 2 | V16: 2 | W16: 2 | Z16: 1 | AA16: 1 | AB16: 1 | AC16: 2 | AD16: 2 | AG16: 1.5 | AH16: 2 | AI16: 1.875 | AJ16: 2 | AK16: 2 | AL16: 1 | AN16: =SUM(I16:AM16) -> 34.25 | AO16: 240000 | AP16: =AN16*AO16 -> 8220000
A17: 12 | B17: 김동열 | C17: 920815-1331213 | D17: 안전보조 | E17: 010-2426-3254 | F17: 새마을 | G17: 김동열 | H17: 9003-2999-8313-9 | L17: 1.5 | N17: 1.5 | O17: 1.5 | P17: 0.5 | S17: 1.5 | T17: 1.5 | U17: 1.5 | V17: 2 | W17: 2 | X17: 1 | Z17: 1 | AA17: 1 | AB17: 1 | AC17: 2 | AD17: 2 | AH17: 2 | AI17: 1 | AJ17: 2 | AK17: 2 | AL17: 1 | AN17: =SUM(I17:AM17) -> 29.5 | AO17: 210000 | AP17: =AN17*AO17 -> 6195000
A18: 13 | B18: 김명수 | C18: 001211-3823418 | D18: 보통인부 | E18: 010-5797-6473 | F18: 국민 | G18: 김명수 | H18: 944502-00-579965 | J18: 1 | L18: 1.5 | N18: 1.5 | O18: 1.5 | P18: 1.5 | S18: 1.5 | T18: 1.375 | U18: 1.5 | V18: 2 | W18: 2 | Z18: 1 | AA18: 1 | AB18: 1 | AC18: 2 | AD18: 2 | AI18: 2 | AJ18: 2 | AK18: 2 | AL18: 1 | AN18: =SUM(I18:AM18) -> 29.375 | AO18: 150000 | AP18: =AN18*AO18 -> 4406250
A19: 14 | B19: 김성인 | C19: 781127-1567319 | D19: 배관공 | E19: 010-8336-3710 | F19: 우체국 | G19: 김성인 | H19: 503904-02-235538 | L19: 2.5 | N19: 2 | O19: 2 | P19: 2 | S19: 2 | AN19: =SUM(I19:AM19) -> 10.5 | AO19: 230000 | AP19: =AN19*AO19 -> 2415000
A20: 15 | B20: 김성중 | C20: 911126-1043210 | D20: 보통인부 | E20: 010-3777-9825 | F20: 기업 | G20: 김성중 | H20: 118-149246-01-011 | L20: 1.5 | O20: 1.5 | P20: 1.5 | Q20: 1 | S20: 1.5 | T20: 1.5 | U20: 1.5 | V20: 2 | W20: 2 | X20: 1 | Z20: 1 | AA20: 1 | AB20: 1 | AC20: 2 | AD20: 2 | AE20: 1 | AG20: 1.5 | AH20: 2 | AI20: 2 | AJ20: 2 | AK20: 1.875 | AL20: 1 | AN20: =SUM(I20:AM20) -> 33.375 | AO20: 150000 | AP20: =AN20*AO20 -> 5006250
A21: 16 | B21: 김승진 | C21: 751018-1332839 | D21: 안전보조 | E21: 010-4742-4181 | F21: 신한 | G21: 김승진 | H21: 110-338-273904 | L21: 1.5 | N21: 1.5 | O21: 1.5 | P21: 1.5 | Q21: 1 | S21: 1.5 | T21: 1.5 | U21: 1.5 | V21: 2 | W21: 2 | X21: 1 | Z21: 1 | AA21: 1 | AB21: 1 | AC21: 2 | AD21: 2 | AE21: 1 | AG21: 1.5 | AH21: 2 | AI21: 2 | AJ21: 2 | AK21: 2 | AL21: 1 | AN21: =SUM(I21:AM21) -> 35 | AO21: 270000 | AP21: =AN21*AO21 -> 9450000
A22: 17 | B22: 김양근 | C22: 930824-1030929 | D22: 용접공 | E22: 010-2301-4979 | F22: 신한 | G22: 김양근 | H22: 110-349-207217 | L22: 1.5 | N22: 1.5 | O22: 1.5 | P22: 1.5 | T22: 1.5 | U22: 1.5 | V22: 2 | W22: 2 | AN22: =SUM(I22:AM22) -> 13 | AO22: 240000 | AP22: =AN22*AO22 -> 3120000
A23: 18 | B23: 김영광 | C23: 920704-1860718 | D23: 공무보조 | E23: 010-7704-1777 | F23: 기업 | G23: 김영광 | H23: 580-022392-01-010 | L23: 1.5 | N23: 1.5 | O23: 1.5 | P23: 1.5 | Q23: 0.625 | S23: 1.5 | T23: 1.5 | U23: 1.5 | V23: 1.875 | W23: 2 | X23: 0.75 | Z23: 1 | AA23: 1 | AB23: 1 | AC23: 2 | AD23: 1.5 | AE23: 0.875 | AG23: 1.5 | AH23: 2 | AI23: 2 | AJ23: 1.875 | AK23: 2 | AL23: 1 | AN23: =SUM(I23:AM23) -> 33.5 | AO23: 200000 | AP23: =AN23*AO23 -> 6700000
A24: 19 | B24: 김영철 | C24: 720622-1921415 | D24: 배관공 | E24: 010-3884-4513 | F24: 새마을 | G24: 김영철 | H24: 9003-2504-8199-8 | J24: 1 | L24: 1.5 | N24: 1.5 | O24: 1.5 | P24: 1.5 | Q24: 1 | S24: 1.5 | T24: 1.5 | U24: 1.5 | V24: 2 | W24: 1 | AA24: 1 | AB24: 1 | AC24: 2 | AD24: 2 | AE24: 1 | AG24: 1.5 | AH24: 2 | AI24: 2 | AJ24: 2 | AK24: 2 | AL24: 1 | AN24: =SUM(I24:AM24) -> 33 | AO24: 210000 | AP24: =AN24*AO24 -> 6930000
A25: 20 | B25: 김윤하 | C25: 860417-1348219 | D25: 배관공 | E25: 010-4807-9031 | F25: 국민 | G25: 김윤하 | H25: 263102-04-214815 | N25: 1.5 | O25: 1.5 | P25: 1.5 | Q25: 1 | S25: 1.5 | T25: 1.5 | U25: 1.5 | V25: 2 | W25: 2 | X25: 1 | Z25: 1 | AA25: 1 | AB25: 1 | AC25: 2 | AD25: 2 | AE25: 1 | AH25: 2 | AI25: 2 | AJ25: 2 | AK25: 2 | AL25: 1 | AN25: =SUM(I25:AM25) -> 32 | AO25: 210000 | AP25: =AN25*AO25 -> 6720000
A26: 21 | B26: 김재호 | C26: 740417-1691211 | D26: 배관공 | E26: 010-7903-8334 | F26: 수협 | G26: 김재호 | H26: 0010-2858-8334 | L26: 1.5 | N26: 1.5 | O26: 1.5 | P26: 1.5 | Q26: 1 | S26: 1.5 | T26: 1.5 | U26: 1.5 | V26: 2 | W26: 2 | Z26: 1 | AA26: 1 | AB26: 1 | AC26: 2 | AD26: 2 | AG26: 1.5 | AH26: 2 | AI26: 2 | AJ26: 2 | AK26: 2 | AL26: 1 | AN26: =SUM(I26:AM26) -> 33 | AO26: 230000 | AP26: =AN26*AO26 -> 7590000
A27: 22 | B27: 김정천 | C27: 010314-3837113 | D27: 보통인부 | E27: 010-2210-3629 | F27: 카카오 | G27: 김정천 | H27: 3333-14-2904871 | J27: 1 | L27: 1.5 | N27: 1.5 | O27: 1.5 | P27: 1.5 | Q27: 0.875 | S27: 1.5 | T27: 1.5 | U27: 1.5 | V27: 2 | W27: 1.375 | X27: 0.75 | Z27: 1 | AA27: 1 | AB27: 1 | AC27: 2 | AD27: 2 | AE27: 1 | AG27: 1.5 | AH27: 2 | AI27: 2 | AJ27: 2 | AK27: 2 | AL27: 1 | AN27: =SUM(I27:AM27) -> 35 | AO27: 150000 | AP27: =AN27*AO27 -> 5250000
A28: 23 | B28: 김태훈 | C28: 810515-1814611 | D28: 보통인부 | E28: 010-5844-3098 | F28: 농협 | G28: 김태훈 | H28: 793-12-097221 | L28: 1.5 | N28: 1.5 | O28: 1.5 | P28: 1.5 | S28: 1.5 | T28: 1.5 | U28: 1.5 | V28: 2 | W28: 2 | X28: 1 | Z28: 1 | AA28: 1 | AB28: 1 | AC28: 2 | AD28: 2 | AG28: 1.5 | AH28: 2 | AI28: 2 | AJ28: 2 | AK28: 2 | AL28: 1 | AN28: =SUM(I28:AM28) -> 33 | AO28: 150000 | AP28: =AN28*AO28 -> 4950000
A29: 24 | B29: 김현규 | C29: 921116-1163211 | D29: 공사보조 | E29: 010-9150-0018 | F29: 국민 | G29: 김현규 | H29: 920302-01-333030 | J29: 1 | L29: 1.5 | N29: 1.5 | O29: 1.5 | S29: 1.5 | T29: 1.5 | U29: 1.5 | V29: 2 | W29: 2 | X29: 1 | Z29: 1 | AA29: 1 | AB29: 1 | AC29: 2 | AD29: 2 | AE29: 1 | AG29: 1.5 | AH29: 2 | AI29: 2 | AJ29: 2 | AK29: 2 | AL29: 1 | AN29: =SUM(I29:AM29) -> 33.5 | AO29: 170000 | AP29: =AN29*AO29 -> 5695000
A30: 25 | B30: 김현수 | C30: 960703-1675511 | D30: 보통인부 | E30: 010-7760-4917 | F30: IM뱅크 | G30: 김현수 | H30: 143-13-132971 | N30: 1.5 | O30: 1.5 | P30: 1.5 | Q30: 1 | S30: 1.375 | T30: 1.5 | U30: 2 | V30: 2 | W30: 2 | AA30: 1 | AB30: 1 | AC30: 2 | AD30: 2 | AE30: 1 | AG30: 1.5 | AH30: 2 | AI30: 2 | AJ30: 2 | AK30: 2 | AL30: 0.5 | AN30: =SUM(I30:AM30) -> 31.375 | AO30: 160000 | AP30: =AN30*AO30 -> 5020000
A31: 26 | B31: 김현재 | C31: 700202-1057315 | D31: 보통인부 | E31: 010-9062-6693 | F31: 국민 | G31: 김현재 | H31: 040001-04-096857 | L31: 1.5 | N31: 1.5 | O31: 1.5 | P31: 1.5 | Q31: 0.5 | S31: 1.5 | T31: 1.5 | U31: 1.5 | V31: 2 | W31: 2 | Z31: 1 | AA31: 1 | AB31: 1 | AC31: 2 | AD31: 2 | AG31: 1.5 | AH31: 2 | AI31: 2 | AJ31: 2 | AK31: 0.5 | AL31: 1 | AN31: =SUM(I31:AM31) -> 31 | AO31: 160000 | AP31: =AN31*AO31 -> 4960000
A32: 27 | B32: 김형식 | C32: 910612-1075819 | D32: 보통인부 | E32: 010-7340-6771 | F32: 기업 | G32: 김형식 | H32: 052-096995-01-018 | L32: 1.5 | N32: 1.5 | O32: 1.5 | S32: 1.5 | T32: 1.5 | U32: 1.5 | V32: 0.5 | Z32: 1 | AB32: 1 | AC32: 2 | AG32: 1.5 | AH32: 1.5 | AI32: 2 | AN32: =SUM(I32:AM32) -> 18.5 | AO32: 150000 | AP32: =AN32*AO32 -> 2775000
A33: 28 | B33: 남희수 | C33: 741212-1068534 | D33: 보통인부 | E33: 010-8994-9296 | F33: 국민 | G33: 남희수 | H33: 547201-01-029724 | N33: 1.5 | O33: 1.5 | P33: 1.5 | S33: 1.5 | T33: 1.5 | U33: 1.5 | V33: 2 | W33: 2 | X33: 1 | Z33: 1 | AA33: 1 | AB33: 1 | AC33: 2 | AD33: 2 | AE33: 1 | AG33: 1.5 | AH33: 2 | AI33: 2 | AJ33: 2 | AK33: 2 | AL33: 1 | AN33: =SUM(I33:AM33) -> 32.5 | AO33: 160000 | AP33: =AN33*AO33 -> 5200000
A34: 29 | B34: 도남철 | C34: 681003-1683610 | D34: 보통인부 | E34: 010-3734-2196 | F34: 새마을 | G34: 도남철 | H34: 9002-1869-8588-9 | J34: 1 | L34: 1.5 | N34: 1.5 | O34: 1.5 | P34: 1.5 | Q34: 1 | S34: 1.5 | T34: 1.5 | U34: 1.5 | V34: 2 | W34: 2 | X34: 1 | AA34: 1 | AB34: 1 | AC34: 2 | AD34: 2 | AE34: 1 | AG34: 1.5 | AH34: 2 | AI34: 2 | AJ34: 2 | AK34: 2 | AL34: 1 | AN34: =SUM(I34:AM34) -> 35 | AO34: 150000 | AP34: =AN34*AO34 -> 5250000
A35: 30 | B35: 박동은 | C35: 740428-1777929 | D35: 보통인부 | E35: 010-8240-5009 | F35: 농협 | G35: 박동은 | H35: 717-12-084497 | L35: 1.5 | N35: 1.5 | O35: 1.5 | P35: 1.5 | Q35: 1 | S35: 1.5 | T35: 1.5 | U35: 1.5 | V35: 2 | W35: 2 | X35: 1 | Z35: 1 | AA35: 1 | AB35: 1 | AC35: 2 | AD35: 2 | AE35: 1 | AG35: 1.5 | AH35: 2 | AI35: 2 | AJ35: 2 | AK35: 2 | AL35: 1 | AN35: =SUM(I35:AM35) -> 35 | AO35: 180000 | AP35: =AN35*AO35 -> 6300000
A36: 31 | B36: 박민우 | C36: 841026-1531716 | D36: 배관공 | E36: 010-4768-4757 | F36: 국민 | G36: 박민우 | H36: 673002-01-201903 | N36: 1.5 | O36: 1.5 | P36: 1.5 | S36: 1.5 | T36: 1.5 | U36: 2 | V36: 2 | W36: 2 | AA36: 1 | AB36: 1 | AC36: 2 | AD36: 2 | AH36: 2 | AI36: 2 | AJ36: 2 | AK36: 2 | AN36: =SUM(I36:AM36) -> 27.5 | AO36: 220000 | AP36: =AN36*AO36 -> 6050000
A37: 32 | B37: 박성근 | C37: 850811-1526610 | D37: 배관공 | E37: 010-9463-2277 | F37: 농협 | G37: 박성근 | H37: 352-0406-9764-83 | L37: 2.5 | M37: 2 | N37: 2 | O37: 2 | P37: 2 | S37: 2 | T37: 2 | U37: 2 | V37: 2 | W37: 2 | AN37: =SUM(I37:AM37) -> 20.5 | AO37: 220000 | AP37: =AN37*AO37 -> 4510000
A38: 33 | B38: 박성호 | C38: 941107-1199714 | D38: 배관공 | E38: 010-2922-3403 | F38: 기업 | G38: 박성호 | H38: 450-033865-01-013 | L38: 1.5 | N38: 1.5 | O38: 1.5 | P38: 1.5 | S38: 1.5 | T38: 1.5 | U38: 1.5 | V38: 2 | W38: 2 | Z38: 1 | AA38: 1 | AB38: 1 | AC38: 2 | AD38: 2 | AE38: 1 | AG38: 1.5 | AH38: 2 | AI38: 2 | AJ38: 2 | AK38: 2 | AL38: 0.5 | AN38: =SUM(I38:AM38) -> 32.5 | AO38: 180000 | AP38: =AN38*AO38 -> 5850000
A39: 34 | B39: 박세호 | C39: 830125-1674711 | D39: 용접공 | E39: 010-8898-7171 | F39: 카카오 | G39: 박세호 | H39: 3333-21-7116487 | L39: 1.5 | N39: 1.5 | O39: 1.5 | P39: 1.5 | Q39: 1 | S39: 1.5 | T39: 1.5 | U39: 1.5 | V39: 2 | W39: 2 | X39: 1 | Z39: 1 | AA39: 1 | AB39: 1 | AC39: 2 | AD39: 2 | AG39: 1.5 | AH39: 2 | AI39: 2 | AJ39: 2 | AK39: 2 | AL39: 1 | AN39: =SUM(I39:AM39) -> 34 | AO39: 240000 | AP39: =AN39*AO39 -> 8160000
A40: 35 | B40: 박승남 | C40: 730316-1654417 | D40: 보통인부 | E40: 010-7618-6130 | F40: 농협 | G40: 박승남 | H40: 211065-56-138642 | L40: 1.5 | N40: 1.5 | O40: 1.5 | P40: 1.5 | S40: 1.5 | T40: 1.5 | U40: 1.5 | V40: 2 | W40: 2 | Z40: 1 | AA40: 1 | AB40: 1 | AC40: 2 | AD40: 2 | AE40: 1 | AG40: 1.5 | AH40: 2 | AI40: 2 | AJ40: 2 | AK40: 2 | AL40: 1 | AN40: =SUM(I40:AM40) -> 33 | AO40: 150000 | AP40: =AN40*AO40 -> 4950000
A41: 36 | B41: 박안서 | C41: 810228-1469327 | D41: 용접공 | E41: 010-3690-0417 | F41: 우리 | G41: 박안서 | H41: 1002-040-987874 | N41: 1.5 | O41: 1.5 | Q41: 1 | S41: 1.5 | U41: 1.5 | V41: 2 | W41: 2 | X41: 1 | Z41: 1 | AA41: 1 | AB41: 1 | AC41: 2 | AD41: 2 | AE41: 1 | AG41: 1.5 | AH41: 2 | AI41: 2 | AJ41: 2 | AK41: 2 | AN41: =SUM(I41:AM41) -> 29.5 | AO41: 240000 | AP41: =AN41*AO41 -> 7080000
...

Sheet 용접기자재
A1: 용접 기자재
A2: No | B2: 구매일 | C2: 구분 | D2: 품명 | E2: 규격 | F2: 거래처명 | G2: 발주수량 | H2: 단가 | I2: 합계 | J2: 비고
I3: =ROUND(SUM(I4:I82),) -> 269800
A4: =ROW()-3 -> 1 | B4: 46148 | C4: 소모품비 | D4: 알곤용접봉 | E4: [TGC50S.2.4mm,5kg [조선선재]] | F4: 미래공구 | G4: 1 | H4: 23400 | I4: 23400 | L4: 입력해야하는 항목 외 수정 금지
A5: =ROW()-3 -> 2 | B5: 46148 | C5: 소모품비 | D5: 알곤용접봉 | E5: [TGC50S.3.2mm,5kg [조선선재]] | F5: 미래공구 | G5: 1 | H5: 23400 | I5: 23400 | L5: 입력항목
A6: =ROW()-3 -> 3 | B6: 46148 | C6: 소모품비 | D6: 알곤스위치 | E6: [350A [조영]] | F6: 미래공구 | G6: 10 | H6: 2500 | I6: 25000 | L6: 구매일
A7: =ROW()-3 -> 4 | B7: 46154 | C7: 소모품비 | D7: 알곤용접봉 | E7: [TGC308L.2.4mm,5kg [조선선재]] | F7: 미래공구 | G7: 2 | H7: 71500 | I7: 143000 | L7: 구분
A8: =ROW()-3 -> 5 | B8: 46155 | C8: 소모품비 | D8: 알곤캡 | E8: [중캡,CTX [크레토스]] | F8: 미래공구 | G8: 10 | H8: 600 | I8: 6000 | L8: 품명
A9: =ROW()-3 -> 6 | B9: 46168 | C9: 소모품비 | D9: 알곤토치헤드 | E9: [350A,플렉시블,CT-35F,CTX [크레토스]] | F9: 미래공구 | G9: 5 | H9: 9800 | I9: 49000 | L9: 규격
L10: 거래처명
L11: 발주수량
L12: 단가
L14: ■ 구분은 [소모성자재, 공구, 임대(공구), 안전용품, 비품] 이외 항목은 입력금지

Sheet 배관기자재
A1: 배관 기자재
A2: No | B2: 구매일 | C2: 구분 | D2: 품명 | E2: 규격 | F2: 거래처명 | G2: 발주수량 | H2: 단가 | I2: 합계 | J2: 비고
I3: =ROUND(SUM(I4:I66),) -> 2325791 | L3: 입력해야하는 항목 외 수정 금지
A4: =ROW()-3 -> 1 | B4: 46155 | C4: 소모품비 | D4: 투명지퍼백 | E4: 25*35 | F4: 네이버파이낸셜㈜ | G4: 10 | H4: 8000 | I4: 80000 | L4: 입력항목
A5: =ROW()-3 -> 2 | B5: 46155 | C5: 소모품비 | D5: 투명지퍼백 | E5: 35*40 | F5: 네이버파이낸셜㈜ | G5: 5 | H5: 12272.727 | I5: 61363.636 | L5: 구매일
A6: =ROW()-3 -> 3 | B6: 46164 | C6: 소모품비 | D6: 면보루 | E6: 5kg | F6: 네이버파이낸셜㈜ | G6: 3 | H6: 9090.9091 | I6: 27272.727 | L6: 구분
A7: =ROW()-3 -> 4 | B7: 46170 | C7: 소모품비 | D7: 면보루 | E7: 5kg | F7: 네이버파이낸셜㈜ | G7: 2 | H7: 9545.4545 | I7: 19090.909 | L7: 품명
A8: =ROW()-3 -> 5 | B8: 46170 | C8: 소모품비 | D8: 라인테이프 | E8: 48mm*30m | F8: 마루한길 | G8: 50 | H8: 1800 | I8: 90000 | L8: 규격
A9: =ROW()-3 -> 6 | B9: 46148 | C9: 소모품비 | D9: 페인트롤러 | E9: [2"] | F9: 미래공구 | G9: 5 | H9: 1400 | I9: 7000 | L9: 거래처명
A10: =ROW()-3 -> 7 | B10: 46148 | C10: 소모품비 | D10: 페인트롤러 | E10: [3" [동양]] | F10: 미래공구 | G10: 5 | H10: 1400 | I10: 7000 | L10: 발주수량
A11: =ROW()-3 -> 8 | B11: 46149 | C11: 비품 | D11: 쓰레받이 | E11: [외각,CTX [리빙엔젤]] | F11: 미래공구 | G11: 2 | H11: 6000 | I11: 12000 | L11: 단가
A12: =ROW()-3 -> 9 | B12: 46149 | C12: 비품 | D12: 빗자루 | E12: [갈대비 [수입/HNS]] | F12: 미래공구 | G12: 2 | H12: 3500 | I12: 7000
A13: =ROW()-3 -> 10 | B13: 46149 | C13: 소모품비 | D13: 마대 | E13: [PP,신재 [국산/SW]] | F13: 미래공구 | G13: 30 | H13: 500 | I13: 15000 | N13: ■ 구분은 [소모성자재, 공구, 임대(공구), 안전용품, 비품] 이외 항목은 입력금지
A14: =ROW()-3 -> 11 | B14: 46149 | C14: 소모품비 | D14: 컷쏘날 | E14: [21098-9114G,5개입 [레녹스]] | F14: 미래공구 | G14: 1 | H14: 30000 | I14: 30000
A15: =ROW()-3 -> 12 | B15: 46153 | C15: 소모품비 | D15: 케이블타이 | E15: [릴리져블타이,270mm(1봉=500개),청색 [전오]] | F15: 미래공구 | G15: 3 | H15: 24400 | I15: 73200
A16: =ROW()-3 -> 13 | B16: 46153 | C16: 소모품비 | D16: 볼소켓어댑터 | E16: [13mm(1/2"),CTX [지니어스]] | F16: 미래공구 | G16: 8 | H16: 2700 | I16: 21600
A17: =ROW()-3 -> 14 | B17: 46153 | C17: 소모품비 | D17: 우의 | E17: [SW-502,고급형,투피스,XXXL [크래커]] | F17: 미래공구 | G17: 2 | H17: 8700 | I17: 17400
A18: =ROW()-3 -> 15 | B18: 46154 | C18: 소모품비 | D18: 튜브컷터날 | E18: [TCBC105 [슈퍼]] | F18: 미래공구 | G18: 3 | H18: 10000 | I18: 30000
A19: =ROW()-3 -> 16 | B19: 46154 | C19: 소모품비 | D19: 튜브컷터날 | E19: [7.0028(7.0031용) [로덴베르거]] | F19: 미래공구 | G19: 6 | H19: 8400 | I19: 50400
A20: =ROW()-3 -> 17 | B20: 46155 | C20: 소모품비 | D20: 낙상경보기부품 | E20: [풀피리] | F20: 미래공구 | G20: 100 | H20: 100 | I20: 10000
A21: =ROW()-3 -> 18 | B21: 46155 | C21: 소모품비 | D21: 롱핸드소켓 | E21: [1/2"*15mm [킹토니]] | F21: 미래공구 | G21: 4 | H21: 4400 | I21: 17600
A22: =ROW()-3 -> 19 | B22: 46155 | C22: 소모품비 | D22: 양면테이프 | E22: [50mm*6m,핫멧트 [HNS]] | F22: 미래공구 | G22: 30 | H22: 800 | I22: 24000
A23: =ROW()-3 -> 20 | B23: 46156 | C23: 소모품비 | D23: 컷쏘날 | E23: [S1122BF,철재,바이메탈,5개입 [보쉬]] | F23: 미래공구 | G23: 3 | H23: 19000 | I23: 57000
A24: =ROW()-3 -> 21 | B24: 46156 | C24: 소모품비 | D24: 다이아몬드줄 | E24: [200mm,반원 [삼익]] | F24: 미래공구 | G24: 10 | H24: 9500 | I24: 95000
A25: =ROW()-3 -> 22 | B25: 46157 | C25: 소모품비 | D25: 볼소켓어댑터 | E25: [13mm(1/2"),CTX [지니어스]] | F25: 미래공구 | G25: 10 | H25: 2500 | I25: 25000
... A50: =ROW()-3 -> 47 | B50: 46171 | C50: 소모품비 | D50: 컷쏘날 | E50: [S1122BF,철재,바이메탈,5개입 [보쉬]] | F50: 미래공구 | G50: 6 | H50: 19000 | I50: 114000
A51: =ROW()-3 -> 48 | B51: 46149 | C51: 안전용품 | D51: 백팩 | F51: 십일번가 주식회사 | G51: 30 | H51: 909.09091 | I51: 27272.727
A52: =ROW()-3 -> 49 | B52: 46156 | C52: 소모품비 | D52: 탭 | F52: 진위공구철물 | G52: 1 | H52: 55000 | I52: 55000
A53: =ROW()-3 -> 50 | B53: 46170 | C53: 소모품비 | D53: P2454 스파이럴탭 | E53: M10 | F53: 진위공구철물 | G53: 5 | H53: 11000 | I53: 55000
A54: =ROW()-3 -> 51 | B54: 46162 | C54: 소모품비 | D54: 스크레퍼 | F54: 쿠팡㈜ | G54: 1 | H54: 17000 | I54: 17000
A55: =ROW()-3 -> 52 | B55: 46164 | C55: 소모품비 | D55: 스크레퍼 | F55: 쿠팡㈜ | G55: 3 | H55: 15181.818 | I55: 45545.455
A56: =ROW()-3 -> 53 | B56: 46168 | C56: 안전용품 | D56: 크린룸가방 | F56: 쿠팡㈜ | G56: 1 | H56: 29545.455 | I56: 29545.455

Sheet 숙소임차료
A1: 숙소 임차료
A2: No. | B2: 납부일 | C2: 구분 | D2: 품명 | E2: 주소 | F2: 호수 | G2: 수량 | H2: 사용인원 | I2: 임차료 | J2: 비 고
I3: =SUM(I4:I21) -> 16867742 | L3: 입력해야하는 항목 외 수정 금지
A4: =ROW()-3 -> 1 | B4: 46173 | C4: KC대납 임대료 | D4: 숙소임대료(5월분) | E4: 함박산1길 16 | F4: 301호 | G4: 1 | I4: =800000 -> 800000 | J4: KC 대납 | L4: 납부일
A5: =ROW()-3 -> 2 | B5: 46173 | C5: KC대납 임대료 | D5: 숙소임대료(5월분) | E5: 함박산8길 37 | F5: 302호 | G5: 1 | I5: =800000/31*22 -> 567741.94 | J5: KC 대납 | L5: 구분
A6: =ROW()-3 -> 3 | B6: 46173 | C6: KC대납 임대료 | D6: 숙소임대료(5월분) | E6: 함박산9길 8-1 | F6: 201호 | G6: 1 | I6: =850000 -> 850000 | J6: KC 대납 | L6: 품명
A7: =ROW()-3 -> 4 | B7: 46173 | C7: KC대납 임대료 | D7: 숙소임대료(5월분) | E7: 함박산12길 8-10 | F7: 301호 | G7: 1 | I7: =950000 -> 950000 | J7: KC 대납 | L7: 주소
A8: =ROW()-3 -> 5 | B8: 46173 | C8: KC대납 임대료 | D8: 숙소임대료(5월분) | E8: 함박산10길 19 | F8: 201호 | G8: 1 | I8: =1000000 -> 1000000 | J8: KC 대납 | L8: 호수
A9: =ROW()-3 -> 6 | B9: 46173 | C9: KC대납 임대료 | D9: 숙소임대료(5월분) | E9: 함박산10길 19 | F9: 301호 | G9: 1 | I9: =1000000 -> 1000000 | J9: KC 대납 | L9: 수량
A10: =ROW()-3 -> 7 | B10: 46173 | C10: KC대납 임대료 | D10: 숙소임대료(5월분) | E10: 고덕여염6길 108 | F10: 302호 | G10: 1 | I10: =1000000 -> 1000000 | J10: KC 대납 | L10: 사용인원
A11: =ROW()-3 -> 8 | B11: 46173 | C11: KC대납 임대료 | D11: 숙소임대료(5월분) | E11: 고덕여염5길 23-16 | F11: 402호 | G11: 1 | I11: =850000 -> 850000 | J11: KC 대납
A12: =ROW()-3 -> 9 | B12: 46173 | C12: KC대납 임대료 | D12: 숙소임대료(5월분) | E12: 고덕여염12길 92 | F12: 202호 | G12: 1 | I12: =850000 -> 850000 | J12: KC 대납 | L12: ■ 구분은 [KC대납 임대료 및 임대료] 이외 항목은 입력금지
A13: =ROW()-3 -> 10 | B13: 46173 | C13: KC대납 임대료 | D13: 숙소임대료(5월분) | E13: 고덕여염16길 32 | F13: 202호 | G13: 1 | I13: =850000 -> 850000 | J13: KC 대납
A14: =ROW()-3 -> 11 | B14: 46173 | C14: KC대납 임대료 | D14: 숙소임대료(5월분) | E14: 고덕여염 5길 15-10 | F14: 301호 | G14: 1 | I14: =1000000 -> 1000000 | J14: KC 대납
A15: =ROW()-3 -> 12 | B15: 46173 | C15: KC대납 임대료 | D15: 숙소임대료(5월분) | E15: 고덕여염 5길 15-10 | F15: 201호 | G15: 1 | I15: =1000000 -> 1000000 | J15: KC 대납
A16: =ROW()-3 -> 13 | B16: 46173 | C16: KC대납 임대료 | D16: 숙소임대료(5월분) | E16: 고덕여염 5길 15-10 | F16: 202호 | G16: 1 | I16: =1000000 -> 1000000 | J16: KC 대납
A17: =ROW()-3 -> 14 | B17: 46173 | C17: KC대납 임대료 | D17: 숙소임대료(5월분) | E17: 고덕 갈평10길 67 | F17: 201호 | G17: 1 | I17: =950000 -> 950000 | J17: KC 대납
A18: =ROW()-3 -> 15 | B18: 46173 | C18: KC대납 임대료 | D18: 숙소임대료(5월분) | E18: 고덕 갈평9길 43 | F18: 202호 | G18: 1 | I18: =1000000 -> 1000000 | J18: KC 대납
A19: =ROW()-3 -> 16 | B19: 46173 | C19: KC대납 임대료 | D19: 숙소임대료(5월분) | E19: 함박산2길 32-2 | F19: 201호 | G19: 1 | I19: =1000000 -> 1000000 | J19: KC 대납
A20: =ROW()-3 -> 17 | B20: 46173 | C20: KC대납 임대료 | D20: 숙소임대료(5월분) | E20: 고덕갈평7길 61 | F20: 301호 | G20: 1 | I20: =1100000 -> 1100000 | J20: KC 대납
A21: =ROW()-3 -> 18 | B21: 46173 | C21: KC대납 임대료 | D21: 숙소임대료(5월분) | E21: 함박산4길 20 | F21: 202호 | G21: 1 | I21: =1100000 -> 1100000 | J21: KC 대납

Sheet 숙소관리비
A1: 숙소 관리비
A2: No. | B2: 납부일 | C2: 구분 | D2: 품명 | E2: 주소 | F2: 호수 | G2: 수량 | H2: 사용인원 | I2: 임차료 | J2: 비 고
I3: =SUM(I4:I58) -> 2704690
A4: =ROW()-3 -> 1 | B4: 46173 | C4: 관리비 | D4: 숙소전기요금(5월) | E4: 함박산1길 16 | F4: 301호 | G4: 1 | I4: 31460
A5: =ROW()-3 -> 2 | B5: 46173 | C5: 관리비 | D5: 숙소전기요금(5월) | E5: 함박산9길 8-1 | F5: 201호 | G5: 1 | I5: 26920
A6: =ROW()-3 -> 3 | B6: 46173 | C6: 관리비 | D6: 숙소전기요금(5월) | E6: 함박산12길 8-10 | F6: 301호 | G6: 1 | I6: 33720
A7: =ROW()-3 -> 4 | B7: 46173 | C7: 관리비 | D7: 숙소전기요금(5월) | E7: 함박산10길 19 | F7: 201호 | G7: 1 | I7: 12950
A8: =ROW()-3 -> 5 | B8: 46173 | C8: 관리비 | D8: 숙소전기요금(5월) | E8: 함박산10길 19 | F8: 301호 | G8: 1 | I8: 17180
A9: =ROW()-3 -> 6 | B9: 46173 | C9: 관리비 | D9: 숙소전기요금(5월) | E9: 고덕여염6길 108 | F9: 302호 | G9: 1 | I9: 39730
A10: =ROW()-3 -> 7 | B10: 46173 | C10: 관리비 | D10: 숙소전기요금(5월) | E10: 고덕여염5길 23-16 | F10: 402호 | G10: 1 | I10: 16200
A11: =ROW()-3 -> 8 | B11: 46173 | C11: 관리비 | D11: 숙소전기요금(5월) | E11: 고덕여염12길 92 | F11: 202호 | G11: 1 | I11: 14390
A12: =ROW()-3 -> 9 | B12: 46173 | C12: 관리비 | D12: 숙소전기요금(5월) | E12: 고덕여염16길 32 | F12: 202호 | G12: 1 | I12: 61040
A13: =ROW()-3 -> 10 | B13: 46173 | C13: 관리비 | D13: 숙소전기요금(5월) | E13: 고덕여염 5길 15-10 | F13: 301호 | G13: 1 | I13: 26170
A14: =ROW()-3 -> 11 | B14: 46173 | C14: 관리비 | D14: 숙소전기요금(5월) | E14: 고덕여염 5길 15-10 | F14: 201호 | G14: 1 | I14: 21180
A15: =ROW()-3 -> 12 | B15: 46173 | C15: 관리비 | D15: 숙소전기요금(5월) | E15: 고덕여염 5길 15-10 | F15: 202호 | G15: 1 | I15: 20430
... A58: =ROW()-3 -> 55 | B58: 46173 | C58: 관리비 | D58: 청소비(5월) | E58: 함박산8길 37 | F58: 302호 | G58: 1 | I58: 250000

Sheet 식대비용
A1: 식대 비용
A2: No. | B2: 납부일 | C2: 구분 | D2: 품명 | E2: 거래처명 | F2: 수량 | G2: 식수인원 | H2: 단가 | I2: 합 계 | J2: 비 고
I3: =SUM(I4:I10) -> 34475819 | L3: 입력해야하는 항목 외 수정 금지
A4: =ROW()-3 -> 1 | B4: 46167 | C4: KC대납 식대 | D4: 기술인및관리자 (현장 식당) | E4: 태정위드유 주식회사 | F4: 1 | H4: 1221818 | I4: =F4*H4 -> 1221818 | J4: KC 대납 | L4: 입력항목
A5: =ROW()-3 -> 2 | B5: 46167 | C5: KC대납 식대 | D5: 기술인및관리자 (현장 식당) | E5: 다모아한식뷔페 | F5: 70 | H5: 7000 | I5: =F5*H5 -> 490000 | J5: KC 대납 | L5: 납부일
A6: =ROW()-3 -> 3 | B6: 46167 | C6: KC대납 식대 | D6: 기술인및관리자 (현장 식당) | E6: 영미손김밥 | F6: 1 | H6: 1937273 | I6: =F6*H6 -> 1937273 | J6: KC 대납 | L6: 구분
A7: =ROW()-3 -> 4 | B7: 46167 | C7: KC대납 식대 | D7: 기술인및관리자 (현장 식당) | E7: 옛날장터 | F7: 4168 | H7: 7000 | I7: =F7*H7 -> 29176000 | J7: KC 대납 | L7: 품명
A8: =ROW()-3 -> 5 | B8: 46167 | C8: KC대납 식대 | D8: 기술인및관리자 (현장 식당) | E8: 은주네한식뷔페 | F8: 65 | H8: 7000 | I8: =F8*H8 -> 455000 | J8: KC 대납 | L8: 거래처명
A9: =ROW()-3 -> 6 | B9: 46167 | C9: KC대납 식대 | D9: 기술인및관리자 (현장 식당) | E9: 삼성김밥 | F9: 1 | H9: 1046273 | I9: =F9*H9 -> 1046273 | J9: KC 대납 | L9: 수량
A10: =ROW()-3 -> 7 | B10: 46167 | C10: KC대납 식대 | D10: 기술인및관리자 (현장 식당) | E10: 한솥 | F10: 1 | H10: 149455 | I10: =F10*H10 -> 149455 | J10: KC 대납 | L10: 식수인원
A11: =ROW()-3 -> 8 | B11: 46173 | C11: 식대 | E11: 법인카드 | F11: 1 | H11: 2547636 | I11: =F11*H11 -> 2547636 | L11: 단가
L13: ■ 구분은 [KC대납 식대 및 식대] 이외 항목은 입력금지

Sheet 기타비용
A1: 기타 비용
A2: No. | B2: 구매일 | C2: 구분 | D2: 품명 | E2: 거래처명 | F2: 수량 | G2: 단가 | H2: 합계 | I2: 비고
H3: =SUM(H4:H28) -> 953690.91 | K3: 입력해야하는 항목 외 수정 금지
A4: =ROW()-3 -> 1 | B4: 46146 | C4: 차량유류대 | D4: 85어 5471 포터2 | E4: SB새벽주유소 | F4: 1 | G4: 63636.364 | H4: =F4*G4 -> 63636.364 | K4: 입력항목
A5: =ROW()-3 -> 2 | B5: 46149 | C5: 차량유류대 | D5: 85어 5471 포터2 | E5: 남사농업협동조합 | F5: 1 | G5: 63636.364 | H5: =F5*G5 -> 63636.364 | K5: 구매일
A6: =ROW()-3 -> 3 | B6: 46153 | C6: 차량유류대 | D6: 85어 5471 포터2 | E6: 청원로셀프주유소 | F6: 1 | G6: 63636.364 | H6: =F6*G6 -> 63636.364 | K6: 구분
A7: =ROW()-3 -> 4 | B7: 46154 | C7: 차량유류대 | D7: 85어 5471 포터2 | E7: (주)소모 칠곡주유소 | F7: 1 | G7: 63636.364 | H7: =F7*G7 -> 63636.364 | K7: 품명
A8: =ROW()-3 -> 5 | B8: 46154 | C8: 차량유류대 | D8: 85어 5471 포터2 | E8: (주)소모 칠곡주유소 | F8: 1 | G8: 13636.364 | H8: =F8*G8 -> 13636.364 | I8: 요소수 | K8: 거래처명
A9: =ROW()-3 -> 6 | B9: 46156 | C9: 차량유류대 | D9: 85어 5471 포터2 | E9: (주)소모 칠곡주유소 | F9: 1 | G9: 63636.364 | H9: =F9*G9 -> 63636.364 | K9: 수량
A10: =ROW()-3 -> 7 | B10: 46157 | C10: 차량유류대 | D10: 85어 5471 포터2 | E10: (주)소모 칠곡주유소 | F10: 1 | G10: 45454.545 | H10: =F10*G10 -> 45454.545 | K10: 단가
A11: =ROW()-3 -> 8 | B11: 46161 | C11: 차량유류대 | D11: 85어 5471 포터2 | E11: (주)소모 칠곡주유소 | F11: 1 | G11: 63636.364 | H11: =F11*G11 -> 63636.364
A12: =ROW()-3 -> 9 | B12: 46163 | C12: 차량유류대 | D12: 85어 5471 포터2 | E12: (주)소모 칠곡주유소 | F12: 1 | G12: 63636.364 | H12: =F12*G12 -> 63636.364 | K12: ■ 구분은 [사무용품, 소모품비, 법인카드] 이외 항목은 입력금지
A13: =ROW()-3 -> 10 | B13: 46164 | C13: 차량유류대 | D13: 85어 5471 포터2 | E13: (주)소모 칠곡주유소 | F13: 1 | G13: 54545.455 | H13: =F13*G13 -> 54545.455
A14: =ROW()-3 -> 11 | B14: 46168 | C14: 차량유류대 | D14: 85어 5471 포터2 | E14: (주)소모 칠곡주유소 | F14: 1 | G14: 63636.364 | H14: =F14*G14 -> 63636.364
A15: =ROW()-3 -> 12 | B15: 46170 | C15: 차량유류대 | D15: 85어 5471 포터2 | E15: (주)소모 칠곡주유소 | F15: 1 | G15: 63636.364 | H15: =F15*G15 -> 63636.364
A16: =ROW()-3 -> 13 | B16: 46149 | C16: 소모품비 | D16: 네임펜 | E16: 쿠팡㈜ | F16: 24 | G16: 493.93939 | H16: 11854.545
A17: =ROW()-3 -> 14 | B17: 46149 | C17: 소모품비 | D17: 네임펜 | E17: 쿠팡㈜ | F17: 24 | G17: 333.71212 | H17: 8009.0909
A18: =ROW()-3 -> 15 | B18: 46149 | C18: 소모품비 | D18: 보드마카 | E18: 쿠팡㈜ | F18: 24 | G18: 174.24242 | H18: 4181.8182
A19: =ROW()-3 -> 16 | B19: 46150 | C19: 소모품비 | D19: 유성매직 | E19: 쿠팡㈜ | F19: 12 | G19: 530.30303 | H19: 6363.6364
A20: =ROW()-3 -> 17 | B20: 46153 | C20: 소모품비 | D20: AA 건전지 | E20: 쿠팡㈜ | F20: 4 | G20: 10272.727 | H20: 41090.909
A21: =ROW()-3 -> 18 | B21: 46153 | C21: 소모품비 | D21: AA, AAA 건전지 | E21: 쿠팡㈜ | F21: 3 | G21: 13454.545 | H21: 40363.636
A22: =ROW()-3 -> 19 | B22: 46161 | C22: 소모품비 | D22: A4 코팅지 | E22: 쿠팡㈜ | F22: 5 | G22: 6203.6364 | H22: 31018.182
A23: =ROW()-3 -> 20 | B23: 46164 | C23: 비품 | D23: 멀티충전기 | E23: 쿠팡㈜ | F23: 1 | G23: 36181.818 | H23: 36181.818
A24: =ROW()-3 -> 21 | B24: 46168 | C24: 소모품비 | D24: AA 건전지 | E24: 쿠팡㈜ | F24: 3 | G24: 10818.182 | H24: 32454.545
A25: =ROW()-3 -> 22 | B25: 46168 | C25: 소모품비 | D25: AAA 건전지 | E25: 쿠팡㈜ | F25: 1 | G25: 28954.545 | H25: 28954.545
A26: =ROW()-3 -> 23 | B26: 46168 | C26: 소모품비 | D26: 보드마카 | E26: 쿠팡㈜ | F26: 1 | G26: 4272.7273 | H26: 4272.7273
A27: =ROW()-3 -> 24 | B27: 46168 | C27: 소모품비 | D27: 네임펜 | E27: 쿠팡㈜ | F27: 12 | G27: 493.93939 | H27: 5927.2727
A28: =ROW()-3 -> 25 | B28: 46170 | C28: 소모품비 | D28: 페인트 마카 | E28: 쿠팡㈜ | F28: 12 | G28: 1387.8788 | H28: 16654.545

Sheet 서명란
B2: 현 장 확 인 | C2: 소 장 | E2: (서명)
C3: 공 사 | E3: (서명)
C4: 공 무 | E4: (서명)
G6: 사 업 부 | H6: Frontier 사업부 GNP 본부장 | I6: BOC 센터장 | J6: Frontier 사업부장
L8: 본 사 | M8: 담 당 | N8: 검 토 | O8: 검 토
Q11: 구 분 | R11: 확 인
Q12: 품 질 | R12: O O O (인)
Q13: 공 무 | R13: O O O (인)

Sheet DIA-INCH
B3: SIZE
B4: A(mm) | C4: Inch
B5: 8A | C5: 0.25
B6: 15A | C6: 0.5
B7: 20A | C7: 0.75
B8: 25A | C8: 1
B9: 32A | C9: 1.25
B10: 40A | C10: 1.5
B11: 50A | C11: 2
B12: 65A | C12: 2.5
B13: 80A | C13: 3
B14: 100A | C14: 4
B15: 110A | C15: 4
B16: 125A | C16: 5
... B27: 550A | C27: 22
