Workbook
Name _: #REF!
Name _??_??_?C?g??: #REF!
Name ___DAT1: [1]원본!#REF!
Name ___DAT10: [1]원본!#REF!
Name ___DAT12: [1]원본!#REF!
Name ___DAT13: [1]원본!#REF!
Name ___DAT14: [1]원본!#REF!
Name ___DAT15: [1]원본!#REF!
Name ___DAT16: [1]원본!#REF!
Name ___DAT17: [1]원본!#REF!
Name ___DAT18: [1]원본!#REF!
Name ___DAT19: [1]원본!#REF!
Name ___DAT2: [1]원본!#REF!
Name ___DAT20: [1]원본!#REF!
Name ___DAT3: [1]원본!#REF!
Name ___DAT4: [1]원본!#REF!
Name ___DAT5: #REF!
Name ___DAT6: [1]원본!#REF!
Name ___DAT7: [1]원본!#REF!
Name ___DAT8: [1]원본!#REF!
Name ___DAT9: [1]원본!#REF!
Name ___QQ123: #REF!
Name __DAT11: #REF!
Name __DAT21: #REF!
Name __DAT22: #REF!
Name __DAT23: #REF!
Name __DAT24: #REF!
Name __DAT25: #REF!
Name __DAT26: #REF!
Name __DAT27: #REF!
Name __DAT28: #REF!
Name __P3: #REF!
Name __P4: #REF!
Name __P5: #REF!
Name __P6: #REF!
Name __PP1: #REF!
Name _0101__장비_설치공사: #REF!
Name _0201__소화_장비설치공사: #REF!
Name _1: #REF!
Name _1._PANEL_BD.__LP___1: #REF!
Name _1._옥외배관및장비설치공사: #REF!
Name _1_3_0Crite: #REF!
Name _10: [6]고정1!$A$416:$L$458
Name _10A_61: #N/A
Name _10A_62: #N/A
Name _10A_63: #N/A
Name _10A_64: #N/A
Name _10A_65: #N/A
Name _10A_66: #N/A
Name _10A_67: #N/A
Name _10A_68: #N/A
Name _10A_69: #N/A
Name _10A_70: #N/A
Name _10A_71: #N/A
Name _10A_72: #N/A
Name _10A_73: #N/A
Name _10A_74: #N/A
Name _10A_75: #N/A
Name _10A_76: #N/A
Name _10A_77: #N/A

Sheet 용역청구서 표지
B4: 용 역 청 구 서
B7: P4 Ph4 GAS 1공구 마감공사
C8: S25-004
C14: 2026년 02월
C15: ㈜태성하이텍

Sheet 용역 청구서(갑지)
A1: 용 역 청 구 서
A3: 1 | B3: 공 사 명 | C3: : | D3: ='용역청구서 표지'!$B$7 -> P4 Ph4 GAS 1공구 마감공사 | E3: ='용역청구서 표지'!$C$8 -> S25-004
A4: 2 | B4: 공 종 | C4: : | D4: 외주용역(M/M부분)
A5: 3 | B5: 계 약 금 액 | C5: : | D5: =ROUNDUP(E5,0) -> 80000000 | E5: =집계장!I22 -> 80000000 | F5: (VAT 별도)
A6: 4 | B6: 누 계 기 성 금 액 | C6: : | D6: =ROUNDUP(E6,0) -> 80000000 | E6: =E7+E13 -> 80000000 | F6: (VAT 별도)
A7: 5 | B7: 전 회 기 성 금 액 | C7: : | D7: =ROUNDUP(E7,0) -> 40000000 | E7: =집계장!G22 -> 40000000 | F7: (VAT 별도)
A8: 6 | B8: 금 회 기 성 금 액 | C8: : | D8: =ROUNDUP(E8,0) -> 40000001 | E8: =집계장!F18 -> 40000000 | F8: (VAT 별도)
A9: 7 | B9: 선 금 액 | C9: : | D9: =ROUNDUP(E9,0) -> 0 | E9: =집계장!K20 -> 0 | F9: (VAT 별도)
A10: 8 | B10: 선 금 전 회 공 제 | C10: : | D10: =ROUNDUP(E10,0) -> 0 | E10: =집계장!G20 -> 0 | F10: (VAT 별도)
A11: 9 | B11: 선 금 금 회 공 제 | C11: : | D11: =ROUNDUP(E11,0) -> 0 | E11: =집계장!F20 -> 0 | F11: (VAT 별도)
A12: 10 | B12: 선 금 잔 여 금 액 | C12: : | D12: =ROUNDUP(E12,0) -> 0 | E12: =집계장!L20 -> 0 | F12: (VAT 별도)
A13: 11 | B13: 금 회 청 구 금 액 | C13: : | D13: =ROUNDUP(E13,0) -> 40000000 | E13: =집계장!F22 -> 40000000 | F13: (VAT 별도)
A14: 12 | B14: 잔 여 기 성 금 액 | C14: : | D14: =ROUNDUP(E14,0) -> 0 | E14: =집계장!I16 -> 0 | F14: (VAT 별도)
A15: 13 | B15: 공 정 율 | C15: : | D15: 1
A16: 14 | B16: 청 구 공 사 기 간 | C16: : | D16: 2026. 02. 01 ~ 2026. 02. 28
B18: 위 공사의 하도급에 있어서 공사설계도서, 시방서,품질관리 기준 및 약정대로 시공 되었음을 확인하오며. 만약 귀사의 현장담당의 검사에
B19: 관하여 하자가 발견된 때에는 즉시 실액배상 또는 재 시공할것을 서약하고 이에 기성 청구서를 제출합니다.
B20: 상기건과 관련하여 본 청구 이전까지의 모든 대금은 수령하였음을 확약합니다.
F21: 작 성 일 : 2026 년 02 월 28 일
F23: 상 호 : | G23: ㈜ 태성하이텍
B24: ※첨 부 : 기성내역서 1부. | F24: 주 소 : | G24: 경기도 용인시 처인구 남사면 봉명리 73-1
F25: 대표이사 : | G25: 유 태 진 | I25: (인)
D26: ㈜케이씨이앤씨 귀하

Sheet 용역 내역서(을지)
A1: 용 역 내 역 서
A2: P4 Ph4 GAS 1공구 마감공사 | G2: 단위 : 원
A3: 품 명 | B3: 규 격 | C3: 단위 | D3: 단 가 | E3: 금 회 청 구
E4: 수 량 | F4: 금 액 | G4: 비 고
A5: 고급기술인 | B5: S+ | C5: M/M | D5: 1400000 | E5: 1 | F5: =D5*E5 -> 1400000
A6: 고급기술인 | B6: S | C6: M/M | D6: 1200000 | F6: =D6*E6 -> 0
A7: 중급기술인 | B7: A+ | C7: M/M | D7: 1000000 | F7: =D7*E7 -> 0
A8: 중급기술인 | B8: A | C8: M/M | D8: 900000 | F8: =D8*E8 -> 0
A9: 중급기술인 | B9: B+ | C9: M/M | D9: 800000 | F9: =D9*E9 -> 0
A10: 중급기술인 | B10: B | C10: M/M | D10: 700000 | F10: =D10*E10 -> 0
A11: 초급 기술인 | B11: C | C11: M/M | D11: 600000 | F11: =D11*E11 -> 0
A13: 인센티브 | E13: 0.01 | F13: =SUM(F5:F11)*E13 -> 14000
A15: 총 계 | E15: =SUM(E5:E11) -> 1 | F15: =SUM(F5:F13) -> 1414000

Sheet 내역서(을지)
A1: 용 역 내 역 서
A2: P4 Ph4 GAS 1공구 마감공사 | G2: 단위 : 원
A3: 품 명 | B3: 규 격 | C3: 단위 | D3: 단 가 | E3: 금 회 청 구 | G3: 비 고
E4: 수 량 | F4: 금 액
A5: 고급기술인 | B5: S+ | C5: M/M | D5: 1400000 | E5: 6 | F5: =D5*E5 -> 8400000
A6: 고급기술인 | B6: S | C6: M/M | D6: 1200000 | E6: 6 | F6: =D6*E6 -> 7200000
A7: 중급기술인 | B7: A+ | C7: M/M | D7: 1000000 | E7: 6 | F7: =D7*E7 -> 6000000
A8: 중급기술인 | B8: A | C8: M/M | D8: 900000 | E8: 6 | F8: =D8*E8 -> 5400000
A9: 중급기술인 | B9: B+ | C9: M/M | D9: 800000 | E9: 5 | F9: =D9*E9 -> 4000000
A10: 중급기술인 | B10: B | C10: M/M | D10: 700000 | E10: 6 | F10: =D10*E10 -> 4200000
A11: 초급기술인 | B11: C | C11: M/M | D11: 600000 | E11: 8 | F11: =D11*E11 -> 4800000
A13: 인센티브 | E13: 0 | F13: =SUM(F5:F11)*E13 -> 0
A27: 총 계 | E27: =SUM(E5:E11) -> 43 | F27: =SUM(F5:F26) -> 40000000

Sheet 집계장
A1: ='용역청구서 표지'!$B$7 -> P4 Ph4 GAS 1공구 마감공사
L2: ='용역청구서 표지'!$C$15 -> ㈜태성하이텍
A3: 구분 | B3: 내역 | C3: 단위 | D3: 수량 | E3: 단가 | F3: 합계 | G3: 전회기성 | H3: 금회기성 | I3: 누계기성 | J3: 비 고
A4: 1. 물량 | B4: WELDING POINT | C4: D/I | D4: =SUM('물량 내역서'!$J$5:$J$27) -> 2056.5 | E4: =F4/D4 -> 437000 | F4: =SUM('물량 내역서'!$K$5:$K$27) -> 898690500 | G4: 939113000 | H4: =F4 -> 898690500 | I4: =G4+H4 -> 1837803500
B5: VALVE 설치비 | C5: EA | D5: =SUM('물량 내역서'!$J$28:$J$50) -> 104 | E5: =F5/D5 -> 124519.23 | F5: =SUM('물량 내역서'!$K$28:$K$50) -> 12950000 | H5: =F5 -> 12950000 | I5: =G5+H5 -> 12950000
B6: 인원 실투입 | C6: M/D | D6: ='근로내역 (02월)'!AN131 -> 0 | E6: 0 | F6: ='근로내역 (02월)'!AP131 -> 0 | H6: =F6 -> 0 | I6: =G6+H6 -> 0
A7: 2. 기타비용 | C7: 式 | E7: 0 | F7: =D7*E7 -> 0 | H7: =F7 -> 0 | I7: =G7+H7 -> 0
A8: 소 계 | B8: 물량 | F8: =SUM(F4:F7) -> 911640500 | G8: 939113000 | H8: =F8 -> 911640500 | I8: =G8+H8 -> 1850753500
A9: 3. 노무비 | B9: 직접노무비 | C9: 式 | D9: ='근로내역 (02월)'!AN132 -> 2975.125 | E9: =F9/D9 -> 183883.03 | F9: ='근로내역 (02월)'!AP132 -> 547075000 | G9: 627525000 | H9: =F9 -> 547075000 | I9: =G9+H9 -> 1174600000
A10: 4. 숙소 및 식대 | B10: 임대료+관리비 | C10: 式 | D10: =SUM(숙소임차료!G4:G100)+SUM(숙소관리비!G4:G8) -> 28 | E10: =F10/D10 -> 983745.46 | F10: =숙소임차료!I3+숙소관리비!I3 -> 27544873 | G10: 29636520 | H10: =F10 -> 27544873 | I10: =G10+H10 -> 57181393
B11: 식대 | C11: 式 | D11: =SUM(식대비용!G4:G9) -> 5283 | E11: =F11/D11 -> 8046.9947 | F11: =식대비용!I3 -> 42512273 | G11: 40830728 | H11: =F11 -> 42512273 | I11: =G11+H11 -> 83343001
A12: 5. 기타 공제 내역 | C12: 式 | E12: 0 | F12: =D12*E12 -> 0 | H12: =F12 -> 0 | I12: =G12+H12 -> 0
A13: 소 계 | B13: 공제 | F13: =SUM(F9:F12) -> 6.1713215e+08 | G13: =SUM(G9:G12) -> 6.9799225e+08 | H13: =F13 -> 6.1713215e+08 | I13: =G13+H13 -> 1.3151244e+09
A14: 합 계 | B14: 기성 (물량-공제) | F14: =F8-F13 -> 2.9450835e+08 | G14: =G8-G13 -> 2.4112075e+08 | H14: =F14 -> 2.9450835e+08 | I14: =G14+H14 -> 5.3562911e+08
A15: 6. 유보금 | B15: 기성금*XX% | C15: 式 | F15: 254508354 | G15: 201068934 | H15: =F15 -> 254508354 | I15: =G15+H15 -> 455577288
A16: 7. 유보금 차액 | B16: 전회 누계유보금+적자 기성액 | C16: 式 | H16: =F16 -> 0 | I16: =G16+H16 -> 0
A17: 8. NEGO | B17: NEGO | C17: 式 | H17: =F17 -> 0 | I17: =G17+H17 -> 0
A18: 총 계 | B18: 최종기성 | F18: =F14-F15+F16+F17 -> 40000000 | G18: =G14-G15-G16-G17 -> 40051818 | H18: =F18 -> 40000000 | I18: =G18+H18 -> 80051818
A19: 선급금 | B19: 선수공제 | C19: 式 | H19: =F19 -> 0 | I19: =G19+H19 -> 0 | K19: 지급 선급금 | L19: 선급금 차액
B20: 단수정리 | C20: 式 | F20: =ROUNDDOWN(F19,-5) -> 0 | H20: =F20 -> 0 | I20: =G20+H20 -> 0 | J20: 만 단위 이하 절사 | K20: 0 | L20: =K20-I20 -> 0
A21: 공제 후 실 지급액 | F21: =F18-F20 -> 40000000 | G21: =G18-G19 -> 40051818 | H21: =F21 -> 40000000 | I21: =G21+H21 -> 80051818
A22: 세금계산서 기준 | F22: =ROUNDDOWN(F21,-5) -> 40000000 | G22: =ROUNDDOWN(G21,-5) -> 40000000 | H22: =F22 -> 40000000 | I22: =G22+H22 -> 80000000 | J22: 만 단위 이하 절사
A23: TERMS AND CONDITIONS | D23: NOTE
A24: 1. 납 기 : KCEnC 지정 납기로 별도 협의 하에 결정하는 것으로 함.
A25: 2. 지불조건 : KCEnC 지불 조건에 따름.
A26: 3. 유효기간 : 기성 제출일로 부터 30일 이내

Sheet 물량 내역서
A1: 2026년 (02)월 물량 내역서
A2: ='용역청구서 표지'!$B$7 -> P4 Ph4 GAS 1공구 마감공사 | M2: 단위 : 원
A3: 품 명 | B3: 규 격 | C3: 단위 | D3: W/P 수량 | E3: 단 가 | F3: 계 약 내 역 | H3: 전 회 누 계 물 량 | J3: 금 회 물 량 | L3: 누 계 물 량
F4: D/I 수량 | G4: 금액 | H4: D/I 수량 | I4: 금액 | J4: D/I 수량 | K4: 금액 | L4: D/I 수량 | M4: 금액
A5: WEDING POINT | B5: 8A | C5: POINT | D5: 0 | E5: 437000 | F5: =L5 -> 0 | G5: =M5 -> 0 | J5: =$D5*'DIA-INCH'!$C5 -> 0 | K5: =$E5*$J5 -> 0 | L5: =H5+J5 -> 0 | M5: =I5+K5 -> 0
A6: WEDING POINT | B6: 15A | C6: POINT | D6: 0 | E6: 437000 | F6: =L6 -> 0 | G6: =M6 -> 0 | J6: =$D6*'DIA-INCH'!$C6 -> 0 | K6: =$E6*$J6 -> 0 | L6: =H6+J6 -> 0 | M6: =I6+K6 -> 0
A7: WEDING POINT | B7: 20A | C7: POINT | D7: 0 | E7: 437000 | F7: =L7 -> 0 | G7: =M7 -> 0 | J7: =$D7*'DIA-INCH'!$C7 -> 0 | K7: =$E7*$J7 -> 0 | L7: =H7+J7 -> 0 | M7: =I7+K7 -> 0
A8: WEDING POINT | B8: 25A | C8: POINT | D8: 179 | E8: 437000 | F8: =L8 -> 310 | G8: =M8 -> 135470000 | H8: 131 | I8: 57247000 | J8: =$D8*'DIA-INCH'!$C8 -> 179 | K8: =$E8*$J8 -> 78223000 | L8: =H8+J8 -> 310 | M8: =I8+K8 -> 135470000
A9: WEDING POINT | B9: 32A | C9: POINT | D9: 0 | E9: 437000 | F9: =L9 -> 0 | G9: =M9 -> 0 | H9: 0 | I9: 0 | J9: =$D9*'DIA-INCH'!$C9 -> 0 | K9: =$E9*$J9 -> 0 | L9: =H9+J9 -> 0 | M9: =I9+K9 -> 0
A10: WEDING POINT | B10: 40A | C10: POINT | D10: 14 | E10: 437000 | F10: =L10 -> 58.5 | G10: =M10 -> 25564500 | H10: 37.5 | I10: 16387500 | J10: =$D10*'DIA-INCH'!$C10 -> 21 | K10: =$E10*$J10 -> 9177000 | L10: =H10+J10 -> 58.5 | M10: =I10+K10 -> 25564500
A11: WEDING POINT | B11: 50A | C11: POINT | D11: 92 | E11: 437000 | F11: =L11 -> 298 | G11: =M11 -> 130226000 | H11: 114 | I11: 49818000 | J11: =$D11*'DIA-INCH'!$C11 -> 184 | K11: =$E11*$J11 -> 80408000 | L11: =H11+J11 -> 298 | M11: =I11+K11 -> 130226000
A12: WEDING POINT | B12: 65A | C12: POINT | D12: 41 | E12: 437000 | F12: =L12 -> 195 | G12: =M12 -> 85215000 | H12: 92.5 | I12: 40422500 | J12: =$D12*'DIA-INCH'!$C12 -> 102.5 | K12: =$E12*$J12 -> 44792500 | L12: =H12+J12 -> 195 | M12: =I12+K12 -> 85215000
A13: WEDING POINT | B13: 80A | C13: POINT | D13: 41 | E13: 437000 | F13: =L13 -> 231 | G13: =M13 -> 100947000 | H13: 108 | I13: 47196000 | J13: =$D13*'DIA-INCH'!$C13 -> 123 | K13: =$E13*$J13 -> 53751000 | L13: =H13+J13 -> 231 | M13: =I13+K13 -> 100947000
A14: WEDING POINT | B14: 100A | C14: POINT | D14: 16 | E14: 437000 | F14: =L14 -> 364 | G14: =M14 -> 159068000 | H14: 300 | I14: 131100000 | J14: =$D14*'DIA-INCH'!$C14 -> 64 | K14: =$E14*$J14 -> 27968000 | L14: =H14+J14 -> 364 | M14: =I14+K14 -> 159068000
A15: WEDING POINT | B15: 110A | C15: POINT | D15: 0 | E15: 437000 | F15: =L15 -> 0 | G15: =M15 -> 0 | H15: 0 | I15: 0 | J15: =$D15*'DIA-INCH'!$C15 -> 0 | K15: =$E15*$J15 -> 0 | L15: =H15+J15 -> 0 | M15: =I15+K15 -> 0
A16: WEDING POINT | B16: 125A | C16: POINT | D16: 105 | E16: 437000 | F16: =L16 -> 1015 | G16: =M16 -> 443555000 | H16: 490 | I16: 214130000 | J16: =$D16*'DIA-INCH'!$C16 -> 525 | K16: =$E16*$J16 -> 229425000 | L16: =H16+J16 -> 1015 | M16: =I16+K16 -> 443555000
A17: WEDING POINT | B17: 150A | C17: POINT | D17: 6 | E17: 437000 | F17: =L17 -> 36 | G17: =M17 -> 15732000 | H17: 0 | I17: 0 | J17: =$D17*'DIA-INCH'!$C17 -> 36 | K17: =$E17*$J17 -> 15732000 | L17: =H17+J17 -> 36 | M17: =I17+K17 -> 15732000
A18: WEDING POINT | B18: 175A | C18: POINT | D18: 0 | E18: 437000 | F18: =L18 -> 0 | G18: =M18 -> 0 | H18: 0 | I18: 0 | J18: =$D18*'DIA-INCH'!$C18 -> 0 | K18: =$E18*$J18 -> 0 | L18: =H18+J18 -> 0 | M18: =I18+K18 -> 0
A19: WEDING POINT | B19: 200A | C19: POINT | D19: 19 | E19: 437000 | F19: =L19 -> 304 | G19: =M19 -> 132848000 | H19: 152 | I19: 66424000 | J19: =$D19*'DIA-INCH'!$C19 -> 152 | K19: =$E19*$J19 -> 66424000 | L19: =H19+J19 -> 304 | M19: =I19+K19 -> 132848000
... A22: WEDING POINT | B22: 300A | C22: POINT | D22: 30 | E22: 437000 | F22: =L22 -> 864 | G22: =M22 -> 377568000 | H22: 504 | I22: 220248000 | J22: =$D22*'DIA-INCH'!$C22 -> 360 | K22: =$E22*$J22 -> 157320000 | L22: =H22+J22 -> 864 | M22: =I22+K22 -> 377568000
A23: WEDING POINT | B23: 350A | C23: POINT | D23: 0 | E23: 437000 | F23: =L23 -> 0 | G23: =M23 -> 0 | J23: =$D23*'DIA-INCH'!$C23 -> 0 | K23: =$E23*$J23 -> 0 | L23: =H23+J23 -> 0 | M23: =I23+K23 -> 0
A24: WEDING POINT | B24: 400A | C24: POINT | D24: 0 | E24: 437000 | F24: =L24 -> 0 | G24: =M24 -> 0 | J24: =$D24*'DIA-INCH'!$C24 -> 0 | K24: =$E24*$J24 -> 0 | L24: =H24+J24 -> 0 | M24: =I24+K24 -> 0
A25: WEDING POINT | B25: 450A | C25: POINT | D25: 0 | E25: 437000 | F25: =L25 -> 0 | G25: =M25 -> 0 | J25: =$D25*'DIA-INCH'!$C25 -> 0 | K25: =$E25*$J25 -> 0 | L25: =H25+J25 -> 0 | M25: =I25+K25 -> 0
A26: WEDING POINT | B26: 500A | C26: POINT | D26: 0 | E26: 437000 | F26: =L26 -> 0 | G26: =M26 -> 0 | J26: =$D26*'DIA-INCH'!$C26 -> 0 | K26: =$E26*$J26 -> 0 | L26: =H26+J26 -> 0 | M26: =I26+K26 -> 0
A27: WEDING POINT | B27: 550A | C27: POINT | D27: 0 | E27: 437000 | F27: =L27 -> 0 | G27: =M27 -> 0 | J27: =$D27*'DIA-INCH'!$C27 -> 0 | K27: =$E27*$J27 -> 0 | L27: =H27+J27 -> 0 | M27: =I27+K27 -> 0
A28: VALVE 설치비 | B28: 8A | C28: EA | D28: 0 | E28: =$E$31*'DIA-INCH'!$C5 -> 21875 | F28: =L28 -> 0 | G28: =M28 -> 0 | J28: =D28 -> 0 | K28: =$J28*$E28 -> 0 | L28: =H28+J28 -> 0 | M28: =I28+K28 -> 0
A29: VALVE 설치비 | B29: 15A | C29: EA | D29: 0 | E29: =$E$31*'DIA-INCH'!$C6 -> 43750 | F29: =L29 -> 0 | G29: =M29 -> 0 | J29: =D29 -> 0 | K29: =$J29*$E29 -> 0 | L29: =H29+J29 -> 0 | M29: =I29+K29 -> 0
A30: VALVE 설치비 | B30: 20A | C30: EA | D30: 0 | E30: =$E$31*'DIA-INCH'!$C7 -> 65625 | F30: =L30 -> 0 | G30: =M30 -> 0 | J30: =D30 -> 0 | K30: =$J30*$E30 -> 0 | L30: =H30+J30 -> 0 | M30: =I30+K30 -> 0
A31: VALVE 설치비 | B31: 25A | C31: EA | D31: 31 | E31: 87500 | F31: =L31 -> 31 | G31: =M31 -> 2712500 | J31: =D31 -> 31 | K31: =$J31*$E31 -> 2712500 | L31: =H31+J31 -> 31 | M31: =I31+K31 -> 2712500 | N31: 1 | O31: =+N31*J31 -> 31
A32: VALVE 설치비 | B32: 32A | C32: EA | D32: 60 | E32: =$E$31*'DIA-INCH'!$C9 -> 109375 | F32: =L32 -> 60 | G32: =M32 -> 6562500 | J32: =D32 -> 60 | K32: =$J32*$E32 -> 6562500 | L32: =H32+J32 -> 60 | M32: =I32+K32 -> 6562500 | N32: 1.25 | O32: =+N32*J32 -> 75
A33: VALVE 설치비 | B33: 40A | C33: EA | D33: 2 | E33: =$E$31*'DIA-INCH'!$C10 -> 131250 | F33: =L33 -> 2 | G33: =M33 -> 262500 | J33: =D33 -> 2 | K33: =$J33*$E33 -> 262500 | L33: =H33+J33 -> 2 | M33: =I33+K33 -> 262500 | N33: 1.5 | O33: =+N33*J33 -> 3
A34: VALVE 설치비 | B34: 50A | C34: EA | D34: 3 | E34: =$E$31*'DIA-INCH'!$C11 -> 175000 | F34: =L34 -> 3 | G34: =M34 -> 525000 | J34: =D34 -> 3 | K34: =$J34*$E34 -> 525000 | L34: =H34+J34 -> 3 | M34: =I34+K34 -> 525000 | N34: 2 | O34: =+N34*J34 -> 6
A35: VALVE 설치비 | B35: 65A | C35: EA | D35: 2 | E35: =$E$31*'DIA-INCH'!$C12 -> 218750 | F35: =L35 -> 2 | G35: =M35 -> 437500 | J35: =D35 -> 2 | K35: =$J35*$E35 -> 437500 | L35: =H35+J35 -> 2 | M35: =I35+K35 -> 437500 | N35: 2.5 | O35: =+N35*J35 -> 5
A36: VALVE 설치비 | B36: 80A | C36: EA | D36: 1 | E36: =$E$31*'DIA-INCH'!$C13 -> 262500 | F36: =L36 -> 1 | G36: =M36 -> 262500 | J36: =D36 -> 1 | K36: =$J36*$E36 -> 262500 | L36: =H36+J36 -> 1 | M36: =I36+K36 -> 262500 | N36: 3 | O36: =+N36*J36 -> 3
A37: VALVE 설치비 | B37: 100A | C37: EA | D37: 0 | E37: =$E$31*'DIA-INCH'!$C14 -> 350000 | F37: =L37 -> 0 | G37: =M37 -> 0 | J37: =D37 -> 0 | K37: =$J37*$E37 -> 0 | L37: =H37+J37 -> 0 | M37: =I37+K37 -> 0 | O37: =+N37*J37 -> 0
A38: VALVE 설치비 | B38: 110A | C38: EA | D38: 0 | E38: =$E$31*'DIA-INCH'!$C15 -> 350000 | F38: =L38 -> 0 | G38: =M38 -> 0 | J38: =D38 -> 0 | K38: =$J38*$E38 -> 0 | L38: =H38+J38 -> 0 | M38: =I38+K38 -> 0 | O38: =+N38*J38 -> 0
A39: VALVE 설치비 | B39: 125A | C39: EA | D39: 5 | E39: =$E$31*'DIA-INCH'!$C16 -> 437500 | F39: =L39 -> 5 | G39: =M39 -> 2187500 | J39: =D39 -> 5 | K39: =$J39*$E39 -> 2187500 | L39: =H39+J39 -> 5 | M39: =I39+K39 -> 2187500 | N39: 5 | O39: =+N39*J39 -> 25
A40: VALVE 설치비 | B40: 150A | C40: EA | D40: 0 | E40: =$E$31*'DIA-INCH'!$C17 -> 525000 | F40: =L40 -> 0 | G40: =M40 -> 0 | J40: =D40 -> 0 | K40: =$J40*$E40 -> 0 | L40: =H40+J40 -> 0 | M40: =I40+K40 -> 0
A41: VALVE 설치비 | B41: 175A | C41: EA | D41: 0 | E41: =$E$31*'DIA-INCH'!$C18 -> 612500 | F41: =L41 -> 0 | G41: =M41 -> 0 | J41: =D41 -> 0 | K41: =$J41*$E41 -> 0 | L41: =H41+J41 -> 0 | M41: =I41+K41 -> 0
A42: VALVE 설치비 | B42: 200A | C42: EA | D42: 0 | E42: =$E$31*'DIA-INCH'!$C19 -> 700000 | F42: =L42 -> 0 | G42: =M42 -> 0 | J42: =D42 -> 0 | K42: =$J42*$E42 -> 0 | L42: =H42+J42 -> 0 | M42: =I42+K42 -> 0
...

Sheet 근로내역 (02월)
A1: 2026년 ( 02 )월 일용 노무비명세서 | AH1: 현장명 | AM1: ='용역청구서 표지'!$B$7 -> P4 Ph4 GAS 1공구 마감공사
AH2: 현장소장 | AM2: 장규철
AH3: 잡코드 | AM3: ='용역청구서 표지'!$C$8 -> S25-004
A5: 번호 | B5: 성명 | C5: 주민등록번호 | D5: 직종 | E5: 연락처(H.P) | F5: 은행명 | G5: 예금주 | H5: 계좌번호 | I5: 1 | J5: 2 | K5: 3 | L5: 4 | M5: 5 | N5: 6 | O5: 7 | P5: 8 | Q5: 9 | R5: 10 | S5: 11 | T5: 12 | U5: 13 | V5: 14 | W5: 15 | X5: 16 | Y5: 17 | Z5: 18 | AA5: 19 | AB5: 20 | AC5: 21 | AD5: 22 | AE5: 23 | AF5: 24 | AG5: 25 | AH5: 26 | AI5: 27 | AJ5: 28 | AN5: 공수 | AO5: 단가 | AP5: 총액
A6: 1 | B6: 강경섭 | C6: 781225-1392311 | D6: 공사보조 | E6: 010-2573-6379 | F6: 농협 | G6: 강경섭 | H6: 356-0973-5567-73 | J6: 2 | K6: 2 | L6: 2 | M6: 2 | N6: 2 | Q6: 2 | R6: 2 | S6: 2 | T6: 2 | U6: 2 | AA6: 2 | AB6: 2 | AE6: 2 | AF6: 2 | AG6: 2 | AH6: 2 | AI6: 2 | AN6: =SUM(I6:AM6) -> 34 | AO6: 230000 | AP6: =AN6*AO6 -> 7820000
A7: 2 | B7: 강동근 | C7: 960219-1406218 | D7: 보통인부 | E7: 010-5555-5945 | F7: 신한 | G7: 강동근 | H7: 110-444-941185 | K7: 1 | L7: 1.5 | M7: 1.5 | N7: 1.5 | Q7: 1.5 | S7: 1.5 | T7: 1.5 | U7: 1.5 | V7: 1 | AA7: 1 | AE7: 1.5 | AF7: 1.5 | AH7: 1.5 | AI7: 1.5 | AN7: =SUM(I7:AM7) -> 19.5 | AO7: 150000 | AP7: =AN7*AO7 -> 2925000
A8: 3 | B8: 강우식 | C8: 751012-1023227 | D8: 보통인부 | E8: 010-9076-7046 | F8: 우체국 | G8: 강우식 | H8: 110-0133-54524 | Q8: 0.75 | R8: 0.375 | AN8: =SUM(I8:AM8) -> 1.125 | AO8: 150000 | AP8: =AN8*AO8 -> 168750
A9: 4 | B9: 강원태 | C9: 920818-1240811 | D9: 보통인부 | E9: 010-9205-4684 | F9: 기업 | G9: 강원태 | H9: 186-075475-01-013 | J9: 1.5 | K9: 1 | L9: 1.5 | M9: 1.5 | N9: 1.5 | O9: 1 | Q9: 1.5 | R9: 1.5 | S9: 1.5 | T9: 1.5 | U9: 1.5 | AA9: 1 | AB9: 1.5 | AE9: 1.5 | AF9: 1.5 | AG9: 1.5 | AH9: 1.375 | AI9: 1.5 | AN9: =SUM(I9:AM9) -> 25.375 | AO9: 160000 | AP9: =AN9*AO9 -> 4060000
A10: 5 | B10: 강인수 | C10: 690511-1067622 | D10: 보통인부 | E10: 010-2486-6843 | F10: 부산 | G10: 강인수 | H10: 1122027356601 | J10: 1.5 | K10: 1.5 | L10: 1.5 | M10: 1.5 | N10: 1.5 | O10: 1 | Q10: 1.5 | R10: 1.5 | S10: 1.5 | T10: 1.5 | U10: 1.5 | V10: 1 | AA10: 1 | AB10: 1.5 | AE10: 1.5 | AF10: 1.5 | AG10: 1.5 | AH10: 1.5 | AI10: 1.5 | AJ10: 1 | AN10: =SUM(I10:AM10) -> 28 | AO10: 160000 | AP10: =AN10*AO10 -> 4480000
A11: 6 | B11: 강희재 | C11: 940122-1491011 | D11: 공사보조 | E11: 010-9127-3784 | F11: 신한 | G11: 강희재 | H11: 110-404-502876 | J11: 1.5 | K11: 1.5 | L11: 1.5 | M11: 1.5 | N11: 1.5 | O11: 0.5 | Q11: 1.5 | R11: 1.5 | S11: 1.5 | T11: 1.5 | U11: 1.5 | V11: 1 | AA11: 1 | AB11: 1.5 | AE11: 1.5 | AF11: 1.5 | AG11: 1.5 | AH11: 1.5 | AI11: 1.5 | AJ11: 1 | AN11: =SUM(I11:AM11) -> 27.5 | AO11: 230000 | AP11: =AN11*AO11 -> 6325000
A12: 7 | B12: 고종진 | C12: 790213-1912022 | D12: 용접공 | E12: 010-7478-4040 | F12: 국민 | G12: 고종진 | H12: 120-21-0593-080 | J12: 1.5 | K12: 1.5 | L12: 1.5 | M12: 1.5 | N12: 1.5 | Q12: 1.5 | R12: 1.5 | S12: 1.5 | T12: 1.5 | U12: 1.5 | AA12: 1 | AB12: 1.5 | AE12: 1.5 | AF12: 1.5 | AG12: 1.5 | AH12: 1.5 | AI12: 1.5 | AN12: =SUM(I12:AM12) -> 25 | AO12: 240000 | AP12: =AN12*AO12 -> 6000000
A13: 8 | B13: 곽명재 | C13: 800514-1894915 | D13: 용접공 | E13: 010-9232-3215 | F13: 농협 | G13: 곽명재 | H13: 3120172259661 | J13: 2 | K13: 2 | L13: 2 | M13: 2 | N13: 2 | Q13: 2 | R13: 2 | S13: 2 | T13: 2 | U13: 2 | AA13: 2 | AB13: 2 | AE13: 2 | AF13: 2 | AG13: 2 | AH13: 2 | AI13: 2 | AN13: =SUM(I13:AM13) -> 34 | AO13: 240000 | AP13: =AN13*AO13 -> 8160000
A14: 9 | B14: 권혁만 | C14: 770319-1772710 | D14: 보통인부 | E14: 010-9084-0127 | F14: 기업 | G14: 권혁만 | H14: 530-023847-01-014 | J14: 1.5 | K14: 1 | L14: 1.5 | M14: 1.5 | N14: 1.5 | O14: 1 | Q14: 1.5 | R14: 1.5 | S14: 1.5 | T14: 1.5 | U14: 1.5 | V14: 1 | AA14: 1 | AB14: 1.5 | AE14: 1.5 | AF14: 1.5 | AG14: 1.5 | AH14: 1.5 | AI14: 1.5 | AN14: =SUM(I14:AM14) -> 26.5 | AO14: 180000 | AP14: =AN14*AO14 -> 4770000
A15: 10 | B15: 김강현 | C15: 910414-1031829 | D15: 보통인부 | E15: 010-6733-7963 | F15: 신한 | G15: 김강현 | H15: 110-302-846665 | J15: 1.5 | K15: 1 | L15: 1.5 | M15: 1.5 | N15: 1.5 | O15: 1 | Q15: 1.5 | R15: 1.5 | S15: 1.5 | T15: 1.5 | U15: 1.5 | V15: 1 | AA15: 1 | AB15: 1.5 | AE15: 1.5 | AF15: 1.5 | AG15: 1.5 | AH15: 1.5 | AI15: 1.5 | AJ15: 1 | AN15: =SUM(I15:AM15) -> 27.5 | AO15: 190000 | AP15: =AN15*AO15 -> 5225000
A16: 11 | B16: 김경태 | C16: 901120-1588112 | D16: 보통인부 | E16: 010-9538-3223 | F16: 국민 | G16: 김경태 | H16: 99538322358 | J16: 2 | K16: 2 | L16: 2 | M16: 2 | N16: 2 | Q16: 2 | R16: 2 | S16: 2 | T16: 2 | U16: 2 | AA16: 2 | AB16: 2 | AE16: 2 | AF16: 2 | AG16: 2 | AH16: 2 | AI16: 2 | AN16: =SUM(I16:AM16) -> 34 | AO16: 140000 | AP16: =AN16*AO16 -> 4760000
A17: 12 | B17: 김광동 | C17: 930520-1692511 | D17: 보통인부 | E17: 010-4348-0266 | F17: 국민 | G17: 김광동 | H17: 926102-01-496205 | J17: 1.5 | K17: 1.5 | L17: 1.5 | M17: 1.5 | N17: 1.5 | O17: 1 | Q17: 1.5 | R17: 1.5 | S17: 1.5 | T17: 1.5 | U17: 1.5 | AA17: 1 | AB17: 1.5 | AE17: 1.5 | AF17: 1.5 | AG17: 1.5 | AH17: 1.5 | AI17: 1.5 | AN17: =SUM(I17:AM17) -> 26 | AO17: 150000 | AP17: =AN17*AO17 -> 3900000
A18: 13 | B18: 김기진 | C18: 871020-1850315 | D18: 보통인부 | E18: 010-6613-2156 | F18: 농협 | G18: 김기진 | H18: 937-12-468305 | J18: 2 | K18: 2 | L18: 2 | M18: 2 | N18: 2 | Q18: 2 | R18: 2 | S18: 2 | T18: 2 | U18: 2 | AA18: 2 | AB18: 2 | AE18: 2 | AF18: 2 | AG18: 2 | AH18: 2 | AI18: 2 | AN18: =SUM(I18:AM18) -> 34 | AO18: 160000 | AP18: =AN18*AO18 -> 5440000
A19: 14 | B19: 김기훈 | C19: 890417-1468411 | D19: 배관공 | E19: 010-4131-6732 | F19: 국민 | G19: 김기훈 | H19: 91041316732 | J19: 1.5 | K19: 1 | L19: 1.5 | M19: 1.5 | Q19: 1.5 | R19: 0.5 | S19: 1.5 | T19: 1.5 | U19: 1.5 | AA19: 1 | AB19: 1.5 | AE19: 1.5 | AF19: 1.5 | AH19: 1.5 | AI19: 1.5 | AN19: =SUM(I19:AM19) -> 20.5 | AO19: 210000 | AP19: =AN19*AO19 -> 4305000
A20: 15 | B20: 김동민 | C20: 840606-1768018 | D20: 용접공 | E20: 010-3804-2432 | F20: 신한 | G20: 김동민 | H20: 110-408-565589 | J20: 2 | K20: 2 | L20: 2 | M20: 2 | N20: 2 | Q20: 2 | R20: 2 | S20: 2 | U20: 2 | AA20: 2 | AB20: 2 | AE20: 2 | AF20: 2 | AG20: 2 | AH20: 2 | AI20: 2 | AN20: =SUM(I20:AM20) -> 32 | AO20: 240000 | AP20: =AN20*AO20 -> 7680000
A21: 16 | B21: 김동열 | C21: 920815-1331213 | D21: 안전보조 | E21: 010-2426-3254 | F21: 새마을 | G21: 김동열 | H21: 9003299983139 | J21: 1.5 | K21: 1.5 | L21: 1.5 | M21: 0.5 | Q21: 1.5 | R21: 1.5 | S21: 1.5 | T21: 1 | U21: 1.5 | V21: 0.625 | AA21: 1 | AB21: 1.5 | AE21: 1.5 | AF21: 1.5 | AG21: 1.5 | AH21: 1.5 | AI21: 1.5 | AJ21: 1 | AN21: =SUM(I21:AM21) -> 23.625 | AO21: 210000 | AP21: =AN21*AO21 -> 4961250
A22: 17 | B22: 김동준 | C22: 981003-1558112 | D22: 배관공 | E22: 010-9930-1495 | F22: 카카오 | G22: 김동준 | H22: 3333-16-2421842 | J22: 1.5 | L22: 1.5 | M22: 1.5 | N22: 1.5 | Q22: 2 | R22: 2 | S22: 2 | T22: 2 | U22: 2 | AA22: 2 | AB22: 2 | AE22: 2 | AF22: 2 | AG22: 2 | AH22: 2 | AI22: 2 | AN22: =SUM(I22:AM22) -> 30 | AO22: 180000 | AP22: =AN22*AO22 -> 5400000
A23: 18 | B23: 김민창 | C23: 950725-1119917 | D23: 보통인부 | E23: 010-6427-2425 | F23: 신한 | G23: 김민창 | H23: 110-4294-08-656 | J23: 1.5 | K23: 0.5 | M23: 1.5 | N23: 1.5 | O23: 1 | R23: 1.5 | S23: 1.5 | T23: 1.5 | U23: 1.5 | AB23: 1.5 | AE23: 1.5 | AF23: 1.5 | AG23: 1.5 | AH23: 1.5 | AI23: 1.5 | AN23: =SUM(I23:AM23) -> 21 | AO23: 160000 | AP23: =AN23*AO23 -> 3360000
A24: 19 | B24: 김상엽 | C24: 951227-1213217 | D24: 보통인부 | E24: 010-2697-7981 | F24: 우리 | G24: 김상엽 | H24: 1002-266-329436 | Q24: 0.75 | R24: 0.375 | S24: 0.625 | T24: 1.5 | U24: 1.5 | AA24: 1 | AB24: 1.5 | AE24: 1.5 | AF24: 1.5 | AG24: 1.5 | AH24: 1.5 | AI24: 1.5 | AJ24: 1 | AN24: =SUM(I24:AM24) -> 15.75 | AO24: 150000 | AP24: =AN24*AO24 -> 2362500
A25: 20 | B25: 김선광 | C25: 880728-1903519 | D25: 용접공 | E25: 010-4560-3710 | F25: 신한 | G25: 김선광 | H25: 110-214-578576 | J25: 2 | K25: 2 | L25: 2 | M25: 2 | N25: 2 | Q25: 2 | R25: 2 | S25: 2 | T25: 2 | U25: 2 | AA25: 2 | AB25: 2 | AE25: 2 | AF25: 2 | AG25: 2 | AH25: 2 | AI25: 2 | AN25: =SUM(I25:AM25) -> 34 | AO25: 240000 | AP25: =AN25*AO25 -> 8160000
A26: 21 | B26: 김성인 | C26: 781127-1567319 | D26: 배관공 | E26: 010-8336-3710 | F26: 우체국 | G26: 김성인 | H26: 503904-02-235538 | J26: 2 | K26: 2 | L26: 2 | M26: 2 | N26: 2 | Q26: 2 | R26: 2 | S26: 2 | T26: 2 | U26: 2 | AA26: 2 | AB26: 2 | AE26: 2 | AF26: 2 | AG26: 2 | AH26: 2 | AI26: 2 | AN26: =SUM(I26:AM26) -> 34 | AO26: 220000 | AP26: =AN26*AO26 -> 7480000
A27: 22 | B27: 김성준 | C27: 961016-1179611 | D27: 보통인부 | E27: 010-7732-6708 | F27: 국민 | G27: 김성준 | H27: 166102-04-160013 | J27: 2 | K27: 2 | L27: 2 | M27: 2 | N27: 2 | Q27: 2 | R27: 2 | S27: 2 | T27: 2 | U27: 2 | AA27: 2 | AB27: 2 | AE27: 2 | AF27: 2 | AG27: 2 | AH27: 2 | AI27: 2 | AN27: =SUM(I27:AM27) -> 34 | AO27: 160000 | AP27: =AN27*AO27 -> 5440000
A28: 23 | B28: 김성중 | C28: 911126-1043210 | D28: 보통인부 | E28: 010-3777-9825 | F28: 기업 | G28: 김성중 | H28: 118-149-246-01-011 | Q28: 0.75 | S28: 1 | T28: 1.5 | U28: 1.5 | AA28: 1 | AB28: 1.5 | AE28: 1.5 | AF28: 1.5 | AG28: 1.5 | AH28: 0.5 | AI28: 1.5 | AJ28: 1 | AN28: =SUM(I28:AM28) -> 14.75 | AO28: 150000 | AP28: =AN28*AO28 -> 2212500
A29: 24 | B29: 김세엽 | C29: 000807-3114418 | D29: 보통인부 | E29: 010-2246-0870 | F29: 하나 | G29: 김세엽 | H29: 161-910525-50607 | J29: 0.625 | L29: 1 | M29: 1.5 | N29: 1.5 | O29: 1 | Q29: 1.5 | R29: 1.5 | S29: 0.125 | T29: 1.5 | U29: 1.5 | V29: 1 | AA29: 1 | AB29: 1.5 | AE29: 1.5 | AF29: 1.5 | AG29: 1.5 | AH29: 1.5 | AN29: =SUM(I29:AM29) -> 21.25 | AO29: 160000 | AP29: =AN29*AO29 -> 3400000
A30: 25 | B30: 김수남 | C30: 800306-1567513 | D30: 보통인부 | E30: 010-2093-0129 | F30: 신한 | G30: 김수남 | H30: 110-500-068-364 | J30: 1.5 | K30: 1 | M30: 1.5 | N30: 1.5 | O30: 0.5 | AN30: =SUM(I30:AM30) -> 6 | AO30: 150000 | AP30: =AN30*AO30 -> 900000
A31: 26 | B31: 김승진 | C31: 751018-1332839 | D31: 안전보조 | E31: 010-4742-4181 | F31: 신한 | G31: 김승진 | H31: 110-338-273904 | J31: 1.5 | K31: 1.375 | L31: 1.5 | M31: 1 | Q31: 1.375 | S31: 1 | T31: 1.25 | U31: 1.25 | AA31: 0.875 | AE31: 1.375 | AH31: 1.5 | AJ31: 0.5 | AN31: =SUM(I31:AM31) -> 14.5 | AO31: 270000 | AP31: =AN31*AO31 -> 3915000
A32: 27 | B32: 김양근 | C32: 930824-1030929 | D32: 용접공 | E32: 010-2301-4979 | F32: 신한 | G32: 김양근 | H32: 110-349-207217 | Q32: 1 | R32: 0.5 | S32: 1 | T32: 1.5 | U32: 1.5 | AA32: 1 | AB32: 1.5 | AE32: 1.5 | AF32: 1.5 | AG32: 1.5 | AI32: 1.5 | AJ32: 1 | AN32: =SUM(I32:AM32) -> 15 | AO32: 240000 | AP32: =AN32*AO32 -> 3600000
A33: 28 | B33: 김영광 | C33: 920704-1860718 | D33: 관리보조 | E33: 010-7704-1777 | F33: 기업 | G33: 김영광 | H33: 580-022392-01-010 | J33: 1.5 | K33: 1.375 | L33: 1.5 | M33: 1.375 | N33: 1.25 | O33: 1 | R33: 1.5 | S33: 1.5 | T33: 1.375 | U33: 1.375 | AA33: 1 | AB33: 1.5 | AE33: 1.5 | AF33: 1.25 | AG33: 1.5 | AH33: 1 | AI33: 1.375 | AJ33: 1 | AN33: =SUM(I33:AM33) -> 23.875 | AO33: 200000 | AP33: =AN33*AO33 -> 4775000
A34: 29 | B34: 김영철 | C34: 720622-1921415 | D34: 배관공 | E34: 010-3884-4513 | F34: 새마을 | G34: 김영철 | H34: 9003-2504-8199-8 | J34: 1.5 | K34: 1 | L34: 1.5 | M34: 1.5 | N34: 1.5 | O34: 1 | Q34: 1.5 | R34: 1.5 | S34: 1.5 | T34: 1.5 | U34: 1.5 | AA34: 1 | AB34: 1.5 | AE34: 1.5 | AF34: 1.5 | AG34: 1.5 | AH34: 1.5 | AI34: 1.5 | AJ34: 1 | AN34: =SUM(I34:AM34) -> 26.5 | AO34: 210000 | AP34: =AN34*AO34 -> 5565000
A35: 30 | B35: 김지웅 | C35: 980518-1056817 | D35: 보통인부 | E35: 010-3273-8579 | F35: 카카오 | G35: 김지웅 | H35: 3333-05-6473488 | J35: 1.5 | K35: 1 | L35: 1.5 | M35: 1.5 | N35: 0.5 | Q35: 1.5 | R35: 1.5 | S35: 1.5 | T35: 1.5 | U35: 1.5 | AA35: 1 | AB35: 1.5 | AE35: 1.5 | AF35: 1.5 | AG35: 1.5 | AH35: 1.5 | AI35: 1.5 | AN35: =SUM(I35:AM35) -> 23.5 | AO35: 150000 | AP35: =AN35*AO35 -> 3525000
A36: 31 | B36: 김태륭 | C36: 850630-1408910 | D36: 보통인부 | E36: 010-2030-6205 | F36: 우리 | G36: 김태륭 | H36: 1002-248-631510 | Q36: 0.75 | S36: 1 | T36: 1.5 | U36: 1.5 | AA36: 1 | AN36: =SUM(I36:AM36) -> 5.75 | AO36: 150000 | AP36: =AN36*AO36 -> 862500
A37: 32 | B37: 김태훈 | C37: 810515-1814611 | D37: 보통인부 | E37: 010-5844-3098 | F37: 농협 | G37: 김태훈 | H37: 793-12-097221 | J37: 1.5 | K37: 1.5 | L37: 1.5 | M37: 1.5 | N37: 0.5 | Q37: 1.5 | R37: 1.5 | S37: 1.5 | T37: 1.5 | U37: 1.5 | AA37: 1 | AB37: 1.5 | AE37: 1.5 | AF37: 1.5 | AG37: 1.5 | AH37: 1.5 | AI37: 1.5 | AN37: =SUM(I37:AM37) -> 24 | AO37: 150000 | AP37: =AN37*AO37 -> 3600000
A38: 33 | B38: 김현규 | C38: 921116-1163211 | D38: 보통인부 | E38: 010-9150-0018 | F38: 국민 | G38: 김현규 | H38: 920302-01-333030 | J38: 0.625 | L38: 1 | M38: 1.5 | N38: 1.5 | Q38: 1.5 | R38: 1.5 | S38: 1.5 | T38: 1.5 | U38: 1.5 | V38: 0.5 | AA38: 1 | AB38: 1.5 | AE38: 1.5 | AF38: 1.5 | AG38: 1.5 | AH38: 1.5 | AI38: 1.5 | AJ38: 1 | AN38: =SUM(I38:AM38) -> 23.625 | AO38: 170000 | AP38: =AN38*AO38 -> 4016250
A39: 34 | B39: 김현수 | C39: 960703-1675511 | D39: 보통인부 | E39: 010-7760-4917 | F39: 대구 | G39: 김현수 | H39: 143-13132-971 | K39: 2 | L39: 2 | M39: 2 | N39: 2 | Q39: 2 | R39: 2 | S39: 2 | T39: 2 | U39: 2 | AA39: 2 | AB39: 2 | AE39: 2 | AF39: 2 | AG39: 2 | AH39: 2 | AI39: 2 | AN39: =SUM(I39:AM39) -> 32 | AO39: 160000 | AP39: =AN39*AO39 -> 5120000
A40: 35 | B40: 김홍진 | C40: 760929-1011711 | D40: 보통인부 | E40: 010-3392-6726 | F40: 농협 | G40: 김홍진 | H40: 515-01-091563 | J40: 1.5 | K40: 1 | L40: 1.5 | M40: 1.5 | N40: 1.5 | Q40: 1.5 | R40: 1.5 | S40: 1.5 | T40: 1.5 | U40: 1.5 | AA40: 1 | AB40: 1.5 | AE40: 1.5 | AF40: 1.5 | AG40: 1.5 | AH40: 1.5 | AI40: 1.5 | AN40: =SUM(I40:AM40) -> 24.5 | AO40: 150000 | AP40: =AN40*AO40 -> 3675000
A41: 36 | B41: 김효형 | C41: 880616-1841518 | D41: 보통인부 | E41: 010-4963-5022 | F41: 국민 | G41: 김효형 | H41: 479402-04-091853 | J41: 2 | K41: 2 | L41: 2 | M41: 2 | N41: 2 | Q41: 2 | R41: 2 | S41: 2 | T41: 2 | U41: 2 | AA41: 2 | AB41: 2 | AE41: 2 | AF41: 2 | AG41: 2 | AH41: 2 | AI41: 2 | AN41: =SUM(I41:AM41) -> 34 | AO41: 150000 | AP41: =AN41*AO41 -> 5100000
...

Sheet 용접기자재
A1: 용접 기자재
A2: No | B2: 구매일 | C2: 구분 | D2: 품명 | E2: 규격 | F2: 거래처명 | G2: 발주수량 | H2: 단가 | I2: 합계 | J2: 비고
I3: =ROUND(SUM(I4:I82),) -> 664400
A4: 1 | B4: 46056 | C4: 소모성자재 | D4: 알곤용접봉 | E4: [TGC316L.2.4mm,5kg [조선선재]] | F4: 미래공구 | G4: 2 | H4: 89500 | I4: 179000 | L4: 입력해야하는 항목 외 수정 금지
A5: 2 | B5: 46063 | C5: 소모성자재 | D5: 텅스텐봉 | E5: [3.2Q,10개,란탄2%,CTX [크레토스]] | F5: 미래공구 | G5: 2 | H5: 54600 | I5: 109200 | L5: 입력항목
A6: 3 | B6: 46063 | C6: 소모성자재 | D6: 텅스텐봉 | E6: [2.4Q,10개,란탄2%,CTX [크레토스]] | F6: 미래공구 | G6: 2 | H6: 31000 | I6: 62000 | L6: 구매일
A7: 4 | B7: 46064 | C7: 소모성자재 | D7: 알곤세라믹 | E7: [350A-12.5mm(#8)YJ-35,변형,CTX [크레토스]] | F7: 미래공구 | G7: 10 | H7: 600 | I7: 6000 | L7: 구분
A8: 5 | B8: 46064 | C8: 소모성자재 | D8: 알곤용접봉 | E8: [TGC308L.2.4mm,5kg [조선선재]] | F8: 미래공구 | G8: 2 | H8: 71500 | I8: 143000 | L8: 품명
A9: 6 | B9: 46064 | C9: 소모성자재 | D9: 알곤용접봉 | E9: [TGC308L.3.2mm,5kg [조선선재]] | F9: 미래공구 | G9: 2 | H9: 71000 | I9: 142000 | L9: 규격
A10: 7 | B10: 46064 | C10: 소모성자재 | D10: 알곤용접봉 | E10: [TGC50S.3.2mm,5kg [조선선재]] | F10: 미래공구 | G10: 1 | H10: 23200 | I10: 23200 | L10: 거래처명
L11: 발주수량
L12: 단가
L14: ■ 구분은 [소모성자재, 공구, 임대(공구), 안전용품, 비품] 이외 항목은 입력금지

Sheet 배관기자재
A1: 배관 기자재
A2: No | B2: 구매일 | C2: 구분 | D2: 품명 | E2: 규격 | F2: 거래처명 | G2: 발주수량 | H2: 단가 | I2: 합계 | J2: 비고
I3: =ROUND(SUM(I4:I108),) -> 4413373 | L3: 입력해야하는 항목 외 수정 금지
A4: 1 | B4: 46059 | C4: 소모성자재 | D4: 청보호테이프 | E4: 500mm*4롤 | F4: 네이버파이낸셜㈜ | G4: 2 | H4: 40909.091 | I4: 81818.182 | L4: 입력항목
A5: 2 | B5: 46059 | C5: 소모성자재 | D5: 커터칼 | E5: SK-10 | F5: 네이버파이낸셜㈜ | G5: 5 | H5: 6709.0909 | I5: 33545.455 | L5: 구매일
A6: 3 | B6: 46063 | C6: 소모성자재 | D6: 브라더 토너 | F6: 네이버파이낸셜㈜ | G6: 1 | H6: 15363.636 | I6: 15363.636 | L6: 구분
A7: 4 | B7: 46077 | C7: 안전용품 | D7: 안전화 | E7: 270 | F7: 네이버파이낸셜㈜ | G7: 1 | H7: 43090.909 | I7: 43090.909 | L7: 품명
A8: 5 | B8: 46073 | C8: 안전용품 | D8: 지벤 안전화 | E8: ZB-171S | F8: 롯데쇼핑㈜ | G8: 2 | H8: 58809.091 | I8: 117618.18 | L8: 규격
A9: 6 | B9: 46055 | C9: 소모성자재 | D9: 빗자루 | E9: [갈대비 [수입/HNS]] | F9: 미래공구 | G9: 5 | H9: 3400 | I9: 17000 | L9: 거래처명
A10: 7 | B10: 46055 | C10: 소모성자재 | D10: 가위 | E10: [SB-P300,CTX [세신]] | F10: 미래공구 | G10: 10 | H10: 4500 | I10: 45000 | L10: 발주수량
A11: 8 | B11: 46055 | C11: 소모성자재 | D11: 가위집 | E11: [PVC [AK]] | F11: 미래공구 | G11: 10 | H11: 2100 | I11: 21000 | L11: 단가
A12: 9 | B12: 46055 | C12: 소모성자재 | D12: 쓰레받이 | E12: [외곽용,주황 [수입]] | F12: 미래공구 | G12: 5 | H12: 5700 | I12: 28500
A13: 10 | B13: 46055 | C13: 소모성자재 | D13: 물파스 | E13: [90ML [현대약품]] | F13: 미래공구 | G13: 20 | H13: 3500 | I13: 70000 | N13: ■ 구분은 [소모성자재, 공구, 임대(공구), 안전용품, 비품] 이외 항목은 입력금지
A14: 11 | B14: 46055 | C14: 소모성자재 | D14: 볼렌치세트 | E14: [10992,mm,7pcs [본더스]] | F14: 미래공구 | G14: 1 | H14: 12000 | I14: 12000
A15: 12 | B15: 46055 | C15: 소모성자재 | D15: L렌치 | E15: [5mm,CTX [에이트]] | F15: 미래공구 | G15: 5 | H15: 700 | I15: 3500
A16: 13 | B16: 46055 | C16: 소모성자재 | D16: 철근절단비트 | E16: [MSRC-17 [모스툴]] | F16: 미래공구 | G16: 5 | H16: 32000 | I16: 160000
A17: 14 | B17: 46056 | C17: 소모성자재 | D17: SNOOP | E17: [8OZ [스웨즈락]] | F17: 미래공구 | G17: 15 | H17: 16800 | I17: 252000
A18: 15 | B18: 46056 | C18: 소모성자재 | D18: 낙상경보기부품 | E18: [풀피리] | F18: 미래공구 | G18: 100 | H18: 100 | I18: 10000
A19: 16 | B19: 46057 | C19: 소모성자재 | D19: 보루 | E19: [5KG,면 [백호]] | F19: 미래공구 | G19: 3 | H19: 12000 | I19: 36000
A20: 17 | B20: 46057 | C20: 소모성자재 | D20: 볼트가방 | E20: [검정,형광띠 [영신티오피]] | F20: 미래공구 | G20: 5 | H20: 24000 | I20: 120000
A21: 18 | B21: 46058 | C21: 소모성자재 | D21: 파이프컷팅날 | E21: [LS6844 [엑서]] | F21: 미래공구 | G21: 3 | H21: 40000 | I21: 120000
A22: 19 | B22: 46058 | C22: 소모성자재 | D22: 철근절단비트 | E22: [MSRC-17 [모스툴]] | F22: 미래공구 | G22: 10 | H22: 32000 | I22: 320000
A23: 20 | B23: 46058 | C23: 소모성자재 | D23: 볼소켓어댑터 | E23: [13mm(1/2"),CTX [지니어스]] | F23: 미래공구 | G23: 5 | H23: 2700 | I23: 13500
A24: 21 | B24: 46058 | C24: 소모성자재 | D24: 실리콘헤라 | E24: [SPK-3(3호),중 [스마토]] | F24: 미래공구 | G24: 2 | H24: 1200 | I24: 2400
A25: 22 | B25: 46059 | C25: 소모성자재 | D25: 번호열쇠 | E25: [XD-40,4열 [자커]] | F25: 미래공구 | G25: 10 | H25: 3500 | I25: 35000
... A76: 73 | B76: 46080 | C76: 소모성자재 | D76: 체인 | E76: [4mm,CTX [KBC]] | F76: 미래공구 | G76: 3 | H76: 1000 | I76: 3000
A77: 74 | B77: 46080 | C77: 안전용품 | D77: K2 벨트 | F77: 옥션 | G77: 1 | H77: 50909.091 | I77: 50909.091
A78: 75 | B78: 46057 | C78: 소모성자재 | D78: 앤드밀 4.5부품 | F78: ㈜비제이테크 | G78: 1 | H78: 65200 | I78: 65200
A79: 76 | B79: 46059 | C79: 안전용품 | D79: 크린룸가방 | F79: 쿠팡㈜ | G79: 2 | H79: 23636.364 | I79: 47272.727
A80: 77 | B80: 46064 | C80: 소모성자재 | D80: 손전등 라이트 | F80: 쿠팡㈜ | G80: 6 | H80: 7242.4242 | I80: 43454.545

Sheet 숙소임차료
A1: 숙소 임차료
A2: No. | B2: 납부일 | C2: 구분 | D2: 품명 | E2: 주소 | F2: 호수 | G2: 수량 | H2: 사용인원 | I2: 임차료 | J2: 비 고
I3: =SUM(I4:I26) -> 21782143 | L3: 입력해야하는 항목 외 수정 금지
A4: =ROW()-3 -> 1 | B4: 46081 | C4: KC대납 임대료 | D4: 숙소임대료(2월분) | E4: 함박산1길 16 | F4: 301호 | G4: 1 | I4: =800000 -> 800000 | J4: KC 대납 | L4: 납부일
A5: =ROW()-3 -> 2 | B5: 46081 | C5: KC대납 임대료 | D5: 숙소임대료(2월분) | E5: 함박산8길 37 | F5: 302호 | G5: 1 | I5: =800000 -> 800000 | J5: KC 대납 | L5: 구분
A6: =ROW()-3 -> 3 | B6: 46081 | C6: KC대납 임대료 | D6: 숙소임대료(2월분) | E6: 고덕여염11길 85 | F6: 202호 | G6: 1 | I6: =850000 -> 850000 | J6: KC 대납 | L6: 품명
A7: =ROW()-3 -> 4 | B7: 46081 | C7: KC대납 임대료 | D7: 숙소임대료(2월분) | E7: 함박산9길 8-1 | F7: 201호 | G7: 1 | I7: =850000 -> 850000 | J7: KC 대납 | L7: 주소
A8: =ROW()-3 -> 5 | B8: 46081 | C8: KC대납 임대료 | D8: 숙소임대료(2월분) | E8: 함박산12길 8-10 | F8: 301호 | G8: 1 | I8: =950000 -> 950000 | J8: KC 대납 | L8: 호수
A9: =ROW()-3 -> 6 | B9: 46081 | C9: KC대납 임대료 | D9: 숙소임대료(2월분) | E9: 함박산10길 19 | F9: 201호 | G9: 1 | I9: =1000000 -> 1000000 | J9: KC 대납 | L9: 수량
A10: =ROW()-3 -> 7 | B10: 46081 | C10: KC대납 임대료 | D10: 숙소임대료(2월분) | E10: 함박산10길 19 | F10: 301호 | G10: 1 | I10: =1000000 -> 1000000 | J10: KC 대납 | L10: 사용인원
A11: =ROW()-3 -> 8 | B11: 46081 | C11: KC대납 임대료 | D11: 숙소임대료(2월분) | E11: 고덕여염6길 108 | F11: 302호 | G11: 1 | I11: =1000000 -> 1000000 | J11: KC 대납
A12: =ROW()-3 -> 9 | B12: 46081 | C12: KC대납 임대료 | D12: 숙소임대료(2월분) | E12: 고덕여염5길 23-16 | F12: 402호 | G12: 1 | I12: =850000 -> 850000 | J12: KC 대납 | L12: ■ 구분은 [KC대납 임대료 및 임대료] 이외 항목은 입력금지
A13: =ROW()-3 -> 10 | B13: 46081 | C13: KC대납 임대료 | D13: 숙소임대료(2월분) | E13: 고덕여염12길 92 | F13: 202호 | G13: 1 | I13: =850000 -> 850000 | J13: KC 대납
A14: =ROW()-3 -> 11 | B14: 46081 | C14: KC대납 임대료 | D14: 숙소임대료(2월분) | E14: 고덕여염16길 32 | F14: 202호 | G14: 1 | I14: =850000 -> 850000 | J14: KC 대납
A15: =ROW()-3 -> 12 | B15: 46081 | C15: KC대납 임대료 | D15: 숙소임대료(2월분) | E15: 고덕여염 5길 15-10 | F15: 301호 | G15: 1 | I15: =1000000 -> 1000000 | J15: KC 대납
A16: =ROW()-3 -> 13 | B16: 46081 | C16: KC대납 임대료 | D16: 숙소임대료(2월분) | E16: 고덕여염 5길 15-10 | F16: 201호 | G16: 1 | I16: =1000000 -> 1000000 | J16: KC 대납
A17: =ROW()-3 -> 14 | B17: 46081 | C17: KC대납 임대료 | D17: 숙소임대료(2월분) | E17: 고덕여염 5길 15-10 | F17: 202호 | G17: 1 | I17: =1000000 -> 1000000 | J17: KC 대납
A18: =ROW()-3 -> 15 | B18: 46081 | C18: KC대납 임대료 | D18: 숙소임대료(2월분) | E18: 고덕 갈평10길 67 | F18: 201호 | G18: 1 | I18: =950000 -> 950000 | J18: KC 대납
A19: =ROW()-3 -> 16 | B19: 46081 | C19: KC대납 임대료 | D19: 숙소임대료(2월분) | E19: 고덕 갈평10길 102 | F19: 302호 | G19: 1 | I19: =950000 -> 950000 | J19: KC 대납
A20: =ROW()-3 -> 17 | B20: 46081 | C20: KC대납 임대료 | D20: 숙소임대료(2월분) | E20: 고덕 갈평9길 43 | F20: 202호 | G20: 1 | I20: =1000000 -> 1000000 | J20: KC 대납
A21: =ROW()-3 -> 18 | B21: 46081 | C21: KC대납 임대료 | D21: 숙소임대료(2월분) | E21: 함박산2길 32-2 | F21: 201호 | G21: 1 | I21: =1000000 -> 1000000 | J21: KC 대납
A22: =ROW()-3 -> 19 | B22: 46081 | C22: KC대납 임대료 | D22: 숙소임대료(2월분) | E22: 함박산8길 36-2 | F22: 301호 | G22: 1 | I22: =1100000 -> 1100000 | J22: KC 대납
A23: =ROW()-3 -> 20 | B23: 46081 | C23: KC대납 임대료 | D23: 숙소임대료(2월분) | E23: 고덕갈평7길 61 | F23: 301호 | G23: 1 | I23: =1100000 -> 1100000 | J23: KC 대납
A24: =ROW()-3 -> 21 | B24: 46081 | C24: KC대납 임대료 | D24: 숙소임대료(2월분) | E24: 함박산4길 20 | F24: 202호 | G24: 1 | I24: =1100000 -> 1100000 | J24: KC 대납
A25: =ROW()-3 -> 22 | B25: 46081 | C25: KC대납 임대료 | D25: 숙소임대료(2월분) | E25: 칠괴길 118-10 | F25: 303호 | G25: 1 | I25: =550000 -> 550000 | J25: KC 대납
A26: =ROW()-3 -> 23 | B26: 46081 | C26: KC대납 임대료 | D26: 숙소임대료(2월분) | E26: 함박산1길 51 | F26: 301호 | G26: 1 | I26: =1500000/28*23 -> 1232142.9 | J26: KC 대납

Sheet 숙소관리비
A1: 숙소 관리비
A2: No. | B2: 납부일 | C2: 구분 | D2: 품명 | E2: 주소 | F2: 호수 | G2: 수량 | H2: 사용인원 | I2: 임차료 | J2: 비 고
I3: =SUM(I4:I66) -> 5762730
A4: =ROW()-3 -> 1 | B4: 46081 | C4: 관리비 | D4: 숙소전기요금(2월) | E4: 함박산1길 16 | F4: 301호 | G4: 1 | I4: 33420
A5: =ROW()-3 -> 2 | B5: 46081 | C5: 관리비 | D5: 숙소전기요금(2월) | E5: 함박산8길 37 | F5: 302호 | G5: 1 | I5: 23300
A6: =ROW()-3 -> 3 | B6: 46081 | C6: 관리비 | D6: 숙소전기요금(2월) | E6: 고덕여염11길 85 | F6: 202호 | G6: 1 | I6: 24660
A7: =ROW()-3 -> 4 | B7: 46081 | C7: 관리비 | D7: 숙소전기요금(2월) | E7: 함박산9길 8-1 | F7: 201호 | G7: 1 | I7: 24050
A8: =ROW()-3 -> 5 | B8: 46081 | C8: 관리비 | D8: 숙소전기요금(2월) | E8: 함박산12길 8-10 | F8: 301호 | G8: 1 | I8: 33420
A9: =ROW()-3 -> 6 | B9: 46081 | C9: 관리비 | D9: 숙소전기요금(2월) | E9: 함박산10길 19 | F9: 201호 | G9: 1 | I9: 27750
A10: =ROW()-3 -> 7 | B10: 46081 | C10: 관리비 | D10: 숙소전기요금(2월) | E10: 함박산10길 19 | F10: 301호 | G10: 1 | I10: 24880
A11: =ROW()-3 -> 8 | B11: 46081 | C11: 관리비 | D11: 숙소전기요금(2월) | E11: 고덕여염6길 108 | F11: 302호 | G11: 1 | I11: 35090
A12: =ROW()-3 -> 9 | B12: 46081 | C12: 관리비 | D12: 숙소전기요금(2월) | E12: 고덕여염5길 23-16 | F12: 402호 | G12: 1 | I12: 26470
A13: =ROW()-3 -> 10 | B13: 46081 | C13: 관리비 | D13: 숙소전기요금(2월) | E13: 고덕여염12길 92 | F13: 202호 | G13: 1 | I13: 18470
A14: =ROW()-3 -> 11 | B14: 46081 | C14: 관리비 | D14: 숙소전기요금(2월) | E14: 고덕여염16길 32 | F14: 202호 | G14: 1 | I14: 75810
A15: =ROW()-3 -> 12 | B15: 46081 | C15: 관리비 | D15: 숙소전기요금(2월) | E15: 고덕여염 5길 15-10 | F15: 301호 | G15: 1 | I15: 44560
... A66: =ROW()-3 -> 63 | B66: 46081 | C66: 관리비 | D66: 숙소수도요금(2월) | E66: 함박산4길 20 | F66: 202호 | G66: 1 | I66: 1200

Sheet 식대비용
A1: 식대 비용
A2: No. | B2: 납부일 | C2: 구분 | D2: 품명 | E2: 거래처명 | F2: 수량 | G2: 식수인원 | H2: 단가 | I2: 합 계 | J2: 비 고
I3: =SUM(I4:I10) -> 42512273 | L3: 입력해야하는 항목 외 수정 금지
A4: =ROW()-3 -> 1 | B4: 46081 | C4: KC대납 식대 | D4: 기술인및관리자 (현장 식당) | E4: 태정위드유 주식회사 | F4: 1 | G4: 1 | H4: 2506546 | I4: =F4*H4 -> 2506546 | J4: KC 대납 | L4: 입력항목
A5: =ROW()-3 -> 2 | B5: 46081 | C5: KC대납 식대 | D5: 기술인및관리자 (현장 식당) | E5: 다모아한식뷔페 | F5: 67 | G5: 67 | H5: 7000 | I5: =F5*H5 -> 469000 | J5: KC 대납 | L5: 납부일
A6: =ROW()-3 -> 3 | B6: 46081 | C6: KC대납 식대 | D6: 기술인및관리자 (현장 식당) | E6: 영미손김밥 | F6: 1 | G6: 1 | H6: 2170909 | I6: =F6*H6 -> 2170909 | J6: KC 대납 | L6: 구분
A7: =ROW()-3 -> 4 | B7: 46081 | C7: KC대납 식대 | D7: 기술인및관리자 (현장 식당) | E7: 옛날장터 | F7: 5144 | G7: 5144 | H7: 7000 | I7: =F7*H7 -> 36008000 | J7: KC 대납 | L7: 품명
A8: =ROW()-3 -> 5 | B8: 46081 | C8: KC대납 식대 | D8: 기술인및관리자 (현장 식당) | E8: 은주네한식뷔페 | F8: 69 | G8: 69 | H8: 7000 | I8: =F8*H8 -> 483000 | J8: KC 대납 | L8: 거래처명
A9: =ROW()-3 -> 6 | B9: 46081 | C9: KC대납 식대 | D9: 기술인및관리자 (현장 식당) | E9: 삼성김밥 | F9: 1 | G9: 1 | H9: 571545 | I9: =F9*H9 -> 571545 | J9: KC 대납 | L9: 수량
A10: =ROW()-3 -> 7 | B10: 46081 | C10: KC대납 식대 | D10: 기술인및관리자 (현장 식당) | E10: 한솥 | F10: 1 | G10: 1 | H10: 303273 | I10: =F10*H10 -> 303273 | J10: KC 대납 | L10: 식수인원
A11: =ROW()-3 -> 8 | B11: 46081 | C11: 식대 | E11: 법인카드 | F11: 1 | G11: 1 | H11: 1428999 | I11: =F11*H11 -> 1428999 | L11: 단가
A12: =ROW()-3 -> 9 | B12: 46057 | C12: 식대 | D12: 설날 선물세트 | E12: 가락씨제이㈜ | F12: 115 | G12: 115 | H12: 19661.66 | I12: 2261090.9
L13: ■ 구분은 [KC대납 식대 및 식대] 이외 항목은 입력금지

Sheet 기타비용
A1: 기타 비용
A2: No. | B2: 구매일 | C2: 구분 | D2: 품명 | E2: 거래처명 | F2: 수량 | G2: 단가 | H2: 합계 | I2: 비고
H3: =SUM(H4:H24) -> 1026800 | K3: 입력해야하는 항목 외 수정 금지
A4: =ROW()-3 -> 1 | B4: 46055 | C4: 차량유류대 | D4: 85어 5471 포터2 | E4: 남사농업협동조합 | F4: 1 | G4: 63636.364 | H4: =F4*G4 -> 63636.364 | K4: 입력항목
A5: =ROW()-3 -> 2 | B5: 46056 | C5: 차량유류대 | D5: 85어 5471 포터2 | E5: (주)소모 칠곡주유소 | F5: 1 | G5: 9090.9091 | H5: =F5*G5 -> 9090.9091 | I5: 요소수 | K5: 구매일
A6: =ROW()-3 -> 3 | B6: 46057 | C6: 차량유류대 | D6: 85어 5471 포터2 | E6: (주)소모 칠곡주유소 | F6: 1 | G6: 63636.364 | H6: =F6*G6 -> 63636.364 | K6: 구분
A7: =ROW()-3 -> 4 | B7: 46059 | C7: 차량유류대 | D7: 85어 5471 포터2 | E7: (주)소모 칠곡주유소 | F7: 1 | G7: 54545.455 | H7: =F7*G7 -> 54545.455 | K7: 품명
A8: =ROW()-3 -> 5 | B8: 46063 | C8: 차량유류대 | D8: 85어 5471 포터2 | E8: 남사농업협동조합 | F8: 1 | G8: 63636.364 | H8: =F8*G8 -> 63636.364 | K8: 거래처명
A9: =ROW()-3 -> 6 | B9: 46065 | C9: 차량유류대 | D9: 85어 5471 포터2 | E9: (주)소모 칠곡주유소 | F9: 1 | G9: 63636.364 | H9: =F9*G9 -> 63636.364 | K9: 수량
A10: =ROW()-3 -> 7 | B10: 46072 | C10: 차량유류대 | D10: 85어 5471 포터2 | E10: (주)소모 칠곡주유소 | F10: 1 | G10: 63636.364 | H10: =F10*G10 -> 63636.364 | K10: 단가
A11: =ROW()-3 -> 8 | B11: 46072 | C11: 차량유류대 | D11: 85어 5471 포터2 | E11: (주)소모 칠곡주유소 | F11: 1 | G11: 9090.9091 | H11: =F11*G11 -> 9090.9091 | I11: 요소수
A12: =ROW()-3 -> 9 | B12: 46077 | C12: 차량유류대 | D12: 85어 5471 포터2 | E12: 청원로셀프주유소 | F12: 1 | G12: 63636.364 | H12: =F12*G12 -> 63636.364 | K12: ■ 구분은 [사무용품, 소모품비, 법인카드] 이외 항목은 입력금지
A13: =ROW()-3 -> 10 | B13: 46079 | C13: 차량유류대 | D13: 85어 5471 포터2 | E13: SB새벽주유소 | F13: 1 | G13: 63636.364 | H13: =F13*G13 -> 63636.364
A14: =ROW()-3 -> 11 | B14: 46056 | C14: 소모품비 | D14: 85어 5471 엔진오일 | E14: 공임나라 평택진위점 | F14: 1 | G14: 116363.64 | H14: 116363.64
A15: =ROW()-3 -> 12 | B15: 46055 | C15: 소모품비 | D15: AAA건전지 | E15: 쿠팡㈜ | F15: 6 | G15: 8572.7273 | H15: 51436.364
A16: =ROW()-3 -> 13 | B16: 46059 | C16: 소모품비 | D16: 페인트 마카 | E16: 쿠팡㈜ | F16: 36 | G16: 713.63636 | H16: 25690.909
A17: =ROW()-3 -> 14 | B17: 46066 | C17: 소모품비 | D17: AAA건전지 | E17: 쿠팡㈜ | F17: 3 | G17: 7590.9091 | H17: 22772.727
A18: =ROW()-3 -> 15 | B18: 46076 | C18: 소모품비 | D18: 책꽂이 | E18: 쿠팡㈜ | F18: 5 | G18: 1418.1818 | H18: 7090.9091
A19: =ROW()-3 -> 16 | B19: 46076 | C19: 소모품비 | D19: A4 용지 | E19: 쿠팡㈜ | F19: 10 | G19: 17800 | H19: 178000
A20: =ROW()-3 -> 17 | B20: 46077 | C20: 소모품비 | D20: 다용도 가방 | E20: 쿠팡㈜ | F20: 1 | G20: 8100 | H20: 8100
A21: =ROW()-3 -> 18 | B21: 46079 | C21: 소모품비 | D21: A4 코팅지 | E21: 쿠팡㈜ | F21: 5 | G21: 6272.7273 | H21: 31363.636
A22: =ROW()-3 -> 19 | B22: 46080 | C22: 소모품비 | D22: 페인트 마카 | E22: 쿠팡㈜ | F22: 12 | G22: 713.63636 | H22: 8563.6364
A23: =ROW()-3 -> 20 | B23: 46080 | C23: 소모품비 | D23: 페인트 마카 | E23: 쿠팡㈜ | F23: 12 | G23: 713.63636 | H23: 8563.6364
A24: =ROW()-3 -> 21 | B24: 46080 | C24: 소모품비 | D24: AA 건전지 | E24: 쿠팡㈜ | F24: 3 | G24: 16890.909 | H24: 50672.727

Sheet 서명란
B2: 현 장 확 인 | C2: 소 장 | E2: (서명)
C3: 공 사 | E3: (서명)
C4: 공 무 | E4: (서명)
G6: 사 업 부 | H6: Frontier 사업부 GNP 본부장 | I6: BOC 센터장 | J6: Frontier 사업부장
L8: 본 사 | M8: 담 당 | N8: 검 토 | O8: 검 토
Q11: 구 분 | R11: 확 인
Q12: 품 질 | R12: O O O (인)
Q13: 공 무 | R13: O O O (인)

Sheet DIA-INCH
B3: SIZE
B4: A(mm) | C4: Inch
B5: 8A | C5: 0.25
B6: 15A | C6: 0.5
B7: 20A | C7: 0.75
B8: 25A | C8: 1
B9: 32A | C9: 1.25
B10: 40A | C10: 1.5
B11: 50A | C11: 2
B12: 65A | C12: 2.5
B13: 80A | C13: 3
B14: 100A | C14: 4
B15: 110A | C15: 4
B16: 125A | C16: 5
... B27: 550A | C27: 22
