Workbook
Name _: #REF!
Name _: #REF!
Name _??_??_?C?g??: #REF!
Name _??_??_?C?g??: #REF!
Name ___DAT1: [1]원본!#REF!
Name ___DAT10: [1]원본!#REF!
Name ___DAT12: [1]원본!#REF!
Name ___DAT13: [1]원본!#REF!
Name ___DAT14: [1]원본!#REF!
Name ___DAT15: [1]원본!#REF!
Name ___DAT16: [1]원본!#REF!
Name ___DAT17: [1]원본!#REF!
Name ___DAT18: [1]원본!#REF!
Name ___DAT19: [1]원본!#REF!
Name ___DAT2: [1]원본!#REF!
Name ___DAT20: [1]원본!#REF!
Name ___DAT3: [1]원본!#REF!
Name ___DAT4: [1]원본!#REF!
Name ___DAT5: #REF!
Name ___DAT6: [1]원본!#REF!
Name ___DAT7: [1]원본!#REF!
Name ___DAT8: [1]원본!#REF!
Name ___DAT9: [1]원본!#REF!
Name ___QQ123: #REF!
Name __DAT11: #REF!
Name __DAT21: #REF!
Name __DAT22: #REF!
Name __DAT23: #REF!
Name __DAT24: #REF!
Name __DAT25: #REF!
Name __DAT26: #REF!
Name __DAT27: #REF!
Name __DAT28: #REF!
Name __P3: #REF!
Name __P4: #REF!
Name __P5: #REF!
Name __P6: #REF!
Name __PP1: #REF!
Name _0101__장비_설치공사: #REF!
Name _0201__소화_장비설치공사: #REF!
Name _1: #REF!
Name _1: #REF!
Name _1._PANEL_BD.__LP___1: #REF!
Name _1._옥외배관및장비설치공사: #REF!
Name _1_3_0Crite: #REF!
Name _10: [7]고정1!$A$416:$L$458
Name _10A_61: #N/A
Name _10A_62: #N/A
Name _10A_63: #N/A
Name _10A_64: #N/A
Name _10A_65: #N/A
Name _10A_66: #N/A
Name _10A_67: #N/A
Name _10A_68: #N/A
Name _10A_69: #N/A
Name _10A_70: #N/A
Name _10A_71: #N/A
Name _10A_72: #N/A
Name _10A_73: #N/A
Name _10A_74: #N/A

Sheet 용역청구서 표지
B4: 용 역 청 구 서
B7: P4 Ph4 GAS 1공구 마감공사
C8: S25-004
C14: 2026년 07월
C15: 대성이엔지

Sheet 용역 청구서(갑지)
A1: 용 역 청 구 서
A3: 1 | B3: 공 사 명 | C3: : | D3: ='용역청구서 표지'!$B$7 -> P4 Ph4 GAS 1공구 마감공사 | E3: ='용역청구서 표지'!$C$8 -> S25-004
A4: 2 | B4: 공 종 | C4: : | D4: 외주용역(M/M부분)
A5: 3 | B5: 계 약 금 액 | C5: : | D5: =ROUNDUP(E5,0) -> 940000000 | E5: =집계장!I22 -> 940000000 | F5: (VAT 별도)
A6: 4 | B6: 누 계 기 성 금 액 | C6: : | D6: =ROUNDUP(E6,0) -> 940000000 | E6: =E7+E13 -> 940000000 | F6: (VAT 별도)
A7: 5 | B7: 전 회 기 성 금 액 | C7: : | D7: =ROUNDUP(E7,0) -> 640000000 | E7: =집계장!G22 -> 640000000 | F7: (VAT 별도)
A8: 6 | B8: 금 회 기 성 금 액 | C8: : | D8: =ROUNDUP(E8,0) -> 300000000 | E8: =집계장!F22 -> 300000000 | F8: (VAT 별도)
A9: 7 | B9: 선 금 액 | C9: : | D9: =ROUNDUP(E9,0) -> 0 | E9: =집계장!K20 -> 0 | F9: (VAT 별도)
A10: 8 | B10: 선 금 전 회 공 제 | C10: : | D10: =ROUNDUP(E10,0) -> 0 | E10: =집계장!G20 -> 0 | F10: (VAT 별도)
A11: 9 | B11: 선 금 금 회 공 제 | C11: : | D11: =ROUNDUP(E11,0) -> 0 | E11: =집계장!F20 -> 0 | F11: (VAT 별도)
A12: 10 | B12: 선 금 잔 여 금 액 | C12: : | D12: =ROUNDUP(E12,0) -> 0 | E12: =집계장!L20 -> 0 | F12: (VAT 별도)
A13: 11 | B13: 금 회 청 구 금 액 | C13: : | D13: =ROUNDUP(E13,0) -> 300000000 | E13: =집계장!F22 -> 300000000 | F13: (VAT 별도)
A14: 12 | B14: 잔 여 기 성 금 액 | C14: : | D14: =ROUNDUP(E14,0) -> 0 | E14: 0 | F14: (VAT 별도)
A15: 13 | B15: 공 정 율 | C15: : | D15: 1
A16: 14 | B16: 청 구 공 사 기 간 | C16: : | D16: 2026. 07. 01 ~ 2026. 07. 31
B18: 위 공사의 하도급에 있어서 공사설계도서, 시방서,품질관리 기준 및 약정대로 시공 되었음을 확인하오며. 만약 귀사의 현장담당의 검사에
B19: 관하여 하자가 발견된 때에는 즉시 실액배상 또는 재 시공할것을 서약하고 이에 기성 청구서를 제출합니다.
B20: 상기건과 관련하여 본 청구 이전까지의 모든 대금은 수령하였음을 확약합니다.
F21: 작 성 일 : 2026 년 07 월 31 일
F23: 상 호 : | G23: 대성이엔지
B24: ※첨 부 : 기성내역서 1부. | F24: 주 소 : | G24: 경기도 파주시 파주읍 주라위길 380
F25: 대표이사 : | G25: 정 성 기 | I25: (인)
D26: ㈜케이씨이앤씨 귀하

Sheet 용역 내역서(을지)
A1: 용 역 내 역 서
A2: P4 Ph4 GAS 1공구 마감공사 | G2: 단위 : 원
A3: 품 명 | B3: 규 격 | C3: 단위 | D3: 단 가 | E3: 금 회 청 구
E4: 수 량 | F4: 금 액 | G4: 비 고
A5: 고급기술인 | B5: S+ | C5: M/M | D5: 1400000 | E5: 1 | F5: =D5*E5 -> 1400000
A6: 고급기술인 | B6: S | C6: M/M | D6: 1200000 | F6: =D6*E6 -> 0
A7: 중급기술인 | B7: A+ | C7: M/M | D7: 1000000 | F7: =D7*E7 -> 0
A8: 중급기술인 | B8: A | C8: M/M | D8: 900000 | F8: =D8*E8 -> 0
A9: 중급기술인 | B9: B+ | C9: M/M | D9: 800000 | F9: =D9*E9 -> 0
A10: 중급기술인 | B10: B | C10: M/M | D10: 700000 | F10: =D10*E10 -> 0
A11: 초급 기술인 | B11: C | C11: M/M | D11: 600000 | F11: =D11*E11 -> 0
A13: 인센티브 | E13: 0.01 | F13: =SUM(F5:F11)*E13 -> 14000
A15: 총 계 | E15: =SUM(E5:E11) -> 1 | F15: =SUM(F5:F13) -> 1414000

Sheet 내역서(을지)
B1: 용 역 내 역 서
B2: =집계장!A1 -> P4 Ph4 GAS 1공구 마감공사 | H2: 단위 : 원
B3: 품 명 | C3: 규 격 | D3: 단위 | E3: 단 가 | F3: 금 회 청 구 | H3: 비 고
F4: 수 량 | G4: 금 액
B5: 고급기술인 | C5: S+ | D5: M/M | E5: 1400000 | F5: 50 | G5: =E5*F5 -> 70000000
B6: 고급기술인 | C6: S | D6: M/M | E6: 1200000 | F6: 50 | G6: =E6*F6 -> 60000000
B7: 중급기술인 | C7: A+ | D7: M/M | E7: 1000000 | F7: 50 | G7: =E7*F7 -> 50000000
B8: 중급기술인 | C8: A | D8: M/M | E8: 900000 | F8: 50 | G8: =E8*F8 -> 45000000
B9: 중급기술인 | C9: B+ | D9: M/M | E9: 800000 | F9: 50 | G9: =E9*F9 -> 40000000
B10: 중급기술인 | C10: B | D10: M/M | E10: 700000 | F10: 50 | G10: =E10*F10 -> 35000000
B11: 초급기술인 | C11: C | D11: M/M | E11: 600000 | G11: =E11*F11 -> 0
B15: 총 계 | F15: =SUM(F5:F11) -> 300 | G15: =SUM(G5:G14) -> 300000000

Sheet 집계장
A1: ='용역청구서 표지'!$B$7 -> P4 Ph4 GAS 1공구 마감공사
L2: ='용역청구서 표지'!$C$15 -> 대성이엔지
A3: 구분 | B3: 내역 | C3: 단위 | D3: 수량 | E3: 단가 | F3: 합계 | G3: 전회기성 | H3: 금회기성 | I3: 누계기성 | J3: 비 고
A4: 1. 물량 | B4: WELDING POINT | C4: D/I | D4: =SUM('물량 내역서'!$J$5:$J$27) -> 474 | E4: =F4/D4 -> 475000 | F4: =SUM('물량 내역서'!$K$5:$K$27) -> 225150000 | G4: 3151031250 | H4: =F4 -> 225150000 | I4: =G4+H4 -> 3376181250
B5: VALVE 설치비 | C5: EA | D5: =SUM('물량 내역서'!$J$28:$J$50) -> 0 | E5: =F5/D5 -> #DIV/0! | F5: =SUM('물량 내역서'!$K$28:$K$50) -> 0 | G5: 750000 | H5: =F5 -> 0 | I5: =G5+H5 -> 750000
B6: 인원 실투입 | C6: M/D | D6: ='근로내역 (07월)'!AN69 -> 0 | E6: =F6/D6 -> #DIV/0! | F6: ='근로내역 (07월)'!AP69 -> 0 | G6: 0 | H6: =F6 -> 0 | I6: =G6+H6 -> 0
A7: 2. 기타비용 | C7: 式 | D7: 166.875 | E7: 187981 | F7: =ROUND(D7*E7,0) -> 31369329 | G7: 305621768 | H7: =F7 -> 31369329 | I7: =G7+H7 -> 336991097
A8: 소 계 | B8: 물량 | F8: =SUM(F4:F7) -> 256519329 | G8: =SUM(G4:G7) -> 3457403018 | H8: =F8 -> 256519329 | I8: =G8+H8 -> 3713922347
A9: 3. 노무비 | B9: 직접노무비 | C9: 式 | D9: ='근로내역 (07월)'!AN64 -> 1232.125 | E9: =F9/D9 -> 207614.89 | F9: ='근로내역 (07월)'!AP64 -> 255807500 | G9: 1940770950 | H9: =F9 -> 255807500 | I9: =G9+H9 -> 2196578450
A10: 4. 숙소 및 식대 | B10: 임대료+관리비 | C10: 式 | D10: =SUM(숙소임차료!H4:H6)+SUM(숙소관리비!H4:H8) -> 33 | E10: =F10/D10 -> 353668.48 | F10: =숙소임차료!I3+숙소관리비!I3 -> 11671060 | G10: 100814260 | H10: =F10 -> 11671060 | I10: =G10+H10 -> 112485320
B11: 식대 | C11: 式 | D11: =SUM(식대비용!G4:G4) -> 38 | E11: =F11/D11 -> 430263.16 | F11: =식대비용!I3 -> 16350000 | G11: 126456183 | H11: =F11 -> 16350000 | I11: =G11+H11 -> 142806183
A12: 5. 기타 공제 내역 | C12: 式 | E12: 0 | F12: =D12*E12 -> 0 | H12: =F12 -> 0 | I12: =G12+H12 -> 0
A13: 소 계 | B13: 공제 | F13: =SUM(F9:F12) -> 283828560 | G13: =SUM(G9:G12) -> 2168041393 | H13: =F13 -> 283828560 | I13: =G13+H13 -> 2451869953
A14: 합 계 | B14: 기성 (물량-공제) | F14: =F8-F13 -> -27309231 | G14: =G8-G13 -> 1289361625 | H14: =F14 -> -27309231 | I14: =G14+H14 -> 1262052394
A15: 6. 유보금 | B15: 기성금*XX% | C15: 式 | F15: -327338540 | G15: 649238540 | H15: =F15 -> -327338540 | I15: =G15+H15 -> 321900000
A16: 7. 유보금 차액 | B16: 전회 누계유보금+적자 기성액 | C16: 式 | H16: =F16 -> 0 | I16: =G16+H16 -> 0
A17: 8. NEGO | B17: NEGO | C17: 式 | H17: =F17 -> 0 | I17: =G17+H17 -> 0
A18: 총 계 | B18: 최종기성 | F18: =F14-F15-F16-F17 -> 300029309 | G18: =G14-G15 -> 640123085 | H18: =F18 -> 300029309 | I18: =G18+H18 -> 940152394
A19: 선급금 | B19: 선수공제 | C19: 式 | F19: 0 | H19: =F19 -> 0 | I19: =G19+H19 -> 0 | K19: 지급 선급금 | L19: 선급금 차액
B20: 단수정리 | C20: 式 | F20: =ROUNDDOWN(F19,-5) -> 0 | H20: =F20 -> 0 | I20: =G20+H20 -> 0 | J20: 만 단위 이하 절사 | K20: 0 | L20: =K20-I20 -> 0
A21: 공제 후 실 지급액 | F21: =F18-F20 -> 300029309 | G21: =G18 -> 640123085 | H21: =F21 -> 300029309 | I21: =G21+H21 -> 940152394
A22: 세금계산서 기준 | F22: =ROUNDDOWN(F21,-5) -> 300000000 | G22: 640000000 | H22: =F22 -> 300000000 | I22: =G22+H22 -> 940000000 | J22: 만 단위 이하 절사
A23: TERMS AND CONDITIONS | D23: NOTE
A24: 1. 납 기 : KCEnC 지정 납기로 별도 협의 하에 결정하는 것으로 함.
A25: 2. 지불조건 : KCEnC 지불 조건에 따름.
A26: 3. 유효기간 : 기성 제출일로 부터 30일 이내

Sheet 물량 내역서
A1: 2026년 (07)월 물량 내역서
A2: ='용역청구서 표지'!$B$7 -> P4 Ph4 GAS 1공구 마감공사 | M2: 단위 : 원
A3: 품 명 | B3: 규 격 | C3: 단위 | D3: W/P 수량 | E3: 단 가 | F3: 계 약 내 역 | H3: 전 회 누 계 물 량 | J3: 금 회 물 량 | L3: 누 계 물 량
F4: D/I 수량 | G4: 금액 | H4: D/I 수량 | I4: 금액 | J4: D/I 수량 | K4: 금액 | L4: D/I 수량 | M4: 금액
A5: WEDING POINT | B5: 8A | C5: POINT | E5: 475000 | F5: =L5 -> 0 | G5: =M5 -> 0 | J5: =$D5*'DIA-INCH'!$C5 -> 0 | K5: =$E5*$J5 -> 0 | L5: =H5+J5 -> 0 | M5: =I5+K5 -> 0
A6: WEDING POINT | B6: 15A | C6: POINT | E6: 475000 | F6: =L6 -> 0 | G6: =M6 -> 0 | J6: =$D6*'DIA-INCH'!$C6 -> 0 | K6: =$E6*$J6 -> 0 | L6: =H6+J6 -> 0 | M6: =I6+K6 -> 0
A7: WEDING POINT | B7: 20A | C7: POINT | E7: 475000 | F7: =L7 -> 158.25 | G7: =M7 -> 75168750 | H7: 158.25 | I7: 75168750 | J7: =$D7*'DIA-INCH'!$C7 -> 0 | K7: =$E7*$J7 -> 0 | L7: =H7+J7 -> 158.25 | M7: =I7+K7 -> 75168750
A8: WEDING POINT | B8: 25A | C8: POINT | D8: 474 | E8: 475000 | F8: =L8 -> 1466 | G8: =M8 -> 696350000 | H8: 992 | I8: 471200000 | J8: =$D8*'DIA-INCH'!$C8 -> 474 | K8: =$E8*$J8 -> 225150000 | L8: =H8+J8 -> 1466 | M8: =I8+K8 -> 696350000
A9: WEDING POINT | B9: 32A | C9: POINT | E9: 475000 | F9: =L9 -> 0 | G9: =M9 -> 0 | H9: 0 | I9: 0 | J9: =$D9*'DIA-INCH'!$C9 -> 0 | K9: =$E9*$J9 -> 0 | L9: =H9+J9 -> 0 | M9: =I9+K9 -> 0
A10: WEDING POINT | B10: 40A | C10: POINT | E10: 475000 | F10: =L10 -> 205.5 | G10: =M10 -> 97612500 | H10: 205.5 | I10: 97612500 | J10: =$D10*'DIA-INCH'!$C10 -> 0 | K10: =$E10*$J10 -> 0 | L10: =H10+J10 -> 205.5 | M10: =I10+K10 -> 97612500
A11: WEDING POINT | B11: 50A | C11: POINT | E11: 475000 | F11: =L11 -> 574 | G11: =M11 -> 272650000 | H11: 574 | I11: 272650000 | J11: =$D11*'DIA-INCH'!$C11 -> 0 | K11: =$E11*$J11 -> 0 | L11: =H11+J11 -> 574 | M11: =I11+K11 -> 272650000
A12: WEDING POINT | B12: 65A | C12: POINT | E12: 475000 | F12: =L12 -> 770 | G12: =M12 -> 365750000 | H12: 770 | I12: 365750000 | J12: =$D12*'DIA-INCH'!$C12 -> 0 | K12: =$E12*$J12 -> 0 | L12: =H12+J12 -> 770 | M12: =I12+K12 -> 365750000
A13: WEDING POINT | B13: 80A | C13: POINT | E13: 475000 | F13: =L13 -> 1284 | G13: =M13 -> 609900000 | H13: 1284 | I13: 609900000 | J13: =$D13*'DIA-INCH'!$C13 -> 0 | K13: =$E13*$J13 -> 0 | L13: =H13+J13 -> 1284 | M13: =I13+K13 -> 609900000
A14: WEDING POINT | B14: 100A | C14: POINT | E14: 475000 | F14: =L14 -> 656 | G14: =M14 -> 311600000 | H14: 656 | I14: 311600000 | J14: =$D14*'DIA-INCH'!$C14 -> 0 | K14: =$E14*$J14 -> 0 | L14: =H14+J14 -> 656 | M14: =I14+K14 -> 311600000
A15: WEDING POINT | B15: 110A | C15: POINT | E15: 475000 | F15: =L15 -> 0 | G15: =M15 -> 0 | H15: 0 | I15: 0 | J15: =$D15*'DIA-INCH'!$C15 -> 0 | K15: =$E15*$J15 -> 0 | L15: =H15+J15 -> 0 | M15: =I15+K15 -> 0
A16: WEDING POINT | B16: 125A | C16: POINT | E16: 475000 | F16: =L16 -> 320 | G16: =M16 -> 152000000 | H16: 320 | I16: 152000000 | J16: =$D16*'DIA-INCH'!$C16 -> 0 | K16: =$E16*$J16 -> 0 | L16: =H16+J16 -> 320 | M16: =I16+K16 -> 152000000
A17: WEDING POINT | B17: 150A | C17: POINT | E17: 475000 | F17: =L17 -> 450 | G17: =M17 -> 213750000 | H17: 450 | I17: 213750000 | J17: =$D17*'DIA-INCH'!$C17 -> 0 | K17: =$E17*$J17 -> 0 | L17: =H17+J17 -> 450 | M17: =I17+K17 -> 213750000
A18: WEDING POINT | B18: 175A | C18: POINT | E18: 475000 | F18: =L18 -> 0 | G18: =M18 -> 0 | H18: 0 | I18: 0 | J18: =$D18*'DIA-INCH'!$C18 -> 0 | K18: =$E18*$J18 -> 0 | L18: =H18+J18 -> 0 | M18: =I18+K18 -> 0
A19: WEDING POINT | B19: 200A | C19: POINT | E19: 475000 | F19: =L19 -> 1224 | G19: =M19 -> 581400000 | H19: 1224 | I19: 581400000 | J19: =$D19*'DIA-INCH'!$C19 -> 0 | K19: =$E19*$J19 -> 0 | L19: =H19+J19 -> 1224 | M19: =I19+K19 -> 581400000
A20: WEDING POINT | B20: 225A | C20: POINT | E20: 475000 | F20: =L20 -> 0 | G20: =M20 -> 0 | H20: 0 | I20: 0 | J20: =$D20*'DIA-INCH'!$C20 -> 0 | K20: =$E20*$J20 -> 0 | L20: =H20+J20 -> 0 | M20: =I20+K20 -> 0
... A27: WEDING POINT | B27: 550A | C27: POINT | E27: 475000 | F27: =L27 -> 0 | G27: =M27 -> 0 | H27: 0 | I27: 0 | J27: =$D27*'DIA-INCH'!$C27 -> 0 | K27: =$E27*$J27 -> 0 | L27: =H27+J27 -> 0 | M27: =I27+K27 -> 0
A28: VALVE 설치비 | B28: 8A | C28: EA | E28: =$E$31*'DIA-INCH'!$C5 -> 12500 | F28: =L28 -> 0 | G28: =M28 -> 0 | H28: 0 | I28: 0 | J28: =D28 -> 0 | K28: =$J28*$E28 -> 0 | L28: =H28+J28 -> 0 | M28: =I28+K28 -> 0
A29: VALVE 설치비 | B29: 15A | C29: EA | D29: 0 | E29: =$E$31*'DIA-INCH'!$C6 -> 25000 | F29: =L29 -> 0 | G29: =M29 -> 0 | H29: 0 | I29: 0 | J29: =D29 -> 0 | K29: =$J29*$E29 -> 0 | L29: =H29+J29 -> 0 | M29: =I29+K29 -> 0
A30: VALVE 설치비 | B30: 20A | C30: EA | D30: 0 | E30: =$E$31*'DIA-INCH'!$C7 -> 37500 | F30: =L30 -> 0 | G30: =M30 -> 0 | H30: 0 | I30: 0 | J30: =D30 -> 0 | K30: =$J30*$E30 -> 0 | L30: =H30+J30 -> 0 | M30: =I30+K30 -> 0
A31: VALVE 설치비 | B31: 25A | C31: EA | D31: 0 | E31: 50000 | F31: =L31 -> 3 | G31: =M31 -> 150000 | H31: 3 | I31: 150000 | J31: =D31 -> 0 | K31: =$J31*$E31 -> 0 | L31: =H31+J31 -> 3 | M31: =I31+K31 -> 150000
A32: VALVE 설치비 | B32: 32A | C32: EA | D32: 0 | E32: =$E$31*'DIA-INCH'!$C9 -> 62500 | F32: =L32 -> 0 | G32: =M32 -> 0 | H32: 0 | I32: 0 | J32: =D32 -> 0 | K32: =$J32*$E32 -> 0 | L32: =H32+J32 -> 0 | M32: =I32+K32 -> 0
A33: VALVE 설치비 | B33: 40A | C33: EA | D33: 0 | E33: =$E$31*'DIA-INCH'!$C10 -> 75000 | F33: =L33 -> 0 | G33: =M33 -> 0 | H33: 0 | I33: 0 | J33: =D33 -> 0 | K33: =$J33*$E33 -> 0 | L33: =H33+J33 -> 0 | M33: =I33+K33 -> 0
A34: VALVE 설치비 | B34: 50A | C34: EA | D34: 0 | E34: =$E$31*'DIA-INCH'!$C11 -> 100000 | F34: =L34 -> 6 | G34: =M34 -> 600000 | H34: 6 | I34: 600000 | J34: =D34 -> 0 | K34: =$J34*$E34 -> 0 | L34: =H34+J34 -> 6 | M34: =I34+K34 -> 600000
A35: VALVE 설치비 | B35: 65A | C35: EA | D35: 0 | E35: =$E$31*'DIA-INCH'!$C12 -> 125000 | F35: =L35 -> 0 | G35: =M35 -> 0 | J35: =D35 -> 0 | K35: =$J35*$E35 -> 0 | L35: =H35+J35 -> 0 | M35: =I35+K35 -> 0
A36: VALVE 설치비 | B36: 80A | C36: EA | D36: 0 | E36: =$E$31*'DIA-INCH'!$C13 -> 150000 | F36: =L36 -> 0 | G36: =M36 -> 0 | J36: =D36 -> 0 | K36: =$J36*$E36 -> 0 | L36: =H36+J36 -> 0 | M36: =I36+K36 -> 0
A37: VALVE 설치비 | B37: 100A | C37: EA | D37: 0 | E37: =$E$31*'DIA-INCH'!$C14 -> 200000 | F37: =L37 -> 0 | G37: =M37 -> 0 | J37: =D37 -> 0 | K37: =$J37*$E37 -> 0 | L37: =H37+J37 -> 0 | M37: =I37+K37 -> 0
A38: VALVE 설치비 | B38: 110A | C38: EA | D38: 0 | E38: =$E$31*'DIA-INCH'!$C15 -> 200000 | F38: =L38 -> 0 | G38: =M38 -> 0 | J38: =D38 -> 0 | K38: =$J38*$E38 -> 0 | L38: =H38+J38 -> 0 | M38: =I38+K38 -> 0
A39: VALVE 설치비 | B39: 125A | C39: EA | D39: 0 | E39: =$E$31*'DIA-INCH'!$C16 -> 250000 | F39: =L39 -> 0 | G39: =M39 -> 0 | J39: =D39 -> 0 | K39: =$J39*$E39 -> 0 | L39: =H39+J39 -> 0 | M39: =I39+K39 -> 0
A40: VALVE 설치비 | B40: 150A | C40: EA | D40: 0 | E40: =$E$31*'DIA-INCH'!$C17 -> 300000 | F40: =L40 -> 0 | G40: =M40 -> 0 | J40: =D40 -> 0 | K40: =$J40*$E40 -> 0 | L40: =H40+J40 -> 0 | M40: =I40+K40 -> 0
A41: VALVE 설치비 | B41: 175A | C41: EA | D41: 0 | E41: =$E$31*'DIA-INCH'!$C18 -> 350000 | F41: =L41 -> 0 | G41: =M41 -> 0 | J41: =D41 -> 0 | K41: =$J41*$E41 -> 0 | L41: =H41+J41 -> 0 | M41: =I41+K41 -> 0
A42: VALVE 설치비 | B42: 200A | C42: EA | D42: 0 | E42: =$E$31*'DIA-INCH'!$C19 -> 400000 | F42: =L42 -> 0 | G42: =M42 -> 0 | J42: =D42 -> 0 | K42: =$J42*$E42 -> 0 | L42: =H42+J42 -> 0 | M42: =I42+K42 -> 0
A43: VALVE 설치비 | B43: 225A | C43: EA | D43: 0 | E43: =$E$31*'DIA-INCH'!$C20 -> 450000 | F43: =L43 -> 0 | G43: =M43 -> 0 | J43: =D43 -> 0 | K43: =$J43*$E43 -> 0 | L43: =H43+J43 -> 0 | M43: =I43+K43 -> 0
A44: VALVE 설치비 | B44: 250A | C44: EA | D44: 0 | E44: =$E$31*'DIA-INCH'!$C21 -> 500000 | F44: =L44 -> 0 | G44: =M44 -> 0 | J44: =D44 -> 0 | K44: =$J44*$E44 -> 0 | L44: =H44+J44 -> 0 | M44: =I44+K44 -> 0
A45: VALVE 설치비 | B45: 300A | C45: EA | D45: 0 | E45: =$E$31*'DIA-INCH'!$C22 -> 600000 | F45: =L45 -> 0 | G45: =M45 -> 0 | J45: =D45 -> 0 | K45: =$J45*$E45 -> 0 | L45: =H45+J45 -> 0 | M45: =I45+K45 -> 0
A46: VALVE 설치비 | B46: 350A | C46: EA | D46: 0 | E46: =$E$31*'DIA-INCH'!$C23 -> 700000 | F46: =L46 -> 0 | G46: =M46 -> 0 | J46: =D46 -> 0 | K46: =$J46*$E46 -> 0 | L46: =H46+J46 -> 0 | M46: =I46+K46 -> 0
...

Sheet 근로내역 (07월)
A1: 2026년 ( 07 )월 일용 노무비명세서 | AH1: 현장명 | AM1: ='용역청구서 표지'!$B$7 -> P4 Ph4 GAS 1공구 마감공사
AH2: 현장소장 | AM2: 장 규 철
AH3: 잡코드 | AM3: ='용역청구서 표지'!$C$8 -> S25-004
A5: 번호 | B5: 성명 | C5: 주민등록번호 | D5: 직종 | E5: 연락처(H.P) | F5: 은행명 | G5: 예금주 | H5: 계좌번호 | I5: 1 | J5: 2 | K5: 3 | L5: 4 | M5: 5 | N5: 6 | O5: 7 | P5: 8 | Q5: 9 | R5: 10 | S5: 11 | T5: 12 | U5: 13 | V5: 14 | W5: 15 | X5: 16 | Y5: 17 | Z5: 18 | AA5: 19 | AB5: 20 | AC5: 21 | AD5: 22 | AE5: 23 | AF5: 24 | AG5: 25 | AH5: 26 | AI5: 27 | AJ5: 28 | AK5: 29 | AL5: 30 | AM5: 31 | AN5: 공수 | AO5: 단가 | AP5: 총액
A6: 1 | B6: 강대민 | C6: 830328-1536322 | D6: 배관공 | E6: 010-7129-4947 | F6: 농협 | G6: 강대민 | H6: 352-1139-6305-23 | I6: 1.5 | J6: 1.5 | K6: 1.5 | N6: 1.5 | O6: 1.5 | P6: 1.5 | Q6: 1.5 | R6: 1.5 | U6: 1.5 | V6: 1.5 | W6: 1.5 | X6: 1.5 | Y6: 1.5 | Z6: 0.375 | AB6: 1.5 | AC6: 1.5 | AD6: 1.5 | AE6: 2 | AF6: 1 | AI6: 1 | AJ6: 1 | AK6: 1 | AL6: 1 | AN6: =SUM(I6:AM6) -> 31.375 | AO6: 240000 | AP6: =AN6*AO6 -> 7530000
A7: 2 | B7: 고용철 | C7: 820421-1231211 | D7: 도비공 | E7: 010-8727-8563 | F7: 농협 | G7: 고용철 | H7: 352-0319-3536-53 | J7: 1.5 | K7: 1.5 | N7: 1.5 | O7: 1.5 | P7: 1.5 | Q7: 1.5 | R7: 1.5 | S7: 1 | U7: 1.5 | V7: 1.5 | W7: 1.5 | X7: 1.5 | Y7: 1.5 | Z7: 1 | AB7: 1.5 | AC7: 1.5 | AD7: 1.5 | AE7: 2 | AF7: 1 | AI7: 1 | AJ7: 1 | AK7: 1 | AL7: 1 | AM7: 1 | AN7: =SUM(I7:AM7) -> 32.5 | AO7: 210000 | AP7: =AN7*AO7 -> 6825000
A8: 3 | B8: 권국진 | C8: 690215-1017539 | D8: 보통인부 | E8: 010-4346-0215 | F8: 국민 | G8: 권국진 | H8: 357-21-0173-310 | I8: 1.5 | J8: 1.5 | K8: 1.5 | L8: 1 | AN8: =SUM(I8:AM8) -> 5.5 | AO8: 170000 | AP8: =AN8*AO8 -> 935000
A9: 4 | B9: 김건표 | C9: 891127-1451011 | D9: 보통인부 | E9: 010-9180-6601 | F9: 신한 | G9: 김건표 | H9: 110-428-726240 | I9: 1.5 | J9: 1.5 | K9: 1.5 | N9: 1.5 | O9: 1.5 | P9: 0.125 | Q9: 1.5 | R9: 1.5 | U9: 1.5 | V9: 1.5 | W9: 1.5 | X9: 1.5 | Y9: 1.5 | Z9: 1 | AB9: 1.5 | AC9: 1.5 | AD9: 1.5 | AE9: 2 | AN9: =SUM(I9:AM9) -> 25.625 | AO9: 170000 | AP9: =AN9*AO9 -> 4356250
A10: 5 | B10: 김구식 | C10: 680210-1249814 | D10: 보통인부 | E10: 010-8920-2965 | F10: 기업 | G10: 김구식 | H10: 605-008322-01-018 | I10: 1.5 | J10: 1.5 | K10: 1 | AN10: =SUM(I10:AM10) -> 4 | AO10: 160000 | AP10: =AN10*AO10 -> 640000
A11: 6 | B11: 김무열 | C11: 690417-1041629 | D11: 배관공 | E11: 010-4797-4619 | F11: 농협 | G11: 김무열 | H11: 170189-56-105161 | I11: 1.5 | J11: 1.5 | K11: 1.5 | L11: 1 | N11: 1.5 | O11: 1.5 | P11: 1.5 | Q11: 1.5 | U11: 1.5 | V11: 1.5 | W11: 1.5 | X11: 1.5 | Y11: 1.5 | Z11: 1 | AB11: 1.5 | AC11: 1.5 | AD11: 1.5 | AE11: 2 | AF11: 1 | AN11: =SUM(I11:AM11) -> 27.5 | AO11: 240000 | AP11: =AN11*AO11 -> 6600000
A12: 7 | B12: 김세영 | C12: 710324-1026013 | D12: 보통인부 | E12: 010-9087-3534 | F12: 신한 | G12: 김세영 | H12: 110-461-373992 | I12: 1.5 | J12: 1.5 | K12: 1.5 | N12: 1.5 | O12: 1.5 | P12: 1.5 | Q12: 1.5 | R12: 1.5 | S12: 1 | V12: 1.5 | W12: 1.5 | X12: 1.5 | Y12: 1.5 | Z12: 1 | AB12: 1.5 | AC12: 1.5 | AD12: 1.5 | AE12: 2 | AF12: 1 | AN12: =SUM(I12:AM12) -> 27.5 | AO12: 160000 | AP12: =AN12*AO12 -> 4400000
A13: 8 | B13: 김용준 | C13: 000505-3621730 | D13: 보통인부 | E13: 010-3889-2811 | F13: 카카오 | G13: 김용준 | H13: 3333-04-6357745 | I13: 1.375 | J13: 0.75 | AN13: =SUM(I13:AM13) -> 2.125 | AO13: 150000 | AP13: =AN13*AO13 -> 318750
A14: 9 | B14: 김은겸 | C14: 940228-1058917 | D14: 보통인부 | E14: 010-2191-1125 | F14: 신한 | G14: 김은겸 | H14: 110-387-390085 | I14: 1.5 | J14: 1.5 | K14: 1.5 | L14: 0.875 | N14: 1.5 | O14: 1.5 | P14: 1.5 | Q14: 1.5 | R14: 1.5 | U14: 1.5 | V14: 1.5 | W14: 1.5 | X14: 1.375 | Y14: 1.5 | Z14: 1 | AB14: 1.5 | AC14: 1.5 | AD14: 1.5 | AE14: 1 | AN14: =SUM(I14:AM14) -> 26.75 | AO14: 160000 | AP14: =AN14*AO14 -> 4280000
A15: 10 | B15: 김종완 | C15: 740404-1471013 | D15: 배관공 | E15: 010-9983-3546 | F15: 우리 | G15: 김종완 | H15: 1006-001-448823 | I15: 1.5 | J15: 1.5 | K15: 1.5 | L15: 1 | N15: 1.5 | O15: 1.5 | P15: 1.5 | Q15: 1.5 | R15: 1.5 | S15: 1 | U15: 1.5 | V15: 1.5 | W15: 1.5 | X15: 1.5 | Y15: 1.5 | AE15: 2 | AF15: 1 | AN15: =SUM(I15:AM15) -> 24.5 | AO15: 210000 | AP15: =AN15*AO15 -> 5145000
A16: 11 | B16: 김창우 | C16: 751012-1143412 | D16: 보통인부 | E16: 010-4761-8752 | F16: 국민 | G16: 김창우 | H16: 201301-04-324384 | I16: 1.5 | J16: 1.5 | K16: 1.5 | L16: 1 | N16: 1.5 | O16: 1.5 | P16: 1.5 | Q16: 1.5 | R16: 1.5 | S16: 1 | U16: 1.5 | V16: 1.5 | W16: 1.5 | X16: 1.5 | Y16: 1.5 | Z16: 1 | AB16: 1.5 | AC16: 1.5 | AD16: 1.5 | AE16: 1.75 | AF16: 1 | AI16: 1 | AJ16: 1 | AK16: 1 | AL16: 1 | AM16: 1 | AN16: =SUM(I16:AM16) -> 34.75 | AO16: 180000 | AP16: =AN16*AO16 -> 6255000
A17: 12 | B17: 김철 | C17: 761102-1565911 | D17: 공사보조 | E17: 010-5534-8412 | F17: 신한 | G17: 김철 | H17: 110-470-878920 | I17: 1.5 | J17: 1 | K17: 1.5 | L17: 1 | N17: 1.5 | O17: 1.5 | P17: 1.5 | Q17: 1.5 | R17: 1.5 | S17: 1 | U17: 1.5 | V17: 1.5 | W17: 1.5 | X17: 1.5 | Y17: 1.5 | Z17: 1 | AB17: 1.5 | AC17: 1.5 | AD17: 1.5 | AE17: 2 | AF17: 1 | AI17: 0.875 | AJ17: 1 | AK17: 1 | AL17: 1 | AM17: 1 | AN17: =SUM(I17:AM17) -> 34.375 | AO17: 250000 | AP17: =AN17*AO17 -> 8593750
A18: 13 | B18: 김현 | C18: 700121-1017419 | D18: 배관공 | E18: 010-8977-3427 | F18: 우리 | G18: 김현 | H18: 114-158637-02-101 | I18: 1.5 | J18: 1.5 | K18: 1.5 | L18: 0.5 | N18: 1.5 | O18: 1.5 | P18: 1.5 | Q18: 1.5 | R18: 1.5 | S18: 1 | V18: 1.5 | W18: 1.5 | X18: 1.5 | Y18: 1.5 | Z18: 1 | AB18: 1.5 | AC18: 1.5 | AD18: 1.5 | AE18: 2 | AF18: 1 | AI18: 1 | AJ18: 1 | AK18: 1 | AL18: 1 | AM18: 1 | AN18: =SUM(I18:AM18) -> 33 | AO18: 220000 | AP18: =AN18*AO18 -> 7260000
A19: 14 | B19: 김효진 | C19: 880506-1127213 | D19: 용접공 | E19: 010-7185-0506 | F19: 우리 | G19: 김효진 | H19: 1002-341-699461 | I19: 1.5 | J19: 1.5 | K19: 1.5 | L19: 1 | N19: 1.5 | O19: 1.5 | P19: 1.5 | Q19: 1.5 | R19: 1.5 | S19: 1 | U19: 1.5 | V19: 1.5 | W19: 1.5 | X19: 1.5 | Y19: 1.5 | Z19: 1 | AB19: 1.5 | AC19: 1.5 | AD19: 1.5 | AE19: 2 | AF19: 1 | AN19: =SUM(I19:AM19) -> 30 | AO19: 270000 | AP19: =AN19*AO19 -> 8100000
A20: 15 | B20: 류대진 | C20: 690415-1696016 | D20: 보통인부 | E20: 010-2478-4445 | F20: 새마을 | G20: 류대진 | H20: 9002-1656-1013-1 | I20: 1.5 | J20: 1.5 | K20: 1.5 | AN20: =SUM(I20:AM20) -> 4.5 | AO20: 170000 | AP20: =AN20*AO20 -> 765000
A21: 16 | B21: 류수창 | C21: 710427-1696018 | D21: 보통인부 | E21: 010-9288-7211 | F21: 하나 | G21: 류수창 | H21: 424-890005-04207 | I21: 1.5 | J21: 1.5 | K21: 1.5 | L21: 1 | AN21: =SUM(I21:AM21) -> 5.5 | AO21: 170000 | AP21: =AN21*AO21 -> 935000
A22: 17 | B22: 류일화 | C22: 821006-2345313 | D22: 보통인부 | E22: 010-8753-3536 | F22: 국민 | G22: 류일화 | H22: 203901-04-045708 | I22: 1.5 | J22: 1.5 | K22: 1.5 | L22: 0.5 | N22: 1.5 | O22: 1.5 | P22: 1.5 | Q22: 1.5 | R22: 1.5 | S22: 1 | U22: 1.375 | V22: 1.5 | W22: 1.5 | X22: 1.5 | AB22: 1.5 | AC22: 1.5 | AD22: 1.5 | AN22: =SUM(I22:AM22) -> 23.875 | AO22: 140000 | AP22: =AN22*AO22 -> 3342500
A23: 18 | B23: 박경수 | C23: 760113-1226111 | D23: 보통인부 | E23: 010-8743-1066 | F23: 우리 | G23: 박경수 | H23: 1002-831-473236 | I23: 1.5 | J23: 1.5 | K23: 1.5 | AN23: =SUM(I23:AM23) -> 4.5 | AO23: 170000 | AP23: =AN23*AO23 -> 765000
A24: 19 | B24: 박기태 | C24: 841117-1836338 | D24: 배관공 | E24: 010-9800-6028 | F24: 농협 | G24: 박기태 | H24: 883-12-137056 | I24: 1.5 | J24: 1.5 | K24: 0.375 | N24: 1.5 | O24: 1.5 | P24: 1.5 | Q24: 1.5 | R24: 1.5 | S24: 1 | U24: 1.5 | V24: 1.5 | W24: 1.5 | X24: 1.5 | Y24: 1.5 | Z24: 1 | AB24: 1.5 | AC24: 1.5 | AD24: 1.5 | AE24: 2 | AF24: 1 | AN24: =SUM(I24:AM24) -> 27.875 | AO24: 220000 | AP24: =AN24*AO24 -> 6132500
A25: 20 | B25: 박지혜 | C25: 811214-2409013 | D25: 안전보조 | E25: 010-3755-6701 | F25: 우리 | G25: 박지혜 | H25: 1002-544-494559 | I25: 1.5 | J25: 1.5 | K25: 1.5 | L25: 1 | N25: 1.5 | O25: 1.5 | P25: 1.5 | Q25: 1.5 | R25: 1.5 | S25: 1 | U25: 1.5 | V25: 1.5 | W25: 1.5 | X25: 1.5 | Y25: 1.5 | Z25: 1 | AB25: 1.5 | AC25: 1.5 | AD25: 1.5 | AE25: 2 | AF25: 1 | AI25: 1 | AJ25: 1 | AK25: 1 | AL25: 1 | AM25: 1 | AN25: =SUM(I25:AM25) -> 35 | AO25: 170000 | AP25: =AN25*AO25 -> 5950000
A26: 21 | B26: 서문수 | C26: 880429-1120329 | D26: 용접공 | E26: 010-5737-0429 | F26: 국민 | G26: 서문수 | H26: 669502-04-148088 | I26: 1.5 | J26: 1.5 | K26: 1.5 | N26: 1.5 | O26: 1.5 | P26: 1.5 | Q26: 1.5 | R26: 1.5 | U26: 1.5 | V26: 1.5 | W26: 1.5 | Y26: 1.5 | Z26: 1 | AB26: 1.5 | AD26: 1.5 | AE26: 2 | AN26: =SUM(I26:AM26) -> 24 | AO26: 240000 | AP26: =AN26*AO26 -> 5760000
A27: 22 | B27: 서승희 | C27: 941121-2216111 | D27: 공사보조 | E27: 010-8540-8270 | F27: 국민 | G27: 서승희 | H27: 865302-00-042896 | I27: 1.5 | J27: 1.5 | K27: 1.5 | L27: 0.5 | N27: 1.5 | O27: 1.5 | P27: 1.5 | Q27: 1.5 | R27: 1.5 | S27: 1 | U27: 1.5 | V27: 1.5 | W27: 1.5 | X27: 1.5 | Y27: 1.5 | Z27: 1 | AB27: 1.5 | AC27: 1.5 | AD27: 1.5 | AE27: 2 | AF27: 1 | AN27: =SUM(I27:AM27) -> 29.5 | AO27: 190000 | AP27: =AN27*AO27 -> 5605000
A28: 23 | B28: 손지형 | C28: 860805-1050416 | D28: 용접공 | E28: 010-6246-2309 | F28: 농협 | G28: 손지형 | H28: 352-1195-1417-73 | I28: 1.5 | J28: 1.5 | K28: 1.5 | L28: 1 | N28: 1.5 | O28: 1.5 | P28: 1.5 | Q28: 1.5 | R28: 1.5 | S28: 1 | U28: 1.5 | V28: 1.5 | W28: 1.5 | X28: 1.5 | Y28: 1.5 | Z28: 1 | AB28: 1.5 | AC28: 1.5 | AD28: 1.5 | AE28: 2 | AF28: 1 | AN28: =SUM(I28:AM28) -> 30 | AO28: 240000 | AP28: =AN28*AO28 -> 7200000
A29: 24 | B29: 송낙준 | C29: 710505-1031117 | D29: 보통인부 | E29: 010-5442-3194 | F29: 국민 | G29: 송낙준 | H29: 097-21-0547-113 | I29: 1.5 | J29: 1.5 | K29: 1.5 | L29: 1 | N29: 1.5 | O29: 1.5 | P29: 1.5 | Q29: 1.5 | R29: 1.5 | S29: 1 | U29: 1.5 | V29: 1.5 | W29: 1.5 | X29: 1.5 | AB29: 1.5 | AC29: 1.5 | AD29: 1.5 | AE29: 2 | AF29: 1 | AI29: 1 | AJ29: 0.5 | AK29: 1 | AL29: 1 | AM29: 1 | AN29: =SUM(I29:AM29) -> 32 | AO29: 170000 | AP29: =AN29*AO29 -> 5440000
A30: 25 | B30: 송태진 | C30: 740212-1068411 | D30: 용접공 | E30: 010-2927-6925 | F30: 신한 | G30: 송태진 | H30: 110-602-619798 | I30: 1.5 | J30: 1.5 | AN30: =SUM(I30:AM30) -> 3 | AO30: 240000 | AP30: =AN30*AO30 -> 720000
A31: 26 | B31: 신민호 | C31: 821012-1075811 | D31: 배관공 | E31: 010-3343-5663 | F31: 카카오 | G31: 신민호 | H31: 3333-04-7421402 | I31: 1.5 | J31: 1.5 | K31: 1.5 | L31: 1 | N31: 1.5 | O31: 1.5 | P31: 1.5 | Q31: 1 | AN31: =SUM(I31:AM31) -> 11 | AO31: 220000 | AP31: =AN31*AO31 -> 2420000
A32: 27 | B32: 안병문 | C32: 751106-1239319 | D32: 용접공 | E32: 010-9291-2123 | F32: 농협 | G32: 안병문 | H32: 302-1102-5800-61 | I32: 1.5 | J32: 1.5 | K32: 1.5 | L32: 1 | N32: 1.5 | O32: 1.5 | P32: 1.5 | Q32: 1.5 | R32: 1.5 | S32: 1 | U32: 1.5 | V32: 1.5 | W32: 1.5 | X32: 1.5 | Y32: 1.5 | Z32: 1 | AB32: 1.5 | AC32: 1.5 | AD32: 1.5 | AE32: 2 | AF32: 1 | AN32: =SUM(I32:AM32) -> 30 | AO32: 240000 | AP32: =AN32*AO32 -> 7200000
A33: 28 | B33: 안성욱 | C33: 880930-1692719 | D33: 보통인부 | E33: 010-3322-9757 | F33: 국민 | G33: 안성욱 | H33: 93322975739 | I33: 1.5 | J33: 1.5 | K33: 1.5 | L33: 1 | N33: 1.5 | O33: 1.5 | P33: 1.5 | Q33: 1.5 | R33: 1.5 | S33: 1 | U33: 1.5 | V33: 1.5 | W33: 1.5 | X33: 1.5 | Y33: 1.5 | Z33: 1 | AB33: 1.5 | AC33: 1.5 | AD33: 1.5 | AE33: 2 | AF33: 1 | AI33: 1 | AJ33: 1 | AK33: 1 | AL33: 1 | AM33: 1 | AN33: =SUM(I33:AM33) -> 35 | AO33: 160000 | AP33: =AN33*AO33 -> 5600000
A34: 29 | B34: 안은준 | C34: 780115-1650724 | D34: 보통인부 | E34: 010-7661-1451 | F34: 농협 | G34: 안은준 | H34: 352-2051-6961-13 | I34: 1.5 | J34: 1.5 | K34: 1.5 | L34: 1 | N34: 1.5 | O34: 1.5 | P34: 1.5 | Q34: 1.5 | R34: 1.5 | U34: 1.5 | V34: 1.5 | W34: 1.5 | X34: 1.5 | Y34: 1.5 | Z34: 0.5 | AB34: 1.5 | AC34: 1.5 | AD34: 1.5 | AE34: 2 | AF34: 1 | AI34: 1 | AJ34: 1 | AK34: 1 | AL34: 1 | AM34: 1 | AN34: =SUM(I34:AM34) -> 33.5 | AO34: 170000 | AP34: =AN34*AO34 -> 5695000
A35: 30 | B35: 엄진용 | C35: 950826-1026312 | D35: 보통인부 | E35: 010-9936-8504 | F35: 국민 | G35: 엄진용 | H35: 99936850449 | I35: 1.5 | K35: 1.5 | L35: 1 | N35: 1.5 | O35: 1.5 | P35: 1.5 | Q35: 1.5 | R35: 1.375 | V35: 1.5 | W35: 1.5 | X35: 1.5 | Y35: 1.5 | Z35: 0.875 | AB35: 1.5 | AC35: 1.5 | AD35: 1.5 | AE35: 2 | AF35: 1 | AI35: 1 | AJ35: 1 | AK35: 1 | AL35: 1 | AN35: =SUM(I35:AM35) -> 29.75 | AO35: 210000 | AP35: =AN35*AO35 -> 6247500
A36: 31 | B36: 오석영 | C36: 850827-1235312 | D36: 도비공 | E36: 010-5555-9610 | F36: 기업 | G36: 오석영 | H36: 452-004136-01-019 | I36: 1.5 | J36: 1.5 | K36: 0.5 | L36: 1 | N36: 1.5 | O36: 1.5 | P36: 1.5 | Q36: 1.5 | R36: 1.5 | S36: 1 | U36: 1.5 | V36: 1.5 | W36: 1.5 | X36: 1.5 | Y36: 1.5 | Z36: 1 | AB36: 1.5 | AC36: 1.5 | AD36: 1.5 | AE36: 2 | AF36: 1 | AN36: =SUM(I36:AM36) -> 29 | AO36: 180000 | AP36: =AN36*AO36 -> 5220000
A37: 32 | B37: 오성민 | C37: 870328-1482316 | D37: 배관공 | E37: 010-7940-5153 | F37: 농협 | G37: 오성민 | H37: 352-2037-6628-33 | I37: 1.5 | J37: 1.5 | K37: 1.5 | AN37: =SUM(I37:AM37) -> 4.5 | AO37: 220000 | AP37: =AN37*AO37 -> 990000
A38: 33 | B38: 오정석 | C38: 840327-1836316 | D38: 배관공 | E38: 010-3646-6264 | F38: 우리 | G38: 오정석 | H38: 1002-339-959255 | I38: 1.5 | J38: 1.5 | K38: 1.5 | L38: 1 | N38: 1.5 | O38: 1.5 | P38: 1.5 | Q38: 1.5 | R38: 1.5 | S38: 1 | U38: 1.5 | V38: 1.5 | W38: 1.5 | X38: 1.5 | Y38: 1.5 | Z38: 1 | AB38: 1.5 | AC38: 1.5 | AD38: 1.5 | AE38: 2 | AF38: 1 | AN38: =SUM(I38:AM38) -> 30 | AO38: 240000 | AP38: =AN38*AO38 -> 7200000
A39: 34 | B39: 유병권 | C39: 750606-1249810 | D39: 배관공 | E39: 010-5699-9585 | F39: 카카오 | G39: 유병권 | H39: 3333-23-8195284 | I39: 1.5 | J39: 1.5 | K39: 1.5 | AN39: =SUM(I39:AM39) -> 4.5 | AO39: 220000 | AP39: =AN39*AO39 -> 990000
A40: 35 | B40: 윤지환 | C40: 770812-1100111 | D40: 공사보조 | E40: 010-6455-8718 | F40: 새마을 | G40: 윤지환 | H40: 9002-1579-4799-1 | I40: 1.5 | J40: 1.5 | K40: 1.5 | L40: 1 | N40: 1.5 | O40: 1.5 | P40: 1.5 | Q40: 1.5 | R40: 1.5 | S40: 1 | U40: 1.5 | V40: 1.5 | W40: 1.5 | X40: 1.5 | Y40: 1.5 | Z40: 1 | AB40: 1.5 | AC40: 1.5 | AD40: 1.5 | AE40: 2 | AF40: 1 | AI40: 1 | AJ40: 1 | AK40: 1 | AL40: 1 | AM40: 1 | AN40: =SUM(I40:AM40) -> 35 | AO40: 240000 | AP40: =AN40*AO40 -> 8400000
A41: 36 | B41: 은소천 | C41: 830224-1026011 | D41: 배관공 | E41: 010-5248-6056 | F41: 우리 | G41: 은소천 | H41: 1002-253-086774 | I41: 1.5 | J41: 1.5 | K41: 1.5 | L41: 0.5 | N41: 1.5 | O41: 1.5 | P41: 1.5 | Q41: 1.5 | R41: 1.5 | S41: 1 | U41: 1.375 | V41: 1.5 | W41: 1.5 | X41: 1.5 | AB41: 1.5 | AC41: 1.5 | AD41: 1.5 | AN41: =SUM(I41:AM41) -> 23.875 | AO41: 230000 | AP41: =AN41*AO41 -> 5491250
...

Sheet 숙소임차료
A1: 숙소 임차료
A2: No. | B2: 납부일 | C2: 구분 | D2: 품명 | E2: 주소 | F2: 호수 | G2: 수량 | H2: 사용인원 | I2: 임차료 | J2: 비 고
I3: =SUM(I4:I11) -> 10730000 | L3: 입력해야하는 항목 외 수정 금지
A4: 1 | B4: 46234 | C4: KC대납 임대료 | D4: 숙소임대료(07월분) | E4: 고덕 함박산1길 16, 202호 | F4: 202호 | G4: 1 | H4: 3 | I4: 1300000 | J4: KC 대납 | L4: 납부일
A5: 2 | B5: 46234 | C5: KC대납 임대료 | D5: 숙소임대료(07월분) | E5: 고덕 여염12길 103, 302호 | F5: 302호 | G5: 1 | H5: 5 | I5: 1600000 | J5: KC 대납 | L5: 구분
A6: 3 | B6: 46234 | C6: KC대납 임대료 | D6: 숙소임대료(07월분) | E6: 고덕 함박산4길 12, 301호 | F6: 301호 | G6: 1 | H6: 6 | I6: 1600000 | J6: KC 대납 | L6: 품명
A7: 4 | B7: 46234 | C7: KC대납 임대료 | D7: 숙소임대료(07월분) | E7: 고덕 함박산9길 46, 301호 | F7: 301호 | G7: 1 | H7: 4 | I7: 850000 | J7: KC 대납 | L7: 주소
A8: 5 | B8: 46234 | C8: KC대납 임대료 | D8: 숙소임대료(07월분) | E8: 평택시 함박산3길39, 301호 | F8: 301호 | G8: 1 | H8: 4 | I8: 1500000 | J8: KC 대납 | L8: 호수
A9: 6 | B9: 46234 | C9: KC대납 임대료 | D9: 숙소임대료(07월분) | E9: 고덕여염5길 199, 401호 | F9: 401호 | G9: 1 | H9: 6 | I9: 1500000 | J9: KC 대납 | L9: 수량
A10: 7 | B10: 46234 | C10: KC대납 임대료 | D10: 숙소임대료(07월분) | E10: 고덕여염5길213, 302호 | F10: 302호 | G10: 1 | H10: 5 | I10: 1350000 | J10: KC 대납 | L10: 사용인원
A11: 8 | B11: 46234 | C11: KC대납 임대료 | D11: 숙소임대료(07월분) | E11: 고덕 함박산3길 9, 201호 | F11: 201호 | G11: 1 | H11: 5 | I11: 1030000 | J11: KC 대납
L12: ■ 구분은 [KC대납 임대료 및 임대료] 이외 항목은 입력금지

Sheet 숙소관리비
A1: 숙소 관리비
A2: No. | B2: 납부일 | C2: 구분 | D2: 품명 | E2: 주소 | F2: 호수 | G2: 수량 | H2: 사용인원 | I2: 관리비 | J2: 비 고
I3: =SUM(I4:I28) -> 941060
A4: 1 | B4: 46234 | C4: KC대납 관리비 | D4: 숙소수도세(07월분) | E4: 고덕 함박산1길 16, 202호 | F4: 202호 | G4: 1 | H4: 3 | I4: 30580 | J4: KC 대납
A5: 2 | B5: 46234 | C5: KC대납 관리비 | D5: 숙소가스료(07월분) | E5: 고덕 함박산1길 16, 202호 | F5: 202호 | G5: 1 | H5: 3 | I5: 가스 혹서기로 익월청구 | J5: KC 대납
A6: 3 | B6: 46234 | C6: KC대납 관리비 | D6: 숙소전기료(07월분) | E6: 고덕 함박산1길 16, 202호 | F6: 202호 | G6: 1 | H6: 3 | I6: 68260 | J6: KC 대납
A7: 4 | B7: 46234 | C7: KC대납 관리비 | D7: 숙소수도세(07월분) | E7: 고덕 여염12길 103, 302호 | F7: 302호 | G7: 1 | H7: 5 | I7: 35770 | J7: KC 대납
A8: 5 | B8: 46234 | C8: KC대납 관리비 | D8: 숙소가스료(07월분) | E8: 고덕 여염12길 103, 302호 | F8: 302호 | G8: 1 | H8: 5 | I8: 가스 혹서기로 익월청구 | J8: KC 대납
A9: 6 | B9: 46234 | C9: KC대납 관리비 | D9: 숙소전기료(07월분) | E9: 고덕 여염12길 103, 302호 | F9: 302호 | G9: 1 | H9: 5 | I9: 47620 | J9: KC 대납
A10: 7 | B10: 46234 | C10: KC대납 관리비 | D10: 숙소수도세(07월분) | E10: 고덕 함박산4길 12, 301호 | F10: 301호 | G10: 1 | H10: 6 | I10: 34040 | J10: KC 대납
A11: 8 | B11: 46234 | C11: KC대납 관리비 | D11: 숙소가스료(07월분) | E11: 고덕 함박산4길 12, 301호 | F11: 301호 | G11: 1 | H11: 6 | I11: 가스 혹서기로 익월청구 | J11: KC 대납
A12: 9 | B12: 46234 | C12: KC대납 관리비 | D12: 숙소전기료(07월분) | E12: 고덕 함박산4길 12, 301호 | F12: 301호 | G12: 1 | H12: 6 | I12: 36940 | J12: KC 대납
A13: 10 | B13: 46234 | C13: KC대납 관리비 | D13: 숙소수도세(07월분) | E13: 고덕 함박산9길 46, 301호 | F13: 301호 | G13: 1 | H13: 4 | I13: 13290 | J13: KC 대납
A14: 11 | B14: 46234 | C14: KC대납 관리비 | D14: 숙소가스료(07월분) | E14: 고덕 함박산9길 46, 301호 | F14: 301호 | G14: 1 | H14: 4 | I14: 가스 혹서기로 익월청구 | J14: KC 대납
A15: 12 | B15: 46234 | C15: KC대납 관리비 | D15: 숙소전기료(07월분) | E15: 고덕 함박산9길 46, 301호 | F15: 301호 | G15: 1 | H15: 4 | I15: 43120 | J15: KC 대납
A16: 13 | B16: 46234 | C16: KC대납 관리비 | D16: 숙소수도세(07월분) | E16: 평택시 함박산3길39, 301호 | F16: 301호 | G16: 1 | H16: 4 | I16: 30580 | J16: KC 대납
A17: 14 | B17: 46234 | C17: KC대납 관리비 | D17: 숙소가스료(07월분) | E17: 평택시 함박산3길39, 301호 | F17: 301호 | G17: 1 | H17: 4 | I17: 가스 혹서기로 익월청구 | J17: KC 대납
A18: 15 | B18: 46234 | C18: KC대납 관리비 | D18: 숙소전기료(07월분) | E18: 평택시 함박산3길39, 301호 | F18: 301호 | G18: 1 | H18: 4 | I18: 57960 | J18: KC 대납
A19: 16 | B19: 46234 | C19: KC대납 관리비 | D19: 숙소수도세(07월분) | E19: 고덕여염5길 199, 401호 | F19: 401호 | G19: 1 | H19: 6 | I19: 이사정산진행예정 | J19: KC 대납
A20: 17 | B20: 46234 | C20: KC대납 관리비 | D20: 숙소가스료(07월분) | E20: 고덕여염5길 199, 401호 | F20: 401호 | G20: 1 | H20: 6 | I20: 이사정산진행예정 | J20: KC 대납
A21: 18 | B21: 46234 | C21: KC대납 관리비 | D21: 숙소전기료(07월분) | E21: 고덕여염5길 199, 401호 | F21: 401호 | G21: 1 | H21: 6 | I21: 이사정산진행예정 | J21: KC 대납
A22: 19 | B22: 46234 | C22: KC대납 관리비 | D22: 숙소수도세(07월분) | E22: 고덕여염5길213, 302호 | F22: 302호 | G22: 1 | H22: 5 | I22: 이사정산진행예정 | J22: KC 대납
A23: 20 | B23: 46234 | C23: KC대납 관리비 | D23: 숙소가스료(07월분) | E23: 고덕여염5길213, 302호 | F23: 302호 | G23: 1 | H23: 5 | I23: 이사정산진행예정 | J23: KC 대납
A24: 21 | B24: 46234 | C24: KC대납 관리비 | D24: 숙소전기료(07월분) | E24: 고덕여염5길213, 302호 | F24: 302호 | G24: 1 | H24: 5 | I24: 이사정산진행예정 | J24: KC 대납
A25: 22 | B25: 46234 | C25: KC대납 관리비 | D25: 숙소수도세(07월분) | E25: 고덕 함박산3길 9, 201호 | F25: 201호 | G25: 1 | H25: 5 | I25: 15020 | J25: KC 대납
A26: 23 | B26: 46234 | C26: KC대납 관리비 | D26: 숙소가스료(07월분) | E26: 고덕 함박산3길 9, 201호 | F26: 201호 | G26: 1 | H26: 5 | I26: 가스 혹서기로 익월청구 | J26: KC 대납
A27: 24 | B27: 46234 | C27: KC대납 관리비 | D27: 숙소전기료(07월분) | E27: 고덕 함박산3길 9, 201호 | F27: 201호 | G27: 1 | H27: 5 | I27: 41020 | J27: KC 대납
A28: 24 | B28: 46234 | C28: KC대납 관리비 | D28: 숙소전기료(07월분) | E28: 고덕 함박산7길 29, 201호 | F28: 201호 | G28: 1 | H28: 5 | I28: 486860 | J28: KC 대납

Sheet 식대비용
A1: 식대 비용
A2: No. | B2: 납부일 | C2: 구분 | D2: 품명 | E2: 거래처명 | F2: 수량 | G2: 식수인원 | H2: 단가 | I2: 합 계 | J2: 비 고
I3: =SUM(I4:I5) -> 16350000 | L3: 입력해야하는 항목 외 수정 금지
A4: 1 | B4: 46234 | C4: KC대납 식대 | D4: 기술인및관리자 (현장 식당) | E4: 포세카 | F4: 1397 | G4: 38 | H4: 6181 | I4: 8636000 | J4: KC 대납 | L4: 입력항목
A5: 2 | B5: 46234 | C5: KC대납 식대 | D5: 기술인및관리자 (현장 식당) | E5: 밥심 | F5: 1102 | G5: 39 | H5: 7000 | I5: =F5*H5 -> 7714000 | J5: KC 대납 | L5: 납부일
L6: 구분
L7: 품명
L8: 거래처명
L9: 수량
L10: 식수인원
L11: 단가
L13: ■ 구분은 [KC대납 식대 및 식대] 이외 항목은 입력금지

Sheet 기타비용
A1: 기타 비용
A2: No. | B2: 구매일 | C2: 구분 | D2: 품명 | E2: 거래처명 | F2: 수량 | G2: 단가 | H2: 합계 | I2: 비고
H3: =SUM(H4:H27) -> 1012800 | K3: 입력해야하는 항목 외 수정 금지
A4: 1 | B4: 46204 | C4: 소모품비 | D4: 귀마개 [1100,끈없음,200개 [3M]] | E4: 미래공구 | F4: 2 | G4: 43000 | H4: =F4*G4 -> 86000 | I4: 거래명세서 첨부 | K4: 입력항목
A5: 2 | B5: 46204 | C5: 소모품비 | D5: 하이스드릴 [9.5mm [와이지원]] | E5: 미래공구 | F5: 5 | G5: 4800 | H5: =F5*G5 -> 24000 | I5: 거래명세서 첨부 | K5: 납부일
A6: 3 | B6: 46204 | C6: 소모품비 | D6: 하이스드릴 [10.5mm [와이지원]] | E6: 미래공구 | F6: 5 | G6: 6800 | H6: =F6*G6 -> 34000 | I6: 거래명세서 첨부 | K6: 구분
A7: 4 | B7: 46205 | C7: 소모품비 | D7: 스티커제거제 [PIC10,420ML [3M]] | E7: 미래공구 | F7: 5 | G7: 7100 | H7: =F7*G7 -> 35500 | I7: 거래명세서 첨부 | K7: 품명
A8: 5 | B8: 46210 | C8: 소모품비 | D8: 귀마개 [1100,끈없음,200개 [3M]] | E8: 미래공구 | F8: 2 | G8: 43000 | H8: =F8*G8 -> 86000 | I8: 거래명세서 첨부 | K8: 거래처명
A9: 6 | B9: 46210 | C9: 소모품비 | D9: 테프론테이프 [12mm [한양화학]] | E9: 미래공구 | F9: 100 | G9: 300 | H9: =F9*G9 -> 30000 | I9: 거래명세서 첨부 | K9: 수량
A10: 7 | B10: 46211 | C10: 소모품비 | D10: 절연테이프 [19*10m,검정,CTX [금성]] | E10: 미래공구 | F10: 40 | G10: 500 | H10: =F10*G10 -> 20000 | I10: 거래명세서 첨부 | K10: 식수인원
A11: 8 | B11: 46212 | C11: 소모품비 | D11: 밴드쏘고무링 [2107FW용 [마끼다]] | E11: 미래공구 | F11: 6 | G11: 4300 | H11: =F11*G11 -> 25800 | I11: 거래명세서 첨부 | K11: 단가
A12: 9 | B12: 46213 | C12: 소모품비 | D12: 자석테이프 [MT-2300 [스마토]] | E12: 미래공구 | F12: 2 | G12: 7000 | H12: =F12*G12 -> 14000 | I12: 거래명세서 첨부
A13: 10 | B13: 46219 | C13: 소모품비 | D13: 알곤게이지 [KX-3 [코리아나]] | E13: 미래공구 | F13: 2 | G13: 20000 | H13: =F13*G13 -> 40000 | I13: 거래명세서 첨부 | K13: ■ 구분은 [KC대납 식대 및 식대] 이외 항목은 입력금지
A14: 11 | B14: 46219 | C14: 소모품비 | D14: 절연테이프 [19*10m,검정,CTX [금성]] | E14: 미래공구 | F14: 13 | G14: 500 | H14: =F14*G14 -> 6500 | I14: 거래명세서 첨부
A15: 12 | B15: 46219 | C15: 소모품비 | D15: 튜브컷터날 [TCBC105 [슈퍼]] | E15: 미래공구 | F15: 3 | G15: 10000 | H15: =F15*G15 -> 30000 | I15: 거래명세서 첨부
A16: 13 | B16: 46219 | C16: 소모품비 | D16: 네임펜 [양면,흑색,12개 [모나미]] | E16: 미래공구 | F16: 1 | G16: 12400 | H16: =F16*G16 -> 12400 | I16: 거래명세서 첨부
A17: 14 | B17: 46219 | C17: 소모품비 | D17: LED암밴드 [22CM*18.5CM,녹색 [수입]] | E17: 미래공구 | F17: 10 | G17: 4800 | H17: =F17*G17 -> 48000 | I17: 거래명세서 첨부
A18: 15 | B18: 46219 | C18: 소모품비 | D18: 밴드쏘안전커버 [휠커버세트,2107FW용 [마끼다]] | E18: 미래공구 | F18: 1 | G18: 188000 | H18: =F18*G18 -> 188000 | I18: 거래명세서 첨부
A19: 16 | B19: 46219 | C19: 소모품비 | D19: 튜브컷터날 [TCBC105 [슈퍼]] | E19: 미래공구 | F19: 5 | G19: 10000 | H19: =F19*G19 -> 50000 | I19: 거래명세서 첨부
A20: 17 | B20: 46219 | C20: 소모품비 | D20: 튜브컷터 [TCB-105,4-32mm [슈퍼]] | E20: 미래공구 | F20: 2 | G20: 38000 | H20: =F20*G20 -> 76000 | I20: 거래명세서 첨부
A21: 18 | B21: 46219 | C21: 소모품비 | D21: 물통 [식수통,하이쿨,DO-40,4L] | E21: 미래공구 | F21: -2 | G21: 15500 | H21: =F21*G21 -> -31000 | I21: 거래명세서 첨부
A22: 19 | B22: 46219 | C22: 소모품비 | D22: 물통 [식수통,하이쿨2호,DO-661,7L] | E22: 미래공구 | F22: -1 | G22: 30000 | H22: =F22*G22 -> -30000 | I22: 거래명세서 첨부
A23: 20 | B23: 46219 | C23: 소모품비 | D23: 밀폐용기 [20L,350*260*270,직사각42호 [쿨맥시2]] | E23: 미래공구 | F23: 3 | G23: 18300 | H23: =F23*G23 -> 54900 | I23: 거래명세서 첨부
A24: 21 | B24: 46224 | C24: 소모품비 | D24: 코발트드릴 [5.0mm [와이지원]] | E24: 미래공구 | F24: 10 | G24: 3700 | H24: =F24*G24 -> 37000 | I24: 거래명세서 첨부
A25: 22 | B25: 46224 | C25: 소모품비 | D25: 절단석 [4",107*1.2*9.8 [M3]] | E25: 미래공구 | F25: 50 | G25: 600 | H25: =F25*G25 -> 30000 | I25: 거래명세서 첨부
... A27: 24 | B27: 46226 | C27: 소모품비 | D27: 직쏘날 [121AFC,5개 [보쉬]] | E27: 미래공구 | F27: 1 | G27: 9700 | H27: =F27*G27 -> 9700 | I27: 거래명세서 첨부

Sheet 서명란
B2: 현 장 확 인 | C2: 소 장 | E2: (서명)
C3: 공 사 | E3: (서명)
C4: 공 무 | E4: (서명)
G6: 사 업 부 | H6: Frontier 사업부 GNP 본부장 | I6: BOC 센터장 | J6: Frontier 사업부장
L8: 본 사 | M8: 담 당 | N8: 검 토 | O8: 검 토
Q11: 구 분 | R11: 확 인
Q12: 품 질 | R12: O O O (인)
Q13: 공 무 | R13: O O O (인)

Sheet DIA-INCH
B3: SIZE
B4: A(mm) | C4: Inch
B5: 8A | C5: 0.25
B6: 15A | C6: 0.5
B7: 20A | C7: 0.75
B8: 25A | C8: 1
B9: 32A | C9: 1.25
B10: 40A | C10: 1.5
B11: 50A | C11: 2
B12: 65A | C12: 2.5
B13: 80A | C13: 3
B14: 100A | C14: 4
B15: 110A | C15: 4
B16: 125A | C16: 5
... B27: 550A | C27: 22
