Workbook
Name _: #REF!
Name _: #REF!
Name _??_??_?C?g??: #REF!
Name _??_??_?C?g??: #REF!
Name ___DAT5: #REF!
Name ___QQ123: #REF!
Name __DAT11: #REF!
Name __DAT21: #REF!
Name __DAT22: #REF!
Name __DAT23: #REF!
Name __DAT24: #REF!
Name __DAT25: #REF!
Name __DAT26: #REF!
Name __DAT27: #REF!
Name __DAT28: #REF!
Name __P3: #REF!
Name __P4: #REF!
Name __P5: #REF!
Name __P6: #REF!
Name __PP1: #REF!
Name _0101__장비_설치공사: #REF!
Name _0201__소화_장비설치공사: #REF!
Name _1: #REF!
Name _1: #REF!
Name _1._PANEL_BD.__LP___1: #REF!
Name _1._옥외배관및장비설치공사: #REF!
Name _1_3_0Crite: #REF!
Name _10A_61: #N/A
Name _10A_62: #N/A
Name _10A_63: #N/A
Name _10A_64: #N/A
Name _10A_65: #N/A
Name _10A_66: #N/A
Name _10A_67: #N/A
Name _10A_68: #N/A
Name _10A_69: #N/A
Name _10A_70: #N/A
Name _10A_71: #N/A
Name _10A_72: #N/A
Name _10A_73: #N/A
Name _10A_74: #N/A
Name _10A_75: #N/A
Name _10A_76: #N/A
Name _10A_77: #N/A
Name _10A_78: #N/A
Name _10A_79: #N/A
Name _10A_80: #N/A
Name _10A_81: #N/A
Name _10A_82: #N/A
Name _10A_83: #N/A
Name _10A_84: #N/A
Name _10A_85: #N/A
Name _10A_86: #N/A
Name _10A_87: #N/A
Name _10A_88: #N/A
Name _10A_89: #N/A
Name _10A_90: #N/A
Name _10B_61: #N/A
Name _10B_62: #N/A
Name _10B_63: #N/A

Sheet 용역청구서 표지
B4: 용 역 청 구 서
B7: P4 Ph4 GAS 1공구 마감공사
C8: S25-004
C14: 2026년 07월
C15: ㈜태성하이텍

Sheet 용역 청구서(갑지)
A1: 용 역 청 구 서
A3: 1 | B3: 공 사 명 | C3: : | D3: ='용역청구서 표지'!$B$7 -> P4 Ph4 GAS 1공구 마감공사 | E3: ='용역청구서 표지'!$C$8 -> S25-004
A4: 2 | B4: 공 종 | C4: : | D4: 외주용역(M/M부분)
A5: 3 | B5: 계 약 금 액 | C5: : | D5: =ROUNDUP(E5,0) -> 1520000000 | E5: =집계장!I22 -> 1520000000 | F5: (VAT 별도)
A6: 4 | B6: 누 계 기 성 금 액 | C6: : | D6: =ROUNDUP(E6,0) -> 1520000000 | E6: =E7+E13 -> 1520000000 | F6: (VAT 별도)
A7: 5 | B7: 전 회 기 성 금 액 | C7: : | D7: =ROUNDUP(E7,0) -> 1220000000 | E7: =집계장!G22 -> 1220000000 | F7: (VAT 별도)
A8: 6 | B8: 금 회 기 성 금 액 | C8: : | D8: =ROUNDUP(E8,0) -> 300000000 | E8: =집계장!F22 -> 300000000 | F8: (VAT 별도)
A9: 7 | B9: 선 금 액 | C9: : | D9: =ROUNDUP(E9,0) -> 0 | E9: =집계장!K20 -> 0 | F9: (VAT 별도)
A10: 8 | B10: 선 금 전 회 공 제 | C10: : | D10: =ROUNDUP(E10,0) -> 0 | E10: =집계장!G20 -> 0 | F10: (VAT 별도)
A11: 9 | B11: 선 금 금 회 공 제 | C11: : | D11: =ROUNDUP(E11,0) -> 0 | E11: =집계장!F20 -> 0 | F11: (VAT 별도)
A12: 10 | B12: 선 금 잔 여 금 액 | C12: : | D12: =ROUNDUP(E12,0) -> 0 | E12: =집계장!L20 -> 0 | F12: (VAT 별도)
A13: 11 | B13: 금 회 청 구 금 액 | C13: : | D13: =ROUNDUP(E13,0) -> 300000000 | E13: =집계장!F22 -> 300000000 | F13: (VAT 별도)
A14: 12 | B14: 잔 여 기 성 금 액 | C14: : | D14: =ROUNDUP(E14,0) -> 0 | E14: =집계장!I16 -> 0 | F14: (VAT 별도)
A15: 13 | B15: 공 정 율 | C15: : | D15: 1
A16: 14 | B16: 청 구 공 사 기 간 | C16: : | D16: 2026. 07. 01 ~ 2026. 07. 31
B18: 위 공사의 하도급에 있어서 공사설계도서, 시방서,품질관리 기준 및 약정대로 시공 되었음을 확인하오며. 만약 귀사의 현장담당의 검사에
B19: 관하여 하자가 발견된 때에는 즉시 실액배상 또는 재 시공할것을 서약하고 이에 기성 청구서를 제출합니다.
B20: 상기건과 관련하여 본 청구 이전까지의 모든 대금은 수령하였음을 확약합니다.
F21: 작 성 일 : 2026 년 07 월 31 일
F23: 상 호 : | G23: ㈜ 태성하이텍
B24: ※첨 부 : 기성내역서 1부. | F24: 주 소 : | G24: 경기도 용인시 처인구 남사면 봉명리 73-1
F25: 대표이사 : | G25: 유 태 진 | I25: (인)
D26: ㈜케이씨이앤씨 귀하

Sheet 용역 내역서(을지)
A1: 용 역 내 역 서
A2: P4 Ph4 GAS 1공구 마감공사 | G2: 단위 : 원
A3: 품 명 | B3: 규 격 | C3: 단위 | D3: 단 가 | E3: 금 회 청 구
E4: 수 량 | F4: 금 액 | G4: 비 고
A5: 고급기술인 | B5: S+ | C5: M/M | D5: 1400000 | E5: 1 | F5: =D5*E5 -> 1400000
A6: 고급기술인 | B6: S | C6: M/M | D6: 1200000 | F6: =D6*E6 -> 0
A7: 중급기술인 | B7: A+ | C7: M/M | D7: 1000000 | F7: =D7*E7 -> 0
A8: 중급기술인 | B8: A | C8: M/M | D8: 900000 | F8: =D8*E8 -> 0
A9: 중급기술인 | B9: B+ | C9: M/M | D9: 800000 | F9: =D9*E9 -> 0
A10: 중급기술인 | B10: B | C10: M/M | D10: 700000 | F10: =D10*E10 -> 0
A11: 초급 기술인 | B11: C | C11: M/M | D11: 600000 | F11: =D11*E11 -> 0
A13: 인센티브 | E13: 0.01 | F13: =SUM(F5:F11)*E13 -> 14000
A15: 총 계 | E15: =SUM(E5:E11) -> 1 | F15: =SUM(F5:F13) -> 1414000

Sheet 내역서(을지)
A1: 용 역 내 역 서
A2: P4 Ph4 GAS 1공구 마감공사 | G2: 단위 : 원
A3: 품 명 | B3: 규 격 | C3: 단위 | D3: 단 가 | E3: 금 회 청 구 | G3: 비 고
E4: 수 량 | F4: 금 액
A5: 고급기술인 | B5: S+ | C5: M/M | D5: 1400000 | E5: 70 | F5: =D5*E5 -> 98000000
A6: 고급기술인 | B6: S | C6: M/M | D6: 1200000 | E6: 70 | F6: =D6*E6 -> 84000000
A7: 중급기술인 | B7: A+ | C7: M/M | D7: 1000000 | E7: 64 | F7: =D7*E7 -> 64000000
A8: 중급기술인 | B8: A | C8: M/M | D8: 900000 | E8: 60 | F8: =D8*E8 -> 54000000
A9: 중급기술인 | B9: B+ | C9: M/M | D9: 800000 | F9: =D9*E9 -> 0
A10: 중급기술인 | B10: B | C10: M/M | D10: 700000 | F10: =D10*E10 -> 0
A11: 초급기술인 | B11: C | C11: M/M | D11: 600000 | F11: =D11*E11 -> 0
A13: 인센티브 | E13: 0 | F13: =SUM(F5:F11)*E13 -> 0
A16: 총 계 | E16: =SUM(E5:E15) -> 264 | F16: =SUM(F5:F15) -> 300000000

Sheet 집계장
A1: ='용역청구서 표지'!$B$7 -> P4 Ph4 GAS 1공구 마감공사
L2: ='용역청구서 표지'!$C$15 -> ㈜태성하이텍
A3: 구분 | B3: 내역 | C3: 단위 | D3: 수량 | E3: 단가 | F3: 합계 | G3: 전회기성 | H3: 금회기성 | I3: 누계기성 | J3: 비 고
A4: 1. 물량 | B4: WELDING POINT | C4: D/I | D4: =SUM('물량 내역서'!$K$6:$K$28) -> 139.5 | E4: =F4/D4 -> 437000 | F4: =SUM('물량 내역서'!$L$6:$L$28) -> 60961500 | G4: 5431910000 | H4: =F4 -> 60961500 | I4: =G4+H4 -> 5492871500
B5: VALVE 설치비 | C5: EA | D5: =SUM('물량 내역서'!$K$29:$K$51) -> 27 | E5: =F5/D5 -> 97222.222 | F5: =SUM('물량 내역서'!$L$29:$L$51) -> 2625000 | G5: 67287500 | H5: =F5 -> 2625000 | I5: =G5+H5 -> 69912500
B6: 인원 실투입 | C6: M/D | E6: =F6/D6 -> #DIV/0! | F6: ='근로내역 (07월)'!AP55 -> 0 | G6: 0 | H6: =F6 -> 0 | I6: =G6+H6 -> 0
A7: 2. 기타비용 | C7: 式 | D7: 98.25 | E7: 187981 | F7: =ROUND(D7*E7,0) -> 18469133 | G7: 769770390 | H7: =F7 -> 18469133 | I7: =G7+H7 -> 788239523
A8: 소 계 | B8: 물량 | F8: =SUM(F4:F7) -> 82055633 | G8: =SUM(G4:G7) -> 6268967890 | H8: =F8 -> 82055633 | I8: =G8+H8 -> 6351023523
A9: 3. 노무비 | B9: 직접노무비 | C9: 式 | D9: ='근로내역 (07월)'!AN56 -> 785.375 | E9: =F9/D9 -> 180650.96 | F9: ='근로내역 (07월)'!AP56 -> 141878750 | G9: 3514232500 | H9: =F9 -> 141878750 | I9: =G9+H9 -> 3656111250
A10: 4. 숙소 및 식대 | B10: 임대료+관리비 | C10: 式 | D10: 785.375 | E10: =F10/D10 -> 14491.504 | F10: =숙소임차료!I3+숙소관리비!I3 -> 11381265 | G10: 1.4241806e+08 | H10: =F10 -> 11381265 | I10: =G10+H10 -> 1.5379933e+08
B11: 식대 | C11: 式 | D11: 785.375 | E11: =F11/D11 -> 17899.266 | F11: =식대비용!I3 -> 14057636 | G11: 245745364 | H11: =F11 -> 14057636 | I11: =G11+H11 -> 259803000
A12: 5. 기타 공제 내역 | C12: 式 | E12: 0 | F12: =D12*E12 -> 0 | G12: 0 | H12: =F12 -> 0 | I12: =G12+H12 -> 0
A13: 소 계 | B13: 공제 | F13: =SUM(F9:F12) -> 1.6731765e+08 | G13: =SUM(G9:G12) -> 3.9023959e+09 | H13: =F13 -> 1.6731765e+08 | I13: =G13+H13 -> 4.0697136e+09
A14: 합 계 | B14: 기성 (물량-공제) | F14: =F8-F13 -> -85262018 | G14: =G8-G13 -> 2.366572e+09 | H14: =F14 -> -85262018 | I14: =G14+H14 -> 2.2813099e+09
A15: 6. 유보금 | B15: 기성금*XX% | C15: 式 | F15: -385300000 | G15: 1146400000 | H15: =F15 -> -385300000 | I15: =G15+H15 -> 761100000
A16: 7. 유보금 차액 | B16: 전회 누계유보금+적자 기성액 | C16: 式 | H16: =F16 -> 0 | I16: =G16+H16 -> 0
A17: 8. NEGO | B17: NEGO | C17: 式 | H17: =F17 -> 0 | I17: =G17+H17 -> 0
A18: 총 계 | B18: 최종기성 | F18: =F14-F15-F16-F17 -> 3.0003798e+08 | G18: =G14-G15-G16-G17 -> 1.220172e+09 | H18: =F18 -> 3.0003798e+08 | I18: =G18+H18 -> 1.5202099e+09
A19: 선급금 | B19: 선수공제 | C19: 式 | G19: 0 | H19: =F19 -> 0 | I19: =G19+H19 -> 0 | K19: 지급 선급금 | L19: 선급금 차액
B20: 단수정리 | C20: 式 | F20: =ROUNDDOWN(F19,-5) -> 0 | H20: =F20 -> 0 | I20: =G20+H20 -> 0 | J20: 만 단위 이하 절사 | K20: 0 | L20: =K20-I20 -> 0
A21: 공제 후 실 지급액 | F21: =F18-F20 -> 3.0003798e+08 | G21: =G18-G19 -> 1.220172e+09 | H21: =F21 -> 3.0003798e+08 | I21: =G21+H21 -> 1.5202099e+09
A22: 세금계산서 기준 | F22: =ROUNDDOWN(F21,-5) -> 300000000 | G22: 1220000000 | H22: =F22 -> 300000000 | I22: =G22+H22 -> 1520000000 | J22: 만 단위 이하 절사
A23: TERMS AND CONDITIONS | D23: NOTE
A24: 1. 납 기 : KCEnC 지정 납기로 별도 협의 하에 결정하는 것으로 함.
A25: 2. 지불조건 : KCEnC 지불 조건에 따름.
A26: 3. 유효기간 : 기성 제출일로 부터 30일 이내

Sheet 근로내역 (07월)
A1: 2026년 ( 07 )월 일용 노무비명세서 | AH1: 현장명 | AM1: ='용역청구서 표지'!$B$7 -> P4 Ph4 GAS 1공구 마감공사
AH2: 현장소장 | AM2: 장규철
AH3: 잡코드 | AM3: ='용역청구서 표지'!$C$8 -> S25-004
A5: 번호 | B5: 성명 | C5: 주민등록번호 | D5: 직종 | E5: 연락처(H.P) | F5: 은행명 | G5: 예금주 | H5: 계좌번호 | I5: 1 | J5: 2 | K5: 3 | L5: 4 | M5: 5 | N5: 6 | O5: 7 | P5: 8 | Q5: 9 | R5: 10 | S5: 11 | T5: 12 | U5: 13 | V5: 14 | W5: 15 | X5: 16 | Y5: 17 | Z5: 18 | AA5: 19 | AB5: 20 | AC5: 21 | AD5: 22 | AE5: 23 | AF5: 24 | AG5: 25 | AH5: 26 | AI5: 27 | AJ5: 28 | AK5: 29 | AL5: 30 | AM5: 31 | AN5: 공수 | AO5: 단가 | AP5: 총액
A6: 1 | B6: 강우형 | C6: 000830-3484718 | D6: 보통인부 | E6: 010-7963-4799 | F6: 토스 | G6: 강우형 | H6: 1002-2019-2812 | I6: 1.5 | J6: 1.5 | K6: 0.5 | N6: 1.5 | O6: 1.5 | P6: 0.5 | Q6: 1 | R6: 1.5 | S6: 1 | U6: 1.5 | V6: 1.5 | W6: 1.5 | X6: 0.5 | Y6: 1.5 | Z6: 1 | AB6: 1 | AC6: 1.5 | AD6: 0.875 | AE6: 1.5 | AF6: 0.5 | AI6: 1 | AJ6: 1 | AK6: 0.75 | AL6: 1 | AM6: 0.5 | AN6: =SUM(I6:AM6) -> 27.625 | AO6: 150000 | AP6: =AN6*AO6 -> 4143750
A7: 2 | B7: 강원태 | C7: 920818-1240811 | D7: 보통인부 | E7: 010-9205-4684 | F7: 기업 | G7: 강원태 | H7: 186-075475-01-013 | I7: 1.5 | J7: 1.5 | K7: 1.5 | N7: 1.5 | O7: 1.5 | P7: 1.5 | Q7: 1.5 | R7: 0.5 | AN7: =SUM(I7:AM7) -> 11 | AO7: 160000 | AP7: =AN7*AO7 -> 1760000
A8: 3 | B8: 강희재 | C8: 940122-1491011 | D8: 공사보조 | E8: 010-9127-3784 | F8: 신한 | G8: 강희재 | H8: 110-404-502876 | I8: 1.5 | J8: 1.5 | K8: 1.5 | L8: 1 | N8: 1.5 | O8: 1.5 | P8: 1.5 | Q8: 1.5 | R8: 1.5 | S8: 1 | U8: 1.5 | V8: 1.5 | W8: 1.5 | X8: 1 | Y8: 1.5 | Z8: 1 | AB8: 1.5 | AC8: 1.5 | AD8: 1 | AE8: 1.5 | AF8: 1 | AN8: =SUM(I8:AM8) -> 28.5 | AO8: 230000 | AP8: =AN8*AO8 -> 6555000
A9: 4 | B9: 김강현 | C9: 910414-1031829 | D9: 보통인부 | E9: 010-6733-7963 | F9: 신한 | G9: 김강현 | H9: 110-302-846665 | I9: 1.5 | J9: 1.5 | K9: 1.5 | L9: 1 | AN9: =SUM(I9:AM9) -> 5.5 | AO9: 190000 | AP9: =AN9*AO9 -> 1045000
A10: 5 | B10: 김광동 | C10: 930520-1692511 | D10: 보통인부 | E10: 010-4348-0266 | F10: 국민 | G10: 김광동 | H10: 926102-01-496205 | I10: 1.5 | J10: 1.5 | K10: 1.5 | AN10: =SUM(I10:AM10) -> 4.5 | AO10: 150000 | AP10: =AN10*AO10 -> 675000
A11: 6 | B11: 김동민 | C11: 840606-1768018 | D11: 용접공 | E11: 010-3804-2432 | F11: 신한 | G11: 김동민 | H11: 110-408-565589 | I11: 1.5 | J11: 1.5 | K11: 1.5 | L11: 1 | AN11: =SUM(I11:AM11) -> 5.5 | AO11: 240000 | AP11: =AN11*AO11 -> 1320000
A12: 7 | B12: 김명수 | C12: 001211-3823418 | D12: 보통인부 | E12: 010-5797-6473 | F12: 국민 | G12: 김명수 | H12: 944502-00-579965 | I12: 1.5 | K12: 1.5 | L12: 1 | N12: 1.5 | O12: 1.5 | P12: 1.375 | Q12: 1.5 | R12: 1.5 | S12: 1 | U12: 1.5 | V12: 1.5 | W12: 1.5 | X12: 1.375 | Y12: 1.5 | Z12: 1 | AB12: 0.875 | AC12: 1.5 | AD12: 1 | AE12: 1.5 | AF12: 1 | AI12: 1 | AJ12: 1 | AK12: 1 | AL12: 0.875 | AM12: 0.875 | AN12: =SUM(I12:AM12) -> 31.375 | AO12: 150000 | AP12: =AN12*AO12 -> 4706250
A13: 8 | B13: 김성중 | C13: 911126-1043210 | D13: 보통인부 | E13: 010-3777-9825 | F13: 기업 | G13: 김성중 | H13: 118-149246-01-011 | I13: 1.5 | J13: 1.5 | K13: 1.5 | L13: 1 | N13: 1.5 | O13: 1.5 | P13: 1.5 | Q13: 1.5 | AN13: =SUM(I13:AM13) -> 11.5 | AO13: 150000 | AP13: =AN13*AO13 -> 1725000
A14: 9 | B14: 김영광 | C14: 920704-1860718 | D14: 관리보조 | E14: 010-7704-1777 | F14: 기업 | G14: 김영광 | H14: 580-022392-01-010 | I14: 1.5 | J14: 1.5 | K14: 1.5 | N14: 1.5 | O14: 1.5 | P14: 1.25 | Q14: 1.5 | R14: 1.375 | U14: 1.5 | V14: 1.5 | W14: 1.5 | X14: 1.5 | Y14: 1.5 | Z14: 1 | AB14: 1.5 | AC14: 1.375 | AD14: 1 | AE14: 1.5 | AF14: 1 | AI14: 1 | AJ14: 0.875 | AN14: =SUM(I14:AM14) -> 28.375 | AO14: 200000 | AP14: =AN14*AO14 -> 5675000
A15: 10 | B15: 김영철 | C15: 720622-1921415 | D15: 배관공 | E15: 010-3884-4513 | F15: 새마을 | G15: 김영철 | H15: 9003-2504-8199-8 | I15: 1.5 | J15: 1.5 | K15: 1.5 | L15: 1 | N15: 1.5 | O15: 1.5 | P15: 1.5 | Q15: 1.5 | R15: 1.5 | S15: 1 | U15: 1.5 | V15: 1.5 | W15: 1.5 | X15: 1.5 | Y15: 1.5 | AN15: =SUM(I15:AM15) -> 21.5 | AO15: 210000 | AP15: =AN15*AO15 -> 4515000
A16: 11 | B16: 김윤하 | C16: 860417-1348219 | D16: 배관공 | E16: 010-4807-9031 | F16: 국민 | G16: 김윤하 | H16: 263102-04-214815 | I16: 1.5 | J16: 1.5 | K16: 1.5 | AN16: =SUM(I16:AM16) -> 4.5 | AO16: 210000 | AP16: =AN16*AO16 -> 945000
A17: 12 | B17: 김정천 | C17: 010314-3837113 | D17: 보통인부 | E17: 010-2210-3629 | F17: 카카오 | G17: 김정천 | H17: 3333-14-2904871 | I17: 1.5 | J17: 1.5 | K17: 1.5 | L17: 1 | N17: 1.5 | O17: 1.5 | P17: 1.5 | Q17: 1.5 | R17: 1.5 | S17: 1 | U17: 1.5 | V17: 1.5 | W17: 1.5 | X17: 1.5 | Y17: 1.5 | Z17: 1 | AB17: 1.5 | AC17: 1.5 | AD17: 1 | AE17: 1.5 | AF17: 0.875 | AI17: 1 | AJ17: 1 | AK17: 1 | AN17: =SUM(I17:AM17) -> 31.875 | AO17: 150000 | AP17: =AN17*AO17 -> 4781250
A18: 13 | B18: 김태훈 | C18: 810515-1814611 | D18: 보통인부 | E18: 010-5844-3098 | F18: 농협 | G18: 김태훈 | H18: 793-12-097221 | I18: 1.5 | J18: 1.5 | K18: 1.5 | L18: 1 | N18: 1.5 | O18: 1.5 | P18: 1.5 | Q18: 1.5 | R18: 1.5 | S18: 1 | AN18: =SUM(I18:AM18) -> 14 | AO18: 150000 | AP18: =AN18*AO18 -> 2100000
A19: 14 | B19: 남희수 | C19: 741212-1068534 | D19: 보통인부 | E19: 010-8994-9296 | F19: 국민 | G19: 남희수 | H19: 547201-01-029724 | I19: 1.5 | J19: 1.5 | K19: 1.5 | L19: 1 | N19: 1.5 | O19: 1.5 | P19: 1.5 | Q19: 1.5 | R19: 1.5 | S19: 1 | U19: 1.5 | V19: 1.5 | W19: 1.5 | X19: 1.5 | Y19: 1.5 | Z19: 1 | AB19: 1.5 | AC19: 1.5 | AD19: 1 | AE19: 1.5 | AF19: 1 | AI19: 1 | AJ19: 1 | AK19: 1 | AL19: 1 | AM19: 1 | AN19: =SUM(I19:AM19) -> 34 | AO19: 160000 | AP19: =AN19*AO19 -> 5440000
A20: 15 | B20: 도남철 | C20: 681003-1683610 | D20: 보통인부 | E20: 010-3734-2196 | F20: 새마을 | G20: 도남철 | H20: 9002-1869-8588-9 | I20: 1.5 | J20: 1.5 | K20: 1.5 | L20: 1 | N20: 1.5 | O20: 1.5 | P20: 1.5 | Q20: 1.5 | R20: 1.5 | S20: 0.875 | AN20: =SUM(I20:AM20) -> 13.875 | AO20: 150000 | AP20: =AN20*AO20 -> 2081250
A21: 16 | B21: 박성호 | C21: 941107-1199714 | D21: 배관공 | E21: 010-2922-3403 | F21: 기업 | G21: 박성호 | H21: 450-033865-01-013 | I21: 1.5 | J21: 1.5 | K21: 1.5 | L21: 0.5 | N21: 1.5 | O21: 1.5 | P21: 1.5 | Q21: 1.5 | R21: 1.5 | S21: 1 | U21: 1.5 | V21: 1.5 | W21: 1.5 | X21: 1.5 | Y21: 1.5 | Z21: 1 | AB21: 1.5 | AC21: 1.5 | AD21: 1 | AE21: 1.5 | AF21: 1 | AI21: 1 | AJ21: 1 | AK21: 1 | AL21: 1 | AM21: 1 | AN21: =SUM(I21:AM21) -> 33.5 | AO21: 190000 | AP21: =AN21*AO21 -> 6365000
A22: 17 | B22: 박세호 | C22: 830125-1674711 | D22: 용접공 | E22: 010-8898-7171 | F22: 카카오 | G22: 박세호 | H22: 3333-21-7116487 | I22: 1.5 | J22: 1.5 | K22: 1.5 | L22: 1 | AN22: =SUM(I22:AM22) -> 5.5 | AO22: 240000 | AP22: =AN22*AO22 -> 1320000
A23: 18 | B23: 박승남 | C23: 730316-1654417 | D23: 보통인부 | E23: 010-7618-6130 | F23: 농협 | G23: 박승남 | H23: 211065-56-138642 | I23: 1.5 | J23: 1.5 | K23: 1.5 | L23: 1 | N23: 1.5 | O23: 1.5 | P23: 1.5 | Q23: 1.5 | R23: 1.5 | AN23: =SUM(I23:AM23) -> 13 | AO23: 150000 | AP23: =AN23*AO23 -> 1950000
A24: 19 | B24: 박주영 | C24: 730810-1457613 | D24: 배관공 | E24: 010-3356-9406 | F24: 하나 | G24: 박주영 | H24: 130-910013-37908 | J24: 1.5 | K24: 1.5 | L24: 1 | N24: 1.5 | O24: 1.5 | P24: 1.5 | Q24: 1.5 | R24: 1.5 | U24: 1.5 | V24: 1.5 | W24: 1.5 | X24: 1.5 | Y24: 1.5 | Z24: 1 | AN24: =SUM(I24:AM24) -> 20 | AO24: 210000 | AP24: =AN24*AO24 -> 4200000
A25: 20 | B25: 백승배 | C25: 850323-1520514 | D25: 도비공 | E25: 010-8113-3288 | F25: 우체국 | G25: 백승배 | H25: 402057-02-369681 | I25: 1.5 | J25: 1.5 | K25: 1.5 | L25: 1 | N25: 1.5 | O25: 1.5 | P25: 1.5 | Q25: 1.5 | R25: 1.5 | AN25: =SUM(I25:AM25) -> 13 | AO25: 190000 | AP25: =AN25*AO25 -> 2470000
A26: 21 | B26: 서현우 | C26: 911210-1163410 | D26: 보통인부 | E26: 010-2320-6077 | F26: 하나 | G26: 서현우 | H26: 576-910358-27807 | I26: 1.5 | J26: 1.5 | K26: 1.5 | O26: 1.5 | P26: 1.5 | Q26: 1.5 | R26: 1.5 | U26: 1.5 | V26: 1.5 | W26: 1.5 | X26: 1.5 | Y26: 1.5 | AN26: =SUM(I26:AM26) -> 18 | AO26: 150000 | AP26: =AN26*AO26 -> 2700000
A27: 22 | B27: 송수림 | C27: 840920-1789928 | D27: 보통인부 | E27: 010-2777-7145 | F27: 농협 | G27: 송수림 | H27: 352-0253-3500-63 | I27: 1.5 | J27: 1.5 | K27: 1.5 | L27: 1 | AN27: =SUM(I27:AM27) -> 5.5 | AO27: 150000 | AP27: =AN27*AO27 -> 825000
A28: 23 | B28: 신원석 | C28: 820823-1151611 | D28: 보통인부 | E28: 010-5794-3572 | F28: 신한 | G28: 신원석 | H28: 110-312-958801 | I28: 1.5 | J28: 1.5 | K28: 1.5 | L28: 1 | N28: 1.5 | P28: 1.5 | Q28: 1.5 | R28: 1.5 | S28: 0.5 | U28: 1.5 | V28: 1 | W28: 1 | X28: 1 | Y28: 1.5 | Z28: 1 | AC28: 1 | AD28: 1 | AE28: 1 | AF28: 1 | AI28: 1 | AJ28: 1 | AK28: 1 | AL28: 1 | AM28: 1 | AN28: =SUM(I28:AM28) -> 28 | AO28: 190000 | AP28: =AN28*AO28 -> 5320000
A29: 24 | B29: 안성원 | C29: 730222-1674813 | D29: 보통인부 | E29: 010-9575-3445 | F29: 새마을 | G29: 안성원 | H29: 9003-2348-2974-4 | I29: 1.5 | J29: 1.5 | K29: 1.5 | L29: 1 | N29: 1.5 | O29: 1.5 | P29: 1.5 | Q29: 1.5 | R29: 1.5 | S29: 1 | U29: 1.5 | V29: 1.5 | W29: 1.5 | X29: 1.5 | Y29: 1.5 | Z29: 1 | AB29: 1.5 | AC29: 1.5 | AD29: 1 | AE29: 1.5 | AF29: 1 | AI29: 1 | AJ29: 1 | AK29: 1 | AM29: 1 | AN29: =SUM(I29:AM29) -> 33 | AO29: 170000 | AP29: =AN29*AO29 -> 5610000
A30: 25 | B30: 양동현 | C30: 970121-1126611 | D30: 보통인부 | E30: 010-5213-3183 | F30: 카카오 | G30: 양동현 | H30: 3333-05-3629952 | I30: 1.5 | J30: 1.5 | K30: 1.5 | L30: 1 | AN30: =SUM(I30:AM30) -> 5.5 | AO30: 150000 | AP30: =AN30*AO30 -> 825000
A31: 26 | B31: 양희성 | C31: 911226-1178314 | D31: 보통인부 | E31: 010-8362-1226 | F31: 신한 | G31: 양희성 | H31: 110-314-832686 | I31: 1.5 | J31: 1.5 | K31: 1.5 | L31: 1 | AN31: =SUM(I31:AM31) -> 5.5 | AO31: 150000 | AP31: =AN31*AO31 -> 825000
A32: 27 | B32: 원홍연 | C32: 801025-1057720 | D32: 공사보조 | E32: 010-2922-2223 | F32: 카카오 | G32: 원홍연 | H32: 3333-28-3099478 | I32: 1.5 | J32: 1.375 | K32: 1.5 | AN32: =SUM(I32:AM32) -> 4.375 | AO32: 230000 | AP32: =AN32*AO32 -> 1006250
A33: 28 | B33: 이명재 | C33: 840407-1011315 | D33: 배관공 | E33: 010-2288-2353 | F33: 신한 | G33: 이명재 | H33: 110-470-707347 | I33: 1.5 | J33: 1.5 | K33: 1.5 | N33: 1.5 | O33: 1.5 | P33: 1.5 | Q33: 1.5 | R33: 1.5 | S33: 0.5 | U33: 1.5 | V33: 1.5 | W33: 1.5 | X33: 1.5 | Y33: 1.5 | Z33: 1 | AN33: =SUM(I33:AM33) -> 21 | AO33: 200000 | AP33: =AN33*AO33 -> 4200000
A34: 29 | B34: 이상수 | C34: 810518-1927711 | D34: 용접공 | E34: 010-3552-7717 | F34: 기업 | G34: 이상수 | H34: 171-077318-02-013 | I34: 1.375 | J34: 1.5 | K34: 1.5 | P34: 1.5 | Q34: 1.5 | R34: 1.5 | S34: 0.875 | U34: 1.5 | V34: 1.5 | W34: 1.5 | X34: 1.5 | Y34: 1.5 | Z34: 1 | AN34: =SUM(I34:AM34) -> 18.25 | AO34: 240000 | AP34: =AN34*AO34 -> 4380000
A35: 30 | B35: 이정완 | C35: 680304-1661020 | D35: 보통인부 | E35: 010-3833-5897 | F35: 카카오 | G35: 이정완 | H35: 3333-22-9072681 | I35: 1.5 | J35: 1.5 | K35: 1.5 | L35: 1 | N35: 1.5 | O35: 1.5 | P35: 1.5 | Q35: 1.5 | R35: 1.5 | S35: 0.5 | AN35: =SUM(I35:AM35) -> 13.5 | AO35: 150000 | AP35: =AN35*AO35 -> 2025000
A36: 31 | B36: 이주문 | C36: 730118-1047421 | D36: 보통인부 | E36: 010-9628-9599 | F36: 하나 | G36: 이주문 | H36: 159-910705-92107 | K36: 1.5 | N36: 1.5 | O36: 1.5 | P36: 0.375 | Q36: 1.5 | R36: 1.5 | U36: 1.5 | V36: 1.5 | W36: 1.5 | X36: 1.5 | Y36: 1.5 | Z36: 1 | AN36: =SUM(I36:AM36) -> 16.375 | AO36: 160000 | AP36: =AN36*AO36 -> 2620000
A37: 32 | B37: 이준희 | C37: 990409-1482511 | D37: 보통인부 | E37: 010-7610-5782 | F37: 농협 | G37: 이준희 | H37: 352-9999-0409-23 | I37: 1.5 | J37: 1.5 | K37: 1.5 | L37: 1 | AN37: =SUM(I37:AM37) -> 5.5 | AO37: 150000 | AP37: =AN37*AO37 -> 825000
A38: 33 | B38: 이희완 | C38: 910415-1692627 | D38: 용접공 | E38: 010-9909-6141 | F38: 신한 | G38: 이희완 | H38: 110-316-569643 | I38: 1.5 | J38: 1.5 | K38: 1.5 | N38: 0.5 | O38: 1.5 | P38: 1.5 | Q38: 1.5 | AN38: =SUM(I38:AM38) -> 9.5 | AO38: 240000 | AP38: =AN38*AO38 -> 2280000
A39: 34 | B39: 임승희 | C39: 881107-1235222 | D39: 공사보조 | E39: 010-4393-9938 | F39: 신한 | G39: 임승희 | H39: 110-353-055995 | I39: 1.5 | J39: 1.5 | K39: 1.5 | L39: 1 | N39: 1.5 | O39: 1.5 | P39: 1.5 | Q39: 1.5 | R39: 1.5 | S39: 1 | U39: 1.5 | V39: 1.5 | W39: 1.5 | X39: 1.5 | Y39: 1.5 | Z39: 0.5 | AB39: 1.5 | AC39: 1.5 | AD39: 1 | AE39: 1.5 | AF39: 1 | AI39: 1 | AJ39: 1 | AK39: 1 | AN39: =SUM(I39:AM39) -> 31.5 | AO39: 210000 | AP39: =AN39*AO39 -> 6615000
A40: 35 | B40: 전용훈 | C40: 941206-1187916 | D40: 보통인부 | E40: 010-5397-1694 | F40: 기업 | G40: 전용훈 | H40: 972-025806-01-019 | I40: 1.5 | J40: 1.5 | K40: 1.5 | L40: 1 | N40: 1.5 | O40: 1.5 | P40: 1.5 | Q40: 1.5 | R40: 1.5 | S40: 1 | U40: 1.5 | V40: 1.5 | W40: 1.5 | X40: 1.5 | Y40: 1.5 | Z40: 0.375 | AB40: 1.5 | AC40: 1.5 | AD40: 1 | AE40: 1.5 | AF40: 1 | AI40: 1 | AJ40: 1 | AK40: 0.75 | AL40: 0.875 | AM40: 0.875 | AN40: =SUM(I40:AM40) -> 32.875 | AO40: 150000 | AP40: =AN40*AO40 -> 4931250
A41: 36 | B41: 전준 | C41: 800228-1168033 | D41: 보통인부 | E41: 010-2822-3392 | F41: 신한 | G41: 전준 | H41: 110-264-802497 | I41: 1.5 | J41: 1.5 | K41: 1.5 | L41: 1 | N41: 1.5 | O41: 1.5 | P41: 1.5 | Q41: 1.5 | R41: 1.5 | S41: 1 | U41: 1.5 | V41: 1.5 | W41: 1.5 | X41: 1.5 | Y41: 1.5 | Z41: 1 | AB41: 1.5 | AC41: 1.5 | AD41: 0.875 | AE41: 1.5 | AF41: 1 | AI41: 1 | AJ41: 1 | AK41: 1 | AL41: 1 | AM41: 1 | AN41: =SUM(I41:AM41) -> 33.875 | AO41: 210000 | AP41: =AN41*AO41 -> 7113750
...

Sheet 물량 내역서
B2: 2026년 (07)월 물량 내역서
B3: ='용역청구서 표지'!$B$7 -> P4 Ph4 GAS 1공구 마감공사 | N3: 단위 : 원
B4: 품 명 | C4: 규 격 | D4: 단위 | E4: W/P 수량 | F4: 단 가 | G4: 계 약 내 역 | I4: 전 회 누 계 물 량 | K4: 금 회 물 량 | M4: 누 계 물 량
G5: D/I 수량 | H5: 금액 | I5: D/I 수량 | J5: 금액 | K5: D/I 수량 | L5: 금액 | M5: D/I 수량 | N5: 금액
B6: WEDING POINT | C6: 8A | D6: POINT | E6: 0 | F6: 437000 | G6: =M6 -> 0 | H6: =N6 -> 0 | I6: 0 | J6: 0 | K6: =$E6*'DIA-INCH'!$C5 -> 0 | L6: =$F6*$K6 -> 0 | M6: =I6+K6 -> 0 | N6: =J6+L6 -> 0
B7: WEDING POINT | C7: 15A | D7: POINT | E7: 0 | F7: 437000 | G7: =M7 -> 0 | H7: =N7 -> 0 | I7: 0 | J7: 0 | K7: =$E7*'DIA-INCH'!$C6 -> 0 | L7: =$F7*$K7 -> 0 | M7: =I7+K7 -> 0 | N7: =J7+L7 -> 0
B8: WEDING POINT | C8: 20A | D8: POINT | E8: 0 | F8: 437000 | G8: =M8 -> 0 | H8: =N8 -> 0 | I8: 0 | J8: 0 | K8: =$E8*'DIA-INCH'!$C7 -> 0 | L8: =$F8*$K8 -> 0 | M8: =I8+K8 -> 0 | N8: =J8+L8 -> 0
B9: WEDING POINT | C9: 25A | D9: POINT | E9: 71 | F9: 437000 | G9: =M9 -> 1127 | H9: =N9 -> 492499000 | I9: 1056 | J9: 461472000 | K9: =$E9*'DIA-INCH'!$C8 -> 71 | L9: =$F9*$K9 -> 31027000 | M9: =I9+K9 -> 1127 | N9: =J9+L9 -> 492499000
B10: WEDING POINT | C10: 32A | D10: POINT | F10: 437000 | G10: =M10 -> 0 | H10: =N10 -> 0 | I10: 0 | J10: 0 | K10: =$E10*'DIA-INCH'!$C9 -> 0 | L10: =$F10*$K10 -> 0 | M10: =I10+K10 -> 0 | N10: =J10+L10 -> 0
B11: WEDING POINT | C11: 40A | D11: POINT | E11: -1 | F11: 437000 | G11: =M11 -> 468 | H11: =N11 -> 204516000 | I11: 469.5 | J11: 205171500 | K11: =$E11*'DIA-INCH'!$C10 -> -1.5 | L11: =$F11*$K11 -> -655500 | M11: =I11+K11 -> 468 | N11: =J11+L11 -> 204516000
B12: WEDING POINT | C12: 50A | D12: POINT | E12: 3 | F12: 437000 | G12: =M12 -> 1064 | H12: =N12 -> 464968000 | I12: 1058 | J12: 462346000 | K12: =$E12*'DIA-INCH'!$C11 -> 6 | L12: =$F12*$K12 -> 2622000 | M12: =I12+K12 -> 1064 | N12: =J12+L12 -> 464968000
B13: WEDING POINT | C13: 65A | D13: POINT | E13: 0 | F13: 437000 | G13: =M13 -> 757.5 | H13: =N13 -> 331027500 | I13: 757.5 | J13: 331027500 | K13: =$E13*'DIA-INCH'!$C12 -> 0 | L13: =$F13*$K13 -> 0 | M13: =I13+K13 -> 757.5 | N13: =J13+L13 -> 331027500
B14: WEDING POINT | C14: 80A | D14: POINT | E14: -2 | F14: 437000 | G14: =M14 -> 633 | H14: =N14 -> 276621000 | I14: 639 | J14: 279243000 | K14: =$E14*'DIA-INCH'!$C13 -> -6 | L14: =$F14*$K14 -> -2622000 | M14: =I14+K14 -> 633 | N14: =J14+L14 -> 276621000
B15: WEDING POINT | C15: 100A | D15: POINT | E15: -1 | F15: 437000 | G15: =M15 -> 1288 | H15: =N15 -> 562856000 | I15: 1292 | J15: 564604000 | K15: =$E15*'DIA-INCH'!$C14 -> -4 | L15: =$F15*$K15 -> -1748000 | M15: =I15+K15 -> 1288 | N15: =J15+L15 -> 562856000
B16: WEDING POINT | C16: 110A | D16: POINT | F16: 437000 | G16: =M16 -> 0 | H16: =N16 -> 0 | I16: 0 | J16: 0 | K16: =$E16*'DIA-INCH'!$C15 -> 0 | L16: =$F16*$K16 -> 0 | M16: =I16+K16 -> 0 | N16: =J16+L16 -> 0
B17: WEDING POINT | C17: 125A | D17: POINT | E17: 8 | F17: 437000 | G17: =M17 -> 2970 | H17: =N17 -> 1297890000 | I17: 2930 | J17: 1280410000 | K17: =$E17*'DIA-INCH'!$C16 -> 40 | L17: =$F17*$K17 -> 17480000 | M17: =I17+K17 -> 2970 | N17: =J17+L17 -> 1297890000
B18: WEDING POINT | C18: 150A | D18: POINT | E18: 1 | F18: 437000 | G18: =M18 -> 144 | H18: =N18 -> 62928000 | I18: 138 | J18: 60306000 | K18: =$E18*'DIA-INCH'!$C17 -> 6 | L18: =$F18*$K18 -> 2622000 | M18: =I18+K18 -> 144 | N18: =J18+L18 -> 62928000
B19: WEDING POINT | C19: 175A | D19: POINT | F19: 437000 | G19: =M19 -> 0 | H19: =N19 -> 0 | I19: 0 | J19: 0 | K19: =$E19*'DIA-INCH'!$C18 -> 0 | L19: =$F19*$K19 -> 0 | M19: =I19+K19 -> 0 | N19: =J19+L19 -> 0
B20: WEDING POINT | C20: 200A | D20: POINT | E20: 2 | F20: 437000 | G20: =M20 -> 904 | H20: =N20 -> 395048000 | I20: 888 | J20: 388056000 | K20: =$E20*'DIA-INCH'!$C19 -> 16 | L20: =$F20*$K20 -> 6992000 | M20: =I20+K20 -> 904 | N20: =J20+L20 -> 395048000
B21: WEDING POINT | C21: 225A | D21: POINT | F21: 437000 | G21: =M21 -> 0 | H21: =N21 -> 0 | I21: 0 | J21: 0 | K21: =$E21*'DIA-INCH'!$C20 -> 0 | L21: =$F21*$K21 -> 0 | M21: =I21+K21 -> 0 | N21: =J21+L21 -> 0
B22: WEDING POINT | C22: 250A | D22: POINT | E22: 0 | F22: 437000 | G22: =M22 -> 1030 | H22: =N22 -> 450110000 | I22: 1030 | J22: 450110000 | K22: =$E22*'DIA-INCH'!$C21 -> 0 | L22: =$F22*$K22 -> 0 | M22: =I22+K22 -> 1030 | N22: =J22+L22 -> 450110000
B23: WEDING POINT | C23: 300A | D23: POINT | E23: 1 | F23: 437000 | G23: =M23 -> 2184 | H23: =N23 -> 954408000 | I23: 2172 | J23: 949164000 | K23: =$E23*'DIA-INCH'!$C22 -> 12 | L23: =$F23*$K23 -> 5244000 | M23: =I23+K23 -> 2184 | N23: =J23+L23 -> 954408000
B24: WEDING POINT | C24: 350A | D24: POINT | E24: 0 | F24: 437000 | G24: =M24 -> 0 | H24: =N24 -> 0 | I24: 0 | J24: 0 | K24: =$E24*'DIA-INCH'!$C23 -> 0 | L24: =$F24*$K24 -> 0 | M24: =I24+K24 -> 0 | N24: =J24+L24 -> 0
B25: WEDING POINT | C25: 400A | D25: POINT | E25: 0 | F25: 437000 | G25: =M25 -> 0 | H25: =N25 -> 0 | I25: 0 | J25: 0 | K25: =$E25*'DIA-INCH'!$C24 -> 0 | L25: =$F25*$K25 -> 0 | M25: =I25+K25 -> 0 | N25: =J25+L25 -> 0
B26: WEDING POINT | C26: 450A | D26: POINT | E26: 0 | F26: 437000 | G26: =M26 -> 0 | H26: =N26 -> 0 | I26: 0 | J26: 0 | K26: =$E26*'DIA-INCH'!$C25 -> 0 | L26: =$F26*$K26 -> 0 | M26: =I26+K26 -> 0 | N26: =J26+L26 -> 0
B27: WEDING POINT | C27: 500A | D27: POINT | E27: 0 | F27: 437000 | G27: =M27 -> 0 | H27: =N27 -> 0 | I27: 0 | J27: 0 | K27: =$E27*'DIA-INCH'!$C26 -> 0 | L27: =$F27*$K27 -> 0 | M27: =I27+K27 -> 0 | N27: =J27+L27 -> 0
B28: WEDING POINT | C28: 550A | D28: POINT | E28: 0 | F28: 437000 | G28: =M28 -> 0 | H28: =N28 -> 0 | I28: 0 | J28: 0 | K28: =$E28*'DIA-INCH'!$C27 -> 0 | L28: =$F28*$K28 -> 0 | M28: =I28+K28 -> 0 | N28: =J28+L28 -> 0
B29: VALVE 설치비 | C29: 8A | D29: EA | E29: 0 | F29: =$F$32*'DIA-INCH'!$C5 -> 21875 | G29: =M29 -> 0 | H29: =N29 -> 0 | I29: 0 | J29: 0 | K29: =E29 -> 0 | L29: =$K29*$F29 -> 0 | M29: =I29+K29 -> 0 | N29: =J29+L29 -> 0
B30: VALVE 설치비 | C30: 15A | D30: EA | E30: 0 | F30: =$F$32*'DIA-INCH'!$C6 -> 43750 | G30: =M30 -> 0 | H30: =N30 -> 0 | I30: 0 | J30: 0 | K30: =E30 -> 0 | L30: =$K30*$F30 -> 0 | M30: =I30+K30 -> 0 | N30: =J30+L30 -> 0
B31: VALVE 설치비 | C31: 20A | D31: EA | E31: 0 | F31: =$F$32*'DIA-INCH'!$C7 -> 65625 | G31: =M31 -> 0 | H31: =N31 -> 0 | I31: 0 | J31: 0 | K31: =E31 -> 0 | L31: =$K31*$F31 -> 0 | M31: =I31+K31 -> 0 | N31: =J31+L31 -> 0
B32: VALVE 설치비 | C32: 25A | D32: EA | E32: 21 | F32: 87500 | G32: =M32 -> 186 | H32: =N32 -> 16275000 | I32: 165 | J32: 14437500 | K32: =E32 -> 21 | L32: =$K32*$F32 -> 1837500 | M32: =I32+K32 -> 186 | N32: =J32+L32 -> 16275000
B33: VALVE 설치비 | C33: 32A | D33: EA | E33: 0 | F33: =$F$32*'DIA-INCH'!$C9 -> 109375 | G33: =M33 -> 90 | H33: =N33 -> 9843750 | I33: 90 | J33: 9843750 | K33: =E33 -> 0 | L33: =$K33*$F33 -> 0 | M33: =I33+K33 -> 90 | N33: =J33+L33 -> 9843750
B34: VALVE 설치비 | C34: 40A | D34: EA | E34: 6 | F34: =$F$32*'DIA-INCH'!$C10 -> 131250 | G34: =M34 -> 39 | H34: =N34 -> 5118750 | I34: 33 | J34: 4331250 | K34: =E34 -> 6 | L34: =$K34*$F34 -> 787500 | M34: =I34+K34 -> 39 | N34: =J34+L34 -> 5118750 | P34: =+K34*1.5 -> 9
B35: VALVE 설치비 | C35: 50A | D35: EA | E35: 0 | F35: =$F$32*'DIA-INCH'!$C11 -> 175000 | G35: =M35 -> 29 | H35: =N35 -> 5075000 | I35: 29 | J35: 5075000 | K35: =E35 -> 0 | L35: =$K35*$F35 -> 0 | M35: =I35+K35 -> 29 | N35: =J35+L35 -> 5075000
B36: VALVE 설치비 | C36: 65A | D36: EA | E36: 0 | F36: =$F$32*'DIA-INCH'!$C12 -> 218750 | G36: =M36 -> 10 | H36: =N36 -> 2187500 | I36: 10 | J36: 2187500 | K36: =E36 -> 0 | L36: =$K36*$F36 -> 0 | M36: =I36+K36 -> 10 | N36: =J36+L36 -> 2187500
B37: VALVE 설치비 | C37: 80A | D37: EA | E37: 0 | F37: =$F$32*'DIA-INCH'!$C13 -> 262500 | G37: =M37 -> 34 | H37: =N37 -> 8925000 | I37: 34 | J37: 8925000 | K37: =E37 -> 0 | L37: =$K37*$F37 -> 0 | M37: =I37+K37 -> 34 | N37: =J37+L37 -> 8925000
B38: VALVE 설치비 | C38: 100A | D38: EA | E38: 0 | F38: =$F$32*'DIA-INCH'!$C14 -> 350000 | G38: =M38 -> 2 | H38: =N38 -> 700000 | I38: 2 | J38: 700000 | K38: =E38 -> 0 | L38: =$K38*$F38 -> 0 | M38: =I38+K38 -> 2 | N38: =J38+L38 -> 700000
B39: VALVE 설치비 | C39: 110A | D39: EA | E39: 0 | F39: =$F$32*'DIA-INCH'!$C15 -> 350000 | G39: =M39 -> 0 | H39: =N39 -> 0 | I39: 0 | J39: 0 | K39: =E39 -> 0 | L39: =$K39*$F39 -> 0 | M39: =I39+K39 -> 0 | N39: =J39+L39 -> 0
B40: VALVE 설치비 | C40: 125A | D40: EA | E40: 0 | F40: =$F$32*'DIA-INCH'!$C16 -> 437500 | G40: =M40 -> 43 | H40: =N40 -> 18812500 | I40: 43 | J40: 18812500 | K40: =E40 -> 0 | L40: =$K40*$F40 -> 0 | M40: =I40+K40 -> 43 | N40: =J40+L40 -> 18812500
B41: VALVE 설치비 | C41: 150A | D41: EA | E41: 0 | F41: =$F$32*'DIA-INCH'!$C17 -> 525000 | G41: =M41 -> 1 | H41: =N41 -> 525000 | I41: 1 | J41: 525000 | K41: =E41 -> 0 | L41: =$K41*$F41 -> 0 | M41: =I41+K41 -> 1 | N41: =J41+L41 -> 525000
...

Sheet 용접기자재
A1: 용접 기자재
A2: No | B2: 구매일 | C2: 구분 | D2: 품명 | E2: 규격 | F2: 거래처명 | G2: 발주수량 | H2: 단가 | I2: 합계 | J2: 비고
I3: =ROUND(SUM(I4:I82),) -> 0
A4: =ROW()-3 -> 1 | L4: 입력해야하는 항목 외 수정 금지
A5: =ROW()-3 -> 2 | L5: 입력항목
A6: =ROW()-3 -> 3 | L6: 구매일
A7: =ROW()-3 -> 4 | L7: 구분
A8: =ROW()-3 -> 5 | L8: 품명
A9: =ROW()-3 -> 6 | L9: 규격
L10: 거래처명
L11: 발주수량
L12: 단가
L14: ■ 구분은 [소모성자재, 공구, 임대(공구), 안전용품, 비품] 이외 항목은 입력금지

Sheet 배관기자재
A1: 배관 기자재
A2: No | B2: 구매일 | C2: 구분 | D2: 품명 | E2: 규격 | F2: 거래처명 | G2: 발주수량 | H2: 단가 | I2: 합계 | J2: 비고
I3: =ROUND(SUM(I4:I34),) -> 215736 | L3: 입력해야하는 항목 외 수정 금지
A4: =ROW()-3 -> 1 | B4: 46204 | C4: 소모성자재 | D4: 면보루 | E4: 5kg | F4: 네이버파이낸셜㈜ | G4: 1 | H4: 10909.091 | I4: 10909.091 | L4: 입력항목
A5: =ROW()-3 -> 2 | B5: 46216 | C5: 소모성자재 | D5: 알곤퍼지 파이렉스 노즐 키트 | E5: 14호 | F5: 네이버파이낸셜㈜ | G5: 1 | H5: 30000 | I5: 30000 | L5: 구매일
A6: =ROW()-3 -> 3 | B6: 46206 | C6: 소모성자재 | D6: 스텝드릴 | E6: [4-22,SJ-SD22A,Co8%,육각생크 [블랑코]] | F6: 미래공구 | G6: 2 | H6: 11200 | I6: 22400 | L6: 구분
A7: =ROW()-3 -> 4 | B7: 46211 | C7: 소모성자재 | D7: 튜브컷터날 | E7: [TCBC105 [슈퍼]] | F7: 미래공구 | G7: 4 | H7: 10000 | I7: 40000 | L7: 품명
A8: =ROW()-3 -> 5 | B8: 46211 | C8: 소모성자재 | D8: 마대 | E8: [수입,정80kg,80L [SW]] | F8: 미래공구 | G8: 50 | H8: 300 | I8: 15000 | L8: 규격
A9: =ROW()-3 -> 6 | B9: 46218 | C9: 소모성자재 | D9: 정전기청소포 | E9: 60매 | F9: 주식회사 아성다이소 | G9: 3 | H9: 1818.1818 | I9: 5454.5455 | L9: 거래처명
A10: =ROW()-3 -> 7 | B10: 46204 | C10: 소모성자재 | D10: AAA 건전지 | F10: 쿠팡㈜ | G10: 1 | H10: 9518.1818 | I10: 9518.1818 | L10: 발주수량
A11: =ROW()-3 -> 8 | B11: 46205 | C11: 소모성자재 | D11: 리빙박스 | E11: 100L | F11: 쿠팡㈜ | G11: 4 | H11: 14956.818 | I11: 59827.273 | L11: 단가
A12: =ROW()-3 -> 9 | B12: 46206 | C12: 소모성자재 | D12: 리빙박스 | E12: 66L | F12: 쿠팡㈜ | G12: 3 | H12: 7542.4242 | I12: 22627.273
N13: ■ 구분은 [소모성자재, 공구, 임대(공구), 안전용품, 비품] 이외 항목은 입력금지

Sheet 숙소임차료
A1: 숙소 임차료
A2: No. | B2: 납부일 | C2: 구분 | D2: 품명 | E2: 주소 | F2: 호수 | G2: 수량 | H2: 사용인원 | I2: 임차료 | J2: 비 고
I3: =SUM(I4:I13) -> 8780645.2 | L3: 입력해야하는 항목 외 수정 금지
A4: =ROW()-3 -> 1 | B4: 46234 | C4: KC대납 임대료 | D4: 숙소임대료(7월분) | E4: 함박산1길 16 | F4: 301호 | G4: 1 | I4: =800000/31*13 -> 335483.87 | J4: KC 대납 | L4: 납부일
A5: =ROW()-3 -> 2 | B5: 46234 | C5: KC대납 임대료 | D5: 숙소임대료(7월분) | E5: 함박산12길 8-10 | F5: 301호 | G5: 1 | I5: =(1700000/31)*15 -> 822580.65 | J5: KC 대납 | L5: 구분
A6: =ROW()-3 -> 3 | B6: 46234 | C6: KC대납 임대료 | D6: 숙소임대료(7월분) | E6: 고덕여염6길 108 | F6: 302호 | G6: 1 | I6: =(1700000/31)*15 -> 822580.65 | J6: KC 대납 | L6: 품명
A7: =ROW()-3 -> 4 | B7: 46234 | C7: KC대납 임대료 | D7: 숙소임대료(7월분) | E7: 고덕여염16길 32 | F7: 202호 | G7: 1 | I7: =(1700000/31)*15 -> 822580.65 | J7: KC 대납 | L7: 주소
A8: =ROW()-3 -> 5 | B8: 46234 | C8: KC대납 임대료 | D8: 숙소임대료(7월분) | E8: 고덕여염 5길 15-10 | F8: 301호 | G8: 1 | I8: =(1400000/31)*15 -> 677419.35 | J8: KC 대납 | L8: 호수
A9: =ROW()-3 -> 6 | B9: 46234 | C9: KC대납 임대료 | D9: 숙소임대료(7월분) | E9: 고덕여염 5길 15-10 | F9: 201호 | G9: 1 | I9: 1400000 | J9: KC 대납 | L9: 수량
A10: =ROW()-3 -> 7 | B10: 46234 | C10: KC대납 임대료 | D10: 숙소임대료(7월분) | E10: 고덕 갈평10길 67 | F10: 201호 | G10: 1 | I10: 1600000 | J10: KC 대납 | L10: 사용인원
A11: =ROW()-3 -> 8 | B11: 46234 | C11: KC대납 임대료 | D11: 숙소임대료(7월분) | E11: 고덕 갈평9길 43 | F11: 202호 | G11: 1 | I11: =1000000/31*1 -> 32258.065 | J11: KC 대납
A12: =ROW()-3 -> 9 | B12: 46234 | C12: KC대납 임대료 | D12: 숙소임대료(7월분) | E12: 함박산2길 32-2 | F12: 201호 | G12: 1 | I12: 1700000 | J12: KC 대납 | L12: ■ 구분은 [KC대납 임대료 및 임대료] 이외 항목은 입력금지
A13: =ROW()-3 -> 10 | B13: 46234 | C13: KC대납 임대료 | D13: 숙소임대료(7월분) | E13: 함박산4길 20 | F13: 202호 | G13: 1 | I13: =(1100000/31)*16 -> 567741.94 | J13: KC 대납

Sheet 숙소관리비
A1: 숙소 관리비
A2: No. | B2: 납부일 | C2: 구분 | D2: 품명 | E2: 주소 | F2: 호수 | G2: 수량 | H2: 사용인원 | I2: 임차료 | J2: 비 고
I3: =SUM(I4:I17) -> 2600620
A4: =ROW()-3 -> 1 | B4: 46234 | C4: 관리비 | D4: 숙소전기요금(7월) | E4: 고덕여염 5길 15-10 | F4: 201호 | G4: 1 | I4: 39540
A5: =ROW()-3 -> 2 | B5: 46234 | C5: 관리비 | D5: 숙소전기요금(7월) | E5: 고덕 갈평10길 67 | F5: 201호 | G5: 1 | I5: 123710
A6: =ROW()-3 -> 3 | B6: 46234 | C6: 관리비 | D6: 숙소전기요금(7월) | E6: 함박산2길 32-2 | F6: 201호 | G6: 1 | I6: 145630
A7: =ROW()-3 -> 4 | B7: 46234 | C7: 관리비 | D7: 숙소수도요금(7월) | E7: 함박산12길 8-10 | F7: 301호 | G7: 1 | I7: 47870
A8: =ROW()-3 -> 5 | B8: 46234 | C8: 관리비 | D8: 숙소수도요금(7월) | E8: 고덕여염6길 108 | F8: 302호 | G8: 1 | I8: 37500
A9: =ROW()-3 -> 6 | B9: 46234 | C9: 관리비 | D9: 숙소수도요금(7월) | E9: 고덕여염16길 32 | F9: 202호 | G9: 1 | I9: 18480
A10: =ROW()-3 -> 7 | B10: 46234 | C10: 관리비 | D10: 숙소수도요금(7월) | E10: 고덕여염 5길 15-10 | F10: 301호 | G10: 1 | I10: 58240
A11: =ROW()-3 -> 8 | B11: 46234 | C11: 관리비 | D11: 숙소수도요금(7월) | E11: 고덕여염 5길 15-10 | F11: 201호 | G11: 1 | I11: 46140
A12: =ROW()-3 -> 9 | B12: 46234 | C12: 관리비 | D12: 숙소수도요금(7월) | E12: 고덕 갈평10길 67 | F12: 201호 | G12: 1 | I12: 68080
A13: =ROW()-3 -> 10 | B13: 46234 | C13: 관리비 | D13: 숙소수도요금(7월) | E13: 함박산2길 32-2 | F13: 201호 | G13: 1 | I13: 40950
A14: =ROW()-3 -> 11 | B14: 46234 | C14: 관리비 | D14: 퇴실정산 | E14: 고덕갈평9길 43 | F14: 202호 | G14: 1 | I14: 571400
A15: =ROW()-3 -> 12 | B15: 46234 | C15: 관리비 | D15: 퇴실정산 | E15: 함박산1길 16 | F15: 301호 | G15: 1 | I15: 465300
A16: =ROW()-3 -> 13 | B16: 46234 | C16: 관리비 | D16: 퇴실정산 | E16: 함박산4길 20 | F16: 202호 | G16: 1 | I16: 937780

Sheet 식대비용
A1: 식대 비용
A2: No. | B2: 납부일 | C2: 구분 | D2: 품명 | E2: 거래처명 | F2: 수량 | G2: 식수인원 | H2: 단가 | I2: 합 계 | J2: 비 고
I3: =SUM(I4:I10) -> 14057636 | L3: 입력해야하는 항목 외 수정 금지
A4: =ROW()-3 -> 1 | B4: 46228 | C4: KC대납 식대 | D4: 기술인및관리자 (현장 식당) | E4: 태정위드유 주식회사 | F4: 1 | H4: 715636 | I4: =F4*H4 -> 715636 | J4: KC 대납 | L4: 입력항목
A5: =ROW()-3 -> 2 | B5: 46228 | C5: KC대납 식대 | D5: 기술인및관리자 (현장 식당) | E5: 다모아한식뷔페 | F5: 38 | H5: 7000 | I5: =F5*H5 -> 266000 | J5: KC 대납 | L5: 납부일
A6: =ROW()-3 -> 3 | B6: 46228 | C6: KC대납 식대 | D6: 기술인및관리자 (현장 식당) | E6: 영미손김밥 | F6: 1 | H6: 1375000 | I6: =F6*H6 -> 1375000 | J6: KC 대납 | L6: 구분
A7: =ROW()-3 -> 4 | B7: 46228 | C7: KC대납 식대 | D7: 기술인및관리자 (현장 식당) | E7: 옛날장터 | F7: 1350 | H7: 7000 | I7: =F7*H7 -> 9450000 | J7: KC 대납 | L7: 품명
A8: =ROW()-3 -> 5 | B8: 46228 | C8: KC대납 식대 | D8: 기술인및관리자 (현장 식당) | E8: 은주네한식뷔페 | F8: 70 | H8: 7000 | I8: =F8*H8 -> 490000 | J8: KC 대납 | L8: 거래처명
A9: =ROW()-3 -> 6 | B9: 46228 | C9: KC대납 식대 | D9: 기술인및관리자 (현장 식당) | E9: 삼성김밥 | F9: 1 | H9: 1612727 | I9: =F9*H9 -> 1612727 | J9: KC 대납 | L9: 수량
A10: =ROW()-3 -> 7 | B10: 46228 | C10: KC대납 식대 | D10: 기술인및관리자 (현장 식당) | E10: 한솥 | F10: 1 | H10: 148273 | I10: =F10*H10 -> 148273 | J10: KC 대납 | L10: 식수인원
I11: =F11*H11 -> 0 | L11: 단가
L13: ■ 구분은 [KC대납 식대 및 식대] 이외 항목은 입력금지

Sheet 기타비용
A1: 기타 비용
A2: No. | B2: 구매일 | C2: 구분 | D2: 품명 | E2: 거래처명 | F2: 수량 | G2: 단가 | H2: 합계 | I2: 비고
H3: =SUM(H4:H19) -> 1166718.2 | K3: 입력해야하는 항목 외 수정 금지
A4: =ROW()-3 -> 1 | B4: 46204 | C4: 법인카드 | D4: 85어5471 포터2 | E4: (주)소모 칠곡주유소 | F4: 1 | G4: =70000/1.1 -> 63636.364 | H4: =F4*G4 -> 63636.364 | K4: 입력항목
A5: =ROW()-3 -> 2 | B5: 46206 | C5: 법인카드 | D5: 85어5471 포터2 | E5: (주)소모 칠곡주유소 | F5: 1 | G5: =70000/1.1 -> 63636.364 | H5: =F5*G5 -> 63636.364 | K5: 구매일
A6: =ROW()-3 -> 3 | B6: 46209 | C6: 법인카드 | D6: 85어5471 포터2 | E6: (주)소모 칠곡주유소 | F6: 1 | G6: =70000/1.1 -> 63636.364 | H6: =F6*G6 -> 63636.364 | K6: 구분
A7: =ROW()-3 -> 4 | B7: 46211 | C7: 법인카드 | D7: 85어5471 포터2 | E7: (주)소모 칠곡주유소 | F7: 1 | G7: =70000/1.1 -> 63636.364 | H7: =F7*G7 -> 63636.364 | K7: 품명
A8: =ROW()-3 -> 5 | B8: 46213 | C8: 법인카드 | D8: 85어5471 포터2 | E8: (주)소모 칠곡주유소 | F8: 1 | G8: =70000/1.1 -> 63636.364 | H8: =F8*G8 -> 63636.364 | K8: 거래처명
A9: =ROW()-3 -> 6 | B9: 46216 | C9: 법인카드 | D9: 85어5471 포터2 | E9: (주)소모 칠곡주유소 | F9: 1 | G9: =70000/1.1 -> 63636.364 | H9: =F9*G9 -> 63636.364 | K9: 수량
A10: =ROW()-3 -> 7 | B10: 46218 | C10: 법인카드 | D10: 85어5471 포터2 | E10: (주)소모 칠곡주유소 | F10: 1 | G10: =70000/1.1 -> 63636.364 | H10: =F10*G10 -> 63636.364 | K10: 단가
A11: =ROW()-3 -> 8 | B11: 46223 | C11: 법인카드 | D11: 85어5471 포터2 | E11: (주)소모 칠곡주유소 | F11: 1 | G11: =70000/1.1 -> 63636.364 | H11: =F11*G11 -> 63636.364
A12: =ROW()-3 -> 9 | B12: 46226 | C12: 법인카드 | D12: 85어5471 포터2 | E12: (주)소모 칠곡주유소 | F12: 1 | G12: =70000/1.1 -> 63636.364 | H12: =F12*G12 -> 63636.364 | K12: ■ 구분은 [사무용품, 소모품비, 법인카드] 이외 항목은 입력금지
A13: =ROW()-3 -> 10 | B13: 46230 | C13: 법인카드 | D13: 85어5471 포터2 | E13: 남사농업협동조합 | F13: 1 | G13: =70000/1.1 -> 63636.364 | H13: =F13*G13 -> 63636.364
A14: =ROW()-3 -> 11 | B14: 46233 | C14: 법인카드 | D14: 85어5471 포터2 | E14: (주)소모 칠곡주유소 | F14: 1 | G14: =70000/1.1 -> 63636.364 | H14: =F14*G14 -> 63636.364
A15: =ROW()-3 -> 12 | B15: 46217 | C15: 법인카드 | D15: 85어5471 타이어 | E15: 주식회사 그린타이어 | F15: 6 | G15: 72727.273 | H15: 436363.64
A16: =ROW()-3 -> 13 | B16: 46226 | C16: 사무용품 | D16: 마우스 | E16: 쿠팡㈜ | F16: 1 | G16: 21263.636 | H16: 21263.636
A17: =ROW()-3 -> 14 | B17: 46230 | C17: 소모품비 | D17: 보드마카 | E17: 주식회사 아성다이소 | F17: 1 | G17: 9090.9091 | H17: 9090.9091

Sheet Sheet1
B3: 사 업 부 | D3: Frontier 사업부 GBC 센터 GNP 1본부장 | E3: Frontier 사업부 GBC 센터장 | F3: BOC 센터장 | G3: Frontier 사업부장

Sheet 서명란
B2: 현 장 확 인 | C2: 소 장 | E2: (서명)
C3: 공 사 | E3: (서명)
C4: 공 무 | E4: (서명)
G6: 사 업 부 | H6: Frontier 사업부 GNP 본부장 | I6: BOC 센터장 | J6: Frontier 사업부장
L8: 본 사 | M8: 담 당 | N8: 검 토 | O8: 검 토
Q11: 구 분 | R11: 확 인
Q12: 품 질 | R12: O O O (인)
Q13: 공 무 | R13: O O O (인)

Sheet DIA-INCH
B3: SIZE
B4: A(mm) | C4: Inch
B5: 8A | C5: 0.25
B6: 15A | C6: 0.5
B7: 20A | C7: 0.75
B8: 25A | C8: 1
B9: 32A | C9: 1.25
B10: 40A | C10: 1.5
B11: 50A | C11: 2
B12: 65A | C12: 2.5
B13: 80A | C13: 3
B14: 100A | C14: 4
B15: 110A | C15: 4
B16: 125A | C16: 5
... B27: 550A | C27: 22
