Workbook
Name _: #REF!
Name _: #REF!
Name _??_??_?C?g??: #REF!
Name _??_??_?C?g??: #REF!
Name ___DAT5: #REF!
Name ___QQ123: #REF!
Name __DAT11: #REF!
Name __DAT21: #REF!
Name __DAT22: #REF!
Name __DAT23: #REF!
Name __DAT24: #REF!
Name __DAT25: #REF!
Name __DAT26: #REF!
Name __DAT27: #REF!
Name __DAT28: #REF!
Name __P3: #REF!
Name __P4: #REF!
Name __P5: #REF!
Name __P6: #REF!
Name __PP1: #REF!
Name _0101__장비_설치공사: #REF!
Name _0201__소화_장비설치공사: #REF!
Name _1: #REF!
Name _1: #REF!
Name _1._PANEL_BD.__LP___1: #REF!
Name _1._옥외배관및장비설치공사: #REF!
Name _1_3_0Crite: #REF!
Name _10A_61: #N/A
Name _10A_62: #N/A
Name _10A_63: #N/A
Name _10A_64: #N/A
Name _10A_65: #N/A
Name _10A_66: #N/A
Name _10A_67: #N/A
Name _10A_68: #N/A
Name _10A_69: #N/A
Name _10A_70: #N/A
Name _10A_71: #N/A
Name _10A_72: #N/A
Name _10A_73: #N/A
Name _10A_74: #N/A
Name _10A_75: #N/A
Name _10A_76: #N/A
Name _10A_77: #N/A
Name _10A_78: #N/A
Name _10A_79: #N/A
Name _10A_80: #N/A
Name _10A_81: #N/A
Name _10A_82: #N/A
Name _10A_83: #N/A
Name _10A_84: #N/A
Name _10A_85: #N/A
Name _10A_86: #N/A
Name _10A_87: #N/A
Name _10A_88: #N/A
Name _10A_89: #N/A
Name _10A_90: #N/A
Name _10B_61: #N/A
Name _10B_62: #N/A
Name _10B_63: #N/A

Sheet 용역청구서 표지
B4: 용 역 청 구 서
B7: P4 Ph4 GAS 1공구 마감공사
C8: S25-004
C14: 2026년 06월
C15: ㈜태성하이텍

Sheet 용역 청구서(갑지)
A1: 용 역 청 구 서
A3: 1 | B3: 공 사 명 | C3: : | D3: ='용역청구서 표지'!$B$7 -> P4 Ph4 GAS 1공구 마감공사 | E3: ='용역청구서 표지'!$C$8 -> S25-004
A4: 2 | B4: 공 종 | C4: : | D4: 외주용역(M/M부분)
A5: 3 | B5: 계 약 금 액 | C5: : | D5: =ROUNDUP(E5,0) -> 1220000000 | E5: =집계장!I22 -> 1220000000 | F5: (VAT 별도)
A6: 4 | B6: 누 계 기 성 금 액 | C6: : | D6: =ROUNDUP(E6,0) -> 1220000000 | E6: =E7+E13 -> 1220000000 | F6: (VAT 별도)
A7: 5 | B7: 전 회 기 성 금 액 | C7: : | D7: =ROUNDUP(E7,0) -> 820000000 | E7: =집계장!G22 -> 820000000 | F7: (VAT 별도)
A8: 6 | B8: 금 회 기 성 금 액 | C8: : | D8: =ROUNDUP(E8,0) -> 400000000 | E8: =집계장!F22 -> 400000000 | F8: (VAT 별도)
A9: 7 | B9: 선 금 액 | C9: : | D9: =ROUNDUP(E9,0) -> 0 | E9: =집계장!K20 -> 0 | F9: (VAT 별도)
A10: 8 | B10: 선 금 전 회 공 제 | C10: : | D10: =ROUNDUP(E10,0) -> 0 | E10: =집계장!G20 -> 0 | F10: (VAT 별도)
A11: 9 | B11: 선 금 금 회 공 제 | C11: : | D11: =ROUNDUP(E11,0) -> 0 | E11: =집계장!F20 -> 0 | F11: (VAT 별도)
A12: 10 | B12: 선 금 잔 여 금 액 | C12: : | D12: =ROUNDUP(E12,0) -> 0 | E12: =집계장!L20 -> 0 | F12: (VAT 별도)
A13: 11 | B13: 금 회 청 구 금 액 | C13: : | D13: =ROUNDUP(E13,0) -> 400000000 | E13: =집계장!F22 -> 400000000 | F13: (VAT 별도)
A14: 12 | B14: 잔 여 기 성 금 액 | C14: : | D14: =ROUNDUP(E14,0) -> 0 | E14: =집계장!I16 -> 0 | F14: (VAT 별도)
A15: 13 | B15: 공 정 율 | C15: : | D15: 1
A16: 14 | B16: 청 구 공 사 기 간 | C16: : | D16: 2026. 06. 01 ~ 2026. 06. 30
B18: 위 공사의 하도급에 있어서 공사설계도서, 시방서,품질관리 기준 및 약정대로 시공 되었음을 확인하오며. 만약 귀사의 현장담당의 검사에
B19: 관하여 하자가 발견된 때에는 즉시 실액배상 또는 재 시공할것을 서약하고 이에 기성 청구서를 제출합니다.
B20: 상기건과 관련하여 본 청구 이전까지의 모든 대금은 수령하였음을 확약합니다.
F21: 작 성 일 : 2026 년 06 월 30 일
F23: 상 호 : | G23: ㈜ 태성하이텍
B24: ※첨 부 : 기성내역서 1부. | F24: 주 소 : | G24: 경기도 용인시 처인구 남사면 봉명리 73-1
F25: 대표이사 : | G25: 유 태 진 | I25: (인)
D26: ㈜케이씨이앤씨 귀하

Sheet 용역 내역서(을지)
A1: 용 역 내 역 서
A2: P4 Ph4 GAS 1공구 마감공사 | G2: 단위 : 원
A3: 품 명 | B3: 규 격 | C3: 단위 | D3: 단 가 | E3: 금 회 청 구
E4: 수 량 | F4: 금 액 | G4: 비 고
A5: 고급기술인 | B5: S+ | C5: M/M | D5: 1400000 | E5: 1 | F5: =D5*E5 -> 1400000
A6: 고급기술인 | B6: S | C6: M/M | D6: 1200000 | F6: =D6*E6 -> 0
A7: 중급기술인 | B7: A+ | C7: M/M | D7: 1000000 | F7: =D7*E7 -> 0
A8: 중급기술인 | B8: A | C8: M/M | D8: 900000 | F8: =D8*E8 -> 0
A9: 중급기술인 | B9: B+ | C9: M/M | D9: 800000 | F9: =D9*E9 -> 0
A10: 중급기술인 | B10: B | C10: M/M | D10: 700000 | F10: =D10*E10 -> 0
A11: 초급 기술인 | B11: C | C11: M/M | D11: 600000 | F11: =D11*E11 -> 0
A13: 인센티브 | E13: 0.01 | F13: =SUM(F5:F11)*E13 -> 14000
A15: 총 계 | E15: =SUM(E5:E11) -> 1 | F15: =SUM(F5:F13) -> 1414000

Sheet 내역서(을지)
A1: 용 역 내 역 서
A2: P4 Ph4 GAS 1공구 마감공사 | G2: 단위 : 원
A3: 품 명 | B3: 규 격 | C3: 단위 | D3: 단 가 | E3: 금 회 청 구 | G3: 비 고
E4: 수 량 | F4: 금 액
A5: 고급기술인 | B5: S+ | C5: M/M | D5: 1400000 | E5: 80 | F5: =D5*E5 -> 112000000
A6: 고급기술인 | B6: S | C6: M/M | D6: 1200000 | E6: 70 | F6: =D6*E6 -> 84000000
A7: 중급기술인 | B7: A+ | C7: M/M | D7: 1000000 | E7: 60 | F7: =D7*E7 -> 60000000
A8: 중급기술인 | B8: A | C8: M/M | D8: 900000 | E8: 60 | F8: =D8*E8 -> 54000000
A9: 중급기술인 | B9: B+ | C9: M/M | D9: 800000 | E9: 60 | F9: =D9*E9 -> 48000000
A10: 중급기술인 | B10: B | C10: M/M | D10: 700000 | E10: 60 | F10: =D10*E10 -> 42000000
A11: 초급기술인 | B11: C | C11: M/M | D11: 600000 | F11: =D11*E11 -> 0
A13: 인센티브 | E13: 0 | F13: =SUM(F5:F11)*E13 -> 0
A16: 총 계 | E16: =SUM(E5:E15) -> 390 | F16: =SUM(F5:F15) -> 400000000

Sheet 집계장
A1: ='용역청구서 표지'!$B$7 -> P4 Ph4 GAS 1공구 마감공사
L2: ='용역청구서 표지'!$C$15 -> ㈜태성하이텍
A3: 구분 | B3: 내역 | C3: 단위 | D3: 수량 | E3: 단가 | F3: 합계 | G3: 전회기성 | H3: 금회기성 | I3: 누계기성 | J3: 비 고
A4: 1. 물량 | B4: WELDING POINT | C4: D/I | D4: =SUM('물량 내역서'!$J$5:$J$27) -> 666.5 | E4: =F4/D4 -> 437000 | F4: =SUM('물량 내역서'!$K$5:$K$27) -> 291260500 | G4: 5140649500 | H4: =F4 -> 291260500 | I4: =G4+H4 -> 5431910000
B5: VALVE 설치비 | C5: EA | D5: =SUM('물량 내역서'!$J$28:$J$50) -> 113 | E5: =F5/D5 -> 204037.61 | F5: =SUM('물량 내역서'!$K$28:$K$50) -> 23056250 | G5: 44231250 | H5: =F5 -> 23056250 | I5: =G5+H5 -> 67287500
B6: 인원 실투입 | C6: M/D | E6: =F6/D6 -> #DIV/0! | F6: ='근로내역 (06월)'!AP87 -> 0 | G6: 0 | H6: =F6 -> 0 | I6: =G6+H6 -> 0
A7: 2. 기타비용 | C7: 式 | D7: =384.5+62.312 -> 446.812 | E7: 187981 | F7: =ROUND(D7*E7,0) -> 83992167 | G7: 685778223 | H7: =F7 -> 83992167 | I7: =G7+H7 -> 769770390
A8: 소 계 | B8: 물량 | F8: =SUM(F4:F7) -> 398308917 | G8: =SUM(G4:G7) -> 5870658973 | H8: =F8 -> 398308917 | I8: =G8+H8 -> 6268967890
A9: 3. 노무비 | B9: 직접노무비 | C9: 式 | D9: ='근로내역 (06월)'!AN88 -> 2282.25 | E9: =F9/D9 -> 184210.21 | F9: ='근로내역 (06월)'!AP88 -> 420413750 | G9: 3093818750 | H9: =F9 -> 420413750 | I9: =G9+H9 -> 3514232500
A10: 4. 숙소 및 식대 | B10: 임대료+관리비 | C10: 式 | D10: =SUM(숙소임차료!H4:H8)+SUM(숙소관리비!H4:H8) -> 0 | E10: =F10/D10 -> #DIV/0! | F10: =숙소임차료!I3+숙소관리비!I3 -> 13174507 | G10: 1.2924355e+08 | H10: =F10 -> 13174507 | I10: =G10+H10 -> 1.4241806e+08 | N10: =+H10+H11 -> 45429962
B11: 식대 | C11: 式 | D11: =SUM(식대비용!G4:G9) -> 0 | E11: =F11/D11 -> #DIV/0! | F11: =식대비용!I3 -> 32255455 | G11: 213489909 | H11: =F11 -> 32255455 | I11: =G11+H11 -> 245745364
A12: 5. 기타 공제 내역 | C12: 式 | E12: 0 | F12: =D12*E12 -> 0 | G12: 0 | H12: =F12 -> 0 | I12: =G12+H12 -> 0
A13: 소 계 | B13: 공제 | F13: =SUM(F9:F12) -> 4.6584371e+08 | G13: =SUM(G9:G12) -> 3.4365522e+09 | H13: =F13 -> 4.6584371e+08 | I13: =G13+H13 -> 3.9023959e+09
A14: 합 계 | B14: 기성 (물량-공제) | F14: =F8-F13 -> -67534795 | G14: =G8-G13 -> 2.4341068e+09 | H14: =F14 -> -67534795 | I14: =G14+H14 -> 2.366572e+09
A15: 6. 유보금 | B15: 기성금*XX% | C15: 式 | F15: -467572449 | G15: 1613972449 | H15: =F15 -> -467572449 | I15: =G15+H15 -> 1146400000
A16: 7. 유보금 차액 | B16: 전회 누계유보금+적자 기성액 | C16: 式 | H16: =F16 -> 0 | I16: =G16+H16 -> 0
A17: 8. NEGO | B17: NEGO | C17: 式 | H17: =F17 -> 0 | I17: =G17+H17 -> 0
A18: 총 계 | B18: 최종기성 | F18: =F14-F15-F16-F17 -> 4.0003765e+08 | G18: =G14-G15-G16-G17 -> 8.2013431e+08 | H18: =F18 -> 4.0003765e+08 | I18: =G18+H18 -> 1.220172e+09
A19: 선급금 | B19: 선수공제 | C19: 式 | G19: 0 | H19: =F19 -> 0 | I19: =G19+H19 -> 0 | K19: 지급 선급금 | L19: 선급금 차액
B20: 단수정리 | C20: 式 | F20: =ROUNDDOWN(F19,-5) -> 0 | H20: =F20 -> 0 | I20: =G20+H20 -> 0 | J20: 만 단위 이하 절사 | K20: 0 | L20: =K20-I20 -> 0
A21: 공제 후 실 지급액 | F21: =F18-F20 -> 4.0003765e+08 | G21: =G18-G19 -> 8.2013431e+08 | H21: =F21 -> 4.0003765e+08 | I21: =G21+H21 -> 1.220172e+09
A22: 세금계산서 기준 | F22: =ROUNDDOWN(F21,-5) -> 400000000 | G22: 820000000 | H22: =F22 -> 400000000 | I22: =G22+H22 -> 1220000000 | J22: 만 단위 이하 절사
A23: TERMS AND CONDITIONS | D23: NOTE
A24: 1. 납 기 : KCEnC 지정 납기로 별도 협의 하에 결정하는 것으로 함.
A25: 2. 지불조건 : KCEnC 지불 조건에 따름.
A26: 3. 유효기간 : 기성 제출일로 부터 30일 이내

Sheet 물량 내역서
A1: 2026년 (06)월 물량 내역서
A2: ='용역청구서 표지'!$B$7 -> P4 Ph4 GAS 1공구 마감공사 | M2: 단위 : 원
A3: 품 명 | B3: 규 격 | C3: 단위 | D3: W/P 수량 | E3: 단 가 | F3: 계 약 내 역 | H3: 전 회 누 계 물 량 | J3: 금 회 물 량 | L3: 누 계 물 량
F4: D/I 수량 | G4: 금액 | H4: D/I 수량 | I4: 금액 | J4: D/I 수량 | K4: 금액 | L4: D/I 수량 | M4: 금액
A5: WEDING POINT | B5: 8A | C5: POINT | D5: 0 | E5: 437000 | F5: =L5 -> 0 | G5: =M5 -> 0 | H5: 0 | I5: 0 | J5: =$D5*'DIA-INCH'!$C5 -> 0 | K5: =$E5*$J5 -> 0 | L5: =H5+J5 -> 0 | M5: =I5+K5 -> 0
A6: WEDING POINT | B6: 15A | C6: POINT | D6: 0 | E6: 437000 | F6: =L6 -> 0 | G6: =M6 -> 0 | H6: 0 | I6: 0 | J6: =$D6*'DIA-INCH'!$C6 -> 0 | K6: =$E6*$J6 -> 0 | L6: =H6+J6 -> 0 | M6: =I6+K6 -> 0
A7: WEDING POINT | B7: 20A | C7: POINT | D7: 0 | E7: 437000 | F7: =L7 -> 0 | G7: =M7 -> 0 | H7: 0 | I7: 0 | J7: =$D7*'DIA-INCH'!$C7 -> 0 | K7: =$E7*$J7 -> 0 | L7: =H7+J7 -> 0 | M7: =I7+K7 -> 0
A8: WEDING POINT | B8: 25A | C8: POINT | D8: 152 | E8: 437000 | F8: =L8 -> 1056 | G8: =M8 -> 461472000 | H8: 904 | I8: 395048000 | J8: =$D8*'DIA-INCH'!$C8 -> 152 | K8: =$E8*$J8 -> 66424000 | L8: =H8+J8 -> 1056 | M8: =I8+K8 -> 461472000
A9: WEDING POINT | B9: 32A | C9: POINT | D9: 0 | E9: 437000 | F9: =L9 -> 0 | G9: =M9 -> 0 | H9: 0 | I9: 0 | J9: =$D9*'DIA-INCH'!$C9 -> 0 | K9: =$E9*$J9 -> 0 | L9: =H9+J9 -> 0 | M9: =I9+K9 -> 0
A10: WEDING POINT | B10: 40A | C10: POINT | D10: 56 | E10: 437000 | F10: =L10 -> 469.5 | G10: =M10 -> 205171500 | H10: 385.5 | I10: 168463500 | J10: =$D10*'DIA-INCH'!$C10 -> 84 | K10: =$E10*$J10 -> 36708000 | L10: =H10+J10 -> 469.5 | M10: =I10+K10 -> 205171500
A11: WEDING POINT | B11: 50A | C11: POINT | D11: 79 | E11: 437000 | F11: =L11 -> 1058 | G11: =M11 -> 462346000 | H11: 900 | I11: 393300000 | J11: =$D11*'DIA-INCH'!$C11 -> 158 | K11: =$E11*$J11 -> 69046000 | L11: =H11+J11 -> 1058 | M11: =I11+K11 -> 462346000
A12: WEDING POINT | B12: 65A | C12: POINT | D12: 27 | E12: 437000 | F12: =L12 -> 757.5 | G12: =M12 -> 331027500 | H12: 690 | I12: 301530000 | J12: =$D12*'DIA-INCH'!$C12 -> 67.5 | K12: =$E12*$J12 -> 29497500 | L12: =H12+J12 -> 757.5 | M12: =I12+K12 -> 331027500
A13: WEDING POINT | B13: 80A | C13: POINT | D13: 5 | E13: 437000 | F13: =L13 -> 639 | G13: =M13 -> 279243000 | H13: 624 | I13: 272688000 | J13: =$D13*'DIA-INCH'!$C13 -> 15 | K13: =$E13*$J13 -> 6555000 | L13: =H13+J13 -> 639 | M13: =I13+K13 -> 279243000
A14: WEDING POINT | B14: 100A | C14: POINT | D14: 0 | E14: 437000 | F14: =L14 -> 1292 | G14: =M14 -> 564604000 | H14: 1292 | I14: 564604000 | J14: =$D14*'DIA-INCH'!$C14 -> 0 | K14: =$E14*$J14 -> 0 | L14: =H14+J14 -> 1292 | M14: =I14+K14 -> 564604000
A15: WEDING POINT | B15: 110A | C15: POINT | D15: 0 | E15: 437000 | F15: =L15 -> 0 | G15: =M15 -> 0 | H15: 0 | I15: 0 | J15: =$D15*'DIA-INCH'!$C15 -> 0 | K15: =$E15*$J15 -> 0 | L15: =H15+J15 -> 0 | M15: =I15+K15 -> 0
A16: WEDING POINT | B16: 125A | C16: POINT | D16: 38 | E16: 437000 | F16: =L16 -> 2930 | G16: =M16 -> 1280410000 | H16: 2740 | I16: 1197380000 | J16: =$D16*'DIA-INCH'!$C16 -> 190 | K16: =$E16*$J16 -> 83030000 | L16: =H16+J16 -> 2930 | M16: =I16+K16 -> 1280410000
... A27: WEDING POINT | B27: 550A | C27: POINT | D27: 0 | E27: 437000 | F27: =L27 -> 0 | G27: =M27 -> 0 | H27: 0 | I27: 0 | J27: =$D27*'DIA-INCH'!$C27 -> 0 | K27: =$E27*$J27 -> 0 | L27: =H27+J27 -> 0 | M27: =I27+K27 -> 0
A28: VALVE 설치비 | B28: 8A | C28: EA | D28: 0 | E28: =$E$31*'DIA-INCH'!$C5 -> 21875 | F28: =L28 -> 0 | G28: =M28 -> 0 | H28: 0 | I28: 0 | J28: =D28 -> 0 | K28: =$J28*$E28 -> 0 | L28: =H28+J28 -> 0 | M28: =I28+K28 -> 0
A29: VALVE 설치비 | B29: 15A | C29: EA | D29: 0 | E29: =$E$31*'DIA-INCH'!$C6 -> 43750 | F29: =L29 -> 0 | G29: =M29 -> 0 | H29: 0 | I29: 0 | J29: =D29 -> 0 | K29: =$J29*$E29 -> 0 | L29: =H29+J29 -> 0 | M29: =I29+K29 -> 0
A30: VALVE 설치비 | B30: 20A | C30: EA | D30: 0 | E30: =$E$31*'DIA-INCH'!$C7 -> 65625 | F30: =L30 -> 0 | G30: =M30 -> 0 | H30: 0 | I30: 0 | J30: =D30 -> 0 | K30: =$J30*$E30 -> 0 | L30: =H30+J30 -> 0 | M30: =I30+K30 -> 0
A31: VALVE 설치비 | B31: 25A | C31: EA | D31: 35 | E31: 87500 | F31: =L31 -> 165 | G31: =M31 -> 14437500 | H31: 130 | I31: 11375000 | J31: =D31 -> 35 | K31: =$J31*$E31 -> 3062500 | L31: =H31+J31 -> 165 | M31: =I31+K31 -> 14437500 | N31: 1 | O31: =+N31*J31 -> 35
A32: VALVE 설치비 | B32: 32A | C32: EA | D32: 6 | E32: =$E$31*'DIA-INCH'!$C9 -> 109375 | F32: =L32 -> 90 | G32: =M32 -> 9843750 | H32: 84 | I32: 9187500 | J32: =D32 -> 6 | K32: =$J32*$E32 -> 656250 | L32: =H32+J32 -> 90 | M32: =I32+K32 -> 9843750 | N32: 1.25 | O32: =+N32*J32 -> 7.5 | Q32: =32/25 -> 1.28
A33: VALVE 설치비 | B33: 40A | C33: EA | D33: 11 | E33: =$E$31*'DIA-INCH'!$C10 -> 131250 | F33: =L33 -> 33 | G33: =M33 -> 4331250 | H33: 22 | I33: 2887500 | J33: =D33 -> 11 | K33: =$J33*$E33 -> 1443750 | L33: =H33+J33 -> 33 | M33: =I33+K33 -> 4331250 | N33: 1.5 | O33: =+N33*J33 -> 16.5
A34: VALVE 설치비 | B34: 50A | C34: EA | D34: 16 | E34: =$E$31*'DIA-INCH'!$C11 -> 175000 | F34: =L34 -> 29 | G34: =M34 -> 5075000 | H34: 13 | I34: 2275000 | J34: =D34 -> 16 | K34: =$J34*$E34 -> 2800000 | L34: =H34+J34 -> 29 | M34: =I34+K34 -> 5075000 | N34: 2 | O34: =+N34*J34 -> 32
A35: VALVE 설치비 | B35: 65A | C35: EA | D35: 1 | E35: =$E$31*'DIA-INCH'!$C12 -> 218750 | F35: =L35 -> 10 | G35: =M35 -> 2187500 | H35: 9 | I35: 1968750 | J35: =D35 -> 1 | K35: =$J35*$E35 -> 218750 | L35: =H35+J35 -> 10 | M35: =I35+K35 -> 2187500 | N35: 2.5 | O35: =+N35*J35 -> 2.5
A36: VALVE 설치비 | B36: 80A | C36: EA | D36: 27 | E36: =$E$31*'DIA-INCH'!$C13 -> 262500 | F36: =L36 -> 34 | G36: =M36 -> 8925000 | H36: 7 | I36: 1837500 | J36: =D36 -> 27 | K36: =$J36*$E36 -> 7087500 | L36: =H36+J36 -> 34 | M36: =I36+K36 -> 8925000 | N36: 3 | O36: =+N36*J36 -> 81
A37: VALVE 설치비 | B37: 100A | C37: EA | D37: 1 | E37: =$E$31*'DIA-INCH'!$C14 -> 350000 | F37: =L37 -> 2 | G37: =M37 -> 700000 | H37: 1 | I37: 350000 | J37: =D37 -> 1 | K37: =$J37*$E37 -> 350000 | L37: =H37+J37 -> 2 | M37: =I37+K37 -> 700000 | N37: 4 | O37: =+N37*J37 -> 4
A38: VALVE 설치비 | B38: 110A | C38: EA | D38: 0 | E38: =$E$31*'DIA-INCH'!$C15 -> 350000 | F38: =L38 -> 0 | G38: =M38 -> 0 | H38: 0 | I38: 0 | J38: =D38 -> 0 | K38: =$J38*$E38 -> 0 | L38: =H38+J38 -> 0 | M38: =I38+K38 -> 0 | O38: =+N38*J38 -> 0
A39: VALVE 설치비 | B39: 125A | C39: EA | D39: 15 | E39: =$E$31*'DIA-INCH'!$C16 -> 437500 | F39: =L39 -> 43 | G39: =M39 -> 18812500 | H39: 28 | I39: 12250000 | J39: =D39 -> 15 | K39: =$J39*$E39 -> 6562500 | L39: =H39+J39 -> 43 | M39: =I39+K39 -> 18812500 | N39: 5 | O39: =+N39*J39 -> 75
A40: VALVE 설치비 | B40: 150A | C40: EA | D40: 0 | E40: =$E$31*'DIA-INCH'!$C17 -> 525000 | F40: =L40 -> 1 | G40: =M40 -> 525000 | H40: 1 | I40: 525000 | J40: =D40 -> 0 | K40: =$J40*$E40 -> 0 | L40: =H40+J40 -> 1 | M40: =I40+K40 -> 525000 | N40: 6 | O40: =+N40*J40 -> 0
A41: VALVE 설치비 | B41: 175A | C41: EA | D41: 0 | E41: =$E$31*'DIA-INCH'!$C18 -> 612500 | F41: =L41 -> 0 | G41: =M41 -> 0 | H41: 0 | I41: 0 | J41: =D41 -> 0 | K41: =$J41*$E41 -> 0 | L41: =H41+J41 -> 0 | M41: =I41+K41 -> 0 | O41: =+N41*J41 -> 0
A42: VALVE 설치비 | B42: 200A | C42: EA | D42: 0 | E42: =$E$31*'DIA-INCH'!$C19 -> 700000 | F42: =L42 -> 1 | G42: =M42 -> 700000 | H42: 1 | I42: 700000 | J42: =D42 -> 0 | K42: =$J42*$E42 -> 0 | L42: =H42+J42 -> 1 | M42: =I42+K42 -> 700000 | N42: 8 | O42: =+N42*J42 -> 0
A43: VALVE 설치비 | B43: 225A | C43: EA | D43: 0 | E43: =$E$31*'DIA-INCH'!$C20 -> 787500 | F43: =L43 -> 0 | G43: =M43 -> 0 | H43: 0 | I43: 0 | J43: =D43 -> 0 | K43: =$J43*$E43 -> 0 | L43: =H43+J43 -> 0 | M43: =I43+K43 -> 0 | O43: =+N43*J43 -> 0
A44: VALVE 설치비 | B44: 250A | C44: EA | D44: 1 | E44: =$E$31*'DIA-INCH'!$C21 -> 875000 | F44: =L44 -> 2 | G44: =M44 -> 1750000 | H44: 1 | I44: 875000 | J44: =D44 -> 1 | K44: =$J44*$E44 -> 875000 | L44: =H44+J44 -> 2 | M44: =I44+K44 -> 1750000 | N44: 10 | O44: =+N44*J44 -> 10
A45: VALVE 설치비 | B45: 300A | C45: EA | D45: 0 | E45: =$E$31*'DIA-INCH'!$C22 -> 1050000 | F45: =L45 -> 0 | G45: =M45 -> 0 | H45: 0 | I45: 0 | J45: =D45 -> 0 | K45: =$J45*$E45 -> 0 | L45: =H45+J45 -> 0 | M45: =I45+K45 -> 0
A46: VALVE 설치비 | B46: 350A | C46: EA | D46: 0 | E46: =$E$31*'DIA-INCH'!$C23 -> 1225000 | F46: =L46 -> 0 | G46: =M46 -> 0 | H46: 0 | I46: 0 | J46: =D46 -> 0 | K46: =$J46*$E46 -> 0 | L46: =H46+J46 -> 0 | M46: =I46+K46 -> 0
A47: VALVE 설치비 | B47: 400A | C47: EA | D47: 0 | E47: =$E$31*'DIA-INCH'!$C24 -> 1400000 | F47: =L47 -> 0 | G47: =M47 -> 0 | H47: 0 | I47: 0 | J47: =D47 -> 0 | K47: =$J47*$E47 -> 0 | L47: =H47+J47 -> 0 | M47: =I47+K47 -> 0
A48: VALVE 설치비 | B48: 450A | C48: EA | D48: 0 | E48: =$E$31*'DIA-INCH'!$C25 -> 1575000 | F48: =L48 -> 0 | G48: =M48 -> 0 | H48: 0 | I48: 0 | J48: =D48 -> 0 | K48: =$J48*$E48 -> 0 | L48: =H48+J48 -> 0 | M48: =I48+K48 -> 0
A49: VALVE 설치비 | B49: 500A | C49: EA | D49: 0 | E49: =$E$31*'DIA-INCH'!$C26 -> 1750000 | F49: =L49 -> 0 | G49: =M49 -> 0 | H49: 0 | I49: 0 | J49: =D49 -> 0 | K49: =$J49*$E49 -> 0 | L49: =H49+J49 -> 0 | M49: =I49+K49 -> 0
A50: VALVE 설치비 | B50: 550A | C50: EA | D50: 0 | E50: =$E$31*'DIA-INCH'!$C27 -> 1925000 | F50: =L50 -> 0 | G50: =M50 -> 0 | H50: 0 | I50: 0 | J50: =D50 -> 0 | K50: =$J50*$E50 -> 0 | L50: =H50+J50 -> 0 | M50: =I50+K50 -> 0
...

Sheet 근로내역 (06월)
A1: 2026년 ( 06 )월 일용 노무비명세서 | AH1: 현장명 | AM1: ='용역청구서 표지'!$B$7 -> P4 Ph4 GAS 1공구 마감공사
AH2: 현장소장 | AM2: 장규철
AH3: 잡코드 | AM3: ='용역청구서 표지'!$C$8 -> S25-004
A5: 번호 | B5: 성명 | C5: 주민등록번호 | D5: 직종 | E5: 연락처(H.P) | F5: 은행명 | G5: 예금주 | H5: 계좌번호 | I5: 1 | J5: 2 | K5: 3 | L5: 4 | M5: 5 | N5: 6 | O5: 7 | P5: 8 | Q5: 9 | R5: 10 | S5: 11 | T5: 12 | U5: 13 | V5: 14 | W5: 15 | X5: 16 | Y5: 17 | Z5: 18 | AA5: 19 | AB5: 20 | AC5: 21 | AD5: 22 | AE5: 23 | AF5: 24 | AG5: 25 | AH5: 26 | AI5: 27 | AJ5: 28 | AK5: 29 | AL5: 30 | AN5: 공수 | AO5: 단가 | AP5: 총액
A6: 1 | B6: 김영광 | C6: 920704-1860718 | D6: 관리보조 | E6: 010-7704-1777 | F6: 기업 | G6: 김영광 | H6: 580-022392-01-010 | I6: 2 | J6: 1.5 | K6: 1.5 | L6: 2 | M6: 2 | N6: 1.3125 | P6: 2 | Q6: 2 | R6: 2 | S6: 1.875 | T6: 2 | U6: 0.875 | W6: 1.5 | X6: 1.375 | Y6: 0.5 | Z6: 1.375 | AA6: 1.5 | AB6: 1 | AD6: 1 | AE6: 1 | AF6: 1.5 | AG6: 1.5 | AH6: 1 | AK6: 1 | AL6: 1.5 | AN6: =SUM(I6:AM6) -> 36.8125 | AO6: 200000 | AP6: =AN6*AO6 -> 7362500
A7: 2 | B7: 최은희 | C7: 850227-2454711 | D7: 보통인부 | E7: 010-2052-6656 | F7: 하나 | G7: 최은희 | H7: 472-910128-17307 | I7: 2 | J7: 2 | K7: 1.5 | L7: 2 | M7: 2 | N7: 1.5 | P7: 2 | Q7: 2 | R7: 2 | S7: 2 | T7: 2 | U7: 1 | W7: 1.5 | X7: 1.5 | Y7: 1 | Z7: 1.5 | AA7: 1.5 | AB7: 1 | AD7: 1 | AE7: 1 | AF7: 1.5 | AG7: 1.5 | AH7: 1 | AI7: 0.875 | AK7: 1 | AL7: 1.5 | AN7: =SUM(I7:AM7) -> 39.375 | AO7: 170000 | AP7: =AN7*AO7 -> 6693750
A8: 3 | B8: 홍성연 | C8: 960406-1213110 | D8: 보통인부 | E8: 010-7451-1297 | F8: 국민 | G8: 홍성연 | H8: 216502-04-453135 | I8: 2 | J8: 2 | K8: 1.5 | L8: 2 | M8: 2 | N8: 1.5 | P8: 2 | Q8: 2 | R8: 2 | S8: 2 | T8: 2 | U8: 1 | W8: 1.5 | X8: 1.5 | Y8: 1 | Z8: 1.5 | AA8: 1.5 | AB8: 1 | AD8: 1 | AE8: 1 | AF8: 1.5 | AG8: 1.5 | AH8: 1 | AK8: 1 | AL8: 1.5 | AN8: =SUM(I8:AM8) -> 38.5 | AO8: 180000 | AP8: =AN8*AO8 -> 6930000
A9: 4 | B9: 황선정 | C9: 730308-1057411 | D9: 보통인부 | E9: 010-7480-0008 | F9: 농협 | G9: 황선정 | H9: 302-0861-0223-61 | I9: 2 | J9: 2 | K9: 1.5 | L9: 2 | M9: 2 | N9: 1.5 | P9: 2 | Q9: 2 | R9: 1.5 | S9: 1.5 | T9: 1.5 | U9: 1 | W9: 1.5 | X9: 1.5 | Y9: 1 | Z9: 1.5 | AA9: 1.5 | AB9: 1 | AD9: 1 | AE9: 1 | AF9: 1.5 | AG9: 1.5 | AH9: 1 | AK9: 1 | AL9: 1.5 | AN9: =SUM(I9:AM9) -> 37 | AO9: 180000 | AP9: =AN9*AO9 -> 6660000
A10: 5 | B10: 김동민 | C10: 840606-1768018 | D10: 용접공 | E10: 010-3804-2432 | F10: 신한 | G10: 김동민 | H10: 110-408-565589 | I10: 2 | J10: 2 | K10: 1.5 | L10: 2 | M10: 2 | N10: 1.5 | P10: 2 | Q10: 2 | R10: 2 | S10: 2 | T10: 2 | U10: 1 | W10: 1.5 | X10: 1.5 | Y10: 1 | Z10: 1.5 | AA10: 1.5 | AB10: 1 | AD10: 1 | AE10: 0.5 | AF10: 1.5 | AG10: 1.5 | AH10: 1 | AK10: 1 | AL10: 1.5 | AN10: =SUM(I10:AM10) -> 38 | AO10: 240000 | AP10: =AN10*AO10 -> 9120000
A11: 6 | B11: 박주영 | C11: 730810-1457613 | D11: 배관공 | E11: 010-3356-9406 | F11: 하나 | G11: 박주영 | H11: 130-910013-37908 | I11: 2 | J11: 2 | K11: 1.5 | L11: 2 | M11: 2 | N11: 1.5 | P11: 2 | Q11: 2 | R11: 2 | S11: 2 | T11: 2 | W11: 1.5 | X11: 1.5 | Y11: 1 | Z11: 1.5 | AA11: 1.5 | AB11: 1 | AE11: 1 | AF11: 1.5 | AG11: 1.5 | AH11: 1 | AK11: 1 | AL11: 1.5 | AN11: =SUM(I11:AM11) -> 36.5 | AO11: 210000 | AP11: =AN11*AO11 -> 7665000
A12: 7 | B12: 김강현 | C12: 910414-1031829 | D12: 보통인부 | E12: 010-6733-7963 | F12: 신한 | G12: 김강현 | H12: 110-302-846665 | I12: 2 | J12: 2 | K12: 1.5 | L12: 2 | M12: 2 | N12: 1.5 | P12: 2 | Q12: 2 | R12: 2 | S12: 2 | T12: 2 | U12: 1 | W12: 1.5 | X12: 1.5 | Y12: 1 | Z12: 1.5 | AA12: 1.5 | AB12: 1 | AD12: 1 | AE12: 1 | AF12: 1.5 | AG12: 1.5 | AH12: 1 | AK12: 1 | AL12: 1.5 | AN12: =SUM(I12:AM12) -> 38.5 | AO12: 190000 | AP12: =AN12*AO12 -> 7315000
A13: 8 | B13: 김태훈 | C13: 810515-1814611 | D13: 보통인부 | E13: 010-5844-3098 | F13: 농협 | G13: 김태훈 | H13: 793-12-097221 | I13: 2 | J13: 2 | K13: 1.5 | L13: 2 | M13: 2 | P13: 2 | Q13: 2 | R13: 2 | S13: 2 | T13: 2 | U13: 1 | W13: 1.5 | X13: 1.5 | Y13: 1 | Z13: 1.5 | AA13: 1.5 | AD13: 1 | AE13: 1 | AF13: 1.5 | AG13: 1.5 | AH13: 1 | AK13: 1 | AL13: 1.5 | AN13: =SUM(I13:AM13) -> 36 | AO13: 150000 | AP13: =AN13*AO13 -> 5400000
A14: 9 | B14: 도남철 | C14: 681003-1683610 | D14: 보통인부 | E14: 010-3734-2196 | F14: 새마을 | G14: 도남철 | H14: 9002-1869-8588-9 | I14: 2 | J14: 2 | K14: 1.5 | L14: 2 | M14: 2 | N14: 1.5 | P14: 2 | Q14: 2 | R14: 2 | S14: 2 | T14: 2 | U14: 1 | W14: 1.5 | X14: 1.5 | Y14: 1 | Z14: 1.5 | AA14: 1.5 | AD14: 1 | AE14: 1 | AF14: 1.5 | AG14: 1.5 | AH14: 1 | AK14: 1 | AL14: 1.5 | AN14: =SUM(I14:AM14) -> 37.5 | AO14: 150000 | AP14: =AN14*AO14 -> 5625000
A15: 10 | B15: 백승배 | C15: 850323-1520514 | D15: 도비공 | E15: 010-8113-3288 | F15: 우체국 | G15: 백승배 | H15: 402057-02-369681 | I15: 2 | J15: 2 | K15: 1.5 | L15: 2 | M15: 2 | P15: 2 | Q15: 2 | R15: 2 | S15: 2 | T15: 1.75 | U15: 1 | W15: 1.5 | X15: 1.5 | Y15: 1 | Z15: 1.5 | AA15: 1.25 | AB15: 0.5 | AD15: 1 | AE15: 1 | AF15: 1.5 | AH15: 1 | AK15: 1 | AL15: 1.5 | AN15: =SUM(I15:AM15) -> 34.5 | AO15: 190000 | AP15: =AN15*AO15 -> 6555000
A16: 11 | B16: 이정완 | C16: 680304-1661020 | D16: 보통인부 | E16: 010-3833-5897 | F16: 카카오 | G16: 이정완 | H16: 3333-22-9072681 | I16: 2 | J16: 2 | K16: 1.5 | L16: 2 | M16: 2 | N16: 1.5 | P16: 2 | Q16: 2 | R16: 2 | S16: 2 | T16: 2 | U16: 1 | W16: 1.5 | X16: 1.5 | Y16: 1 | Z16: 1.5 | AA16: 1.5 | AB16: 1 | AD16: 1 | AE16: 1 | AF16: 1.5 | AG16: 1.5 | AH16: 0.5 | AK16: 1 | AL16: 1.5 | AN16: =SUM(I16:AM16) -> 38 | AO16: 150000 | AP16: =AN16*AO16 -> 5700000
A17: 12 | B17: 임세훈 | C17: 801028-1113827 | D17: 용접공 | E17: 010-7444-3839 | F17: 기업 | G17: 임세훈 | H17: 453-050090-01-012 | I17: 2 | J17: 0.5 | K17: 1.5 | L17: 2 | M17: 1.5 | P17: 2 | Q17: 2 | R17: 2 | S17: 2 | T17: 2 | W17: 1.5 | Y17: 1 | AA17: 1.5 | AD17: 1 | AE17: 1 | AF17: 1.5 | AG17: 1.5 | AK17: 1 | AL17: 1.5 | AN17: =SUM(I17:AM17) -> 29 | AO17: 240000 | AP17: =AN17*AO17 -> 6960000
A18: 13 | B18: 정일교 | C18: 761021-1348015 | D18: 보통인부 | E18: 010-3789-1185 | F18: 신한 | G18: 정일교 | H18: 360-13-033492 | I18: 2 | J18: 2 | K18: 1.5 | M18: 2 | N18: 1.5 | Q18: 2 | R18: 2 | S18: 2 | T18: 2 | U18: 1 | W18: 1.5 | X18: 1.5 | Y18: 1 | Z18: 1.5 | AA18: 1.5 | AB18: 1 | AD18: 1 | AE18: 1 | AF18: 1.5 | AH18: 1 | AK18: 1 | AL18: 1.5 | AN18: =SUM(I18:AM18) -> 33 | AO18: 160000 | AP18: =AN18*AO18 -> 5280000
A19: 14 | B19: 전준 | C19: 800228-1168033 | D19: 보통인부 | E19: 010-2822-3392 | F19: 신한 | G19: 전준 | H19: 110-264-802497 | I19: 2 | J19: 2 | K19: 1.5 | L19: 2 | M19: 2 | N19: 1.5 | P19: 2 | Q19: 2 | R19: 2 | S19: 2 | T19: 2 | U19: 1 | W19: 1.5 | X19: 1.5 | Y19: 1 | Z19: 1.5 | AA19: 1.5 | AB19: 1 | AD19: 1 | AE19: 1 | AF19: 1.5 | AG19: 1.5 | AH19: 1 | AI19: 1 | AK19: 1 | AL19: 1.5 | AN19: =SUM(I19:AM19) -> 39.5 | AO19: 210000 | AP19: =AN19*AO19 -> 8295000
A20: 15 | B20: 안성원 | C20: 730222-1674813 | D20: 보통인부 | E20: 010-9575-3445 | F20: 새마을 | G20: 안성원 | H20: 9003-2348-2974-4 | I20: 2 | J20: 2 | K20: 1.5 | L20: 2 | M20: 1.5 | P20: 2 | Q20: 2 | R20: 2 | S20: 2 | T20: 2 | U20: 1 | W20: 1.5 | X20: 1.5 | Y20: 1 | Z20: 1.5 | AA20: 1.5 | AB20: 1 | AD20: 1 | AE20: 1 | AF20: 1.5 | AG20: 1.5 | AH20: 1 | AK20: 1 | AL20: 1.5 | AN20: =SUM(I20:AM20) -> 36.5 | AO20: 170000 | AP20: =AN20*AO20 -> 6205000
A21: 16 | B21: 강희재 | C21: 940122-1491011 | D21: 공사보조 | E21: 010-9127-3784 | F21: 신한 | G21: 강희재 | H21: 110-404-502876 | I21: 2 | J21: 2 | K21: 1.5 | L21: 2 | M21: 2 | P21: 2 | Q21: 2 | R21: 2 | S21: 2 | T21: 3 | U21: 1 | W21: 1.5 | X21: 1.5 | Y21: 1 | Z21: 1.5 | AA21: 1.5 | AD21: 1 | AE21: 1 | AF21: 1.5 | AG21: 1.5 | AH21: 1 | AI21: 1 | AK21: 1 | AL21: 1.5 | AN21: =SUM(I21:AM21) -> 38 | AO21: 230000 | AP21: =AN21*AO21 -> 8740000
A22: 17 | B22: 김광동 | C22: 930520-1692511 | D22: 보통인부 | E22: 010-4348-0266 | F22: 국민 | G22: 김광동 | H22: 926102-01-496205 | I22: 2 | J22: 2 | K22: 1.5 | L22: 2 | M22: 2 | N22: 1.5 | P22: 2 | Q22: 2 | R22: 2 | S22: 2 | T22: 2 | U22: 1 | W22: 1.5 | X22: 1.5 | Y22: 1 | Z22: 1.5 | AA22: 1.5 | AD22: 1 | AE22: 1 | AF22: 1.5 | AG22: 1.5 | AH22: 1 | AK22: 1 | AL22: 1.5 | AN22: =SUM(I22:AM22) -> 37.5 | AO22: 150000 | AP22: =AN22*AO22 -> 5625000
A23: 18 | B23: 박세호 | C23: 830125-1674711 | D23: 용접공 | E23: 010-8898-7171 | F23: 카카오 | G23: 박세호 | H23: 3333-21-7116487 | I23: 2 | J23: 2 | K23: 1.5 | L23: 2 | M23: 2 | N23: 1.5 | P23: 2 | Q23: 2 | R23: 2 | S23: 2 | T23: 2 | W23: 1.5 | X23: 1.5 | Y23: 1 | Z23: 1.5 | AA23: 1.5 | AB23: 1 | AD23: 1 | AE23: 1 | AF23: 1.5 | AG23: 1.5 | AH23: 1 | AK23: 1 | AL23: 1.5 | AN23: =SUM(I23:AM23) -> 37.5 | AO23: 240000 | AP23: =AN23*AO23 -> 9000000
A24: 19 | B24: 이상수 | C24: 810518-1927711 | D24: 용접공 | E24: 010-3552-7717 | F24: 기업 | G24: 이상수 | H24: 171-077318-02-013 | I24: 2 | J24: 2 | K24: 1.5 | L24: 2 | M24: 2 | N24: 1.5 | R24: 2 | S24: 2 | T24: 2 | Z24: 1.5 | AA24: 1.5 | AD24: 1 | AE24: 1 | AF24: 1.5 | AG24: 1.5 | AH24: 1 | AL24: 1.5 | AN24: =SUM(I24:AM24) -> 27.5 | AO24: 240000 | AP24: =AN24*AO24 -> 6600000
A25: 20 | B25: 박성호 | C25: 941107-1199714 | D25: 배관공 | E25: 010-2922-3403 | F25: 기업 | G25: 박성호 | H25: 450-033865-01-013 | I25: 2 | J25: 2 | K25: 1.5 | L25: 2 | M25: 2 | P25: 2 | Q25: 2 | R25: 2 | S25: 2 | T25: 2 | U25: 0.5 | W25: 1.5 | X25: 1.5 | Y25: 1 | Z25: 1.5 | AA25: 1.5 | AB25: 1 | AD25: 1 | AE25: 1 | AF25: 1.5 | AG25: 1.5 | AH25: 1 | AI25: 1 | AK25: 1 | AL25: 1.5 | AN25: =SUM(I25:AM25) -> 37.5 | AO25: 190000 | AP25: =AN25*AO25 -> 7125000
A26: 21 | B26: 김영철 | C26: 720622-1921415 | D26: 배관공 | E26: 010-3884-4513 | F26: 새마을 | G26: 김영철 | H26: 9003-2504-8199-8 | I26: 2 | J26: 2 | K26: 1.5 | L26: 2 | M26: 2 | N26: 1.5 | P26: 2 | Q26: 2 | R26: 2 | S26: 2 | T26: 2 | U26: 1 | W26: 1.5 | X26: 1.5 | Y26: 1 | Z26: 1.5 | AA26: 0.5 | AD26: 1 | AE26: 1 | AF26: 1.5 | AG26: 1.5 | AK26: 1 | AL26: 1.5 | AN26: =SUM(I26:AM26) -> 35.5 | AO26: 210000 | AP26: =AN26*AO26 -> 7455000
A27: 22 | B27: 강원태 | C27: 920818-1240811 | D27: 보통인부 | E27: 010-9205-4684 | F27: 기업 | G27: 강원태 | H27: 186-075475-01-013 | I27: 2 | J27: 2 | K27: 1.5 | L27: 2 | M27: 2 | N27: 1.5 | P27: 2 | Q27: 2 | R27: 2 | S27: 2 | T27: 2 | W27: 1.5 | X27: 1.5 | Y27: 1 | Z27: 1.5 | AA27: 1.5 | AB27: 1 | AD27: 1 | AE27: 1 | AF27: 1.5 | AG27: 1.5 | AH27: 1 | AK27: 1 | AL27: 1.5 | AN27: =SUM(I27:AM27) -> 37.5 | AO27: 160000 | AP27: =AN27*AO27 -> 6000000
A28: 23 | B28: 양동현 | C28: 970121-1126611 | D28: 보통인부 | E28: 010-5213-3183 | F28: 카카오 | G28: 양동현 | H28: 3333-05-3629952 | I28: 2 | J28: 2 | K28: 1.5 | L28: 2 | M28: 2 | N28: 1.5 | P28: 2 | Q28: 2 | R28: 2 | S28: 2 | T28: 2 | U28: 1 | W28: 1.5 | X28: 1.5 | Y28: 1 | Z28: 1.5 | AA28: 1.5 | AB28: 1 | AD28: 1 | AE28: 1 | AF28: 1.5 | AG28: 1.5 | AH28: 1 | AL28: 1.5 | AN28: =SUM(I28:AM28) -> 37.5 | AO28: 150000 | AP28: =AN28*AO28 -> 5625000
A29: 24 | B29: 박승남 | C29: 730316-1654417 | D29: 보통인부 | E29: 010-7618-6130 | F29: 농협 | G29: 박승남 | H29: 211065-56-138642 | I29: 2 | J29: 2 | K29: 1.5 | L29: 2 | M29: 2 | N29: 1.5 | P29: 0.5 | Q29: 2 | R29: 2 | S29: 2 | T29: 2 | X29: 1.5 | Y29: 1 | Z29: 1.5 | AA29: 1.5 | AD29: 1 | AE29: 1 | AF29: 1.5 | AG29: 1.5 | AH29: 1 | AK29: 1 | AL29: 1.5 | AN29: =SUM(I29:AM29) -> 33.5 | AO29: 150000 | AP29: =AN29*AO29 -> 5025000
A30: 25 | B30: 남희수 | C30: 741212-1068534 | D30: 보통인부 | E30: 010-8994-9296 | F30: 국민 | G30: 남희수 | H30: 547201-01-029724 | I30: 2 | J30: 2 | K30: 1.5 | L30: 2 | M30: 2 | N30: 1.5 | P30: 2 | Q30: 2 | R30: 2 | S30: 2 | T30: 2 | U30: 1 | W30: 1.5 | X30: 1.5 | Y30: 1 | Z30: 1.5 | AA30: 1.5 | AB30: 1 | AD30: 1 | AE30: 1 | AF30: 1.5 | AG30: 1.5 | AH30: 1 | AK30: 1 | AL30: 1.5 | AN30: =SUM(I30:AM30) -> 38.5 | AO30: 160000 | AP30: =AN30*AO30 -> 6160000
A31: 26 | B31: 신원석 | C31: 820823-1151611 | D31: 보통인부 | E31: 010-5794-3572 | F31: 신한 | G31: 신원석 | H31: 110-312-958801 | I31: 2 | J31: 2 | K31: 1.5 | L31: 2 | M31: 2 | N31: 1.5 | P31: 2 | Q31: 2 | R31: 2 | S31: 2 | T31: 2 | W31: 1.5 | X31: 1.5 | Y31: 1 | Z31: 1.5 | AA31: 1.5 | AB31: 1 | AD31: 1 | AE31: 1 | AF31: 1.5 | AG31: 1.5 | AH31: 1 | AK31: 1 | AL31: 1.5 | AN31: =SUM(I31:AM31) -> 37.5 | AO31: 190000 | AP31: =AN31*AO31 -> 7125000
A32: 27 | B32: 원홍연 | C32: 801025-1057720 | D32: 공사보조 | E32: 010-2922-2223 | F32: 케이뱅크 | G32: 원홍연 | H32: 100-214-461370 | I32: 2 | J32: 2 | K32: 1.5 | L32: 2 | M32: 2 | N32: 1.5 | P32: 2 | Q32: 2 | R32: 2 | S32: 2 | T32: 3 | U32: 0.875 | W32: 1.5 | X32: 1.5 | Y32: 1 | Z32: 1.5 | AA32: 1.5 | AB32: 1 | AE32: 1 | AF32: 1.5 | AG32: 1.5 | AH32: 1 | AI32: 1 | AK32: 1 | AL32: 1.5 | AN32: =SUM(I32:AM32) -> 39.375 | AO32: 230000 | AP32: =AN32*AO32 -> 9056250
A33: 28 | B33: 최연지 | C33: 981006-2192118 | D33: 보통인부 | E33: 010-6714-4859 | F33: 토스 | G33: 최연지 | H33: 1000-8388-0973 | I33: 2 | J33: 2 | K33: 1.5 | L33: 2 | M33: 2 | N33: 1.5 | P33: 2 | Q33: 2 | R33: 2 | S33: 2 | T33: 2 | U33: 0.875 | W33: 1.5 | X33: 1.5 | Y33: 1 | Z33: 1 | AA33: 1.5 | AB33: 1 | AD33: 1 | AE33: 1 | AF33: 1.5 | AG33: 1.5 | AH33: 1 | AK33: 1 | AL33: 1.5 | AN33: =SUM(I33:AM33) -> 37.875 | AO33: 160000 | AP33: =AN33*AO33 -> 6060000
A34: 29 | B34: 송수림 | C34: 840920-1789928 | D34: 보통인부 | E34: 010-2777-7145 | F34: 농협 | G34: 송수림 | H34: 352-0253-3500-63 | I34: 2 | J34: 2 | K34: 1.5 | L34: 2 | M34: 2 | N34: 1.5 | P34: 2 | Q34: 2 | R34: 2 | S34: 2 | T34: 2 | U34: 1 | W34: 1.5 | X34: 1.5 | Y34: 1 | Z34: 1.5 | AA34: 1.5 | AB34: 1 | AD34: 1 | AE34: 1 | AF34: 1.5 | AG34: 1.5 | AH34: 1 | AK34: 1 | AL34: 1.5 | AN34: =SUM(I34:AM34) -> 38.5 | AO34: 150000 | AP34: =AN34*AO34 -> 5775000
A35: 30 | B35: 임승희 | C35: 881107-1235222 | D35: 공사보조 | E35: 010-4393-9938 | F35: 신한 | G35: 임승희 | H35: 110-353-055995 | I35: 2 | J35: 2 | K35: 1.5 | L35: 2 | M35: 2 | N35: 1.5 | P35: 2 | Q35: 2 | R35: 2 | S35: 2 | T35: 2 | U35: 1 | W35: 1.5 | X35: 1.5 | Y35: 1 | Z35: 1.5 | AA35: 1.5 | AB35: 1 | AD35: 1 | AE35: 1 | AF35: 1.5 | AG35: 1.5 | AH35: 1 | AK35: 1 | AL35: 1.5 | AN35: =SUM(I35:AM35) -> 38.5 | AO35: 210000 | AP35: =AN35*AO35 -> 8085000
A36: 31 | B36: 이명재 | C36: 840407-1011315 | D36: 배관공 | E36: 010-2288-2353 | F36: 신한 | G36: 이명재 | H36: 110-470-707347 | I36: 2 | J36: 2 | K36: 1.5 | L36: 2 | M36: 2 | N36: 1.5 | P36: 2 | Q36: 2 | R36: 2 | S36: 2 | T36: 2 | U36: 1 | W36: 1.5 | X36: 1.5 | Y36: 1 | Z36: 1.5 | AA36: 1.5 | AE36: 1 | AF36: 1.5 | AG36: 1.5 | AH36: 1 | AK36: 1 | AL36: 1.5 | AN36: =SUM(I36:AM36) -> 36.5 | AO36: 200000 | AP36: =AN36*AO36 -> 7300000
A37: 32 | B37: 최동건 | C37: 830504-1000819 | D37: 보통인부 | E37: 010-9456-1177 | F37: 우리 | G37: 최동건 | H37: 1002-646-504814 | I37: 2 | J37: 2 | K37: 1.5 | L37: 2 | M37: 2 | N37: 1.5 | P37: 2 | Q37: 2 | R37: 2 | S37: 2 | T37: 2 | X37: 1.5 | Y37: 1 | Z37: 1.5 | AA37: 1.5 | AB37: 1 | AD37: 1 | AE37: 1 | AF37: 1.5 | AG37: 1.5 | AH37: 1 | AK37: 1 | AL37: 1.5 | AN37: =SUM(I37:AM37) -> 36 | AO37: 160000 | AP37: =AN37*AO37 -> 5760000
A38: 33 | B38: 김성중 | C38: 911126-1043210 | D38: 보통인부 | E38: 010-3777-9825 | F38: 기업 | G38: 김성중 | H38: 118-149246-01-011 | I38: 2 | J38: 2 | K38: 1.5 | M38: 2 | N38: 1.5 | P38: 2 | R38: 2 | S38: 2 | T38: 2 | U38: 1 | W38: 1.5 | X38: 1.5 | Y38: 1 | Z38: 1.5 | AA38: 1.5 | AD38: 1 | AE38: 1 | AF38: 1.5 | AG38: 1.5 | AH38: 1 | AK38: 1 | AL38: 1.5 | AN38: =SUM(I38:AM38) -> 33.5 | AO38: 150000 | AP38: =AN38*AO38 -> 5025000
A39: 34 | B39: 서현우 | C39: 911210-1163410 | D39: 보통인부 | E39: 010-2320-6077 | F39: 하나 | G39: 서현우 | H39: 576-910358-27807 | I39: 2 | J39: 2 | K39: 1.5 | L39: 2 | M39: 2 | N39: 1.5 | P39: 2 | Q39: 2 | R39: 2 | S39: 2 | T39: 2 | U39: 1 | W39: 1.5 | X39: 1.5 | Y39: 1 | Z39: 1.5 | AA39: 1.5 | AD39: 1 | AE39: 1 | AF39: 1.5 | AG39: 1.5 | AH39: 1 | AK39: 1 | AL39: 1.5 | AN39: =SUM(I39:AM39) -> 37.5 | AO39: 150000 | AP39: =AN39*AO39 -> 5625000
A40: 35 | B40: 정의돈 | C40: 781215-1324314 | D40: 배관공 | E40: 010-4169-5213 | F40: 신한 | G40: 정의돈 | H40: 605-04-400370 | I40: 2 | J40: 2 | K40: 1.5 | L40: 2 | M40: 2 | N40: 1.5 | P40: 2 | Q40: 2 | R40: 2 | S40: 2 | T40: 2 | U40: 1 | W40: 1.5 | X40: 1.5 | Y40: 1 | Z40: 1.5 | AA40: 1.5 | AB40: 1 | AD40: 1 | AE40: 1 | AF40: 1.5 | AG40: 1.5 | AH40: 1 | AK40: 1 | AL40: 1.5 | AN40: =SUM(I40:AM40) -> 38.5 | AO40: 220000 | AP40: =AN40*AO40 -> 8470000
A41: 36 | B41: 김재호 | C41: 740417-1691211 | D41: 배관공 | E41: 010-7903-8334 | F41: 수협 | G41: 김재호 | H41: 0010-2858-8334 | I41: 2 | J41: 2 | K41: 1.5 | L41: 2 | M41: 2 | N41: 1.5 | P41: 2 | Q41: 2 | R41: 2 | S41: 2 | T41: 2 | U41: 1 | W41: 1.5 | X41: 1.5 | Y41: 1 | Z41: 1.5 | AA41: 1.5 | AD41: 1 | AE41: 1 | AF41: 1.5 | AG41: 1.5 | AK41: 1 | AL41: 1.5 | AN41: =SUM(I41:AM41) -> 36.5 | AO41: 230000 | AP41: =AN41*AO41 -> 8395000
...

Sheet 용접기자재
A1: 용접 기자재
A2: No | B2: 구매일 | C2: 구분 | D2: 품명 | E2: 규격 | F2: 거래처명 | G2: 발주수량 | H2: 단가 | I2: 합계 | J2: 비고
I3: =ROUND(SUM(I4:I82),) -> 0
A4: =ROW()-3 -> 1 | L4: 입력해야하는 항목 외 수정 금지
A5: =ROW()-3 -> 2 | L5: 입력항목
A6: =ROW()-3 -> 3 | L6: 구매일
A7: =ROW()-3 -> 4 | L7: 구분
A8: =ROW()-3 -> 5 | L8: 품명
A9: =ROW()-3 -> 6 | L9: 규격
L10: 거래처명
L11: 발주수량
L12: 단가
L14: ■ 구분은 [소모성자재, 공구, 임대(공구), 안전용품, 비품] 이외 항목은 입력금지

Sheet 배관기자재
A1: 배관 기자재
A2: No | B2: 구매일 | C2: 구분 | D2: 품명 | E2: 규격 | F2: 거래처명 | G2: 발주수량 | H2: 단가 | I2: 합계 | J2: 비고
I3: =ROUND(SUM(I4:I34),) -> 1346664 | L3: 입력해야하는 항목 외 수정 금지
A4: =ROW()-3 -> 1 | B4: 46174 | C4: 소모성자재 | D4: 청보호테이프 | E4: 500mm*4롤 | F4: 네이버파이낸셜㈜ | G4: 1 | H4: 62727.273 | I4: 62727.273 | L4: 입력항목
A5: =ROW()-3 -> 2 | B5: 46174 | C5: 소모성자재 | D5: 페인트붓 | E5: [1" [동양]] | F5: 미래공구 | G5: 10 | H5: 1500 | I5: 15000 | L5: 구매일
A6: =ROW()-3 -> 3 | B6: 46175 | C6: 소모성자재 | D6: 포장용비닐 | E6: [300*0.045T*440m [국산]] | F6: 미래공구 | G6: 1 | H6: 60100 | I6: 60100 | L6: 구분
A7: =ROW()-3 -> 4 | B7: 46175 | C7: 소모성자재 | D7: 포장용비닐 | E7: [700*0.045T*440m [국산]] | F7: 미래공구 | G7: 1 | H7: 89500 | I7: 89500 | L7: 품명
A8: =ROW()-3 -> 5 | B8: 46175 | C8: ㅗㅅ | D8: 엑서부품 | E8: [CCDT,손잡이,Penetration handle [엑서]] | F8: 미래공구 | G8: 1 | H8: 181000 | I8: 181000 | L8: 규격
A9: =ROW()-3 -> 6 | B9: 46175 | C9: 소모성자재 | D9: 엑서부품 | E9: [CCFE-13,삽입레버,Penetration lever CCFE [엑서]] | F9: 미래공구 | G9: 1 | H9: 52000 | I9: 52000 | L9: 거래처명
A10: =ROW()-3 -> 7 | B10: 46178 | C10: 소모성자재 | D10: 번호열쇠 | E10: [XD-40,4열 [자커]] | F10: 미래공구 | G10: 5 | H10: 3600 | I10: 18000 | L10: 발주수량
A11: =ROW()-3 -> 8 | B11: 46178 | C11: 소모성자재 | D11: 실리콘헤라 | E11: [SPK-4(4호),소 [스마토]] | F11: 미래공구 | G11: 1 | H11: 1200 | I11: 1200 | L11: 단가
A12: =ROW()-3 -> 9 | B12: 46178 | C12: 소모성자재 | D12: 티별렌치 | E12: [SB-TS15,T15*100,CTX [세신]] | F12: 미래공구 | G12: 2 | H12: 2400 | I12: 4800
A13: =ROW()-3 -> 10 | B13: 46178 | C13: 소모성자재 | D13: 수리비,디월트 | E13: [DCB380,프란쟈,니플,구리스] | F13: 미래공구 | G13: 1 | H13: 64900 | I13: 64900 | N13: ■ 구분은 [소모성자재, 공구, 임대(공구), 안전용품, 비품] 이외 항목은 입력금지
A14: =ROW()-3 -> 11 | B14: 46182 | C14: 소모성자재 | D14: 컷쏘날 | E14: [S1122BF,철재,바이메탈,5개입 [보쉬]] | F14: 미래공구 | G14: 2 | H14: 19500 | I14: 39000
A15: =ROW()-3 -> 12 | B15: 46182 | C15: 소모성자재 | D15: 쇠톱날 | E15: [12"*24TPI [레녹스]] | F15: 미래공구 | G15: 2 | H15: 1500 | I15: 3000
A16: =ROW()-3 -> 13 | B16: 46182 | C16: 소모성자재 | D16: 가위 | E16: [SB-P300,CTX [세신]] | F16: 미래공구 | G16: 20 | H16: 4500 | I16: 90000
A17: =ROW()-3 -> 14 | B17: 46182 | C17: 소모성자재 | D17: 케이블타이 | E17: [300mm(1봉=500개),백색 [HNS]] | F17: 미래공구 | G17: 3 | H17: 12500 | I17: 37500
A18: =ROW()-3 -> 15 | B18: 46182 | C18: 소모성자재 | D18: 튜브컷터날 | E18: [RBN67P용,스텐 [렉스]] | F18: 미래공구 | G18: 2 | H18: 45000 | I18: 90000
A19: =ROW()-3 -> 16 | B19: 46184 | C19: 소모성자재 | D19: 파이프안전커버 | E19: [10T*50mm*2m,난연,황/흑 [SW]] | F19: 미래공구 | G19: 5 | H19: 2700 | I19: 13500
A20: =ROW()-3 -> 17 | B20: 46184 | C20: 소모성자재 | D20: 칫솔브러쉬 | E20: [브러쉬,스텐 [스마토]] | F20: 미래공구 | G20: 10 | H20: 800 | I20: 8000
A21: =ROW()-3 -> 18 | B21: 46184 | C21: 소모성자재 | D21: 양면테이프 | E21: [50mm*6m,핫멧트 [HNS]] | F21: 미래공구 | G21: 10 | H21: 900 | I21: 9000
A22: =ROW()-3 -> 19 | B22: 46184 | C22: 소모성자재 | D22: 밴드쏘날 | E22: [1640*13*0.65-14T [WESPA]] | F22: 미래공구 | G22: 10 | H22: 12000 | I22: 120000
A23: =ROW()-3 -> 20 | B23: 46184 | C23: 소모성자재 | D23: 스텝드릴 | E23: [4-22,SJ-SD22A,Co8%,육각생크 [블랑코]] | F23: 미래공구 | G23: 5 | H23: 11200 | I23: 56000
A24: =ROW()-3 -> 21 | B24: 46195 | C24: 소모성자재 | D24: 컷쏘날 | E24: [S1122BF,철재,바이메탈,5개입 [보쉬]] | F24: 미래공구 | G24: 3 | H24: 19500 | I24: 58500
A25: =ROW()-3 -> 22 | B25: 46195 | C25: 소모성자재 | D25: 컷쏘날 | E25: [S922BF,철재,바이메탈,5개입 [보쉬]] | F25: 미래공구 | G25: 3 | H25: 15500 | I25: 46500
... A30: =ROW()-3 -> 27 | B30: 46199 | C30: 소모성자재 | D30: 방청유 | E30: [WD-40,360ML [BEX]] | F30: 미래공구 | G30: 2 | H30: 5500 | I30: 11000
A31: =ROW()-3 -> 28 | B31: 46174 | C31: 소모성자재 | D31: AAA 건전지 | F31: 쿠팡㈜ | G31: 5 | H31: 9500 | I31: 47500
A32: =ROW()-3 -> 29 | B32: 46191 | C32: 소모성자재 | D32: 쓰리엠 슈퍼그립 장갑 | E32: M | F32: 쿠팡㈜ | G32: 20 | H32: 1863.6364 | I32: 37272.727
A33: =ROW()-3 -> 30 | B33: 46191 | C33: 소모성자재 | D33: 쓰리엠 슈퍼그립 장갑 | E33: S | F33: 쿠팡㈜ | G33: 10 | H33: 2090.9091 | I33: 20909.091
A34: =ROW()-3 -> 31 | B34: 46195 | C34: 소모성자재 | D34: AA 건전지 | F34: 쿠팡㈜ | G34: 80 | H34: 293.18182 | I34: 23454.545

Sheet 숙소임차료
A1: 숙소 임차료
A2: No. | B2: 납부일 | C2: 구분 | D2: 품명 | E2: 주소 | F2: 호수 | G2: 수량 | H2: 사용인원 | I2: 임차료 | J2: 비 고
I3: =SUM(I4:I14) -> 12046667 | L3: 입력해야하는 항목 외 수정 금지
A4: =ROW()-3 -> 1 | B4: 46203 | C4: KC대납 임대료 | D4: 숙소임대료(6월분) | E4: 함박산1길 16 | F4: 301호 | G4: 1 | I4: =800000 -> 800000 | J4: KC 대납 | L4: 납부일
A5: =ROW()-3 -> 2 | B5: 46203 | C5: KC대납 임대료 | D5: 숙소임대료(6월분) | E5: 함박산9길 8-1 | F5: 201호 | G5: 1 | I5: =850000/30*5 -> 141666.67 | J5: KC 대납 | L5: 구분
A6: =ROW()-3 -> 3 | B6: 46203 | C6: KC대납 임대료 | D6: 숙소임대료(6월분) | E6: 함박산12길 8-10 | F6: 301호 | G6: 1 | I6: =950000/30*5+1700000/30*25 -> 1575000 | J6: KC 대납 | L6: 품명
A7: =ROW()-3 -> 4 | B7: 46203 | C7: KC대납 임대료 | D7: 숙소임대료(6월분) | E7: 고덕여염6길 108 | F7: 302호 | G7: 1 | I7: =1000000/30*12+1700000/30*18 -> 1420000 | J7: KC 대납 | L7: 주소
A8: =ROW()-3 -> 5 | B8: 46203 | C8: KC대납 임대료 | D8: 숙소임대료(6월분) | E8: 고덕여염16길 32 | F8: 202호 | G8: 1 | I8: =850000/30*12+1700000/30*18 -> 1360000 | J8: KC 대납 | L8: 호수
A9: =ROW()-3 -> 6 | B9: 46203 | C9: KC대납 임대료 | D9: 숙소임대료(6월분) | E9: 고덕여염 5길 15-10 | F9: 301호 | G9: 1 | I9: 1000000 | J9: KC 대납 | L9: 수량
A10: =ROW()-3 -> 7 | B10: 46203 | C10: KC대납 임대료 | D10: 숙소임대료(6월분) | E10: 고덕여염 5길 15-10 | F10: 201호 | G10: 1 | I10: 1000000 | J10: KC 대납 | L10: 사용인원
A11: =ROW()-3 -> 8 | B11: 46203 | C11: KC대납 임대료 | D11: 숙소임대료(6월분) | E11: 고덕 갈평10길 67 | F11: 201호 | G11: 1 | I11: 950000 | J11: KC 대납
A12: =ROW()-3 -> 9 | B12: 46203 | C12: KC대납 임대료 | D12: 숙소임대료(6월분) | E12: 고덕 갈평9길 43 | F12: 202호 | G12: 1 | I12: 1000000 | J12: KC 대납 | L12: ■ 구분은 [KC대납 임대료 및 임대료] 이외 항목은 입력금지
A13: =ROW()-3 -> 10 | B13: 46203 | C13: KC대납 임대료 | D13: 숙소임대료(6월분) | E13: 함박산2길 32-2 | F13: 201호 | G13: 1 | I13: 1700000 | J13: KC 대납
A14: =ROW()-3 -> 11 | B14: 46203 | C14: KC대납 임대료 | D14: 숙소임대료(6월분) | E14: 함박산4길 20 | F14: 202호 | G14: 1 | I14: 1100000 | J14: KC 대납

Sheet 숙소관리비
A1: 숙소 관리비
A2: No. | B2: 납부일 | C2: 구분 | D2: 품명 | E2: 주소 | F2: 호수 | G2: 수량 | H2: 사용인원 | I2: 임차료 | J2: 비 고
I3: =SUM(I4:I25) -> 1127840
A4: =ROW()-3 -> 1 | B4: 46173 | C4: 관리비 | D4: 숙소전기요금(5월) | E4: 함박산12길 8-10 | F4: 301호 | G4: 1 | I4: 67990
A5: =ROW()-3 -> 2 | B5: 46173 | C5: 관리비 | D5: 숙소전기요금(5월) | E5: 고덕여염6길 108 | F5: 302호 | G5: 1 | I5: 52090
A6: =ROW()-3 -> 3 | B6: 46173 | C6: 관리비 | D6: 숙소전기요금(5월) | E6: 고덕여염16길 32 | F6: 202호 | G6: 1 | I6: 77780
A7: =ROW()-3 -> 4 | B7: 46173 | C7: 관리비 | D7: 숙소전기요금(5월) | E7: 고덕여염 5길 15-10 | F7: 301호 | G7: 1 | I7: 50990
A8: =ROW()-3 -> 5 | B8: 46173 | C8: 관리비 | D8: 숙소전기요금(5월) | E8: 고덕여염 5길 15-10 | F8: 201호 | G8: 1 | I8: 21180
A9: =ROW()-3 -> 6 | B9: 46173 | C9: 관리비 | D9: 숙소전기요금(5월) | E9: 함박산2길 32-2 | F9: 201호 | G9: 1 | I9: 47120
A10: =ROW()-3 -> 7 | B10: 46173 | C10: 관리비 | D10: 숙소도시가스(5월) | E10: 함박산12길 8-10 | F10: 301호 | G10: 1 | I10: 45050
A11: =ROW()-3 -> 8 | B11: 46173 | C11: 관리비 | D11: 숙소도시가스(5월) | E11: 고덕여염6길 108 | F11: 302호 | G11: 1 | I11: 110240
A12: =ROW()-3 -> 9 | B12: 46173 | C12: 관리비 | D12: 숙소도시가스(5월) | E12: 고덕여염16길 32 | F12: 202호 | G12: 1 | I12: 12280
A13: =ROW()-3 -> 10 | B13: 46173 | C13: 관리비 | D13: 숙소도시가스(5월) | E13: 고덕여염 5길 15-10 | F13: 301호 | G13: 1 | I13: 32300
A14: =ROW()-3 -> 11 | B14: 46173 | C14: 관리비 | D14: 숙소도시가스(5월) | E14: 고덕여염 5길 15-10 | F14: 201호 | G14: 1 | I14: 49160
A15: =ROW()-3 -> 12 | B15: 46173 | C15: 관리비 | D15: 숙소도시가스(5월) | E15: 함박산2길 32-2 | F15: 201호 | G15: 1 | I15: 41860
... A25: =ROW()-3 -> 22 | B25: 46173 | C25: 관리비 | D25: 청소비(5월) | E25: 함박산 9길 8-1 | F25: 201호 | G25: 1 | I25: 250000

Sheet 식대비용
A1: 식대 비용
A2: No. | B2: 납부일 | C2: 구분 | D2: 품명 | E2: 거래처명 | F2: 수량 | G2: 식수인원 | H2: 단가 | I2: 합 계 | J2: 비 고
I3: =SUM(I4:I10) -> 32255455 | L3: 입력해야하는 항목 외 수정 금지
A4: =ROW()-3 -> 1 | B4: 46198 | C4: KC대납 식대 | D4: 기술인및관리자 (현장 식당) | E4: 태정위드유 주식회사 | F4: 1 | H4: 948364 | I4: =F4*H4 -> 948364 | J4: KC 대납 | L4: 입력항목
A5: =ROW()-3 -> 2 | B5: 46198 | C5: KC대납 식대 | D5: 기술인및관리자 (현장 식당) | E5: 다모아한식뷔페 | F5: 59 | H5: 7000 | I5: =F5*H5 -> 413000 | J5: KC 대납 | L5: 납부일
A6: =ROW()-3 -> 3 | B6: 46198 | C6: KC대납 식대 | D6: 기술인및관리자 (현장 식당) | E6: 영미손김밥 | F6: 1 | H6: 2124545 | I6: =F6*H6 -> 2124545 | J6: KC 대납 | L6: 구분
A7: =ROW()-3 -> 4 | B7: 46198 | C7: KC대납 식대 | D7: 기술인및관리자 (현장 식당) | E7: 옛날장터 | F7: 3788 | H7: 7000 | I7: =F7*H7 -> 26516000 | J7: KC 대납 | L7: 품명
A8: =ROW()-3 -> 5 | B8: 46198 | C8: KC대납 식대 | D8: 기술인및관리자 (현장 식당) | E8: 은주네한식뷔페 | F8: 81 | H8: 7000 | I8: =F8*H8 -> 567000 | J8: KC 대납 | L8: 거래처명
A9: =ROW()-3 -> 6 | B9: 46198 | C9: KC대납 식대 | D9: 기술인및관리자 (현장 식당) | E9: 삼성김밥 | F9: 1 | H9: 1522273 | I9: =F9*H9 -> 1522273 | J9: KC 대납 | L9: 수량
A10: =ROW()-3 -> 7 | B10: 46198 | C10: KC대납 식대 | D10: 기술인및관리자 (현장 식당) | E10: 한솥 | F10: 1 | H10: 164273 | I10: =F10*H10 -> 164273 | J10: KC 대납 | L10: 식수인원
A11: =ROW()-3 -> 8 | B11: 46203 | C11: 식대 | E11: 법인카드 | F11: 1 | H11: 1900455 | I11: =F11*H11 -> 1900455 | L11: 단가
L13: ■ 구분은 [KC대납 식대 및 식대] 이외 항목은 입력금지

Sheet 기타비용
A1: 기타 비용
A2: No. | B2: 구매일 | C2: 구분 | D2: 품명 | E2: 거래처명 | F2: 수량 | G2: 단가 | H2: 합계 | I2: 비고
H3: =SUM(H4:H19) -> 1313990.9 | K3: 입력해야하는 항목 외 수정 금지
A4: =ROW()-3 -> 1 | B4: 46174 | C4: 법인카드 | D4: 85어5471 포터2 | E4: (주)소모 칠곡주유소 | F4: 1 | G4: =70000/1.1 -> 63636.364 | H4: =F4*G4 -> 63636.364 | K4: 입력항목
A5: =ROW()-3 -> 2 | B5: 46176 | C5: 법인카드 | D5: 85어5471 포터2 | E5: (주)소모 칠곡주유소 | F5: 1 | G5: =70000/1.1 -> 63636.364 | H5: =F5*G5 -> 63636.364 | K5: 구매일
A6: =ROW()-3 -> 3 | B6: 46178 | C6: 법인카드 | D6: 85어5471 포터2 | E6: (주)소모 칠곡주유소 | F6: 1 | G6: =70000/1.1 -> 63636.364 | H6: =F6*G6 -> 63636.364 | K6: 구분
A7: =ROW()-3 -> 4 | B7: 46181 | C7: 법인카드 | D7: 85어5471 포터2 | E7: (주)소모 칠곡주유소 | F7: 1 | G7: =70000/1.1 -> 63636.364 | H7: =F7*G7 -> 63636.364 | K7: 품명
A8: =ROW()-3 -> 5 | B8: 46183 | C8: 법인카드 | D8: 85어5471 포터2 | E8: (주)소모 칠곡주유소 | F8: 1 | G8: =70000/1.1 -> 63636.364 | H8: =F8*G8 -> 63636.364 | K8: 거래처명
A9: =ROW()-3 -> 6 | B9: 46185 | C9: 법인카드 | D9: 85어5471 포터2 | E9: (주)소모 칠곡주유소 | F9: 1 | G9: =70000/1.1 -> 63636.364 | H9: =F9*G9 -> 63636.364 | K9: 수량
A10: =ROW()-3 -> 7 | B10: 46188 | C10: 법인카드 | D10: 85어5471 포터2 | E10: (주)소모 칠곡주유소 | F10: 1 | G10: =70000/1.1 -> 63636.364 | H10: =F10*G10 -> 63636.364 | K10: 단가
A11: =ROW()-3 -> 8 | B11: 46190 | C11: 법인카드 | D11: 85어5471 포터2 | E11: (주)소모 칠곡주유소 | F11: 1 | G11: =70000/1.1 -> 63636.364 | H11: =F11*G11 -> 63636.364
A12: =ROW()-3 -> 9 | B12: 46192 | C12: 법인카드 | D12: 85어5471 포터2 | E12: (주)소모 칠곡주유소 | F12: 1 | G12: =60000/1.1 -> 54545.455 | H12: =F12*G12 -> 54545.455 | K12: ■ 구분은 [사무용품, 소모품비, 법인카드] 이외 항목은 입력금지
A13: =ROW()-3 -> 10 | B13: 46197 | C13: 법인카드 | D13: 85어5471 포터2 | E13: (주)소모 칠곡주유소 | F13: 1 | G13: =70000/1.1 -> 63636.364 | H13: =F13*G13 -> 63636.364
A14: =ROW()-3 -> 11 | B14: 46199 | C14: 법인카드 | D14: 85어5471 포터2 | E14: (주)소모 칠곡주유소 | F14: 1 | G14: =70000/1.1 -> 63636.364 | H14: =F14*G14 -> 63636.364
A15: =ROW()-3 -> 12 | B15: 46198 | C15: 법인카드 | D15: 85어 5471 차량수리 | E15: 공임나라 평택진위점 | F15: 1 | G15: 407272.73 | H15: 407272.73
A16: =ROW()-3 -> 13 | B16: 46190 | C16: 소모품비 | D16: 네임펜 | E16: 쿠팡㈜ | F16: 24 | G16: 493.93939 | H16: 11854.545
A17: =ROW()-3 -> 14 | B17: 46192 | C17: 소모품비 | D17: A4 용지 | E17: 쿠팡㈜ | F17: 10 | G17: 16718.182 | H17: 167181.82
A18: =ROW()-3 -> 15 | B18: 46195 | C18: 소모품비 | D18: A4 코팅지 | E18: 쿠팡㈜ | F18: 5 | G18: 6081.8182 | H18: 30409.091
A19: =ROW()-3 -> 16 | B19: 46195 | C19: 소모품비 | D19: 네임펜 | E19: 쿠팡㈜ | F19: 12 | G19: 530.30303 | H19: 6363.6364

Sheet 서명란
B2: 현 장 확 인 | C2: 소 장 | E2: (서명)
C3: 공 사 | E3: (서명)
C4: 공 무 | E4: (서명)
G6: 사 업 부 | H6: Frontier 사업부 GNP 본부장 | I6: BOC 센터장 | J6: Frontier 사업부장
L8: 본 사 | M8: 담 당 | N8: 검 토 | O8: 검 토
Q11: 구 분 | R11: 확 인
Q12: 품 질 | R12: O O O (인)
Q13: 공 무 | R13: O O O (인)

Sheet DIA-INCH
B3: SIZE
B4: A(mm) | C4: Inch
B5: 8A | C5: 0.25
B6: 15A | C6: 0.5
B7: 20A | C7: 0.75
B8: 25A | C8: 1
B9: 32A | C9: 1.25
B10: 40A | C10: 1.5
B11: 50A | C11: 2
B12: 65A | C12: 2.5
B13: 80A | C13: 3
B14: 100A | C14: 4
B15: 110A | C15: 4
B16: 125A | C16: 5
... B27: 550A | C27: 22
